Workbook

Sheet Veda
G1: 1,2,3,4,5,6,7,8,9,10,11,12,13,14,15,21,22,23,24,25,31,32,33,34,35,36,37,38,39,40,41,42,43,44,45,46,47,48,49,50,56,57,58,59,60,66,67,68,69,70
D2: ="~Inputcell: "&_xlfn.TEXTJOIN(",",TRUE,G1:EE1) -> ~Inputcell: 1,2,3,4,5,6,7,8,9,10,11,12,13,14,15,21,22,23,24,25,31,32,33,34,35,36,37,38,39,40,41,42,43,44,45,46,47,48,49,50,56,57,58,59,60,66,67,68,69,70 | G2: 5 | H2: 6 | I2: 7 | J2: 9 | K2: 10 | L2: 11 | M2: 16 | N2: 17 | O2: 18 | P2: 20 | Q2: 21 | R2: 22 | S2: 27 | T2: 28 | U2: 29 | V2: 31 | W2: 32 | X2: 33 | Y2: 38 | Z2: 39 | AA2: 40 | AB2: 42 | AC2: 43 | AD2: 44 | AE2: 49 | AF2: 50 | AG2: 51 | AH2: 53 | AI2: 54 | AJ2: 55
D3: 3
D5: =VLOOKUP(D3,$C$9:$E$999,2,FALSE) -> ts_annual | E5: =VLOOKUP(D3,$C$9:$E$999,3,FALSE) -> C3
B7: ~Scenmap
A8: priority | B8: scen | C8: case_no | D8: timeslice | E8: climate | AM8: bio price multiplier
A9: 5 | B9: =VLOOKUP(E9,$AK$9:$AL$15,2,FALSE)&"."&VLOOKUP(D9,$AH$9:$AI$24,2,FALSE) -> e 1.5 deg no OS.kAnn | C9: 1 | D9: =VLOOKUP(AJ9,$AG$9:$AH$22,2,FALSE) -> ts_annual | E9: C1 | G9: Limit warming to 1.5°C (>50%) with no or limited overshoot | AG9: 1 | AH9: ts_annual | AI9: kAnn | AJ9: 1 | AK9: C1 | AL9: e 1.5 deg no OS | AM9: 5
A10: 5 | B10: =VLOOKUP(E10,$AK$9:$AL$15,2,FALSE)&"."&VLOOKUP(D10,$AH$9:$AI$24,2,FALSE) -> d 1.5 deg OS.kAnn | C10: =C9+1 -> 2 | D10: =VLOOKUP(AJ10,$AG$9:$AH$22,2,FALSE) -> ts_annual | E10: C2 | G10: Limit warming to 1.5°C (>67%) with high overshoot | S10: IEA | AG10: 2 | AH10: ts_12t | AI10: k12 | AJ10: 1 | AK10: C2 | AL10: d 1.5 deg OS | AM10: 4
A11: 5 | B11: =VLOOKUP(E11,$AK$9:$AL$15,2,FALSE)&"."&VLOOKUP(D11,$AH$9:$AI$24,2,FALSE) -> c 2 deg (67%).kAnn | C11: =C10+1 -> 3 | D11: =VLOOKUP(AJ11,$AG$9:$AH$22,2,FALSE) -> ts_annual | E11: C3 | G11: Limit warming to 2°C (>67%) with higher action post-2030 | S11: 2022 | AG11: 3 | AH11: ts_012 | AI11: j12 | AJ11: 1 | AK11: C3 | AL11: c 2 deg (67%) | AM11: 3
A12: 5 | B12: =VLOOKUP(E12,$AK$9:$AL$15,2,FALSE)&"."&VLOOKUP(D12,$AH$9:$AI$24,2,FALSE) -> b 2 deg (50%).kAnn | C12: =C11+1 -> 4 | D12: =VLOOKUP(AJ12,$AG$9:$AH$22,2,FALSE) -> ts_annual | E12: C4 | G12: Limit warming to 2°C (>50%) with immediate action | S12: =SUMIFS(iea_data!I3:I9999,iea_data!$B$3:$B$9999,Veda!$S$11)+T28-T29 -> 22.63 | T12: base-year generation (TWh) | AG12: 4 | AH12: ts_024 | AI12: i24 | AJ12: 1 | AK12: C4 | AL12: b 2 deg (50%) | AM12: 3
A13: 5 | B13: =VLOOKUP(E13,$AK$9:$AL$15,2,FALSE)&"."&VLOOKUP(D13,$AH$9:$AI$24,2,FALSE) -> a 3 deg.kAnn | C13: =C12+1 -> 5 | D13: =VLOOKUP(AJ13,$AG$9:$AH$22,2,FALSE) -> ts_annual | E13: C7 | G13: Likely above 3°C warming with limited mitigation | AG13: 5 | AH13: ts_048 | AI13: h48 | AJ13: 1 | AK13: C7 | AL13: a 3 deg | AM13: 1.5
A14: 5 | B14: =VLOOKUP(E14,$AK$9:$AL$15,2,FALSE)&"."&VLOOKUP(D14,$AH$9:$AI$24,2,FALSE) -> e 1.5 deg no OS.k12 | C14: =C13+1 -> 6 | D14: =VLOOKUP(AJ14,$AG$9:$AH$22,2,FALSE) -> ts_12t | E14: =E9 -> C1 | T14: =S12 -> 22.63 | U14: =$S$12*J15 -> 26.4771 | V14: =$S$12*K15 -> 31.682 | W14: =$S$12*L15 -> 37.1132 | X14: =$S$12*M15 -> 42.3181 | Y14: =$S$12*N15 -> 53.4068 | Z14: =$S$12*O15 -> 65.627 | AG14: 6 | AH14: ts_064 | AI14: g64 | AJ14: =AJ9+1 -> 2
A15: 5 | B15: =VLOOKUP(E15,$AK$9:$AL$15,2,FALSE)&"."&VLOOKUP(D15,$AH$9:$AI$24,2,FALSE) -> d 1.5 deg OS.k12 | C15: =C14+1 -> 7 | D15: =VLOOKUP(AJ15,$AG$9:$AH$22,2,FALSE) -> ts_12t | E15: =E10 -> C2 | G15: Electricity growth relative to 2020 | I15: =SUMIFS(ar6_r10!$F$2:$F$999,ar6_r10!$A$2:$A$999,Veda!$E$5,ar6_r10!$C$2:$C$999,Veda!I$17,ar6_r10!$M$2:$M$999,Veda!$G15) -> 1 | J15: =SUMIFS(ar6_r10!$F$2:$F$999,ar6_r10!$A$2:$A$999,Veda!$E$5,ar6_r10!$C$2:$C$999,Veda!J$17,ar6_r10!$M$2:$M$999,Veda!$G15) -> 1.17 | K15: =SUMIFS(ar6_r10!$F$2:$F$999,ar6_r10!$A$2:$A$999,Veda!$E$5,ar6_r10!$C$2:$C$999,Veda!K$17,ar6_r10!$M$2:$M$999,Veda!$G15) -> 1.4 | L15: =SUMIFS(ar6_r10!$F$2:$F$999,ar6_r10!$A$2:$A$999,Veda!$E$5,ar6_r10!$C$2:$C$999,Veda!L$17,ar6_r10!$M$2:$M$999,Veda!$G15) -> 1.64 | M15: =SUMIFS(ar6_r10!$F$2:$F$999,ar6_r10!$A$2:$A$999,Veda!$E$5,ar6_r10!$C$2:$C$999,Veda!M$17,ar6_r10!$M$2:$M$999,Veda!$G15) -> 1.87 | N15: =SUMIFS(ar6_r10!$F$2:$F$999,ar6_r10!$A$2:$A$999,Veda!$E$5,ar6_r10!$C$2:$C$999,Veda!N$17,ar6_r10!$M$2:$M$999,Veda!$G15) -> 2.36 | O15: =SUMIFS(ar6_r10!$F$2:$F$999,ar6_r10!$A$2:$A$999,Veda!$E$5,ar6_r10!$C$2:$C$999,Veda!O$17,ar6_r10!$M$2:$M$999,Veda!$G15) -> 2.9 | AG15: 7 | AH15: ts_096P50 | AI15: f96p50 | AJ15: =AJ10+1 -> 2
A16: 5 | B16: =VLOOKUP(E16,$AK$9:$AL$15,2,FALSE)&"."&VLOOKUP(D16,$AH$9:$AI$24,2,FALSE) -> c 2 deg (67%).k12 | C16: =C15+1 -> 8 | D16: =VLOOKUP(AJ16,$AG$9:$AH$22,2,FALSE) -> ts_12t | E16: =E11 -> C3 | S16: ~TFM_INS-TS | AG16: 8 | AH16: ts_096P10 | AI16: f96p10 | AJ16: =AJ11+1 -> 2
A17: 5 | B17: =VLOOKUP(E17,$AK$9:$AL$15,2,FALSE)&"."&VLOOKUP(D17,$AH$9:$AI$24,2,FALSE) -> b 2 deg (50%).k12 | C17: =C16+1 -> 9 | D17: =VLOOKUP(AJ17,$AG$9:$AH$22,2,FALSE) -> ts_12t | E17: =E12 -> C4 | I17: 2020 | J17: =U17 -> 2025 | K17: =V17 -> 2030 | L17: =W17 -> 2035 | M17: =X17 -> 2040 | N17: =Y17 -> 2045 | O17: =Z17 -> 2050 | S17: commodity | T17: 2022 | U17: 2025 | V17: 2030 | W17: 2035 | X17: 2040 | Y17: 2045 | Z17: 2050 | AA17: attribute | AG17: 9 | AH17: ts_096P90 | AI17: f96p90 | AJ17: =AJ12+1 -> 2
A18: 5 | B18: =VLOOKUP(E18,$AK$9:$AL$15,2,FALSE)&"."&VLOOKUP(D18,$AH$9:$AI$24,2,FALSE) -> a 3 deg.k12 | C18: =C17+1 -> 10 | D18: =VLOOKUP(AJ18,$AG$9:$AH$22,2,FALSE) -> ts_12t | E18: =E13 -> C7 | G18: Hydrogen as a share of electricity | I18: =SUMIFS(ar6_r10!$F$2:$F$999,ar6_r10!$A$2:$A$999,Veda!$E$5,ar6_r10!$C$2:$C$999,Veda!I$17,ar6_r10!$M$2:$M$999,Veda!$G18) -> 0 | J18: =SUMIFS(ar6_r10!$F$2:$F$999,ar6_r10!$A$2:$A$999,Veda!$E$5,ar6_r10!$C$2:$C$999,Veda!J$17,ar6_r10!$M$2:$M$999,Veda!$G18) -> 0 | K18: =SUMIFS(ar6_r10!$F$2:$F$999,ar6_r10!$A$2:$A$999,Veda!$E$5,ar6_r10!$C$2:$C$999,Veda!K$17,ar6_r10!$M$2:$M$999,Veda!$G18) -> 0 | L18: =SUMIFS(ar6_r10!$F$2:$F$999,ar6_r10!$A$2:$A$999,Veda!$E$5,ar6_r10!$C$2:$C$999,Veda!L$17,ar6_r10!$M$2:$M$999,Veda!$G18) -> 0.02 | M18: =SUMIFS(ar6_r10!$F$2:$F$999,ar6_r10!$A$2:$A$999,Veda!$E$5,ar6_r10!$C$2:$C$999,Veda!M$17,ar6_r10!$M$2:$M$999,Veda!$G18) -> 0.03 | N18: =SUMIFS(ar6_r10!$F$2:$F$999,ar6_r10!$A$2:$A$999,Veda!$E$5,ar6_r10!$C$2:$C$999,Veda!N$17,ar6_r10!$M$2:$M$999,Veda!$G18) -> 0.04 | O18: =SUMIFS(ar6_r10!$F$2:$F$999,ar6_r10!$A$2:$A$999,Veda!$E$5,ar6_r10!$C$2:$C$999,Veda!O$17,ar6_r10!$M$2:$M$999,Veda!$G18) -> 0.06 | S18: hydrogen_allsect | T18: =I18*T$14 -> 0 | U18: =J18*U$14 -> 0 | V18: =K18*V$14 -> 0 | W18: =L18*W$14 -> 0.742264 | X18: =M18*X$14 -> 1.269543 | Y18: =N18*Y$14 -> 2.136272 | Z18: =O18*Z$14 -> 3.93762 | AA18: demand | AG18: 10 | AH18: s1p1v1_d | AI18: e3d | AJ18: =AJ13+1 -> 2
A19: 5 | B19: =VLOOKUP(E19,$AK$9:$AL$15,2,FALSE)&"."&VLOOKUP(D19,$AH$9:$AI$24,2,FALSE) -> e 1.5 deg no OS.j12 | C19: =C18+1 -> 11 | D19: =VLOOKUP(AJ19,$AG$9:$AH$22,2,FALSE) -> ts_012 | E19: =E14 -> C1 | G19: Industry electricity share | I19: =SUMIFS(ar6_r10!$F$2:$F$999,ar6_r10!$A$2:$A$999,Veda!$E$5,ar6_r10!$C$2:$C$999,Veda!I$17,ar6_r10!$M$2:$M$999,Veda!$G19) -> 0.25 | J19: =SUMIFS(ar6_r10!$F$2:$F$999,ar6_r10!$A$2:$A$999,Veda!$E$5,ar6_r10!$C$2:$C$999,Veda!J$17,ar6_r10!$M$2:$M$999,Veda!$G19) -> 0.27 | K19: =SUMIFS(ar6_r10!$F$2:$F$999,ar6_r10!$A$2:$A$999,Veda!$E$5,ar6_r10!$C$2:$C$999,Veda!K$17,ar6_r10!$M$2:$M$999,Veda!$G19) -> 0.29 | L19: =SUMIFS(ar6_r10!$F$2:$F$999,ar6_r10!$A$2:$A$999,Veda!$E$5,ar6_r10!$C$2:$C$999,Veda!L$17,ar6_r10!$M$2:$M$999,Veda!$G19) -> 0.3 | M19: =SUMIFS(ar6_r10!$F$2:$F$999,ar6_r10!$A$2:$A$999,Veda!$E$5,ar6_r10!$C$2:$C$999,Veda!M$17,ar6_r10!$M$2:$M$999,Veda!$G19) -> 0.31 | N19: =SUMIFS(ar6_r10!$F$2:$F$999,ar6_r10!$A$2:$A$999,Veda!$E$5,ar6_r10!$C$2:$C$999,Veda!N$17,ar6_r10!$M$2:$M$999,Veda!$G19) -> 0.33 | O19: =SUMIFS(ar6_r10!$F$2:$F$999,ar6_r10!$A$2:$A$999,Veda!$E$5,ar6_r10!$C$2:$C$999,Veda!O$17,ar6_r10!$M$2:$M$999,Veda!$G19) -> 0.33 | S19: elc_industry | T19: =I19*T$14 -> 5.6575 | U19: =J19*U$14 -> 7.148817 | V19: =K19*V$14 -> 9.18778 | W19: =L19*W$14 -> 11.13396 | X19: =M19*X$14 -> 13.118611 | Y19: =N19*Y$14 -> 17.624244 | Z19: =O19*Z$14 -> 21.65691 | AA19: demand | AG19: 11 | AH19: s3p3v3_d | AI19: d9d | AJ19: =AJ14+1 -> 3
A20: 5 | B20: =VLOOKUP(E20,$AK$9:$AL$15,2,FALSE)&"."&VLOOKUP(D20,$AH$9:$AI$24,2,FALSE) -> d 1.5 deg OS.j12 | C20: =C19+1 -> 12 | D20: =VLOOKUP(AJ20,$AG$9:$AH$22,2,FALSE) -> ts_012 | E20: =E15 -> C2 | G20: Residential and commercial electricity share | I20: =SUMIFS(ar6_r10!$F$2:$F$999,ar6_r10!$A$2:$A$999,Veda!$E$5,ar6_r10!$C$2:$C$999,Veda!I$17,ar6_r10!$M$2:$M$999,Veda!$G20) -> 0.73 | J20: =SUMIFS(ar6_r10!$F$2:$F$999,ar6_r10!$A$2:$A$999,Veda!$E$5,ar6_r10!$C$2:$C$999,Veda!J$17,ar6_r10!$M$2:$M$999,Veda!$G20) -> 0.71 | K20: =SUMIFS(ar6_r10!$F$2:$F$999,ar6_r10!$A$2:$A$999,Veda!$E$5,ar6_r10!$C$2:$C$999,Veda!K$17,ar6_r10!$M$2:$M$999,Veda!$G20) -> 0.69 | L20: =SUMIFS(ar6_r10!$F$2:$F$999,ar6_r10!$A$2:$A$999,Veda!$E$5,ar6_r10!$C$2:$C$999,Veda!L$17,ar6_r10!$M$2:$M$999,Veda!$G20) -> 0.65 | M20: =SUMIFS(ar6_r10!$F$2:$F$999,ar6_r10!$A$2:$A$999,Veda!$E$5,ar6_r10!$C$2:$C$999,Veda!M$17,ar6_r10!$M$2:$M$999,Veda!$G20) -> 0.64 | N20: =SUMIFS(ar6_r10!$F$2:$F$999,ar6_r10!$A$2:$A$999,Veda!$E$5,ar6_r10!$C$2:$C$999,Veda!N$17,ar6_r10!$M$2:$M$999,Veda!$G20) -> 0.59 | O20: =SUMIFS(ar6_r10!$F$2:$F$999,ar6_r10!$A$2:$A$999,Veda!$E$5,ar6_r10!$C$2:$C$999,Veda!O$17,ar6_r10!$M$2:$M$999,Veda!$G20) -> 0.58 | S20: elc_buildings | T20: =I20*T$14 -> 16.5199 | U20: =J20*U$14 -> 18.798741 | V20: =K20*V$14 -> 21.86058 | W20: =L20*W$14 -> 24.12358 | X20: =M20*X$14 -> 27.083584 | Y20: =N20*Y$14 -> 31.510012 | Z20: =O20*Z$14 -> 38.06366 | AA20: demand | AG20: 12 | AH20: s5p5v5_d | AI20: c15d | AJ20: =AJ15+1 -> 3
A21: 5 | B21: =VLOOKUP(E21,$AK$9:$AL$15,2,FALSE)&"."&VLOOKUP(D21,$AH$9:$AI$24,2,FALSE) -> c 2 deg (67%).j12 | C21: =C20+1 -> 13 | D21: =VLOOKUP(AJ21,$AG$9:$AH$22,2,FALSE) -> ts_012 | E21: =E16 -> C3 | G21: Transportation electricity share | I21: =SUMIFS(ar6_r10!$F$2:$F$999,ar6_r10!$A$2:$A$999,Veda!$E$5,ar6_r10!$C$2:$C$999,Veda!I$17,ar6_r10!$M$2:$M$999,Veda!$G21) -> 0 | J21: =SUMIFS(ar6_r10!$F$2:$F$999,ar6_r10!$A$2:$A$999,Veda!$E$5,ar6_r10!$C$2:$C$999,Veda!J$17,ar6_r10!$M$2:$M$999,Veda!$G21) -> 0.01 | K21: =SUMIFS(ar6_r10!$F$2:$F$999,ar6_r10!$A$2:$A$999,Veda!$E$5,ar6_r10!$C$2:$C$999,Veda!K$17,ar6_r10!$M$2:$M$999,Veda!$G21) -> 0.01 | L21: =SUMIFS(ar6_r10!$F$2:$F$999,ar6_r10!$A$2:$A$999,Veda!$E$5,ar6_r10!$C$2:$C$999,Veda!L$17,ar6_r10!$M$2:$M$999,Veda!$G21) -> 0.01 | M21: =SUMIFS(ar6_r10!$F$2:$F$999,ar6_r10!$A$2:$A$999,Veda!$E$5,ar6_r10!$C$2:$C$999,Veda!M$17,ar6_r10!$M$2:$M$999,Veda!$G21) -> 0.03 | N21: =SUMIFS(ar6_r10!$F$2:$F$999,ar6_r10!$A$2:$A$999,Veda!$E$5,ar6_r10!$C$2:$C$999,Veda!N$17,ar6_r10!$M$2:$M$999,Veda!$G21) -> 0.05 | O21: =SUMIFS(ar6_r10!$F$2:$F$999,ar6_r10!$A$2:$A$999,Veda!$E$5,ar6_r10!$C$2:$C$999,Veda!O$17,ar6_r10!$M$2:$M$999,Veda!$G21) -> 0.07 | S21: elc_transport | T21: =I21*T$14 -> 0 | U21: =T21 -> 0 | V21: =U21 -> 0 | W21: =V21 -> 0 | X21: =W21 -> 0 | Y21: =X21 -> 0 | Z21: =Y21 -> 0 | AA21: demand | AC21: non-road transport demand assumed to be constant | AG21: 13 | AH21: s2_w | AI21: b2w | AJ21: =AJ16+1 -> 3
A22: 5 | B22: =VLOOKUP(E22,$AK$9:$AL$15,2,FALSE)&"."&VLOOKUP(D22,$AH$9:$AI$24,2,FALSE) -> b 2 deg (50%).j12 | C22: =C21+1 -> 14 | D22: =VLOOKUP(AJ22,$AG$9:$AH$22,2,FALSE) -> ts_012 | E22: =E17 -> C4 | S22: elc_roadtransport | T22: =T14-SUM(T19:T21) -> 0.4526 | U22: =U14-SUM(U19:U21) -> 0.529542 | V22: =V14-SUM(V19:V21) -> 0.63364 | W22: =W14-SUM(W19:W21) -> 1.85566 | X22: =X14-SUM(X19:X21) -> 2.115905 | Y22: =Y14-SUM(Y19:Y21) -> 4.272544 | Z22: =Z14-SUM(Z19:Z21) -> 5.90643 | AA22: demand | AG22: 14 | AH22: s2_w_p2_d | AI22: a2w2d | AJ22: =AJ17+1 -> 3
A23: 5 | B23: =VLOOKUP(E23,$AK$9:$AL$15,2,FALSE)&"."&VLOOKUP(D23,$AH$9:$AI$24,2,FALSE) -> a 3 deg.j12 | C23: =C22+1 -> 15 | D23: =VLOOKUP(AJ23,$AG$9:$AH$22,2,FALSE) -> ts_012 | E23: =E18 -> C7 | S23: * | AJ23: =AJ18+1 -> 3
A24: 5 | B24: =VLOOKUP(E24,$AK$9:$AL$15,2,FALSE)&"."&VLOOKUP(D24,$AH$9:$AI$24,2,FALSE) -> e 1.5 deg no OS.i24 | C24: =C23+1 -> 16 | D24: =VLOOKUP(AJ24,$AG$9:$AH$22,2,FALSE) -> ts_024 | E24: =E19 -> C1 | G24: CO2 price | I24: 0 | J24: 0 | K24: =SUMIFS(ar6_r10!$F$2:$F$999,ar6_r10!$A$2:$A$999,Veda!$E$5,ar6_r10!$C$2:$C$999,Veda!K$17,ar6_r10!$M$2:$M$999,Veda!$G24) -> 49.21 | L24: =SUMIFS(ar6_r10!$F$2:$F$999,ar6_r10!$A$2:$A$999,Veda!$E$5,ar6_r10!$C$2:$C$999,Veda!L$17,ar6_r10!$M$2:$M$999,Veda!$G24) -> 100.47 | M24: =SUMIFS(ar6_r10!$F$2:$F$999,ar6_r10!$A$2:$A$999,Veda!$E$5,ar6_r10!$C$2:$C$999,Veda!M$17,ar6_r10!$M$2:$M$999,Veda!$G24) -> 127.66 | N24: =SUMIFS(ar6_r10!$F$2:$F$999,ar6_r10!$A$2:$A$999,Veda!$E$5,ar6_r10!$C$2:$C$999,Veda!N$17,ar6_r10!$M$2:$M$999,Veda!$G24) -> 171.28 | O24: =SUMIFS(ar6_r10!$F$2:$F$999,ar6_r10!$A$2:$A$999,Veda!$E$5,ar6_r10!$C$2:$C$999,Veda!O$17,ar6_r10!$M$2:$M$999,Veda!$G24) -> 208.73 | S24: co2net | U24: 0 | V24: =K24/1000 -> 0.04921 | W24: =L24/1000 -> 0.10047 | X24: =M24/1000 -> 0.12766 | Y24: =N24/1000 -> 0.17128 | Z24: =O24/1000 -> 0.20873 | AA24: com_taxnet | AJ24: =AJ19+1 -> 4
A25: 5 | B25: =VLOOKUP(E25,$AK$9:$AL$15,2,FALSE)&"."&VLOOKUP(D25,$AH$9:$AI$24,2,FALSE) -> d 1.5 deg OS.i24 | C25: =C24+1 -> 17 | D25: =VLOOKUP(AJ25,$AG$9:$AH$22,2,FALSE) -> ts_024 | E25: =E20 -> C2 | AJ25: =AJ20+1 -> 4
A26: 5 | B26: =VLOOKUP(E26,$AK$9:$AL$15,2,FALSE)&"."&VLOOKUP(D26,$AH$9:$AI$24,2,FALSE) -> c 2 deg (67%).i24 | C26: =C25+1 -> 18 | D26: =VLOOKUP(AJ26,$AG$9:$AH$22,2,FALSE) -> ts_024 | E26: =E21 -> C3 | S26: ~TFM_INS-TS | AJ26: =AJ21+1 -> 4
A27: 5 | B27: =VLOOKUP(E27,$AK$9:$AL$15,2,FALSE)&"."&VLOOKUP(D27,$AH$9:$AI$24,2,FALSE) -> b 2 deg (50%).i24 | C27: =C26+1 -> 19 | D27: =VLOOKUP(AJ27,$AG$9:$AH$22,2,FALSE) -> ts_024 | E27: =E22 -> C4 | S27: process | T27: =T17 -> 2022 | U27: =U17 -> 2025 | V27: =V17 -> 2030 | W27: =W17 -> 2035 | X27: =X17 -> 2040 | Y27: =Y17 -> 2045 | Z27: =Z17 -> 2050 | AA27: attribute | AB27: limtype | AJ27: =AJ22+1 -> 4
A28: 5 | B28: =VLOOKUP(E28,$AK$9:$AL$15,2,FALSE)&"."&VLOOKUP(D28,$AH$9:$AI$24,2,FALSE) -> a 3 deg.i24 | C28: =C27+1 -> 20 | D28: =VLOOKUP(AJ28,$AG$9:$AH$22,2,FALSE) -> ts_024 | E28: =E23 -> C7 | Q28: =SUMIFS(iea_data!G3:G9999,iea_data!$B$3:$B$9999,Veda!$S$11) -> 0.26 | S28: Trd_electricity import | T28: =Q28 -> 0.26 | AA28: ACT_BND | AB28: FX | AJ28: =AJ23+1 -> 4
A29: 5 | B29: =VLOOKUP(E29,$AK$9:$AL$15,2,FALSE)&"."&VLOOKUP(D29,$AH$9:$AI$24,2,FALSE) -> e 1.5 deg no OS.h48 | C29: =C28+1 -> 21 | D29: =VLOOKUP(AJ29,$AG$9:$AH$22,2,FALSE) -> ts_048 | E29: =E24 -> C1 | Q29: =SUMIFS(iea_data!H3:H9999,iea_data!$B$3:$B$9999,Veda!$S$11) -> -0.19 | S29: Trd_electricity export | T29: =-1*Q29 -> 0.19 | AA29: ACT_BND | AB29: FX | AJ29: =AJ24+1 -> 5
A30: 5 | B30: =VLOOKUP(E30,$AK$9:$AL$15,2,FALSE)&"."&VLOOKUP(D30,$AH$9:$AI$24,2,FALSE) -> d 1.5 deg OS.h48 | C30: =C29+1 -> 22 | D30: =VLOOKUP(AJ30,$AG$9:$AH$22,2,FALSE) -> ts_048 | E30: =E25 -> C2 | AJ30: =AJ25+1 -> 5
A31: 5 | B31: =VLOOKUP(E31,$AK$9:$AL$15,2,FALSE)&"."&VLOOKUP(D31,$AH$9:$AI$24,2,FALSE) -> c 2 deg (67%).h48 | C31: =C30+1 -> 23 | D31: =VLOOKUP(AJ31,$AG$9:$AH$22,2,FALSE) -> ts_048 | E31: =E26 -> C3 | AJ31: =AJ26+1 -> 5
A32: 5 | B32: =VLOOKUP(E32,$AK$9:$AL$15,2,FALSE)&"."&VLOOKUP(D32,$AH$9:$AI$24,2,FALSE) -> b 2 deg (50%).h48 | C32: =C31+1 -> 24 | D32: =VLOOKUP(AJ32,$AG$9:$AH$22,2,FALSE) -> ts_048 | E32: =E27 -> C4 | AJ32: =AJ27+1 -> 5
A33: 5 | B33: =VLOOKUP(E33,$AK$9:$AL$15,2,FALSE)&"."&VLOOKUP(D33,$AH$9:$AI$24,2,FALSE) -> a 3 deg.h48 | C33: =C32+1 -> 25 | D33: =VLOOKUP(AJ33,$AG$9:$AH$22,2,FALSE) -> ts_048 | E33: =E28 -> C7 | AJ33: =AJ28+1 -> 5
A34: 5 | B34: =VLOOKUP(E34,$AK$9:$AL$15,2,FALSE)&"."&VLOOKUP(D34,$AH$9:$AI$24,2,FALSE) -> e 1.5 deg no OS.g64 | C34: =C33+1 -> 26 | D34: =VLOOKUP(AJ34,$AG$9:$AH$22,2,FALSE) -> ts_064 | E34: =E29 -> C1 | AJ34: =AJ29+1 -> 6
A35: 5 | B35: =VLOOKUP(E35,$AK$9:$AL$15,2,FALSE)&"."&VLOOKUP(D35,$AH$9:$AI$24,2,FALSE) -> d 1.5 deg OS.g64 | C35: =C34+1 -> 27 | D35: =VLOOKUP(AJ35,$AG$9:$AH$22,2,FALSE) -> ts_064 | E35: =E30 -> C2 | AJ35: =AJ30+1 -> 6
A36: 5 | B36: =VLOOKUP(E36,$AK$9:$AL$15,2,FALSE)&"."&VLOOKUP(D36,$AH$9:$AI$24,2,FALSE) -> c 2 deg (67%).g64 | C36: =C35+1 -> 28 | D36: =VLOOKUP(AJ36,$AG$9:$AH$22,2,FALSE) -> ts_064 | E36: =E31 -> C3 | G36: C7 | AJ36: =AJ31+1 -> 6
A37: 5 | B37: =VLOOKUP(E37,$AK$9:$AL$15,2,FALSE)&"."&VLOOKUP(D37,$AH$9:$AI$24,2,FALSE) -> b 2 deg (50%).g64 | C37: =C36+1 -> 29 | D37: =VLOOKUP(AJ37,$AG$9:$AH$22,2,FALSE) -> ts_064 | E37: =E32 -> C4 | G37: Gas Price | I37: =SUMIFS(ar6_r10!$F$2:$F$999,ar6_r10!$A$2:$A$999,Veda!$G$36,ar6_r10!$C$2:$C$999,Veda!I$17,ar6_r10!$M$2:$M$999,Veda!$G37) -> 1 | J37: =SUMIFS(ar6_r10!$F$2:$F$999,ar6_r10!$A$2:$A$999,Veda!$G$36,ar6_r10!$C$2:$C$999,Veda!J$17,ar6_r10!$M$2:$M$999,Veda!$G37) -> 1.15 | K37: =SUMIFS(ar6_r10!$F$2:$F$999,ar6_r10!$A$2:$A$999,Veda!$G$36,ar6_r10!$C$2:$C$999,Veda!K$17,ar6_r10!$M$2:$M$999,Veda!$G37) -> 1.28 | L37: =SUMIFS(ar6_r10!$F$2:$F$999,ar6_r10!$A$2:$A$999,Veda!$G$36,ar6_r10!$C$2:$C$999,Veda!L$17,ar6_r10!$M$2:$M$999,Veda!$G37) -> 1.22 | M37: =SUMIFS(ar6_r10!$F$2:$F$999,ar6_r10!$A$2:$A$999,Veda!$G$36,ar6_r10!$C$2:$C$999,Veda!M$17,ar6_r10!$M$2:$M$999,Veda!$G37) -> 1.41 | N37: =SUMIFS(ar6_r10!$F$2:$F$999,ar6_r10!$A$2:$A$999,Veda!$G$36,ar6_r10!$C$2:$C$999,Veda!N$17,ar6_r10!$M$2:$M$999,Veda!$G37) -> 1.47 | O37: =SUMIFS(ar6_r10!$F$2:$F$999,ar6_r10!$A$2:$A$999,Veda!$G$36,ar6_r10!$C$2:$C$999,Veda!O$17,ar6_r10!$M$2:$M$999,Veda!$G37) -> 1.59 | AJ37: =AJ32+1 -> 6
A38: 5 | B38: =VLOOKUP(E38,$AK$9:$AL$15,2,FALSE)&"."&VLOOKUP(D38,$AH$9:$AI$24,2,FALSE) -> a 3 deg.g64 | C38: =C37+1 -> 30 | D38: =VLOOKUP(AJ38,$AG$9:$AH$22,2,FALSE) -> ts_064 | E38: =E33 -> C7 | G38: Coal Price | I38: =SUMIFS(ar6_r10!$F$2:$F$999,ar6_r10!$A$2:$A$999,Veda!$G$36,ar6_r10!$C$2:$C$999,Veda!I$17,ar6_r10!$M$2:$M$999,Veda!$G38) -> 1 | J38: =SUMIFS(ar6_r10!$F$2:$F$999,ar6_r10!$A$2:$A$999,Veda!$G$36,ar6_r10!$C$2:$C$999,Veda!J$17,ar6_r10!$M$2:$M$999,Veda!$G38) -> 1.02 | K38: =SUMIFS(ar6_r10!$F$2:$F$999,ar6_r10!$A$2:$A$999,Veda!$G$36,ar6_r10!$C$2:$C$999,Veda!K$17,ar6_r10!$M$2:$M$999,Veda!$G38) -> 1.06 | L38: =SUMIFS(ar6_r10!$F$2:$F$999,ar6_r10!$A$2:$A$999,Veda!$G$36,ar6_r10!$C$2:$C$999,Veda!L$17,ar6_r10!$M$2:$M$999,Veda!$G38) -> 1.08 | M38: =SUMIFS(ar6_r10!$F$2:$F$999,ar6_r10!$A$2:$A$999,Veda!$G$36,ar6_r10!$C$2:$C$999,Veda!M$17,ar6_r10!$M$2:$M$999,Veda!$G38) -> 1.17 | N38: =SUMIFS(ar6_r10!$F$2:$F$999,ar6_r10!$A$2:$A$999,Veda!$G$36,ar6_r10!$C$2:$C$999,Veda!N$17,ar6_r10!$M$2:$M$999,Veda!$G38) -> 1.21 | O38: =SUMIFS(ar6_r10!$F$2:$F$999,ar6_r10!$A$2:$A$999,Veda!$G$36,ar6_r10!$C$2:$C$999,Veda!O$17,ar6_r10!$M$2:$M$999,Veda!$G38) -> 1.26 | AJ38: =AJ33+1 -> 6
A39: 5 | B39: =VLOOKUP(E39,$AK$9:$AL$15,2,FALSE)&"."&VLOOKUP(D39,$AH$9:$AI$24,2,FALSE) -> e 1.5 deg no OS.f96p50 | C39: =C38+1 -> 31 | D39: =VLOOKUP(AJ39,$AG$9:$AH$22,2,FALSE) -> ts_096P50 | E39: =E34 -> C1 | G39: Oil Price | I39: =SUMIFS(ar6_r10!$F$2:$F$999,ar6_r10!$A$2:$A$999,Veda!$G$36,ar6_r10!$C$2:$C$999,Veda!I$17,ar6_r10!$M$2:$M$999,Veda!$G39) -> 1 | J39: =SUMIFS(ar6_r10!$F$2:$F$999,ar6_r10!$A$2:$A$999,Veda!$G$36,ar6_r10!$C$2:$C$999,Veda!J$17,ar6_r10!$M$2:$M$999,Veda!$G39) -> 0.97 | K39: =SUMIFS(ar6_r10!$F$2:$F$999,ar6_r10!$A$2:$A$999,Veda!$G$36,ar6_r10!$C$2:$C$999,Veda!K$17,ar6_r10!$M$2:$M$999,Veda!$G39) -> 1.28 | L39: =SUMIFS(ar6_r10!$F$2:$F$999,ar6_r10!$A$2:$A$999,Veda!$G$36,ar6_r10!$C$2:$C$999,Veda!L$17,ar6_r10!$M$2:$M$999,Veda!$G39) -> 1.09 | M39: =SUMIFS(ar6_r10!$F$2:$F$999,ar6_r10!$A$2:$A$999,Veda!$G$36,ar6_r10!$C$2:$C$999,Veda!M$17,ar6_r10!$M$2:$M$999,Veda!$G39) -> 1.39 | N39: =SUMIFS(ar6_r10!$F$2:$F$999,ar6_r10!$A$2:$A$999,Veda!$G$36,ar6_r10!$C$2:$C$999,Veda!N$17,ar6_r10!$M$2:$M$999,Veda!$G39) -> 1.53 | O39: =SUMIFS(ar6_r10!$F$2:$F$999,ar6_r10!$A$2:$A$999,Veda!$G$36,ar6_r10!$C$2:$C$999,Veda!O$17,ar6_r10!$M$2:$M$999,Veda!$G39) -> 1.73 | AJ39: =AJ34+1 -> 7
A40: 5 | B40: =VLOOKUP(E40,$AK$9:$AL$15,2,FALSE)&"."&VLOOKUP(D40,$AH$9:$AI$24,2,FALSE) -> d 1.5 deg OS.f96p50 | C40: =C39+1 -> 32 | D40: =VLOOKUP(AJ40,$AG$9:$AH$22,2,FALSE) -> ts_096P50 | E40: =E35 -> C2 | G40: Biomass Price | I40: =SUMIFS(ar6_r10!$F$2:$F$999,ar6_r10!$A$2:$A$999,Veda!$G$36,ar6_r10!$C$2:$C$999,Veda!I$17,ar6_r10!$M$2:$M$999,Veda!$G40) -> 1 | J40: =SUMIFS(ar6_r10!$F$2:$F$999,ar6_r10!$A$2:$A$999,Veda!$G$36,ar6_r10!$C$2:$C$999,Veda!J$17,ar6_r10!$M$2:$M$999,Veda!$G40) -> 1.05 | K40: =SUMIFS(ar6_r10!$F$2:$F$999,ar6_r10!$A$2:$A$999,Veda!$G$36,ar6_r10!$C$2:$C$999,Veda!K$17,ar6_r10!$M$2:$M$999,Veda!$G40) -> 1.1 | L40: =SUMIFS(ar6_r10!$F$2:$F$999,ar6_r10!$A$2:$A$999,Veda!$G$36,ar6_r10!$C$2:$C$999,Veda!L$17,ar6_r10!$M$2:$M$999,Veda!$G40) -> 1.16 | M40: =SUMIFS(ar6_r10!$F$2:$F$999,ar6_r10!$A$2:$A$999,Veda!$G$36,ar6_r10!$C$2:$C$999,Veda!M$17,ar6_r10!$M$2:$M$999,Veda!$G40) -> 1.17 | N40: =SUMIFS(ar6_r10!$F$2:$F$999,ar6_r10!$A$2:$A$999,Veda!$G$36,ar6_r10!$C$2:$C$999,Veda!N$17,ar6_r10!$M$2:$M$999,Veda!$G40) -> 1.16 | O40: =SUMIFS(ar6_r10!$F$2:$F$999,ar6_r10!$A$2:$A$999,Veda!$G$36,ar6_r10!$C$2:$C$999,Veda!O$17,ar6_r10!$M$2:$M$999,Veda!$G40) -> 1.17 | AJ40: =AJ35+1 -> 7
A41: 5 | B41: =VLOOKUP(E41,$AK$9:$AL$15,2,FALSE)&"."&VLOOKUP(D41,$AH$9:$AI$24,2,FALSE) -> c 2 deg (67%).f96p50 | C41: =C40+1 -> 33 | D41: =VLOOKUP(AJ41,$AG$9:$AH$22,2,FALSE) -> ts_096P50 | E41: =E36 -> C3 | AJ41: =AJ36+1 -> 7
A42: 5 | B42: =VLOOKUP(E42,$AK$9:$AL$15,2,FALSE)&"."&VLOOKUP(D42,$AH$9:$AI$24,2,FALSE) -> b 2 deg (50%).f96p50 | C42: =C41+1 -> 34 | D42: =VLOOKUP(AJ42,$AG$9:$AH$22,2,FALSE) -> ts_096P50 | E42: =E37 -> C4 | AJ42: =AJ37+1 -> 7
...

Sheet fuel_prices
A9: Fuel Prices
A10: iso | B10: gas_low | C10: gas_high | D10: coal_low | E10: coal_high | F10: oil_low | G10: oil_high | H10: bioenergy_low | I10: bioenergy_high | J10: Notes
A11: JOR | B11: 30.9 | C11: 42.9 | D11: 15.2 | E11: 19.8 | F11: 48 | G11: 58 | H11: 24 | I11: 32 | J11: LNG via Aqaba, limited biomass

Sheet iea_data
A9: IEA Baseline Data
A10: iso | B10: year | C10: industry_twh | D10: buildings_agri_twh | E10: nonroad_transport_twh | F10: road_transport_twh | G10: imports_twh | H10: exports_twh | I10: total_production_twh
A11: JOR | B11: 2000 | C11: 3.21 | D11: 4.22 | E11: 0 | F11: 0 | G11: 0.04 | H11: 0 | I11: 7.38
A12: JOR | B12: 2001 | C12: 3.37 | D12: 4.42 | E12: 0 | F12: 0 | G12: 0.27 | H12: 0 | I12: 7.55
A13: JOR | B13: 2002 | C13: 3.62 | D13: 5 | E13: 0 | F13: 0 | G13: 0.32 | H13: 0 | I13: 8.13
A14: JOR | B14: 2003 | C14: 3.81 | D14: 5.3 | E14: 0 | F14: 0 | G14: 0.97 | H14: 0 | I14: 7.99
A15: JOR | B15: 2004 | C15: 4.03 | D15: 5.86 | E15: 0 | F15: 0 | G15: 0.79 | H15: 0 | I15: 8.97
A16: JOR | B16: 2005 | C16: 4.48 | D16: 6.3 | E16: 0 | F16: 0 | G16: 0.74 | H16: 0 | I16: 9.65
A17: JOR | B17: 2006 | C17: 4.73 | D17: 7.12 | E17: 0 | F17: 0 | G17: 0.47 | H17: -0.01 | I17: 11.12
A18: JOR | B18: 2007 | C18: 5.34 | D18: 7.95 | E18: 0 | F18: 0 | G18: 0.2 | H18: -0.18 | I18: 13
A19: JOR | B19: 2008 | C19: 5.62 | D19: 8.44 | E19: 0 | F19: 0 | G19: 0.55 | H19: -0.32 | I19: 13.84
A20: JOR | B20: 2009 | C20: 5.51 | D20: 9.01 | E20: 0 | F20: 0 | G20: 0.38 | H20: -0.14 | I20: 14.27
A21: JOR | B21: 2010 | C21: 5.73 | D21: 9.66 | E21: 0 | F21: 0 | G21: 0.67 | H21: -0.06 | I21: 14.78
A22: JOR | B22: 2011 | C22: 6.19 | D22: 10.11 | E22: 0 | F22: 0 | G22: 1.74 | H22: -0.09 | I22: 14.65
... A33: JOR | B33: 2022 | C33: 7.84 | D33: 15.3 | E33: 0 | F33: 0 | G33: 0.26 | H33: -0.19 | I33: 22.56

Sheet ar6_r10
A9: AR6 Scenario Drivers
A10: Category | B10: Region | C10: Year | D10: count | E10: mean | F10: median | G10: std | H10: min | I10: max | J10: q25 | K10: q75 | L10: category_description | M10: attribute
A11: C1 | B11: R10MIDDLE_EAST | C11: 2020 | D11: 60 | E11: 2.9 | F11: 0.74 | G11: 3.32 | H11: 0 | I11: 15.11 | J11: 0 | K11: 5.64 | L11: Limit warming to 1.5°C (>50%) with no or limited overshoot | M11: CO2 price
A12: C1 | B12: R10MIDDLE_EAST | C12: 2025 | D12: 60 | E12: 153.67 | F12: 131.07 | G12: 125.79 | H12: 0 | I12: 626.48 | J12: 101.54 | K12: 190.02 | L12: Limit warming to 1.5°C (>50%) with no or limited overshoot | M12: CO2 price
A13: C1 | B13: R10MIDDLE_EAST | C13: 2030 | D13: 60 | E13: 220.76 | F13: 197.09 | G13: 111.16 | H13: 0 | I13: 673.46 | J13: 164.67 | K13: 241.99 | L13: Limit warming to 1.5°C (>50%) with no or limited overshoot | M13: CO2 price
A14: C1 | B14: R10MIDDLE_EAST | C14: 2035 | D14: 60 | E14: 310.56 | F14: 256.63 | G14: 147.59 | H14: 92.6 | I14: 859.53 | J14: 220.16 | K14: 396.19 | L14: Limit warming to 1.5°C (>50%) with no or limited overshoot | M14: CO2 price
A15: C1 | B15: R10MIDDLE_EAST | C15: 2040 | D15: 60 | E15: 420.22 | F15: 335.79 | G15: 205.86 | H15: 162.1 | I15: 1097.01 | J15: 287.98 | K15: 560.56 | L15: Limit warming to 1.5°C (>50%) with no or limited overshoot | M15: CO2 price
A16: C1 | B16: R10MIDDLE_EAST | C16: 2045 | D16: 60 | E16: 529.59 | F16: 460.87 | G16: 243.64 | H16: 193.42 | I16: 1269.88 | J16: 355.81 | K16: 713.93 | L16: Limit warming to 1.5°C (>50%) with no or limited overshoot | M16: CO2 price
A17: C1 | B17: R10MIDDLE_EAST | C17: 2050 | D17: 60 | E17: 625.34 | F17: 581.75 | G17: 256.99 | H17: 209.76 | I17: 1170.26 | J17: 412.98 | K17: 771.78 | L17: Limit warming to 1.5°C (>50%) with no or limited overshoot | M17: CO2 price
A18: C2 | B18: R10MIDDLE_EAST | C18: 2020 | D18: 86 | E18: 3.36 | F18: 0.55 | G18: 5.17 | H18: 0 | I18: 15.11 | J18: 0 | K18: 5.35 | L18: Limit warming to 1.5°C (>67%) with high overshoot | M18: CO2 price
A19: C2 | B19: R10MIDDLE_EAST | C19: 2025 | D19: 75 | E19: 37.47 | F19: 21.41 | G19: 46.36 | H19: 0 | I19: 174.97 | J19: 1.26 | K19: 55.72 | L19: Limit warming to 1.5°C (>67%) with high overshoot | M19: CO2 price
A20: C2 | B20: R10MIDDLE_EAST | C20: 2030 | D20: 86 | E20: 52.47 | F20: 41.97 | G20: 54.93 | H20: 0 | I20: 221.93 | J20: 1.28 | K20: 77.17 | L20: Limit warming to 1.5°C (>67%) with high overshoot | M20: CO2 price
A21: C2 | B21: R10MIDDLE_EAST | C21: 2035 | D21: 75 | E21: 208.06 | F21: 129.57 | G21: 312.6 | H21: 54.48 | I21: 2037.12 | J21: 87.35 | K21: 202.85 | L21: Limit warming to 1.5°C (>67%) with high overshoot | M21: CO2 price
A22: C2 | B22: R10MIDDLE_EAST | C22: 2040 | D22: 86 | E22: 247.16 | F22: 165.64 | G22: 360.3 | H22: 0 | I22: 2600 | J22: 108.54 | K22: 257.75 | L22: Limit warming to 1.5°C (>67%) with high overshoot | M22: CO2 price
... A360: C7 | B360: R10MIDDLE_EAST | C360: 2050 | D360: 7 | E360: 1.15 | F360: 1.17 | G360: 0.19 | H360: 0.9 | I360: 1.35 | J360: 1.03 | K360: 1.29 | L360: Likely above 3°C warming with limited mitigation | M360: Biomass price

Sheet ev_charging_uc
A10: =IFERROR(Veda!D5,"ts_12t") -> ts_annual | C10: day_night | D10: s5p5v5_d | F10: day_night | G10: s2_w_p2_d | I10: day_night | J10: ts_012 | L10: day_night | M10: ts_048 | O10: day_night | P10: ts_096P50 | R10: day_night | S10: ts_096P10 | U10: day_night | V10: ts_096P90 | X10: day_night | Y10: ts_annual | AA10: day_night | AB10: ts_12t
C11: D | D11: S01b0107h08,S02aH04,S02aH05,S02d0212h07,S02d0212h08,S02d0212h12,S10aH03,S10aH05,S11j1119h14,S12k1203h11,S12l1206h15,S12m1211h14,S12m1211h16,S12n1213h08,S12n1213h11,S12o1215h13,S12o1215h18,S12p1229h07,S12p1229h10,S01b0107h17,S03f0331h15,S04aH06,S04g0402h15,S04h0404h14,S05aH04,S06aH02,S06aH03,S10aH04,S11j1119h11,S12aH06,S12k1203h17,S12l1206h07,S12l1206h09,S12l1206h10,S01b0107h10,S01b0107h16,S01c0108h13,S03aH04,S03f0331h08,S04g0402h17,S08aH05,S10i1004h09,S10i1004h10,S11aH05,S12aH03,S12k1203h13,S12k1203h14,S12l1206h18,S12n1213h12,S12n1213h18,S12o1215h11,S12p1229h11,S01c0108h15,S01c0108h18,S02e0222h08,S02e0222h13,S03aH02,S03f0331h09,S04g0402h13,S07aH05,S11j1119h15,S12l1206h12,S12m1211h15,S12o1215h16,S12p1229h17,S01aH04,S01b0107h11,S01c0108h08,S02e0222h17,S04g0402h16,S07aH02,S07aH06,S11j1119h09,S01c0108h07,S01c0108h12,S01c0108h16,S02d0212h10,S02e0222h16,S03f0331h13,S03f0331h16,S04aH02,S04g0402h09,S04h0404h09,S04h0404h12,S09aH02,S09aH03,S11aH03,S11aH04,S11j1119h07,S11j1119h10,S12n1213h10,S01b0107h09,S02d0212h09,S02d0212h13,S02e0222h12,S02e0222h14,S03aH03,S09aH05,S11j1119h16,S12k1203h10,S12l1206h11,S12o1215h08,S12o1215h10,S12p1229h08,S01b0107h15,S03f0331h18,S04g0402h08,S04h0404h15,S08aH02,S09aH06,S11j1119h18,S12k1203h08,S12k1203h16,S12l1206h16,S12m1211h07,S12m1211h09,S12n1213h07,S01aH06,S01b0107h14,S01c0108h09,S01c0108h14,S02aH03,S07aH03,S08aH06,S10i1004h11,S12l1206h08,S12m1211h18,S12n1213h09,S12n1213h15,S12p1229h09,S02aH06,S03aH05,S03f0331h11,S04h0404h08,S05aH05,S06aH04,S08aH04,S11aH02,S12k1203h18,S12o1215h09,S12o1215h15,S01c0108h17,S02aH02,S02d0212h14,S02d0212h16,S02d0212h17,S03f0331h12,S03f0331h14,S04g0402h10,S06aH06,S12n1213h14,S12n1213h16,S12p1229h16,S01b0107h13,S02d0212h15,S02e0222h09,S02e0222h15,S02e0222h18,S03f0331h10,S03f0331h17,S04aH05,S04h0404h07,S04h0404h11,S10i1004h12,S12m1211h11,S12n1213h17,S12o1215h12,S12o1215h17,S01aH02,S01b0107h18,S02d0212h11,S02e0222h10,S04aH04,S04g0402h14,S04h0404h18,S10i1004h07,S10i1004h13,S10i1004h15,S10i1004h16,S10i1004h17,S12l1206h13,S12o1215h07,S12p1229h12,S01aH03,S01c0108h11,S04g0402h07,S04h0404h13,S04h0404h16,S04h0404h17,S05aH02,S05aH03,S05aH06,S10i1004h14,S11j1119h08,S12k1203h07,S12k1203h12,S12l1206h14,S12l1206h17,S12m1211h13,S12m1211h17,S12p1229h13,S12p1229h14,S01aH05,S01b0107h12,S02e0222h07,S02e0222h11,S03aH06,S03f0331h07,S04h0404h10,S06aH05,S10aH02,S10aH06,S10i1004h18,S11aH06,S11j1119h13,S12aH04,S12aH05,S12m1211h08,S12m1211h10,S12m1211h12,S01b0107h07,S01c0108h10,S02d0212h18,S04aH03,S04g0402h11,S04g0402h12,S04g0402h18,S07aH04,S08aH03,S09aH04,S10i1004h08,S11j1119h12,S11j1119h17,S12aH02,S12k1203h09,S12k1203h15,S12n1213h13,S12o1215h14,S12p1229h15,S12p1229h18 | F11: D | G11: S01c0108h17,S02aH02,S06aH06,S11d1114h18,S11d1115h09,S11d1116h08,S11d1118h09,S11d1118h15,S12e1203h16,S01c0108h15,S01c0108h18,S03aH02,S07aH05,S11d1112h08,S11d1115h10,S11d1115h11,S11d1115h13,S11d1115h17,S11d1116h16,S11d1117h13,S11d1118h11,S11d1118h14,S12e1203h18,S12e1204h08,S12e1207h10,S12e1207h11,S12e1207h15,S12e1208h07,S12e1209h10,S01b0107h13,S04aH05,S11d1112h12,S11d1112h16,S11d1118h12,S12e1204h10,S12e1205h09,S12e1206h18,S12e1207h07,S12e1207h13,S12e1209h13,S01aH06,S01b0107h14,S01c0108h09,S01c0108h14,S02aH03,S07aH03,S08aH06,S11d1112h07,S11d1112h17,S11d1113h10,S11d1113h14,S11d1116h11,S11d1117h14,S12e1204h12,S12e1205h10,S12e1205h12,S12e1205h18,S12e1207h17,S12e1208h10,S12e1208h15,S01b0107h08,S02aH04,S02aH05,S10aH03,S10aH05,S11d1114h09,S11d1114h15,S11d1116h07,S11d1116h09,S11d1117h16,S12e1203h11,S12e1203h15,S12e1204h13,S12e1208h09,S12e1208h18,S01aH03,S01c0108h11,S05aH02,S05aH03,S05aH06,S11d1112h13,S11d1117h07,S11d1118h13,S11d1118h16,S12e1203h10,S12e1203h17,S12e1204h17,S12e1206h08,S12e1206h14,S12e1206h17,S12e1207h08,S12e1207h09,S12e1208h11,S01aH02,S01b0107h18,S04aH04,S11d1115h07,S11d1115h16,S11d1116h12,S11d1116h13,S11d1116h18,S11d1118h10,S12e1203h08,S12e1203h12,S12e1204h14,S12e1204h16,S12e1205h16,S12e1206h11,S12e1208h14,S12e1209h14,S01b0107h10,S01b0107h16,S01c0108h13,S03aH04,S08aH05,S11aH05,S11d1112h09,S11d1113h12,S11d1113h17,S12aH03,S12e1205h11,S12e1209h07,S12e1209h11,S12e1209h15,S01b0107h17,S04aH06,S05aH04,S06aH02,S06aH03,S10aH04,S11d1112h18,S11d1113h11,S11d1113h16,S11d1114h10,S12aH06,S12e1204h15,S12e1209h09,S12e1209h12,S01aH05,S01b0107h12,S03aH06,S06aH05,S10aH02,S10aH06,S11aH06,S11d1112h15,S11d1113h15,S11d1114h08,S11d1117h08,S11d1117h09,S11d1117h10,S12aH04,S12aH05,S12e1203h09,S12e1206h09,S12e1209h08,S12e1209h16,S12e1209h17,S12e1209h18,S01aH04,S01b0107h11,S01c0108h08,S07aH02,S07aH06,S11d1112h11,S11d1116h14,S12e1203h07,S12e1203h14,S12e1204h07,S12e1204h09,S12e1205h13,S12e1205h15,S12e1205h17,S12e1207h18,S01c0108h07,S01c0108h12,S01c0108h16,S04aH02,S09aH02,S09aH03,S11aH03,S11aH04,S11d1113h08,S11d1114h12,S11d1117h12,S12e1204h11,S12e1206h13,S02aH06,S03aH05,S05aH05,S06aH04,S08aH04,S11aH02,S11d1114h17,S11d1115h18,S11d1118h18,S12e1205h07,S12e1205h14,S12e1206h07,S12e1206h16,S12e1207h16,S12e1208h13,S01b0107h07,S01c0108h10,S04aH03,S07aH04,S08aH03,S09aH04,S11d1113h07,S11d1113h18,S11d1114h16,S11d1115h08,S11d1115h14,S11d1115h15,S11d1116h10,S11d1117h18,S12aH02,S12e1205h08,S12e1208h12,S12e1208h16,S01b0107h09,S03aH03,S09aH05,S11d1112h10,S11d1112h14,S11d1114h11,S11d1114h13,S11d1116h15,S11d1116h17,S11d1117h11,S11d1117h17,S11d1118h08,S11d1118h17,S12e1204h18,S12e1206h10,S12e1206h12,S12e1208h17,S01b0107h15,S08aH02,S09aH06,S11d1113h09,S11d1113h13,S11d1114h07,S11d1114h14,S11d1115h12,S11d1117h15,S11d1118h07,S12e1203h13,S12e1206h15,S12e1207h12,S12e1207h14,S12e1208h08 | I11: D | J11: S02aH02,S04aH02,S03aH02,S03aH01,S01aH01,S04aH01,S01aH02,S02aH01 | L11: D | M11: S06aH04,S08aH04,S08aH02,S02aH04,S02aH03,S07aH03,S03aH02,S01aH03,S05aH02,S05aH03,S01aH04,S07aH02,S03aH03,S03aH04,S02aH02,S04aH03,S07aH04,S08aH03,S01aH02,S04aH04,S05aH04,S06aH02,S06aH03,S04aH02 | O11: D | P11: S01aH04,S07aH02,S07aH06,S02aH04,S02aH05,S10aH03,S10aH05,S04aH03,S07aH04,S08aH03,S09aH04,S12aH02,S03aH03,S09aH05,S04aH02,S09aH02,S09aH03,S11aH03,S11aH04,S04aH06,S05aH04,S06aH02,S06aH03,S10aH04,S12aH06,S01aH02,S04aH04,S04aH05,S02aH06,S03aH05,S05aH05,S06aH04,S08aH04,S11aH02,S03aH04,S08aH05,S11aH05,S12aH03,S02aH02,S06aH06,S01aH03,S05aH02,S05aH03,S05aH06,S01aH06,S02aH03,S07aH03,S08aH06,S03aH02,S07aH05,S08aH02,S09aH06,S01aH05,S03aH06,S06aH05,S10aH02,S10aH06,S11aH06,S12aH04,S12aH05 | R11: D | S11: S01aH06,S02aH03,S07aH03,S08aH06,S01aH04,S07aH02,S07aH06,S01aH03,S05aH02,S05aH03,S05aH06,S03aH02,S07aH05,S02aH02,S06aH06,S03aH03,S09aH05,S02aH04,S02aH05,S10aH03,S10aH05,S01aH02,S04aH04,S02aH06,S03aH05,S05aH05,S06aH04,S08aH04,S11aH02,S08aH02,S09aH06,S03aH04,S08aH05,S11aH05,S12aH03,S01aH05,S03aH06,S06aH05,S10aH02,S10aH06,S11aH06,S12aH04,S12aH05,S04aH06,S05aH04,S06aH02,S06aH03,S10aH04,S12aH06,S04aH03,S07aH04,S08aH03,S09aH04,S12aH02,S04aH02,S09aH02,S09aH03,S11aH03,S11aH04,S04aH05 | U11: D | V11: S01aH06,S02aH03,S07aH03,S08aH06,S03aH02,S07aH05,S03aH03,S09aH05,S01aH02,S04aH04,S04aH05,S04aH02,S09aH02,S09aH03,S11aH03,S11aH04,S01aH05,S03aH06,S06aH05,S10aH02,S10aH06,S11aH06,S12aH04,S12aH05,S01aH04,S07aH02,S07aH06,S04aH06,S05aH04,S06aH02,S06aH03,S10aH04,S12aH06,S08aH02,S09aH06,S01aH03,S05aH02,S05aH03,S05aH06,S04aH03,S07aH04,S08aH03,S09aH04,S12aH02,S02aH02,S06aH06,S02aH06,S03aH05,S05aH05,S06aH04,S08aH04,S11aH02,S02aH04,S02aH05,S10aH03,S10aH05,S03aH04,S08aH05,S11aH05,S12aH03 | X11: D | Y11: AllSaAllH | AA11: D | AB11: RaD,SaD,FaP,SaP,WaD,FaD,WaP,RaP
C12: N | D12: S02d0212h21,S03aH08,S03f0331h03,S03f0331h04,S04aH07,S04h0404h23,S06aH08,S11j1119h20,S12aH01,S12l1206h19,S12m1211h20,S12n1213h19,S12p1229h01,S01b0107h24,S02d0212h01,S02d0212h05,S02d0212h06,S04g0402h24,S05aH07,S07aH01,S10aH07,S10i1004h06,S11j1119h05,S11j1119h21,S12k1203h20,S12k1203h22,S12l1206h03,S12l1206h04,S12m1211h06,S12o1215h06,S12o1215h20,S01aH07,S01c0108h21,S01c0108h24,S02aH07,S05aH01,S10i1004h02,S11j1119h03,S12l1206h05,S12l1206h23,S12m1211h22,S12o1215h19,S12o1215h22,S01b0107h21,S01c0108h02,S01c0108h23,S03f0331h01,S04h0404h04,S08aH07,S12m1211h01,S12n1213h01,S12n1213h05,S12n1213h21,S12o1215h21,S12p1229h04,S01c0108h06,S01c0108h20,S02d0212h23,S02e0222h01,S04g0402h19,S08aH01,S09aH07,S10aH01,S10i1004h03,S10i1004h24,S11j1119h06,S12k1203h24,S12m1211h02,S12p1229h24,S01b0107h04,S01b0107h20,S01c0108h04,S02d0212h02,S02e0222h19,S03f0331h21,S10i1004h01,S10i1004h22,S12k1203h02,S12k1203h19,S12l1206h06,S12o1215h02,S12p1229h03,S12p1229h20,S02d0212h03,S02e0222h05,S03f0331h05,S03f0331h20,S10i1004h04,S11aH08,S11j1119h19,S12k1203h01,S12o1215h05,S01b0107h19,S02d0212h04,S02e0222h21,S02e0222h24,S04aH08,S04g0402h01,S04h0404h01,S04h0404h24,S06aH01,S10i1004h05,S12aH08,S12k1203h04,S12k1203h21,S12m1211h21,S12n1213h03,S12n1213h04,S12n1213h06,S12n1213h20,S12o1215h04,S12o1215h24,S12p1229h02,S12p1229h23,S01aH01,S01b0107h01,S01b0107h23,S01c0108h05,S04aH01,S04h0404h21,S09aH08,S10i1004h21,S11aH01,S11j1119h02,S12p1229h05,S12p1229h21,S01b0107h22,S02d0212h20,S02e0222h04,S02e0222h22,S04g0402h21,S04h0404h05,S04h0404h22,S06aH07,S07aH07,S07aH08,S08aH08,S10i1004h20,S12k1203h05,S12k1203h06,S12m1211h04,S12m1211h19,S12m1211h24,S12p1229h22,S02d0212h22,S02e0222h23,S03aH01,S03f0331h19,S04g0402h04,S04h0404h20,S12aH07,S12l1206h22,S12m1211h23,S12n1213h02,S12n1213h23,S12n1213h24,S12o1215h23,S01b0107h02,S01b0107h03,S02d0212h24,S02e0222h20,S03f0331h02,S03f0331h24,S04h0404h06,S05aH08,S10aH08,S10i1004h23,S11j1119h01,S11j1119h22,S12m1211h05,S12p1229h06,S01aH08,S02aH08,S02e0222h03,S03aH07,S04g0402h20,S11j1119h04,S12o1215h03,S12p1229h19,S01b0107h06,S01c0108h03,S02d0212h19,S02e0222h06,S04g0402h06,S04h0404h02,S09aH01,S11aH07,S12k1203h03,S12k1203h23,S12l1206h02,S01b0107h05,S01c0108h01,S01c0108h19,S01c0108h22,S02e0222h02,S03f0331h06,S03f0331h22,S04g0402h02,S04g0402h03,S04g0402h22,S04g0402h23,S11j1119h24,S12l1206h21,S12l1206h24,S12m1211h03,S02aH01,S03f0331h23,S04g0402h05,S04h0404h03,S04h0404h19,S10i1004h19,S11j1119h23,S12l1206h01,S12l1206h20,S12n1213h22,S12o1215h01 | F12: N | G12: S03aH01,S11d1112h21,S11d1113h03,S11d1116h04,S11d1116h05,S11d1117h20,S12aH07,S12e1203h20,S12e1206h21,S12e1207h05,S12e1207h24,S12e1209h20,S01b0107h21,S01c0108h02,S01c0108h23,S08aH07,S11d1113h20,S11d1118h02,S11d1118h06,S12e1204h24,S12e1205h05,S12e1206h22,S12e1208h01,S12e1208h06,S01b0107h02,S01b0107h03,S05aH08,S10aH08,S11d1112h03,S11d1113h22,S11d1114h19,S11d1114h21,S11d1116h21,S11d1117h06,S11d1118h03,S11d1118h24,S12e1203h03,S12e1204h01,S12e1204h20,S12e1205h06,S12e1208h21,S12e1209h23,S01aH01,S01b0107h01,S01b0107h23,S01c0108h05,S04aH01,S09aH08,S11aH01,S11d1112h20,S11d1112h24,S11d1113h01,S11d1113h04,S11d1114h22,S11d1114h24,S11d1117h03,S11d1117h05,S11d1118h04,S11d1118h20,S12e1203h06,S12e1203h22,S12e1204h03,S12e1204h19,S12e1205h20,S12e1205h21,S12e1205h22,S12e1209h04,S03aH08,S04aH07,S06aH08,S11d1114h04,S11d1115h01,S11d1116h06,S11d1116h19,S12aH01,S12e1203h19,S12e1204h21,S12e1206h04,S12e1206h24,S01b0107h06,S01c0108h03,S09aH01,S11aH07,S11d1112h01,S11d1112h06,S11d1112h19,S11d1113h23,S11d1114h05,S11d1118h19,S12e1203h05,S12e1204h04,S12e1204h22,S12e1207h02,S12e1207h21,S12e1207h23,S12e1208h03,S12e1208h20,S12e1209h03,S12e1209h05,S01aH08,S02aH08,S03aH07,S11d1116h23,S11d1117h01,S11d1117h02,S11d1117h23,S11d1118h05,S11d1118h21,S12e1205h01,S01aH07,S01c0108h21,S01c0108h24,S02aH07,S05aH01,S11d1112h02,S11d1114h03,S11d1115h03,S12e1204h05,S12e1205h04,S12e1206h23,S12e1207h01,S12e1208h04,S12e1209h24,S01b0107h24,S05aH07,S07aH01,S10aH07,S11d1113h02,S11d1113h21,S11d1115h22,S11d1115h23,S11d1118h01,S12e1203h02,S12e1204h23,S12e1205h02,S12e1207h22,S01b0107h05,S01c0108h01,S01c0108h19,S01c0108h22,S11d1113h19,S11d1113h24,S11d1114h01,S11d1114h06,S11d1115h06,S11d1117h04,S12e1203h21,S01c0108h06,S01c0108h20,S08aH01,S09aH07,S10aH01,S11d1112h04,S11d1112h23,S11d1113h06,S11d1115h04,S11d1115h19,S11d1116h02,S11d1118h23,S12e1205h24,S12e1206h01,S12e1206h03,S12e1208h24,S12e1209h06,S01b0107h04,S01b0107h20,S01c0108h04,S11d1112h05,S11d1115h02,S11d1115h05,S11d1116h22,S12e1203h23,S12e1204h06,S12e1205h03,S12e1207h19,S12e1208h19,S01b0107h22,S06aH07,S07aH07,S07aH08,S08aH08,S11d1112h22,S11d1114h02,S11d1115h20,S11d1117h24,S12e1203h04,S12e1206h02,S12e1206h20,S12e1209h19,S12e1209h22,S02aH01,S11d1114h20,S11d1115h21,S11d1116h01,S11d1116h03,S11d1116h24,S11d1117h21,S12e1203h01,S12e1204h02,S12e1205h19,S12e1205h23,S12e1206h06,S12e1208h05,S11aH08,S11d1117h19,S11d1118h22,S12e1207h04,S12e1207h20,S12e1208h02,S12e1208h23,S12e1209h21,S01b0107h19,S04aH08,S06aH01,S11d1113h05,S11d1114h23,S11d1115h24,S11d1116h20,S11d1117h22,S12aH08,S12e1203h24,S12e1206h05,S12e1206h19,S12e1207h03,S12e1207h06,S12e1208h22,S12e1209h01,S12e1209h02 | I12: N | J12: S03aH03,S03aH02,S04aH02,S02aH02,S02aH03,S01aH03,S01aH02,S04aH03 | L12: N | M12: S02aH05,S04aH05,S06aH01,S02aH06,S03aH05,S05aH05,S01aH01,S04aH01,S04aH06,S08aH01,S08aH05,S06aH06,S05aH01,S07aH06,S03aH01,S02aH01,S05aH06,S01aH05,S03aH06,S06aH05,S01aH06,S07aH01,S08aH06,S07aH05 | O12: N | P12: S08aH01,S09aH07,S10aH01,S03aH08,S04aH07,S06aH08,S12aH01,S02aH01,S11aH08,S05aH07,S07aH01,S10aH07,S01aH08,S02aH08,S03aH07,S05aH08,S10aH08,S06aH07,S07aH07,S07aH08,S08aH08,S01aH07,S02aH07,S05aH01,S03aH01,S12aH07,S09aH01,S11aH07,S01aH01,S04aH01,S09aH08,S11aH01,S08aH07,S04aH08,S06aH01,S12aH08 | R12: N | S12: S01aH01,S04aH01,S09aH08,S11aH01,S08aH01,S09aH07,S10aH01,S09aH01,S11aH07,S08aH07,S03aH01,S12aH07,S11aH08,S03aH08,S04aH07,S06aH08,S12aH01,S01aH08,S02aH08,S03aH07,S06aH07,S07aH07,S07aH08,S08aH08,S04aH08,S06aH01,S12aH08,S01aH07,S02aH07,S05aH01,S05aH07,S07aH01,S10aH07,S02aH01,S05aH08,S10aH08 | U12: N | V12: S01aH01,S04aH01,S09aH08,S11aH01,S08aH07,S11aH08,S01aH08,S02aH08,S03aH07,S05aH08,S10aH08,S08aH01,S09aH07,S10aH01,S05aH07,S07aH01,S10aH07,S04aH08,S06aH01,S12aH08,S09aH01,S11aH07,S02aH01,S03aH01,S12aH07,S06aH07,S07aH07,S07aH08,S08aH08,S03aH08,S04aH07,S06aH08,S12aH01,S01aH07,S02aH07,S05aH01 | X12: N | Y12: AllSaAllH | AA12: N | AB12: WaP,FaN,FaP,SaP,RaP,RaN,SaN,WaN
I17: 0.75 | K17: share of charging at night
C18: ~UC_Sets: R_E: AllRegions
H21: =IF(H23=H24,"Not Required!","~UC_T: LO") -> Not Required!
C22: UC_N | D22: Pset_CI | E22: Pset_CO | F22: pset_pn | G22: Cset_CN | H22: TimeSlice | I22: UC_FLO | J22: UC_RHSRT | K22: UC_RHSRT~0
C23: UC_bev night chg limit | D23: ELC | E23: =G23 -> AuxStoIN | F23: *EV* | G23: AuxStoIN | H23: =HLOOKUP($A$10,$D$10:$CU$12,3,FALSE) -> AllSaAllH | I23: =1+I24 -> 0.25 | J23: 0 | K23: 3 | M23: night
D24: ELC | E24: =G24 -> AuxStoIN | F24: *EV* | G24: AuxStoIN | H24: =HLOOKUP($A$10,$D$10:$CU$12,2,FALSE) -> AllSaAllH | I24: =-$I$17 -> -0.75 | M24: day

Sheet s1p1v1_d
C9: =IF(A11="x","DeActivated","~TimeSlices") -> DeActivated
A10: s1p1v1_d | C10: season | D10: weekly | E10: daynite | F10: wparent | G10: dparent
A11: =IFERROR(IF(Veda!D5=A10,"ok","x"),"") -> x | C11: S01 | D11: a | E11: 0107h01 | F11: S01,S02,S03,S04,S05,S06,S07,S08,S09,S10,S11,S12 | G11: b
C12: S02 | D12: b | E12: 0107h02 | F12: S01 | G12: b
C13: S03 | D13: c | E13: 0107h03 | F13: S03 | G13: b
C14: S04 | D14: d | E14: 0107h04 | F14: S12 | G14: b
C15: S05 | E15: 0107h05 | G15: b
C16: S06 | E16: 0107h06 | G16: b
C17: S07 | E17: 0107h07 | G17: b
C18: S08 | E18: 0107h08 | G18: b
C19: S09 | E19: 0107h09 | G19: b
C20: S10 | E20: 0107h10 | G20: b
C21: S11 | E21: 0107h11 | G21: b
C22: S12 | E22: 0107h12 | G22: b
E23: 0107h13 | G23: b
E24: 0107h14 | G24: b
E25: 0107h15 | G25: b
E26: 0107h16 | G26: b
E27: 0107h17 | G27: b
E28: 0107h18 | G28: b
E29: 0107h19 | G29: b
E30: 0107h20 | G30: b
E31: 0107h21 | G31: b
E32: 0107h22 | G32: b
E33: 0107h23 | G33: b
E34: 0107h24 | G34: b
... E90: H08 | G90: a

Sheet s5p5v5_d
C9: =IF(A11="x","DeActivated","~TimeSlices") -> DeActivated | I9: =IF(A11="x","DeActivated","~TFM_DINS-AT") -> DeActivated | N9: =IF(A11="x","DeActivated","~TFM_DINS-AT") -> DeActivated | S9: =IF(A11="x","DeActivated","~TFM_DINS-AT") -> DeActivated | X9: =IF(A11="x","DeActivated","~TFM_DINS-AT") -> DeActivated | AC9: =IF(A11="x","DeActivated","~TFM_DINS-AT") -> DeActivated | AG9: =IF(A11="x","DeActivated","~TFM_DINS-AT") -> DeActivated | AK9: =IF(A11="x","DeActivated","~TFM_INS-AT") -> DeActivated
A10: s5p5v5_d | C10: season | D10: weekly | E10: daynite | F10: wparent | G10: dparent | I10: commodity | J10: timeslice | K10: com_fr | L10: process | N10: commodity | O10: timeslice | P10: com_fr | Q10: process | S10: commodity | T10: timeslice | U10: com_fr | V10: process | X10: g_yrfr | Y10: com_fr | Z10: timeslice | AA10: commodity | AC10: commodity | AD10: timeslice | AE10: com_fr | AG10: commodity | AH10: timeslice | AI10: com_pkflx | AK10: Year | AL10: timeslice | AM10: ncap_afs | AN10: pset_ci
A11: =IFERROR(IF(Veda!D5=A10,"ok","x"),"") -> x | C11: S01 | D11: a | E11: 0107h01 | F11: S01,S02,S03,S04,S05,S06,S07,S08,S09,S10,S11,S12 | G11: b | I11: elc_spv_001 | J11: S01aH01 | K11: 0 | L11: IMPNRGZ | N11: elc_won_001 | O11: S01aH01 | P11: 0.023761553 | Q11: IMPNRGZ | S11: elc_wof_001 | T11: S01aH01 | U11: 0.023761553 | V11: IMPNRGZ | X11: 0.026484018 | Y11: 0.014679164 | Z11: S01aH01 | AA11: elc_roadtransport | AC11: elc_buildings | AD11: S01aH01 | AE11: 0.026088609 | AG11: ELC | AH11: S01aH01 | AI11: 0.20690356 | AK11: 2025 | AL11: S01 | AM11: 0.282 | AN11: hydro
C12: S02 | D12: b | E12: 0107h02 | F12: S01 | G12: b | I12: elc_spv_001 | J12: S01aH02 | K12: 0.0045185361 | L12: IMPNRGZ | N12: elc_won_001 | O12: S01aH02 | P12: 0.0019364168 | Q12: IMPNRGZ | S12: elc_wof_001 | T12: S01aH02 | U12: 0.0019364168 | V12: IMPNRGZ | X12: 0.0033105023 | Y12: 0.0042297525 | Z12: S01aH02 | AA12: elc_roadtransport | AC12: elc_buildings | AD12: S01aH02 | AE12: 0.0038097721 | AG12: ELC | AH12: S01aH02 | AI12: 0.084970608 | AK12: 2025 | AL12: S02 | AM12: 0.2808 | AN12: hydro
C13: S03 | D13: c | E13: 0107h03 | F13: S01 | G13: b | I13: elc_spv_001 | J13: S01aH03 | K13: 0.0063555069 | L13: IMPNRGZ | N13: elc_won_001 | O13: S01aH03 | P13: 0.0022390369 | Q13: IMPNRGZ | S13: elc_wof_001 | T13: S01aH03 | U13: 0.0022390369 | V13: IMPNRGZ | X13: 0.0033105023 | Y13: 0.0041913002 | Z13: S01aH03 | AA13: elc_roadtransport | AC13: elc_buildings | AD13: S01aH03 | AE13: 0.003773453 | AG13: ELC | AH13: S01aH03 | AI13: 0.10445604 | AK13: 2025 | AL13: S03 | AM13: 0.3252 | AN13: hydro
C14: S04 | D14: d | E14: 0107h04 | F14: S02 | G14: b | I14: elc_spv_001 | J14: S01aH04 | K14: 0.040736272 | L14: IMPNRGZ | N14: elc_won_001 | O14: S01aH04 | P14: 0.022063506 | Q14: IMPNRGZ | S14: elc_wof_001 | T14: S01aH04 | U14: 0.022063506 | V14: IMPNRGZ | X14: 0.019863014 | Y14: 0.025974525 | Z14: S01aH04 | AA14: elc_roadtransport | AC14: elc_buildings | AD14: S01aH04 | AE14: 0.022666706 | AG14: ELC | AH14: S01aH04 | AI14: 0.20545166 | AK14: 2025 | AL14: S04 | AM14: 0.3822 | AN14: hydro
C15: S05 | D15: e | E15: 0107h05 | F15: S02 | G15: b | I15: elc_spv_001 | J15: S01aH05 | K15: 0.0053880625 | L15: IMPNRGZ | N15: elc_won_001 | O15: S01aH05 | P15: 0.0041188464 | Q15: IMPNRGZ | S15: elc_wof_001 | T15: S01aH05 | U15: 0.0041188464 | V15: IMPNRGZ | X15: 0.0033105023 | Y15: 0.0064407594 | Z15: S01aH05 | AA15: elc_roadtransport | AC15: elc_buildings | AD15: S01aH05 | AE15: 0.0041793919 | AG15: ELC | AH15: S01aH05 | AI15: 0.11508497 | AK15: 2025 | AL15: S05 | AM15: 0.3801 | AN15: hydro
C16: S06 | D16: f | E16: 0107h06 | F16: S03 | G16: b | I16: elc_spv_001 | J16: S01aH06 | K16: 0.0034244644 | L16: IMPNRGZ | N16: elc_won_001 | O16: S01aH06 | P16: 0.0039878622 | Q16: IMPNRGZ | S16: elc_wof_001 | T16: S01aH06 | U16: 0.0039878622 | V16: IMPNRGZ | X16: 0.0033105023 | Y16: 0.0064407594 | Z16: S01aH06 | AA16: elc_roadtransport | AC16: elc_buildings | AD16: S01aH06 | AE16: 0.0043900063 | AG16: ELC | AH16: S01aH06 | AI16: 0.073903984 | AK16: 2025 | AL16: S06 | AM16: 0.3925 | AN16: hydro
C17: S07 | D17: g | E17: 0107h07 | F17: S04 | G17: b | I17: elc_spv_001 | J17: S01aH07 | K17: 0 | L17: IMPNRGZ | N17: elc_won_001 | O17: S01aH07 | P17: 0.0040839655 | Q17: IMPNRGZ | S17: elc_wof_001 | T17: S01aH07 | U17: 0.0040839655 | V17: IMPNRGZ | X17: 0.0033105023 | Y17: 0.0049987984 | Z17: S01aH07 | AA17: elc_roadtransport | AC17: elc_buildings | AD17: S01aH07 | AE17: 0.0043095624 | AG17: ELC | AH17: S01aH07 | AI17: 0.067987279 | AK17: 2025 | AL17: S07 | AM17: 0.3537 | AN17: hydro
C18: S08 | D18: h | E18: 0107h08 | F18: S04 | G18: b | I18: elc_spv_001 | J18: S01aH08 | K18: 0 | L18: IMPNRGZ | N18: elc_won_001 | O18: S01aH08 | P18: 0.01990172 | Q18: IMPNRGZ | S18: elc_wof_001 | T18: S01aH08 | U18: 0.01990172 | V18: IMPNRGZ | X18: 0.016552511 | Y18: 0.012496996 | Z18: S01aH08 | AA18: elc_roadtransport | AC18: elc_buildings | AD18: S01aH08 | AE18: 0.016800608 | AG18: ELC | AH18: S01aH08 | AI18: 0.28248078 | AK18: 2025 | AL18: S08 | AM18: 0.3485 | AN18: hydro
C19: S09 | D19: i | E19: 0107h09 | F19: S10 | G19: b | I19: elc_spv_001 | J19: S01b0107h01 | K19: 0 | L19: IMPNRGZ | N19: elc_won_001 | O19: S01b0107h01 | P19: 0.00040735053 | Q19: IMPNRGZ | S19: elc_wof_001 | T19: S01b0107h01 | U19: 0.00040735053 | V19: IMPNRGZ | X19: 0.00011415525 | Y19: 2.1546545e-05 | Z19: S01b0107h01 | AA19: elc_roadtransport | AC19: elc_buildings | AD19: S01b0107h01 | AE19: 8.8739699e-05 | AG19: ELC | AH19: S01b0107h01 | AI19: 0 | AK19: 2025 | AL19: S09 | AM19: 0.2918 | AN19: hydro
C20: S10 | D20: j | E20: 0107h10 | F20: S11 | G20: b | I20: elc_spv_001 | J20: S01b0107h02 | K20: 0 | L20: IMPNRGZ | N20: elc_won_001 | O20: S01b0107h02 | P20: 0.00048312598 | Q20: IMPNRGZ | S20: elc_wof_001 | T20: S01b0107h02 | U20: 0.00048312598 | V20: IMPNRGZ | X20: 0.00011415525 | Y20: 1.4916839e-05 | Z20: S01b0107h02 | AA20: elc_roadtransport | AC20: elc_buildings | AD20: S01b0107h02 | AE20: 8.9015192e-05 | AG20: ELC | AH20: S01b0107h02 | AI20: 0 | AK20: 2025 | AL20: S10 | AM20: 0.3121 | AN20: hydro
C21: S11 | D21: k | E21: 0107h11 | F21: S12 | G21: b | I21: elc_spv_001 | J21: S01b0107h03 | K21: 0 | L21: IMPNRGZ | N21: elc_won_001 | O21: S01b0107h03 | P21: 0.0005709368 | Q21: IMPNRGZ | S21: elc_wof_001 | T21: S01b0107h03 | U21: 0.0005709368 | V21: IMPNRGZ | X21: 0.00011415525 | Y21: 1.6574265e-05 | Z21: S01b0107h03 | AA21: elc_roadtransport | AC21: elc_buildings | AD21: S01b0107h03 | AE21: 9.6178011e-05 | AG21: ELC | AH21: S01b0107h03 | AI21: 0 | AK21: 2025 | AL21: S11 | AM21: 0.297 | AN21: hydro
C22: S12 | D22: l | E22: 0107h12 | F22: S12 | G22: b | I22: elc_spv_001 | J22: S01b0107h04 | K22: 0 | L22: IMPNRGZ | N22: elc_won_001 | O22: S01b0107h04 | P22: 0.00064412741 | Q22: IMPNRGZ | S22: elc_wof_001 | T22: S01b0107h04 | U22: 0.00064412741 | V22: IMPNRGZ | X22: 0.00011415525 | Y22: 1.4585353e-05 | Z22: S01b0107h04 | AA22: elc_roadtransport | AC22: elc_buildings | AD22: S01b0107h04 | AE22: 0.00010053998 | AG22: ELC | AH22: S01b0107h04 | AI22: 0 | AK22: 2025 | AL22: S12 | AM22: 0.3012 | AN22: hydro
D23: m | E23: 0107h13 | F23: S12 | G23: b | I23: elc_spv_001 | J23: S01b0107h05 | K23: 0 | L23: IMPNRGZ | N23: elc_won_001 | O23: S01b0107h05 | P23: 0.0006713354 | Q23: IMPNRGZ | S23: elc_wof_001 | T23: S01b0107h05 | U23: 0.0006713354 | V23: IMPNRGZ | X23: 0.00011415525 | Y23: 2.1215059e-05 | Z23: S01b0107h05 | AA23: elc_roadtransport | AC23: elc_buildings | AD23: S01b0107h05 | AE23: 0.00011133013 | AG23: ELC | AH23: S01b0107h05 | AI23: 0 | AK23: 2026 | AL23: S01 | AM23: 0.281 | AN23: hydro
D24: n | E24: 0107h14 | F24: S12 | G24: b | I24: elc_spv_001 | J24: S01b0107h06 | K24: 0 | L24: IMPNRGZ | N24: elc_won_001 | O24: S01b0107h06 | P24: 0.00067741423 | Q24: IMPNRGZ | S24: elc_wof_001 | T24: S01b0107h06 | U24: 0.00067741423 | V24: IMPNRGZ | X24: 0.00011415525 | Y24: 5.7678443e-05 | Z24: S01b0107h06 | AA24: elc_roadtransport | AC24: elc_buildings | AD24: S01b0107h06 | AE24: 0.00012533436 | AG24: ELC | AH24: S01b0107h06 | AI24: 0 | AK24: 2026 | AL24: S02 | AM24: 0.3212 | AN24: hydro
D25: o | E25: 0107h15 | F25: S12 | G25: b | I25: elc_spv_001 | J25: S01b0107h07 | K25: 0 | L25: IMPNRGZ | N25: elc_won_001 | O25: S01b0107h07 | P25: 0.00067928526 | Q25: IMPNRGZ | S25: elc_wof_001 | T25: S01b0107h07 | U25: 0.00067928526 | V25: IMPNRGZ | X25: 0.00011415525 | Y25: 0.0001690575 | Z25: S01b0107h07 | AA25: elc_roadtransport | AC25: elc_buildings | AD25: S01b0107h07 | AE25: 0.00013167069 | AG25: ELC | AH25: S01b0107h07 | AI25: 0 | AK25: 2026 | AL25: S03 | AM25: 0.3635 | AN25: hydro
D26: p | E26: 0107h16 | F26: S12 | G26: b | I26: elc_spv_001 | J26: S01b0107h08 | K26: 0 | L26: IMPNRGZ | N26: elc_won_001 | O26: S01b0107h08 | P26: 0.00067976116 | Q26: IMPNRGZ | S26: elc_wof_001 | T26: S01b0107h08 | U26: 0.00067976116 | V26: IMPNRGZ | X26: 0.00011415525 | Y26: 0.00019060405 | Z26: S01b0107h08 | AA26: elc_roadtransport | AC26: elc_buildings | AD26: S01b0107h08 | AE26: 0.00013649182 | AG26: ELC | AH26: S01b0107h08 | AI26: 0 | AK26: 2026 | AL26: S04 | AM26: 0.3661 | AN26: hydro
E27: 0107h17 | G27: b | I27: elc_spv_001 | J27: S01b0107h09 | K27: 0.00011889051 | L27: IMPNRGZ | N27: elc_won_001 | O27: S01b0107h09 | P27: 0.00067817399 | Q27: IMPNRGZ | S27: elc_wof_001 | T27: S01b0107h09 | U27: 0.00067817399 | V27: IMPNRGZ | X27: 0.00011415525 | Y27: 0.00014585353 | Z27: S01b0107h09 | AA27: elc_roadtransport | AC27: elc_buildings | AD27: S01b0107h09 | AE27: 0.00013809887 | AG27: ELC | AH27: S01b0107h09 | AI27: 0 | AK27: 2026 | AL27: S05 | AM27: 0.3922 | AN27: hydro
E28: 0107h18 | G28: b | I28: elc_spv_001 | J28: S01b0107h10 | K28: 0.00019302034 | L28: IMPNRGZ | N28: elc_won_001 | O28: S01b0107h10 | P28: 0.00068012151 | Q28: IMPNRGZ | S28: elc_wof_001 | T28: S01b0107h10 | U28: 0.00068012151 | V28: IMPNRGZ | X28: 0.00011415525 | Y28: 0.00014452759 | Z28: S01b0107h10 | AA28: elc_roadtransport | AC28: elc_buildings | AD28: S01b0107h10 | AE28: 0.00013860394 | AG28: ELC | AH28: S01b0107h10 | AI28: 0 | AK28: 2026 | AL28: S06 | AM28: 0.388 | AN28: hydro
E29: 0107h19 | G29: b | I29: elc_spv_001 | J29: S01b0107h11 | K29: 0.00021992335 | L29: IMPNRGZ | N29: elc_won_001 | O29: S01b0107h11 | P29: 0.00068012151 | Q29: IMPNRGZ | S29: elc_wof_001 | T29: S01b0107h11 | U29: 0.00068012151 | V29: IMPNRGZ | X29: 0.00011415525 | Y29: 0.00014088125 | Z29: S01b0107h11 | AA29: elc_roadtransport | AC29: elc_buildings | AD29: S01b0107h11 | AE29: 0.00013796112 | AG29: ELC | AH29: S01b0107h11 | AI29: 0 | AK29: 2026 | AL29: S07 | AM29: 0.3399 | AN29: hydro
E30: 0107h20 | G30: b | I30: elc_spv_001 | J30: S01b0107h12 | K30: 0.00019814477 | L30: IMPNRGZ | N30: elc_won_001 | O30: S01b0107h12 | P30: 0.000679224 | Q30: IMPNRGZ | S30: elc_wof_001 | T30: S01b0107h12 | U30: 0.000679224 | V30: IMPNRGZ | X30: 0.00011415525 | Y30: 0.00014054977 | Z30: S01b0107h12 | AA30: elc_roadtransport | AC30: elc_buildings | AD30: S01b0107h12 | AE30: 0.00013828253 | AG30: ELC | AH30: S01b0107h12 | AI30: 0 | AK30: 2026 | AL30: S08 | AM30: 0.3691 | AN30: hydro
E31: 0107h21 | G31: b | I31: elc_spv_001 | J31: S01b0107h13 | K31: 0.00014611046 | L31: IMPNRGZ | N31: elc_won_001 | O31: S01b0107h13 | P31: 0.00067995075 | Q31: IMPNRGZ | S31: elc_wof_001 | T31: S01b0107h13 | U31: 0.00067995075 | V31: IMPNRGZ | X31: 0.00011415525 | Y31: 0.00014253868 | Z31: S01b0107h13 | AA31: elc_roadtransport | AC31: elc_buildings | AD31: S01b0107h13 | AE31: 0.00013970591 | AG31: ELC | AH31: S01b0107h13 | AI31: 0 | AK31: 2026 | AL31: S09 | AM31: 0.3272 | AN31: hydro
E32: 0107h22 | G32: b | I32: elc_spv_001 | J32: S01b0107h14 | K32: 0.00019029256 | L32: IMPNRGZ | N32: elc_won_001 | O32: S01b0107h14 | P32: 0.00067577752 | Q32: IMPNRGZ | S32: elc_wof_001 | T32: S01b0107h14 | U32: 0.00067577752 | V32: IMPNRGZ | X32: 0.00011415525 | Y32: 0.0001488369 | Z32: S01b0107h14 | AA32: elc_roadtransport | AC32: elc_buildings | AD32: S01b0107h14 | AE32: 0.0001470983 | AG32: ELC | AH32: S01b0107h14 | AI32: 0 | AK32: 2026 | AL32: S10 | AM32: 0.3148 | AN32: hydro
E33: 0107h23 | G33: b | I33: elc_spv_001 | J33: S01b0107h15 | K33: 0.00023654525 | L33: IMPNRGZ | N33: elc_won_001 | O33: S01b0107h15 | P33: 0.00067504594 | Q33: IMPNRGZ | S33: elc_wof_001 | T33: S01b0107h15 | U33: 0.00067504594 | V33: IMPNRGZ | X33: 0.00011415525 | Y33: 0.00015049433 | Z33: S01b0107h15 | AA33: elc_roadtransport | AC33: elc_buildings | AD33: S01b0107h15 | AE33: 0.00015136845 | AG33: ELC | AH33: S01b0107h15 | AI33: 0 | AK33: 2026 | AL33: S11 | AM33: 0.3137 | AN33: hydro
E34: 0107h24 | G34: b | I34: elc_spv_001 | J34: S01b0107h16 | K34: 0.00021829986 | L34: IMPNRGZ | N34: elc_won_001 | O34: S01b0107h16 | P34: 0.00066272338 | Q34: IMPNRGZ | S34: elc_wof_001 | T34: S01b0107h16 | U34: 0.00066272338 | V34: IMPNRGZ | X34: 0.00011415525 | Y34: 0.00017237236 | Z34: S01b0107h16 | AA34: elc_roadtransport | AC34: elc_buildings | AD34: S01b0107h16 | AE34: 0.00015651098 | AG34: ELC | AH34: S01b0107h16 | AI34: 0 | AK34: 2026 | AL34: S12 | AM34: 0.3006 | AN34: hydro
E35: 0108h01 | G35: c | I35: elc_spv_001 | J35: S01b0107h17 | K35: 0.00017161159 | L35: IMPNRGZ | N35: elc_won_001 | O35: S01b0107h17 | P35: 0.00065881778 | Q35: IMPNRGZ | S35: elc_wof_001 | T35: S01b0107h17 | U35: 0.00065881778 | V35: IMPNRGZ | X35: 0.00011415525 | Y35: 0.00022209515 | Z35: S01b0107h17 | AA35: elc_roadtransport | AC35: elc_buildings | AD35: S01b0107h17 | AE35: 0.00015692422 | AG35: ELC | AH35: S01b0107h17 | AI35: 0 | AK35: 2027 | AL35: S01 | AM35: 0.3258 | AN35: hydro
E36: 0108h02 | G36: c | I36: elc_spv_001 | J36: S01b0107h18 | K36: 0.00011249392 | L36: IMPNRGZ | N36: elc_won_001 | O36: S01b0107h18 | P36: 0.0006357937 | Q36: IMPNRGZ | S36: elc_wof_001 | T36: S01b0107h18 | U36: 0.0006357937 | V36: IMPNRGZ | X36: 0.00011415525 | Y36: 0.00022209515 | Z36: S01b0107h18 | AA36: elc_roadtransport | AC36: elc_buildings | AD36: S01b0107h18 | AE36: 0.00016036788 | AG36: ELC | AH36: S01b0107h18 | AI36: 0 | AK36: 2027 | AL36: S02 | AM36: 0.2767 | AN36: hydro
E37: 0108h03 | G37: c | I37: elc_spv_001 | J37: S01b0107h19 | K37: 0 | L37: IMPNRGZ | N37: elc_won_001 | O37: S01b0107h19 | P37: 0.00059667111 | Q37: IMPNRGZ | S37: elc_wof_001 | T37: S01b0107h19 | U37: 0.00059667111 | V37: IMPNRGZ | X37: 0.00011415525 | Y37: 0.00017237236 | Z37: S01b0107h19 | AA37: elc_roadtransport | AC37: elc_buildings | AD37: S01b0107h19 | AE37: 0.00015439887 | AG37: ELC | AH37: S01b0107h19 | AI37: 0 | AK37: 2027 | AL37: S03 | AM37: 0.366 | AN37: hydro
E38: 0108h04 | G38: c | I38: elc_spv_001 | J38: S01b0107h20 | K38: 0 | L38: IMPNRGZ | N38: elc_won_001 | O38: S01b0107h20 | P38: 0.00056038356 | Q38: IMPNRGZ | S38: elc_wof_001 | T38: S01b0107h20 | U38: 0.00056038356 | V38: IMPNRGZ | X38: 0.00011415525 | Y38: 0.00015579809 | Z38: S01b0107h20 | AA38: elc_roadtransport | AC38: elc_buildings | AD38: S01b0107h20 | AE38: 0.00014888901 | AG38: ELC | AH38: S01b0107h20 | AI38: 0 | AK38: 2027 | AL38: S04 | AM38: 0.3432 | AN38: hydro
... E322: 1213h24 | G322: n | I322: elc_spv_001 | J322: S12aH08 | K322: 0 | L322: IMPNRGZ | N322: elc_won_001 | O322: S12aH08 | P322: 0.0099431473 | Q322: IMPNRGZ | S322: elc_wof_001 | T322: S12aH08 | U322: 0.0099431473 | V322: IMPNRGZ | X322: 0.014269406 | Y322: 0.010773272 | Z322: S12aH08 | AA322: elc_roadtransport | AC322: elc_buildings | AD322: S12aH08 | AE322: 0.01521927 | AG322: ELC | AH322: S12aH08 | AI322: 0.21640076 | AK322: 2050 | AL322: S12 | AM322: 0.391 | AN322: hydro
E323: 1215h01 | G323: o | I323: elc_spv_001 | J323: S12k1203h01 | K323: 0 | L323: IMPNRGZ | N323: elc_won_001 | O323: S12k1203h01 | P323: 4.9117799e-08 | Q323: IMPNRGZ | S323: elc_wof_001 | T323: S12k1203h01 | U323: 4.9117799e-08 | V323: IMPNRGZ | X323: 0.00011415525 | Y323: 2.1546545e-05 | Z323: S12k1203h01 | AA323: elc_roadtransport | AC323: elc_buildings | AD323: S12k1203h01 | AE323: 8.5644007e-05 | AG323: ELC | AH323: S12k1203h01 | AI323: 0
E324: 1215h02 | G324: o | I324: elc_spv_001 | J324: S12k1203h02 | K324: 0 | L324: IMPNRGZ | N324: elc_won_001 | O324: S12k1203h02 | P324: 2.1017612e-07 | Q324: IMPNRGZ | S324: elc_wof_001 | T324: S12k1203h02 | U324: 2.1017612e-07 | V324: IMPNRGZ | X324: 0.00011415525 | Y324: 1.4916839e-05 | Z324: S12k1203h02 | AA324: elc_roadtransport | AC324: elc_buildings | AD324: S12k1203h02 | AE324: 8.59195e-05 | AG324: ELC | AH324: S12k1203h02 | AI324: 0
E325: 1215h03 | G325: o | I325: elc_spv_001 | J325: S12k1203h03 | K325: 0 | L325: IMPNRGZ | N325: elc_won_001 | O325: S12k1203h03 | P325: 2.9529355e-07 | Q325: IMPNRGZ | S325: elc_wof_001 | T325: S12k1203h03 | U325: 2.9529355e-07 | V325: IMPNRGZ | X325: 0.00011415525 | Y325: 1.6574265e-05 | Z325: S12k1203h03 | AA325: elc_roadtransport | AC325: elc_buildings | AD325: S12k1203h03 | AE325: 9.1567107e-05 | AG325: ELC | AH325: S12k1203h03 | AI325: 0
E326: 1215h04 | G326: o | I326: elc_spv_001 | J326: S12k1203h04 | K326: 0 | L326: IMPNRGZ | N326: elc_won_001 | O326: S12k1203h04 | P326: 3.312996e-07 | Q326: IMPNRGZ | S326: elc_wof_001 | T326: S12k1203h04 | U326: 3.312996e-07 | V326: IMPNRGZ | X326: 0.00011415525 | Y326: 1.4585353e-05 | Z326: S12k1203h04 | AA326: elc_roadtransport | AC326: elc_buildings | AD326: S12k1203h04 | AE326: 9.6296404e-05 | AG326: ELC | AH326: S12k1203h04 | AI326: 0
E327: 1215h05 | G327: o | I327: elc_spv_001 | J327: S12k1203h05 | K327: 0 | L327: IMPNRGZ | N327: elc_won_001 | O327: S12k1203h05 | P327: 4.6256548e-07 | Q327: IMPNRGZ | S327: elc_wof_001 | T327: S12k1203h05 | U327: 4.6256548e-07 | V327: IMPNRGZ | X327: 0.00011415525 | Y327: 2.1215059e-05 | Z327: S12k1203h05 | AA327: elc_roadtransport | AC327: elc_buildings | AD327: S12k1203h05 | AE327: 0.00010639781 | AG327: ELC | AH327: S12k1203h05 | AI327: 0
