Workbook

Sheet Veda
G1: 1,2,3,4,5,6,7,8,9,10,11,12,13,14,15,21,22,23,24,25
D2: ="~Inputcell: "&_xlfn.TEXTJOIN(",",TRUE,G1:EE1) -> ~Inputcell: 1,2,3,4,5,6,7,8,9,10,11,12,13,14,15,21,22,23,24,25 | G2: 5 | H2: 6 | I2: 7 | J2: 9 | K2: 10 | L2: 11 | M2: 16 | N2: 17 | O2: 18 | P2: 20 | Q2: 21 | R2: 22 | S2: 27 | T2: 28 | U2: 29 | V2: 31 | W2: 32 | X2: 33 | Y2: 38 | Z2: 39 | AA2: 40 | AB2: 42 | AC2: 43 | AD2: 44 | AE2: 49 | AF2: 50 | AG2: 51 | AH2: 53 | AI2: 54 | AJ2: 55
D3: 3
D5: =VLOOKUP(D3,$C$9:$E$999,2,FALSE) -> ts_annual | E5: =VLOOKUP(D3,$C$9:$E$999,3,FALSE) -> C3
B7: ~Scenmap
A8: priority | B8: scen | C8: case_no | D8: timeslice | E8: climate | AM8: bio price multiplier
A9: 5 | B9: =VLOOKUP(E9,$AK$9:$AL$15,2,FALSE)&"."&VLOOKUP(D9,$AH$9:$AI$24,2,FALSE) -> e 1.5 deg no OS.kAnn | C9: 1 | D9: =VLOOKUP(AJ9,$AG$9:$AH$22,2,FALSE) -> ts_annual | E9: C1 | G9: Limit warming to 1.5°C (>50%) with no or limited overshoot | AG9: 1 | AH9: ts_annual | AI9: kAnn | AJ9: 1 | AK9: C1 | AL9: e 1.5 deg no OS | AM9: 5
A10: 5 | B10: =VLOOKUP(E10,$AK$9:$AL$15,2,FALSE)&"."&VLOOKUP(D10,$AH$9:$AI$24,2,FALSE) -> d 1.5 deg OS.kAnn | C10: =C9+1 -> 2 | D10: =VLOOKUP(AJ10,$AG$9:$AH$22,2,FALSE) -> ts_annual | E10: C2 | G10: Limit warming to 1.5°C (>67%) with high overshoot | S10: IEA | AG10: 2 | AH10: ts_12t | AI10: k12 | AJ10: 1 | AK10: C2 | AL10: d 1.5 deg OS | AM10: 4
A11: 5 | B11: =VLOOKUP(E11,$AK$9:$AL$15,2,FALSE)&"."&VLOOKUP(D11,$AH$9:$AI$24,2,FALSE) -> c 2 deg (67%).kAnn | C11: =C10+1 -> 3 | D11: =VLOOKUP(AJ11,$AG$9:$AH$22,2,FALSE) -> ts_annual | E11: C3 | G11: Limit warming to 2°C (>67%) with higher action post-2030 | S11: 2022 | AG11: 3 | AH11: ts_012 | AI11: j12 | AJ11: 1 | AK11: C3 | AL11: c 2 deg (67%) | AM11: 3
A12: 5 | B12: =VLOOKUP(E12,$AK$9:$AL$15,2,FALSE)&"."&VLOOKUP(D12,$AH$9:$AI$24,2,FALSE) -> b 2 deg (50%).kAnn | C12: =C11+1 -> 4 | D12: =VLOOKUP(AJ12,$AG$9:$AH$22,2,FALSE) -> ts_annual | E12: C4 | G12: Limit warming to 2°C (>50%) with immediate action | S12: =SUMIFS(iea_data!I3:I9999,iea_data!$B$3:$B$9999,Veda!$S$11)+T28-T29 -> 81.78 | T12: base-year generation (TWh) | AG12: 4 | AH12: ts_024 | AI12: i24 | AJ12: 1 | AK12: C4 | AL12: b 2 deg (50%) | AM12: 3
A13: 5 | B13: =VLOOKUP(E13,$AK$9:$AL$15,2,FALSE)&"."&VLOOKUP(D13,$AH$9:$AI$24,2,FALSE) -> a 3 deg.kAnn | C13: =C12+1 -> 5 | D13: =VLOOKUP(AJ13,$AG$9:$AH$22,2,FALSE) -> ts_annual | E13: C7 | G13: Likely above 3°C warming with limited mitigation | AG13: 5 | AH13: ts_048 | AI13: h48 | AJ13: 1 | AK13: C7 | AL13: a 3 deg | AM13: 1.5
A14: 5 | B14: =VLOOKUP(E14,$AK$9:$AL$15,2,FALSE)&"."&VLOOKUP(D14,$AH$9:$AI$24,2,FALSE) -> e 1.5 deg no OS.k12 | C14: =C13+1 -> 6 | D14: =VLOOKUP(AJ14,$AG$9:$AH$22,2,FALSE) -> ts_12t | E14: =E9 -> C1 | T14: =S12 -> 81.78 | U14: =$S$12*J15 -> 95.6826 | V14: =$S$12*K15 -> 116.1276 | W14: =$S$12*L15 -> 133.3014 | X14: =$S$12*M15 -> 163.56 | Y14: =$S$12*N15 -> 193.8186 | Z14: =$S$12*O15 -> 234.7086 | AG14: 6 | AH14: ts_064 | AI14: g64 | AJ14: =AJ9+1 -> 2
A15: 5 | B15: =VLOOKUP(E15,$AK$9:$AL$15,2,FALSE)&"."&VLOOKUP(D15,$AH$9:$AI$24,2,FALSE) -> d 1.5 deg OS.k12 | C15: =C14+1 -> 7 | D15: =VLOOKUP(AJ15,$AG$9:$AH$22,2,FALSE) -> ts_12t | E15: =E10 -> C2 | G15: Electricity growth relative to 2020 | I15: =SUMIFS(ar6_r10!$F$2:$F$999,ar6_r10!$A$2:$A$999,Veda!$E$5,ar6_r10!$C$2:$C$999,Veda!I$17,ar6_r10!$M$2:$M$999,Veda!$G15) -> 1 | J15: =SUMIFS(ar6_r10!$F$2:$F$999,ar6_r10!$A$2:$A$999,Veda!$E$5,ar6_r10!$C$2:$C$999,Veda!J$17,ar6_r10!$M$2:$M$999,Veda!$G15) -> 1.17 | K15: =SUMIFS(ar6_r10!$F$2:$F$999,ar6_r10!$A$2:$A$999,Veda!$E$5,ar6_r10!$C$2:$C$999,Veda!K$17,ar6_r10!$M$2:$M$999,Veda!$G15) -> 1.42 | L15: =SUMIFS(ar6_r10!$F$2:$F$999,ar6_r10!$A$2:$A$999,Veda!$E$5,ar6_r10!$C$2:$C$999,Veda!L$17,ar6_r10!$M$2:$M$999,Veda!$G15) -> 1.63 | M15: =SUMIFS(ar6_r10!$F$2:$F$999,ar6_r10!$A$2:$A$999,Veda!$E$5,ar6_r10!$C$2:$C$999,Veda!M$17,ar6_r10!$M$2:$M$999,Veda!$G15) -> 2 | N15: =SUMIFS(ar6_r10!$F$2:$F$999,ar6_r10!$A$2:$A$999,Veda!$E$5,ar6_r10!$C$2:$C$999,Veda!N$17,ar6_r10!$M$2:$M$999,Veda!$G15) -> 2.37 | O15: =SUMIFS(ar6_r10!$F$2:$F$999,ar6_r10!$A$2:$A$999,Veda!$E$5,ar6_r10!$C$2:$C$999,Veda!O$17,ar6_r10!$M$2:$M$999,Veda!$G15) -> 2.87 | AG15: 7 | AH15: ts_096P50 | AI15: f96p50 | AJ15: =AJ10+1 -> 2
A16: 5 | B16: =VLOOKUP(E16,$AK$9:$AL$15,2,FALSE)&"."&VLOOKUP(D16,$AH$9:$AI$24,2,FALSE) -> c 2 deg (67%).k12 | C16: =C15+1 -> 8 | D16: =VLOOKUP(AJ16,$AG$9:$AH$22,2,FALSE) -> ts_12t | E16: =E11 -> C3 | S16: ~TFM_INS-TS | AG16: 8 | AH16: ts_096P10 | AI16: f96p10 | AJ16: =AJ11+1 -> 2
A17: 5 | B17: =VLOOKUP(E17,$AK$9:$AL$15,2,FALSE)&"."&VLOOKUP(D17,$AH$9:$AI$24,2,FALSE) -> b 2 deg (50%).k12 | C17: =C16+1 -> 9 | D17: =VLOOKUP(AJ17,$AG$9:$AH$22,2,FALSE) -> ts_12t | E17: =E12 -> C4 | I17: 2020 | J17: =U17 -> 2025 | K17: =V17 -> 2030 | L17: =W17 -> 2035 | M17: =X17 -> 2040 | N17: =Y17 -> 2045 | O17: =Z17 -> 2050 | S17: commodity | T17: 2022 | U17: 2025 | V17: 2030 | W17: 2035 | X17: 2040 | Y17: 2045 | Z17: 2050 | AA17: attribute | AG17: 9 | AH17: ts_096P90 | AI17: f96p90 | AJ17: =AJ12+1 -> 2
A18: 5 | B18: =VLOOKUP(E18,$AK$9:$AL$15,2,FALSE)&"."&VLOOKUP(D18,$AH$9:$AI$24,2,FALSE) -> a 3 deg.k12 | C18: =C17+1 -> 10 | D18: =VLOOKUP(AJ18,$AG$9:$AH$22,2,FALSE) -> ts_12t | E18: =E13 -> C7 | G18: Hydrogen as a share of electricity | I18: =SUMIFS(ar6_r10!$F$2:$F$999,ar6_r10!$A$2:$A$999,Veda!$E$5,ar6_r10!$C$2:$C$999,Veda!I$17,ar6_r10!$M$2:$M$999,Veda!$G18) -> 0 | J18: =SUMIFS(ar6_r10!$F$2:$F$999,ar6_r10!$A$2:$A$999,Veda!$E$5,ar6_r10!$C$2:$C$999,Veda!J$17,ar6_r10!$M$2:$M$999,Veda!$G18) -> 0 | K18: =SUMIFS(ar6_r10!$F$2:$F$999,ar6_r10!$A$2:$A$999,Veda!$E$5,ar6_r10!$C$2:$C$999,Veda!K$17,ar6_r10!$M$2:$M$999,Veda!$G18) -> 0 | L18: =SUMIFS(ar6_r10!$F$2:$F$999,ar6_r10!$A$2:$A$999,Veda!$E$5,ar6_r10!$C$2:$C$999,Veda!L$17,ar6_r10!$M$2:$M$999,Veda!$G18) -> 0 | M18: =SUMIFS(ar6_r10!$F$2:$F$999,ar6_r10!$A$2:$A$999,Veda!$E$5,ar6_r10!$C$2:$C$999,Veda!M$17,ar6_r10!$M$2:$M$999,Veda!$G18) -> 0.01 | N18: =SUMIFS(ar6_r10!$F$2:$F$999,ar6_r10!$A$2:$A$999,Veda!$E$5,ar6_r10!$C$2:$C$999,Veda!N$17,ar6_r10!$M$2:$M$999,Veda!$G18) -> 0.01 | O18: =SUMIFS(ar6_r10!$F$2:$F$999,ar6_r10!$A$2:$A$999,Veda!$E$5,ar6_r10!$C$2:$C$999,Veda!O$17,ar6_r10!$M$2:$M$999,Veda!$G18) -> 0.03 | S18: hydrogen_allsect | T18: =I18*T$14 -> 0 | U18: =J18*U$14 -> 0 | V18: =K18*V$14 -> 0 | W18: =L18*W$14 -> 0 | X18: =M18*X$14 -> 1.6356 | Y18: =N18*Y$14 -> 1.938186 | Z18: =O18*Z$14 -> 7.041258 | AA18: demand | AG18: 10 | AH18: s1p1v1_d | AI18: e3d | AJ18: =AJ13+1 -> 2
A19: 5 | B19: =VLOOKUP(E19,$AK$9:$AL$15,2,FALSE)&"."&VLOOKUP(D19,$AH$9:$AI$24,2,FALSE) -> e 1.5 deg no OS.j12 | C19: =C18+1 -> 11 | D19: =VLOOKUP(AJ19,$AG$9:$AH$22,2,FALSE) -> ts_012 | E19: =E14 -> C1 | G19: Industry electricity share | I19: =SUMIFS(ar6_r10!$F$2:$F$999,ar6_r10!$A$2:$A$999,Veda!$E$5,ar6_r10!$C$2:$C$999,Veda!I$17,ar6_r10!$M$2:$M$999,Veda!$G19) -> 0.43 | J19: =SUMIFS(ar6_r10!$F$2:$F$999,ar6_r10!$A$2:$A$999,Veda!$E$5,ar6_r10!$C$2:$C$999,Veda!J$17,ar6_r10!$M$2:$M$999,Veda!$G19) -> 0.42 | K19: =SUMIFS(ar6_r10!$F$2:$F$999,ar6_r10!$A$2:$A$999,Veda!$E$5,ar6_r10!$C$2:$C$999,Veda!K$17,ar6_r10!$M$2:$M$999,Veda!$G19) -> 0.43 | L19: =SUMIFS(ar6_r10!$F$2:$F$999,ar6_r10!$A$2:$A$999,Veda!$E$5,ar6_r10!$C$2:$C$999,Veda!L$17,ar6_r10!$M$2:$M$999,Veda!$G19) -> 0.45 | M19: =SUMIFS(ar6_r10!$F$2:$F$999,ar6_r10!$A$2:$A$999,Veda!$E$5,ar6_r10!$C$2:$C$999,Veda!M$17,ar6_r10!$M$2:$M$999,Veda!$G19) -> 0.43 | N19: =SUMIFS(ar6_r10!$F$2:$F$999,ar6_r10!$A$2:$A$999,Veda!$E$5,ar6_r10!$C$2:$C$999,Veda!N$17,ar6_r10!$M$2:$M$999,Veda!$G19) -> 0.45 | O19: =SUMIFS(ar6_r10!$F$2:$F$999,ar6_r10!$A$2:$A$999,Veda!$E$5,ar6_r10!$C$2:$C$999,Veda!O$17,ar6_r10!$M$2:$M$999,Veda!$G19) -> 0.43 | S19: elc_industry | T19: =I19*T$14 -> 35.1654 | U19: =J19*U$14 -> 40.186692 | V19: =K19*V$14 -> 49.934868 | W19: =L19*W$14 -> 59.98563 | X19: =M19*X$14 -> 70.3308 | Y19: =N19*Y$14 -> 87.21837 | Z19: =O19*Z$14 -> 100.9247 | AA19: demand | AG19: 11 | AH19: s3p3v3_d | AI19: d9d | AJ19: =AJ14+1 -> 3
A20: 5 | B20: =VLOOKUP(E20,$AK$9:$AL$15,2,FALSE)&"."&VLOOKUP(D20,$AH$9:$AI$24,2,FALSE) -> d 1.5 deg OS.j12 | C20: =C19+1 -> 12 | D20: =VLOOKUP(AJ20,$AG$9:$AH$22,2,FALSE) -> ts_012 | E20: =E15 -> C2 | G20: Residential and commercial electricity share | I20: =SUMIFS(ar6_r10!$F$2:$F$999,ar6_r10!$A$2:$A$999,Veda!$E$5,ar6_r10!$C$2:$C$999,Veda!I$17,ar6_r10!$M$2:$M$999,Veda!$G20) -> 0.57 | J20: =SUMIFS(ar6_r10!$F$2:$F$999,ar6_r10!$A$2:$A$999,Veda!$E$5,ar6_r10!$C$2:$C$999,Veda!J$17,ar6_r10!$M$2:$M$999,Veda!$G20) -> 0.57 | K20: =SUMIFS(ar6_r10!$F$2:$F$999,ar6_r10!$A$2:$A$999,Veda!$E$5,ar6_r10!$C$2:$C$999,Veda!K$17,ar6_r10!$M$2:$M$999,Veda!$G20) -> 0.53 | L20: =SUMIFS(ar6_r10!$F$2:$F$999,ar6_r10!$A$2:$A$999,Veda!$E$5,ar6_r10!$C$2:$C$999,Veda!L$17,ar6_r10!$M$2:$M$999,Veda!$G20) -> 0.51 | M20: =SUMIFS(ar6_r10!$F$2:$F$999,ar6_r10!$A$2:$A$999,Veda!$E$5,ar6_r10!$C$2:$C$999,Veda!M$17,ar6_r10!$M$2:$M$999,Veda!$G20) -> 0.5 | N20: =SUMIFS(ar6_r10!$F$2:$F$999,ar6_r10!$A$2:$A$999,Veda!$E$5,ar6_r10!$C$2:$C$999,Veda!N$17,ar6_r10!$M$2:$M$999,Veda!$G20) -> 0.47 | O20: =SUMIFS(ar6_r10!$F$2:$F$999,ar6_r10!$A$2:$A$999,Veda!$E$5,ar6_r10!$C$2:$C$999,Veda!O$17,ar6_r10!$M$2:$M$999,Veda!$G20) -> 0.48 | S20: elc_buildings | T20: =I20*T$14 -> 46.6146 | U20: =J20*U$14 -> 54.539082 | V20: =K20*V$14 -> 61.547628 | W20: =L20*W$14 -> 67.983714 | X20: =M20*X$14 -> 81.78 | Y20: =N20*Y$14 -> 91.094742 | Z20: =O20*Z$14 -> 112.66013 | AA20: demand | AG20: 12 | AH20: s5p5v5_d | AI20: c15d | AJ20: =AJ15+1 -> 3
A21: 5 | B21: =VLOOKUP(E21,$AK$9:$AL$15,2,FALSE)&"."&VLOOKUP(D21,$AH$9:$AI$24,2,FALSE) -> c 2 deg (67%).j12 | C21: =C20+1 -> 13 | D21: =VLOOKUP(AJ21,$AG$9:$AH$22,2,FALSE) -> ts_012 | E21: =E16 -> C3 | G21: Transportation electricity share | I21: =SUMIFS(ar6_r10!$F$2:$F$999,ar6_r10!$A$2:$A$999,Veda!$E$5,ar6_r10!$C$2:$C$999,Veda!I$17,ar6_r10!$M$2:$M$999,Veda!$G21) -> 0.01 | J21: =SUMIFS(ar6_r10!$F$2:$F$999,ar6_r10!$A$2:$A$999,Veda!$E$5,ar6_r10!$C$2:$C$999,Veda!J$17,ar6_r10!$M$2:$M$999,Veda!$G21) -> 0.01 | K21: =SUMIFS(ar6_r10!$F$2:$F$999,ar6_r10!$A$2:$A$999,Veda!$E$5,ar6_r10!$C$2:$C$999,Veda!K$17,ar6_r10!$M$2:$M$999,Veda!$G21) -> 0.02 | L21: =SUMIFS(ar6_r10!$F$2:$F$999,ar6_r10!$A$2:$A$999,Veda!$E$5,ar6_r10!$C$2:$C$999,Veda!L$17,ar6_r10!$M$2:$M$999,Veda!$G21) -> 0.02 | M21: =SUMIFS(ar6_r10!$F$2:$F$999,ar6_r10!$A$2:$A$999,Veda!$E$5,ar6_r10!$C$2:$C$999,Veda!M$17,ar6_r10!$M$2:$M$999,Veda!$G21) -> 0.04 | N21: =SUMIFS(ar6_r10!$F$2:$F$999,ar6_r10!$A$2:$A$999,Veda!$E$5,ar6_r10!$C$2:$C$999,Veda!N$17,ar6_r10!$M$2:$M$999,Veda!$G21) -> 0.05 | O21: =SUMIFS(ar6_r10!$F$2:$F$999,ar6_r10!$A$2:$A$999,Veda!$E$5,ar6_r10!$C$2:$C$999,Veda!O$17,ar6_r10!$M$2:$M$999,Veda!$G21) -> 0.07 | S21: elc_transport | T21: =I21*T$14 -> 0.8178 | U21: =T21 -> 0.8178 | V21: =U21 -> 0.8178 | W21: =V21 -> 0.8178 | X21: =W21 -> 0.8178 | Y21: =X21 -> 0.8178 | Z21: =Y21 -> 0.8178 | AA21: demand | AC21: non-road transport demand assumed to be constant | AG21: 13 | AH21: s2_w | AI21: b2w | AJ21: =AJ16+1 -> 3
A22: 5 | B22: =VLOOKUP(E22,$AK$9:$AL$15,2,FALSE)&"."&VLOOKUP(D22,$AH$9:$AI$24,2,FALSE) -> b 2 deg (50%).j12 | C22: =C21+1 -> 14 | D22: =VLOOKUP(AJ22,$AG$9:$AH$22,2,FALSE) -> ts_012 | E22: =E17 -> C4 | S22: elc_roadtransport | T22: =T14-SUM(T19:T21) -> -0.8178 | U22: =U14-SUM(U19:U21) -> 0.139026 | V22: =V14-SUM(V19:V21) -> 3.827304 | W22: =W14-SUM(W19:W21) -> 4.514256 | X22: =X14-SUM(X19:X21) -> 10.6314 | Y22: =Y14-SUM(Y19:Y21) -> 14.687688 | Z22: =Z14-SUM(Z19:Z21) -> 20.305974 | AA22: demand | AG22: 14 | AH22: s2_w_p2_d | AI22: a2w2d | AJ22: =AJ17+1 -> 3
A23: 5 | B23: =VLOOKUP(E23,$AK$9:$AL$15,2,FALSE)&"."&VLOOKUP(D23,$AH$9:$AI$24,2,FALSE) -> a 3 deg.j12 | C23: =C22+1 -> 15 | D23: =VLOOKUP(AJ23,$AG$9:$AH$22,2,FALSE) -> ts_012 | E23: =E18 -> C7 | S23: * | AJ23: =AJ18+1 -> 3
A24: 5 | B24: =VLOOKUP(E24,$AK$9:$AL$15,2,FALSE)&"."&VLOOKUP(D24,$AH$9:$AI$24,2,FALSE) -> e 1.5 deg no OS.i24 | C24: =C23+1 -> 16 | D24: =VLOOKUP(AJ24,$AG$9:$AH$22,2,FALSE) -> ts_024 | E24: =E19 -> C1 | G24: CO2 price | I24: 0 | J24: 0 | K24: =SUMIFS(ar6_r10!$F$2:$F$999,ar6_r10!$A$2:$A$999,Veda!$E$5,ar6_r10!$C$2:$C$999,Veda!K$17,ar6_r10!$M$2:$M$999,Veda!$G24) -> 61.35 | L24: =SUMIFS(ar6_r10!$F$2:$F$999,ar6_r10!$A$2:$A$999,Veda!$E$5,ar6_r10!$C$2:$C$999,Veda!L$17,ar6_r10!$M$2:$M$999,Veda!$G24) -> 98.16 | M24: =SUMIFS(ar6_r10!$F$2:$F$999,ar6_r10!$A$2:$A$999,Veda!$E$5,ar6_r10!$C$2:$C$999,Veda!M$17,ar6_r10!$M$2:$M$999,Veda!$G24) -> 128.76 | N24: =SUMIFS(ar6_r10!$F$2:$F$999,ar6_r10!$A$2:$A$999,Veda!$E$5,ar6_r10!$C$2:$C$999,Veda!N$17,ar6_r10!$M$2:$M$999,Veda!$G24) -> 172.36 | O24: =SUMIFS(ar6_r10!$F$2:$F$999,ar6_r10!$A$2:$A$999,Veda!$E$5,ar6_r10!$C$2:$C$999,Veda!O$17,ar6_r10!$M$2:$M$999,Veda!$G24) -> 209.45 | S24: co2net | U24: 0 | V24: =K24/1000 -> 0.06135 | W24: =L24/1000 -> 0.09816 | X24: =M24/1000 -> 0.12876 | Y24: =N24/1000 -> 0.17236 | Z24: =O24/1000 -> 0.20945 | AA24: com_taxnet | AJ24: =AJ19+1 -> 4
A25: 5 | B25: =VLOOKUP(E25,$AK$9:$AL$15,2,FALSE)&"."&VLOOKUP(D25,$AH$9:$AI$24,2,FALSE) -> d 1.5 deg OS.i24 | C25: =C24+1 -> 17 | D25: =VLOOKUP(AJ25,$AG$9:$AH$22,2,FALSE) -> ts_024 | E25: =E20 -> C2 | AJ25: =AJ20+1 -> 4
A26: 5 | B26: =VLOOKUP(E26,$AK$9:$AL$15,2,FALSE)&"."&VLOOKUP(D26,$AH$9:$AI$24,2,FALSE) -> c 2 deg (67%).i24 | C26: =C25+1 -> 18 | D26: =VLOOKUP(AJ26,$AG$9:$AH$22,2,FALSE) -> ts_024 | E26: =E21 -> C3 | S26: ~TFM_INS-TS | AJ26: =AJ21+1 -> 4
A27: 5 | B27: =VLOOKUP(E27,$AK$9:$AL$15,2,FALSE)&"."&VLOOKUP(D27,$AH$9:$AI$24,2,FALSE) -> b 2 deg (50%).i24 | C27: =C26+1 -> 19 | D27: =VLOOKUP(AJ27,$AG$9:$AH$22,2,FALSE) -> ts_024 | E27: =E22 -> C4 | S27: process | T27: =T17 -> 2022 | U27: =U17 -> 2025 | V27: =V17 -> 2030 | W27: =W17 -> 2035 | X27: =X17 -> 2040 | Y27: =Y17 -> 2045 | Z27: =Z17 -> 2050 | AA27: attribute | AB27: limtype | AJ27: =AJ22+1 -> 4
A28: 5 | B28: =VLOOKUP(E28,$AK$9:$AL$15,2,FALSE)&"."&VLOOKUP(D28,$AH$9:$AI$24,2,FALSE) -> a 3 deg.i24 | C28: =C27+1 -> 20 | D28: =VLOOKUP(AJ28,$AG$9:$AH$22,2,FALSE) -> ts_024 | E28: =E23 -> C7 | Q28: =SUMIFS(iea_data!G3:G9999,iea_data!$B$3:$B$9999,Veda!$S$11) -> 0 | S28: Trd_electricity import | T28: =Q28 -> 0 | AA28: ACT_BND | AB28: FX | AJ28: =AJ23+1 -> 4
A29: 5 | B29: =VLOOKUP(E29,$AK$9:$AL$15,2,FALSE)&"."&VLOOKUP(D29,$AH$9:$AI$24,2,FALSE) -> e 1.5 deg no OS.h48 | C29: =C28+1 -> 21 | D29: =VLOOKUP(AJ29,$AG$9:$AH$22,2,FALSE) -> ts_048 | E29: =E24 -> C1 | Q29: =SUMIFS(iea_data!H3:H9999,iea_data!$B$3:$B$9999,Veda!$S$11) -> -0.64 | S29: Trd_electricity export | T29: =-1*Q29 -> 0.64 | AA29: ACT_BND | AB29: FX | AJ29: =AJ24+1 -> 5
A30: 5 | B30: =VLOOKUP(E30,$AK$9:$AL$15,2,FALSE)&"."&VLOOKUP(D30,$AH$9:$AI$24,2,FALSE) -> d 1.5 deg OS.h48 | C30: =C29+1 -> 22 | D30: =VLOOKUP(AJ30,$AG$9:$AH$22,2,FALSE) -> ts_048 | E30: =E25 -> C2 | AJ30: =AJ25+1 -> 5
A31: 5 | B31: =VLOOKUP(E31,$AK$9:$AL$15,2,FALSE)&"."&VLOOKUP(D31,$AH$9:$AI$24,2,FALSE) -> c 2 deg (67%).h48 | C31: =C30+1 -> 23 | D31: =VLOOKUP(AJ31,$AG$9:$AH$22,2,FALSE) -> ts_048 | E31: =E26 -> C3 | AJ31: =AJ26+1 -> 5
A32: 5 | B32: =VLOOKUP(E32,$AK$9:$AL$15,2,FALSE)&"."&VLOOKUP(D32,$AH$9:$AI$24,2,FALSE) -> b 2 deg (50%).h48 | C32: =C31+1 -> 24 | D32: =VLOOKUP(AJ32,$AG$9:$AH$22,2,FALSE) -> ts_048 | E32: =E27 -> C4 | AJ32: =AJ27+1 -> 5
A33: 5 | B33: =VLOOKUP(E33,$AK$9:$AL$15,2,FALSE)&"."&VLOOKUP(D33,$AH$9:$AI$24,2,FALSE) -> a 3 deg.h48 | C33: =C32+1 -> 25 | D33: =VLOOKUP(AJ33,$AG$9:$AH$22,2,FALSE) -> ts_048 | E33: =E28 -> C7 | AJ33: =AJ28+1 -> 5
A34: 5 | B34: =VLOOKUP(E34,$AK$9:$AL$15,2,FALSE)&"."&VLOOKUP(D34,$AH$9:$AI$24,2,FALSE) -> e 1.5 deg no OS.g64 | C34: =C33+1 -> 26 | D34: =VLOOKUP(AJ34,$AG$9:$AH$22,2,FALSE) -> ts_064 | E34: =E29 -> C1 | AJ34: =AJ29+1 -> 6
A35: 5 | B35: =VLOOKUP(E35,$AK$9:$AL$15,2,FALSE)&"."&VLOOKUP(D35,$AH$9:$AI$24,2,FALSE) -> d 1.5 deg OS.g64 | C35: =C34+1 -> 27 | D35: =VLOOKUP(AJ35,$AG$9:$AH$22,2,FALSE) -> ts_064 | E35: =E30 -> C2 | AJ35: =AJ30+1 -> 6
A36: 5 | B36: =VLOOKUP(E36,$AK$9:$AL$15,2,FALSE)&"."&VLOOKUP(D36,$AH$9:$AI$24,2,FALSE) -> c 2 deg (67%).g64 | C36: =C35+1 -> 28 | D36: =VLOOKUP(AJ36,$AG$9:$AH$22,2,FALSE) -> ts_064 | E36: =E31 -> C3 | G36: C7 | AJ36: =AJ31+1 -> 6
A37: 5 | B37: =VLOOKUP(E37,$AK$9:$AL$15,2,FALSE)&"."&VLOOKUP(D37,$AH$9:$AI$24,2,FALSE) -> b 2 deg (50%).g64 | C37: =C36+1 -> 29 | D37: =VLOOKUP(AJ37,$AG$9:$AH$22,2,FALSE) -> ts_064 | E37: =E32 -> C4 | G37: Gas Price | I37: =SUMIFS(ar6_r10!$F$2:$F$999,ar6_r10!$A$2:$A$999,Veda!$G$36,ar6_r10!$C$2:$C$999,Veda!I$17,ar6_r10!$M$2:$M$999,Veda!$G37) -> 1 | J37: =SUMIFS(ar6_r10!$F$2:$F$999,ar6_r10!$A$2:$A$999,Veda!$G$36,ar6_r10!$C$2:$C$999,Veda!J$17,ar6_r10!$M$2:$M$999,Veda!$G37) -> 1.03 | K37: =SUMIFS(ar6_r10!$F$2:$F$999,ar6_r10!$A$2:$A$999,Veda!$G$36,ar6_r10!$C$2:$C$999,Veda!K$17,ar6_r10!$M$2:$M$999,Veda!$G37) -> 1.21 | L37: =SUMIFS(ar6_r10!$F$2:$F$999,ar6_r10!$A$2:$A$999,Veda!$G$36,ar6_r10!$C$2:$C$999,Veda!L$17,ar6_r10!$M$2:$M$999,Veda!$G37) -> 1.15 | M37: =SUMIFS(ar6_r10!$F$2:$F$999,ar6_r10!$A$2:$A$999,Veda!$G$36,ar6_r10!$C$2:$C$999,Veda!M$17,ar6_r10!$M$2:$M$999,Veda!$G37) -> 1.28 | N37: =SUMIFS(ar6_r10!$F$2:$F$999,ar6_r10!$A$2:$A$999,Veda!$G$36,ar6_r10!$C$2:$C$999,Veda!N$17,ar6_r10!$M$2:$M$999,Veda!$G37) -> 1.36 | O37: =SUMIFS(ar6_r10!$F$2:$F$999,ar6_r10!$A$2:$A$999,Veda!$G$36,ar6_r10!$C$2:$C$999,Veda!O$17,ar6_r10!$M$2:$M$999,Veda!$G37) -> 1.38 | AJ37: =AJ32+1 -> 6
A38: 5 | B38: =VLOOKUP(E38,$AK$9:$AL$15,2,FALSE)&"."&VLOOKUP(D38,$AH$9:$AI$24,2,FALSE) -> a 3 deg.g64 | C38: =C37+1 -> 30 | D38: =VLOOKUP(AJ38,$AG$9:$AH$22,2,FALSE) -> ts_064 | E38: =E33 -> C7 | G38: Coal Price | I38: =SUMIFS(ar6_r10!$F$2:$F$999,ar6_r10!$A$2:$A$999,Veda!$G$36,ar6_r10!$C$2:$C$999,Veda!I$17,ar6_r10!$M$2:$M$999,Veda!$G38) -> 1 | J38: =SUMIFS(ar6_r10!$F$2:$F$999,ar6_r10!$A$2:$A$999,Veda!$G$36,ar6_r10!$C$2:$C$999,Veda!J$17,ar6_r10!$M$2:$M$999,Veda!$G38) -> 1.03 | K38: =SUMIFS(ar6_r10!$F$2:$F$999,ar6_r10!$A$2:$A$999,Veda!$G$36,ar6_r10!$C$2:$C$999,Veda!K$17,ar6_r10!$M$2:$M$999,Veda!$G38) -> 1.08 | L38: =SUMIFS(ar6_r10!$F$2:$F$999,ar6_r10!$A$2:$A$999,Veda!$G$36,ar6_r10!$C$2:$C$999,Veda!L$17,ar6_r10!$M$2:$M$999,Veda!$G38) -> 1.09 | M38: =SUMIFS(ar6_r10!$F$2:$F$999,ar6_r10!$A$2:$A$999,Veda!$G$36,ar6_r10!$C$2:$C$999,Veda!M$17,ar6_r10!$M$2:$M$999,Veda!$G38) -> 1.1 | N38: =SUMIFS(ar6_r10!$F$2:$F$999,ar6_r10!$A$2:$A$999,Veda!$G$36,ar6_r10!$C$2:$C$999,Veda!N$17,ar6_r10!$M$2:$M$999,Veda!$G38) -> 1.12 | O38: =SUMIFS(ar6_r10!$F$2:$F$999,ar6_r10!$A$2:$A$999,Veda!$G$36,ar6_r10!$C$2:$C$999,Veda!O$17,ar6_r10!$M$2:$M$999,Veda!$G38) -> 1.14 | AJ38: =AJ33+1 -> 6
A39: 5 | B39: =VLOOKUP(E39,$AK$9:$AL$15,2,FALSE)&"."&VLOOKUP(D39,$AH$9:$AI$24,2,FALSE) -> e 1.5 deg no OS.f96p50 | C39: =C38+1 -> 31 | D39: =VLOOKUP(AJ39,$AG$9:$AH$22,2,FALSE) -> ts_096P50 | E39: =E34 -> C1 | G39: Oil Price | I39: =SUMIFS(ar6_r10!$F$2:$F$999,ar6_r10!$A$2:$A$999,Veda!$G$36,ar6_r10!$C$2:$C$999,Veda!I$17,ar6_r10!$M$2:$M$999,Veda!$G39) -> 1 | J39: =SUMIFS(ar6_r10!$F$2:$F$999,ar6_r10!$A$2:$A$999,Veda!$G$36,ar6_r10!$C$2:$C$999,Veda!J$17,ar6_r10!$M$2:$M$999,Veda!$G39) -> 1.05 | K39: =SUMIFS(ar6_r10!$F$2:$F$999,ar6_r10!$A$2:$A$999,Veda!$G$36,ar6_r10!$C$2:$C$999,Veda!K$17,ar6_r10!$M$2:$M$999,Veda!$G39) -> 1.25 | L39: =SUMIFS(ar6_r10!$F$2:$F$999,ar6_r10!$A$2:$A$999,Veda!$G$36,ar6_r10!$C$2:$C$999,Veda!L$17,ar6_r10!$M$2:$M$999,Veda!$G39) -> 1.18 | M39: =SUMIFS(ar6_r10!$F$2:$F$999,ar6_r10!$A$2:$A$999,Veda!$G$36,ar6_r10!$C$2:$C$999,Veda!M$17,ar6_r10!$M$2:$M$999,Veda!$G39) -> 1.3 | N39: =SUMIFS(ar6_r10!$F$2:$F$999,ar6_r10!$A$2:$A$999,Veda!$G$36,ar6_r10!$C$2:$C$999,Veda!N$17,ar6_r10!$M$2:$M$999,Veda!$G39) -> 1.4 | O39: =SUMIFS(ar6_r10!$F$2:$F$999,ar6_r10!$A$2:$A$999,Veda!$G$36,ar6_r10!$C$2:$C$999,Veda!O$17,ar6_r10!$M$2:$M$999,Veda!$G39) -> 1.5 | AJ39: =AJ34+1 -> 7
A40: 5 | B40: =VLOOKUP(E40,$AK$9:$AL$15,2,FALSE)&"."&VLOOKUP(D40,$AH$9:$AI$24,2,FALSE) -> d 1.5 deg OS.f96p50 | C40: =C39+1 -> 32 | D40: =VLOOKUP(AJ40,$AG$9:$AH$22,2,FALSE) -> ts_096P50 | E40: =E35 -> C2 | G40: Biomass Price | I40: =SUMIFS(ar6_r10!$F$2:$F$999,ar6_r10!$A$2:$A$999,Veda!$G$36,ar6_r10!$C$2:$C$999,Veda!I$17,ar6_r10!$M$2:$M$999,Veda!$G40) -> 1 | J40: =SUMIFS(ar6_r10!$F$2:$F$999,ar6_r10!$A$2:$A$999,Veda!$G$36,ar6_r10!$C$2:$C$999,Veda!J$17,ar6_r10!$M$2:$M$999,Veda!$G40) -> 1.03 | K40: =SUMIFS(ar6_r10!$F$2:$F$999,ar6_r10!$A$2:$A$999,Veda!$G$36,ar6_r10!$C$2:$C$999,Veda!K$17,ar6_r10!$M$2:$M$999,Veda!$G40) -> 1.01 | L40: =SUMIFS(ar6_r10!$F$2:$F$999,ar6_r10!$A$2:$A$999,Veda!$G$36,ar6_r10!$C$2:$C$999,Veda!L$17,ar6_r10!$M$2:$M$999,Veda!$G40) -> 0.93 | M40: =SUMIFS(ar6_r10!$F$2:$F$999,ar6_r10!$A$2:$A$999,Veda!$G$36,ar6_r10!$C$2:$C$999,Veda!M$17,ar6_r10!$M$2:$M$999,Veda!$G40) -> 0.94 | N40: =SUMIFS(ar6_r10!$F$2:$F$999,ar6_r10!$A$2:$A$999,Veda!$G$36,ar6_r10!$C$2:$C$999,Veda!N$17,ar6_r10!$M$2:$M$999,Veda!$G40) -> 0.92 | O40: =SUMIFS(ar6_r10!$F$2:$F$999,ar6_r10!$A$2:$A$999,Veda!$G$36,ar6_r10!$C$2:$C$999,Veda!O$17,ar6_r10!$M$2:$M$999,Veda!$G40) -> 0.87 | AJ40: =AJ35+1 -> 7
A41: 5 | B41: =VLOOKUP(E41,$AK$9:$AL$15,2,FALSE)&"."&VLOOKUP(D41,$AH$9:$AI$24,2,FALSE) -> c 2 deg (67%).f96p50 | C41: =C40+1 -> 33 | D41: =VLOOKUP(AJ41,$AG$9:$AH$22,2,FALSE) -> ts_096P50 | E41: =E36 -> C3 | AJ41: =AJ36+1 -> 7
A42: 5 | B42: =VLOOKUP(E42,$AK$9:$AL$15,2,FALSE)&"."&VLOOKUP(D42,$AH$9:$AI$24,2,FALSE) -> b 2 deg (50%).f96p50 | C42: =C41+1 -> 34 | D42: =VLOOKUP(AJ42,$AG$9:$AH$22,2,FALSE) -> ts_096P50 | E42: =E37 -> C4 | AJ42: =AJ37+1 -> 7
...

Sheet fuel_prices
A9: Fuel Prices
A10: iso | B10: gas_low | C10: gas_high | D10: coal_low | E10: coal_high | F10: oil_low | G10: oil_high | H10: bioenergy_low | I10: bioenergy_high | J10: Notes
A11: VEN | B11: 5.1 | C11: 10.3 | D11: 10.7 | E11: 13.7 | F11: 35 | G11: 45 | H11: 14 | I11: 22 | J11: Oil/gas reserves, limited biomass use

Sheet iea_data
A9: IEA Baseline Data
A10: iso | B10: year | C10: industry_twh | D10: buildings_agri_twh | E10: nonroad_transport_twh | F10: road_transport_twh | G10: imports_twh | H10: exports_twh | I10: total_production_twh
A11: VEN | B11: 2000 | C11: 51.18 | D11: 32.88 | E11: 0.25 | F11: 0 | G11: 0.01 | H11: -0.06 | I11: 85.27
A12: VEN | B12: 2001 | C12: 54.88 | D12: 34.54 | E12: 0.25 | F12: 0 | G12: 0.18 | H12: -0.21 | I12: 90.12
A13: VEN | B13: 2002 | C13: 55.98 | D13: 34.65 | E13: 0.24 | F13: 0 | G13: 0.56 | H13: -0.42 | I13: 91.85
A14: VEN | B14: 2003 | C14: 56.56 | D14: 34.33 | E14: 0.2 | F14: 0 | G14: 0.04 | H14: -0.45 | I14: 91.94
A15: VEN | B15: 2004 | C15: 62.59 | D15: 36.25 | E15: 0.24 | F15: 0 | G15: 0.87 | H15: -0.48 | I15: 98.55
A16: VEN | B16: 2005 | C16: 66.24 | D16: 36.4 | E16: 0.26 | F16: 0 | G16: 0 | H16: -0.58 | I16: 105.38
A17: VEN | B17: 2006 | C17: 67.94 | D17: 39.77 | E17: 0.26 | F17: 0 | G17: 0 | H17: -0.55 | I17: 110.42
A18: VEN | B18: 2007 | C18: 68.02 | D18: 42.58 | E18: 0.29 | F18: 0 | G18: 0 | H18: -0.54 | I18: 114.21
A19: VEN | B19: 2008 | C19: 70.07 | D19: 43.22 | E19: 0.28 | F19: 0 | G19: 0.1 | H19: -0.57 | I19: 119.3
A20: VEN | B20: 2009 | C20: 71.26 | D20: 44.92 | E20: 0.29 | F20: 0 | G20: 0.26 | H20: -0.63 | I20: 119.58
A21: VEN | B21: 2010 | C21: 62.67 | D21: 44.55 | E21: 0.28 | F21: 0 | G21: 0 | H21: -0.46 | I21: 113.77
A22: VEN | B22: 2011 | C22: 65.22 | D22: 46.49 | E22: 0.29 | F22: 0 | G22: 0.24 | H22: -0.73 | I22: 117.96
... A33: VEN | B33: 2022 | C33: 43.44 | D33: 30.78 | E33: 0.16 | F33: 0 | G33: 0 | H33: -0.64 | I33: 82.42

Sheet ar6_r10
A9: AR6 Scenario Drivers
A10: Category | B10: Region | C10: Year | D10: count | E10: mean | F10: median | G10: std | H10: min | I10: max | J10: q25 | K10: q75 | L10: category_description | M10: attribute
A11: C1 | B11: R10LATIN_AM | C11: 2020 | D11: 60 | E11: 5.67 | F11: 0.55 | G11: 7.11 | H11: 0 | I11: 17.35 | J11: 0 | K11: 13.55 | L11: Limit warming to 1.5°C (>50%) with no or limited overshoot | M11: CO2 price
A12: C1 | B12: R10LATIN_AM | C12: 2025 | D12: 60 | E12: 165.38 | F12: 153.36 | G12: 124.95 | H12: 1.73 | I12: 626.48 | J12: 108.64 | K12: 200.87 | L12: Limit warming to 1.5°C (>50%) with no or limited overshoot | M12: CO2 price
A13: C1 | B13: R10LATIN_AM | C13: 2030 | D13: 60 | E13: 234.48 | F13: 220.73 | G13: 112.04 | H13: 21.58 | I13: 673.46 | J13: 173.6 | K13: 252.97 | L13: Limit warming to 1.5°C (>50%) with no or limited overshoot | M13: CO2 price
A14: C1 | B14: R10LATIN_AM | C14: 2035 | D14: 60 | E14: 322.99 | F14: 286.86 | G14: 152.29 | H14: 0 | I14: 859.53 | J14: 236.35 | K14: 439.44 | L14: Limit warming to 1.5°C (>50%) with no or limited overshoot | M14: CO2 price
A15: C1 | B15: R10LATIN_AM | C15: 2040 | D15: 60 | E15: 431.53 | F15: 360.55 | G15: 207.19 | H15: 162.1 | I15: 1097.01 | J15: 289.44 | K15: 573.35 | L15: Limit warming to 1.5°C (>50%) with no or limited overshoot | M15: CO2 price
A16: C1 | B16: R10LATIN_AM | C16: 2045 | D16: 60 | E16: 534.47 | F16: 471.06 | G16: 243.62 | H16: 193.42 | I16: 1269.88 | J16: 352.78 | K16: 713.93 | L16: Limit warming to 1.5°C (>50%) with no or limited overshoot | M16: CO2 price
A17: C1 | B17: R10LATIN_AM | C17: 2050 | D17: 60 | E17: 624.12 | F17: 581.75 | G17: 257.63 | H17: 209.76 | I17: 1170.26 | J17: 409.79 | K17: 771.78 | L17: Limit warming to 1.5°C (>50%) with no or limited overshoot | M17: CO2 price
A18: C2 | B18: R10LATIN_AM | C18: 2020 | D18: 86 | E18: 2.57 | F18: 0 | G18: 5.21 | H18: 0 | I18: 17.25 | J18: 0 | K18: 0.95 | L18: Limit warming to 1.5°C (>67%) with high overshoot | M18: CO2 price
A19: C2 | B19: R10LATIN_AM | C19: 2025 | D19: 75 | E19: 47.44 | F19: 28.56 | G19: 42.96 | H19: 0 | I19: 174.97 | J19: 22.45 | K19: 61.4 | L19: Limit warming to 1.5°C (>67%) with high overshoot | M19: CO2 price
A20: C2 | B20: R10LATIN_AM | C20: 2030 | D20: 86 | E20: 66.05 | F20: 57.59 | G20: 49.35 | H20: 0 | I20: 221.93 | J20: 28.65 | K20: 83.92 | L20: Limit warming to 1.5°C (>67%) with high overshoot | M20: CO2 price
A21: C2 | B21: R10LATIN_AM | C21: 2035 | D21: 75 | E21: 198.06 | F21: 135.74 | G21: 296.93 | H21: -204.26 | I21: 2037.12 | J21: 87.23 | K21: 201.85 | L21: Limit warming to 1.5°C (>67%) with high overshoot | M21: CO2 price
A22: C2 | B22: R10LATIN_AM | C22: 2040 | D22: 86 | E22: 249.05 | F22: 169.66 | G22: 359.66 | H22: 0 | I22: 2600 | J22: 111.56 | K22: 257.75 | L22: Limit warming to 1.5°C (>67%) with high overshoot | M22: CO2 price
... A221: C1 | B221: R10LATIN_AM | C221: 2020 | D221: 35 | E221: 1 | F221: 1 | G221: 0 | H221: 1 | I221: 1 | J221: 1 | K221: 1 | L221: Limit warming to 1.5°C (>50%) with no or limited overshoot | M221: Gas price
A222: C1 | B222: R10LATIN_AM | C222: 2025 | D222: 37 | E222: 65535 | F222: 1.93 | H222: 1.26 | I222: 65535 | J222: 1.7 | K222: 2.38 | L222: Limit warming to 1.5°C (>50%) with no or limited overshoot | M222: Gas price
A223: C1 | B223: R10LATIN_AM | C223: 2030 | D223: 37 | E223: 65535 | F223: 2.65 | H223: 1.63 | I223: 65535 | J223: 2.34 | K223: 3.32 | L223: Limit warming to 1.5°C (>50%) with no or limited overshoot | M223: Gas price
A224: C1 | B224: R10LATIN_AM | C224: 2035 | D224: 37 | E224: 65535 | F224: 3.13 | H224: 1.95 | I224: 65535 | J224: 2.48 | K224: 4.02 | L224: Limit warming to 1.5°C (>50%) with no or limited overshoot | M224: Gas price
A225: C1 | B225: R10LATIN_AM | C225: 2040 | D225: 37 | E225: 65535 | F225: 3.66 | H225: 2.43 | I225: 65535 | J225: 2.98 | K225: 4.33 | L225: Limit warming to 1.5°C (>50%) with no or limited overshoot | M225: Gas price
A226: C1 | B226: R10LATIN_AM | C226: 2045 | D226: 37 | E226: 65535 | F226: 3.74 | H226: 2.45 | I226: 65535 | J226: 3.23 | K226: 4.96 | L226: Limit warming to 1.5°C (>50%) with no or limited overshoot | M226: Gas price
A227: C1 | B227: R10LATIN_AM | C227: 2050 | D227: 37 | E227: 65535 | F227: 3.74 | H227: 2.21 | I227: 65535 | J227: 3.22 | K227: 4.2 | L227: Limit warming to 1.5°C (>50%) with no or limited overshoot | M227: Gas price
A228: C2 | B228: R10LATIN_AM | C228: 2020 | D228: 43 | E228: 1 | F228: 1 | G228: 0 | H228: 1 | I228: 1 | J228: 1 | K228: 1 | L228: Limit warming to 1.5°C (>67%) with high overshoot | M228: Gas price
A229: C2 | B229: R10LATIN_AM | C229: 2025 | D229: 43 | E229: 1.25 | F229: 1.17 | G229: 0.19 | H229: 1.04 | I229: 1.83 | J229: 1.13 | K229: 1.28 | L229: Limit warming to 1.5°C (>67%) with high overshoot | M229: Gas price
A230: C2 | B230: R10LATIN_AM | C230: 2030 | D230: 43 | E230: 1.59 | F230: 1.56 | G230: 0.32 | H230: 1.05 | I230: 2.39 | J230: 1.34 | K230: 1.77 | L230: Limit warming to 1.5°C (>67%) with high overshoot | M230: Gas price
A231: C2 | B231: R10LATIN_AM | C231: 2035 | D231: 43 | E231: 2.72 | F231: 2.15 | G231: 2.08 | H231: 1.05 | I231: 10.54 | J231: 1.84 | K231: 2.47 | L231: Limit warming to 1.5°C (>67%) with high overshoot | M231: Gas price
A232: C2 | B232: R10LATIN_AM | C232: 2040 | D232: 43 | E232: 3.74 | F232: 2.7 | G232: 3.88 | H232: 1.04 | I232: 18.89 | J232: 2.05 | K232: 3.02 | L232: Limit warming to 1.5°C (>67%) with high overshoot | M232: Gas price
A233: C2 | B233: R10LATIN_AM | C233: 2045 | D233: 43 | E233: 3.42 | F233: 2.8 | G233: 1.73 | H233: 1.1 | I233: 10.94 | J233: 2.56 | K233: 3.85 | L233: Limit warming to 1.5°C (>67%) with high overshoot | M233: Gas price
A234: C2 | B234: R10LATIN_AM | C234: 2050 | D234: 43 | E234: 3.32 | F234: 2.92 | G234: 1.23 | H234: 1.2 | I234: 8.44 | J234: 2.7 | K234: 3.67 | L234: Limit warming to 1.5°C (>67%) with high overshoot | M234: Gas price
A235: C3 | B235: R10LATIN_AM | C235: 2020 | D235: 113 | E235: 1 | F235: 1 | G235: 0 | H235: 1 | I235: 1 | J235: 1 | K235: 1 | L235: Limit warming to 2°C (>67%) with higher action post-2030 | M235: Gas price
A236: C3 | B236: R10LATIN_AM | C236: 2025 | D236: 113 | E236: 1.38 | F236: 1.33 | G236: 0.3 | H236: 1.02 | I236: 2.65 | J236: 1.2 | K236: 1.41 | L236: Limit warming to 2°C (>67%) with higher action post-2030 | M236: Gas price
A237: C3 | B237: R10LATIN_AM | C237: 2030 | D237: 113 | E237: 1.78 | F237: 1.71 | G237: 0.49 | H237: 1.05 | I237: 3.7 | J237: 1.44 | K237: 2.04 | L237: Limit warming to 2°C (>67%) with higher action post-2030 | M237: Gas price
A238: C3 | B238: R10LATIN_AM | C238: 2035 | D238: 113 | E238: 2.22 | F238: 1.89 | G238: 0.9 | H238: 1.05 | I238: 7.88 | J238: 1.64 | K238: 2.71 | L238: Limit warming to 2°C (>67%) with higher action post-2030 | M238: Gas price
A239: C3 | B239: R10LATIN_AM | C239: 2040 | D239: 113 | E239: 2.73 | F239: 2.4 | G239: 1.19 | H239: 1.06 | I239: 8.68 | J239: 1.86 | K239: 3.31 | L239: Limit warming to 2°C (>67%) with higher action post-2030 | M239: Gas price
... A360: C7 | B360: R10LATIN_AM | C360: 2050 | D360: 10 | E360: 0.96 | F360: 0.87 | G360: 0.2 | H360: 0.76 | I360: 1.36 | J360: 0.79 | K360: 1.07 | L360: Likely above 3°C warming with limited mitigation | M360: Biomass price

Sheet ev_charging_uc
A10: =IFERROR(Veda!D5,"ts_12t") -> ts_annual | C10: day_night | D10: ts_012 | F10: day_night | G10: ts_048 | I10: day_night | J10: ts_annual | L10: day_night | M10: ts_12t
C11: D | D11: S03aH02,S02aH02,S04aH02,S01aH02 | F11: D | G11: S01aH03,S05aH02,S05aH03,S08aH02,S05aH04,S06aH02,S06aH03,S02aH04,S02aH05,S04aH02,S01aH02,S04aH04,S03aH04,S08aH05,S03aH02,S07aH05,S02aH03,S07aH03,S01aH05,S06aH05,S01aH04,S07aH02,S04aH05,S03aH03,S03aH05,S05aH05,S06aH04,S08aH04,S02aH02,S04aH03,S07aH04,S08aH03 | I11: D | J11: AllSaAllH | L11: D | M11: RaP,WaP,SaD,FaD,WaD,FaP,SaP,RaD
C12: N | D12: S02aH03,S01aH03,S02aH01,S03aH01,S03aH03,S01aH01,S04aH01,S04aH03 | F12: N | G12: S06aH01,S01aH06,S07aH01,S08aH06,S02aH06,S03aH06,S05aH01,S07aH06,S01aH01,S04aH01,S04aH06,S08aH01,S06aH06,S03aH01,S02aH01,S05aH06 | I12: N | J12: AllSaAllH | L12: N | M12: WaP,RaN,FaP,SaP,RaP,SaN,WaN,FaN
I17: 0.75 | K17: share of charging at night
C18: ~UC_Sets: R_E: AllRegions
H21: =IF(H23=H24,"Not Required!","~UC_T: LO") -> Not Required!
C22: UC_N | D22: Pset_CI | E22: Pset_CO | F22: pset_pn | G22: Cset_CN | H22: TimeSlice | I22: UC_FLO | J22: UC_RHSRT | K22: UC_RHSRT~0
C23: UC_bev night chg limit | D23: ELC | E23: =G23 -> AuxStoIN | F23: *EV* | G23: AuxStoIN | H23: =HLOOKUP($A$10,$D$10:$CU$12,3,FALSE) -> AllSaAllH | I23: =1+I24 -> 0.25 | J23: 0 | K23: 3 | M23: night
D24: ELC | E24: =G24 -> AuxStoIN | F24: *EV* | G24: AuxStoIN | H24: =HLOOKUP($A$10,$D$10:$CU$12,2,FALSE) -> AllSaAllH | I24: =-$I$17 -> -0.75 | M24: day

Sheet ts_012
C9: =IF(A11="x","DeActivated","~TimeSlices") -> DeActivated | I9: =IF(A11="x","DeActivated","~TFM_DINS-AT") -> DeActivated | N9: =IF(A11="x","DeActivated","~TFM_DINS-AT") -> DeActivated | S9: =IF(A11="x","DeActivated","~TFM_DINS-AT") -> DeActivated | X9: =IF(A11="x","DeActivated","~TFM_DINS-AT") -> DeActivated | AC9: =IF(A11="x","DeActivated","~TFM_DINS-AT") -> DeActivated | AG9: =IF(A11="x","DeActivated","~TFM_DINS-AT") -> DeActivated | AK9: =IF(A11="x","DeActivated","~TFM_INS-AT") -> DeActivated
A10: ts_012 | C10: season | D10: weekly | E10: daynite | F10: wparent | G10: dparent | I10: commodity | J10: timeslice | K10: com_fr | L10: process | N10: commodity | O10: timeslice | P10: com_fr | Q10: process | S10: commodity | T10: timeslice | U10: com_fr | V10: process | X10: g_yrfr | Y10: com_fr | Z10: timeslice | AA10: commodity | AC10: commodity | AD10: timeslice | AE10: com_fr | AG10: commodity | AH10: timeslice | AI10: com_pkflx | AK10: Year | AL10: timeslice | AM10: ncap_afs | AN10: pset_ci
A11: =IFERROR(IF(Veda!D5=A10,"ok","x"),"") -> x | C11: S01 | D11: a | E11: H01 | F11: S01,S02,S03,S04 | G11: a | I11: elc_spv_001 | J11: S01aH01 | K11: 0.024357216 | L11: IMPNRGZ | N11: elc_won_001 | O11: S01aH01 | P11: 0.23316484 | Q11: IMPNRGZ | S11: elc_wof_001 | T11: S01aH01 | U11: 0.072747674 | V11: IMPNRGZ | X11: 0.067351598 | Y11: 0.046996992 | Z11: S01aH01 | AA11: elc_roadtransport | AC11: elc_buildings | AD11: S01aH01 | AE11: 0.05742054 | AG11: ELC | AH11: S01aH01 | AI11: 0.20529178 | AK11: 2025 | AL11: S01 | AM11: 0.3766 | AN11: hydro
C12: S02 | E12: H02 | G12: a | I12: elc_spv_001 | J12: S01aH02 | K12: 0.13843284 | L12: IMPNRGZ | N12: elc_won_001 | O12: S01aH02 | P12: 0.1445897 | Q12: IMPNRGZ | S12: elc_wof_001 | T12: S01aH02 | U12: 0.062156649 | V12: IMPNRGZ | X12: 0.053881279 | Y12: 0.079051952 | Z12: S01aH02 | AA12: elc_roadtransport | AC12: elc_buildings | AD12: S01aH02 | AE12: 0.047677271 | AG12: ELC | AH12: S01aH02 | AI12: 0.14839769 | AK12: 2025 | AL12: S02 | AM12: 0.31056667 | AN12: hydro
C13: S03 | E13: H03 | G13: a | I13: elc_spv_001 | J13: S01aH03 | K13: 0.0091490199 | L13: IMPNRGZ | N13: elc_won_001 | O13: S01aH03 | P13: 0.08968593 | Q13: IMPNRGZ | S13: elc_wof_001 | T13: S01aH03 | U13: 0.049717287 | V13: IMPNRGZ | X13: 0.040410959 | Y13: 0.035594892 | Z13: S01aH03 | AA13: elc_roadtransport | AC13: elc_buildings | AD13: S01aH03 | AE13: 0.037570869 | AG13: ELC | AH13: S01aH03 | AI13: 0.13828823 | AK13: 2025 | AL13: S03 | AM13: 0.31893333 | AN13: hydro
C14: S04 | I14: elc_spv_001 | J14: S02aH01 | K14: 0.042698711 | L14: IMPNRGZ | N14: elc_won_001 | O14: S02aH01 | P14: 0.037157215 | Q14: IMPNRGZ | S14: elc_wof_001 | T14: S02aH01 | U14: 0.10656041 | V14: IMPNRGZ | X14: 0.10502283 | Y14: 0.073283445 | Z14: S02aH01 | AA14: elc_roadtransport | AC14: elc_buildings | AD14: S02aH01 | AE14: 0.098389354 | AG14: ELC | AH14: S02aH01 | AI14: 0.24392052 | AK14: 2025 | AL14: S04 | AM14: 0.3453 | AN14: hydro
I15: elc_spv_001 | J15: S02aH02 | K15: 0.19898295 | L15: IMPNRGZ | N15: elc_won_001 | O15: S02aH02 | P15: 0.016040733 | Q15: IMPNRGZ | S15: elc_wof_001 | T15: S02aH02 | U15: 0.089547318 | V15: IMPNRGZ | X15: 0.084018265 | Y15: 0.12326745 | Z15: S02aH02 | AA15: elc_roadtransport | AC15: elc_buildings | AD15: S02aH02 | AE15: 0.083316202 | AG15: ELC | AH15: S02aH02 | AI15: 0.27400378 | AK15: 2026 | AL15: S01 | AM15: 0.40475 | AN15: hydro
I16: elc_spv_001 | J16: S02aH03 | K16: 0.009518131 | L16: IMPNRGZ | N16: elc_won_001 | O16: S02aH03 | P16: 0.028161513 | Q16: IMPNRGZ | S16: elc_wof_001 | T16: S02aH03 | U16: 0.072604059 | V16: IMPNRGZ | X16: 0.063013699 | Y16: 0.055503899 | Z16: S02aH03 | AA16: elc_roadtransport | AC16: elc_buildings | AD16: S02aH03 | AE16: 0.069324353 | AG16: ELC | AH16: S02aH03 | AI16: 0.20107454 | AK16: 2026 | AL16: S02 | AM16: 0.32743333 | AN16: hydro
I17: elc_spv_001 | J17: S03aH01 | K17: 0.082220009 | L17: IMPNRGZ | N17: elc_won_001 | O17: S03aH01 | P17: 0.10361223 | Q17: IMPNRGZ | S17: elc_wof_001 | T17: S03aH01 | U17: 0.18636946 | V17: IMPNRGZ | X17: 0.20890411 | Y17: 0.14577033 | Z17: S03aH01 | AA17: elc_roadtransport | AC17: elc_buildings | AD17: S03aH01 | AE17: 0.20614562 | AG17: ELC | AH17: S03aH01 | AI17: 0.23725338 | AK17: 2026 | AL17: S03 | AM17: 0.32223333 | AN17: hydro
I18: elc_spv_001 | J18: S03aH02 | K18: 0.39387057 | L18: IMPNRGZ | N18: elc_won_001 | O18: S03aH02 | P18: 0.058489084 | Q18: IMPNRGZ | S18: elc_wof_001 | T18: S03aH02 | U18: 0.14901369 | V18: IMPNRGZ | X18: 0.16712329 | Y18: 0.24519504 | Z18: S03aH02 | AA18: elc_roadtransport | AC18: elc_buildings | AD18: S03aH02 | AE18: 0.17591403 | AG18: ELC | AH18: S03aH02 | AI18: 0.25018954 | AK18: 2026 | AL18: S04 | AM18: 0.3731 | AN18: hydro
I19: elc_spv_001 | J19: S03aH03 | K19: 0.017458887 | L19: IMPNRGZ | N19: elc_won_001 | O19: S03aH03 | P19: 0.043974194 | Q19: IMPNRGZ | S19: elc_wof_001 | T19: S03aH03 | U19: 0.1273791 | V19: IMPNRGZ | X19: 0.12534247 | Y19: 0.11040449 | Z19: S03aH03 | AA19: elc_roadtransport | AC19: elc_buildings | AD19: S03aH03 | AE19: 0.14952849 | AG19: ELC | AH19: S03aH03 | AI19: 0.14740177 | AK19: 2027 | AL19: S01 | AM19: 0.3983 | AN19: hydro
I20: elc_spv_001 | J20: S04aH01 | K20: 0.013599298 | L20: IMPNRGZ | N20: elc_won_001 | O20: S04aH01 | P20: 0.11852796 | Q20: IMPNRGZ | S20: elc_wof_001 | T20: S04aH01 | U20: 0.032706514 | V20: IMPNRGZ | X20: 0.035388128 | Y20: 0.024693335 | Z20: S04aH01 | AA20: elc_roadtransport | AC20: elc_buildings | AD20: S04aH01 | AE20: 0.030028692 | AG20: ELC | AH20: S04aH01 | AI20: 0.20500542 | AK20: 2027 | AL20: S02 | AM20: 0.29833333 | AN20: hydro
I21: elc_spv_001 | J21: S04aH02 | K21: 0.065773791 | L21: IMPNRGZ | N21: elc_won_001 | O21: S04aH02 | P21: 0.07983088 | Q21: IMPNRGZ | S21: elc_wof_001 | T21: S04aH02 | U21: 0.02796684 | V21: IMPNRGZ | X21: 0.028310502 | Y21: 0.041535771 | Z21: S04aH02 | AA21: elc_roadtransport | AC21: elc_buildings | AD21: S04aH02 | AE21: 0.024935203 | AG21: ELC | AH21: S04aH02 | AI21: 0.14997272 | AK21: 2027 | AL21: S03 | AM21: 0.3083 | AN21: hydro
I22: elc_spv_001 | J22: S04aH03 | K22: 0.0039385718 | L22: IMPNRGZ | N22: elc_won_001 | O22: S04aH03 | P22: 0.046765715 | Q22: IMPNRGZ | S22: elc_wof_001 | T22: S04aH03 | U22: 0.023230995 | V22: IMPNRGZ | X22: 0.021232877 | Y22: 0.018702401 | Z22: S04aH03 | AA22: elc_roadtransport | AC22: elc_buildings | AD22: S04aH03 | AE22: 0.019749378 | AG22: ELC | AH22: S04aH03 | AI22: 0.1343314 | AK22: 2027 | AL22: S04 | AM22: 0.3556 | AN22: hydro
I23: elc_spv_002 | J23: S01aH01 | K23: 0.024313103 | L23: IMPNRGZ | N23: elc_won_002 | O23: S01aH01 | P23: 0.2355826 | Q23: IMPNRGZ | S23: elc_wof_002 | T23: S01aH01 | U23: 0.059417292 | V23: IMPNRGZ | AC23: elc_industry | AD23: S01aH01 | AE23: 0.067168532 | AK23: 2028 | AL23: S01 | AM23: 0.42925 | AN23: hydro
I24: elc_spv_002 | J24: S01aH02 | K24: 0.12871792 | L24: IMPNRGZ | N24: elc_won_002 | O24: S01aH02 | P24: 0.13834514 | Q24: IMPNRGZ | S24: elc_wof_002 | T24: S01aH02 | U24: 0.090288361 | V24: IMPNRGZ | AC24: elc_industry | AD24: S01aH02 | AE24: 0.053849087 | AK24: 2028 | AL24: S02 | AM24: 0.3661 | AN24: hydro
I25: elc_spv_002 | J25: S01aH03 | K25: 0.0079708021 | L25: IMPNRGZ | N25: elc_won_002 | O25: S01aH03 | P25: 0.080241419 | Q25: IMPNRGZ | S25: elc_wof_002 | T25: S01aH03 | U25: 0.058292999 | V25: IMPNRGZ | AC25: elc_industry | AD25: S01aH03 | AE25: 0.040505809 | AK25: 2028 | AL25: S03 | AM25: 0.36876667 | AN25: hydro
I26: elc_spv_002 | J26: S02aH01 | K26: 0.038963415 | L26: IMPNRGZ | N26: elc_won_002 | O26: S02aH01 | P26: 0.068384983 | Q26: IMPNRGZ | S26: elc_wof_002 | T26: S02aH01 | U26: 0.086727458 | V26: IMPNRGZ | AC26: elc_industry | AD26: S02aH01 | AE26: 0.10461275 | AK26: 2028 | AL26: S04 | AM26: 0.4614 | AN26: hydro
I27: elc_spv_002 | J27: S02aH02 | K27: 0.19350473 | L27: IMPNRGZ | N27: elc_won_002 | O27: S02aH02 | P27: 0.026794345 | Q27: IMPNRGZ | S27: elc_wof_002 | T27: S02aH02 | U27: 0.1152708 | V27: IMPNRGZ | AC27: elc_industry | AD27: S02aH02 | AE27: 0.083992439 | AK27: 2029 | AL27: S01 | AM27: 0.42055 | AN27: hydro
I28: elc_spv_002 | J28: S02aH03 | K28: 0.0099635924 | L28: IMPNRGZ | N28: elc_won_002 | O28: S02aH03 | P28: 0.035674325 | Q28: IMPNRGZ | S28: elc_wof_002 | T28: S02aH03 | U28: 0.080812496 | V28: IMPNRGZ | AC28: elc_industry | AD28: S02aH03 | AE28: 0.063443098 | AK28: 2029 | AL28: S02 | AM28: 0.3669 | AN28: hydro
I29: elc_spv_002 | J29: S03aH01 | K29: 0.095750646 | L29: IMPNRGZ | N29: elc_won_002 | O29: S03aH01 | P29: 0.10343798 | Q29: IMPNRGZ | S29: elc_wof_002 | T29: S03aH01 | U29: 0.1203907 | V29: IMPNRGZ | AC29: elc_industry | AD29: S03aH01 | AE29: 0.20797653 | AK29: 2029 | AL29: S03 | AM29: 0.38345 | AN29: hydro
I30: elc_spv_002 | J30: S03aH02 | K30: 0.40476141 | L30: IMPNRGZ | N30: elc_won_002 | O30: S03aH02 | P30: 0.052778895 | Q30: IMPNRGZ | S30: elc_wof_002 | T30: S03aH02 | U30: 0.18046963 | V30: IMPNRGZ | AC30: elc_industry | AD30: S03aH02 | AE30: 0.16710306 | AK30: 2029 | AL30: S04 | AM30: 0.4309 | AN30: hydro
I31: elc_spv_002 | J31: S03aH03 | K31: 0.018004185 | L31: IMPNRGZ | N31: elc_won_002 | O31: S03aH03 | P31: 0.041955461 | Q31: IMPNRGZ | S31: elc_wof_002 | T31: S03aH03 | U31: 0.12996456 | V31: IMPNRGZ | AC31: elc_industry | AD31: S03aH03 | AE31: 0.12648203 | AK31: 2030 | AL31: S01 | AM31: 0.4233 | AN31: hydro
I32: elc_spv_002 | J32: S04aH01 | K32: 0.012418543 | L32: IMPNRGZ | N32: elc_won_002 | O32: S04aH01 | P32: 0.10200763 | Q32: IMPNRGZ | S32: elc_wof_002 | T32: S04aH01 | U32: 0.02120905 | V32: IMPNRGZ | AC32: elc_industry | AD32: S04aH01 | AE32: 0.03528879 | AK32: 2030 | AL32: S02 | AM32: 0.34406667 | AN32: hydro
I33: elc_spv_002 | J33: S04aH02 | K33: 0.062393112 | L33: IMPNRGZ | N33: elc_won_002 | O33: S04aH02 | P33: 0.070585504 | Q33: IMPNRGZ | S33: elc_wof_002 | T33: S04aH02 | U33: 0.035504382 | V33: IMPNRGZ | AC33: elc_industry | AD33: S04aH02 | AE33: 0.028290909 | AK33: 2030 | AL33: S03 | AM33: 0.37698333 | AN33: hydro
I34: elc_spv_002 | J34: S04aH03 | K34: 0.0032385463 | L34: IMPNRGZ | N34: elc_won_002 | O34: S04aH03 | P34: 0.044211723 | Q34: IMPNRGZ | S34: elc_wof_002 | T34: S04aH03 | U34: 0.021652278 | V34: IMPNRGZ | AC34: elc_industry | AD34: S04aH03 | AE34: 0.021286967 | AK34: 2030 | AL34: S04 | AM34: 0.471 | AN34: hydro
I35: elc_spv_003 | J35: S01aH01 | K35: 0.030760723 | L35: IMPNRGZ | N35: elc_won_003 | O35: S01aH01 | P35: 0.098835476 | Q35: IMPNRGZ | S35: elc_wof_003 | T35: S01aH01 | U35: 0.084879672 | V35: IMPNRGZ | AK35: 2031 | AL35: S01 | AM35: 0.44945 | AN35: hydro
I36: elc_spv_003 | J36: S01aH02 | K36: 0.12974924 | L36: IMPNRGZ | N36: elc_won_003 | O36: S01aH02 | P36: 0.088675659 | Q36: IMPNRGZ | S36: elc_wof_003 | T36: S01aH02 | U36: 0.073452456 | V36: IMPNRGZ | AK36: 2031 | AL36: S02 | AM36: 0.35076667 | AN36: hydro
I37: elc_spv_003 | J37: S01aH03 | K37: 0.0072724992 | L37: IMPNRGZ | N37: elc_won_003 | O37: S01aH03 | P37: 0.091050104 | Q37: IMPNRGZ | S37: elc_wof_003 | T37: S01aH03 | U37: 0.05672839 | V37: IMPNRGZ | AK37: 2031 | AL37: S03 | AM37: 0.37016667 | AN37: hydro
I38: elc_spv_003 | J38: S02aH01 | K38: 0.044851141 | L38: IMPNRGZ | N38: elc_won_003 | O38: S02aH01 | P38: 0.10920484 | Q38: IMPNRGZ | S38: elc_wof_003 | T38: S02aH01 | U38: 0.1164213 | V38: IMPNRGZ | AK38: 2031 | AL38: S04 | AM38: 0.4607 | AN38: hydro
I39: elc_spv_003 | J39: S02aH02 | K39: 0.18841157 | L39: IMPNRGZ | N39: elc_won_003 | O39: S02aH02 | P39: 0.078965094 | Q39: IMPNRGZ | S39: elc_wof_003 | T39: S02aH02 | U39: 0.08960531 | V39: IMPNRGZ | AK39: 2032 | AL39: S01 | AM39: 0.4287 | AN39: hydro
I40: elc_spv_003 | J40: S02aH03 | K40: 0.0089600025 | L40: IMPNRGZ | N40: elc_won_003 | O40: S02aH03 | P40: 0.099646698 | Q40: IMPNRGZ | S40: elc_wof_003 | T40: S02aH03 | U40: 0.075095234 | V40: IMPNRGZ | AK40: 2032 | AL40: S02 | AM40: 0.34626667 | AN40: hydro
I41: elc_spv_003 | J41: S03aH01 | K41: 0.09664789 | L41: IMPNRGZ | N41: elc_won_003 | O41: S03aH01 | P41: 0.12020855 | Q41: IMPNRGZ | S41: elc_wof_003 | T41: S03aH01 | U41: 0.17518074 | V41: IMPNRGZ | AK41: 2032 | AL41: S03 | AM41: 0.37836667 | AN41: hydro
I42: elc_spv_003 | J42: S03aH02 | K42: 0.38786525 | L42: IMPNRGZ | N42: elc_won_003 | O42: S03aH02 | P42: 0.081543148 | Q42: IMPNRGZ | S42: elc_wof_003 | T42: S03aH02 | U42: 0.1228775 | V42: IMPNRGZ | AK42: 2032 | AL42: S04 | AM42: 0.4161 | AN42: hydro
I43: elc_spv_003 | J43: S03aH03 | K43: 0.018600488 | L43: IMPNRGZ | N43: elc_won_003 | O43: S03aH03 | P43: 0.12535034 | Q43: IMPNRGZ | S43: elc_wof_003 | T43: S03aH03 | U43: 0.11332944 | V43: IMPNRGZ | AK43: 2033 | AL43: S01 | AM43: 0.4581 | AN43: hydro
I44: elc_spv_003 | J44: S04aH01 | K44: 0.017794998 | L44: IMPNRGZ | N44: elc_won_003 | O44: S04aH01 | P44: 0.034461168 | Q44: IMPNRGZ | S44: elc_wof_003 | T44: S04aH01 | U44: 0.034875575 | V44: IMPNRGZ | AK44: 2033 | AL44: S02 | AM44: 0.3362 | AN44: hydro
I45: elc_spv_003 | J45: S04aH02 | K45: 0.065595626 | L45: IMPNRGZ | N45: elc_won_003 | O45: S04aH02 | P45: 0.033861402 | Q45: IMPNRGZ | S45: elc_wof_003 | T45: S04aH02 | U45: 0.03137857 | V45: IMPNRGZ | AK45: 2033 | AL45: S03 | AM45: 0.38125 | AN45: hydro
I46: elc_spv_003 | J46: S04aH03 | K46: 0.00349058 | L46: IMPNRGZ | N46: elc_won_003 | O46: S04aH03 | P46: 0.038197516 | Q46: IMPNRGZ | S46: elc_wof_003 | T46: S04aH03 | U46: 0.026175809 | V46: IMPNRGZ | AK46: 2033 | AL46: S04 | AM46: 0.4668 | AN46: hydro
... I114: elc_spv_009 | J114: S03aH02 | K114: 0.3789369 | L114: IMPNRGZ | N114: elc_won_009 | O114: S03aH02 | P114: 0.10005251 | Q114: IMPNRGZ | S114: elc_wof_009 | T114: S03aH02 | U114: 0.078670143 | V114: IMPNRGZ | AK114: 2050 | AL114: S04 | AM114: 0.4675 | AN114: hydro
I115: elc_spv_009 | J115: S03aH03 | K115: 0.010139986 | L115: IMPNRGZ | N115: elc_won_009 | O115: S03aH03 | P115: 0.11502981 | Q115: IMPNRGZ | S115: elc_wof_009 | T115: S03aH03 | U115: 0.13255254 | V115: IMPNRGZ
...

Sheet ts_048
C9: =IF(A11="x","DeActivated","~TimeSlices") -> DeActivated | I9: =IF(A11="x","DeActivated","~TFM_DINS-AT") -> DeActivated | N9: =IF(A11="x","DeActivated","~TFM_DINS-AT") -> DeActivated | S9: =IF(A11="x","DeActivated","~TFM_DINS-AT") -> DeActivated | X9: =IF(A11="x","DeActivated","~TFM_DINS-AT") -> DeActivated | AC9: =IF(A11="x","DeActivated","~TFM_DINS-AT") -> DeActivated | AG9: =IF(A11="x","DeActivated","~TFM_DINS-AT") -> DeActivated | AK9: =IF(A11="x","DeActivated","~TFM_INS-AT") -> DeActivated
A10: ts_048 | C10: season | D10: weekly | E10: daynite | F10: wparent | G10: dparent | I10: commodity | J10: timeslice | K10: com_fr | L10: process | N10: commodity | O10: timeslice | P10: com_fr | Q10: process | S10: commodity | T10: timeslice | U10: com_fr | V10: process | X10: g_yrfr | Y10: com_fr | Z10: timeslice | AA10: commodity | AC10: commodity | AD10: timeslice | AE10: com_fr | AG10: commodity | AH10: timeslice | AI10: com_pkflx | AK10: Year | AL10: timeslice | AM10: ncap_afs | AN10: pset_ci
A11: =IFERROR(IF(Veda!D5=A10,"ok","x"),"") -> x | C11: S01 | D11: a | E11: H01 | F11: S01,S02,S03,S04,S05,S06,S07,S08 | G11: a | I11: elc_spv_001 | J11: S01aH01 | K11: 0.0064009278 | L11: IMPNRGZ | N11: elc_won_001 | O11: S01aH01 | P11: 0.13441499 | Q11: IMPNRGZ | S11: elc_wof_001 | T11: S01aH01 | U11: 0.035011851 | V11: IMPNRGZ | X11: 0.031849315 | Y11: 0.020212979 | Z11: S01aH01 | AA11: elc_roadtransport | AC11: elc_buildings | AD11: S01aH01 | AE11: 0.027755784 | AG11: ELC | AH11: S01aH01 | AI11: 0.18918869 | AK11: 2025 | AL11: S01 | AM11: 0.3884 | AN11: hydro
C12: S02 | E12: H02 | G12: a | I12: elc_spv_001 | J12: S01aH02 | K12: 0.0088434826 | L12: IMPNRGZ | N12: elc_won_001 | O12: S01aH02 | P12: 0.020191866 | Q12: IMPNRGZ | S12: elc_wof_001 | T12: S01aH02 | U12: 0.0037824027 | V12: IMPNRGZ | X12: 0.0035388128 | Y12: 0.0044803554 | Z12: S01aH02 | AA12: elc_roadtransport | AC12: elc_buildings | AD12: S01aH02 | AE12: 0.0025720116 | AG12: ELC | AH12: S01aH02 | AI12: 0.010601384 | AK12: 2025 | AL12: S02 | AM12: 0.3648 | AN12: hydro
C13: S03 | E13: H03 | G13: a | I13: elc_spv_001 | J13: S01aH03 | K13: 0.010154199 | L13: IMPNRGZ | N13: elc_won_001 | O13: S01aH03 | P13: 0.018132496 | Q13: IMPNRGZ | S13: elc_wof_001 | T13: S01aH03 | U13: 0.0039151412 | V13: IMPNRGZ | X13: 0.0035388128 | Y13: 0.0043673189 | Z13: S01aH03 | AA13: elc_roadtransport | AC13: elc_buildings | AD13: S01aH03 | AE13: 0.0027593877 | AG13: ELC | AH13: S01aH03 | AI13: 0.01281905 | AK13: 2025 | AL13: S03 | AM13: 0.3707 | AN13: hydro
C14: S04 | E14: H04 | G14: a | I14: elc_spv_001 | J14: S01aH04 | K14: 0.061122282 | L14: IMPNRGZ | N14: elc_won_001 | O14: S01aH04 | P14: 0.061042845 | Q14: IMPNRGZ | S14: elc_wof_001 | T14: S01aH04 | U14: 0.025055355 | V14: IMPNRGZ | X14: 0.021232877 | Y14: 0.030283503 | Z14: S01aH04 | AA14: elc_roadtransport | AC14: elc_buildings | AD14: S01aH04 | AE14: 0.019255604 | AG14: ELC | AH14: S01aH04 | AI14: 0.1309542 | AK14: 2025 | AL14: S04 | AM14: 0.2805 | AN14: hydro
C15: S05 | E15: H05 | G15: a | I15: elc_spv_001 | J15: S01aH05 | K15: 0.0077344626 | L15: IMPNRGZ | N15: elc_won_001 | O15: S01aH05 | P15: 0.0067109422 | Q15: IMPNRGZ | S15: elc_wof_001 | T15: S01aH05 | U15: 0.0041482647 | V15: IMPNRGZ | X15: 0.0035388128 | Y15: 0.0068849497 | Z15: S01aH05 | AA15: elc_roadtransport | AC15: elc_buildings | AD15: S01aH05 | AE15: 0.0032398398 | AG15: ELC | AH15: S01aH05 | AI15: 0.038138927 | AK15: 2025 | AL15: S05 | AM15: 0.281 | AN15: hydro
C16: S06 | E16: H06 | G16: a | I16: elc_spv_001 | J16: S01aH06 | K16: 0.0053759466 | L16: IMPNRGZ | N16: elc_won_001 | O16: S01aH06 | P16: 0.059472607 | Q16: IMPNRGZ | S16: elc_wof_001 | T16: S01aH06 | U16: 0.026386359 | V16: IMPNRGZ | X16: 0.021232877 | Y16: 0.018702401 | Z16: S01aH06 | AA16: elc_roadtransport | AC16: elc_buildings | AD16: S01aH06 | AE16: 0.01998228 | AG16: ELC | AH16: S01aH06 | AI16: 0.12964816 | AK16: 2025 | AL16: S06 | AM16: 0.30985 | AN16: hydro
C17: S07 | I17: elc_spv_001 | J17: S02aH01 | K17: 0.0034976088 | L17: IMPNRGZ | N17: elc_won_001 | O17: S02aH01 | P17: 0.065854716 | Q17: IMPNRGZ | S17: elc_wof_001 | T17: S02aH01 | U17: 0.030611565 | V17: IMPNRGZ | X17: 0.028767123 | Y17: 0.018256885 | Z17: S02aH01 | AA17: elc_roadtransport | AC17: elc_buildings | AD17: S02aH01 | AE17: 0.02478771 | AG17: ELC | AH17: S02aH01 | AI17: 0.19484596 | AK17: 2025 | AL17: S07 | AM17: 0.36595 | AN17: hydro
C18: S08 | I18: elc_spv_001 | J18: S02aH02 | K18: 0.0056151964 | L18: IMPNRGZ | N18: elc_won_001 | O18: S02aH02 | P18: 0.012703268 | Q18: IMPNRGZ | S18: elc_wof_001 | T18: S02aH02 | U18: 0.0033418555 | V18: IMPNRGZ | X18: 0.003196347 | Y18: 0.0040467726 | Z18: S02aH02 | AA18: elc_roadtransport | AC18: elc_buildings | AD18: S02aH02 | AE18: 0.0023050336 | AG18: ELC | AH18: S02aH02 | AI18: 0.0087320577 | AK18: 2025 | AL18: S08 | AM18: 0.3453 | AN18: hydro
I19: elc_spv_001 | J19: S02aH03 | K19: 0.0070671437 | L19: IMPNRGZ | N19: elc_won_001 | O19: S02aH03 | P19: 0.011655641 | Q19: IMPNRGZ | S19: elc_wof_001 | T19: S02aH03 | U19: 0.0034144851 | V19: IMPNRGZ | X19: 0.003196347 | Y19: 0.0039446751 | Z19: S02aH03 | AA19: elc_roadtransport | AC19: elc_buildings | AD19: S02aH03 | AE19: 0.0024812755 | AG19: ELC | AH19: S02aH03 | AI19: 0.014111143 | AK19: 2026 | AL19: S01 | AM19: 0.4063 | AN19: hydro
I20: elc_spv_001 | J20: S02aH04 | K20: 0.046809987 | L20: IMPNRGZ | N20: elc_won_001 | O20: S02aH04 | P20: 0.042495718 | Q20: IMPNRGZ | S20: elc_wof_001 | T20: S02aH04 | U20: 0.021886092 | V20: IMPNRGZ | X20: 0.019178082 | Y20: 0.027352841 | Z20: S02aH04 | AA20: elc_roadtransport | AC20: elc_buildings | AD20: S02aH04 | AE20: 0.017089164 | AG20: ELC | AH20: S02aH04 | AI20: 0.13789922 | AK20: 2026 | AL20: S02 | AM20: 0.4032 | AN20: hydro
I21: elc_spv_001 | J21: S02aH05 | K21: 0.0055447685 | L21: IMPNRGZ | N21: elc_won_001 | O21: S02aH05 | P21: 0.0045520574 | Q21: IMPNRGZ | S21: elc_wof_001 | T21: S02aH05 | U21: 0.0037373116 | V21: IMPNRGZ | X21: 0.003196347 | Y21: 0.0062186643 | Z21: S02aH05 | AA21: elc_roadtransport | AC21: elc_buildings | AD21: S02aH05 | AE21: 0.0028520005 | AG21: ELC | AH21: S02aH05 | AI21: 0.045072574 | AK21: 2026 | AL21: S03 | AM21: 0.3683 | AN21: hydro
I22: elc_spv_001 | J22: S02aH06 | K22: 0.0037730733 | L22: IMPNRGZ | N22: elc_won_001 | O22: S02aH06 | P22: 0.030213324 | Q22: IMPNRGZ | S22: elc_wof_001 | T22: S02aH06 | U22: 0.023330927 | V22: IMPNRGZ | X22: 0.019178082 | Y22: 0.016892491 | Z22: S02aH06 | AA22: elc_roadtransport | AC22: elc_buildings | AD22: S02aH06 | AE22: 0.017588589 | AG22: ELC | AH22: S02aH06 | AI22: 0.1403709 | AK22: 2026 | AL22: S04 | AM22: 0.307 | AN22: hydro
I23: elc_spv_001 | J23: S03aH01 | K23: 0.010640968 | L23: IMPNRGZ | N23: elc_won_001 | O23: S03aH01 | P23: 0.016720685 | Q23: IMPNRGZ | S23: elc_wof_001 | T23: S03aH01 | U23: 0.034997041 | V23: IMPNRGZ | X23: 0.031849315 | Y23: 0.020212979 | Z23: S03aH01 | AA23: elc_roadtransport | AC23: elc_buildings | AD23: S03aH01 | AE23: 0.027867239 | AG23: ELC | AH23: S03aH01 | AI23: 0.20417945 | AK23: 2026 | AL23: S05 | AM23: 0.269 | AN23: hydro
I24: elc_spv_001 | J24: S03aH02 | K24: 0.0092222929 | L24: IMPNRGZ | N24: elc_won_001 | O24: S03aH02 | P24: 0.0022849406 | Q24: IMPNRGZ | S24: elc_wof_001 | T24: S03aH02 | U24: 0.0039240622 | V24: IMPNRGZ | X24: 0.0035388128 | Y24: 0.0044803554 | Z24: S03aH02 | AA24: elc_roadtransport | AC24: elc_buildings | AD24: S03aH02 | AE24: 0.002596116 | AG24: ELC | AH24: S03aH02 | AI24: 0.0050020882 | AK24: 2026 | AL24: S06 | AM24: 0.31925 | AN24: hydro
I25: elc_spv_001 | J25: S03aH03 | K25: 0.010598697 | L25: IMPNRGZ | N25: elc_won_001 | O25: S03aH03 | P25: 0.0020313521 | Q25: IMPNRGZ | S25: elc_wof_001 | T25: S03aH03 | U25: 0.0039528167 | V25: IMPNRGZ | X25: 0.0035388128 | Y25: 0.0043673189 | Z25: S03aH03 | AA25: elc_roadtransport | AC25: elc_buildings | AD25: S03aH03 | AE25: 0.0027765682 | AG25: ELC | AH25: S03aH03 | AI25: 0.0090095943 | AK25: 2026 | AL25: S07 | AM25: 0.37845 | AN25: hydro
I26: elc_spv_001 | J26: S03aH04 | K26: 0.064870929 | L26: IMPNRGZ | N26: elc_won_001 | O26: S03aH04 | P26: 0.0050936432 | Q26: IMPNRGZ | S26: elc_wof_001 | T26: S03aH04 | U26: 0.024907875 | V26: IMPNRGZ | X26: 0.021232877 | Y26: 0.030283503 | Z26: S03aH04 | AA26: elc_roadtransport | AC26: elc_buildings | AD26: S03aH04 | AE26: 0.0193028 | AG26: ELC | AH26: S03aH04 | AI26: 0.11775017 | AK26: 2026 | AL26: S08 | AM26: 0.3731 | AN26: hydro
I27: elc_spv_001 | J27: S03aH05 | K27: 0.0070256512 | L27: IMPNRGZ | N27: elc_won_001 | O27: S03aH05 | P27: 0.00060332171 | Q27: IMPNRGZ | S27: elc_wof_001 | T27: S03aH05 | U27: 0.004253404 | V27: IMPNRGZ | X27: 0.0035388128 | Y27: 0.0068849497 | Z27: S03aH05 | AA27: elc_roadtransport | AC27: elc_buildings | AD27: S03aH05 | AE27: 0.0033755882 | AG27: ELC | AH27: S03aH05 | AI27: 0.045662476 | AK27: 2027 | AL27: S01 | AM27: 0.4034 | AN27: hydro
I28: elc_spv_001 | J28: S03aH06 | K28: 0.0046886388 | L28: IMPNRGZ | N28: elc_won_001 | O28: S03aH06 | P28: 0.012526303 | Q28: IMPNRGZ | S28: elc_wof_001 | T28: S03aH06 | U28: 0.026322826 | V28: IMPNRGZ | X28: 0.021232877 | Y28: 0.018702401 | Z28: S03aH06 | AA28: elc_roadtransport | AC28: elc_buildings | AD28: S03aH06 | AE28: 0.020638392 | AG28: ELC | AH28: S03aH06 | AI28: 0.094882124 | AK28: 2027 | AL28: S02 | AM28: 0.3932 | AN28: hydro
I29: elc_spv_001 | J29: S04aH01 | K29: 0.011575472 | L29: IMPNRGZ | N29: elc_won_001 | O29: S04aH01 | P29: 0.016721341 | Q29: IMPNRGZ | S29: elc_wof_001 | T29: S04aH01 | U29: 0.061177995 | V29: IMPNRGZ | X29: 0.062671233 | Y29: 0.039773927 | Z29: S04aH01 | AA29: elc_roadtransport | AC29: elc_buildings | AD29: S04aH01 | AE29: 0.062244137 | AG29: ELC | AH29: S04aH01 | AI29: 0.19897403 | AK29: 2027 | AL29: S03 | AM29: 0.3216 | AN29: hydro
I30: elc_spv_001 | J30: S04aH02 | K30: 0.011259978 | L30: IMPNRGZ | N30: elc_won_001 | O30: S04aH02 | P30: 0.0014302486 | Q30: IMPNRGZ | S30: elc_wof_001 | T30: S04aH02 | U30: 0.0064613084 | V30: IMPNRGZ | X30: 0.0069634703 | Y30: 0.0088161831 | Z30: S04aH02 | AA30: elc_roadtransport | AC30: elc_buildings | AD30: S04aH02 | AE30: 0.0056818614 | AG30: ELC | AH30: S04aH02 | AI30: 0.056620084 | AK30: 2027 | AL30: S04 | AM30: 0.2867 | AN30: hydro
... I58: elc_spv_001 | J58: S08aH06 | K58: 0.0039385718 | L58: IMPNRGZ | N58: elc_won_001 | O58: S08aH06 | P58: 0.046765715 | Q58: IMPNRGZ | S58: elc_wof_001 | T58: S08aH06 | U58: 0.023230995 | V58: IMPNRGZ | X58: 0.021232877 | Y58: 0.018702401 | Z58: S08aH06 | AA58: elc_roadtransport | AC58: elc_buildings | AD58: S08aH06 | AE58: 0.019749378 | AG58: ELC | AH58: S08aH06 | AI58: 0.1343314 | AK58: 2030 | AL58: S08 | AM58: 0.471 | AN58: hydro
I59: elc_spv_002 | J59: S01aH01 | K59: 0.0076951796 | L59: IMPNRGZ | N59: elc_won_002 | O59: S01aH01 | P59: 0.11589491 | Q59: IMPNRGZ | S59: elc_wof_002 | T59: S01aH01 | U59: 0.026564371 | V59: IMPNRGZ | AC59: elc_industry | AD59: S01aH01 | AE59: 0.031788888 | AK59: 2031 | AL59: S01 | AM59: 0.4597 | AN59: hydro
I60: elc_spv_002 | J60: S01aH02 | K60: 0.0085961324 | L60: IMPNRGZ | N60: elc_won_002 | O60: S01aH02 | P60: 0.017430614 | Q60: IMPNRGZ | S60: elc_wof_002 | T60: S01aH02 | U60: 0.003981662 | V60: IMPNRGZ | AC60: elc_industry | AD60: S01aH02 | AE60: 0.0034984952 | AK60: 2031 | AL60: S02 | AM60: 0.4392 | AN60: hydro
I61: elc_spv_002 | J61: S01aH03 | K61: 0.009609722 | L61: IMPNRGZ | N61: elc_won_002 | O61: S01aH03 | P61: 0.015532995 | Q61: IMPNRGZ | S61: elc_wof_002 | T61: S01aH03 | U61: 0.0046630068 | V61: IMPNRGZ | AC61: elc_industry | AD61: S01aH03 | AE61: 0.0035107939 | AK61: 2031 | AL61: S03 | AM61: 0.3692 | AN61: hydro
I62: elc_spv_002 | J62: S01aH04 | K62: 0.057161808 | L62: IMPNRGZ | N62: elc_won_002 | O62: S01aH04 | P62: 0.05746313 | Q62: IMPNRGZ | S62: elc_wof_002 | T62: S01aH04 | U62: 0.036701048 | V62: IMPNRGZ | AC62: elc_industry | AD62: S01aH04 | AE62: 0.021241934 | AK62: 2031 | AL62: S04 | AM62: 0.34155 | AN62: hydro
I63: elc_spv_002 | J63: S01aH05 | K63: 0.0065795908 | L63: IMPNRGZ | N63: elc_won_002 | O63: S01aH05 | P63: 0.0070044883 | Q63: IMPNRGZ | S63: elc_wof_002 | T63: S01aH05 | U63: 0.0057956586 | V63: IMPNRGZ | AC63: elc_industry | AD63: S01aH05 | AE63: 0.003542329 | AK63: 2031 | AL63: S05 | AM63: 0.30835 | AN63: hydro
I64: elc_spv_002 | J64: S01aH06 | K64: 0.0048033032 | L64: IMPNRGZ | N64: elc_won_002 | O64: S01aH06 | P64: 0.049348778 | Q64: IMPNRGZ | S64: elc_wof_002 | T64: S01aH06 | U64: 0.030605786 | V64: IMPNRGZ | AC64: elc_industry | AD64: S01aH06 | AE64: 0.02128963 | AK64: 2031 | AL64: S06 | AM64: 0.36895 | AN64: hydro
I65: elc_spv_002 | J65: S02aH01 | K65: 0.0033955568 | L65: IMPNRGZ | N65: elc_won_002 | O65: S02aH01 | P65: 0.08862811 | Q65: IMPNRGZ | S65: elc_wof_002 | T65: S02aH01 | U65: 0.024841466 | V65: IMPNRGZ | AC65: elc_industry | AD65: S02aH01 | AE65: 0.028719566 | AK65: 2031 | AL65: S07 | AM65: 0.4332 | AN65: hydro
I66: elc_spv_002 | J66: S02aH02 | K66: 0.004626234 | L66: IMPNRGZ | N66: elc_won_002 | O66: S02aH02 | P66: 0.013628963 | Q66: IMPNRGZ | S66: elc_wof_002 | T66: S02aH02 | U66: 0.0040297929 | V66: IMPNRGZ | AC66: elc_industry | AD66: S02aH02 | AE66: 0.003161582 | AK66: 2031 | AL66: S08 | AM66: 0.4607 | AN66: hydro
I67: elc_spv_002 | J67: S02aH03 | K67: 0.0062198255 | L67: IMPNRGZ | N67: elc_won_002 | O67: S02aH03 | P67: 0.012036086 | Q67: IMPNRGZ | S67: elc_wof_002 | T67: S02aH03 | U67: 0.004467159 | V67: IMPNRGZ | AC67: elc_industry | AD67: S02aH03 | AE67: 0.0031731498 | AK67: 2032 | AL67: S01 | AM67: 0.3998 | AN67: hydro
I68: elc_spv_002 | J68: S02aH04 | K68: 0.043822308 | L68: IMPNRGZ | N68: elc_won_002 | O68: S02aH04 | P68: 0.041706017 | Q68: IMPNRGZ | S68: elc_wof_002 | T68: S02aH04 | U68: 0.033056126 | V68: IMPNRGZ | AC68: elc_industry | AD68: S02aH04 | AE68: 0.019183398 | AK68: 2032 | AL68: S02 | AM68: 0.4576 | AN68: hydro
I69: elc_spv_002 | J69: S02aH05 | K69: 0.0053246634 | L69: IMPNRGZ | N69: elc_won_002 | O69: S02aH05 | P69: 0.0046024267 | Q69: IMPNRGZ | S69: elc_wof_002 | T69: S02aH05 | U69: 0.0056053626 | V69: IMPNRGZ | AC69: elc_industry | AD69: S02aH05 | AE69: 0.0031974828 | AK69: 2032 | AL69: S03 | AM69: 0.3723 | AN69: hydro
I70: elc_spv_002 | J70: S02aH06 | K70: 0.0031674989 | L70: IMPNRGZ | N70: elc_won_002 | O70: S02aH06 | P70: 0.030892641 | Q70: IMPNRGZ | S70: elc_wof_002 | T70: S02aH06 | U70: 0.027687214 | V70: IMPNRGZ | AC70: elc_industry | AD70: S02aH06 | AE70: 0.019216178 | AK70: 2032 | AL70: S04 | AM70: 0.33325 | AN70: hydro
