Workbook

Sheet Veda
G1: 1-55
D2: ="~Inputcell: "&_xlfn.TEXTJOIN(",",TRUE,G1:EE1) -> ~Inputcell: 1-55
D3: 3
D5: =VLOOKUP(D3,$C$9:$E$1001,2,FALSE) -> s2_w | E5: =VLOOKUP(D3,$C$9:$E$1001,3,FALSE) -> C1
B7: ~Scenmap
A8: priority | B8: scen | C8: case_no | D8: timeslice | E8: climate
A9: 5 | B9: =VLOOKUP(E9,$AK$9:$AL$15,2,FALSE)&"."&VLOOKUP(D9,$AH$9:$AI$19,2,FALSE) -> e 1.5 deg no OS.e3d | C9: 1 | D9: s1p1v1_d | E9: C1 | G9: Limit warming to 1.5°C (>50%) with no or limited overshoot | AH9: s1p1v1_d | AI9: e3d | AK9: C1 | AL9: e 1.5 deg no OS
A10: 5 | B10: =VLOOKUP(E10,$AK$9:$AL$15,2,FALSE)&"."&VLOOKUP(D10,$AH$9:$AI$19,2,FALSE) -> e 1.5 deg no OS.d9d | C10: 2 | D10: s3p3v3_d | E10: C1 | G10: Limit warming to 1.5°C (>67%) with high overshoot | S10: IEA | AH10: s3p3v3_d | AI10: d9d | AK10: C2 | AL10: d 1.5 deg OS
A11: 5 | B11: =VLOOKUP(E11,$AK$9:$AL$15,2,FALSE)&"."&VLOOKUP(D11,$AH$9:$AI$19,2,FALSE) -> e 1.5 deg no OS.b2w | C11: 3 | D11: s2_w | E11: C1 | G11: Limit warming to 2°C (>67%) with higher action post-2030 | S11: 2022 | AH11: s2_w | AI11: b2w | AK11: C3 | AL11: c 2 deg (67%)
A12: 5 | B12: =VLOOKUP(E12,$AK$9:$AL$15,2,FALSE)&"."&VLOOKUP(D12,$AH$9:$AI$19,2,FALSE) -> e 1.5 deg no OS.a2w2d | C12: 4 | D12: s2_w_p2_d | E12: C1 | G12: Limit warming to 2°C (>50%) with immediate action | S12: =SUMIFS(iea_data!I3:I9999,iea_data!$B$3:$B$9999,Veda!$S$11)+T28-T29 -> 55.98 | T12: base-year generation (TWh) | AH12: s2_w_p2_d | AI12: a2w2d | AK12: C4 | AL12: b 2 deg (50%)
A13: 5 | B13: =VLOOKUP(E13,$AK$9:$AL$15,2,FALSE)&"."&VLOOKUP(D13,$AH$9:$AI$19,2,FALSE) -> e 1.5 deg no OS.hTS12c | C13: 5 | D13: ts12_clu | E13: C1 | G13: Likely above 3°C warming with limited mitigation | AH13: ts12_clu | AI13: hTS12c | AK13: C7 | AL13: a 3 deg
A14: 5 | B14: =VLOOKUP(E14,$AK$9:$AL$15,2,FALSE)&"."&VLOOKUP(D14,$AH$9:$AI$19,2,FALSE) -> e 1.5 deg no OS.gTS24c | C14: 6 | D14: ts24_clu | E14: =E13 -> C1 | T14: =S12 -> 55.98 | U14: =$S$12*J15 -> 57.6594 | V14: =$S$12*K15 -> 66.6162 | W14: =$S$12*L15 -> 80.0514 | X14: =$S$12*M15 -> 92.367 | Y14: =$S$12*N15 -> 101.3238 | Z14: =$S$12*O15 -> 108.0414 | AH14: ts24_clu | AI14: gTS24c
A15: 5 | B15: =VLOOKUP(E15,$AK$9:$AL$15,2,FALSE)&"."&VLOOKUP(D15,$AH$9:$AI$19,2,FALSE) -> e 1.5 deg no OS.fTS48c | C15: 7 | D15: ts48_clu | E15: =E14 -> C1 | G15: Electricity growth relative to 2020 | I15: =SUMIFS(ar6_r10!$F$2:$F$999,ar6_r10!$A$2:$A$999,Veda!$E$5,ar6_r10!$C$2:$C$999,Veda!I$17,ar6_r10!$M$2:$M$999,Veda!$G15) -> 1 | J15: =SUMIFS(ar6_r10!$F$2:$F$999,ar6_r10!$A$2:$A$999,Veda!$E$5,ar6_r10!$C$2:$C$999,Veda!J$17,ar6_r10!$M$2:$M$999,Veda!$G15) -> 1.03 | K15: =SUMIFS(ar6_r10!$F$2:$F$999,ar6_r10!$A$2:$A$999,Veda!$E$5,ar6_r10!$C$2:$C$999,Veda!K$17,ar6_r10!$M$2:$M$999,Veda!$G15) -> 1.19 | L15: =SUMIFS(ar6_r10!$F$2:$F$999,ar6_r10!$A$2:$A$999,Veda!$E$5,ar6_r10!$C$2:$C$999,Veda!L$17,ar6_r10!$M$2:$M$999,Veda!$G15) -> 1.43 | M15: =SUMIFS(ar6_r10!$F$2:$F$999,ar6_r10!$A$2:$A$999,Veda!$E$5,ar6_r10!$C$2:$C$999,Veda!M$17,ar6_r10!$M$2:$M$999,Veda!$G15) -> 1.65 | N15: =SUMIFS(ar6_r10!$F$2:$F$999,ar6_r10!$A$2:$A$999,Veda!$E$5,ar6_r10!$C$2:$C$999,Veda!N$17,ar6_r10!$M$2:$M$999,Veda!$G15) -> 1.81 | O15: =SUMIFS(ar6_r10!$F$2:$F$999,ar6_r10!$A$2:$A$999,Veda!$E$5,ar6_r10!$C$2:$C$999,Veda!O$17,ar6_r10!$M$2:$M$999,Veda!$G15) -> 1.93 | AH15: ts48_clu | AI15: fTS48c
A16: 5 | B16: =VLOOKUP(E16,$AK$9:$AL$15,2,FALSE)&"."&VLOOKUP(D16,$AH$9:$AI$19,2,FALSE) -> e 1.5 deg no OS.c15d | C16: 8 | D16: s5p5v5_d | E16: =E15 -> C1 | S16: ~TFM_INS-TS | AH16: s5p5v5_d | AI16: c15d
A17: 5 | B17: =VLOOKUP(E17,$AK$9:$AL$15,2,FALSE)&"."&VLOOKUP(D17,$AH$9:$AI$19,2,FALSE) -> e 1.5 deg no OS.f1d | C17: 9 | D17: s1_d | E17: =E16 -> C1 | I17: 2020 | J17: =U17 -> 2025 | K17: =V17 -> 2030 | L17: =W17 -> 2035 | M17: =X17 -> 2040 | N17: =Y17 -> 2045 | O17: =Z17 -> 2050 | S17: commodity | T17: 2022 | U17: 2025 | V17: 2030 | W17: 2035 | X17: 2040 | Y17: 2045 | Z17: 2050 | AA17: attribute | AH17: ts_12 | AI17: iTS12
A18: 5 | B18: =VLOOKUP(E18,$AK$9:$AL$15,2,FALSE)&"."&VLOOKUP(D18,$AH$9:$AI$19,2,FALSE) -> e 1.5 deg no OS.jAnn | C18: 10 | D18: ts_annual | E18: =E17 -> C1 | G18: Hydrogen as a share of electricity | I18: =SUMIFS(ar6_r10!$F$2:$F$999,ar6_r10!$A$2:$A$999,Veda!$E$5,ar6_r10!$C$2:$C$999,Veda!I$17,ar6_r10!$M$2:$M$999,Veda!$G18) -> 0.01 | J18: =SUMIFS(ar6_r10!$F$2:$F$999,ar6_r10!$A$2:$A$999,Veda!$E$5,ar6_r10!$C$2:$C$999,Veda!J$17,ar6_r10!$M$2:$M$999,Veda!$G18) -> 0.01 | K18: =SUMIFS(ar6_r10!$F$2:$F$999,ar6_r10!$A$2:$A$999,Veda!$E$5,ar6_r10!$C$2:$C$999,Veda!K$17,ar6_r10!$M$2:$M$999,Veda!$G18) -> 0.01 | L18: =SUMIFS(ar6_r10!$F$2:$F$999,ar6_r10!$A$2:$A$999,Veda!$E$5,ar6_r10!$C$2:$C$999,Veda!L$17,ar6_r10!$M$2:$M$999,Veda!$G18) -> 0.03 | M18: =SUMIFS(ar6_r10!$F$2:$F$999,ar6_r10!$A$2:$A$999,Veda!$E$5,ar6_r10!$C$2:$C$999,Veda!M$17,ar6_r10!$M$2:$M$999,Veda!$G18) -> 0.03 | N18: =SUMIFS(ar6_r10!$F$2:$F$999,ar6_r10!$A$2:$A$999,Veda!$E$5,ar6_r10!$C$2:$C$999,Veda!N$17,ar6_r10!$M$2:$M$999,Veda!$G18) -> 0.04 | O18: =SUMIFS(ar6_r10!$F$2:$F$999,ar6_r10!$A$2:$A$999,Veda!$E$5,ar6_r10!$C$2:$C$999,Veda!O$17,ar6_r10!$M$2:$M$999,Veda!$G18) -> 0.05 | S18: hydrogen_allsect | T18: =I18*T$14 -> 0.5598 | U18: =J18*U$14 -> 0.576594 | V18: =K18*V$14 -> 0.666162 | W18: =L18*W$14 -> 2.401542 | X18: =M18*X$14 -> 2.77101 | Y18: =N18*Y$14 -> 4.052952 | Z18: =O18*Z$14 -> 5.40207 | AA18: demand | AH18: ts_annual | AI18: jAnn
A19: 5 | B19: =VLOOKUP(E19,$AK$9:$AL$15,2,FALSE)&"."&VLOOKUP(D19,$AH$9:$AI$19,2,FALSE) -> e 1.5 deg no OS.iTS12 | C19: 11 | D19: ts_12 | E19: =E18 -> C1 | G19: Industry electricity share | I19: =SUMIFS(ar6_r10!$F$2:$F$999,ar6_r10!$A$2:$A$999,Veda!$E$5,ar6_r10!$C$2:$C$999,Veda!I$17,ar6_r10!$M$2:$M$999,Veda!$G19) -> 0.35 | J19: =SUMIFS(ar6_r10!$F$2:$F$999,ar6_r10!$A$2:$A$999,Veda!$E$5,ar6_r10!$C$2:$C$999,Veda!J$17,ar6_r10!$M$2:$M$999,Veda!$G19) -> 0.32 | K19: =SUMIFS(ar6_r10!$F$2:$F$999,ar6_r10!$A$2:$A$999,Veda!$E$5,ar6_r10!$C$2:$C$999,Veda!K$17,ar6_r10!$M$2:$M$999,Veda!$G19) -> 0.3 | L19: =SUMIFS(ar6_r10!$F$2:$F$999,ar6_r10!$A$2:$A$999,Veda!$E$5,ar6_r10!$C$2:$C$999,Veda!L$17,ar6_r10!$M$2:$M$999,Veda!$G19) -> 0.29 | M19: =SUMIFS(ar6_r10!$F$2:$F$999,ar6_r10!$A$2:$A$999,Veda!$E$5,ar6_r10!$C$2:$C$999,Veda!M$17,ar6_r10!$M$2:$M$999,Veda!$G19) -> 0.29 | N19: =SUMIFS(ar6_r10!$F$2:$F$999,ar6_r10!$A$2:$A$999,Veda!$E$5,ar6_r10!$C$2:$C$999,Veda!N$17,ar6_r10!$M$2:$M$999,Veda!$G19) -> 0.3 | O19: =SUMIFS(ar6_r10!$F$2:$F$999,ar6_r10!$A$2:$A$999,Veda!$E$5,ar6_r10!$C$2:$C$999,Veda!O$17,ar6_r10!$M$2:$M$999,Veda!$G19) -> 0.31 | S19: elc_industry | T19: =I19*T$14 -> 19.593 | U19: =J19*U$14 -> 18.451008 | V19: =K19*V$14 -> 19.98486 | W19: =L19*W$14 -> 23.214906 | X19: =M19*X$14 -> 26.78643 | Y19: =N19*Y$14 -> 30.39714 | Z19: =O19*Z$14 -> 33.492834 | AA19: demand | AH19: s1_d | AI19: f1d
A20: 5 | B20: =VLOOKUP(E20,$AK$9:$AL$15,2,FALSE)&"."&VLOOKUP(D20,$AH$9:$AI$19,2,FALSE) -> d 1.5 deg OS.e3d | C20: 12 | D20: =D9 -> s1p1v1_d | E20: C2 | G20: Residential and commercial electricity share | I20: =SUMIFS(ar6_r10!$F$2:$F$999,ar6_r10!$A$2:$A$999,Veda!$E$5,ar6_r10!$C$2:$C$999,Veda!I$17,ar6_r10!$M$2:$M$999,Veda!$G20) -> 0.61 | J20: =SUMIFS(ar6_r10!$F$2:$F$999,ar6_r10!$A$2:$A$999,Veda!$E$5,ar6_r10!$C$2:$C$999,Veda!J$17,ar6_r10!$M$2:$M$999,Veda!$G20) -> 0.62 | K20: =SUMIFS(ar6_r10!$F$2:$F$999,ar6_r10!$A$2:$A$999,Veda!$E$5,ar6_r10!$C$2:$C$999,Veda!K$17,ar6_r10!$M$2:$M$999,Veda!$G20) -> 0.59 | L20: =SUMIFS(ar6_r10!$F$2:$F$999,ar6_r10!$A$2:$A$999,Veda!$E$5,ar6_r10!$C$2:$C$999,Veda!L$17,ar6_r10!$M$2:$M$999,Veda!$G20) -> 0.56 | M20: =SUMIFS(ar6_r10!$F$2:$F$999,ar6_r10!$A$2:$A$999,Veda!$E$5,ar6_r10!$C$2:$C$999,Veda!M$17,ar6_r10!$M$2:$M$999,Veda!$G20) -> 0.54 | N20: =SUMIFS(ar6_r10!$F$2:$F$999,ar6_r10!$A$2:$A$999,Veda!$E$5,ar6_r10!$C$2:$C$999,Veda!N$17,ar6_r10!$M$2:$M$999,Veda!$G20) -> 0.53 | O20: =SUMIFS(ar6_r10!$F$2:$F$999,ar6_r10!$A$2:$A$999,Veda!$E$5,ar6_r10!$C$2:$C$999,Veda!O$17,ar6_r10!$M$2:$M$999,Veda!$G20) -> 0.53 | S20: elc_buildings | T20: =I20*T$14 -> 34.1478 | U20: =J20*U$14 -> 35.748828 | V20: =K20*V$14 -> 39.303558 | W20: =L20*W$14 -> 44.828784 | X20: =M20*X$14 -> 49.87818 | Y20: =N20*Y$14 -> 53.701614 | Z20: =O20*Z$14 -> 57.261942 | AA20: demand
A21: 5 | B21: =VLOOKUP(E21,$AK$9:$AL$15,2,FALSE)&"."&VLOOKUP(D21,$AH$9:$AI$19,2,FALSE) -> d 1.5 deg OS.d9d | C21: 13 | D21: =D10 -> s3p3v3_d | E21: =E20 -> C2 | G21: Transportation electricity share | I21: =SUMIFS(ar6_r10!$F$2:$F$999,ar6_r10!$A$2:$A$999,Veda!$E$5,ar6_r10!$C$2:$C$999,Veda!I$17,ar6_r10!$M$2:$M$999,Veda!$G21) -> 0.03 | J21: =SUMIFS(ar6_r10!$F$2:$F$999,ar6_r10!$A$2:$A$999,Veda!$E$5,ar6_r10!$C$2:$C$999,Veda!J$17,ar6_r10!$M$2:$M$999,Veda!$G21) -> 0.06 | K21: =SUMIFS(ar6_r10!$F$2:$F$999,ar6_r10!$A$2:$A$999,Veda!$E$5,ar6_r10!$C$2:$C$999,Veda!K$17,ar6_r10!$M$2:$M$999,Veda!$G21) -> 0.1 | L21: =SUMIFS(ar6_r10!$F$2:$F$999,ar6_r10!$A$2:$A$999,Veda!$E$5,ar6_r10!$C$2:$C$999,Veda!L$17,ar6_r10!$M$2:$M$999,Veda!$G21) -> 0.14 | M21: =SUMIFS(ar6_r10!$F$2:$F$999,ar6_r10!$A$2:$A$999,Veda!$E$5,ar6_r10!$C$2:$C$999,Veda!M$17,ar6_r10!$M$2:$M$999,Veda!$G21) -> 0.17 | N21: =SUMIFS(ar6_r10!$F$2:$F$999,ar6_r10!$A$2:$A$999,Veda!$E$5,ar6_r10!$C$2:$C$999,Veda!N$17,ar6_r10!$M$2:$M$999,Veda!$G21) -> 0.19 | O21: =SUMIFS(ar6_r10!$F$2:$F$999,ar6_r10!$A$2:$A$999,Veda!$E$5,ar6_r10!$C$2:$C$999,Veda!O$17,ar6_r10!$M$2:$M$999,Veda!$G21) -> 0.2 | S21: elc_transport | T21: =I21*T$14 -> 1.6794 | U21: =T21 -> 1.6794 | V21: =U21 -> 1.6794 | W21: =V21 -> 1.6794 | X21: =W21 -> 1.6794 | Y21: =X21 -> 1.6794 | Z21: =Y21 -> 1.6794 | AA21: demand | AC21: non-road transport demand assumed to be constant
A22: 5 | B22: =VLOOKUP(E22,$AK$9:$AL$15,2,FALSE)&"."&VLOOKUP(D22,$AH$9:$AI$19,2,FALSE) -> d 1.5 deg OS.b2w | C22: 14 | D22: =D11 -> s2_w | E22: =E21 -> C2 | S22: elc_roadtransport | T22: =T14-SUM(T19:T21) -> 0.5598 | U22: =U14-SUM(U19:U21) -> 1.780164 | V22: =V14-SUM(V19:V21) -> 5.648382 | W22: =W14-SUM(W19:W21) -> 10.32831 | X22: =X14-SUM(X19:X21) -> 14.02299 | Y22: =Y14-SUM(Y19:Y21) -> 15.545646 | Z22: =Z14-SUM(Z19:Z21) -> 15.607224 | AA22: demand
A23: 5 | B23: =VLOOKUP(E23,$AK$9:$AL$15,2,FALSE)&"."&VLOOKUP(D23,$AH$9:$AI$19,2,FALSE) -> d 1.5 deg OS.a2w2d | C23: 15 | D23: =D12 -> s2_w_p2_d | E23: =E22 -> C2 | S23: *
A24: 5 | B24: =VLOOKUP(E24,$AK$9:$AL$15,2,FALSE)&"."&VLOOKUP(D24,$AH$9:$AI$19,2,FALSE) -> d 1.5 deg OS.hTS12c | C24: 16 | D24: =D13 -> ts12_clu | E24: =E23 -> C2 | G24: CO2 price | I24: 0 | J24: 0 | K24: =SUMIFS(ar6_r10!$F$2:$F$999,ar6_r10!$A$2:$A$999,Veda!$E$5,ar6_r10!$C$2:$C$999,Veda!K$17,ar6_r10!$M$2:$M$999,Veda!$G24) -> 241.69 | L24: =SUMIFS(ar6_r10!$F$2:$F$999,ar6_r10!$A$2:$A$999,Veda!$E$5,ar6_r10!$C$2:$C$999,Veda!L$17,ar6_r10!$M$2:$M$999,Veda!$G24) -> 339.03 | M24: =SUMIFS(ar6_r10!$F$2:$F$999,ar6_r10!$A$2:$A$999,Veda!$E$5,ar6_r10!$C$2:$C$999,Veda!M$17,ar6_r10!$M$2:$M$999,Veda!$G24) -> 410.28 | N24: =SUMIFS(ar6_r10!$F$2:$F$999,ar6_r10!$A$2:$A$999,Veda!$E$5,ar6_r10!$C$2:$C$999,Veda!N$17,ar6_r10!$M$2:$M$999,Veda!$G24) -> 494.2 | O24: =SUMIFS(ar6_r10!$F$2:$F$999,ar6_r10!$A$2:$A$999,Veda!$E$5,ar6_r10!$C$2:$C$999,Veda!O$17,ar6_r10!$M$2:$M$999,Veda!$G24) -> 635.43 | S24: co2net | U24: 0 | V24: =K24/1000 -> 0.24169 | W24: =L24/1000 -> 0.33903 | X24: =M24/1000 -> 0.41028 | Y24: =N24/1000 -> 0.4942 | Z24: =O24/1000 -> 0.63543 | AA24: com_taxnet
A25: 5 | B25: =VLOOKUP(E25,$AK$9:$AL$15,2,FALSE)&"."&VLOOKUP(D25,$AH$9:$AI$19,2,FALSE) -> d 1.5 deg OS.gTS24c | C25: 17 | D25: =D14 -> ts24_clu | E25: =E24 -> C2
A26: 5 | B26: =VLOOKUP(E26,$AK$9:$AL$15,2,FALSE)&"."&VLOOKUP(D26,$AH$9:$AI$19,2,FALSE) -> d 1.5 deg OS.fTS48c | C26: 18 | D26: =D15 -> ts48_clu | E26: =E25 -> C2 | S26: ~TFM_INS-TS
A27: 5 | B27: =VLOOKUP(E27,$AK$9:$AL$15,2,FALSE)&"."&VLOOKUP(D27,$AH$9:$AI$19,2,FALSE) -> d 1.5 deg OS.c15d | C27: 19 | D27: =D16 -> s5p5v5_d | E27: =E26 -> C2 | S27: process | T27: =T17 -> 2022 | U27: =U17 -> 2025 | V27: =V17 -> 2030 | W27: =W17 -> 2035 | X27: =X17 -> 2040 | Y27: =Y17 -> 2045 | Z27: =Z17 -> 2050 | AA27: attribute | AB27: limtype
A28: 5 | B28: =VLOOKUP(E28,$AK$9:$AL$15,2,FALSE)&"."&VLOOKUP(D28,$AH$9:$AI$19,2,FALSE) -> d 1.5 deg OS.f1d | C28: 20 | D28: =D17 -> s1_d | E28: =E27 -> C2 | Q28: =SUMIFS(iea_data!G3:G9999,iea_data!$B$3:$B$9999,Veda!$S$11) -> 7.75 | S28: Trd_electricity import | T28: =Q28 -> 7.75 | AA28: ACT_BND | AB28: FX
A29: 5 | B29: =VLOOKUP(E29,$AK$9:$AL$15,2,FALSE)&"."&VLOOKUP(D29,$AH$9:$AI$19,2,FALSE) -> d 1.5 deg OS.jAnn | C29: 21 | D29: =D18 -> ts_annual | E29: =E28 -> C2 | Q29: =SUMIFS(iea_data!H3:H9999,iea_data!$B$3:$B$9999,Veda!$S$11) -> -4.3 | S29: Trd_electricity export | T29: =-1*Q29 -> 4.3 | AA29: ACT_BND | AB29: FX
A30: 5 | B30: =VLOOKUP(E30,$AK$9:$AL$15,2,FALSE)&"."&VLOOKUP(D30,$AH$9:$AI$19,2,FALSE) -> d 1.5 deg OS.iTS12 | C30: 22 | D30: =D19 -> ts_12 | E30: =E29 -> C2
A31: 5 | B31: =VLOOKUP(E31,$AK$9:$AL$15,2,FALSE)&"."&VLOOKUP(D31,$AH$9:$AI$19,2,FALSE) -> c 2 deg (67%).e3d | C31: 23 | D31: =D20 -> s1p1v1_d | E31: C3
A32: 5 | B32: =VLOOKUP(E32,$AK$9:$AL$15,2,FALSE)&"."&VLOOKUP(D32,$AH$9:$AI$19,2,FALSE) -> c 2 deg (67%).d9d | C32: 24 | D32: =D21 -> s3p3v3_d | E32: =E31 -> C3
A33: 5 | B33: =VLOOKUP(E33,$AK$9:$AL$15,2,FALSE)&"."&VLOOKUP(D33,$AH$9:$AI$19,2,FALSE) -> c 2 deg (67%).b2w | C33: 25 | D33: =D22 -> s2_w | E33: =E32 -> C3
A34: 5 | B34: =VLOOKUP(E34,$AK$9:$AL$15,2,FALSE)&"."&VLOOKUP(D34,$AH$9:$AI$19,2,FALSE) -> c 2 deg (67%).a2w2d | C34: 26 | D34: =D23 -> s2_w_p2_d | E34: =E33 -> C3
A35: 5 | B35: =VLOOKUP(E35,$AK$9:$AL$15,2,FALSE)&"."&VLOOKUP(D35,$AH$9:$AI$19,2,FALSE) -> c 2 deg (67%).hTS12c | C35: 27 | D35: =D24 -> ts12_clu | E35: =E34 -> C3
A36: 5 | B36: =VLOOKUP(E36,$AK$9:$AL$15,2,FALSE)&"."&VLOOKUP(D36,$AH$9:$AI$19,2,FALSE) -> c 2 deg (67%).gTS24c | C36: 28 | D36: =D25 -> ts24_clu | E36: =E35 -> C3 | G36: C7
A37: 5 | B37: =VLOOKUP(E37,$AK$9:$AL$15,2,FALSE)&"."&VLOOKUP(D37,$AH$9:$AI$19,2,FALSE) -> c 2 deg (67%).fTS48c | C37: 29 | D37: =D26 -> ts48_clu | E37: =E36 -> C3 | G37: Gas Price | I37: =SUMIFS(ar6_r10!$F$2:$F$999,ar6_r10!$A$2:$A$999,Veda!$G$36,ar6_r10!$C$2:$C$999,Veda!I$17,ar6_r10!$M$2:$M$999,Veda!$G37) -> 1 | J37: =SUMIFS(ar6_r10!$F$2:$F$999,ar6_r10!$A$2:$A$999,Veda!$G$36,ar6_r10!$C$2:$C$999,Veda!J$17,ar6_r10!$M$2:$M$999,Veda!$G37) -> 1.07 | K37: =SUMIFS(ar6_r10!$F$2:$F$999,ar6_r10!$A$2:$A$999,Veda!$G$36,ar6_r10!$C$2:$C$999,Veda!K$17,ar6_r10!$M$2:$M$999,Veda!$G37) -> 1.24 | L37: =SUMIFS(ar6_r10!$F$2:$F$999,ar6_r10!$A$2:$A$999,Veda!$G$36,ar6_r10!$C$2:$C$999,Veda!L$17,ar6_r10!$M$2:$M$999,Veda!$G37) -> 1.15 | M37: =SUMIFS(ar6_r10!$F$2:$F$999,ar6_r10!$A$2:$A$999,Veda!$G$36,ar6_r10!$C$2:$C$999,Veda!M$17,ar6_r10!$M$2:$M$999,Veda!$G37) -> 1.25 | N37: =SUMIFS(ar6_r10!$F$2:$F$999,ar6_r10!$A$2:$A$999,Veda!$G$36,ar6_r10!$C$2:$C$999,Veda!N$17,ar6_r10!$M$2:$M$999,Veda!$G37) -> 1.17 | O37: =SUMIFS(ar6_r10!$F$2:$F$999,ar6_r10!$A$2:$A$999,Veda!$G$36,ar6_r10!$C$2:$C$999,Veda!O$17,ar6_r10!$M$2:$M$999,Veda!$G37) -> 1.34
A38: 5 | B38: =VLOOKUP(E38,$AK$9:$AL$15,2,FALSE)&"."&VLOOKUP(D38,$AH$9:$AI$19,2,FALSE) -> c 2 deg (67%).c15d | C38: 30 | D38: =D27 -> s5p5v5_d | E38: =E37 -> C3 | G38: Coal Price | I38: =SUMIFS(ar6_r10!$F$2:$F$999,ar6_r10!$A$2:$A$999,Veda!$G$36,ar6_r10!$C$2:$C$999,Veda!I$17,ar6_r10!$M$2:$M$999,Veda!$G38) -> 1 | J38: =SUMIFS(ar6_r10!$F$2:$F$999,ar6_r10!$A$2:$A$999,Veda!$G$36,ar6_r10!$C$2:$C$999,Veda!J$17,ar6_r10!$M$2:$M$999,Veda!$G38) -> 1.02 | K38: =SUMIFS(ar6_r10!$F$2:$F$999,ar6_r10!$A$2:$A$999,Veda!$G$36,ar6_r10!$C$2:$C$999,Veda!K$17,ar6_r10!$M$2:$M$999,Veda!$G38) -> 1.06 | L38: =SUMIFS(ar6_r10!$F$2:$F$999,ar6_r10!$A$2:$A$999,Veda!$G$36,ar6_r10!$C$2:$C$999,Veda!L$17,ar6_r10!$M$2:$M$999,Veda!$G38) -> 1.07 | M38: =SUMIFS(ar6_r10!$F$2:$F$999,ar6_r10!$A$2:$A$999,Veda!$G$36,ar6_r10!$C$2:$C$999,Veda!M$17,ar6_r10!$M$2:$M$999,Veda!$G38) -> 1.08 | N38: =SUMIFS(ar6_r10!$F$2:$F$999,ar6_r10!$A$2:$A$999,Veda!$G$36,ar6_r10!$C$2:$C$999,Veda!N$17,ar6_r10!$M$2:$M$999,Veda!$G38) -> 1.1 | O38: =SUMIFS(ar6_r10!$F$2:$F$999,ar6_r10!$A$2:$A$999,Veda!$G$36,ar6_r10!$C$2:$C$999,Veda!O$17,ar6_r10!$M$2:$M$999,Veda!$G38) -> 1.12
A39: 5 | B39: =VLOOKUP(E39,$AK$9:$AL$15,2,FALSE)&"."&VLOOKUP(D39,$AH$9:$AI$19,2,FALSE) -> c 2 deg (67%).f1d | C39: 31 | D39: =D28 -> s1_d | E39: =E38 -> C3 | G39: Oil Price | I39: =SUMIFS(ar6_r10!$F$2:$F$999,ar6_r10!$A$2:$A$999,Veda!$G$36,ar6_r10!$C$2:$C$999,Veda!I$17,ar6_r10!$M$2:$M$999,Veda!$G39) -> 1 | J39: =SUMIFS(ar6_r10!$F$2:$F$999,ar6_r10!$A$2:$A$999,Veda!$G$36,ar6_r10!$C$2:$C$999,Veda!J$17,ar6_r10!$M$2:$M$999,Veda!$G39) -> 1.01 | K39: =SUMIFS(ar6_r10!$F$2:$F$999,ar6_r10!$A$2:$A$999,Veda!$G$36,ar6_r10!$C$2:$C$999,Veda!K$17,ar6_r10!$M$2:$M$999,Veda!$G39) -> 1.11 | L39: =SUMIFS(ar6_r10!$F$2:$F$999,ar6_r10!$A$2:$A$999,Veda!$G$36,ar6_r10!$C$2:$C$999,Veda!L$17,ar6_r10!$M$2:$M$999,Veda!$G39) -> 1.01 | M39: =SUMIFS(ar6_r10!$F$2:$F$999,ar6_r10!$A$2:$A$999,Veda!$G$36,ar6_r10!$C$2:$C$999,Veda!M$17,ar6_r10!$M$2:$M$999,Veda!$G39) -> 1.01 | N39: =SUMIFS(ar6_r10!$F$2:$F$999,ar6_r10!$A$2:$A$999,Veda!$G$36,ar6_r10!$C$2:$C$999,Veda!N$17,ar6_r10!$M$2:$M$999,Veda!$G39) -> 1.04 | O39: =SUMIFS(ar6_r10!$F$2:$F$999,ar6_r10!$A$2:$A$999,Veda!$G$36,ar6_r10!$C$2:$C$999,Veda!O$17,ar6_r10!$M$2:$M$999,Veda!$G39) -> 1.14
A40: 5 | B40: =VLOOKUP(E40,$AK$9:$AL$15,2,FALSE)&"."&VLOOKUP(D40,$AH$9:$AI$19,2,FALSE) -> c 2 deg (67%).jAnn | C40: 32 | D40: =D29 -> ts_annual | E40: =E39 -> C3 | G40: Biomass Price | I40: =SUMIFS(ar6_r10!$F$2:$F$999,ar6_r10!$A$2:$A$999,Veda!$G$36,ar6_r10!$C$2:$C$999,Veda!I$17,ar6_r10!$M$2:$M$999,Veda!$G40) -> 1 | J40: =SUMIFS(ar6_r10!$F$2:$F$999,ar6_r10!$A$2:$A$999,Veda!$G$36,ar6_r10!$C$2:$C$999,Veda!J$17,ar6_r10!$M$2:$M$999,Veda!$G40) -> 0.96 | K40: =SUMIFS(ar6_r10!$F$2:$F$999,ar6_r10!$A$2:$A$999,Veda!$G$36,ar6_r10!$C$2:$C$999,Veda!K$17,ar6_r10!$M$2:$M$999,Veda!$G40) -> 1.04 | L40: =SUMIFS(ar6_r10!$F$2:$F$999,ar6_r10!$A$2:$A$999,Veda!$G$36,ar6_r10!$C$2:$C$999,Veda!L$17,ar6_r10!$M$2:$M$999,Veda!$G40) -> 1.04 | M40: =SUMIFS(ar6_r10!$F$2:$F$999,ar6_r10!$A$2:$A$999,Veda!$G$36,ar6_r10!$C$2:$C$999,Veda!M$17,ar6_r10!$M$2:$M$999,Veda!$G40) -> 0.98 | N40: =SUMIFS(ar6_r10!$F$2:$F$999,ar6_r10!$A$2:$A$999,Veda!$G$36,ar6_r10!$C$2:$C$999,Veda!N$17,ar6_r10!$M$2:$M$999,Veda!$G40) -> 0.99 | O40: =SUMIFS(ar6_r10!$F$2:$F$999,ar6_r10!$A$2:$A$999,Veda!$G$36,ar6_r10!$C$2:$C$999,Veda!O$17,ar6_r10!$M$2:$M$999,Veda!$G40) -> 1
A41: 5 | B41: =VLOOKUP(E41,$AK$9:$AL$15,2,FALSE)&"."&VLOOKUP(D41,$AH$9:$AI$19,2,FALSE) -> c 2 deg (67%).iTS12 | C41: 33 | D41: =D30 -> ts_12 | E41: =E40 -> C3
A42: 5 | B42: =VLOOKUP(E42,$AK$9:$AL$15,2,FALSE)&"."&VLOOKUP(D42,$AH$9:$AI$19,2,FALSE) -> b 2 deg (50%).e3d | C42: 34 | D42: =D31 -> s1p1v1_d | E42: C4
...

Sheet fuel_prices
A9: Fuel Prices
A10: iso | B10: gas_low | C10: gas_high | D10: coal_low | E10: coal_high | F10: oil_low | G10: oil_high | H10: bioenergy_low | I10: bioenergy_high | J10: Notes
A11: GRC | B11: 29.1 | C11: 41.1 | D11: 15.2 | E11: 18.3 | F11: 50 | G11: 60 | H11: 24 | I11: 32 | J11: TAP pipeline, olive residues

Sheet iea_data
A9: IEA Baseline Data
A10: iso | B10: year | C10: industry_twh | D10: buildings_agri_twh | E10: nonroad_transport_twh | F10: road_transport_twh | G10: imports_twh | H10: exports_twh | I10: total_production_twh
A11: GRC | B11: 2000 | C11: 23.63 | D11: 29.38 | E11: 0.1 | F11: 0 | G11: 1.73 | H11: -1.74 | I11: 53.42
A12: GRC | B12: 2001 | C12: 24.53 | D12: 30.57 | E12: 0.11 | F12: 0 | G12: 3.56 | H12: -1.06 | I12: 53.08
A13: GRC | B13: 2002 | C13: 24.09 | D13: 32.25 | E13: 0.1 | F13: 0 | G13: 4.6 | H13: -1.71 | I13: 53.95
A14: GRC | B14: 2003 | C14: 25.29 | D14: 34.23 | E14: 0.11 | F14: 0 | G14: 4.17 | H14: -2.08 | I14: 57.91
A15: GRC | B15: 2004 | C15: 25.66 | D15: 35.51 | E15: 0.11 | F15: 0 | G15: 4.85 | H15: -2.03 | I15: 58.81
A16: GRC | B16: 2005 | C16: 26.47 | D16: 36.29 | E16: 0.05 | F16: 0 | G16: 5.62 | H16: -1.84 | I16: 59.43
A17: GRC | B17: 2006 | C17: 25.83 | D17: 38.15 | E17: 0.08 | F17: 0 | G17: 6.14 | H17: -1.94 | I17: 60.18
A18: GRC | B18: 2007 | C18: 26.77 | D18: 39.61 | E18: 0.11 | F18: 0 | G18: 6.41 | H18: -2.06 | I18: 62.71
A19: GRC | B19: 2008 | C19: 27 | D19: 40.92 | E19: 0.09 | F19: 0 | G19: 7.58 | H19: -1.96 | I19: 62.91
A20: GRC | B20: 2009 | C20: 24.67 | D20: 40.41 | E20: 0.09 | F20: 0 | G20: 7.6 | H20: -3.23 | I20: 61.07
A21: GRC | B21: 2010 | C21: 24.1 | D21: 38.8 | E21: 0.05 | F21: 0 | G21: 8.52 | H21: -2.81 | I21: 57.38
A22: GRC | B22: 2011 | C22: 25.13 | D22: 36.97 | E22: 0.06 | F22: 0 | G22: 7.18 | H22: -3.95 | I22: 59.17
... A33: GRC | B33: 2022 | C33: 19.75 | D33: 36 | E33: 0.2 | F33: 0.02 | G33: 7.75 | H33: -4.3 | I33: 52.53

Sheet ar6_r10
A9: AR6 Scenario Drivers
A10: Category | B10: Region | C10: Year | D10: count | E10: mean | F10: median | G10: std | H10: min | I10: max | J10: q25 | K10: q75 | L10: category_description | M10: attribute
A11: C1 | B11: R10EUROPE | C11: 2020 | D11: 60 | E11: 8.68 | F11: 6.87 | G11: 10.43 | H11: 0 | I11: 55.17 | J11: 0 | K11: 13.64 | L11: Limit warming to 1.5°C (>50%) with no or limited overshoot | M11: CO2 price
A12: C1 | B12: R10EUROPE | C12: 2025 | D12: 60 | E12: 190.52 | F12: 181.51 | G12: 136.23 | H12: 1.81 | I12: 626.48 | J12: 115.48 | K12: 238.58 | L12: Limit warming to 1.5°C (>50%) with no or limited overshoot | M12: CO2 price
A13: C1 | B13: R10EUROPE | C13: 2030 | D13: 60 | E13: 268.18 | F13: 241.69 | G13: 134.29 | H13: 1.27 | I13: 673.46 | J13: 182.47 | K13: 329.7 | L13: Limit warming to 1.5°C (>50%) with no or limited overshoot | M13: CO2 price
A14: C1 | B14: R10EUROPE | C14: 2035 | D14: 60 | E14: 363.27 | F14: 339.03 | G14: 173.79 | H14: 14.37 | I14: 859.53 | J14: 227.05 | K14: 483.38 | L14: Limit warming to 1.5°C (>50%) with no or limited overshoot | M14: CO2 price
A15: C1 | B15: R10EUROPE | C15: 2040 | D15: 60 | E15: 471.65 | F15: 410.28 | G15: 224.31 | H15: 162.1 | I15: 1097.01 | J15: 298.63 | K15: 622.14 | L15: Limit warming to 1.5°C (>50%) with no or limited overshoot | M15: CO2 price
A16: C1 | B16: R10EUROPE | C16: 2045 | D16: 60 | E16: 565.69 | F16: 494.2 | G16: 256.15 | H16: 193.42 | I16: 1269.88 | J16: 352.78 | K16: 748.01 | L16: Limit warming to 1.5°C (>50%) with no or limited overshoot | M16: CO2 price
A17: C1 | B17: R10EUROPE | C17: 2050 | D17: 60 | E17: 647.44 | F17: 635.43 | G17: 273.56 | H17: 209.76 | I17: 1170.26 | J17: 409.79 | K17: 887.68 | L17: Limit warming to 1.5°C (>50%) with no or limited overshoot | M17: CO2 price
A18: C2 | B18: R10EUROPE | C18: 2020 | D18: 86 | E18: 6.44 | F18: 0 | G18: 8.34 | H18: 0 | I18: 24.5 | J18: 0 | K18: 12.68 | L18: Limit warming to 1.5°C (>67%) with high overshoot | M18: CO2 price
A19: C2 | B19: R10EUROPE | C19: 2025 | D19: 75 | E19: 63.21 | F19: 44.89 | G19: 56.62 | H19: 3.21 | I19: 273 | J19: 27.09 | K19: 77.31 | L19: Limit warming to 1.5°C (>67%) with high overshoot | M19: CO2 price
A20: C2 | B20: R10EUROPE | C20: 2030 | D20: 86 | E20: 85.48 | F20: 63.36 | G20: 73.46 | H20: 0 | I20: 409.5 | J20: 50 | K20: 111.1 | L20: Limit warming to 1.5°C (>67%) with high overshoot | M20: CO2 price
A21: C2 | B21: R10EUROPE | C21: 2035 | D21: 75 | E21: 208.71 | F21: 154.82 | G21: 291.78 | H21: 60.83 | I21: 2037.12 | J21: 93.79 | K21: 206.26 | L21: Limit warming to 1.5°C (>67%) with high overshoot | M21: CO2 price
A22: C2 | B22: R10EUROPE | C22: 2040 | D22: 86 | E22: 253.33 | F22: 172.09 | G22: 359.35 | H22: 0 | I22: 2600 | J22: 119.07 | K22: 259.4 | L22: Limit warming to 1.5°C (>67%) with high overshoot | M22: CO2 price
... A221: C1 | B221: R10EUROPE | C221: 2020 | D221: 33 | E221: 1 | F221: 1 | G221: 0 | H221: 1 | I221: 1 | J221: 1 | K221: 1 | L221: Limit warming to 1.5°C (>50%) with no or limited overshoot | M221: Gas price
A222: C1 | B222: R10EUROPE | C222: 2025 | D222: 34 | E222: 65535 | F222: 2.42 | H222: 1.18 | I222: 65535 | J222: 2.01 | K222: 2.75 | L222: Limit warming to 1.5°C (>50%) with no or limited overshoot | M222: Gas price
A223: C1 | B223: R10EUROPE | C223: 2030 | D223: 34 | E223: 65535 | F223: 3.1 | H223: 1.71 | I223: 65535 | J223: 2.38 | K223: 3.46 | L223: Limit warming to 1.5°C (>50%) with no or limited overshoot | M223: Gas price
A224: C1 | B224: R10EUROPE | C224: 2035 | D224: 34 | E224: 65535 | F224: 3.54 | H224: 1.91 | I224: 65535 | J224: 2.66 | K224: 4.16 | L224: Limit warming to 1.5°C (>50%) with no or limited overshoot | M224: Gas price
A225: C1 | B225: R10EUROPE | C225: 2040 | D225: 34 | E225: 65535 | F225: 4.1 | H225: 2.27 | I225: 65535 | J225: 2.96 | K225: 4.52 | L225: Limit warming to 1.5°C (>50%) with no or limited overshoot | M225: Gas price
A226: C1 | B226: R10EUROPE | C226: 2045 | D226: 34 | E226: 65535 | F226: 3.86 | H226: 2.54 | I226: 65535 | J226: 3.3 | K226: 4.89 | L226: Limit warming to 1.5°C (>50%) with no or limited overshoot | M226: Gas price
A227: C1 | B227: R10EUROPE | C227: 2050 | D227: 34 | E227: 65535 | F227: 3.59 | H227: 2.73 | I227: 65535 | J227: 3.07 | K227: 4.06 | L227: Limit warming to 1.5°C (>50%) with no or limited overshoot | M227: Gas price
A228: C2 | B228: R10EUROPE | C228: 2020 | D228: 43 | E228: 1 | F228: 1 | G228: 0 | H228: 1 | I228: 1 | J228: 1 | K228: 1 | L228: Limit warming to 1.5°C (>67%) with high overshoot | M228: Gas price
A229: C2 | B229: R10EUROPE | C229: 2025 | D229: 44 | E229: 65535 | F229: 1.22 | H229: 0 | I229: 65535 | J229: 1.13 | K229: 1.35 | L229: Limit warming to 1.5°C (>67%) with high overshoot | M229: Gas price
A230: C2 | B230: R10EUROPE | C230: 2030 | D230: 44 | E230: 65535 | F230: 1.5 | H230: 0 | I230: 65535 | J230: 1.31 | K230: 1.83 | L230: Limit warming to 1.5°C (>67%) with high overshoot | M230: Gas price
A231: C2 | B231: R10EUROPE | C231: 2035 | D231: 44 | E231: 65535 | F231: 2.12 | H231: 0 | I231: 65535 | J231: 1.68 | K231: 2.46 | L231: Limit warming to 1.5°C (>67%) with high overshoot | M231: Gas price
A232: C2 | B232: R10EUROPE | C232: 2040 | D232: 44 | E232: 65535 | F232: 2.5 | H232: 0 | I232: 65535 | J232: 2 | K232: 2.94 | L232: Limit warming to 1.5°C (>67%) with high overshoot | M232: Gas price
A233: C2 | B233: R10EUROPE | C233: 2045 | D233: 44 | E233: 65535 | F233: 2.79 | H233: 0 | I233: 65535 | J233: 2.08 | K233: 3.44 | L233: Limit warming to 1.5°C (>67%) with high overshoot | M233: Gas price
A234: C2 | B234: R10EUROPE | C234: 2050 | D234: 44 | E234: 65535 | F234: 2.95 | H234: 0 | I234: 65535 | J234: 2.49 | K234: 3.78 | L234: Limit warming to 1.5°C (>67%) with high overshoot | M234: Gas price
A235: C3 | B235: R10EUROPE | C235: 2020 | D235: 103 | E235: 1 | F235: 1 | G235: 0 | H235: 1 | I235: 1 | J235: 1 | K235: 1 | L235: Limit warming to 2°C (>67%) with higher action post-2030 | M235: Gas price
A236: C3 | B236: R10EUROPE | C236: 2025 | D236: 112 | E236: 65535 | F236: 1.41 | H236: 0.98 | I236: 65535 | J236: 1.23 | K236: 1.96 | L236: Limit warming to 2°C (>67%) with higher action post-2030 | M236: Gas price
A237: C3 | B237: R10EUROPE | C237: 2030 | D237: 112 | E237: 65535 | F237: 2.04 | H237: 1.05 | I237: 65535 | J237: 1.52 | K237: 2.55 | L237: Limit warming to 2°C (>67%) with higher action post-2030 | M237: Gas price
A238: C3 | B238: R10EUROPE | C238: 2035 | D238: 112 | E238: 65535 | F238: 2.4 | H238: 1.05 | I238: 65535 | J238: 1.71 | K238: 3.14 | L238: Limit warming to 2°C (>67%) with higher action post-2030 | M238: Gas price
A239: C3 | B239: R10EUROPE | C239: 2040 | D239: 112 | E239: 65535 | F239: 2.6 | H239: 1.06 | I239: 65535 | J239: 1.85 | K239: 3.74 | L239: Limit warming to 2°C (>67%) with higher action post-2030 | M239: Gas price
A240: C3 | B240: R10EUROPE | C240: 2045 | D240: 112 | E240: 65535 | F240: 2.85 | H240: 1.08 | I240: 65535 | J240: 2 | K240: 4.28 | L240: Limit warming to 2°C (>67%) with higher action post-2030 | M240: Gas price
A241: C3 | B241: R10EUROPE | C241: 2050 | D241: 112 | E241: 65535 | F241: 2.97 | H241: 0 | I241: 65535 | J241: 2.15 | K241: 4.51 | L241: Limit warming to 2°C (>67%) with higher action post-2030 | M241: Gas price
A242: C4 | B242: R10EUROPE | C242: 2020 | D242: 27 | E242: 1 | F242: 1 | G242: 0 | H242: 1 | I242: 1 | J242: 1 | K242: 1 | L242: Limit warming to 2°C (>50%) with immediate action | M242: Gas price
A243: C4 | B243: R10EUROPE | C243: 2025 | D243: 27 | E243: 1.33 | F243: 1.31 | G243: 0.18 | H243: 1.06 | I243: 1.66 | J243: 1.22 | K243: 1.45 | L243: Limit warming to 2°C (>50%) with immediate action | M243: Gas price
A244: C4 | B244: R10EUROPE | C244: 2030 | D244: 27 | E244: 1.84 | F244: 2.02 | G244: 0.28 | H244: 1.24 | I244: 2.17 | J244: 1.52 | K244: 2.07 | L244: Limit warming to 2°C (>50%) with immediate action | M244: Gas price
A245: C4 | B245: R10EUROPE | C245: 2035 | D245: 27 | E245: 1.84 | F245: 1.96 | G245: 0.41 | H245: 1.19 | I245: 2.46 | J245: 1.42 | K245: 2.11 | L245: Limit warming to 2°C (>50%) with immediate action | M245: Gas price
A246: C4 | B246: R10EUROPE | C246: 2040 | D246: 27 | E246: 2.12 | F246: 2.22 | G246: 0.47 | H246: 1.41 | I246: 2.78 | J246: 1.54 | K246: 2.43 | L246: Limit warming to 2°C (>50%) with immediate action | M246: Gas price
...

Sheet ev_charging_uc
A10: =IFERROR(Veda!D5,"ts_12") -> s2_w | C10: day_night | D10: ts12_clu | F10: day_night | G10: ts24_clu | I10: day_night | J10: ts48_clu | L10: day_night | M10: s1_d | O10: day_night | P10: ts_annual | R10: day_night | S10: ts_12
C11: D | D11: S1aH2,S2aH3,S1aH4,S2aH2,S1aH3,S3aH2,S3aH3,S2aH4,S3aH4 | F11: D | G11: S3aH2,S1aH6,S1aH4,S2aH2,S4aH6,S2aH6,S3aH5,S4aH2,S2aH7,S3aH4,S4aH3,S4aH4,S4aH5,S3aH7,S1aH3,S3aH3,S1aH2,S1aH7,S2aH3,S3aH6,S4aH7,S1aH5,S2aH4,S2aH5 | I11: D | J11: S4aH2,S3aH7,S6aH5,S2aH6,S3aH5,S5aH3,S4aH5,S6aH7,S5aH4,S6aH3,S6aH4,S3aH3,S3aH2,S1aH5,S2aH4,S2aH5,S5aH2,S5aH5,S6aH2,S1aH2,S1aH7,S2aH3,S3aH6,S4aH7,S5aH6,S5aH7,S6aH6,S1aH4,S2aH2,S4aH6,S1aH3,S2aH7,S3aH4,S4aH3,S4aH4,S1aH6 | L11: D | M11: S3aH3,S3aH2,S3b1119h13,S3b1119h14,S1aH5,S2aH4,S2aH5,S3b1119h10,S3b1119h15,S3b1119h11,S3b1119h12,S1aH4,S2aH2,S3b1119h17,S4aH6,S1aH3,S3b1119h09,S2aH7,S3aH4,S3b1119h07,S4aH3,S4aH4,S3aH7,S1aH6,S3b1119h08,S4aH5,S1aH2,S1aH7,S2aH3,S3aH6,S4aH7,S3b1119h18,S3b1119h16,S4aH2,S2aH6,S3aH5 | O11: D | P11: AllSaAllH | R11: D | S11: RaD,FaD,RaP,SaD,WaD,FaP,SaP,WaP
C12: N | D12: S3aH1,S3aH5,S1aH1,S2aH1,S1aH5,S2aH5 | F12: N | G12: S3aH8,S4aH8,S1aH9,S4aH1,S1aH8,S2aH1,S2aH9,S3aH9,S2aH8,S1aH1,S3aH1,S4aH9 | I12: N | J12: S2aH1,S5aH8,S1aH1,S2aH8,S4aH8,S1aH8,S5aH1,S3aH1,S3aH8,S4aH1,S6aH1,S6aH8 | L12: N | M12: S3b1119h05,S3b1119h19,S4aH8,S3b1119h02,S3b1119h20,S3aH1,S4aH9,S3aH8,S3b1119h23,S1aH9,S4aH1,S3b1119h22,S3b1119h24,S3aH9,S2aH8,S3b1119h04,S1aH1,S3b1119h03,S3b1119h21,S2aH1,S2aH9,S1aH8,S3b1119h01,S3b1119h06 | O12: N | P12: AllSaAllH | R12: N | S12: SaN,WaN,RaP,FaP,SaP,FaN,RaN,WaP
I17: 0.75 | K17: share of charging at night
C18: ~UC_Sets: R_E: AllRegions
H21: =IF(H23=H24,"Not Required!","~UC_T: LO") -> #N/A
C22: UC_N | D22: Pset_CI | E22: Pset_CO | F22: pset_pn | G22: Cset_CN | H22: TimeSlice | I22: UC_FLO | J22: UC_RHSRT | K22: UC_RHSRT~0
C23: UC_bev night chg limit | D23: ELC | E23: =G23 -> AuxStoIN | F23: *EV* | G23: AuxStoIN | H23: =HLOOKUP($A$10,$D$10:$CU$12,3,FALSE) -> #N/A | I23: =1+I24 -> 0.25 | J23: 0 | K23: 3 | M23: night
D24: ELC | E24: =G24 -> AuxStoIN | F24: *EV* | G24: AuxStoIN | H24: =HLOOKUP($A$10,$D$10:$CU$12,2,FALSE) -> #N/A | I24: =-$I$17 -> -0.75 | M24: day

Sheet ts12_clu
C9: =IF(A11="x","DeActivated","~TimeSlices") -> DeActivated | I9: =IF(A11="x","DeActivated","~TFM_DINS-AT") -> DeActivated | N9: =IF(A11="x","DeActivated","~TFM_DINS-AT") -> DeActivated | S9: =IF(A11="x","DeActivated","~TFM_DINS-AT") -> DeActivated | X9: =IF(A11="x","DeActivated","~TFM_DINS-AT") -> DeActivated | AC9: =IF(A11="x","DeActivated","~TFM_DINS-AT") -> DeActivated | AG9: =IF(A11="x","DeActivated","~TFM_DINS-AT") -> DeActivated | AK9: =IF(A11="x","DeActivated","~TFM_INS-AT") -> DeActivated
A10: ts12_clu | C10: season | D10: weekly | E10: daynite | F10: wparent | G10: dparent | I10: commodity | J10: timeslice | K10: com_fr | L10: process | N10: commodity | O10: timeslice | P10: com_fr | Q10: process | S10: commodity | T10: timeslice | U10: com_fr | V10: process | X10: g_yrfr | Y10: com_fr | Z10: timeslice | AA10: commodity | AC10: commodity | AD10: timeslice | AE10: com_fr | AG10: commodity | AH10: timeslice | AI10: com_pkflx | AK10: timeslice | AL10: ncap_afs | AM10: pset_ci
A11: =IFERROR(IF(Veda!D5=A10,"ok","x"),"") -> x | C11: S1 | D11: a | E11: H1 | F11: S1,S2,S3 | G11: a | I11: elc_spv-GRC_0000 | J11: S1aH1 | K11: 0.02059134 | L11: IMPNRGZ | N11: elc_won-GRC_0000 | O11: S1aH1 | P11: 0.194829 | Q11: IMPNRGZ | S11: elc_wof-GRC_0100 | T11: S1aH1 | U11: 0.18804035 | V11: IMPNRGZ | X11: 0.19417808 | Y11: 0.076684484 | Z11: S1aH1 | AA11: elc_roadtransport | AC11: elc_buildings | AD11: S1aH1 | AE11: 0.15731577 | AG11: ELC | AH11: S1aH1 | AI11: 0.41366692 | AK11: S1 | AL11: 0.87375 | AM11: hydro
C12: S2 | E12: H2 | G12: a | I12: elc_spv-GRC_0000 | J12: S1aH2 | K12: 0.034603514 | L12: IMPNRGZ | N12: elc_won-GRC_0000 | O12: S1aH2 | P12: 0.024459735 | Q12: IMPNRGZ | S12: elc_wof-GRC_0100 | T12: S1aH2 | U12: 0.024748754 | V12: IMPNRGZ | X12: 0.027739726 | Y12: 0.046316784 | Z12: S1aH2 | AA12: elc_roadtransport | AC12: elc_buildings | AD12: S1aH2 | AE12: 0.030496425 | AG12: ELC | AH12: S1aH2 | AI12: 0.18909138 | AK12: S2 | AL12: 0.22329545 | AM12: hydro
C13: S3 | E13: H3 | G13: a | I13: elc_spv-GRC_0000 | J13: S1aH3 | K13: 0.051722957 | L13: IMPNRGZ | N13: elc_won-GRC_0000 | O13: S1aH3 | P13: 0.023639506 | Q13: IMPNRGZ | S13: elc_wof-GRC_0100 | T13: S1aH3 | U13: 0.023785237 | V13: IMPNRGZ | X13: 0.027739726 | Y13: 0.035442409 | Z13: S1aH3 | AA13: elc_roadtransport | AC13: elc_buildings | AD13: S1aH3 | AE13: 0.031727257 | AG13: ELC | AH13: S1aH3 | AI13: 0.23931525 | AK13: S3 | AL13: 0.10295455 | AM13: hydro
E14: H4 | G14: a | I14: elc_spv-GRC_0000 | J14: S1aH4 | K14: 0.56622166 | L14: IMPNRGZ | N14: elc_won-GRC_0000 | O14: S1aH4 | P14: 0.23039006 | Q14: IMPNRGZ | S14: elc_wof-GRC_0100 | T14: S1aH4 | U14: 0.24017083 | V14: IMPNRGZ | X14: 0.22191781 | Y14: 0.30673794 | Z14: S1aH4 | AA14: elc_roadtransport | AC14: elc_buildings | AD14: S1aH4 | AE14: 0.26042918 | AG14: ELC | AH14: S1aH4 | AI14: 0.28176191
E15: H5 | G15: a | I15: elc_spv-GRC_0000 | J15: S1aH5 | K15: 0.07951416 | L15: IMPNRGZ | N15: elc_won-GRC_0000 | O15: S1aH5 | P15: 0.25025306 | Q15: IMPNRGZ | S15: elc_wof-GRC_0100 | T15: S1aH5 | U15: 0.21763506 | V15: IMPNRGZ | X15: 0.19417808 | Y15: 0.20057181 | Z15: S1aH5 | AA15: elc_roadtransport | AC15: elc_buildings | AD15: S1aH5 | AE15: 0.19924644 | AG15: ELC | AH15: S1aH5 | AI15: 0.38335447
I16: elc_spv-GRC_0000 | J16: S2aH1 | K16: 0.0011872213 | L16: IMPNRGZ | N16: elc_won-GRC_0000 | O16: S2aH1 | P16: 0.060076805 | Q16: IMPNRGZ | S16: elc_wof-GRC_0100 | T16: S2aH1 | U16: 0.075227682 | V16: IMPNRGZ | X16: 0.072716895 | Y16: 0.028717235 | Z16: S2aH1 | AA16: elc_roadtransport | AC16: elc_buildings | AD16: S2aH1 | AE16: 0.052461856 | AG16: ELC | AH16: S2aH1 | AI16: 0.36836089
I17: elc_spv-GRC_0000 | J17: S2aH2 | K17: 0.007767198 | L17: IMPNRGZ | N17: elc_won-GRC_0000 | O17: S2aH2 | P17: 0.0080103547 | Q17: IMPNRGZ | S17: elc_wof-GRC_0100 | T17: S2aH2 | U17: 0.0085646909 | V17: IMPNRGZ | X17: 0.010388128 | Y17: 0.017344968 | Z17: S2aH2 | AA17: elc_roadtransport | AC17: elc_buildings | AD17: S2aH2 | AE17: 0.0099627542 | AG17: ELC | AH17: S2aH2 | AI17: 0.18154515
I18: elc_spv-GRC_0000 | J18: S2aH3 | K18: 0.014320823 | L18: IMPNRGZ | N18: elc_won-GRC_0000 | O18: S2aH3 | P18: 0.0082975278 | Q18: IMPNRGZ | S18: elc_wof-GRC_0100 | T18: S2aH3 | U18: 0.0082395264 | V18: IMPNRGZ | X18: 0.010388128 | Y18: 0.013272672 | Z18: S2aH3 | AA18: elc_roadtransport | AC18: elc_buildings | AD18: S2aH3 | AE18: 0.010407338 | AG18: ELC | AH18: S2aH3 | AI18: 0.23150258
I19: elc_spv-GRC_0000 | J19: S2aH4 | K19: 0.16613964 | L19: IMPNRGZ | N19: elc_won-GRC_0000 | O19: S2aH4 | P19: 0.072994264 | Q19: IMPNRGZ | S19: elc_wof-GRC_0100 | T19: S2aH4 | U19: 0.071488166 | V19: IMPNRGZ | X19: 0.083105023 | Y19: 0.11486894 | Z19: S2aH4 | AA19: elc_roadtransport | AC19: elc_buildings | AD19: S2aH4 | AE19: 0.085510461 | AG19: ELC | AH19: S2aH4 | AI19: 0.24655656
I20: elc_spv-GRC_0000 | J20: S2aH5 | K20: 0.009936505 | L20: IMPNRGZ | N20: elc_won-GRC_0000 | O20: S2aH5 | P20: 0.068643829 | Q20: IMPNRGZ | S20: elc_wof-GRC_0100 | T20: S2aH5 | U20: 0.058936903 | V20: IMPNRGZ | X20: 0.072716895 | Y20: 0.075111255 | Z20: S2aH5 | AA20: elc_roadtransport | AC20: elc_buildings | AD20: S2aH5 | AE20: 0.067086051 | AG20: ELC | AH20: S2aH5 | AI20: 0.31512174
I21: elc_spv-GRC_0000 | J21: S3aH1 | K21: 0 | L21: IMPNRGZ | N21: elc_won-GRC_0000 | O21: S3aH1 | P21: 0.015867122 | Q21: IMPNRGZ | S21: elc_wof-GRC_0100 | T21: S3aH1 | U21: 0.025343254 | V21: IMPNRGZ | X21: 0.024771689 | Y21: 0.0097827943 | Z21: S3aH1 | AA21: elc_roadtransport | AC21: elc_buildings | AD21: S3aH1 | AE21: 0.022339264 | AG21: ELC | AH21: S3aH1 | AI21: 0.30726019
I22: elc_spv-GRC_0000 | J22: S3aH2 | K22: 0 | L22: IMPNRGZ | N22: elc_won-GRC_0000 | O22: S3aH2 | P22: 0.0024295256 | Q22: IMPNRGZ | S22: elc_wof-GRC_0100 | T22: S3aH2 | U22: 0.0043948 | V22: IMPNRGZ | X22: 0.0035388128 | Y22: 0.0059087255 | Z22: S3aH2 | AA22: elc_roadtransport | AC22: elc_buildings | AD22: S3aH2 | AE22: 0.0042579411 | AG22: ELC | AH22: S3aH2 | AI22: 0.085071887
I23: elc_spv-GRC_0000 | J23: S3aH3 | K23: 0.0027227402 | L23: IMPNRGZ | N23: elc_won-GRC_0000 | O23: S3aH3 | P23: 0.0025039598 | Q23: IMPNRGZ | S23: elc_wof-GRC_0100 | T23: S3aH3 | U23: 0.0045260464 | V23: IMPNRGZ | X23: 0.0035388128 | Y23: 0.0045214595 | Z23: S3aH3 | AA23: elc_roadtransport | AC23: elc_buildings | AD23: S3aH3 | AE23: 0.0043283482 | AG23: ELC | AH23: S3aH3 | AI23: 0.075104511
I24: elc_spv-GRC_0000 | J24: S3aH4 | K24: 0.045272238 | L24: IMPNRGZ | N24: elc_won-GRC_0000 | O24: S3aH4 | P24: 0.020300938 | Q24: IMPNRGZ | S24: elc_wof-GRC_0100 | T24: S3aH4 | U24: 0.031499489 | V24: IMPNRGZ | X24: 0.028310502 | Y24: 0.039131177 | Z24: S3aH4 | AA24: elc_roadtransport | AC24: elc_buildings | AD24: S3aH4 | AE24: 0.035353738 | AG24: ELC | AH24: S3aH4 | AI24: 0.1523381
I25: elc_spv-GRC_0000 | J25: S3aH5 | K25: 0 | L25: IMPNRGZ | N25: elc_won-GRC_0000 | O25: S3aH5 | P25: 0.017304311 | Q25: IMPNRGZ | S25: elc_wof-GRC_0100 | T25: S3aH5 | U25: 0.017399209 | V25: IMPNRGZ | X25: 0.024771689 | Y25: 0.025587351 | Z25: S3aH5 | AA25: elc_roadtransport | AC25: elc_buildings | AD25: S3aH5 | AE25: 0.029077177 | AG25: ELC | AH25: S3aH5 | AI25: 0.2339143
I26: elc_spv-GRC_0001 | J26: S1aH1 | K26: 0.021074279 | L26: IMPNRGZ | N26: elc_won-GRC_0001 | O26: S1aH1 | P26: 0.18156309 | Q26: IMPNRGZ | S26: elc_wof-GRC_0104 | T26: S1aH1 | U26: 0.2141412 | V26: IMPNRGZ | AC26: elc_industry | AD26: S1aH1 | AE26: 0.1911028
I27: elc_spv-GRC_0001 | J27: S1aH2 | K27: 0.034670156 | L27: IMPNRGZ | N27: elc_won-GRC_0001 | O27: S1aH2 | P27: 0.022470795 | Q27: IMPNRGZ | S27: elc_wof-GRC_0104 | T27: S1aH2 | U27: 0.029268929 | V27: IMPNRGZ | AC27: elc_industry | AD27: S1aH2 | AE27: 0.02791102
I28: elc_spv-GRC_0001 | J28: S1aH3 | K28: 0.051840669 | L28: IMPNRGZ | N28: elc_won-GRC_0001 | O28: S1aH3 | P28: 0.021703971 | Q28: IMPNRGZ | S28: elc_wof-GRC_0104 | T28: S1aH3 | U28: 0.029318238 | V28: IMPNRGZ | AC28: elc_industry | AD28: S1aH3 | AE28: 0.0280047
I29: elc_spv-GRC_0001 | J29: S1aH4 | K29: 0.5620056 | L29: IMPNRGZ | N29: elc_won-GRC_0001 | O29: S1aH4 | P29: 0.24507925 | Q29: IMPNRGZ | S29: elc_wof-GRC_0104 | T29: S1aH4 | U29: 0.26362412 | V29: IMPNRGZ | AC29: elc_industry | AD29: S1aH4 | AE29: 0.22454078
I30: elc_spv-GRC_0001 | J30: S1aH5 | K30: 0.078927561 | L30: IMPNRGZ | N30: elc_won-GRC_0001 | O30: S1aH5 | P30: 0.2495773 | Q30: IMPNRGZ | S30: elc_wof-GRC_0104 | T30: S1aH5 | U30: 0.22759996 | V30: IMPNRGZ | AC30: elc_industry | AD30: S1aH5 | AE30: 0.19429419
I31: elc_spv-GRC_0001 | J31: S2aH1 | K31: 0.0012832623 | L31: IMPNRGZ | N31: elc_won-GRC_0001 | O31: S2aH1 | P31: 0.059057378 | Q31: IMPNRGZ | S31: elc_wof-GRC_0104 | T31: S2aH1 | U31: 0.044994495 | V31: IMPNRGZ | AC31: elc_industry | AD31: S2aH1 | AE31: 0.071653732
I32: elc_spv-GRC_0001 | J32: S2aH2 | K32: 0.0077970188 | L32: IMPNRGZ | N32: elc_won-GRC_0001 | O32: S2aH2 | P32: 0.0081911827 | Q32: IMPNRGZ | S32: elc_wof-GRC_0104 | T32: S2aH2 | U32: 0.0059841791 | V32: IMPNRGZ | AC32: elc_industry | AD32: S2aH2 | AE32: 0.010424105
I33: elc_spv-GRC_0001 | J33: S2aH3 | K33: 0.014500914 | L33: IMPNRGZ | N33: elc_won-GRC_0001 | O33: S2aH3 | P33: 0.0088057194 | Q33: IMPNRGZ | S33: elc_wof-GRC_0104 | T33: S2aH3 | U33: 0.0059760968 | V33: IMPNRGZ | AC33: elc_industry | AD33: S2aH3 | AE33: 0.010457943
I34: elc_spv-GRC_0001 | J34: S2aH4 | K34: 0.16823525 | L34: IMPNRGZ | N34: elc_won-GRC_0001 | O34: S2aH4 | P34: 0.080246615 | Q34: IMPNRGZ | S34: elc_wof-GRC_0104 | T34: S2aH4 | U34: 0.051906195 | V34: IMPNRGZ | AC34: elc_industry | AD34: S2aH4 | AE34: 0.083834929
I35: elc_spv-GRC_0001 | J35: S2aH5 | K35: 0.010086705 | L35: IMPNRGZ | N35: elc_won-GRC_0001 | O35: S2aH5 | P35: 0.070448154 | Q35: IMPNRGZ | S35: elc_wof-GRC_0104 | T35: S2aH5 | U35: 0.046533624 | V35: IMPNRGZ | AC35: elc_industry | AD35: S2aH5 | AE35: 0.072766797
I36: elc_spv-GRC_0001 | J36: S3aH1 | K36: 0 | L36: IMPNRGZ | N36: elc_won-GRC_0001 | O36: S3aH1 | P36: 0.014241699 | Q36: IMPNRGZ | S36: elc_wof-GRC_0104 | T36: S3aH1 | U36: 0.025321678 | V36: IMPNRGZ | AC36: elc_industry | AD36: S3aH1 | AE36: 0.024377733
I37: elc_spv-GRC_0001 | J37: S3aH2 | K37: 0 | L37: IMPNRGZ | N37: elc_won-GRC_0001 | O37: S3aH2 | P37: 0.0022212365 | Q37: IMPNRGZ | S37: elc_wof-GRC_0104 | T37: S3aH2 | U37: 0.00345881 | V37: IMPNRGZ | AC37: elc_industry | AD37: S3aH2 | AE37: 0.0035637147
... I40: elc_spv-GRC_0001 | J40: S3aH5 | K40: 0 | L40: IMPNRGZ | N40: elc_won-GRC_0001 | O40: S3aH5 | P40: 0.014807621 | Q40: IMPNRGZ | S40: elc_wof-GRC_0104 | T40: S3aH5 | U40: 0.021924771 | V40: IMPNRGZ | AC40: elc_industry | AD40: S3aH5 | AE40: 0.024890563
I41: elc_spv-GRC_0010 | J41: S1aH1 | K41: 0.021092576 | L41: IMPNRGZ | N41: elc_won-GRC_0010 | O41: S1aH1 | P41: 0.18602835 | Q41: IMPNRGZ | S41: elc_wof-GRC_0105 | T41: S1aH1 | U41: 0.18873656 | V41: IMPNRGZ
I42: elc_spv-GRC_0010 | J42: S1aH2 | K42: 0.035790487 | L42: IMPNRGZ | N42: elc_won-GRC_0010 | O42: S1aH2 | P42: 0.024078574 | Q42: IMPNRGZ | S42: elc_wof-GRC_0105 | T42: S1aH2 | U42: 0.028156129 | V42: IMPNRGZ
I43: elc_spv-GRC_0010 | J43: S1aH3 | K43: 0.053516478 | L43: IMPNRGZ | N43: elc_won-GRC_0010 | O43: S1aH3 | P43: 0.023341544 | Q43: IMPNRGZ | S43: elc_wof-GRC_0105 | T43: S1aH3 | U43: 0.028998555 | V43: IMPNRGZ
I44: elc_spv-GRC_0010 | J44: S1aH4 | K44: 0.56881667 | L44: IMPNRGZ | N44: elc_won-GRC_0010 | O44: S1aH4 | P44: 0.24795107 | Q44: IMPNRGZ | S44: elc_wof-GRC_0105 | T44: S1aH4 | U44: 0.2507837 | V44: IMPNRGZ
I45: elc_spv-GRC_0010 | J45: S1aH5 | K45: 0.074287284 | L45: IMPNRGZ | N45: elc_won-GRC_0010 | O45: S1aH5 | P45: 0.25812097 | Q45: IMPNRGZ | S45: elc_wof-GRC_0105 | T45: S1aH5 | U45: 0.18773045 | V45: IMPNRGZ
I46: elc_spv-GRC_0010 | J46: S2aH1 | K46: 0.0014690707 | L46: IMPNRGZ | N46: elc_won-GRC_0010 | O46: S2aH1 | P46: 0.055415322 | Q46: IMPNRGZ | S46: elc_wof-GRC_0105 | T46: S2aH1 | U46: 0.058274801 | V46: IMPNRGZ
I47: elc_spv-GRC_0010 | J47: S2aH2 | K47: 0.0083580259 | L47: IMPNRGZ | N47: elc_won-GRC_0010 | O47: S2aH2 | P47: 0.0071428657 | Q47: IMPNRGZ | S47: elc_wof-GRC_0105 | T47: S2aH2 | U47: 0.0090739713 | V47: IMPNRGZ
I48: elc_spv-GRC_0010 | J48: S2aH3 | K48: 0.015098009 | L48: IMPNRGZ | N48: elc_won-GRC_0010 | O48: S2aH3 | P48: 0.0070664599 | Q48: IMPNRGZ | S48: elc_wof-GRC_0105 | T48: S2aH3 | U48: 0.0091597613 | V48: IMPNRGZ
I49: elc_spv-GRC_0010 | J49: S2aH4 | K49: 0.16506044 | L49: IMPNRGZ | N49: elc_won-GRC_0010 | O49: S2aH4 | P49: 0.066919855 | Q49: IMPNRGZ | S49: elc_wof-GRC_0105 | T49: S2aH4 | U49: 0.078102737 | V49: IMPNRGZ
I50: elc_spv-GRC_0010 | J50: S2aH5 | K50: 0.0090378325 | L50: IMPNRGZ | N50: elc_won-GRC_0010 | O50: S2aH5 | P50: 0.062052886 | Q50: IMPNRGZ | S50: elc_wof-GRC_0105 | T50: S2aH5 | U50: 0.062300516 | V50: IMPNRGZ
...

Sheet ts24_clu
C9: =IF(A11="x","DeActivated","~TimeSlices") -> DeActivated | I9: =IF(A11="x","DeActivated","~TFM_DINS-AT") -> DeActivated | N9: =IF(A11="x","DeActivated","~TFM_DINS-AT") -> DeActivated | S9: =IF(A11="x","DeActivated","~TFM_DINS-AT") -> DeActivated | X9: =IF(A11="x","DeActivated","~TFM_DINS-AT") -> DeActivated | AC9: =IF(A11="x","DeActivated","~TFM_DINS-AT") -> DeActivated | AG9: =IF(A11="x","DeActivated","~TFM_DINS-AT") -> DeActivated | AK9: =IF(A11="x","DeActivated","~TFM_INS-AT") -> DeActivated
A10: ts24_clu | C10: season | D10: weekly | E10: daynite | F10: wparent | G10: dparent | I10: commodity | J10: timeslice | K10: com_fr | L10: process | N10: commodity | O10: timeslice | P10: com_fr | Q10: process | S10: commodity | T10: timeslice | U10: com_fr | V10: process | X10: g_yrfr | Y10: com_fr | Z10: timeslice | AA10: commodity | AC10: commodity | AD10: timeslice | AE10: com_fr | AG10: commodity | AH10: timeslice | AI10: com_pkflx | AK10: timeslice | AL10: ncap_afs | AM10: pset_ci
A11: =IFERROR(IF(Veda!D5=A10,"ok","x"),"") -> x | C11: S1 | D11: a | E11: H1 | F11: S1,S2,S3,S4 | G11: a | I11: elc_spv-GRC_0000 | J11: S1aH1 | K11: 0.0024139239 | L11: IMPNRGZ | N11: elc_won-GRC_0000 | O11: S1aH1 | P11: 0.14054506 | Q11: IMPNRGZ | S11: elc_wof-GRC_0100 | T11: S1aH1 | U11: 0.14320032 | V11: IMPNRGZ | X11: 0.1239726 | Y11: 0.026519487 | Z11: S1aH1 | AA11: elc_roadtransport | AC11: elc_buildings | AD11: S1aH1 | AE11: 0.09347113 | AG11: ELC | AH11: S1aH1 | AI11: 0.38767808 | AK11: S1 | AL11: 0.62522727 | AM11: hydro
C12: S2 | E12: H2 | G12: a | I12: elc_spv-GRC_0000 | J12: S1aH2 | K12: 0.010416959 | L12: IMPNRGZ | N12: elc_won-GRC_0000 | O12: S1aH2 | P12: 0.022296913 | Q12: IMPNRGZ | S12: elc_wof-GRC_0100 | T12: S1aH2 | U12: 0.023243127 | V12: IMPNRGZ | X12: 0.0206621 | Y12: 0.030599408 | Z12: S1aH2 | AA12: elc_roadtransport | AC12: elc_buildings | AD12: S1aH2 | AE12: 0.020414058 | AG12: ELC | AH12: S1aH2 | AI12: 0.21967487 | AK12: S4 | AL12: 0.10295455 | AM12: hydro
C13: S3 | E13: H3 | G13: a | I13: elc_spv-GRC_0000 | J13: S1aH3 | K13: 0.021408687 | L13: IMPNRGZ | N13: elc_won-GRC_0000 | O13: S1aH3 | P13: 0.021760632 | Q13: IMPNRGZ | S13: elc_wof-GRC_0100 | T13: S1aH3 | U13: 0.022087119 | V13: IMPNRGZ | X13: 0.0206621 | Y13: 0.034499333 | Z13: S1aH3 | AA13: elc_roadtransport | AC13: elc_buildings | AD13: S1aH3 | AE13: 0.021962482 | AG13: ELC | AH13: S1aH3 | AI13: 0.21300976 | AK13: S2 | AL13: 0.24852273 | AM13: hydro
C14: S4 | E14: H4 | G14: a | I14: elc_spv-GRC_0000 | J14: S1aH4 | K14: 0.03458057 | L14: IMPNRGZ | N14: elc_won-GRC_0000 | O14: S1aH4 | P14: 0.02126073 | Q14: IMPNRGZ | S14: elc_wof-GRC_0100 | T14: S1aH4 | U14: 0.021261114 | V14: IMPNRGZ | X14: 0.0206621 | Y14: 0.02639949 | Z14: S1aH4 | AA14: elc_roadtransport | AC14: elc_buildings | AD14: S1aH4 | AE14: 0.022496841 | AG14: ELC | AH14: S1aH4 | AI14: 0.2046286 | AK14: S3 | AL14: 0.22329545 | AM14: hydro
E15: H5 | G15: a | I15: elc_spv-GRC_0000 | J15: S1aH5 | K15: 0.35639327 | L15: IMPNRGZ | N15: elc_won-GRC_0000 | O15: S1aH5 | P15: 0.16448629 | Q15: IMPNRGZ | S15: elc_wof-GRC_0100 | T15: S1aH5 | U15: 0.18058271 | V15: IMPNRGZ | X15: 0.1446347 | Y15: 0.18827636 | Z15: S1aH5 | AA15: elc_roadtransport | AC15: elc_buildings | AD15: S1aH5 | AE15: 0.15970551 | AG15: ELC | AH15: S1aH5 | AI15: 0.2908656
E16: H6 | G16: a | I16: elc_spv-GRC_0000 | J16: S1aH6 | K16: 0.041941006 | L16: IMPNRGZ | N16: elc_won-GRC_0000 | O16: S1aH6 | P16: 0.027404187 | Q16: IMPNRGZ | S16: elc_wof-GRC_0100 | T16: S1aH6 | U16: 0.030690511 | V16: IMPNRGZ | X16: 0.0206621 | Y16: 0.040199223 | Z16: S1aH6 | AA16: elc_roadtransport | AC16: elc_buildings | AD16: S1aH6 | AE16: 0.023906176 | AG16: ELC | AH16: S1aH6 | AI16: 0.25480609
E17: H7 | G17: a | I17: elc_spv-GRC_0000 | J17: S1aH7 | K17: 0.030197591 | L17: IMPNRGZ | N17: elc_won-GRC_0000 | O17: S1aH7 | P17: 0.027650388 | Q17: IMPNRGZ | S17: elc_wof-GRC_0100 | T17: S1aH7 | U17: 0.029928623 | V17: IMPNRGZ | X17: 0.0206621 | Y17: 0.040199223 | Z17: S1aH7 | AA17: elc_roadtransport | AC17: elc_buildings | AD17: S1aH7 | AE17: 0.024143872 | AG17: ELC | AH17: S1aH7 | AI17: 0.24968173
E18: H8 | G18: a | I18: elc_spv-GRC_0000 | J18: S1aH8 | K18: 0.015748242 | L18: IMPNRGZ | N18: elc_won-GRC_0000 | O18: S1aH8 | P18: 0.027665653 | Q18: IMPNRGZ | S18: elc_wof-GRC_0100 | T18: S1aH8 | U18: 0.029174774 | V18: IMPNRGZ | X18: 0.0206621 | Y18: 0.031199397 | Z18: S1aH8 | AA18: elc_roadtransport | AC18: elc_buildings | AD18: S1aH8 | AE18: 0.023909565 | AG18: ELC | AH18: S1aH8 | AI18: 0.21345946
E19: H9 | G19: a | I19: elc_spv-GRC_0000 | J19: S1aH9 | K19: 0.0039976088 | L19: IMPNRGZ | N19: elc_won-GRC_0000 | O19: S1aH9 | P19: 0.13476782 | Q19: IMPNRGZ | S19: elc_wof-GRC_0100 | T19: S1aH9 | U19: 0.13267113 | V19: IMPNRGZ | X19: 0.1033105 | Y19: 0.077998492 | Z19: S1aH9 | AA19: elc_roadtransport | AC19: elc_buildings | AD19: S1aH9 | AE19: 0.097386325 | AG19: ELC | AH19: S1aH9 | AI19: 0.35313463
I20: elc_spv-GRC_0000 | J20: S2aH1 | K20: 0.00025328159 | L20: IMPNRGZ | N20: elc_won-GRC_0000 | O20: S2aH1 | P20: 0.028841789 | Q20: IMPNRGZ | S20: elc_wof-GRC_0100 | T20: S2aH1 | U20: 0.018894905 | V20: IMPNRGZ | X20: 0.042465753 | Y20: 0.0090840232 | Z20: S2aH1 | AA20: elc_roadtransport | AC20: elc_buildings | AD20: S2aH1 | AE20: 0.035450834 | AG20: ELC | AH20: S2aH1 | AI20: 0.25039166
I21: elc_spv-GRC_0000 | J21: S2aH2 | K21: 0.007507175 | L21: IMPNRGZ | N21: elc_won-GRC_0000 | O21: S2aH2 | P21: 0.0031452431 | Q21: IMPNRGZ | S21: elc_wof-GRC_0100 | T21: S2aH2 | U21: 0.0027019939 | V21: IMPNRGZ | X21: 0.0070776256 | Y21: 0.010481565 | Z21: S2aH2 | AA21: elc_roadtransport | AC21: elc_buildings | AD21: S2aH2 | AE21: 0.0079797433 | AG21: ELC | AH21: S2aH2 | AI21: 0.097551035
I22: elc_spv-GRC_0000 | J22: S2aH3 | K22: 0.013194827 | L22: IMPNRGZ | N22: elc_won-GRC_0000 | O22: S2aH3 | P22: 0.0026991027 | Q22: IMPNRGZ | S22: elc_wof-GRC_0100 | T22: S2aH3 | U22: 0.0026616347 | V22: IMPNRGZ | X22: 0.0070776256 | Y22: 0.011817451 | Z22: S2aH3 | AA22: elc_roadtransport | AC22: elc_buildings | AD22: S2aH3 | AE22: 0.0085339431 | AG22: ELC | AH22: S2aH3 | AI22: 0.10767459
I23: elc_spv-GRC_0000 | J23: S2aH4 | K23: 0.017142387 | L23: IMPNRGZ | N23: elc_won-GRC_0000 | O23: S2aH4 | P23: 0.002378776 | Q23: IMPNRGZ | S23: elc_wof-GRC_0100 | T23: S2aH4 | U23: 0.0025241236 | V23: IMPNRGZ | X23: 0.0070776256 | Y23: 0.0090429191 | Z23: S2aH4 | AA23: elc_roadtransport | AC23: elc_buildings | AD23: S2aH4 | AE23: 0.0092304155 | AG23: ELC | AH23: S2aH4 | AI23: 0.11816592
I24: elc_spv-GRC_0000 | J24: S2aH5 | K24: 0.14942084 | L24: IMPNRGZ | N24: elc_won-GRC_0000 | O24: S2aH5 | P24: 0.029771878 | Q24: IMPNRGZ | S24: elc_wof-GRC_0100 | T24: S2aH5 | U24: 0.021402144 | V24: IMPNRGZ | X24: 0.049543379 | Y24: 0.064492455 | Z24: S2aH5 | AA24: elc_roadtransport | AC24: elc_buildings | AD24: S2aH5 | AE24: 0.067386002 | AG24: ELC | AH24: S2aH5 | AI24: 0.14057688
I25: elc_spv-GRC_0000 | J25: S2aH6 | K25: 0.018466543 | L25: IMPNRGZ | N25: elc_won-GRC_0000 | O25: S2aH6 | P25: 0.0087276979 | Q25: IMPNRGZ | S25: elc_wof-GRC_0100 | T25: S2aH6 | U25: 0.0074954657 | V25: IMPNRGZ | X25: 0.0070776256 | Y25: 0.013769899 | Z25: S2aH6 | AA25: elc_roadtransport | AC25: elc_buildings | AD25: S2aH6 | AE25: 0.0094314908 | AG25: ELC | AH25: S2aH6 | AI25: 0.099493044
I26: elc_spv-GRC_0000 | J26: S2aH7 | K26: 0.015230579 | L26: IMPNRGZ | N26: elc_won-GRC_0000 | O26: S2aH7 | P26: 0.0092091822 | Q26: IMPNRGZ | S26: elc_wof-GRC_0100 | T26: S2aH7 | U26: 0.0067765433 | V26: IMPNRGZ | X26: 0.0070776256 | Y26: 0.013769899 | Z26: S2aH7 | AA26: elc_roadtransport | AC26: elc_buildings | AD26: S2aH7 | AE26: 0.0089399756 | AG26: ELC | AH26: S2aH7 | AI26: 0.091192684
I27: elc_spv-GRC_0000 | J27: S2aH8 | K27: 0.010378977 | L27: IMPNRGZ | N27: elc_won-GRC_0000 | O27: S2aH8 | P27: 0.0094186338 | Q27: IMPNRGZ | S27: elc_wof-GRC_0100 | T27: S2aH8 | U27: 0.0053462106 | V27: IMPNRGZ | X27: 0.0070776256 | Y27: 0.010687086 | Z27: S2aH8 | AA27: elc_roadtransport | AC27: elc_buildings | AD27: S2aH8 | AE27: 0.0087843938 | AG27: ELC | AH27: S2aH8 | AI27: 0.084621785
I28: elc_spv-GRC_0000 | J28: S2aH9 | K28: 0.0039611622 | L28: IMPNRGZ | N28: elc_won-GRC_0000 | O28: S2aH9 | P28: 0.041541382 | Q28: IMPNRGZ | S28: elc_wof-GRC_0100 | T28: S2aH9 | U28: 0.013737779 | V28: IMPNRGZ | X28: 0.035388128 | Y28: 0.026717715 | Z28: S2aH9 | AA28: elc_roadtransport | AC28: elc_buildings | AD28: S2aH9 | AE28: 0.036082311 | AG28: ELC | AH28: S2aH9 | AI28: 0.23411692
I29: elc_spv-GRC_0000 | J29: S3aH1 | K29: 0 | L29: IMPNRGZ | N29: elc_won-GRC_0000 | O29: S3aH1 | P29: 0.052088742 | Q29: IMPNRGZ | S29: elc_wof-GRC_0100 | T29: S3aH1 | U29: 0.065666263 | V29: IMPNRGZ | X29: 0.062328767 | Y29: 0.013333002 | Z29: S3aH1 | AA29: elc_roadtransport | AC29: elc_buildings | AD29: S3aH1 | AE29: 0.043221432 | AG29: ELC | AH29: S3aH1 | AI29: 0.28353425
I30: elc_spv-GRC_0000 | J30: S3aH2 | K30: 0.0011872213 | L30: IMPNRGZ | N30: elc_won-GRC_0000 | O30: S3aH2 | P30: 0.0079880629 | Q30: IMPNRGZ | S30: elc_wof-GRC_0100 | T30: S3aH2 | U30: 0.0095614197 | V30: IMPNRGZ | X30: 0.010388128 | Y30: 0.015384233 | Z30: S3aH2 | AA30: elc_roadtransport | AC30: elc_buildings | AD30: S3aH2 | AE30: 0.0092404234 | AG30: ELC | AH30: S3aH2 | AI30: 0.17761054
I31: elc_spv-GRC_0000 | J31: S3aH3 | K31: 0.007767198 | L31: IMPNRGZ | N31: elc_won-GRC_0000 | O31: S3aH3 | P31: 0.0080103547 | Q31: IMPNRGZ | S31: elc_wof-GRC_0100 | T31: S3aH3 | U31: 0.0085646909 | V31: IMPNRGZ | X31: 0.010388128 | Y31: 0.017344968 | Z31: S3aH3 | AA31: elc_roadtransport | AC31: elc_buildings | AD31: S3aH3 | AE31: 0.0099627542 | AG31: ELC | AH31: S3aH3 | AI31: 0.18154515
... I46: elc_spv-GRC_0000 | J46: S4aH9 | K46: 0 | L46: IMPNRGZ | N46: elc_won-GRC_0000 | O46: S4aH9 | P46: 0.011857563 | Q46: IMPNRGZ | S46: elc_wof-GRC_0100 | T46: S4aH9 | U46: 0.010888513 | V46: IMPNRGZ | X46: 0.017694064 | Y46: 0.013358858 | Z46: S4aH9 | AA46: elc_roadtransport | AC46: elc_buildings | AD46: S4aH9 | AE46: 0.019354083 | AG46: ELC | AH46: S4aH9 | AI46: 0.2046589
I47: elc_spv-GRC_0001 | J47: S1aH1 | K47: 0.0024809564 | L47: IMPNRGZ | N47: elc_won-GRC_0001 | O47: S1aH1 | P47: 0.13525984 | Q47: IMPNRGZ | S47: elc_wof-GRC_0104 | T47: S1aH1 | U47: 0.14206056 | V47: IMPNRGZ | AC47: elc_industry | AD47: S1aH1 | AE47: 0.12179694
I48: elc_spv-GRC_0001 | J48: S1aH2 | K48: 0.010412676 | L48: IMPNRGZ | N48: elc_won-GRC_0001 | O48: S1aH2 | P48: 0.021032524 | Q48: IMPNRGZ | S48: elc_wof-GRC_0104 | T48: S1aH2 | U48: 0.022656052 | V48: IMPNRGZ | AC48: elc_industry | AD48: S1aH2 | AE48: 0.020667529
I49: elc_spv-GRC_0001 | J49: S1aH3 | K49: 0.021054998 | L49: IMPNRGZ | N49: elc_won-GRC_0001 | O49: S1aH3 | P49: 0.020503203 | Q49: IMPNRGZ | S49: elc_wof-GRC_0104 | T49: S1aH3 | U49: 0.022451864 | V49: IMPNRGZ | AC49: elc_industry | AD49: S1aH3 | AE49: 0.020785381
I50: elc_spv-GRC_0001 | J50: S1aH4 | K50: 0.03416273 | L50: IMPNRGZ | N50: elc_won-GRC_0001 | O50: S1aH4 | P50: 0.019998041 | Q50: IMPNRGZ | S50: elc_wof-GRC_0104 | T50: S1aH4 | U50: 0.02251569 | V50: IMPNRGZ | AC50: elc_industry | AD50: S1aH4 | AE50: 0.020826052
I51: elc_spv-GRC_0001 | J51: S1aH5 | K51: 0.35322722 | L51: IMPNRGZ | N51: elc_won-GRC_0001 | O51: S1aH5 | P51: 0.17222151 | Q51: IMPNRGZ | S51: elc_wof-GRC_0104 | T51: S1aH5 | U51: 0.17200699 | V51: IMPNRGZ | AC51: elc_industry | AD51: S1aH5 | AE51: 0.14595191
I52: elc_spv-GRC_0001 | J52: S1aH6 | K52: 0.0413438 | L52: IMPNRGZ | N52: elc_won-GRC_0001 | O52: S1aH6 | P52: 0.029504329 | Q52: IMPNRGZ | S52: elc_wof-GRC_0104 | T52: S1aH6 | U52: 0.025558875 | V52: IMPNRGZ | AC52: elc_industry | AD52: S1aH6 | AE52: 0.020933318
I53: elc_spv-GRC_0001 | J53: S1aH7 | K53: 0.029769927 | L53: IMPNRGZ | N53: elc_won-GRC_0001 | O53: S1aH7 | P53: 0.029432947 | Q53: IMPNRGZ | S53: elc_wof-GRC_0104 | T53: S1aH7 | U53: 0.025156715 | V53: IMPNRGZ | AC53: elc_industry | AD53: S1aH7 | AE53: 0.02095141
I54: elc_spv-GRC_0001 | J54: S1aH8 | K54: 0.015912397 | L54: IMPNRGZ | N54: elc_won-GRC_0001 | O54: S1aH8 | P54: 0.028939708 | Q54: IMPNRGZ | S54: elc_wof-GRC_0104 | T54: S1aH8 | U54: 0.024699382 | V54: IMPNRGZ | AC54: elc_industry | AD54: S1aH8 | AE54: 0.020933576
I55: elc_spv-GRC_0001 | J55: S1aH9 | K55: 0.004082808 | L55: IMPNRGZ | N55: elc_won-GRC_0001 | O55: S1aH9 | P55: 0.13628439 | Q55: IMPNRGZ | S55: elc_wof-GRC_0104 | T55: S1aH9 | U55: 0.1213937 | V55: IMPNRGZ | AC55: elc_industry | AD55: S1aH9 | AE55: 0.10298114
I56: elc_spv-GRC_0001 | J56: S2aH1 | K56: 0.00042762012 | L56: IMPNRGZ | N56: elc_won-GRC_0001 | O56: S2aH1 | P56: 0.022857307 | Q56: IMPNRGZ | S56: elc_wof-GRC_0104 | T56: S2aH1 | U56: 0.042491053 | V56: IMPNRGZ | AC56: elc_industry | AD56: S2aH1 | AE56: 0.041554866
I57: elc_spv-GRC_0001 | J57: S2aH2 | K57: 0.007753027 | L57: IMPNRGZ | N57: elc_won-GRC_0001 | O57: S2aH2 | P57: 0.002413422 | Q57: IMPNRGZ | S57: elc_wof-GRC_0104 | T57: S2aH2 | U57: 0.0069335384 | V57: IMPNRGZ | AC57: elc_industry | AD57: S2aH2 | AE57: 0.007083458
I58: elc_spv-GRC_0001 | J58: S2aH3 | K58: 0.013615158 | L58: IMPNRGZ | N58: elc_won-GRC_0001 | O58: S2aH3 | P58: 0.0019675927 | Q58: IMPNRGZ | S58: elc_wof-GRC_0104 | T58: S2aH3 | U58: 0.0068170652 | V58: IMPNRGZ | AC58: elc_industry | AD58: S2aH3 | AE58: 0.0071256388
... I82: elc_spv-GRC_0001 | J82: S4aH9 | K82: 0 | L82: IMPNRGZ | N82: elc_won-GRC_0001 | O82: S4aH9 | P82: 0.0097942398 | Q82: IMPNRGZ | S82: elc_wof-GRC_0104 | T82: S4aH9 | U82: 0.016053247 | V82: IMPNRGZ | AC82: elc_industry | AD82: S4aH9 | AE82: 0.017671251
I83: elc_spv-GRC_0010 | J83: S1aH1 | K83: 0.0024956788 | L83: IMPNRGZ | N83: elc_won-GRC_0010 | O83: S1aH1 | P83: 0.13776996 | Q83: IMPNRGZ | S83: elc_wof-GRC_0105 | T83: S1aH1 | U83: 0.1394516 | V83: IMPNRGZ
I84: elc_spv-GRC_0010 | J84: S1aH2 | K84: 0.01050848 | L84: IMPNRGZ | N84: elc_won-GRC_0010 | O84: S1aH2 | P84: 0.022160519 | Q84: IMPNRGZ | S84: elc_wof-GRC_0105 | T84: S1aH2 | U84: 0.022603936 | V84: IMPNRGZ
I85: elc_spv-GRC_0010 | J85: S1aH3 | K85: 0.02236241 | L85: IMPNRGZ | N85: elc_won-GRC_0010 | O85: S1aH3 | P85: 0.021523925 | Q85: IMPNRGZ | S85: elc_wof-GRC_0105 | T85: S1aH3 | U85: 0.022715456 | V85: IMPNRGZ
...

Sheet ts48_clu
C9: =IF(A11="x","DeActivated","~TimeSlices") -> DeActivated | I9: =IF(A11="x","DeActivated","~TFM_DINS-AT") -> DeActivated | N9: =IF(A11="x","DeActivated","~TFM_DINS-AT") -> DeActivated | S9: =IF(A11="x","DeActivated","~TFM_DINS-AT") -> DeActivated | X9: =IF(A11="x","DeActivated","~TFM_DINS-AT") -> DeActivated | AC9: =IF(A11="x","DeActivated","~TFM_DINS-AT") -> DeActivated | AG9: =IF(A11="x","DeActivated","~TFM_DINS-AT") -> DeActivated | AK9: =IF(A11="x","DeActivated","~TFM_INS-AT") -> DeActivated
A10: ts48_clu | C10: season | D10: weekly | E10: daynite | F10: wparent | G10: dparent | I10: commodity | J10: timeslice | K10: com_fr | L10: process | N10: commodity | O10: timeslice | P10: com_fr | Q10: process | S10: commodity | T10: timeslice | U10: com_fr | V10: process | X10: g_yrfr | Y10: com_fr | Z10: timeslice | AA10: commodity | AC10: commodity | AD10: timeslice | AE10: com_fr | AG10: commodity | AH10: timeslice | AI10: com_pkflx | AK10: timeslice | AL10: ncap_afs | AM10: pset_ci
A11: =IFERROR(IF(Veda!D5=A10,"ok","x"),"") -> x | C11: S1 | D11: a | E11: H1 | F11: S1,S2,S3,S4,S5,S6 | G11: a | I11: elc_spv-GRC_0000 | J11: S1aH1 | K11: 0 | L11: IMPNRGZ | N11: elc_won-GRC_0000 | O11: S1aH1 | P11: 0.088125058 | Q11: IMPNRGZ | S11: elc_wof-GRC_0100 | T11: S1aH1 | U11: 0.1021958 | V11: IMPNRGZ | X11: 0.061643836 | Y11: 0.013186485 | Z11: S1aH1 | AA11: elc_roadtransport | AC11: elc_buildings | AD11: S1aH1 | AE11: 0.049276668 | AG11: ELC | AH11: S1aH1 | AI11: 0.33276257 | AK11: S2 | AL11: 0.26795455 | AM11: hydro
C12: S2 | E12: H2 | G12: a | I12: elc_spv-GRC_0000 | J12: S1aH2 | K12: 0 | L12: IMPNRGZ | N12: elc_won-GRC_0000 | O12: S1aH2 | P12: 0.014100291 | Q12: IMPNRGZ | S12: elc_wof-GRC_0100 | T12: S1aH2 | U12: 0.01673628 | V12: IMPNRGZ | X12: 0.010273973 | Y12: 0.015215175 | Z12: S1aH2 | AA12: elc_roadtransport | AC12: elc_buildings | AD12: S1aH2 | AE12: 0.010734422 | AG12: ELC | AH12: S1aH2 | AI12: 0.16988272 | AK12: S1 | AL12: 0.35727273 | AM12: hydro
