Workbook

Sheet Veda
G1: 1,2,3,4,5,6,7,8,9,10,11,12,13,14,15,21,22,23,24,25
D2: ="~Inputcell: "&_xlfn.TEXTJOIN(",",TRUE,G1:EE1) -> ~Inputcell: 1,2,3,4,5,6,7,8,9,10,11,12,13,14,15,21,22,23,24,25 | G2: 5 | H2: 6 | I2: 7 | J2: 9 | K2: 10 | L2: 11 | M2: 16 | N2: 17 | O2: 18 | P2: 20 | Q2: 21 | R2: 22 | S2: 27 | T2: 28 | U2: 29 | V2: 31 | W2: 32 | X2: 33 | Y2: 38 | Z2: 39 | AA2: 40 | AB2: 42 | AC2: 43 | AD2: 44 | AE2: 49 | AF2: 50 | AG2: 51 | AH2: 53 | AI2: 54 | AJ2: 55
D3: 3
D5: =VLOOKUP(D3,$C$9:$E$999,2,FALSE) -> ts_annual | E5: =VLOOKUP(D3,$C$9:$E$999,3,FALSE) -> C3
B7: ~Scenmap
A8: priority | B8: scen | C8: case_no | D8: timeslice | E8: climate | AM8: bio price multiplier
A9: 5 | B9: =VLOOKUP(E9,$AK$9:$AL$15,2,FALSE)&"."&VLOOKUP(D9,$AH$9:$AI$24,2,FALSE) -> e 1.5 deg no OS.kAnn | C9: 1 | D9: =VLOOKUP(AJ9,$AG$9:$AH$22,2,FALSE) -> ts_annual | E9: C1 | G9: Limit warming to 1.5°C (>50%) with no or limited overshoot | AG9: 1 | AH9: ts_annual | AI9: kAnn | AJ9: 1 | AK9: C1 | AL9: e 1.5 deg no OS | AM9: 5
A10: 5 | B10: =VLOOKUP(E10,$AK$9:$AL$15,2,FALSE)&"."&VLOOKUP(D10,$AH$9:$AI$24,2,FALSE) -> d 1.5 deg OS.kAnn | C10: =C9+1 -> 2 | D10: =VLOOKUP(AJ10,$AG$9:$AH$22,2,FALSE) -> ts_annual | E10: C2 | G10: Limit warming to 1.5°C (>67%) with high overshoot | S10: IEA | AG10: 2 | AH10: ts_12t | AI10: k12 | AJ10: 1 | AK10: C2 | AL10: d 1.5 deg OS | AM10: 4
A11: 5 | B11: =VLOOKUP(E11,$AK$9:$AL$15,2,FALSE)&"."&VLOOKUP(D11,$AH$9:$AI$24,2,FALSE) -> c 2 deg (67%).kAnn | C11: =C10+1 -> 3 | D11: =VLOOKUP(AJ11,$AG$9:$AH$22,2,FALSE) -> ts_annual | E11: C3 | G11: Limit warming to 2°C (>67%) with higher action post-2030 | S11: 2022 | AG11: 3 | AH11: ts_012 | AI11: j12 | AJ11: 1 | AK11: C3 | AL11: c 2 deg (67%) | AM11: 3
A12: 5 | B12: =VLOOKUP(E12,$AK$9:$AL$15,2,FALSE)&"."&VLOOKUP(D12,$AH$9:$AI$24,2,FALSE) -> b 2 deg (50%).kAnn | C12: =C11+1 -> 4 | D12: =VLOOKUP(AJ12,$AG$9:$AH$22,2,FALSE) -> ts_annual | E12: C4 | G12: Limit warming to 2°C (>50%) with immediate action | S12: =SUMIFS(iea_data!I3:I9999,iea_data!$B$3:$B$9999,Veda!$S$11)+T28-T29 -> 325.04 | T12: base-year generation (TWh) | AG12: 4 | AH12: ts_024 | AI12: i24 | AJ12: 1 | AK12: C4 | AL12: b 2 deg (50%) | AM12: 3
A13: 5 | B13: =VLOOKUP(E13,$AK$9:$AL$15,2,FALSE)&"."&VLOOKUP(D13,$AH$9:$AI$24,2,FALSE) -> a 3 deg.kAnn | C13: =C12+1 -> 5 | D13: =VLOOKUP(AJ13,$AG$9:$AH$22,2,FALSE) -> ts_annual | E13: C7 | G13: Likely above 3°C warming with limited mitigation | AG13: 5 | AH13: ts_048 | AI13: h48 | AJ13: 1 | AK13: C7 | AL13: a 3 deg | AM13: 1.5
A14: 5 | B14: =VLOOKUP(E14,$AK$9:$AL$15,2,FALSE)&"."&VLOOKUP(D14,$AH$9:$AI$24,2,FALSE) -> e 1.5 deg no OS.k12 | C14: =C13+1 -> 6 | D14: =VLOOKUP(AJ14,$AG$9:$AH$22,2,FALSE) -> ts_12t | E14: =E9 -> C1 | T14: =S12 -> 325.04 | U14: =$S$12*J15 -> 341.292 | V14: =$S$12*K15 -> 380.2968 | W14: =$S$12*L15 -> 429.0528 | X14: =$S$12*M15 -> 487.56 | Y14: =$S$12*N15 -> 546.0672 | Z14: =$S$12*O15 -> 588.3224 | AG14: 6 | AH14: ts_064 | AI14: g64 | AJ14: =AJ9+1 -> 2
A15: 5 | B15: =VLOOKUP(E15,$AK$9:$AL$15,2,FALSE)&"."&VLOOKUP(D15,$AH$9:$AI$24,2,FALSE) -> d 1.5 deg OS.k12 | C15: =C14+1 -> 7 | D15: =VLOOKUP(AJ15,$AG$9:$AH$22,2,FALSE) -> ts_12t | E15: =E10 -> C2 | G15: Electricity growth relative to 2020 | I15: =SUMIFS(ar6_r10!$F$2:$F$999,ar6_r10!$A$2:$A$999,Veda!$E$5,ar6_r10!$C$2:$C$999,Veda!I$17,ar6_r10!$M$2:$M$999,Veda!$G15) -> 1 | J15: =SUMIFS(ar6_r10!$F$2:$F$999,ar6_r10!$A$2:$A$999,Veda!$E$5,ar6_r10!$C$2:$C$999,Veda!J$17,ar6_r10!$M$2:$M$999,Veda!$G15) -> 1.05 | K15: =SUMIFS(ar6_r10!$F$2:$F$999,ar6_r10!$A$2:$A$999,Veda!$E$5,ar6_r10!$C$2:$C$999,Veda!K$17,ar6_r10!$M$2:$M$999,Veda!$G15) -> 1.17 | L15: =SUMIFS(ar6_r10!$F$2:$F$999,ar6_r10!$A$2:$A$999,Veda!$E$5,ar6_r10!$C$2:$C$999,Veda!L$17,ar6_r10!$M$2:$M$999,Veda!$G15) -> 1.32 | M15: =SUMIFS(ar6_r10!$F$2:$F$999,ar6_r10!$A$2:$A$999,Veda!$E$5,ar6_r10!$C$2:$C$999,Veda!M$17,ar6_r10!$M$2:$M$999,Veda!$G15) -> 1.5 | N15: =SUMIFS(ar6_r10!$F$2:$F$999,ar6_r10!$A$2:$A$999,Veda!$E$5,ar6_r10!$C$2:$C$999,Veda!N$17,ar6_r10!$M$2:$M$999,Veda!$G15) -> 1.68 | O15: =SUMIFS(ar6_r10!$F$2:$F$999,ar6_r10!$A$2:$A$999,Veda!$E$5,ar6_r10!$C$2:$C$999,Veda!O$17,ar6_r10!$M$2:$M$999,Veda!$G15) -> 1.81 | AG15: 7 | AH15: ts_096P50 | AI15: f96p50 | AJ15: =AJ10+1 -> 2
A16: 5 | B16: =VLOOKUP(E16,$AK$9:$AL$15,2,FALSE)&"."&VLOOKUP(D16,$AH$9:$AI$24,2,FALSE) -> c 2 deg (67%).k12 | C16: =C15+1 -> 8 | D16: =VLOOKUP(AJ16,$AG$9:$AH$22,2,FALSE) -> ts_12t | E16: =E11 -> C3 | S16: ~TFM_INS-TS | AG16: 8 | AH16: ts_096P10 | AI16: f96p10 | AJ16: =AJ11+1 -> 2
A17: 5 | B17: =VLOOKUP(E17,$AK$9:$AL$15,2,FALSE)&"."&VLOOKUP(D17,$AH$9:$AI$24,2,FALSE) -> b 2 deg (50%).k12 | C17: =C16+1 -> 9 | D17: =VLOOKUP(AJ17,$AG$9:$AH$22,2,FALSE) -> ts_12t | E17: =E12 -> C4 | I17: 2020 | J17: =U17 -> 2025 | K17: =V17 -> 2030 | L17: =W17 -> 2035 | M17: =X17 -> 2040 | N17: =Y17 -> 2045 | O17: =Z17 -> 2050 | S17: commodity | T17: 2022 | U17: 2025 | V17: 2030 | W17: 2035 | X17: 2040 | Y17: 2045 | Z17: 2050 | AA17: attribute | AG17: 9 | AH17: ts_096P90 | AI17: f96p90 | AJ17: =AJ12+1 -> 2
A18: 5 | B18: =VLOOKUP(E18,$AK$9:$AL$15,2,FALSE)&"."&VLOOKUP(D18,$AH$9:$AI$24,2,FALSE) -> a 3 deg.k12 | C18: =C17+1 -> 10 | D18: =VLOOKUP(AJ18,$AG$9:$AH$22,2,FALSE) -> ts_12t | E18: =E13 -> C7 | G18: Hydrogen as a share of electricity | I18: =SUMIFS(ar6_r10!$F$2:$F$999,ar6_r10!$A$2:$A$999,Veda!$E$5,ar6_r10!$C$2:$C$999,Veda!I$17,ar6_r10!$M$2:$M$999,Veda!$G18) -> 0 | J18: =SUMIFS(ar6_r10!$F$2:$F$999,ar6_r10!$A$2:$A$999,Veda!$E$5,ar6_r10!$C$2:$C$999,Veda!J$17,ar6_r10!$M$2:$M$999,Veda!$G18) -> 0 | K18: =SUMIFS(ar6_r10!$F$2:$F$999,ar6_r10!$A$2:$A$999,Veda!$E$5,ar6_r10!$C$2:$C$999,Veda!K$17,ar6_r10!$M$2:$M$999,Veda!$G18) -> 0.01 | L18: =SUMIFS(ar6_r10!$F$2:$F$999,ar6_r10!$A$2:$A$999,Veda!$E$5,ar6_r10!$C$2:$C$999,Veda!L$17,ar6_r10!$M$2:$M$999,Veda!$G18) -> 0.01 | M18: =SUMIFS(ar6_r10!$F$2:$F$999,ar6_r10!$A$2:$A$999,Veda!$E$5,ar6_r10!$C$2:$C$999,Veda!M$17,ar6_r10!$M$2:$M$999,Veda!$G18) -> 0.01 | N18: =SUMIFS(ar6_r10!$F$2:$F$999,ar6_r10!$A$2:$A$999,Veda!$E$5,ar6_r10!$C$2:$C$999,Veda!N$17,ar6_r10!$M$2:$M$999,Veda!$G18) -> 0.02 | O18: =SUMIFS(ar6_r10!$F$2:$F$999,ar6_r10!$A$2:$A$999,Veda!$E$5,ar6_r10!$C$2:$C$999,Veda!O$17,ar6_r10!$M$2:$M$999,Veda!$G18) -> 0.03 | S18: hydrogen_allsect | T18: =I18*T$14 -> 0 | U18: =J18*U$14 -> 0 | V18: =K18*V$14 -> 3.802968 | W18: =L18*W$14 -> 4.290528 | X18: =M18*X$14 -> 4.8756 | Y18: =N18*Y$14 -> 10.921344 | Z18: =O18*Z$14 -> 17.649672 | AA18: demand | AG18: 10 | AH18: s1p1v1_d | AI18: e3d | AJ18: =AJ13+1 -> 2
A19: 5 | B19: =VLOOKUP(E19,$AK$9:$AL$15,2,FALSE)&"."&VLOOKUP(D19,$AH$9:$AI$24,2,FALSE) -> e 1.5 deg no OS.j12 | C19: =C18+1 -> 11 | D19: =VLOOKUP(AJ19,$AG$9:$AH$22,2,FALSE) -> ts_012 | E19: =E14 -> C1 | G19: Industry electricity share | I19: =SUMIFS(ar6_r10!$F$2:$F$999,ar6_r10!$A$2:$A$999,Veda!$E$5,ar6_r10!$C$2:$C$999,Veda!I$17,ar6_r10!$M$2:$M$999,Veda!$G19) -> 0.36 | J19: =SUMIFS(ar6_r10!$F$2:$F$999,ar6_r10!$A$2:$A$999,Veda!$E$5,ar6_r10!$C$2:$C$999,Veda!J$17,ar6_r10!$M$2:$M$999,Veda!$G19) -> 0.32 | K19: =SUMIFS(ar6_r10!$F$2:$F$999,ar6_r10!$A$2:$A$999,Veda!$E$5,ar6_r10!$C$2:$C$999,Veda!K$17,ar6_r10!$M$2:$M$999,Veda!$G19) -> 0.31 | L19: =SUMIFS(ar6_r10!$F$2:$F$999,ar6_r10!$A$2:$A$999,Veda!$E$5,ar6_r10!$C$2:$C$999,Veda!L$17,ar6_r10!$M$2:$M$999,Veda!$G19) -> 0.29 | M19: =SUMIFS(ar6_r10!$F$2:$F$999,ar6_r10!$A$2:$A$999,Veda!$E$5,ar6_r10!$C$2:$C$999,Veda!M$17,ar6_r10!$M$2:$M$999,Veda!$G19) -> 0.29 | N19: =SUMIFS(ar6_r10!$F$2:$F$999,ar6_r10!$A$2:$A$999,Veda!$E$5,ar6_r10!$C$2:$C$999,Veda!N$17,ar6_r10!$M$2:$M$999,Veda!$G19) -> 0.29 | O19: =SUMIFS(ar6_r10!$F$2:$F$999,ar6_r10!$A$2:$A$999,Veda!$E$5,ar6_r10!$C$2:$C$999,Veda!O$17,ar6_r10!$M$2:$M$999,Veda!$G19) -> 0.3 | S19: elc_industry | T19: =I19*T$14 -> 117.0144 | U19: =J19*U$14 -> 109.21344 | V19: =K19*V$14 -> 117.89201 | W19: =L19*W$14 -> 124.42531 | X19: =M19*X$14 -> 141.3924 | Y19: =N19*Y$14 -> 158.35949 | Z19: =O19*Z$14 -> 176.49672 | AA19: demand | AG19: 11 | AH19: s3p3v3_d | AI19: d9d | AJ19: =AJ14+1 -> 3
A20: 5 | B20: =VLOOKUP(E20,$AK$9:$AL$15,2,FALSE)&"."&VLOOKUP(D20,$AH$9:$AI$24,2,FALSE) -> d 1.5 deg OS.j12 | C20: =C19+1 -> 12 | D20: =VLOOKUP(AJ20,$AG$9:$AH$22,2,FALSE) -> ts_012 | E20: =E15 -> C2 | G20: Residential and commercial electricity share | I20: =SUMIFS(ar6_r10!$F$2:$F$999,ar6_r10!$A$2:$A$999,Veda!$E$5,ar6_r10!$C$2:$C$999,Veda!I$17,ar6_r10!$M$2:$M$999,Veda!$G20) -> 0.6 | J20: =SUMIFS(ar6_r10!$F$2:$F$999,ar6_r10!$A$2:$A$999,Veda!$E$5,ar6_r10!$C$2:$C$999,Veda!J$17,ar6_r10!$M$2:$M$999,Veda!$G20) -> 0.6 | K20: =SUMIFS(ar6_r10!$F$2:$F$999,ar6_r10!$A$2:$A$999,Veda!$E$5,ar6_r10!$C$2:$C$999,Veda!K$17,ar6_r10!$M$2:$M$999,Veda!$G20) -> 0.6 | L20: =SUMIFS(ar6_r10!$F$2:$F$999,ar6_r10!$A$2:$A$999,Veda!$E$5,ar6_r10!$C$2:$C$999,Veda!L$17,ar6_r10!$M$2:$M$999,Veda!$G20) -> 0.57 | M20: =SUMIFS(ar6_r10!$F$2:$F$999,ar6_r10!$A$2:$A$999,Veda!$E$5,ar6_r10!$C$2:$C$999,Veda!M$17,ar6_r10!$M$2:$M$999,Veda!$G20) -> 0.54 | N20: =SUMIFS(ar6_r10!$F$2:$F$999,ar6_r10!$A$2:$A$999,Veda!$E$5,ar6_r10!$C$2:$C$999,Veda!N$17,ar6_r10!$M$2:$M$999,Veda!$G20) -> 0.52 | O20: =SUMIFS(ar6_r10!$F$2:$F$999,ar6_r10!$A$2:$A$999,Veda!$E$5,ar6_r10!$C$2:$C$999,Veda!O$17,ar6_r10!$M$2:$M$999,Veda!$G20) -> 0.53 | S20: elc_buildings | T20: =I20*T$14 -> 195.024 | U20: =J20*U$14 -> 204.7752 | V20: =K20*V$14 -> 228.17808 | W20: =L20*W$14 -> 244.5601 | X20: =M20*X$14 -> 263.2824 | Y20: =N20*Y$14 -> 283.95494 | Z20: =O20*Z$14 -> 311.81087 | AA20: demand | AG20: 12 | AH20: s5p5v5_d | AI20: c15d | AJ20: =AJ15+1 -> 3
A21: 5 | B21: =VLOOKUP(E21,$AK$9:$AL$15,2,FALSE)&"."&VLOOKUP(D21,$AH$9:$AI$24,2,FALSE) -> c 2 deg (67%).j12 | C21: =C20+1 -> 13 | D21: =VLOOKUP(AJ21,$AG$9:$AH$22,2,FALSE) -> ts_012 | E21: =E16 -> C3 | G21: Transportation electricity share | I21: =SUMIFS(ar6_r10!$F$2:$F$999,ar6_r10!$A$2:$A$999,Veda!$E$5,ar6_r10!$C$2:$C$999,Veda!I$17,ar6_r10!$M$2:$M$999,Veda!$G21) -> 0.03 | J21: =SUMIFS(ar6_r10!$F$2:$F$999,ar6_r10!$A$2:$A$999,Veda!$E$5,ar6_r10!$C$2:$C$999,Veda!J$17,ar6_r10!$M$2:$M$999,Veda!$G21) -> 0.06 | K21: =SUMIFS(ar6_r10!$F$2:$F$999,ar6_r10!$A$2:$A$999,Veda!$E$5,ar6_r10!$C$2:$C$999,Veda!K$17,ar6_r10!$M$2:$M$999,Veda!$G21) -> 0.08 | L21: =SUMIFS(ar6_r10!$F$2:$F$999,ar6_r10!$A$2:$A$999,Veda!$E$5,ar6_r10!$C$2:$C$999,Veda!L$17,ar6_r10!$M$2:$M$999,Veda!$G21) -> 0.11 | M21: =SUMIFS(ar6_r10!$F$2:$F$999,ar6_r10!$A$2:$A$999,Veda!$E$5,ar6_r10!$C$2:$C$999,Veda!M$17,ar6_r10!$M$2:$M$999,Veda!$G21) -> 0.12 | N21: =SUMIFS(ar6_r10!$F$2:$F$999,ar6_r10!$A$2:$A$999,Veda!$E$5,ar6_r10!$C$2:$C$999,Veda!N$17,ar6_r10!$M$2:$M$999,Veda!$G21) -> 0.18 | O21: =SUMIFS(ar6_r10!$F$2:$F$999,ar6_r10!$A$2:$A$999,Veda!$E$5,ar6_r10!$C$2:$C$999,Veda!O$17,ar6_r10!$M$2:$M$999,Veda!$G21) -> 0.19 | S21: elc_transport | T21: =I21*T$14 -> 9.7512 | U21: =T21 -> 9.7512 | V21: =U21 -> 9.7512 | W21: =V21 -> 9.7512 | X21: =W21 -> 9.7512 | Y21: =X21 -> 9.7512 | Z21: =Y21 -> 9.7512 | AA21: demand | AC21: non-road transport demand assumed to be constant | AG21: 13 | AH21: s2_w | AI21: b2w | AJ21: =AJ16+1 -> 3
A22: 5 | B22: =VLOOKUP(E22,$AK$9:$AL$15,2,FALSE)&"."&VLOOKUP(D22,$AH$9:$AI$24,2,FALSE) -> b 2 deg (50%).j12 | C22: =C21+1 -> 14 | D22: =VLOOKUP(AJ22,$AG$9:$AH$22,2,FALSE) -> ts_012 | E22: =E17 -> C4 | S22: elc_roadtransport | T22: =T14-SUM(T19:T21) -> 3.2504 | U22: =U14-SUM(U19:U21) -> 17.55216 | V22: =V14-SUM(V19:V21) -> 24.475512 | W22: =W14-SUM(W19:W21) -> 50.316192 | X22: =X14-SUM(X19:X21) -> 73.134 | Y22: =Y14-SUM(Y19:Y21) -> 94.001568 | Z22: =Z14-SUM(Z19:Z21) -> 90.263608 | AA22: demand | AG22: 14 | AH22: s2_w_p2_d | AI22: a2w2d | AJ22: =AJ17+1 -> 3
A23: 5 | B23: =VLOOKUP(E23,$AK$9:$AL$15,2,FALSE)&"."&VLOOKUP(D23,$AH$9:$AI$24,2,FALSE) -> a 3 deg.j12 | C23: =C22+1 -> 15 | D23: =VLOOKUP(AJ23,$AG$9:$AH$22,2,FALSE) -> ts_012 | E23: =E18 -> C7 | S23: * | AG23: 15 | AH23: s1v1_d | AI23: e2d | AJ23: =AJ18+1 -> 3
A24: 5 | B24: =VLOOKUP(E24,$AK$9:$AL$15,2,FALSE)&"."&VLOOKUP(D24,$AH$9:$AI$24,2,FALSE) -> e 1.5 deg no OS.i24 | C24: =C23+1 -> 16 | D24: =VLOOKUP(AJ24,$AG$9:$AH$22,2,FALSE) -> ts_024 | E24: =E19 -> C1 | G24: CO2 price | I24: 0 | J24: 0 | K24: =SUMIFS(ar6_r10!$F$2:$F$999,ar6_r10!$A$2:$A$999,Veda!$E$5,ar6_r10!$C$2:$C$999,Veda!K$17,ar6_r10!$M$2:$M$999,Veda!$G24) -> 71.48 | L24: =SUMIFS(ar6_r10!$F$2:$F$999,ar6_r10!$A$2:$A$999,Veda!$E$5,ar6_r10!$C$2:$C$999,Veda!L$17,ar6_r10!$M$2:$M$999,Veda!$G24) -> 104.42 | M24: =SUMIFS(ar6_r10!$F$2:$F$999,ar6_r10!$A$2:$A$999,Veda!$E$5,ar6_r10!$C$2:$C$999,Veda!M$17,ar6_r10!$M$2:$M$999,Veda!$G24) -> 134.85 | N24: =SUMIFS(ar6_r10!$F$2:$F$999,ar6_r10!$A$2:$A$999,Veda!$E$5,ar6_r10!$C$2:$C$999,Veda!N$17,ar6_r10!$M$2:$M$999,Veda!$G24) -> 178.1 | O24: =SUMIFS(ar6_r10!$F$2:$F$999,ar6_r10!$A$2:$A$999,Veda!$E$5,ar6_r10!$C$2:$C$999,Veda!O$17,ar6_r10!$M$2:$M$999,Veda!$G24) -> 209.45 | S24: co2net | U24: 0 | V24: =K24/1000 -> 0.07148 | W24: =L24/1000 -> 0.10442 | X24: =M24/1000 -> 0.13485 | Y24: =N24/1000 -> 0.1781 | Z24: =O24/1000 -> 0.20945 | AA24: com_taxnet | AJ24: =AJ19+1 -> 4
A25: 5 | B25: =VLOOKUP(E25,$AK$9:$AL$15,2,FALSE)&"."&VLOOKUP(D25,$AH$9:$AI$24,2,FALSE) -> d 1.5 deg OS.i24 | C25: =C24+1 -> 17 | D25: =VLOOKUP(AJ25,$AG$9:$AH$22,2,FALSE) -> ts_024 | E25: =E20 -> C2 | AJ25: =AJ20+1 -> 4
A26: 5 | B26: =VLOOKUP(E26,$AK$9:$AL$15,2,FALSE)&"."&VLOOKUP(D26,$AH$9:$AI$24,2,FALSE) -> c 2 deg (67%).i24 | C26: =C25+1 -> 18 | D26: =VLOOKUP(AJ26,$AG$9:$AH$22,2,FALSE) -> ts_024 | E26: =E21 -> C3 | S26: ~TFM_INS-TS | AJ26: =AJ21+1 -> 4
A27: 5 | B27: =VLOOKUP(E27,$AK$9:$AL$15,2,FALSE)&"."&VLOOKUP(D27,$AH$9:$AI$24,2,FALSE) -> b 2 deg (50%).i24 | C27: =C26+1 -> 19 | D27: =VLOOKUP(AJ27,$AG$9:$AH$22,2,FALSE) -> ts_024 | E27: =E22 -> C4 | S27: process | T27: =T17 -> 2022 | U27: =U17 -> 2025 | V27: =V17 -> 2030 | W27: =W17 -> 2035 | X27: =X17 -> 2040 | Y27: =Y17 -> 2045 | Z27: =Z17 -> 2050 | AA27: attribute | AB27: limtype | AJ27: =AJ22+1 -> 4
A28: 5 | B28: =VLOOKUP(E28,$AK$9:$AL$15,2,FALSE)&"."&VLOOKUP(D28,$AH$9:$AI$24,2,FALSE) -> a 3 deg.i24 | C28: =C27+1 -> 20 | D28: =VLOOKUP(AJ28,$AG$9:$AH$22,2,FALSE) -> ts_024 | E28: =E23 -> C7 | Q28: =SUMIFS(iea_data!G3:G9999,iea_data!$B$3:$B$9999,Veda!$S$11) -> 47.39 | S28: Trd_electricity import | T28: =Q28 -> 47.39 | AA28: ACT_BND | AB28: FX | AJ28: =AJ23+1 -> 4
A29: 5 | B29: =VLOOKUP(E29,$AK$9:$AL$15,2,FALSE)&"."&VLOOKUP(D29,$AH$9:$AI$24,2,FALSE) -> e 1.5 deg no OS.h48 | C29: =C28+1 -> 21 | D29: =VLOOKUP(AJ29,$AG$9:$AH$22,2,FALSE) -> ts_048 | E29: =E24 -> C1 | Q29: =SUMIFS(iea_data!H3:H9999,iea_data!$B$3:$B$9999,Veda!$S$11) -> -4.4 | S29: Trd_electricity export | T29: =-1*Q29 -> 4.4 | AA29: ACT_BND | AB29: FX | AJ29: =AJ24+1 -> 5
A30: 5 | B30: =VLOOKUP(E30,$AK$9:$AL$15,2,FALSE)&"."&VLOOKUP(D30,$AH$9:$AI$24,2,FALSE) -> d 1.5 deg OS.h48 | C30: =C29+1 -> 22 | D30: =VLOOKUP(AJ30,$AG$9:$AH$22,2,FALSE) -> ts_048 | E30: =E25 -> C2 | AJ30: =AJ25+1 -> 5
A31: 5 | B31: =VLOOKUP(E31,$AK$9:$AL$15,2,FALSE)&"."&VLOOKUP(D31,$AH$9:$AI$24,2,FALSE) -> c 2 deg (67%).h48 | C31: =C30+1 -> 23 | D31: =VLOOKUP(AJ31,$AG$9:$AH$22,2,FALSE) -> ts_048 | E31: =E26 -> C3 | AJ31: =AJ26+1 -> 5
A32: 5 | B32: =VLOOKUP(E32,$AK$9:$AL$15,2,FALSE)&"."&VLOOKUP(D32,$AH$9:$AI$24,2,FALSE) -> b 2 deg (50%).h48 | C32: =C31+1 -> 24 | D32: =VLOOKUP(AJ32,$AG$9:$AH$22,2,FALSE) -> ts_048 | E32: =E27 -> C4 | AJ32: =AJ27+1 -> 5
A33: 5 | B33: =VLOOKUP(E33,$AK$9:$AL$15,2,FALSE)&"."&VLOOKUP(D33,$AH$9:$AI$24,2,FALSE) -> a 3 deg.h48 | C33: =C32+1 -> 25 | D33: =VLOOKUP(AJ33,$AG$9:$AH$22,2,FALSE) -> ts_048 | E33: =E28 -> C7 | AJ33: =AJ28+1 -> 5
A34: 5 | B34: =VLOOKUP(E34,$AK$9:$AL$15,2,FALSE)&"."&VLOOKUP(D34,$AH$9:$AI$24,2,FALSE) -> e 1.5 deg no OS.g64 | C34: =C33+1 -> 26 | D34: =VLOOKUP(AJ34,$AG$9:$AH$22,2,FALSE) -> ts_064 | E34: =E29 -> C1 | AJ34: =AJ29+1 -> 6
A35: 5 | B35: =VLOOKUP(E35,$AK$9:$AL$15,2,FALSE)&"."&VLOOKUP(D35,$AH$9:$AI$24,2,FALSE) -> d 1.5 deg OS.g64 | C35: =C34+1 -> 27 | D35: =VLOOKUP(AJ35,$AG$9:$AH$22,2,FALSE) -> ts_064 | E35: =E30 -> C2 | AJ35: =AJ30+1 -> 6
A36: 5 | B36: =VLOOKUP(E36,$AK$9:$AL$15,2,FALSE)&"."&VLOOKUP(D36,$AH$9:$AI$24,2,FALSE) -> c 2 deg (67%).g64 | C36: =C35+1 -> 28 | D36: =VLOOKUP(AJ36,$AG$9:$AH$22,2,FALSE) -> ts_064 | E36: =E31 -> C3 | G36: C7 | AJ36: =AJ31+1 -> 6
A37: 5 | B37: =VLOOKUP(E37,$AK$9:$AL$15,2,FALSE)&"."&VLOOKUP(D37,$AH$9:$AI$24,2,FALSE) -> b 2 deg (50%).g64 | C37: =C36+1 -> 29 | D37: =VLOOKUP(AJ37,$AG$9:$AH$22,2,FALSE) -> ts_064 | E37: =E32 -> C4 | G37: Gas Price | I37: =SUMIFS(ar6_r10!$F$2:$F$999,ar6_r10!$A$2:$A$999,Veda!$G$36,ar6_r10!$C$2:$C$999,Veda!I$17,ar6_r10!$M$2:$M$999,Veda!$G37) -> 1 | J37: =SUMIFS(ar6_r10!$F$2:$F$999,ar6_r10!$A$2:$A$999,Veda!$G$36,ar6_r10!$C$2:$C$999,Veda!J$17,ar6_r10!$M$2:$M$999,Veda!$G37) -> 1.07 | K37: =SUMIFS(ar6_r10!$F$2:$F$999,ar6_r10!$A$2:$A$999,Veda!$G$36,ar6_r10!$C$2:$C$999,Veda!K$17,ar6_r10!$M$2:$M$999,Veda!$G37) -> 1.24 | L37: =SUMIFS(ar6_r10!$F$2:$F$999,ar6_r10!$A$2:$A$999,Veda!$G$36,ar6_r10!$C$2:$C$999,Veda!L$17,ar6_r10!$M$2:$M$999,Veda!$G37) -> 1.15 | M37: =SUMIFS(ar6_r10!$F$2:$F$999,ar6_r10!$A$2:$A$999,Veda!$G$36,ar6_r10!$C$2:$C$999,Veda!M$17,ar6_r10!$M$2:$M$999,Veda!$G37) -> 1.25 | N37: =SUMIFS(ar6_r10!$F$2:$F$999,ar6_r10!$A$2:$A$999,Veda!$G$36,ar6_r10!$C$2:$C$999,Veda!N$17,ar6_r10!$M$2:$M$999,Veda!$G37) -> 1.17 | O37: =SUMIFS(ar6_r10!$F$2:$F$999,ar6_r10!$A$2:$A$999,Veda!$G$36,ar6_r10!$C$2:$C$999,Veda!O$17,ar6_r10!$M$2:$M$999,Veda!$G37) -> 1.34 | AJ37: =AJ32+1 -> 6
A38: 5 | B38: =VLOOKUP(E38,$AK$9:$AL$15,2,FALSE)&"."&VLOOKUP(D38,$AH$9:$AI$24,2,FALSE) -> a 3 deg.g64 | C38: =C37+1 -> 30 | D38: =VLOOKUP(AJ38,$AG$9:$AH$22,2,FALSE) -> ts_064 | E38: =E33 -> C7 | G38: Coal Price | I38: =SUMIFS(ar6_r10!$F$2:$F$999,ar6_r10!$A$2:$A$999,Veda!$G$36,ar6_r10!$C$2:$C$999,Veda!I$17,ar6_r10!$M$2:$M$999,Veda!$G38) -> 1 | J38: =SUMIFS(ar6_r10!$F$2:$F$999,ar6_r10!$A$2:$A$999,Veda!$G$36,ar6_r10!$C$2:$C$999,Veda!J$17,ar6_r10!$M$2:$M$999,Veda!$G38) -> 1.02 | K38: =SUMIFS(ar6_r10!$F$2:$F$999,ar6_r10!$A$2:$A$999,Veda!$G$36,ar6_r10!$C$2:$C$999,Veda!K$17,ar6_r10!$M$2:$M$999,Veda!$G38) -> 1.06 | L38: =SUMIFS(ar6_r10!$F$2:$F$999,ar6_r10!$A$2:$A$999,Veda!$G$36,ar6_r10!$C$2:$C$999,Veda!L$17,ar6_r10!$M$2:$M$999,Veda!$G38) -> 1.07 | M38: =SUMIFS(ar6_r10!$F$2:$F$999,ar6_r10!$A$2:$A$999,Veda!$G$36,ar6_r10!$C$2:$C$999,Veda!M$17,ar6_r10!$M$2:$M$999,Veda!$G38) -> 1.08 | N38: =SUMIFS(ar6_r10!$F$2:$F$999,ar6_r10!$A$2:$A$999,Veda!$G$36,ar6_r10!$C$2:$C$999,Veda!N$17,ar6_r10!$M$2:$M$999,Veda!$G38) -> 1.1 | O38: =SUMIFS(ar6_r10!$F$2:$F$999,ar6_r10!$A$2:$A$999,Veda!$G$36,ar6_r10!$C$2:$C$999,Veda!O$17,ar6_r10!$M$2:$M$999,Veda!$G38) -> 1.12 | AJ38: =AJ33+1 -> 6
A39: 5 | B39: =VLOOKUP(E39,$AK$9:$AL$15,2,FALSE)&"."&VLOOKUP(D39,$AH$9:$AI$24,2,FALSE) -> e 1.5 deg no OS.f96p50 | C39: =C38+1 -> 31 | D39: =VLOOKUP(AJ39,$AG$9:$AH$22,2,FALSE) -> ts_096P50 | E39: =E34 -> C1 | G39: Oil Price | I39: =SUMIFS(ar6_r10!$F$2:$F$999,ar6_r10!$A$2:$A$999,Veda!$G$36,ar6_r10!$C$2:$C$999,Veda!I$17,ar6_r10!$M$2:$M$999,Veda!$G39) -> 1 | J39: =SUMIFS(ar6_r10!$F$2:$F$999,ar6_r10!$A$2:$A$999,Veda!$G$36,ar6_r10!$C$2:$C$999,Veda!J$17,ar6_r10!$M$2:$M$999,Veda!$G39) -> 1.01 | K39: =SUMIFS(ar6_r10!$F$2:$F$999,ar6_r10!$A$2:$A$999,Veda!$G$36,ar6_r10!$C$2:$C$999,Veda!K$17,ar6_r10!$M$2:$M$999,Veda!$G39) -> 1.11 | L39: =SUMIFS(ar6_r10!$F$2:$F$999,ar6_r10!$A$2:$A$999,Veda!$G$36,ar6_r10!$C$2:$C$999,Veda!L$17,ar6_r10!$M$2:$M$999,Veda!$G39) -> 1.01 | M39: =SUMIFS(ar6_r10!$F$2:$F$999,ar6_r10!$A$2:$A$999,Veda!$G$36,ar6_r10!$C$2:$C$999,Veda!M$17,ar6_r10!$M$2:$M$999,Veda!$G39) -> 1.01 | N39: =SUMIFS(ar6_r10!$F$2:$F$999,ar6_r10!$A$2:$A$999,Veda!$G$36,ar6_r10!$C$2:$C$999,Veda!N$17,ar6_r10!$M$2:$M$999,Veda!$G39) -> 1.04 | O39: =SUMIFS(ar6_r10!$F$2:$F$999,ar6_r10!$A$2:$A$999,Veda!$G$36,ar6_r10!$C$2:$C$999,Veda!O$17,ar6_r10!$M$2:$M$999,Veda!$G39) -> 1.14 | AJ39: =AJ34+1 -> 7
A40: 5 | B40: =VLOOKUP(E40,$AK$9:$AL$15,2,FALSE)&"."&VLOOKUP(D40,$AH$9:$AI$24,2,FALSE) -> d 1.5 deg OS.f96p50 | C40: =C39+1 -> 32 | D40: =VLOOKUP(AJ40,$AG$9:$AH$22,2,FALSE) -> ts_096P50 | E40: =E35 -> C2 | G40: Biomass Price | I40: =SUMIFS(ar6_r10!$F$2:$F$999,ar6_r10!$A$2:$A$999,Veda!$G$36,ar6_r10!$C$2:$C$999,Veda!I$17,ar6_r10!$M$2:$M$999,Veda!$G40) -> 1 | J40: =SUMIFS(ar6_r10!$F$2:$F$999,ar6_r10!$A$2:$A$999,Veda!$G$36,ar6_r10!$C$2:$C$999,Veda!J$17,ar6_r10!$M$2:$M$999,Veda!$G40) -> 0.96 | K40: =SUMIFS(ar6_r10!$F$2:$F$999,ar6_r10!$A$2:$A$999,Veda!$G$36,ar6_r10!$C$2:$C$999,Veda!K$17,ar6_r10!$M$2:$M$999,Veda!$G40) -> 1.04 | L40: =SUMIFS(ar6_r10!$F$2:$F$999,ar6_r10!$A$2:$A$999,Veda!$G$36,ar6_r10!$C$2:$C$999,Veda!L$17,ar6_r10!$M$2:$M$999,Veda!$G40) -> 1.04 | M40: =SUMIFS(ar6_r10!$F$2:$F$999,ar6_r10!$A$2:$A$999,Veda!$G$36,ar6_r10!$C$2:$C$999,Veda!M$17,ar6_r10!$M$2:$M$999,Veda!$G40) -> 0.98 | N40: =SUMIFS(ar6_r10!$F$2:$F$999,ar6_r10!$A$2:$A$999,Veda!$G$36,ar6_r10!$C$2:$C$999,Veda!N$17,ar6_r10!$M$2:$M$999,Veda!$G40) -> 0.99 | O40: =SUMIFS(ar6_r10!$F$2:$F$999,ar6_r10!$A$2:$A$999,Veda!$G$36,ar6_r10!$C$2:$C$999,Veda!O$17,ar6_r10!$M$2:$M$999,Veda!$G40) -> 1 | AJ40: =AJ35+1 -> 7
A41: 5 | B41: =VLOOKUP(E41,$AK$9:$AL$15,2,FALSE)&"."&VLOOKUP(D41,$AH$9:$AI$24,2,FALSE) -> c 2 deg (67%).f96p50 | C41: =C40+1 -> 33 | D41: =VLOOKUP(AJ41,$AG$9:$AH$22,2,FALSE) -> ts_096P50 | E41: =E36 -> C3 | AJ41: =AJ36+1 -> 7
A42: 5 | B42: =VLOOKUP(E42,$AK$9:$AL$15,2,FALSE)&"."&VLOOKUP(D42,$AH$9:$AI$24,2,FALSE) -> b 2 deg (50%).f96p50 | C42: =C41+1 -> 34 | D42: =VLOOKUP(AJ42,$AG$9:$AH$22,2,FALSE) -> ts_096P50 | E42: =E37 -> C4 | AJ42: =AJ37+1 -> 7
...

Sheet fuel_prices
A9: Fuel Prices
A10: iso | B10: gas_low | C10: gas_high | D10: coal_low | E10: coal_high | F10: oil_low | G10: oil_high | H10: bioenergy_low | I10: bioenergy_high | J10: Notes
A11: ITA | B11: 29.1 | C11: 41.1 | D11: 15.2 | E11: 18.3 | F11: 50 | G11: 60 | H11: 25 | I11: 33 | J11: Pipeline gas, Mediterranean pellet imports

Sheet iea_data
A9: IEA Baseline Data
A10: iso | B10: year | C10: industry_twh | D10: buildings_agri_twh | E10: nonroad_transport_twh | F10: road_transport_twh | G10: imports_twh | H10: exports_twh | I10: total_production_twh
A11: ITA | B11: 2000 | C11: 179.49 | D11: 122.61 | E11: 4.5 | F11: 0 | G11: 44.83 | H11: -0.48 | I11: 269.94
A12: ITA | B12: 2001 | C12: 181.93 | D12: 125.95 | E12: 4.39 | F12: 0 | G12: 48.93 | H12: -0.55 | I12: 271.89
A13: ITA | B13: 2002 | C13: 183.71 | D13: 130.68 | E13: 4.44 | F13: 0 | G13: 51.52 | H13: -0.92 | I13: 277.53
A14: ITA | B14: 2003 | C14: 185.3 | D14: 137.6 | E14: 4.53 | F14: 0 | G14: 51.49 | H14: -0.52 | I14: 286.28
A15: ITA | B15: 2004 | C15: 185.28 | D15: 141.66 | E15: 4.47 | F15: 0 | G15: 46.43 | H15: -0.79 | I15: 295.78
A16: ITA | B16: 2005 | C16: 185.44 | D16: 146.13 | E16: 4.58 | F16: 0 | G16: 50.26 | H16: -1.11 | I16: 296.84
A17: ITA | B17: 2006 | C17: 186.96 | D17: 151.12 | E17: 4.38 | F17: 0 | G17: 46.6 | H17: -1.61 | I17: 307.69
A18: ITA | B18: 2007 | C18: 186.6 | D18: 152.67 | E18: 4.41 | F18: 0 | G18: 48.93 | H18: -2.65 | I18: 308.22
A19: ITA | B19: 2008 | C19: 181.03 | D19: 156.76 | E19: 4.55 | F19: 0 | G19: 43.43 | H19: -3.4 | I19: 313.53
A20: ITA | B20: 2009 | C20: 159.32 | D20: 158.8 | E20: 4.46 | F20: 0 | G20: 47.07 | H20: -2.11 | I20: 288.33
A21: ITA | B21: 2010 | C21: 166.69 | D21: 160.71 | E21: 4.58 | F21: 0.06 | G21: 45.99 | H21: -1.83 | I21: 298.77
A22: ITA | B22: 2011 | C22: 167 | D22: 162.89 | E22: 4.7 | F22: 0.06 | G22: 47.52 | H22: -1.79 | I22: 300.65
... A33: ITA | B33: 2022 | C33: 146.43 | D33: 165.99 | E33: 5.58 | F33: 0.6 | G33: 47.39 | H33: -4.4 | I33: 282.05

Sheet ar6_r10
A9: AR6 Scenario Drivers
A10: Category | B10: Region | C10: Year | D10: count | E10: mean | F10: median | G10: std | H10: min | I10: max | J10: q25 | K10: q75 | L10: category_description | M10: attribute
A11: C1 | B11: R10EUROPE | C11: 2020 | D11: 60 | E11: 8.68 | F11: 6.87 | G11: 10.43 | H11: 0 | I11: 55.17 | J11: 0 | K11: 13.64 | L11: Limit warming to 1.5°C (>50%) with no or limited overshoot | M11: CO2 price
A12: C1 | B12: R10EUROPE | C12: 2025 | D12: 60 | E12: 190.52 | F12: 181.51 | G12: 136.23 | H12: 1.81 | I12: 626.48 | J12: 115.48 | K12: 238.58 | L12: Limit warming to 1.5°C (>50%) with no or limited overshoot | M12: CO2 price
A13: C1 | B13: R10EUROPE | C13: 2030 | D13: 60 | E13: 268.18 | F13: 241.69 | G13: 134.29 | H13: 1.27 | I13: 673.46 | J13: 182.47 | K13: 329.7 | L13: Limit warming to 1.5°C (>50%) with no or limited overshoot | M13: CO2 price
A14: C1 | B14: R10EUROPE | C14: 2035 | D14: 60 | E14: 363.27 | F14: 339.03 | G14: 173.79 | H14: 14.37 | I14: 859.53 | J14: 227.05 | K14: 483.38 | L14: Limit warming to 1.5°C (>50%) with no or limited overshoot | M14: CO2 price
A15: C1 | B15: R10EUROPE | C15: 2040 | D15: 60 | E15: 471.65 | F15: 410.28 | G15: 224.31 | H15: 162.1 | I15: 1097.01 | J15: 298.63 | K15: 622.14 | L15: Limit warming to 1.5°C (>50%) with no or limited overshoot | M15: CO2 price
A16: C1 | B16: R10EUROPE | C16: 2045 | D16: 60 | E16: 565.69 | F16: 494.2 | G16: 256.15 | H16: 193.42 | I16: 1269.88 | J16: 352.78 | K16: 748.01 | L16: Limit warming to 1.5°C (>50%) with no or limited overshoot | M16: CO2 price
A17: C1 | B17: R10EUROPE | C17: 2050 | D17: 60 | E17: 647.44 | F17: 635.43 | G17: 273.56 | H17: 209.76 | I17: 1170.26 | J17: 409.79 | K17: 887.68 | L17: Limit warming to 1.5°C (>50%) with no or limited overshoot | M17: CO2 price
A18: C2 | B18: R10EUROPE | C18: 2020 | D18: 86 | E18: 6.44 | F18: 0 | G18: 8.34 | H18: 0 | I18: 24.5 | J18: 0 | K18: 12.68 | L18: Limit warming to 1.5°C (>67%) with high overshoot | M18: CO2 price
A19: C2 | B19: R10EUROPE | C19: 2025 | D19: 75 | E19: 63.21 | F19: 44.89 | G19: 56.62 | H19: 3.21 | I19: 273 | J19: 27.09 | K19: 77.31 | L19: Limit warming to 1.5°C (>67%) with high overshoot | M19: CO2 price
A20: C2 | B20: R10EUROPE | C20: 2030 | D20: 86 | E20: 85.48 | F20: 63.36 | G20: 73.46 | H20: 0 | I20: 409.5 | J20: 50 | K20: 111.1 | L20: Limit warming to 1.5°C (>67%) with high overshoot | M20: CO2 price
A21: C2 | B21: R10EUROPE | C21: 2035 | D21: 75 | E21: 208.71 | F21: 154.82 | G21: 291.78 | H21: 60.83 | I21: 2037.12 | J21: 93.79 | K21: 206.26 | L21: Limit warming to 1.5°C (>67%) with high overshoot | M21: CO2 price
A22: C2 | B22: R10EUROPE | C22: 2040 | D22: 86 | E22: 253.33 | F22: 172.09 | G22: 359.35 | H22: 0 | I22: 2600 | J22: 119.07 | K22: 259.4 | L22: Limit warming to 1.5°C (>67%) with high overshoot | M22: CO2 price
... A221: C1 | B221: R10EUROPE | C221: 2020 | D221: 33 | E221: 1 | F221: 1 | G221: 0 | H221: 1 | I221: 1 | J221: 1 | K221: 1 | L221: Limit warming to 1.5°C (>50%) with no or limited overshoot | M221: Gas price
A222: C1 | B222: R10EUROPE | C222: 2025 | D222: 34 | E222: 65535 | F222: 2.42 | H222: 1.18 | I222: 65535 | J222: 2.01 | K222: 2.75 | L222: Limit warming to 1.5°C (>50%) with no or limited overshoot | M222: Gas price
A223: C1 | B223: R10EUROPE | C223: 2030 | D223: 34 | E223: 65535 | F223: 3.1 | H223: 1.71 | I223: 65535 | J223: 2.38 | K223: 3.46 | L223: Limit warming to 1.5°C (>50%) with no or limited overshoot | M223: Gas price
A224: C1 | B224: R10EUROPE | C224: 2035 | D224: 34 | E224: 65535 | F224: 3.54 | H224: 1.91 | I224: 65535 | J224: 2.66 | K224: 4.16 | L224: Limit warming to 1.5°C (>50%) with no or limited overshoot | M224: Gas price
A225: C1 | B225: R10EUROPE | C225: 2040 | D225: 34 | E225: 65535 | F225: 4.1 | H225: 2.27 | I225: 65535 | J225: 2.96 | K225: 4.52 | L225: Limit warming to 1.5°C (>50%) with no or limited overshoot | M225: Gas price
A226: C1 | B226: R10EUROPE | C226: 2045 | D226: 34 | E226: 65535 | F226: 3.86 | H226: 2.54 | I226: 65535 | J226: 3.3 | K226: 4.89 | L226: Limit warming to 1.5°C (>50%) with no or limited overshoot | M226: Gas price
A227: C1 | B227: R10EUROPE | C227: 2050 | D227: 34 | E227: 65535 | F227: 3.59 | H227: 2.73 | I227: 65535 | J227: 3.07 | K227: 4.06 | L227: Limit warming to 1.5°C (>50%) with no or limited overshoot | M227: Gas price
A228: C2 | B228: R10EUROPE | C228: 2020 | D228: 43 | E228: 1 | F228: 1 | G228: 0 | H228: 1 | I228: 1 | J228: 1 | K228: 1 | L228: Limit warming to 1.5°C (>67%) with high overshoot | M228: Gas price
A229: C2 | B229: R10EUROPE | C229: 2025 | D229: 44 | E229: 65535 | F229: 1.22 | H229: 0 | I229: 65535 | J229: 1.13 | K229: 1.35 | L229: Limit warming to 1.5°C (>67%) with high overshoot | M229: Gas price
A230: C2 | B230: R10EUROPE | C230: 2030 | D230: 44 | E230: 65535 | F230: 1.5 | H230: 0 | I230: 65535 | J230: 1.31 | K230: 1.83 | L230: Limit warming to 1.5°C (>67%) with high overshoot | M230: Gas price
A231: C2 | B231: R10EUROPE | C231: 2035 | D231: 44 | E231: 65535 | F231: 2.12 | H231: 0 | I231: 65535 | J231: 1.68 | K231: 2.46 | L231: Limit warming to 1.5°C (>67%) with high overshoot | M231: Gas price
A232: C2 | B232: R10EUROPE | C232: 2040 | D232: 44 | E232: 65535 | F232: 2.5 | H232: 0 | I232: 65535 | J232: 2 | K232: 2.94 | L232: Limit warming to 1.5°C (>67%) with high overshoot | M232: Gas price
A233: C2 | B233: R10EUROPE | C233: 2045 | D233: 44 | E233: 65535 | F233: 2.79 | H233: 0 | I233: 65535 | J233: 2.08 | K233: 3.44 | L233: Limit warming to 1.5°C (>67%) with high overshoot | M233: Gas price
A234: C2 | B234: R10EUROPE | C234: 2050 | D234: 44 | E234: 65535 | F234: 2.95 | H234: 0 | I234: 65535 | J234: 2.49 | K234: 3.78 | L234: Limit warming to 1.5°C (>67%) with high overshoot | M234: Gas price
A235: C3 | B235: R10EUROPE | C235: 2020 | D235: 103 | E235: 1 | F235: 1 | G235: 0 | H235: 1 | I235: 1 | J235: 1 | K235: 1 | L235: Limit warming to 2°C (>67%) with higher action post-2030 | M235: Gas price
A236: C3 | B236: R10EUROPE | C236: 2025 | D236: 112 | E236: 65535 | F236: 1.41 | H236: 0.98 | I236: 65535 | J236: 1.23 | K236: 1.96 | L236: Limit warming to 2°C (>67%) with higher action post-2030 | M236: Gas price
A237: C3 | B237: R10EUROPE | C237: 2030 | D237: 112 | E237: 65535 | F237: 2.04 | H237: 1.05 | I237: 65535 | J237: 1.52 | K237: 2.55 | L237: Limit warming to 2°C (>67%) with higher action post-2030 | M237: Gas price
A238: C3 | B238: R10EUROPE | C238: 2035 | D238: 112 | E238: 65535 | F238: 2.4 | H238: 1.05 | I238: 65535 | J238: 1.71 | K238: 3.14 | L238: Limit warming to 2°C (>67%) with higher action post-2030 | M238: Gas price
A239: C3 | B239: R10EUROPE | C239: 2040 | D239: 112 | E239: 65535 | F239: 2.6 | H239: 1.06 | I239: 65535 | J239: 1.85 | K239: 3.74 | L239: Limit warming to 2°C (>67%) with higher action post-2030 | M239: Gas price
A240: C3 | B240: R10EUROPE | C240: 2045 | D240: 112 | E240: 65535 | F240: 2.85 | H240: 1.08 | I240: 65535 | J240: 2 | K240: 4.28 | L240: Limit warming to 2°C (>67%) with higher action post-2030 | M240: Gas price
A241: C3 | B241: R10EUROPE | C241: 2050 | D241: 112 | E241: 65535 | F241: 2.97 | H241: 0 | I241: 65535 | J241: 2.15 | K241: 4.51 | L241: Limit warming to 2°C (>67%) with higher action post-2030 | M241: Gas price
A242: C4 | B242: R10EUROPE | C242: 2020 | D242: 27 | E242: 1 | F242: 1 | G242: 0 | H242: 1 | I242: 1 | J242: 1 | K242: 1 | L242: Limit warming to 2°C (>50%) with immediate action | M242: Gas price
A243: C4 | B243: R10EUROPE | C243: 2025 | D243: 27 | E243: 1.33 | F243: 1.31 | G243: 0.18 | H243: 1.06 | I243: 1.66 | J243: 1.22 | K243: 1.45 | L243: Limit warming to 2°C (>50%) with immediate action | M243: Gas price
A244: C4 | B244: R10EUROPE | C244: 2030 | D244: 27 | E244: 1.84 | F244: 2.02 | G244: 0.28 | H244: 1.24 | I244: 2.17 | J244: 1.52 | K244: 2.07 | L244: Limit warming to 2°C (>50%) with immediate action | M244: Gas price
A245: C4 | B245: R10EUROPE | C245: 2035 | D245: 27 | E245: 1.84 | F245: 1.96 | G245: 0.41 | H245: 1.19 | I245: 2.46 | J245: 1.42 | K245: 2.11 | L245: Limit warming to 2°C (>50%) with immediate action | M245: Gas price
A246: C4 | B246: R10EUROPE | C246: 2040 | D246: 27 | E246: 2.12 | F246: 2.22 | G246: 0.47 | H246: 1.41 | I246: 2.78 | J246: 1.54 | K246: 2.43 | L246: Limit warming to 2°C (>50%) with immediate action | M246: Gas price
...

Sheet ev_charging_uc
A10: =IFERROR(Veda!D5,"ts_12t") -> ts_annual | C10: day_night | D10: ts_012 | F10: day_night | G10: ts_048 | I10: day_night | J10: s1v1_d | L10: day_night | M10: ts_annual | O10: day_night | P10: ts_12t
C11: D | D11: S02aH02,S03aH02,S01aH02 | F11: D | G11: S03aH02,S07aH05,S04aH03,S07aH04,S05aH04,S06aH02,S06aH03,S01aH04,S07aH02,S01aH05,S06aH05,S03aH04,S03aH03,S02aH02,S03aH05,S05aH05,S06aH04,S02aH04,S02aH05,S04aH02,S01aH02,S04aH04,S02aH03,S07aH03,S04aH05,S01aH03,S05aH02,S05aH03 | I11: D | J11: S01aH03,S05aH02,S05aH03,S05aH04,S05b0925h16,S06aH02,S06aH03,S07c1209h10,S07c1209h11,S01aH02,S04aH04,S07c1209h12,S02aH03,S07aH03,S07c1209h08,S07c1209h17,S03aH03,S05b0925h17,S07c1209h15,S04aH03,S07aH04,S03aH05,S05aH05,S06aH04,S07c1209h13,S03aH02,S05b0925h10,S05b0925h18,S07aH05,S01aH05,S05b0925h11,S06aH05,S04aH05,S05b0925h13,S03aH04,S05b0925h12,S02aH04,S02aH05,S07c1209h16,S04aH02,S05b0925h15,S07c1209h09,S01aH04,S05b0925h09,S05b0925h14,S07aH02,S07c1209h14,S05b0925h08,S07c1209h07,S07c1209h18,S02aH02,S05b0925h07 | L11: D | M11: AllSaAllH | O11: D | P11: FaD,WaD,SaD,WaP,RaD,FaP,SaP,RaP
C12: N | D12: S03aH01,S03aH03,S01aH01,S02aH03,S01aH03,S02aH01 | F12: N | G12: S02aH01,S05aH06,S01aH06,S07aH01,S05aH01,S07aH06,S06aH01,S06aH06,S03aH01,S02aH06,S03aH06,S01aH01,S04aH01,S04aH06 | I12: N | J12: S05b0925h03,S05b0925h24,S07c1209h20,S01aH06,S05b0925h02,S07aH01,S03aH06,S07c1209h02,S07c1209h19,S01aH01,S04aH01,S04aH06,S07c1209h23,S06aH06,S02aH01,S05aH06,S05b0925h04,S05b0925h19,S05b0925h06,S05b0925h20,S05b0925h05,S07c1209h01,S05b0925h21,S05aH01,S07aH06,S07c1209h05,S07c1209h06,S02aH06,S07c1209h24,S05b0925h01,S05b0925h22,S07c1209h03,S07c1209h21,S07c1209h22,S05b0925h23,S06aH01,S03aH01,S07c1209h04 | L12: N | M12: AllSaAllH | O12: N | P12: SaN,WaN,RaP,FaP,SaP,FaN,WaP,RaN
I17: 0.75 | K17: share of charging at night
C18: ~UC_Sets: R_E: AllRegions
H21: =IF(H23=H24,"Not Required!","~UC_T: LO") -> Not Required!
C22: UC_N | D22: Pset_CI | E22: Pset_CO | F22: pset_pn | G22: Cset_CN | H22: TimeSlice | I22: UC_FLO | J22: UC_RHSRT | K22: UC_RHSRT~0
C23: UC_bev night chg limit | D23: ELC | E23: =G23 -> AuxStoIN | F23: *EV* | G23: AuxStoIN | H23: =HLOOKUP($A$10,$D$10:$CU$12,3,FALSE) -> AllSaAllH | I23: =1+I24 -> 0.25 | J23: 0 | K23: 3 | M23: night
D24: ELC | E24: =G24 -> AuxStoIN | F24: *EV* | G24: AuxStoIN | H24: =HLOOKUP($A$10,$D$10:$CU$12,2,FALSE) -> AllSaAllH | I24: =-$I$17 -> -0.75 | M24: day

Sheet ts_012
C9: =IF(A11="x","DeActivated","~TimeSlices") -> DeActivated | I9: =IF(A11="x","DeActivated","~TFM_DINS-AT") -> DeActivated | N9: =IF(A11="x","DeActivated","~TFM_DINS-AT") -> DeActivated | S9: =IF(A11="x","DeActivated","~TFM_DINS-AT") -> DeActivated | X9: =IF(A11="x","DeActivated","~TFM_DINS-AT") -> DeActivated | AC9: =IF(A11="x","DeActivated","~TFM_DINS-AT") -> DeActivated | AG9: =IF(A11="x","DeActivated","~TFM_DINS-AT") -> DeActivated | AK9: =IF(A11="x","DeActivated","~TFM_INS-AT") -> DeActivated
A10: ts_012 | C10: season | D10: weekly | E10: daynite | F10: wparent | G10: dparent | I10: commodity | J10: timeslice | K10: com_fr | L10: process | N10: commodity | O10: timeslice | P10: com_fr | Q10: process | S10: commodity | T10: timeslice | U10: com_fr | V10: process | X10: g_yrfr | Y10: com_fr | Z10: timeslice | AA10: commodity | AC10: commodity | AD10: timeslice | AE10: com_fr | AG10: commodity | AH10: timeslice | AI10: com_pkflx | AK10: Year | AL10: timeslice | AM10: ncap_afs | AN10: pset_ci
A11: =IFERROR(IF(Veda!D5=A10,"ok","x"),"") -> x | C11: S01 | D11: a | E11: H01 | F11: S01,S02,S03 | G11: a | I11: elc_spv_001 | J11: S01aH01 | K11: 0.007872801 | L11: IMPNRGZ | N11: elc_won_001 | O11: S01aH01 | P11: 0.072241717 | Q11: IMPNRGZ | S11: elc_wof_001 | T11: S01aH01 | U11: 0.076795046 | V11: IMPNRGZ | X11: 0.060616438 | Y11: 0.038469864 | Z11: S01aH01 | AA11: elc_roadtransport | AC11: elc_buildings | AD11: S01aH01 | AE11: 0.057807536 | AG11: ELC | AH11: S01aH01 | AI11: 0.30252383 | AK11: 2020 | AL11: S01 | AM11: 0.20444939 | AN11: hydro
C12: S02 | E12: H02 | G12: a | I12: elc_spv_001 | J12: S01aH02 | K12: 0.11132761 | L12: IMPNRGZ | N12: elc_won_001 | O12: S01aH02 | P12: 0.050135149 | Q12: IMPNRGZ | S12: elc_wof_001 | T12: S01aH02 | U12: 0.066759258 | V12: IMPNRGZ | X12: 0.053881279 | Y12: 0.074475466 | Z12: S01aH02 | AA12: elc_roadtransport | AC12: elc_buildings | AD12: S01aH02 | AE12: 0.067402909 | AG12: ELC | AH12: S01aH02 | AI12: 0.083799018 | AK12: 2020 | AL12: S02 | AM12: 0.28240276 | AN12: hydro
C13: S03 | E13: H03 | G13: a | I13: elc_spv_001 | J13: S01aH03 | K13: 0.0028461972 | L13: IMPNRGZ | N13: elc_won_001 | O13: S01aH03 | P13: 0.058821264 | Q13: IMPNRGZ | S13: elc_wof_001 | T13: S01aH03 | U13: 0.062602418 | V13: IMPNRGZ | X13: 0.047146119 | Y13: 0.048698506 | Z13: S01aH03 | AA13: elc_roadtransport | AC13: elc_buildings | AD13: S01aH03 | AE13: 0.054728049 | AG13: ELC | AH13: S01aH03 | AI13: 0.15334979 | AK13: 2020 | AL13: S03 | AM13: 0.23154122 | AN13: hydro
I14: elc_spv_001 | J14: S02aH01 | K14: 0.13295821 | L14: IMPNRGZ | N14: elc_won_001 | O14: S02aH01 | P14: 0.31075019 | Q14: IMPNRGZ | S14: elc_wof_001 | T14: S02aH01 | U14: 0.25682471 | V14: IMPNRGZ | X14: 0.28253425 | Y14: 0.17930869 | Z14: S02aH01 | AA14: elc_roadtransport | AC14: elc_buildings | AD14: S02aH01 | AE14: 0.23826401 | AG14: ELC | AH14: S02aH01 | AI14: 0.40785115 | AK14: 2021 | AL14: S01 | AM14: 0.24603807 | AN14: hydro
I15: elc_spv_001 | J15: S02aH02 | K15: 0.62233483 | L15: IMPNRGZ | N15: elc_won_001 | O15: S02aH02 | P15: 0.20388217 | Q15: IMPNRGZ | S15: elc_wof_001 | T15: S02aH02 | U15: 0.21641115 | V15: IMPNRGZ | X15: 0.25114155 | Y15: 0.34713141 | Z15: S02aH02 | AA15: elc_roadtransport | AC15: elc_buildings | AD15: S02aH02 | AE15: 0.26989362 | AG15: ELC | AH15: S02aH02 | AI15: 0.1789314 | AK15: 2021 | AL15: S02 | AM15: 0.25602924 | AN15: hydro
I16: elc_spv_001 | J16: S02aH03 | K16: 0.069784572 | L16: IMPNRGZ | N16: elc_won_001 | O16: S02aH03 | P16: 0.21188123 | Q16: IMPNRGZ | S16: elc_wof_001 | T16: S02aH03 | U16: 0.24466171 | V16: IMPNRGZ | X16: 0.21974886 | Y16: 0.22698456 | Z16: S02aH03 | AA16: elc_roadtransport | AC16: elc_buildings | AD16: S02aH03 | AE16: 0.22051454 | AG16: ELC | AH16: S02aH03 | AI16: 0.2516284 | AK16: 2021 | AL16: S03 | AM16: 0.18792909 | AN16: hydro
I17: elc_spv_001 | J17: S03aH01 | K17: 0.003350594 | L17: IMPNRGZ | N17: elc_won_001 | O17: S03aH01 | P17: 0.040719517 | Q17: IMPNRGZ | S17: elc_wof_001 | T17: S03aH01 | U17: 0.029119549 | V17: IMPNRGZ | X17: 0.031849315 | Y17: 0.020212979 | Z17: S03aH01 | AA17: elc_roadtransport | AC17: elc_buildings | AD17: S03aH01 | AE17: 0.029565445 | AG17: ELC | AH17: S03aH01 | AI17: 0.31276891 | AK17: 2022 | AL17: S01 | AM17: 0.13808808 | AN17: hydro
I18: elc_spv_001 | J18: S03aH02 | K18: 0.049525188 | L18: IMPNRGZ | N18: elc_won_001 | O18: S03aH02 | P18: 0.029731617 | Q18: IMPNRGZ | S18: elc_wof_001 | T18: S03aH02 | U18: 0.026908589 | V18: IMPNRGZ | X18: 0.028310502 | Y18: 0.039131177 | Z18: S03aH02 | AA18: elc_roadtransport | AC18: elc_buildings | AD18: S03aH02 | AE18: 0.033907224 | AG18: ELC | AH18: S03aH02 | AI18: 0.080434653 | AK18: 2022 | AL18: S02 | AM18: 0.16381698 | AN18: hydro
I19: elc_spv_001 | J19: S03aH03 | K19: 0 | L19: IMPNRGZ | N19: elc_won_001 | O19: S03aH03 | P19: 0.021837141 | Q19: IMPNRGZ | S19: elc_wof_001 | T19: S03aH03 | U19: 0.019917567 | V19: IMPNRGZ | X19: 0.024771689 | Y19: 0.025587351 | Z19: S03aH03 | AA19: elc_roadtransport | AC19: elc_buildings | AD19: S03aH03 | AE19: 0.027916676 | AG19: ELC | AH19: S03aH03 | AI19: 0.15671262 | AK19: 2022 | AL19: S03 | AM19: 0.15407642 | AN19: hydro
I20: elc_spv_002 | J20: S01aH01 | K20: 0.0072816599 | L20: IMPNRGZ | N20: elc_won_002 | O20: S01aH01 | P20: 0.075816687 | Q20: IMPNRGZ | S20: elc_wof_002 | T20: S01aH01 | U20: 0.075355411 | V20: IMPNRGZ | AC20: elc_industry | AD20: S01aH01 | AE20: 0.059897088 | AK20: 2025 | AL20: S01 | AM20: 0.1916 | AN20: hydro
I21: elc_spv_002 | J21: S01aH02 | K21: 0.10071256 | L21: IMPNRGZ | N21: elc_won_002 | O21: S01aH02 | P21: 0.066024767 | Q21: IMPNRGZ | S21: elc_wof_002 | T21: S01aH02 | U21: 0.058881582 | V21: IMPNRGZ | AC21: elc_industry | AD21: S01aH02 | AE21: 0.054522625 | AK21: 2025 | AL21: S02 | AM21: 0.28716667 | AN21: hydro
I22: elc_spv_002 | J22: S01aH03 | K22: 0.0025626876 | L22: IMPNRGZ | N22: elc_won_002 | O22: S01aH03 | P22: 0.058104259 | Q22: IMPNRGZ | S22: elc_wof_002 | T22: S01aH03 | U22: 0.062155866 | V22: IMPNRGZ | AC22: elc_industry | AD22: S01aH03 | AE22: 0.047367524 | AK22: 2025 | AL22: S03 | AM22: 0.2449 | AN22: hydro
I23: elc_spv_002 | J23: S02aH01 | K23: 0.14696927 | L23: IMPNRGZ | N23: elc_won_002 | O23: S02aH01 | P23: 0.25874436 | Q23: IMPNRGZ | S23: elc_wof_002 | T23: S02aH01 | U23: 0.28071728 | V23: IMPNRGZ | AC23: elc_industry | AD23: S02aH01 | AE23: 0.27966399 | AK23: 2026 | AL23: S01 | AM23: 0.13995 | AN23: hydro
I24: elc_spv_002 | J24: S02aH02 | K24: 0.6240052 | L24: IMPNRGZ | N24: elc_won_002 | O24: S02aH02 | P24: 0.24043395 | Q24: IMPNRGZ | S24: elc_wof_002 | T24: S02aH02 | U24: 0.21414456 | V24: IMPNRGZ | AC24: elc_industry | AD24: S02aH02 | AE24: 0.25323592 | AK24: 2026 | AL24: S02 | AM24: 0.21811111 | AN24: hydro
I25: elc_spv_002 | J25: S02aH03 | K25: 0.073428503 | L25: IMPNRGZ | N25: elc_won_002 | O25: S02aH03 | P25: 0.21829123 | Q25: IMPNRGZ | S25: elc_wof_002 | T25: S02aH03 | U25: 0.22338933 | V25: IMPNRGZ | AC25: elc_industry | AD25: S02aH03 | AE25: 0.22033073 | AK25: 2026 | AL25: S03 | AM25: 0.1556 | AN25: hydro
I26: elc_spv_002 | J26: S03aH01 | K26: 0.0027406934 | L26: IMPNRGZ | N26: elc_won_002 | O26: S03aH01 | P26: 0.032548142 | Q26: IMPNRGZ | S26: elc_wof_002 | T26: S03aH01 | U26: 0.033084229 | V26: IMPNRGZ | AC26: elc_industry | AD26: S03aH01 | AE26: 0.03149206 | AK26: 2027 | AL26: S01 | AM26: 0.1575 | AN26: hydro
I27: elc_spv_002 | J27: S03aH02 | K27: 0.042299429 | L27: IMPNRGZ | N27: elc_won_002 | O27: S03aH02 | P27: 0.026305322 | Q27: IMPNRGZ | S27: elc_wof_002 | T27: S03aH02 | U27: 0.03071761 | V27: IMPNRGZ | AC27: elc_industry | AD27: S03aH02 | AE27: 0.028602752 | AK27: 2027 | AL27: S02 | AM27: 0.21561111 | AN27: hydro
I28: elc_spv_002 | J28: S03aH03 | K28: 0 | L28: IMPNRGZ | N28: elc_won_002 | O28: S03aH03 | P28: 0.023731281 | Q28: IMPNRGZ | S28: elc_wof_002 | T28: S03aH03 | U28: 0.021554129 | V28: IMPNRGZ | AC28: elc_industry | AD28: S03aH03 | AE28: 0.024887314 | AK28: 2027 | AL28: S03 | AM28: 0.1713 | AN28: hydro
I29: elc_spv_003 | J29: S01aH01 | K29: 0.0082697007 | L29: IMPNRGZ | N29: elc_won_003 | O29: S01aH01 | P29: 0.082016971 | Q29: IMPNRGZ | S29: elc_wof_003 | T29: S01aH01 | U29: 0.076609735 | V29: IMPNRGZ | AK29: 2028 | AL29: S01 | AM29: 0.16795 | AN29: hydro
I30: elc_spv_003 | J30: S01aH02 | K30: 0.10433937 | L30: IMPNRGZ | N30: elc_won_003 | O30: S01aH02 | P30: 0.074909594 | Q30: IMPNRGZ | S30: elc_wof_003 | T30: S01aH02 | U30: 0.063459413 | V30: IMPNRGZ | AK30: 2028 | AL30: S02 | AM30: 0.25663333 | AN30: hydro
I31: elc_spv_003 | J31: S01aH03 | K31: 0.0031007801 | L31: IMPNRGZ | N31: elc_won_003 | O31: S01aH03 | P31: 0.065044374 | Q31: IMPNRGZ | S31: elc_wof_003 | T31: S01aH03 | U31: 0.063314425 | V31: IMPNRGZ | AK31: 2028 | AL31: S03 | AM31: 0.1885 | AN31: hydro
I32: elc_spv_003 | J32: S02aH01 | K32: 0.15014598 | L32: IMPNRGZ | N32: elc_won_003 | O32: S02aH01 | P32: 0.23552682 | Q32: IMPNRGZ | S32: elc_wof_003 | T32: S02aH01 | U32: 0.28215069 | V32: IMPNRGZ | AK32: 2029 | AL32: S01 | AM32: 0.1786 | AN32: hydro
I33: elc_spv_003 | J33: S02aH02 | K33: 0.61328893 | L33: IMPNRGZ | N33: elc_won_003 | O33: S02aH02 | P33: 0.24146973 | Q33: IMPNRGZ | S33: elc_wof_003 | T33: S02aH02 | U33: 0.21495384 | V33: IMPNRGZ | AK33: 2029 | AL33: S02 | AM33: 0.24352222 | AN33: hydro
I34: elc_spv_003 | J34: S02aH03 | K34: 0.071596045 | L34: IMPNRGZ | N34: elc_won_003 | O34: S02aH03 | P34: 0.21282366 | Q34: IMPNRGZ | S34: elc_wof_003 | T34: S02aH03 | U34: 0.23103267 | V34: IMPNRGZ | AK34: 2029 | AL34: S03 | AM34: 0.1898 | AN34: hydro
I35: elc_spv_003 | J35: S03aH01 | K35: 0.0034576674 | L35: IMPNRGZ | N35: elc_won_003 | O35: S03aH01 | P35: 0.03750662 | Q35: IMPNRGZ | S35: elc_wof_003 | T35: S03aH01 | U35: 0.026915331 | V35: IMPNRGZ | AK35: 2030 | AL35: S01 | AM35: 0.17745 | AN35: hydro
I36: elc_spv_003 | J36: S03aH02 | K36: 0.045801528 | L36: IMPNRGZ | N36: elc_won_003 | O36: S03aH02 | P36: 0.026712644 | Q36: IMPNRGZ | S36: elc_wof_003 | T36: S03aH02 | U36: 0.023082444 | V36: IMPNRGZ | AK36: 2030 | AL36: S02 | AM36: 0.25435556 | AN36: hydro
I37: elc_spv_003 | J37: S03aH03 | K37: 0 | L37: IMPNRGZ | N37: elc_won_003 | O37: S03aH03 | P37: 0.023989588 | Q37: IMPNRGZ | S37: elc_wof_003 | T37: S03aH03 | U37: 0.018481453 | V37: IMPNRGZ | AK37: 2030 | AL37: S03 | AM37: 0.1824 | AN37: hydro
I38: elc_spv_004 | J38: S01aH01 | K38: 0.0082928763 | L38: IMPNRGZ | N38: elc_won_004 | O38: S01aH01 | P38: 0.072875411 | Q38: IMPNRGZ | S38: elc_wof_004 | T38: S01aH01 | U38: 0.089387021 | V38: IMPNRGZ | AK38: 2031 | AL38: S01 | AM38: 0.17805 | AN38: hydro
I39: elc_spv_004 | J39: S01aH02 | K39: 0.1129525 | L39: IMPNRGZ | N39: elc_won_004 | O39: S01aH02 | P39: 0.064185283 | Q39: IMPNRGZ | S39: elc_wof_004 | T39: S01aH02 | U39: 0.082235751 | V39: IMPNRGZ | AK39: 2031 | AL39: S02 | AM39: 0.24632222 | AN39: hydro
I40: elc_spv_004 | J40: S01aH03 | K40: 0.0032474065 | L40: IMPNRGZ | N40: elc_won_004 | O40: S01aH03 | P40: 0.061379895 | Q40: IMPNRGZ | S40: elc_wof_004 | T40: S01aH03 | U40: 0.078481723 | V40: IMPNRGZ | AK40: 2031 | AL40: S03 | AM40: 0.2086 | AN40: hydro
... I97: elc_spv_010 | J97: S02aH03 | K97: 0.069082105 | L97: IMPNRGZ | N97: elc_won_010 | O97: S02aH03 | P97: 0.21428533 | Q97: IMPNRGZ | S97: elc_wof_010 | T97: S02aH03 | U97: 0.23081241 | V97: IMPNRGZ | AK97: 2050 | AL97: S03 | AM97: 0.1942 | AN97: hydro
I98: elc_spv_010 | J98: S03aH01 | K98: 0.0027040058 | L98: IMPNRGZ | N98: elc_won_010 | O98: S03aH01 | P98: 0.029158206 | Q98: IMPNRGZ | S98: elc_wof_010 | T98: S03aH01 | U98: 0.027153745 | V98: IMPNRGZ
I99: elc_spv_010 | J99: S03aH02 | K99: 0.042323053 | L99: IMPNRGZ | N99: elc_won_010 | O99: S03aH02 | P99: 0.028990741 | Q99: IMPNRGZ | S99: elc_wof_010 | T99: S03aH02 | U99: 0.021913199 | V99: IMPNRGZ
I100: elc_spv_010 | J100: S03aH03 | K100: 0 | L100: IMPNRGZ | N100: elc_won_010 | O100: S03aH03 | P100: 0.021371497 | Q100: IMPNRGZ | S100: elc_wof_010 | T100: S03aH03 | U100: 0.018560494 | V100: IMPNRGZ
I101: elc_spv_011 | J101: S01aH01 | K101: 0.0094340013 | L101: IMPNRGZ | N101: elc_won_011 | O101: S01aH01 | P101: 0.081636 | Q101: IMPNRGZ | S101: elc_wof_011 | T101: S01aH01 | U101: 0.0721047 | V101: IMPNRGZ
I102: elc_spv_011 | J102: S01aH02 | K102: 0.09674754 | L102: IMPNRGZ | N102: elc_won_011 | O102: S01aH02 | P102: 0.069277282 | Q102: IMPNRGZ | S102: elc_wof_011 | T102: S01aH02 | U102: 0.068033248 | V102: IMPNRGZ
I103: elc_spv_011 | J103: S01aH03 | K103: 0.0030298538 | L103: IMPNRGZ | N103: elc_won_011 | O103: S01aH03 | P103: 0.068662627 | Q103: IMPNRGZ | S103: elc_wof_011 | T103: S01aH03 | U103: 0.058420744 | V103: IMPNRGZ
I104: elc_spv_011 | J104: S02aH01 | K104: 0.14317457 | L104: IMPNRGZ | N104: elc_won_011 | O104: S02aH01 | P104: 0.26914742 | Q104: IMPNRGZ | S104: elc_wof_011 | T104: S02aH01 | U104: 0.26674771 | V104: IMPNRGZ
...

Sheet ts_048
C9: =IF(A11="x","DeActivated","~TimeSlices") -> DeActivated | I9: =IF(A11="x","DeActivated","~TFM_DINS-AT") -> DeActivated | N9: =IF(A11="x","DeActivated","~TFM_DINS-AT") -> DeActivated | S9: =IF(A11="x","DeActivated","~TFM_DINS-AT") -> DeActivated | X9: =IF(A11="x","DeActivated","~TFM_DINS-AT") -> DeActivated | AC9: =IF(A11="x","DeActivated","~TFM_DINS-AT") -> DeActivated | AG9: =IF(A11="x","DeActivated","~TFM_DINS-AT") -> DeActivated | AK9: =IF(A11="x","DeActivated","~TFM_INS-AT") -> DeActivated
A10: ts_048 | C10: season | D10: weekly | E10: daynite | F10: wparent | G10: dparent | I10: commodity | J10: timeslice | K10: com_fr | L10: process | N10: commodity | O10: timeslice | P10: com_fr | Q10: process | S10: commodity | T10: timeslice | U10: com_fr | V10: process | X10: g_yrfr | Y10: com_fr | Z10: timeslice | AA10: commodity | AC10: commodity | AD10: timeslice | AE10: com_fr | AG10: commodity | AH10: timeslice | AI10: com_pkflx | AK10: Year | AL10: timeslice | AM10: ncap_afs | AN10: pset_ci
A11: =IFERROR(IF(Veda!D5=A10,"ok","x"),"") -> x | C11: S01 | D11: a | E11: H01 | F11: S01,S02,S03,S04,S05,S06,S07 | G11: a | I11: elc_spv_001 | J11: S01aH01 | K11: 0.00063754206 | L11: IMPNRGZ | N11: elc_won_001 | O11: S01aH01 | P11: 0.064828535 | Q11: IMPNRGZ | S11: elc_wof_001 | T11: S01aH01 | U11: 0.06866819 | V11: IMPNRGZ | X11: 0.053881279 | Y11: 0.029864505 | Z11: S01aH01 | AA11: elc_roadtransport | AC11: elc_buildings | AD11: S01aH01 | AE11: 0.04941315 | AG11: ELC | AH11: S01aH01 | AI11: 0.30170208 | AK11: 2020 | AL11: S01 | AM11: 0.20444939 | AN11: hydro
C12: S02 | E12: H02 | G12: a | I12: elc_spv_001 | J12: S01aH02 | K12: 0.007235259 | L12: IMPNRGZ | N12: elc_won_001 | O12: S01aH02 | P12: 0.0074131828 | Q12: IMPNRGZ | S12: elc_wof_001 | T12: S01aH02 | U12: 0.0081268559 | V12: IMPNRGZ | X12: 0.0067351598 | Y12: 0.0086053585 | Z12: S01aH02 | AA12: elc_roadtransport | AC12: elc_buildings | AD12: S01aH02 | AE12: 0.0083943859 | AG12: ELC | AH12: S01aH02 | AI12: 0.047484009 | AK12: 2020 | AL12: S02 | AM12: 0.29145161 | AN12: hydro
C13: S03 | E13: H03 | G13: a | I13: elc_spv_001 | J13: S01aH03 | K13: 0.012089442 | L13: IMPNRGZ | N13: elc_won_001 | O13: S01aH03 | P13: 0.0068657912 | Q13: IMPNRGZ | S13: elc_wof_001 | T13: S01aH03 | U13: 0.0081269404 | V13: IMPNRGZ | X13: 0.0067351598 | Y13: 0.0085271279 | Z13: S01aH03 | AA13: elc_roadtransport | AC13: elc_buildings | AD13: S01aH03 | AE13: 0.0085234446 | AG13: ELC | AH13: S01aH03 | AI13: 0.04519733 | AK13: 2020 | AL13: S03 | AM13: 0.31541219 | AN13: hydro
C14: S04 | E14: H04 | G14: a | I14: elc_spv_001 | J14: S01aH04 | K14: 0.090128861 | L14: IMPNRGZ | N14: elc_won_001 | O14: S01aH04 | P14: 0.036095868 | Q14: IMPNRGZ | S14: elc_wof_001 | T14: S01aH04 | U14: 0.049841672 | V14: IMPNRGZ | X14: 0.040410959 | Y14: 0.052844724 | Z14: S01aH04 | AA14: elc_roadtransport | AC14: elc_buildings | AD14: S01aH04 | AE14: 0.050248408 | AG14: ELC | AH14: S01aH04 | AI14: 0.064766515 | AK14: 2020 | AL14: S04 | AM14: 0.28172043 | AN14: hydro
C15: S05 | E15: H05 | G15: a | I15: elc_spv_001 | J15: S01aH05 | K15: 0.0091093059 | L15: IMPNRGZ | N15: elc_won_001 | O15: S01aH05 | P15: 0.00717349 | Q15: IMPNRGZ | S15: elc_wof_001 | T15: S01aH05 | U15: 0.0087906453 | V15: IMPNRGZ | X15: 0.0067351598 | Y15: 0.013103614 | Z15: S01aH05 | AA15: elc_roadtransport | AC15: elc_buildings | AD15: S01aH05 | AE15: 0.0086310567 | AG15: ELC | AH15: S01aH05 | AI15: 0.062164802 | AK15: 2020 | AL15: S05 | AM15: 0.26814815 | AN15: hydro
C16: S06 | E16: H06 | G16: a | I16: elc_spv_001 | J16: S01aH06 | K16: 0.0028461972 | L16: IMPNRGZ | N16: elc_won_001 | O16: S01aH06 | P16: 0.058821264 | Q16: IMPNRGZ | S16: elc_wof_001 | T16: S01aH06 | U16: 0.062602418 | V16: IMPNRGZ | X16: 0.047146119 | Y16: 0.048698506 | Z16: S01aH06 | AA16: elc_roadtransport | AC16: elc_buildings | AD16: S01aH06 | AE16: 0.054728049 | AG16: ELC | AH16: S01aH06 | AI16: 0.15334979 | AK16: 2020 | AL16: S06 | AM16: 0.25526882 | AN16: hydro
C17: S07 | I17: elc_spv_001 | J17: S02aH01 | K17: 0.036890601 | L17: IMPNRGZ | N17: elc_won_001 | O17: S02aH01 | P17: 0.1166189 | Q17: IMPNRGZ | S17: elc_wof_001 | T17: S02aH01 | U17: 0.11714684 | V17: IMPNRGZ | X17: 0.11141553 | Y17: 0.061753723 | Z17: S02aH01 | AA17: elc_roadtransport | AC17: elc_buildings | AD17: S02aH01 | AE17: 0.090904601 | AG17: ELC | AH17: S02aH01 | AI17: 0.39609049 | AK17: 2020 | AL17: S07 | AM17: 0.23154122 | AN17: hydro
I18: elc_spv_001 | J18: S02aH02 | K18: 0.03098125 | L18: IMPNRGZ | N18: elc_won_001 | O18: S02aH02 | P18: 0.012037205 | Q18: IMPNRGZ | S18: elc_wof_001 | T18: S02aH02 | U18: 0.012893721 | V18: IMPNRGZ | X18: 0.013926941 | Y18: 0.017794131 | Z18: S02aH02 | AA18: elc_roadtransport | AC18: elc_buildings | AD18: S02aH02 | AE18: 0.014801271 | AG18: ELC | AH18: S02aH02 | AI18: 0.17260864 | AK18: 2021 | AL18: S01 | AM18: 0.24603807 | AN18: hydro
I19: elc_spv_001 | J19: S02aH03 | K19: 0.03787145 | L19: IMPNRGZ | N19: elc_won_001 | O19: S02aH03 | P19: 0.011232926 | Q19: IMPNRGZ | S19: elc_wof_001 | T19: S02aH03 | U19: 0.012158599 | V19: IMPNRGZ | X19: 0.013926941 | Y19: 0.017632366 | Z19: S02aH03 | AA19: elc_roadtransport | AC19: elc_buildings | AD19: S02aH03 | AE19: 0.014950244 | AG19: ELC | AH19: S02aH03 | AI19: 0.16646817 | AK19: 2021 | AL19: S02 | AM19: 0.26922212 | AN19: hydro
I20: elc_spv_001 | J20: S02aH04 | K20: 0.23912916 | L20: IMPNRGZ | N20: elc_won_001 | O20: S02aH04 | P20: 0.063417342 | Q20: IMPNRGZ | S20: elc_wof_001 | T20: S02aH04 | U20: 0.074842824 | V20: IMPNRGZ | X20: 0.083561644 | Y20: 0.10927214 | Z20: S02aH04 | AA20: elc_roadtransport | AC20: elc_buildings | AD20: S02aH04 | AE20: 0.08871793 | AG20: ELC | AH20: S02aH04 | AI20: 0.17061162 | AK20: 2021 | AL20: S03 | AM20: 0.33584287 | AN20: hydro
I21: elc_spv_001 | J21: S02aH05 | K21: 0.030327046 | L21: IMPNRGZ | N21: elc_won_001 | O21: S02aH05 | P21: 0.012796742 | Q21: IMPNRGZ | S21: elc_wof_001 | T21: S02aH05 | U21: 0.016533281 | V21: IMPNRGZ | X21: 0.013926941 | Y21: 0.027095609 | Z21: S02aH05 | AA21: elc_roadtransport | AC21: elc_buildings | AD21: S02aH05 | AE21: 0.014843447 | AG21: ELC | AH21: S02aH05 | AI21: 0.18674182 | AK21: 2021 | AL21: S04 | AM21: 0.30726049 | AN21: hydro
I22: elc_spv_001 | J22: S02aH06 | K22: 0.039177781 | L22: IMPNRGZ | N22: elc_won_001 | O22: S02aH06 | P22: 0.093504477 | Q22: IMPNRGZ | S22: elc_wof_001 | T22: S02aH06 | U22: 0.11989268 | V22: IMPNRGZ | X22: 0.097488584 | Y22: 0.10069861 | Z22: S02aH06 | AA22: elc_roadtransport | AC22: elc_buildings | AD22: S02aH06 | AE22: 0.096799028 | AG22: ELC | AH22: S02aH06 | AI22: 0.26211435 | AK22: 2021 | AL22: S05 | AM22: 0.20010042 | AN22: hydro
I23: elc_spv_001 | J23: S03aH01 | K23: 0.012969968 | L23: IMPNRGZ | N23: elc_won_001 | O23: S03aH01 | P23: 0.016572055 | Q23: IMPNRGZ | S23: elc_wof_001 | T23: S03aH01 | U23: 0.017417922 | V23: IMPNRGZ | X23: 0.028310502 | Y23: 0.01569152 | Z23: S03aH01 | AA23: elc_roadtransport | AC23: elc_buildings | AD23: S03aH01 | AE23: 0.023847088 | AG23: ELC | AH23: S03aH01 | AI23: 0.29079454 | AK23: 2021 | AL23: S06 | AM23: 0.19208545 | AN23: hydro
I24: elc_spv_001 | J24: S03aH02 | K24: 0.00905701 | L24: IMPNRGZ | N24: elc_won_001 | O24: S03aH02 | P24: 0.0012235336 | Q24: IMPNRGZ | S24: elc_wof_001 | T24: S03aH02 | U24: 0.0019935651 | V24: IMPNRGZ | X24: 0.0035388128 | Y24: 0.0045214595 | Z24: S03aH02 | AA24: elc_roadtransport | AC24: elc_buildings | AD24: S03aH02 | AE24: 0.0039226118 | AG24: ELC | AH24: S03aH02 | AI24: 0.074383366 | AK24: 2021 | AL24: S07 | AM24: 0.18792909 | AN24: hydro
I25: elc_spv_001 | J25: S03aH03 | K25: 0.010424155 | L25: IMPNRGZ | N25: elc_won_001 | O25: S03aH03 | P25: 0.0012093637 | Q25: IMPNRGZ | S25: elc_wof_001 | T25: S03aH03 | U25: 0.0019207938 | V25: IMPNRGZ | X25: 0.0035388128 | Y25: 0.0044803554 | Z25: S03aH03 | AA25: elc_roadtransport | AC25: elc_buildings | AD25: S03aH03 | AE25: 0.0039935522 | AG25: ELC | AH25: S03aH03 | AI25: 0.069020627 | AK25: 2022 | AL25: S01 | AM25: 0.13808808 | AN25: hydro
I26: elc_spv_001 | J26: S03aH04 | K26: 0.060481442 | L26: IMPNRGZ | N26: elc_won_001 | O26: S03aH04 | P26: 0.0067963857 | Q26: IMPNRGZ | S26: elc_wof_001 | T26: S03aH04 | U26: 0.013590984 | V26: IMPNRGZ | X26: 0.021232877 | Y26: 0.027765872 | Z26: S03aH04 | AA26: elc_roadtransport | AC26: elc_buildings | AD26: S03aH04 | AE26: 0.024369651 | AG26: ELC | AH26: S03aH04 | AI26: 0.077676552 | AK26: 2022 | AL26: S02 | AM26: 0.16723564 | AN26: hydro
I27: elc_spv_001 | J27: S03aH05 | K27: 0.0074231169 | L27: IMPNRGZ | N27: elc_won_001 | O27: S03aH05 | P27: 0.0010893799 | Q27: IMPNRGZ | S27: elc_wof_001 | T27: S03aH05 | U27: 0.0033008992 | V27: IMPNRGZ | X27: 0.0035388128 | Y27: 0.0068849497 | Z27: S03aH05 | AA27: elc_roadtransport | AC27: elc_buildings | AD27: S03aH05 | AE27: 0.0040189562 | AG27: ELC | AH27: S03aH05 | AI27: 0.070840188 | AK27: 2022 | AL27: S03 | AM27: 0.22223926 | AN27: hydro
I28: elc_spv_001 | J28: S03aH06 | K28: 0.012521754 | L28: IMPNRGZ | N28: elc_won_001 | O28: S03aH06 | P28: 0.0083676261 | Q28: IMPNRGZ | S28: elc_wof_001 | T28: S03aH06 | U28: 0.023130289 | V28: IMPNRGZ | X28: 0.024771689 | Y28: 0.025587351 | Z28: S03aH06 | AA28: elc_roadtransport | AC28: elc_buildings | AD28: S03aH06 | AE28: 0.026192679 | AG28: ELC | AH28: S03aH06 | AI28: 0.126544 | AK28: 2022 | AL28: S04 | AM28: 0.1704071 | AN28: hydro
I29: elc_spv_001 | J29: S04aH01 | K29: 0.010813125 | L29: IMPNRGZ | N29: elc_won_001 | O29: S04aH01 | P29: 0.034882492 | Q29: IMPNRGZ | S29: elc_wof_001 | T29: S04aH01 | U29: 0.020534219 | V29: IMPNRGZ | X29: 0.028310502 | Y29: 0.01569152 | Z29: S04aH01 | AA29: elc_roadtransport | AC29: elc_buildings | AD29: S04aH01 | AE29: 0.023274743 | AG29: ELC | AH29: S04aH01 | AI29: 0.29227722 | AK29: 2022 | AL29: S05 | AM29: 0.13940248 | AN29: hydro
... I52: elc_spv_001 | J52: S07aH06 | K52: 0 | L52: IMPNRGZ | N52: elc_won_001 | O52: S07aH06 | P52: 0.021837141 | Q52: IMPNRGZ | S52: elc_wof_001 | T52: S07aH06 | U52: 0.019917567 | V52: IMPNRGZ | X52: 0.024771689 | Y52: 0.025587351 | Z52: S07aH06 | AA52: elc_roadtransport | AC52: elc_buildings | AD52: S07aH06 | AE52: 0.027916676 | AG52: ELC | AH52: S07aH06 | AI52: 0.15671262 | AK52: 2027 | AL52: S07 | AM52: 0.1713 | AN52: hydro
I53: elc_spv_002 | J53: S01aH01 | K53: 0.00051548577 | L53: IMPNRGZ | N53: elc_won_002 | O53: S01aH01 | P53: 0.067031166 | Q53: IMPNRGZ | S53: elc_wof_002 | T53: S01aH01 | U53: 0.067317426 | V53: IMPNRGZ | AC53: elc_industry | AD53: S01aH01 | AE53: 0.053084237 | AK53: 2028 | AL53: S01 | AM53: 0.16795 | AN53: hydro
I54: elc_spv_002 | J54: S01aH02 | K54: 0.0067661742 | L54: IMPNRGZ | N54: elc_won_002 | O54: S01aH02 | P54: 0.0087855213 | Q54: IMPNRGZ | S54: elc_wof_002 | T54: S01aH02 | U54: 0.0080379846 | V54: IMPNRGZ | AC54: elc_industry | AD54: S01aH02 | AE54: 0.0068128513 | AK54: 2028 | AL54: S02 | AM54: 0.264975 | AN54: hydro
I55: elc_spv_002 | J55: S01aH03 | K55: 0.01087102 | L55: IMPNRGZ | N55: elc_won_002 | O55: S01aH03 | P55: 0.0086955578 | Q55: IMPNRGZ | S55: elc_wof_002 | T55: S01aH03 | U55: 0.0081333198 | V55: IMPNRGZ | AC55: elc_industry | AD55: S01aH03 | AE55: 0.0068231703 | AK55: 2028 | AL55: S03 | AM55: 0.3273 | AN55: hydro
I56: elc_spv_002 | J56: S01aH04 | K56: 0.081463728 | L56: IMPNRGZ | N56: elc_won_002 | O56: S01aH04 | P56: 0.048859315 | Q56: IMPNRGZ | S56: elc_wof_002 | T56: S01aH04 | U56: 0.04307072 | V56: IMPNRGZ | AC56: elc_industry | AD56: S01aH04 | AE56: 0.04086768 | AK56: 2028 | AL56: S04 | AM56: 0.2751 | AN56: hydro
I57: elc_spv_002 | J57: S01aH05 | K57: 0.0083778082 | L57: IMPNRGZ | N57: elc_won_002 | O57: S01aH05 | P57: 0.0084698938 | Q57: IMPNRGZ | S57: elc_wof_002 | T57: S01aH05 | U57: 0.0076775426 | V57: IMPNRGZ | AC57: elc_industry | AD57: S01aH05 | AE57: 0.0068317745 | AK57: 2028 | AL57: S05 | AM57: 0.2221 | AN57: hydro
I58: elc_spv_002 | J58: S01aH06 | K58: 0.0025626876 | L58: IMPNRGZ | N58: elc_won_002 | O58: S01aH06 | P58: 0.058104259 | Q58: IMPNRGZ | S58: elc_wof_002 | T58: S01aH06 | U58: 0.062155866 | V58: IMPNRGZ | AC58: elc_industry | AD58: S01aH06 | AE58: 0.047367524 | AK58: 2028 | AL58: S06 | AM58: 0.21265 | AN58: hydro
I59: elc_spv_002 | J59: S02aH01 | K59: 0.041364492 | L59: IMPNRGZ | N59: elc_won_002 | O59: S02aH01 | P59: 0.10557271 | Q59: IMPNRGZ | S59: elc_wof_002 | T59: S02aH01 | U59: 0.11462969 | V59: IMPNRGZ | AC59: elc_industry | AD59: S02aH01 | AE59: 0.11009359 | AK59: 2028 | AL59: S07 | AM59: 0.1885 | AN59: hydro
I60: elc_spv_002 | J60: S02aH02 | K60: 0.031124278 | L60: IMPNRGZ | N60: elc_won_002 | O60: S02aH02 | P60: 0.014293732 | Q60: IMPNRGZ | S60: elc_wof_002 | T60: S02aH02 | U60: 0.013698514 | V60: IMPNRGZ | AC60: elc_industry | AD60: S02aH02 | AE60: 0.014036603 | AK60: 2029 | AL60: S01 | AM60: 0.1786 | AN60: hydro
I61: elc_spv_002 | J61: S02aH03 | K61: 0.036672887 | L61: IMPNRGZ | N61: elc_won_002 | O61: S02aH03 | P61: 0.014383114 | Q61: IMPNRGZ | S61: elc_wof_002 | T61: S02aH03 | U61: 0.013032659 | V61: IMPNRGZ | AC61: elc_industry | AD61: S02aH03 | AE61: 0.014048515 | AK61: 2029 | AL61: S02 | AM61: 0.255075 | AN61: hydro
