Workbook

Sheet geolocation
B9: ~geolocation | F9: ~geolocation
B10: region | C10: lat | D10: lng | F10: region | G10: lat | H10: lng
B11: p_w153608703 | C11: 20.933212 | D11: 106.06495 | F11: VNM-e_w153608703-220 | G11: 20.933212 | H11: 106.06495
B12: p_w183249722 | C12: 12.576826 | D12: 107.92741 | F12: VNM-e_w183249722-220 | G12: 12.576826 | H12: 107.92741
B13: p_w241065371 | C13: 20.829349 | D13: 106.77614 | F13: VNM-e_w241065371-220 | G13: 20.829349 | H13: 106.77614
B14: p_w251790836 | C14: 20.877412 | D14: 105.8543 | F14: VNM-e_w251790836-500 | G14: 20.877412 | H14: 105.8543
B15: p_w1216970886 | C15: 10.607022 | D15: 107.03685 | F15: VNM-e_w251790836-220 | G15: 20.877589 | H15: 105.85402
B16: p_w294127333 | C16: 10.925577 | D16: 106.86961 | F16: VNM-e_w1216970886-500 | G16: 10.607022 | H16: 107.03685
B17: p_w306259034 | C17: 10.78021 | D17: 106.80148 | F17: VNM-e_w294127333-220 | G17: 10.925577 | H17: 106.86961
B18: p_w306295536 | C18: 10.700425 | D18: 106.71842 | F18: VNM-e_w306259034-220 | G18: 10.78021 | H18: 106.80148
B19: p_w306295540 | C19: 10.645185 | D19: 106.83978 | F19: VNM-e_w306295536-500 | G19: 10.700425 | H19: 106.71842
B20: p_w306440153 | C20: 11.041369 | D20: 106.68731 | F20: VNM-e_w306295540-220 | G20: 10.645185 | H20: 106.83978
B21: p_w306440155 | C21: 11.106401 | D21: 106.98091 | F21: VNM-e_w306440153-500 | G21: 11.041369 | H21: 106.68731
B22: p_w307638314 | C22: 10.699753 | D22: 106.66088 | F22: VNM-e_w306440155-220 | G22: 11.106401 | H22: 106.98091
... B1514: rez_wof_022 | C1514: 17.684982 | D1514: 107.85128 | F1514: VNM-e_VN875-220 | G1514: 12.045219 | H1514: 109.07068
F1515: VNM-e_VN894-220 | G1515: 11.94974 | H1515: 109.0508
F1516: VNM-e_VN923-500 | G1516: 11.785274 | H1516: 108.89644
F1517: VNM-e_VN1219-220 | G1517: 9.8867993 | H1517: 105.88333
F1518: VNM-e_VN888-220 | G1518: 11.987709 | H1518: 107.66911
F1519: VNM-e_VN1206-220 | G1519: 10.070634 | H1519: 104.03018
F1520: VNM-e_VN859-500 | G1520: 12.165247 | H1520: 107.88113
F1521: VNM-e_VN1225-220 | G1521: 9.6661201 | H1521: 106.42716
F1522: VNM-e_VN840-500 | G1522: 12.27842 | H1522: 108.12631
F1523: VNM-e_VN827-500 | G1523: 12.347213 | H1523: 109.10048
F1524: VNM-e_VN1170-500 | G1524: 10.389348 | H1524: 105.9159
F1525: VNM-e_VN1136-220 | G1525: 10.682754 | H1525: 106.55436
F1526: VNM-e_VN307-220 | G1526: 20.580722 | H1526: 104.94056
... F1606: VNM-elc_wof_022 | G1606: 17.684982 | H1606: 107.85128

Sheet process_map_geo
B9: ~process_map | F9: ~process_map | J9: ~commodity_map
B10: dimension | C10: description | D10: pset_set | F10: pset_set | G10: dimension | H10: description | J10: dimension | K10: name | L10: description
B11: grid_node | C11: p_w153608703 | D11: p_w153608703 | F11: p_w153608703 | G11: admin_1 | H11: Đồng Bằng Sông Hồng | J11: region_com | K11: e_w153608703-220 | L11: e_w153608703-220
B12: grid_node | C12: p_w183249722 | D12: p_w183249722 | F12: p_w183249722 | G12: admin_1 | H12: Đắk Lắk | J12: region_com | K12: e_w183249722-220 | L12: e_w183249722-220
B13: grid_node | C13: p_w241065371 | D13: p_w241065371 | F13: p_w241065371 | G13: admin_1 | H13: Unknown | J13: region_com | K13: e_w241065371-220 | L13: e_w241065371-220
B14: grid_node | C14: p_w251790836 | D14: p_w251790836 | F14: p_w251790836 | G14: admin_1 | H14: Ha Noi | J14: region_com | K14: e_w251790836-500 | L14: e_w251790836-500
B15: grid_node | C15: p_w1216970886 | D15: p_w1216970886 | F15: p_w1216970886 | G15: admin_1 | H15: Bà Rịa - Vũng Tàu | J15: region_com | K15: e_w251790836-220 | L15: e_w251790836-220
B16: grid_node | C16: p_w294127333 | D16: p_w294127333 | F16: p_w294127333 | G16: admin_1 | H16: Đông Nam Bộ | J16: region_com | K16: e_w1216970886-500 | L16: e_w1216970886-500
B17: grid_node | C17: p_w306259034 | D17: p_w306259034 | F17: p_w306259034 | G17: admin_1 | H17: Hồ Chí Minh city | J17: region_com | K17: e_w294127333-220 | L17: e_w294127333-220
B18: grid_node | C18: p_w306295536 | D18: p_w306295536 | F18: p_w306295536 | G18: admin_1 | H18: Hồ Chí Minh city | J18: region_com | K18: e_w306259034-220 | L18: e_w306259034-220
B19: grid_node | C19: p_w306295540 | D19: p_w306295540 | F19: p_w306295540 | G19: admin_1 | H19: Hồ Chí Minh city | J19: region_com | K19: e_w306295536-500 | L19: e_w306295536-500
B20: grid_node | C20: p_w306440153 | D20: p_w306440153 | F20: p_w306440153 | G20: admin_1 | H20: Bình Dương | J20: region_com | K20: e_w306295540-220 | L20: e_w306295540-220
B21: grid_node | C21: p_w306440155 | D21: p_w306440155 | F21: p_w306440155 | G21: admin_1 | H21: Đông Nam Bộ | J21: region_com | K21: e_w306440153-500 | L21: e_w306440153-500
... B1514: grid_node | C1514: rez_wof_022 | D1514: rez_wof_022 | F1514: rez_wof_022 | G1514: admin_1 | H1514: Unknown | J1514: region_com | K1514: e_VN875-220 | L1514: e_VN875-220
J1515: region_com | K1515: e_VN894-220 | L1515: e_VN894-220
J1516: region_com | K1516: e_VN923-500 | L1516: e_VN923-500
J1517: region_com | K1517: e_VN1219-220 | L1517: e_VN1219-220
J1518: region_com | K1518: e_VN888-220 | L1518: e_VN888-220
J1519: region_com | K1519: e_VN1206-220 | L1519: e_VN1206-220
J1520: region_com | K1520: e_VN859-500 | L1520: e_VN859-500
J1521: region_com | K1521: e_VN1225-220 | L1521: e_VN1225-220
J1522: region_com | K1522: e_VN840-500 | L1522: e_VN840-500
J1523: region_com | K1523: e_VN827-500 | L1523: e_VN827-500
J1524: region_com | K1524: e_VN1170-500 | L1524: e_VN1170-500
J1525: region_com | K1525: e_VN1136-220 | L1525: e_VN1136-220
J1526: region_com | K1526: e_VN307-220 | L1526: e_VN307-220
... J1606: region_com | K1606: elc_wof_022 | L1606: elc_wof_022

Sheet ScenMap
I1: C
I2: ar6_r10 | J2: timeslice
B4: ~ScenMap | H4: ~ScenG
B5: Oname | C5: Name | D5: Desc | E5: Ldesc | H5: Scen | I5: ="sg_"&I2 -> sg_ar6_r10 | J5: ="sg_"&J2 -> sg_timeslice | N5: priority | O5: scen | P5: case_no | Q5: timeslice | R5: climate
B6: ="vs~"&TEXT(P6,"0000") -> vs~0001 | C6: =H6 -> e 1.5 deg no OS.kAnn | H6: =_xlfn.TEXTJOIN(".",TRUE,I6:J6) -> e 1.5 deg no OS.kAnn | I6: =VLOOKUP(R6,$W$6:$X$12,2,FALSE) -> e 1.5 deg no OS | J6: =VLOOKUP(Q6,$T$6:$U$20,2,FALSE) -> kAnn | L6: Limit warming to 1.5°C (>50%) with no or limited overshoot | N6: 5 | O6: e 1.5 deg no OS.kAnn | P6: 1 | Q6: ts_annual | R6: C1 | T6: ts_annual | U6: kAnn | W6: C1 | X6: e 1.5 deg no OS
B7: ="vs~"&TEXT(P7,"0000") -> vs~0002 | C7: =H7 -> d 1.5 deg OS.kAnn | H7: =_xlfn.TEXTJOIN(".",TRUE,I7:J7) -> d 1.5 deg OS.kAnn | I7: =VLOOKUP(R7,$W$6:$X$12,2,FALSE) -> d 1.5 deg OS | J7: =VLOOKUP(Q7,$T$6:$U$20,2,FALSE) -> kAnn | L7: Limit warming to 1.5°C (>67%) with high overshoot | N7: 5 | O7: d 1.5 deg OS.kAnn | P7: 2 | Q7: ts_annual | R7: C2 | T7: ts_12t | U7: k12 | W7: C2 | X7: d 1.5 deg OS
B8: ="vs~"&TEXT(P8,"0000") -> vs~0003 | C8: =H8 -> c 2 deg (67%).kAnn | H8: =_xlfn.TEXTJOIN(".",TRUE,I8:J8) -> c 2 deg (67%).kAnn | I8: =VLOOKUP(R8,$W$6:$X$12,2,FALSE) -> c 2 deg (67%) | J8: =VLOOKUP(Q8,$T$6:$U$20,2,FALSE) -> kAnn | L8: Limit warming to 2°C (>67%) with higher action post-2030 | N8: 5 | O8: c 2 deg (67%).kAnn | P8: 3 | Q8: ts_annual | R8: C3 | T8: ts_012 | U8: j12 | W8: C3 | X8: c 2 deg (67%)
B9: ="vs~"&TEXT(P9,"0000") -> vs~0004 | C9: =H9 -> b 2 deg (50%).kAnn | H9: =_xlfn.TEXTJOIN(".",TRUE,I9:J9) -> b 2 deg (50%).kAnn | I9: =VLOOKUP(R9,$W$6:$X$12,2,FALSE) -> b 2 deg (50%) | J9: =VLOOKUP(Q9,$T$6:$U$20,2,FALSE) -> kAnn | L9: Limit warming to 2°C (>50%) with immediate action | N9: 5 | O9: b 2 deg (50%).kAnn | P9: 4 | Q9: ts_annual | R9: C4 | T9: ts_030 | U9: i30 | W9: C4 | X9: b 2 deg (50%)
B10: ="vs~"&TEXT(P10,"0000") -> vs~0005 | C10: =H10 -> a 3 deg.kAnn | H10: =_xlfn.TEXTJOIN(".",TRUE,I10:J10) -> a 3 deg.kAnn | I10: =VLOOKUP(R10,$W$6:$X$12,2,FALSE) -> a 3 deg | J10: =VLOOKUP(Q10,$T$6:$U$20,2,FALSE) -> kAnn | L10: Likely above 3°C warming with limited mitigation | N10: 5 | O10: a 3 deg.kAnn | P10: 5 | Q10: ts_annual | R10: C7 | T10: ts_048 | U10: h48 | W10: C7 | X10: a 3 deg
B11: ="vs~"&TEXT(P11,"0000") -> vs~0006 | C11: =H11 -> e 1.5 deg no OS.k12 | H11: =_xlfn.TEXTJOIN(".",TRUE,I11:J11) -> e 1.5 deg no OS.k12 | I11: =VLOOKUP(R11,$W$6:$X$12,2,FALSE) -> e 1.5 deg no OS | J11: =VLOOKUP(Q11,$T$6:$U$20,2,FALSE) -> k12 | N11: 5 | O11: e 1.5 deg no OS.k12 | P11: 6 | Q11: ts_12t | R11: C1 | T11: ts_048P10 | U11: h48P10
B12: ="vs~"&TEXT(P12,"0000") -> vs~0007 | C12: =H12 -> d 1.5 deg OS.k12 | H12: =_xlfn.TEXTJOIN(".",TRUE,I12:J12) -> d 1.5 deg OS.k12 | I12: =VLOOKUP(R12,$W$6:$X$12,2,FALSE) -> d 1.5 deg OS | J12: =VLOOKUP(Q12,$T$6:$U$20,2,FALSE) -> k12 | N12: 5 | O12: d 1.5 deg OS.k12 | P12: 7 | Q12: ts_12t | R12: C2 | T12: ts_048P90 | U12: h48P90
B13: ="vs~"&TEXT(P13,"0000") -> vs~0008 | C13: =H13 -> c 2 deg (67%).k12 | H13: =_xlfn.TEXTJOIN(".",TRUE,I13:J13) -> c 2 deg (67%).k12 | I13: =VLOOKUP(R13,$W$6:$X$12,2,FALSE) -> c 2 deg (67%) | J13: =VLOOKUP(Q13,$T$6:$U$20,2,FALSE) -> k12 | N13: 5 | O13: c 2 deg (67%).k12 | P13: 8 | Q13: ts_12t | R13: C3 | T13: s1_d | U13: g1d72
B14: ="vs~"&TEXT(P14,"0000") -> vs~0009 | C14: =H14 -> b 2 deg (50%).k12 | H14: =_xlfn.TEXTJOIN(".",TRUE,I14:J14) -> b 2 deg (50%).k12 | I14: =VLOOKUP(R14,$W$6:$X$12,2,FALSE) -> b 2 deg (50%) | J14: =VLOOKUP(Q14,$T$6:$U$20,2,FALSE) -> k12 | N14: 5 | O14: b 2 deg (50%).k12 | P14: 9 | Q14: ts_12t | R14: C4 | T14: s1v1_d | U14: f2d96
B15: ="vs~"&TEXT(P15,"0000") -> vs~0010 | C15: =H15 -> a 3 deg.k12 | H15: =_xlfn.TEXTJOIN(".",TRUE,I15:J15) -> a 3 deg.k12 | I15: =VLOOKUP(R15,$W$6:$X$12,2,FALSE) -> a 3 deg | J15: =VLOOKUP(Q15,$T$6:$U$20,2,FALSE) -> k12 | N15: 5 | O15: a 3 deg.k12 | P15: 10 | Q15: ts_12t | R15: C7 | T15: ts_096 | U15: e96
B16: ="vs~"&TEXT(P16,"0000") -> vs~0011 | C16: =H16 -> e 1.5 deg no OS.j12 | H16: =_xlfn.TEXTJOIN(".",TRUE,I16:J16) -> e 1.5 deg no OS.j12 | I16: =VLOOKUP(R16,$W$6:$X$12,2,FALSE) -> e 1.5 deg no OS | J16: =VLOOKUP(Q16,$T$6:$U$20,2,FALSE) -> j12 | N16: 5 | O16: e 1.5 deg no OS.j12 | P16: 11 | Q16: ts_012 | R16: C1 | T16: s1p1v1_d | U16: d9d
B17: ="vs~"&TEXT(P17,"0000") -> vs~0012 | C17: =H17 -> d 1.5 deg OS.j12 | H17: =_xlfn.TEXTJOIN(".",TRUE,I17:J17) -> d 1.5 deg OS.j12 | I17: =VLOOKUP(R17,$W$6:$X$12,2,FALSE) -> d 1.5 deg OS | J17: =VLOOKUP(Q17,$T$6:$U$20,2,FALSE) -> j12 | N17: 5 | O17: d 1.5 deg OS.j12 | P17: 12 | Q17: ts_012 | R17: C2 | T17: s5p5v5_d | U17: c15d
B18: ="vs~"&TEXT(P18,"0000") -> vs~0013 | C18: =H18 -> c 2 deg (67%).j12 | H18: =_xlfn.TEXTJOIN(".",TRUE,I18:J18) -> c 2 deg (67%).j12 | I18: =VLOOKUP(R18,$W$6:$X$12,2,FALSE) -> c 2 deg (67%) | J18: =VLOOKUP(Q18,$T$6:$U$20,2,FALSE) -> j12 | N18: 5 | O18: c 2 deg (67%).j12 | P18: 13 | Q18: ts_012 | R18: C3
B19: ="vs~"&TEXT(P19,"0000") -> vs~0014 | C19: =H19 -> b 2 deg (50%).j12 | H19: =_xlfn.TEXTJOIN(".",TRUE,I19:J19) -> b 2 deg (50%).j12 | I19: =VLOOKUP(R19,$W$6:$X$12,2,FALSE) -> b 2 deg (50%) | J19: =VLOOKUP(Q19,$T$6:$U$20,2,FALSE) -> j12 | N19: 5 | O19: b 2 deg (50%).j12 | P19: 14 | Q19: ts_012 | R19: C4
B20: ="vs~"&TEXT(P20,"0000") -> vs~0015 | C20: =H20 -> a 3 deg.j12 | H20: =_xlfn.TEXTJOIN(".",TRUE,I20:J20) -> a 3 deg.j12 | I20: =VLOOKUP(R20,$W$6:$X$12,2,FALSE) -> a 3 deg | J20: =VLOOKUP(Q20,$T$6:$U$20,2,FALSE) -> j12 | N20: 5 | O20: a 3 deg.j12 | P20: 15 | Q20: ts_012 | R20: C7
B21: ="vs~"&TEXT(P21,"0000") -> vs~0016 | C21: =H21 -> e 1.5 deg no OS.i30 | H21: =_xlfn.TEXTJOIN(".",TRUE,I21:J21) -> e 1.5 deg no OS.i30 | I21: =VLOOKUP(R21,$W$6:$X$12,2,FALSE) -> e 1.5 deg no OS | J21: =VLOOKUP(Q21,$T$6:$U$20,2,FALSE) -> i30 | N21: 5 | O21: e 1.5 deg no OS.i24 | P21: 16 | Q21: ts_030 | R21: C1
B22: ="vs~"&TEXT(P22,"0000") -> vs~0017 | C22: =H22 -> d 1.5 deg OS.i30 | H22: =_xlfn.TEXTJOIN(".",TRUE,I22:J22) -> d 1.5 deg OS.i30 | I22: =VLOOKUP(R22,$W$6:$X$12,2,FALSE) -> d 1.5 deg OS | J22: =VLOOKUP(Q22,$T$6:$U$20,2,FALSE) -> i30 | N22: 5 | O22: d 1.5 deg OS.i24 | P22: 17 | Q22: ts_030 | R22: C2
B23: ="vs~"&TEXT(P23,"0000") -> vs~0018 | C23: =H23 -> c 2 deg (67%).i30 | H23: =_xlfn.TEXTJOIN(".",TRUE,I23:J23) -> c 2 deg (67%).i30 | I23: =VLOOKUP(R23,$W$6:$X$12,2,FALSE) -> c 2 deg (67%) | J23: =VLOOKUP(Q23,$T$6:$U$20,2,FALSE) -> i30 | N23: 5 | O23: c 2 deg (67%).i24 | P23: 18 | Q23: ts_030 | R23: C3
B24: ="vs~"&TEXT(P24,"0000") -> vs~0019 | C24: =H24 -> b 2 deg (50%).i30 | H24: =_xlfn.TEXTJOIN(".",TRUE,I24:J24) -> b 2 deg (50%).i30 | I24: =VLOOKUP(R24,$W$6:$X$12,2,FALSE) -> b 2 deg (50%) | J24: =VLOOKUP(Q24,$T$6:$U$20,2,FALSE) -> i30 | N24: 5 | O24: b 2 deg (50%).i24 | P24: 19 | Q24: ts_030 | R24: C4
B25: ="vs~"&TEXT(P25,"0000") -> vs~0020 | C25: =H25 -> a 3 deg.i30 | H25: =_xlfn.TEXTJOIN(".",TRUE,I25:J25) -> a 3 deg.i30 | I25: =VLOOKUP(R25,$W$6:$X$12,2,FALSE) -> a 3 deg | J25: =VLOOKUP(Q25,$T$6:$U$20,2,FALSE) -> i30 | N25: 5 | O25: a 3 deg.i24 | P25: 20 | Q25: ts_030 | R25: C7
B26: ="vs~"&TEXT(P26,"0000") -> vs~0021 | C26: =H26 -> e 1.5 deg no OS.h48 | H26: =_xlfn.TEXTJOIN(".",TRUE,I26:J26) -> e 1.5 deg no OS.h48 | I26: =VLOOKUP(R26,$W$6:$X$12,2,FALSE) -> e 1.5 deg no OS | J26: =VLOOKUP(Q26,$T$6:$U$20,2,FALSE) -> h48 | N26: 5 | O26: e 1.5 deg no OS.h48 | P26: 21 | Q26: ts_048 | R26: C1
B27: ="vs~"&TEXT(P27,"0000") -> vs~0022 | C27: =H27 -> d 1.5 deg OS.h48 | H27: =_xlfn.TEXTJOIN(".",TRUE,I27:J27) -> d 1.5 deg OS.h48 | I27: =VLOOKUP(R27,$W$6:$X$12,2,FALSE) -> d 1.5 deg OS | J27: =VLOOKUP(Q27,$T$6:$U$20,2,FALSE) -> h48 | N27: 5 | O27: d 1.5 deg OS.h48 | P27: 22 | Q27: ts_048 | R27: C2
B28: ="vs~"&TEXT(P28,"0000") -> vs~0023 | C28: =H28 -> c 2 deg (67%).h48 | H28: =_xlfn.TEXTJOIN(".",TRUE,I28:J28) -> c 2 deg (67%).h48 | I28: =VLOOKUP(R28,$W$6:$X$12,2,FALSE) -> c 2 deg (67%) | J28: =VLOOKUP(Q28,$T$6:$U$20,2,FALSE) -> h48 | N28: 5 | O28: c 2 deg (67%).h48 | P28: 23 | Q28: ts_048 | R28: C3
B29: ="vs~"&TEXT(P29,"0000") -> vs~0024 | C29: =H29 -> b 2 deg (50%).h48 | H29: =_xlfn.TEXTJOIN(".",TRUE,I29:J29) -> b 2 deg (50%).h48 | I29: =VLOOKUP(R29,$W$6:$X$12,2,FALSE) -> b 2 deg (50%) | J29: =VLOOKUP(Q29,$T$6:$U$20,2,FALSE) -> h48 | N29: 5 | O29: b 2 deg (50%).h48 | P29: 24 | Q29: ts_048 | R29: C4
... B65: ="vs~"&TEXT(P65,"0000") -> vs~0060 | C65: =H65 -> a 3 deg.c15d | H65: =_xlfn.TEXTJOIN(".",TRUE,I65:J65) -> a 3 deg.c15d | I65: =VLOOKUP(R65,$W$6:$X$12,2,FALSE) -> a 3 deg | J65: =VLOOKUP(Q65,$T$6:$U$20,2,FALSE) -> c15d | N65: 5 | O65: a 3 deg.c15d | P65: 60 | Q65: s5p5v5_d | R65: C7

Sheet TS_Defs
A1: ~TS_Defs
A2: Attribute | B2: WAttribute | C2: PSET_Set | D2: PSET_PN | E2: PSET_PD | F2: PSET_CI | G2: PSET_CO | H2: CSET_Set | I2: CSET_CN | J2: CSET_CD | K2: Unit | L2: TS | M2: UC_N | N2: Name | O2: Desc | P2: Ldesc | Q2: show_me | R2: discard
A3: VAR_CAP | C3: ELE,STG,IRE | D3: -ElcAgg*,-*EV*,-g[_]* | K3: GW | N3: Elec Capacity
A4: VAR_NCAP | C4: ELE,STG,IRE | D4: -ElcAgg*,-*EV*,-g[_]* | K4: GW | N4: Elec New Capacity | T4: group_by
A5: VAR_FOUT | C5: ELE,IRE | D5: -ElcAgg*,-*EV*,-g[_]* | I5: ELC,ELC_???[_]???*,e[_]* | K5: TWh | N5: Elec Production | T5: p | U5: process
A6: VAR_POUT | C6: ELE,STG,IRE,-Grid | H6: NRG | I6: -elc_roadtransport | K6: TWh2GW | N6: Power | Q6: t
A7: VAR_FOUT | I7: CO2 | K7: kt | N7: CO2_emission
A8: VAR_FOUT | I8: CO2Captured | K8: ktneg | N8: CO2_captured
A9: Cost_Inv | C9: ELE,STG,IRE | D9: -ElcAgg*,-*EV* | K9: m$2020 | N9: Cost_Investment
A10: Cost_Dec | C10: ELE,STG,IRE | D10: -ElcAgg*,-*EV* | K10: m$2020 | N10: Cost_Investment
A11: Cost_Act | C11: ELE,STG,IRE | D11: -ElcAgg*,-*EV* | K11: m$2020 | N11: Cost_Variable
A12: Cost_Flo | C12: ELE,STG,IRE | D12: -ElcAgg*,-*EV* | K12: m$2020 | N12: Cost_Variable
A13: Cost_Fom | C13: ELE,STG,IRE | D13: -ElcAgg*,-*EV* | K13: m$2020 | N13: Cost_Fixed
A14: Val_Flo | C14: ELE | I14: coal,gas,oil,bioenergy | K14: m$2020 | N14: Cost_Fuel
A15: EQ_COMBALM | B15: VAR_COMPRD | H15: NRG | K15: $/MWh | N15: Price_NRG | P15: Prices of all NRG - native TS | Q15: ct
A16: EQ_COMBALM | B16: VAR_COMPRD | I16: co2net | K16: 000$/t | N16: Price_CO2
A17: User_conFXM | K17: m$/UCU | N17: UC_shadowprice | P17: shadow prices of all Ucs | Q17: u
A18: VAR_NCAPR | B18: VAR_NCAP | K18: $/MWh | N18: LCOE | Q18: p
A19: Reg_wobj | K19: m$2020 | N19: SysCost_NPV | Q19: u
A20: Reg_ACost | K20: m$2020 | N20: SysCost_Annual | Q20: u
A21: VAR_CAP | C21: IRE | D21: g[_]* | K21: GW | N21: Grid Capacity
A22: VAR_NCAP | C22: IRE | D22: g[_]* | K22: GW | N22: Grid New Capacity
A23: VAR_FIN | D23: e_dem*,ev_bat*,H2Prd* | I23: e* | K23: TWh | N23: Demand
A24: VAR_FIN | I24: ELC_???[_]???*,e[_]* | K24: TWh | N24: ~tradeflow_exp | P24: internal variable to enable grid flows visualization | Q24: p,c
A25: VAR_FOUT | I25: ELC_???[_]???*,e[_]* | K25: TWh | N25: ~tradeflow_imp | P25: internal variable to enable grid flows visualization | Q25: p,c
A26: VAR_CAP | F26: e[_]* | G26: e[_]* | K26: GW | N26: ~tradeflow_cap | P26: internal variable to enable grid capacity visualization | Q26: p
A27: VAR_NCAP | F27: e[_]* | G27: e[_]* | K27: GW | N27: ~tradeflow_ncap | P27: internal variable to enable grid new capacity visualization | Q27: p

Sheet TS_ratios
C1: ~TS_Ratios
C2: var_num | D2: var_den | E2: Name | F2: Unit | G2: show_me | H2: ignore | I2: include_null | J2: include_dim | K2: Ldesc
C3: Elec Production | D3: Elec Capacity | E3: Capacity_factor | F3: Twh/GW | G3: p | I3: y | J3: p

Sheet Sankey
A3: DeACT TS_Defs: Snk_attr=SANKEY Grid Flows
A4: Attribute | B4: PSET_Set | C4: PSET_PN | D4: PSET_PD | E4: PSET_CI | F4: PSET_CO | G4: CSET_Set | H4: CSET_CN | I4: CSET_CD | J4: Unit | K4: TS | L4: UC_N | M4: Name | N4: Desc | O4: Ldesc | P4: show_me | Q4: ignore | R4: T_neg_andor | S4: downscale_option
A5: VAR_FOUT | B5: =_xlfn.TEXTJOIN(",",TRUE,PSet_MAP!$A$3:$A$49) -> CCGT,Int Comb,Gas_Oil Steam,OCGT (Peaker),Subcritical Coal,Supercritical Coal,IGCC,Bio Power,Solar Util,Wind onshore,Wind offshore,Geothermal P,Hydro Dam,Hydro RoR,Nuclear P,Nuclear SMR,Hydro pumped stg,Util Batt Stg,EV Batt,Demand,Transformers Dn,Transformers Up,Grid-220V,Grid-400V,Grid-380V,Grid-225V,Grid-330V,Grid-275V,Grid-420V,Grid-300V,Grid-500V,Grid-750V,Grid-450V,Grid-515V,Grid-525V,Grid-320V,Grid-150V,Grid-270V,Grid-350V,Grid-250V,Grid-200V,Grid-236V,Grid-600V,Aggregators,DUMMY_IMP | G5: =_xlfn.TEXTJOIN(",",TRUE,CSET_MAP!$A$3:$A$43) -> Elec-220V,Elec-400V,Elec-380V,Elec-225V,Elec-330V,Elec-275V,Elec-420V,Elec-300V,Elec-500V,Elec-750V,Elec-450V,Elec-515V,Elec-525V,Elec-320V,Elec-150V,Elec-270V,Elec-350V,Elec-250V,Elec-200V,Elec-236V,Elec-600V,Solar elec,Wind elec,hydrogen,ELC,buildings,industry,transport,EVs,fossil,renewable,bioenergy,nuclear | J5: TWh | M5: <cset>_Src_<pset> | S5: -1
A6: VAR_FIN | B6: =_xlfn.TEXTJOIN(",",TRUE,PSet_MAP!$A$3:$A$49) -> CCGT,Int Comb,Gas_Oil Steam,OCGT (Peaker),Subcritical Coal,Supercritical Coal,IGCC,Bio Power,Solar Util,Wind onshore,Wind offshore,Geothermal P,Hydro Dam,Hydro RoR,Nuclear P,Nuclear SMR,Hydro pumped stg,Util Batt Stg,EV Batt,Demand,Transformers Dn,Transformers Up,Grid-220V,Grid-400V,Grid-380V,Grid-225V,Grid-330V,Grid-275V,Grid-420V,Grid-300V,Grid-500V,Grid-750V,Grid-450V,Grid-515V,Grid-525V,Grid-320V,Grid-150V,Grid-270V,Grid-350V,Grid-250V,Grid-200V,Grid-236V,Grid-600V,Aggregators,DUMMY_IMP | G6: =_xlfn.TEXTJOIN(",",TRUE,CSET_MAP!$A$3:$A$43) -> Elec-220V,Elec-400V,Elec-380V,Elec-225V,Elec-330V,Elec-275V,Elec-420V,Elec-300V,Elec-500V,Elec-750V,Elec-450V,Elec-515V,Elec-525V,Elec-320V,Elec-150V,Elec-270V,Elec-350V,Elec-250V,Elec-200V,Elec-236V,Elec-600V,Solar elec,Wind elec,hydrogen,ELC,buildings,industry,transport,EVs,fossil,renewable,bioenergy,nuclear | J6: TWh | M6: <cset>_Snk_<pset> | S6: -1
A10: ~TS_Defs: Snk_attr=SANKEY whole system
A11: Attribute | B11: PSET_Set | C11: PSET_PN | D11: PSET_PD | E11: PSET_CI | F11: PSET_CO | G11: CSET_Set | H11: CSET_CN | I11: CSET_CD | J11: Unit | K11: TS | L11: UC_N | M11: Name | N11: Desc | O11: Ldesc | P11: show_me | Q11: ignore | R11: T_neg_andor | S11: downscale_option
A12: * | B12: Fuels
A13: VAR_FOUT | F13: =H13 -> bioenergy,coal,gas,geothermal,hydro,hydrogen,nuclear,oil,solar,windon,windoff | H13: =_xlfn.TEXTJOIN(",",TRUE,CName_MAP!$A$3:$A$16) -> bioenergy,coal,gas,geothermal,hydro,hydrogen,nuclear,oil,solar,windon,windoff | J13: TWh | M13: <gen_cname>_src_<gen_pname> | S13: -1
A14: VAR_FIN | B14: =B5 -> CCGT,Int Comb,Gas_Oil Steam,OCGT (Peaker),Subcritical Coal,Supercritical Coal,IGCC,Bio Power,Solar Util,Wind onshore,Wind offshore,Geothermal P,Hydro Dam,Hydro RoR,Nuclear P,Nuclear SMR,Hydro pumped stg,Util Batt Stg,EV Batt,Demand,Transformers Dn,Transformers Up,Grid-220V,Grid-400V,Grid-380V,Grid-225V,Grid-330V,Grid-275V,Grid-420V,Grid-300V,Grid-500V,Grid-750V,Grid-450V,Grid-515V,Grid-525V,Grid-320V,Grid-150V,Grid-270V,Grid-350V,Grid-250V,Grid-200V,Grid-236V,Grid-600V,Aggregators,DUMMY_IMP | H14: =_xlfn.TEXTJOIN(",",TRUE,CName_MAP!$A$3:$A$16) -> bioenergy,coal,gas,geothermal,hydro,hydrogen,nuclear,oil,solar,windon,windoff | J14: TWh | M14: <gen_cname>_snk_<pset> | S14: -1
A15: * | B15: Electricity
A16: VAR_FOUT | B16: =_xlfn.TEXTJOIN(",",TRUE,PSet_MAP!$A$3:$A$49) -> CCGT,Int Comb,Gas_Oil Steam,OCGT (Peaker),Subcritical Coal,Supercritical Coal,IGCC,Bio Power,Solar Util,Wind onshore,Wind offshore,Geothermal P,Hydro Dam,Hydro RoR,Nuclear P,Nuclear SMR,Hydro pumped stg,Util Batt Stg,EV Batt,Demand,Transformers Dn,Transformers Up,Grid-220V,Grid-400V,Grid-380V,Grid-225V,Grid-330V,Grid-275V,Grid-420V,Grid-300V,Grid-500V,Grid-750V,Grid-450V,Grid-515V,Grid-525V,Grid-320V,Grid-150V,Grid-270V,Grid-350V,Grid-250V,Grid-200V,Grid-236V,Grid-600V,Aggregators,DUMMY_IMP | G16: =_xlfn.TEXTJOIN(",",TRUE,CSET_MAP!$A$3:$A$31) -> Elec-220V,Elec-400V,Elec-380V,Elec-225V,Elec-330V,Elec-275V,Elec-420V,Elec-300V,Elec-500V,Elec-750V,Elec-450V,Elec-515V,Elec-525V,Elec-320V,Elec-150V,Elec-270V,Elec-350V,Elec-250V,Elec-200V,Elec-236V,Elec-600V,Solar elec,Wind elec,hydrogen,ELC,buildings,industry,transport,EVs | J16: TWh | M16: <cset>_src_<pset> | S16: -1
A17: VAR_FIN | B17: =_xlfn.TEXTJOIN(",",TRUE,PSet_MAP!$A$3:$A$49) -> CCGT,Int Comb,Gas_Oil Steam,OCGT (Peaker),Subcritical Coal,Supercritical Coal,IGCC,Bio Power,Solar Util,Wind onshore,Wind offshore,Geothermal P,Hydro Dam,Hydro RoR,Nuclear P,Nuclear SMR,Hydro pumped stg,Util Batt Stg,EV Batt,Demand,Transformers Dn,Transformers Up,Grid-220V,Grid-400V,Grid-380V,Grid-225V,Grid-330V,Grid-275V,Grid-420V,Grid-300V,Grid-500V,Grid-750V,Grid-450V,Grid-515V,Grid-525V,Grid-320V,Grid-150V,Grid-270V,Grid-350V,Grid-250V,Grid-200V,Grid-236V,Grid-600V,Aggregators,DUMMY_IMP | G17: =_xlfn.TEXTJOIN(",",TRUE,CSET_MAP!$A$3:$A$31) -> Elec-220V,Elec-400V,Elec-380V,Elec-225V,Elec-330V,Elec-275V,Elec-420V,Elec-300V,Elec-500V,Elec-750V,Elec-450V,Elec-515V,Elec-525V,Elec-320V,Elec-150V,Elec-270V,Elec-350V,Elec-250V,Elec-200V,Elec-236V,Elec-600V,Solar elec,Wind elec,hydrogen,ELC,buildings,industry,transport,EVs | J17: TWh | M17: <cset>_snk_<pset> | S17: -1
A18: * | B18: Hydrogen
A19: VAR_FOUT | F19: =H19 -> hydrogen | H19: hydrogen | J19: TWh | M19: <gen_cname>_src_<gen_pname> | S19: -1
A20: VAR_FIN | F20: hydrogen | G20: =_xlfn.TEXTJOIN(",",TRUE,CSET_MAP!$A$3:$A$43) -> Elec-220V,Elec-400V,Elec-380V,Elec-225V,Elec-330V,Elec-275V,Elec-420V,Elec-300V,Elec-500V,Elec-750V,Elec-450V,Elec-515V,Elec-525V,Elec-320V,Elec-150V,Elec-270V,Elec-350V,Elec-250V,Elec-200V,Elec-236V,Elec-600V,Solar elec,Wind elec,hydrogen,ELC,buildings,industry,transport,EVs,fossil,renewable,bioenergy,nuclear | J20: TWh | M20: <cset>_snk_<gen_pname> | S20: -1
A23: VAR_FIN | E23: hydrogen | H23: hydrogen | J23: TWh | M23: <gen_cname>_snk_<gen_pname> | S23: -1

Sheet PSet_MAP
A1: ~Pset_Map
A2: Pset | B2: Desc | C2: Ldesc
A3: CCGT | B3: =A3 -> CCGT
A4: Int Comb | B4: =A4 -> Int Comb
A5: Gas_Oil Steam | B5: =A5 -> Gas_Oil Steam
A6: OCGT (Peaker) | B6: =A6 -> OCGT (Peaker)
A7: Subcritical Coal | B7: =A7 -> Subcritical Coal
A8: Supercritical Coal | B8: =A8 -> Supercritical Coal
A9: IGCC | B9: =A9 -> IGCC
A10: Bio Power | B10: =A10 -> Bio Power
A11: Solar Util | B11: =A11 -> Solar Util
A12: Wind onshore | B12: Onshore Wind
A13: Wind offshore | B13: Offshore Wind
A14: Geothermal P | B14: =A14 -> Geothermal P
A15: Hydro Dam | B15: =A15 -> Hydro Dam
A16: Hydro RoR | B16: =A16 -> Hydro RoR
A17: Nuclear P | B17: =A17 -> Nuclear P
A18: Nuclear SMR | B18: =A18 -> Nuclear SMR
A19: Hydro pumped stg | B19: =A19 -> Hydro pumped stg
A20: Util Batt Stg | B20: =A20 -> Util Batt Stg
A21: EV Batt | B21: =A21 -> EV Batt
A22: Demand | B22: =A22 -> Demand
A23: Transformers Dn | B23: =A23 -> Transformers Dn
A24: Transformers Up | B24: =A24 -> Transformers Up
A25: Grid-220V | B25: =A25 -> Grid-220V
... A47: DUMMY_IMP | B47: =A47 -> DUMMY_IMP

Sheet CSET_MAP
A1: ~Cset_Map
A2: Cset | B2: Desc | C2: Ldesc
A3: Elec-220V | B3: =A3 -> Elec-220V
A4: Elec-400V | B4: =A4 -> Elec-400V
A5: Elec-380V | B5: =A5 -> Elec-380V
A6: Elec-225V | B6: =A6 -> Elec-225V
A7: Elec-330V | B7: =A7 -> Elec-330V
A8: Elec-275V | B8: =A8 -> Elec-275V
A9: Elec-420V | B9: =A9 -> Elec-420V
A10: Elec-300V | B10: =A10 -> Elec-300V
A11: Elec-500V | B11: =A11 -> Elec-500V
A12: Elec-750V | B12: =A12 -> Elec-750V
A13: Elec-450V | B13: =A13 -> Elec-450V
A14: Elec-515V | B14: =A14 -> Elec-515V
... A23: Elec-600V | B23: =A23 -> Elec-600V
A24: Solar elec | B24: Electricity
A25: Wind elec | B25: Electricity
A26: hydrogen | B26: =A26 -> hydrogen
A27: ELC | B27: Electricity
A28: buildings | B28: =A28 -> buildings
A29: industry | B29: =A29 -> industry
A30: transport | B30: =A30 -> transport
A31: EVs | B31: =A31 -> EVs
A32: fossil | B32: =A32 -> fossil
A33: renewable | B33: =A33 -> renewable
A34: bioenergy | B34: =A34 -> bioenergy
A35: nuclear | B35: =A35 -> nuclear

Sheet CName_MAP
A1: ~CName_Map
A2: CName | B2: Desc | C2: Ldesc
A3: bioenergy | B3: =A3 -> bioenergy
A4: coal | B4: =A4 -> coal
A5: gas | B5: =A5 -> gas
A6: geothermal | B6: =A6 -> geothermal
A7: hydro | B7: =A7 -> hydro
A8: hydrogen | B8: =A8 -> hydrogen
A9: nuclear | B9: =A9 -> nuclear
A10: oil | B10: =A10 -> oil
A11: solar | B11: =A11 -> solar
A12: windon | B12: wind onshore
A13: windoff | B13: wind offshore

Sheet timeslice map
A1: ~Timeslice_Map
A2: dimension | B2: name | C2: description
A3: ts_season | B3: S01* | C3: S01
A4: ts_season | B4: S02* | C4: S02
A5: ts_season | B5: S03* | C5: S03
A6: ts_season | B6: S04* | C6: S04
A7: ts_season | B7: S05* | C7: S05
A8: ts_season | B8: S06* | C8: S06
A9: ts_season | B9: S07* | C9: S07
A10: ts_season | B10: S08* | C10: S08
A11: ts_season | B11: S09* | C11: S09
A12: ts_season | B12: S10* | C12: S10
A13: ts_season | B13: S11* | C13: S11
... A30: ts_type | B30: S??p* | C30: type - p

Sheet process map
A1: ~process_map
A2: dimension | B2: name | C2: description | D2: pset_set | E2: pset_ci | F2: pset_co | G2: pset_pd
A3: old_new | B3: * | C3: new
A4: old_new | B4: ep* | C4: old
A5: Tech | C5: =D5 -> CCGT | D5: CCGT
A6: Tech | C6: =D6 -> Int Comb | D6: Int Comb
A7: Tech | C7: =D7 -> Gas_Oil Steam | D7: Gas_Oil Steam
A8: Tech | C8: =D8 -> OCGT (Peaker) | D8: OCGT (Peaker)
A9: Tech | C9: =D9 -> Subcritical Coal | D9: Subcritical Coal
A10: Tech | C10: =D10 -> Supercritical Coal | D10: Supercritical Coal
A11: Tech | C11: =D11 -> IGCC | D11: IGCC
A12: Tech | C12: =D12 -> Bio Power | D12: Bio Power
A13: Tech | C13: =D13 -> Solar Util | D13: Solar Util
A14: Tech | C14: =D14 -> Wind onshore | D14: Wind onshore
A15: Tech | C15: =D15 -> Wind offshore | D15: Wind offshore
A16: Tech | C16: =D16 -> Geothermal P | D16: Geothermal P
... A49: Tech | C49: =D49 -> DUMMY_IMP | D49: DUMMY_IMP
A50: Tech | C50: Coal CCS | E50: coal | F50: co2captured
A51: Tech | C51: Gas CCS | E51: gas | F51: co2captured
A52: Tech | B52: *ccs-rf | C52: Coal CCS Retrofit | E52: coal
A53: Tech | B53: *ccs-rf | C53: Gas CCS Retrofit | E53: gas
A54: Tech | B54: ElcAgg_Solar | C54: Solar
A55: Tech | B55: ElcAgg_Wind | C55: Wind
A56: Tech | B56: Trd* | C56: Trade
A57: Sector | B57: e_dem* | C57: Industry and Buildings
A58: Sector | B58: ev_bat* | C58: EV Batt
A59: Sector | B59: H2Prd* | C59: Hydrogen
A60: Tech_origin | B60: * | C60: VerveStacks
A61: Tech_origin | B61: ep_* | C61: GEM_operating
A62: Tech_origin | B62: en_pc_* | C62: GEM_pre-constr
A63: Tech_origin | B63: ep_m_* | C63: GEM_mothballed
A64: Tech_origin | B64: en_a_* | C64: GEM_announced
A65: Tech_origin | B65: en_can_* | C65: GEM_cancelled
A66: Tech_origin | B66: en_she_* | C66: GEM_shelved
A67: Tech_by_fuel | C67: =E67 -> bioenergy | E67: bioenergy
A68: Tech_by_fuel | C68: =E68 -> coal | E68: coal
A69: Tech_by_fuel | C69: =E69 -> gas | E69: gas
A70: Tech_by_fuel | C70: =E70 -> hydro | E70: hydro
A71: Tech_by_fuel | C71: =E71 -> nuclear | E71: nuclear
A72: Tech_by_fuel | C72: =E72 -> oil | E72: oil
...

Sheet commodity map
A1: ~commodity_map
A2: dimension | B2: name | C2: description | D2: cset_set | E2: cset_cd | F2: c_set_andor | G2: c_pos_andor | H2: c_neg_andor

Sheet ATS
A1: ~ATS_final
A2: Tech_by_fuel | B2: Year | C2: Unit | D2: val | E2: scen | F2: varbl | G2: model | H2: region
A3: coal | B3: 2000 | C3: TWh | D3: 3.13 | E3: History | F3: Elec Production | G3: EMBER | H3: VNM
A4: gas | B4: 2000 | C4: TWh | D4: 4.36 | E4: History | F4: Elec Production | G4: EMBER | H4: VNM
A5: hydro | B5: 2000 | C5: TWh | D5: 14.55 | E5: History | F5: Elec Production | G5: EMBER | H5: VNM
A6: oil | B6: 2000 | C6: TWh | D6: 4.52 | E6: History | F6: Elec Production | G6: EMBER | H6: VNM
A7: coal | B7: 2001 | C7: TWh | D7: 3.22 | E7: History | F7: Elec Production | G7: EMBER | H7: VNM
A8: gas | B8: 2001 | C8: TWh | D8: 4.42 | E8: History | F8: Elec Production | G8: EMBER | H8: VNM
A9: hydro | B9: 2001 | C9: TWh | D9: 18.21 | E9: History | F9: Elec Production | G9: EMBER | H9: VNM
A10: oil | B10: 2001 | C10: TWh | D10: 4.76 | E10: History | F10: Elec Production | G10: EMBER | H10: VNM
A11: coal | B11: 2002 | C11: TWh | D11: 4.88 | E11: History | F11: Elec Production | G11: EMBER | H11: VNM
A12: gas | B12: 2002 | C12: TWh | D12: 8.33 | E12: History | F12: Elec Production | G12: EMBER | H12: VNM
A13: hydro | B13: 2002 | C13: TWh | D13: 18.2 | E13: History | F13: Elec Production | G13: EMBER | H13: VNM
A14: oil | B14: 2002 | C14: TWh | D14: 4.39 | E14: History | F14: Elec Production | G14: EMBER | H14: VNM
... A115: hydro | B115: 2000 | C115: GW | D115: 3.27 | E115: History | F115: Elec Capacity | G115: EMBER | H115: VNM
A116: oil | B116: 2000 | C116: GW | E116: History | F116: Elec Capacity | G116: EMBER | H116: VNM
A117: coal | B117: 2001 | C117: GW | D117: 0.55 | E117: History | F117: Elec Capacity | G117: EMBER | H117: VNM
A118: gas | B118: 2001 | C118: GW | D118: 1.88 | E118: History | F118: Elec Capacity | G118: EMBER | H118: VNM
A119: hydro | B119: 2001 | C119: GW | D119: 3.81 | E119: History | F119: Elec Capacity | G119: EMBER | H119: VNM
A120: oil | B120: 2001 | C120: GW | E120: History | F120: Elec Capacity | G120: EMBER | H120: VNM
A121: coal | B121: 2002 | C121: GW | D121: 1.14 | E121: History | F121: Elec Capacity | G121: EMBER | H121: VNM
A122: gas | B122: 2002 | C122: GW | D122: 1.88 | E122: History | F122: Elec Capacity | G122: EMBER | H122: VNM
A123: hydro | B123: 2002 | C123: GW | D123: 4.12 | E123: History | F123: Elec Capacity | G123: EMBER | H123: VNM
A124: oil | B124: 2002 | C124: GW | E124: History | F124: Elec Capacity | G124: EMBER | H124: VNM
A125: coal | B125: 2003 | C125: GW | D125: 1.14 | E125: History | F125: Elec Capacity | G125: EMBER | H125: VNM
A126: gas | B126: 2003 | C126: GW | D126: 2.36 | E126: History | F126: Elec Capacity | G126: EMBER | H126: VNM
A127: hydro | B127: 2003 | C127: GW | D127: 4.17 | E127: History | F127: Elec Capacity | G127: EMBER | H127: VNM
A128: oil | B128: 2003 | C128: GW | E128: History | F128: Elec Capacity | G128: EMBER | H128: VNM
A129: coal | B129: 2004 | C129: GW | D129: 1.39 | E129: History | F129: Elec Capacity | G129: EMBER | H129: VNM
A130: gas | B130: 2004 | C130: GW | D130: 3.57 | E130: History | F130: Elec Capacity | G130: EMBER | H130: VNM
A131: hydro | B131: 2004 | C131: GW | D131: 4.21 | E131: History | F131: Elec Capacity | G131: EMBER | H131: VNM
A132: oil | B132: 2004 | C132: GW | E132: History | F132: Elec Capacity | G132: EMBER | H132: VNM
A133: coal | B133: 2005 | C133: GW | D133: 1.39 | E133: History | F133: Elec Capacity | G133: EMBER | H133: VNM
A134: gas | B134: 2005 | C134: GW | D134: 4.3 | E134: History | F134: Elec Capacity | G134: EMBER | H134: VNM
A135: hydro | B135: 2005 | C135: GW | D135: 4.27 | E135: History | F135: Elec Capacity | G135: EMBER | H135: VNM
A136: oil | B136: 2005 | C136: GW | E136: History | F136: Elec Capacity | G136: EMBER | H136: VNM
A137: coal | B137: 2006 | C137: GW | D137: 1.51 | E137: History | F137: Elec Capacity | G137: EMBER | H137: VNM
A138: gas | B138: 2006 | C138: GW | D138: 4.3 | E138: History | F138: Elec Capacity | G138: EMBER | H138: VNM
A139: hydro | B139: 2006 | C139: GW | D139: 4.51 | E139: History | F139: Elec Capacity | G139: EMBER | H139: VNM
A140: oil | B140: 2006 | C140: GW | E140: History | F140: Elec Capacity | G140: EMBER | H140: VNM
...

Sheet UnitConv
A1: ~UnitConv
A2: Model | B2: Unit1 | C2: Unit2 | D2: MultFact
A3: VS | B3: Twh2GW | C3: GW | D3: =1/8.76 -> 0.11415525
A4: VS | B4: Twh/GW | C4: % | D4: =1/8.76*100 -> 11.415525
A5: VS | B5: kt | C5: mtCO2 | D5: 0.001
A6: VS | B6: ktneg | C6: mtCO2 | D6: -0.001
A7: VS | B7: 000$/t | C7: $/tCO2 | D7: -1000
