Workbook

Sheet Veda
G1: 1-70
D2: ="~Inputcell: "&_xlfn.TEXTJOIN(",",TRUE,G1:EE1) -> ~Inputcell: 1-70 | G2: 5 | H2: 6 | I2: 7 | J2: 9 | K2: 10 | L2: 11 | M2: 16 | N2: 17 | O2: 18 | P2: 20 | Q2: 21 | R2: 22 | S2: 27 | T2: 28 | U2: 29 | V2: 31 | W2: 32 | X2: 33 | Y2: 38 | Z2: 39 | AA2: 40 | AB2: 42 | AC2: 43 | AD2: 44 | AE2: 49 | AF2: 50 | AG2: 51 | AH2: 53 | AI2: 54 | AJ2: 55
D3: 3
D5: =VLOOKUP(D3,$C$9:$E$999,2,FALSE) -> ts_annual | E5: =VLOOKUP(D3,$C$9:$E$999,3,FALSE) -> C3
B7: ~Scenmap
A8: priority | B8: scen | C8: case_no | D8: timeslice | E8: climate
A9: 5 | B9: =VLOOKUP(E9,$AK$9:$AL$15,2,FALSE)&"."&VLOOKUP(D9,$AH$9:$AI$24,2,FALSE) -> e 1.5 deg no OS.kAnn | C9: 1 | D9: =VLOOKUP(AJ9,$AG$9:$AH$22,2,FALSE) -> ts_annual | E9: C1 | G9: Limit warming to 1.5°C (>50%) with no or limited overshoot | AG9: 1 | AH9: ts_annual | AI9: kAnn | AJ9: 1 | AK9: C1 | AL9: e 1.5 deg no OS
A10: 5 | B10: =VLOOKUP(E10,$AK$9:$AL$15,2,FALSE)&"."&VLOOKUP(D10,$AH$9:$AI$24,2,FALSE) -> d 1.5 deg OS.kAnn | C10: =C9+1 -> 2 | D10: =VLOOKUP(AJ10,$AG$9:$AH$22,2,FALSE) -> ts_annual | E10: C2 | G10: Limit warming to 1.5°C (>67%) with high overshoot | S10: IEA | AG10: 2 | AH10: ts_12t | AI10: k12 | AJ10: 1 | AK10: C2 | AL10: d 1.5 deg OS
A11: 5 | B11: =VLOOKUP(E11,$AK$9:$AL$15,2,FALSE)&"."&VLOOKUP(D11,$AH$9:$AI$24,2,FALSE) -> c 2 deg (67%).kAnn | C11: =C10+1 -> 3 | D11: =VLOOKUP(AJ11,$AG$9:$AH$22,2,FALSE) -> ts_annual | E11: C3 | G11: Limit warming to 2°C (>67%) with higher action post-2030 | S11: 2022 | AG11: 3 | AH11: ts_012 | AI11: j12 | AJ11: 1 | AK11: C3 | AL11: c 2 deg (67%)
A12: 5 | B12: =VLOOKUP(E12,$AK$9:$AL$15,2,FALSE)&"."&VLOOKUP(D12,$AH$9:$AI$24,2,FALSE) -> b 2 deg (50%).kAnn | C12: =C11+1 -> 4 | D12: =VLOOKUP(AJ12,$AG$9:$AH$22,2,FALSE) -> ts_annual | E12: C4 | G12: Limit warming to 2°C (>50%) with immediate action | S12: =SUMIFS(iea_data!I3:I9999,iea_data!$B$3:$B$9999,Veda!$S$11)+T28-T29 -> 1811.65 | T12: base-year generation (TWh) | AG12: 4 | AH12: ts_024 | AI12: i24 | AJ12: 1 | AK12: C4 | AL12: b 2 deg (50%)
A13: 5 | B13: =VLOOKUP(E13,$AK$9:$AL$15,2,FALSE)&"."&VLOOKUP(D13,$AH$9:$AI$24,2,FALSE) -> a 3 deg.kAnn | C13: =C12+1 -> 5 | D13: =VLOOKUP(AJ13,$AG$9:$AH$22,2,FALSE) -> ts_annual | E13: C7 | G13: Likely above 3°C warming with limited mitigation | AG13: 5 | AH13: ts_048 | AI13: h48 | AJ13: 1 | AK13: C7 | AL13: a 3 deg
A14: 5 | B14: =VLOOKUP(E14,$AK$9:$AL$15,2,FALSE)&"."&VLOOKUP(D14,$AH$9:$AI$24,2,FALSE) -> e 1.5 deg no OS.k12 | C14: =C13+1 -> 6 | D14: =VLOOKUP(AJ14,$AG$9:$AH$22,2,FALSE) -> ts_12t | E14: =E9 -> C1 | T14: =S12 -> 1811.65 | U14: =$S$12*J15 -> 2355.145 | V14: =$S$12*K15 -> 2934.873 | W14: =$S$12*L15 -> 3840.698 | X14: =$S$12*M15 -> 4782.756 | Y14: =$S$12*N15 -> 6213.9595 | Z14: =$S$12*O15 -> 7445.8815 | AG14: 6 | AH14: ts_064 | AI14: g64 | AJ14: =AJ9+1 -> 2
A15: 5 | B15: =VLOOKUP(E15,$AK$9:$AL$15,2,FALSE)&"."&VLOOKUP(D15,$AH$9:$AI$24,2,FALSE) -> d 1.5 deg OS.k12 | C15: =C14+1 -> 7 | D15: =VLOOKUP(AJ15,$AG$9:$AH$22,2,FALSE) -> ts_12t | E15: =E10 -> C2 | G15: Electricity growth relative to 2020 | I15: =SUMIFS(ar6_r10!$F$2:$F$999,ar6_r10!$A$2:$A$999,Veda!$E$5,ar6_r10!$C$2:$C$999,Veda!I$17,ar6_r10!$M$2:$M$999,Veda!$G15) -> 1 | J15: =SUMIFS(ar6_r10!$F$2:$F$999,ar6_r10!$A$2:$A$999,Veda!$E$5,ar6_r10!$C$2:$C$999,Veda!J$17,ar6_r10!$M$2:$M$999,Veda!$G15) -> 1.3 | K15: =SUMIFS(ar6_r10!$F$2:$F$999,ar6_r10!$A$2:$A$999,Veda!$E$5,ar6_r10!$C$2:$C$999,Veda!K$17,ar6_r10!$M$2:$M$999,Veda!$G15) -> 1.62 | L15: =SUMIFS(ar6_r10!$F$2:$F$999,ar6_r10!$A$2:$A$999,Veda!$E$5,ar6_r10!$C$2:$C$999,Veda!L$17,ar6_r10!$M$2:$M$999,Veda!$G15) -> 2.12 | M15: =SUMIFS(ar6_r10!$F$2:$F$999,ar6_r10!$A$2:$A$999,Veda!$E$5,ar6_r10!$C$2:$C$999,Veda!M$17,ar6_r10!$M$2:$M$999,Veda!$G15) -> 2.64 | N15: =SUMIFS(ar6_r10!$F$2:$F$999,ar6_r10!$A$2:$A$999,Veda!$E$5,ar6_r10!$C$2:$C$999,Veda!N$17,ar6_r10!$M$2:$M$999,Veda!$G15) -> 3.43 | O15: =SUMIFS(ar6_r10!$F$2:$F$999,ar6_r10!$A$2:$A$999,Veda!$E$5,ar6_r10!$C$2:$C$999,Veda!O$17,ar6_r10!$M$2:$M$999,Veda!$G15) -> 4.11 | AG15: 7 | AH15: ts_096P50 | AI15: f97p50 | AJ15: =AJ10+1 -> 2
A16: 5 | B16: =VLOOKUP(E16,$AK$9:$AL$15,2,FALSE)&"."&VLOOKUP(D16,$AH$9:$AI$24,2,FALSE) -> c 2 deg (67%).k12 | C16: =C15+1 -> 8 | D16: =VLOOKUP(AJ16,$AG$9:$AH$22,2,FALSE) -> ts_12t | E16: =E11 -> C3 | S16: ~TFM_INS-TS | AG16: 8 | AH16: ts_096P10 | AI16: f96p10 | AJ16: =AJ11+1 -> 2
A17: 5 | B17: =VLOOKUP(E17,$AK$9:$AL$15,2,FALSE)&"."&VLOOKUP(D17,$AH$9:$AI$24,2,FALSE) -> b 2 deg (50%).k12 | C17: =C16+1 -> 9 | D17: =VLOOKUP(AJ17,$AG$9:$AH$22,2,FALSE) -> ts_12t | E17: =E12 -> C4 | I17: 2020 | J17: =U17 -> 2025 | K17: =V17 -> 2030 | L17: =W17 -> 2035 | M17: =X17 -> 2040 | N17: =Y17 -> 2045 | O17: =Z17 -> 2050 | S17: commodity | T17: 2022 | U17: 2025 | V17: 2030 | W17: 2035 | X17: 2040 | Y17: 2045 | Z17: 2050 | AA17: attribute | AG17: 9 | AH17: ts_096P90 | AI17: f96p90 | AJ17: =AJ12+1 -> 2
A18: 5 | B18: =VLOOKUP(E18,$AK$9:$AL$15,2,FALSE)&"."&VLOOKUP(D18,$AH$9:$AI$24,2,FALSE) -> a 3 deg.k12 | C18: =C17+1 -> 10 | D18: =VLOOKUP(AJ18,$AG$9:$AH$22,2,FALSE) -> ts_12t | E18: =E13 -> C7 | G18: Hydrogen as a share of electricity | I18: =SUMIFS(ar6_r10!$F$2:$F$999,ar6_r10!$A$2:$A$999,Veda!$E$5,ar6_r10!$C$2:$C$999,Veda!I$17,ar6_r10!$M$2:$M$999,Veda!$G18) -> 0 | J18: =SUMIFS(ar6_r10!$F$2:$F$999,ar6_r10!$A$2:$A$999,Veda!$E$5,ar6_r10!$C$2:$C$999,Veda!J$17,ar6_r10!$M$2:$M$999,Veda!$G18) -> 0 | K18: =SUMIFS(ar6_r10!$F$2:$F$999,ar6_r10!$A$2:$A$999,Veda!$E$5,ar6_r10!$C$2:$C$999,Veda!K$17,ar6_r10!$M$2:$M$999,Veda!$G18) -> 0 | L18: =SUMIFS(ar6_r10!$F$2:$F$999,ar6_r10!$A$2:$A$999,Veda!$E$5,ar6_r10!$C$2:$C$999,Veda!L$17,ar6_r10!$M$2:$M$999,Veda!$G18) -> 0.01 | M18: =SUMIFS(ar6_r10!$F$2:$F$999,ar6_r10!$A$2:$A$999,Veda!$E$5,ar6_r10!$C$2:$C$999,Veda!M$17,ar6_r10!$M$2:$M$999,Veda!$G18) -> 0.02 | N18: =SUMIFS(ar6_r10!$F$2:$F$999,ar6_r10!$A$2:$A$999,Veda!$E$5,ar6_r10!$C$2:$C$999,Veda!N$17,ar6_r10!$M$2:$M$999,Veda!$G18) -> 0.02 | O18: =SUMIFS(ar6_r10!$F$2:$F$999,ar6_r10!$A$2:$A$999,Veda!$E$5,ar6_r10!$C$2:$C$999,Veda!O$17,ar6_r10!$M$2:$M$999,Veda!$G18) -> 0.03 | S18: hydrogen_allsect | T18: =I18*T$14 -> 0 | U18: =J18*U$14 -> 0 | V18: =K18*V$14 -> 0 | W18: =L18*W$14 -> 38.40698 | X18: =M18*X$14 -> 95.65512 | Y18: =N18*Y$14 -> 124.27919 | Z18: =O18*Z$14 -> 223.37645 | AA18: demand | AG18: 10 | AH18: s1p1v1_d | AI18: e3d | AJ18: =AJ13+1 -> 2
A19: 5 | B19: =VLOOKUP(E19,$AK$9:$AL$15,2,FALSE)&"."&VLOOKUP(D19,$AH$9:$AI$24,2,FALSE) -> e 1.5 deg no OS.j12 | C19: =C18+1 -> 11 | D19: =VLOOKUP(AJ19,$AG$9:$AH$22,2,FALSE) -> ts_012 | E19: =E14 -> C1 | G19: Industry electricity share | I19: =SUMIFS(ar6_r10!$F$2:$F$999,ar6_r10!$A$2:$A$999,Veda!$E$5,ar6_r10!$C$2:$C$999,Veda!I$17,ar6_r10!$M$2:$M$999,Veda!$G19) -> 0.49 | J19: =SUMIFS(ar6_r10!$F$2:$F$999,ar6_r10!$A$2:$A$999,Veda!$E$5,ar6_r10!$C$2:$C$999,Veda!J$17,ar6_r10!$M$2:$M$999,Veda!$G19) -> 0.49 | K19: =SUMIFS(ar6_r10!$F$2:$F$999,ar6_r10!$A$2:$A$999,Veda!$E$5,ar6_r10!$C$2:$C$999,Veda!K$17,ar6_r10!$M$2:$M$999,Veda!$G19) -> 0.46 | L19: =SUMIFS(ar6_r10!$F$2:$F$999,ar6_r10!$A$2:$A$999,Veda!$E$5,ar6_r10!$C$2:$C$999,Veda!L$17,ar6_r10!$M$2:$M$999,Veda!$G19) -> 0.48 | M19: =SUMIFS(ar6_r10!$F$2:$F$999,ar6_r10!$A$2:$A$999,Veda!$E$5,ar6_r10!$C$2:$C$999,Veda!M$17,ar6_r10!$M$2:$M$999,Veda!$G19) -> 0.46 | N19: =SUMIFS(ar6_r10!$F$2:$F$999,ar6_r10!$A$2:$A$999,Veda!$E$5,ar6_r10!$C$2:$C$999,Veda!N$17,ar6_r10!$M$2:$M$999,Veda!$G19) -> 0.48 | O19: =SUMIFS(ar6_r10!$F$2:$F$999,ar6_r10!$A$2:$A$999,Veda!$E$5,ar6_r10!$C$2:$C$999,Veda!O$17,ar6_r10!$M$2:$M$999,Veda!$G19) -> 0.47 | S19: elc_industry | T19: =I19*T$14 -> 887.7085 | U19: =J19*U$14 -> 1154.0211 | V19: =K19*V$14 -> 1350.0416 | W19: =L19*W$14 -> 1843.535 | X19: =M19*X$14 -> 2200.0678 | Y19: =N19*Y$14 -> 2982.7006 | Z19: =O19*Z$14 -> 3499.5643 | AA19: demand | AG19: 11 | AH19: s3p3v3_d | AI19: d9d | AJ19: =AJ14+1 -> 3
A20: 5 | B20: =VLOOKUP(E20,$AK$9:$AL$15,2,FALSE)&"."&VLOOKUP(D20,$AH$9:$AI$24,2,FALSE) -> d 1.5 deg OS.j12 | C20: =C19+1 -> 12 | D20: =VLOOKUP(AJ20,$AG$9:$AH$22,2,FALSE) -> ts_012 | E20: =E15 -> C2 | G20: Residential and commercial electricity share | I20: =SUMIFS(ar6_r10!$F$2:$F$999,ar6_r10!$A$2:$A$999,Veda!$E$5,ar6_r10!$C$2:$C$999,Veda!I$17,ar6_r10!$M$2:$M$999,Veda!$G20) -> 0.46 | J20: =SUMIFS(ar6_r10!$F$2:$F$999,ar6_r10!$A$2:$A$999,Veda!$E$5,ar6_r10!$C$2:$C$999,Veda!J$17,ar6_r10!$M$2:$M$999,Veda!$G20) -> 0.47 | K20: =SUMIFS(ar6_r10!$F$2:$F$999,ar6_r10!$A$2:$A$999,Veda!$E$5,ar6_r10!$C$2:$C$999,Veda!K$17,ar6_r10!$M$2:$M$999,Veda!$G20) -> 0.45 | L20: =SUMIFS(ar6_r10!$F$2:$F$999,ar6_r10!$A$2:$A$999,Veda!$E$5,ar6_r10!$C$2:$C$999,Veda!L$17,ar6_r10!$M$2:$M$999,Veda!$G20) -> 0.45 | M20: =SUMIFS(ar6_r10!$F$2:$F$999,ar6_r10!$A$2:$A$999,Veda!$E$5,ar6_r10!$C$2:$C$999,Veda!M$17,ar6_r10!$M$2:$M$999,Veda!$G20) -> 0.47 | N20: =SUMIFS(ar6_r10!$F$2:$F$999,ar6_r10!$A$2:$A$999,Veda!$E$5,ar6_r10!$C$2:$C$999,Veda!N$17,ar6_r10!$M$2:$M$999,Veda!$G20) -> 0.44 | O20: =SUMIFS(ar6_r10!$F$2:$F$999,ar6_r10!$A$2:$A$999,Veda!$E$5,ar6_r10!$C$2:$C$999,Veda!O$17,ar6_r10!$M$2:$M$999,Veda!$G20) -> 0.44 | S20: elc_buildings | T20: =I20*T$14 -> 833.359 | U20: =J20*U$14 -> 1106.9181 | V20: =K20*V$14 -> 1320.6929 | W20: =L20*W$14 -> 1728.3141 | X20: =M20*X$14 -> 2247.8953 | Y20: =N20*Y$14 -> 2734.1422 | Z20: =O20*Z$14 -> 3276.1879 | AA20: demand | AG20: 12 | AH20: s5p5v5_d | AI20: c15d | AJ20: =AJ15+1 -> 3
A21: 5 | B21: =VLOOKUP(E21,$AK$9:$AL$15,2,FALSE)&"."&VLOOKUP(D21,$AH$9:$AI$24,2,FALSE) -> c 2 deg (67%).j12 | C21: =C20+1 -> 13 | D21: =VLOOKUP(AJ21,$AG$9:$AH$22,2,FALSE) -> ts_012 | E21: =E16 -> C3 | G21: Transportation electricity share | I21: =SUMIFS(ar6_r10!$F$2:$F$999,ar6_r10!$A$2:$A$999,Veda!$E$5,ar6_r10!$C$2:$C$999,Veda!I$17,ar6_r10!$M$2:$M$999,Veda!$G21) -> 0.02 | J21: =SUMIFS(ar6_r10!$F$2:$F$999,ar6_r10!$A$2:$A$999,Veda!$E$5,ar6_r10!$C$2:$C$999,Veda!J$17,ar6_r10!$M$2:$M$999,Veda!$G21) -> 0.02 | K21: =SUMIFS(ar6_r10!$F$2:$F$999,ar6_r10!$A$2:$A$999,Veda!$E$5,ar6_r10!$C$2:$C$999,Veda!K$17,ar6_r10!$M$2:$M$999,Veda!$G21) -> 0.03 | L21: =SUMIFS(ar6_r10!$F$2:$F$999,ar6_r10!$A$2:$A$999,Veda!$E$5,ar6_r10!$C$2:$C$999,Veda!L$17,ar6_r10!$M$2:$M$999,Veda!$G21) -> 0.04 | M21: =SUMIFS(ar6_r10!$F$2:$F$999,ar6_r10!$A$2:$A$999,Veda!$E$5,ar6_r10!$C$2:$C$999,Veda!M$17,ar6_r10!$M$2:$M$999,Veda!$G21) -> 0.05 | N21: =SUMIFS(ar6_r10!$F$2:$F$999,ar6_r10!$A$2:$A$999,Veda!$E$5,ar6_r10!$C$2:$C$999,Veda!N$17,ar6_r10!$M$2:$M$999,Veda!$G21) -> 0.06 | O21: =SUMIFS(ar6_r10!$F$2:$F$999,ar6_r10!$A$2:$A$999,Veda!$E$5,ar6_r10!$C$2:$C$999,Veda!O$17,ar6_r10!$M$2:$M$999,Veda!$G21) -> 0.06 | S21: elc_transport | T21: =I21*T$14 -> 36.233 | U21: =T21 -> 36.233 | V21: =U21 -> 36.233 | W21: =V21 -> 36.233 | X21: =W21 -> 36.233 | Y21: =X21 -> 36.233 | Z21: =Y21 -> 36.233 | AA21: demand | AC21: non-road transport demand assumed to be constant | AG21: 13 | AH21: s2_w | AI21: b2w | AJ21: =AJ16+1 -> 3
A22: 5 | B22: =VLOOKUP(E22,$AK$9:$AL$15,2,FALSE)&"."&VLOOKUP(D22,$AH$9:$AI$24,2,FALSE) -> b 2 deg (50%).j12 | C22: =C21+1 -> 14 | D22: =VLOOKUP(AJ22,$AG$9:$AH$22,2,FALSE) -> ts_012 | E22: =E17 -> C4 | S22: elc_roadtransport | T22: =T14-SUM(T19:T21) -> 54.3495 | U22: =U14-SUM(U19:U21) -> 57.9728 | V22: =V14-SUM(V19:V21) -> 227.90557 | W22: =W14-SUM(W19:W21) -> 232.61586 | X22: =X14-SUM(X19:X21) -> 298.55992 | Y22: =Y14-SUM(Y19:Y21) -> 460.88376 | Z22: =Z14-SUM(Z19:Z21) -> 633.89634 | AA22: demand | AG22: 14 | AH22: s2_w_p2_d | AI22: a2w2d | AJ22: =AJ17+1 -> 3
A23: 5 | B23: =VLOOKUP(E23,$AK$9:$AL$15,2,FALSE)&"."&VLOOKUP(D23,$AH$9:$AI$24,2,FALSE) -> a 3 deg.j12 | C23: =C22+1 -> 15 | D23: =VLOOKUP(AJ23,$AG$9:$AH$22,2,FALSE) -> ts_012 | E23: =E18 -> C7 | S23: * | AJ23: =AJ18+1 -> 3
A24: 5 | B24: =VLOOKUP(E24,$AK$9:$AL$15,2,FALSE)&"."&VLOOKUP(D24,$AH$9:$AI$24,2,FALSE) -> e 1.5 deg no OS.i24 | C24: =C23+1 -> 16 | D24: =VLOOKUP(AJ24,$AG$9:$AH$22,2,FALSE) -> ts_024 | E24: =E19 -> C1 | G24: CO2 price | I24: 0 | J24: 0 | K24: =SUMIFS(ar6_r10!$F$2:$F$999,ar6_r10!$A$2:$A$999,Veda!$E$5,ar6_r10!$C$2:$C$999,Veda!K$17,ar6_r10!$M$2:$M$999,Veda!$G24) -> 47.87 | L24: =SUMIFS(ar6_r10!$F$2:$F$999,ar6_r10!$A$2:$A$999,Veda!$E$5,ar6_r10!$C$2:$C$999,Veda!L$17,ar6_r10!$M$2:$M$999,Veda!$G24) -> 86.21 | M24: =SUMIFS(ar6_r10!$F$2:$F$999,ar6_r10!$A$2:$A$999,Veda!$E$5,ar6_r10!$C$2:$C$999,Veda!M$17,ar6_r10!$M$2:$M$999,Veda!$G24) -> 123.26 | N24: =SUMIFS(ar6_r10!$F$2:$F$999,ar6_r10!$A$2:$A$999,Veda!$E$5,ar6_r10!$C$2:$C$999,Veda!N$17,ar6_r10!$M$2:$M$999,Veda!$G24) -> 172.36 | O24: =SUMIFS(ar6_r10!$F$2:$F$999,ar6_r10!$A$2:$A$999,Veda!$E$5,ar6_r10!$C$2:$C$999,Veda!O$17,ar6_r10!$M$2:$M$999,Veda!$G24) -> 209.45 | S24: co2net | U24: 0 | V24: =K24/1000 -> 0.04787 | W24: =L24/1000 -> 0.08621 | X24: =M24/1000 -> 0.12326 | Y24: =N24/1000 -> 0.17236 | Z24: =O24/1000 -> 0.20945 | AA24: com_taxnet | AJ24: =AJ19+1 -> 4
A25: 5 | B25: =VLOOKUP(E25,$AK$9:$AL$15,2,FALSE)&"."&VLOOKUP(D25,$AH$9:$AI$24,2,FALSE) -> d 1.5 deg OS.i24 | C25: =C24+1 -> 17 | D25: =VLOOKUP(AJ25,$AG$9:$AH$22,2,FALSE) -> ts_024 | E25: =E20 -> C2 | AJ25: =AJ20+1 -> 4
A26: 5 | B26: =VLOOKUP(E26,$AK$9:$AL$15,2,FALSE)&"."&VLOOKUP(D26,$AH$9:$AI$24,2,FALSE) -> c 2 deg (67%).i24 | C26: =C25+1 -> 18 | D26: =VLOOKUP(AJ26,$AG$9:$AH$22,2,FALSE) -> ts_024 | E26: =E21 -> C3 | S26: ~TFM_INS-TS | AJ26: =AJ21+1 -> 4
A27: 5 | B27: =VLOOKUP(E27,$AK$9:$AL$15,2,FALSE)&"."&VLOOKUP(D27,$AH$9:$AI$24,2,FALSE) -> b 2 deg (50%).i24 | C27: =C26+1 -> 19 | D27: =VLOOKUP(AJ27,$AG$9:$AH$22,2,FALSE) -> ts_024 | E27: =E22 -> C4 | S27: process | T27: =T17 -> 2022 | U27: =U17 -> 2025 | V27: =V17 -> 2030 | W27: =W17 -> 2035 | X27: =X17 -> 2040 | Y27: =Y17 -> 2045 | Z27: =Z17 -> 2050 | AA27: attribute | AB27: limtype | AJ27: =AJ22+1 -> 4
A28: 5 | B28: =VLOOKUP(E28,$AK$9:$AL$15,2,FALSE)&"."&VLOOKUP(D28,$AH$9:$AI$24,2,FALSE) -> a 3 deg.i24 | C28: =C27+1 -> 20 | D28: =VLOOKUP(AJ28,$AG$9:$AH$22,2,FALSE) -> ts_024 | E28: =E23 -> C7 | Q28: =SUMIFS(iea_data!G3:G9999,iea_data!$B$3:$B$9999,Veda!$S$11) -> 7.84 | S28: Trd_electricity import | T28: =Q28 -> 7.84 | AA28: ACT_BND | AB28: FX | AJ28: =AJ23+1 -> 4
A29: 5 | B29: =VLOOKUP(E29,$AK$9:$AL$15,2,FALSE)&"."&VLOOKUP(D29,$AH$9:$AI$24,2,FALSE) -> e 1.5 deg no OS.h48 | C29: =C28+1 -> 21 | D29: =VLOOKUP(AJ29,$AG$9:$AH$22,2,FALSE) -> ts_048 | E29: =E24 -> C1 | Q29: =SUMIFS(iea_data!H3:H9999,iea_data!$B$3:$B$9999,Veda!$S$11) -> -10.25 | S29: Trd_electricity export | T29: =-1*Q29 -> 10.25 | AA29: ACT_BND | AB29: FX | AJ29: =AJ24+1 -> 5
A30: 5 | B30: =VLOOKUP(E30,$AK$9:$AL$15,2,FALSE)&"."&VLOOKUP(D30,$AH$9:$AI$24,2,FALSE) -> d 1.5 deg OS.h48 | C30: =C29+1 -> 22 | D30: =VLOOKUP(AJ30,$AG$9:$AH$22,2,FALSE) -> ts_048 | E30: =E25 -> C2 | AJ30: =AJ25+1 -> 5
A31: 5 | B31: =VLOOKUP(E31,$AK$9:$AL$15,2,FALSE)&"."&VLOOKUP(D31,$AH$9:$AI$24,2,FALSE) -> c 2 deg (67%).h48 | C31: =C30+1 -> 23 | D31: =VLOOKUP(AJ31,$AG$9:$AH$22,2,FALSE) -> ts_048 | E31: =E26 -> C3 | AJ31: =AJ26+1 -> 5
A32: 5 | B32: =VLOOKUP(E32,$AK$9:$AL$15,2,FALSE)&"."&VLOOKUP(D32,$AH$9:$AI$24,2,FALSE) -> b 2 deg (50%).h48 | C32: =C31+1 -> 24 | D32: =VLOOKUP(AJ32,$AG$9:$AH$22,2,FALSE) -> ts_048 | E32: =E27 -> C4 | AJ32: =AJ27+1 -> 5
A33: 5 | B33: =VLOOKUP(E33,$AK$9:$AL$15,2,FALSE)&"."&VLOOKUP(D33,$AH$9:$AI$24,2,FALSE) -> a 3 deg.h48 | C33: =C32+1 -> 25 | D33: =VLOOKUP(AJ33,$AG$9:$AH$22,2,FALSE) -> ts_048 | E33: =E28 -> C7 | AJ33: =AJ28+1 -> 5
A34: 5 | B34: =VLOOKUP(E34,$AK$9:$AL$15,2,FALSE)&"."&VLOOKUP(D34,$AH$9:$AI$24,2,FALSE) -> e 1.5 deg no OS.g64 | C34: =C33+1 -> 26 | D34: =VLOOKUP(AJ34,$AG$9:$AH$22,2,FALSE) -> ts_064 | E34: =E29 -> C1 | AJ34: =AJ29+1 -> 6
A35: 5 | B35: =VLOOKUP(E35,$AK$9:$AL$15,2,FALSE)&"."&VLOOKUP(D35,$AH$9:$AI$24,2,FALSE) -> d 1.5 deg OS.g64 | C35: =C34+1 -> 27 | D35: =VLOOKUP(AJ35,$AG$9:$AH$22,2,FALSE) -> ts_064 | E35: =E30 -> C2 | AJ35: =AJ30+1 -> 6
A36: 5 | B36: =VLOOKUP(E36,$AK$9:$AL$15,2,FALSE)&"."&VLOOKUP(D36,$AH$9:$AI$24,2,FALSE) -> c 2 deg (67%).g64 | C36: =C35+1 -> 28 | D36: =VLOOKUP(AJ36,$AG$9:$AH$22,2,FALSE) -> ts_064 | E36: =E31 -> C3 | G36: C7 | AJ36: =AJ31+1 -> 6
A37: 5 | B37: =VLOOKUP(E37,$AK$9:$AL$15,2,FALSE)&"."&VLOOKUP(D37,$AH$9:$AI$24,2,FALSE) -> b 2 deg (50%).g64 | C37: =C36+1 -> 29 | D37: =VLOOKUP(AJ37,$AG$9:$AH$22,2,FALSE) -> ts_064 | E37: =E32 -> C4 | G37: Gas Price | I37: =SUMIFS(ar6_r10!$F$2:$F$999,ar6_r10!$A$2:$A$999,Veda!$G$36,ar6_r10!$C$2:$C$999,Veda!I$17,ar6_r10!$M$2:$M$999,Veda!$G37) -> 1 | J37: =SUMIFS(ar6_r10!$F$2:$F$999,ar6_r10!$A$2:$A$999,Veda!$G$36,ar6_r10!$C$2:$C$999,Veda!J$17,ar6_r10!$M$2:$M$999,Veda!$G37) -> 1.11 | K37: =SUMIFS(ar6_r10!$F$2:$F$999,ar6_r10!$A$2:$A$999,Veda!$G$36,ar6_r10!$C$2:$C$999,Veda!K$17,ar6_r10!$M$2:$M$999,Veda!$G37) -> 1.21 | L37: =SUMIFS(ar6_r10!$F$2:$F$999,ar6_r10!$A$2:$A$999,Veda!$G$36,ar6_r10!$C$2:$C$999,Veda!L$17,ar6_r10!$M$2:$M$999,Veda!$G37) -> 1.16 | M37: =SUMIFS(ar6_r10!$F$2:$F$999,ar6_r10!$A$2:$A$999,Veda!$G$36,ar6_r10!$C$2:$C$999,Veda!M$17,ar6_r10!$M$2:$M$999,Veda!$G37) -> 1.36 | N37: =SUMIFS(ar6_r10!$F$2:$F$999,ar6_r10!$A$2:$A$999,Veda!$G$36,ar6_r10!$C$2:$C$999,Veda!N$17,ar6_r10!$M$2:$M$999,Veda!$G37) -> 1.4 | O37: =SUMIFS(ar6_r10!$F$2:$F$999,ar6_r10!$A$2:$A$999,Veda!$G$36,ar6_r10!$C$2:$C$999,Veda!O$17,ar6_r10!$M$2:$M$999,Veda!$G37) -> 1.44 | AJ37: =AJ32+1 -> 6
A38: 5 | B38: =VLOOKUP(E38,$AK$9:$AL$15,2,FALSE)&"."&VLOOKUP(D38,$AH$9:$AI$24,2,FALSE) -> a 3 deg.g64 | C38: =C37+1 -> 30 | D38: =VLOOKUP(AJ38,$AG$9:$AH$22,2,FALSE) -> ts_064 | E38: =E33 -> C7 | G38: Coal Price | I38: =SUMIFS(ar6_r10!$F$2:$F$999,ar6_r10!$A$2:$A$999,Veda!$G$36,ar6_r10!$C$2:$C$999,Veda!I$17,ar6_r10!$M$2:$M$999,Veda!$G38) -> 1 | J38: =SUMIFS(ar6_r10!$F$2:$F$999,ar6_r10!$A$2:$A$999,Veda!$G$36,ar6_r10!$C$2:$C$999,Veda!J$17,ar6_r10!$M$2:$M$999,Veda!$G38) -> 1.07 | K38: =SUMIFS(ar6_r10!$F$2:$F$999,ar6_r10!$A$2:$A$999,Veda!$G$36,ar6_r10!$C$2:$C$999,Veda!K$17,ar6_r10!$M$2:$M$999,Veda!$G38) -> 1.17 | L38: =SUMIFS(ar6_r10!$F$2:$F$999,ar6_r10!$A$2:$A$999,Veda!$G$36,ar6_r10!$C$2:$C$999,Veda!L$17,ar6_r10!$M$2:$M$999,Veda!$G38) -> 1.21 | M38: =SUMIFS(ar6_r10!$F$2:$F$999,ar6_r10!$A$2:$A$999,Veda!$G$36,ar6_r10!$C$2:$C$999,Veda!M$17,ar6_r10!$M$2:$M$999,Veda!$G38) -> 1.37 | N38: =SUMIFS(ar6_r10!$F$2:$F$999,ar6_r10!$A$2:$A$999,Veda!$G$36,ar6_r10!$C$2:$C$999,Veda!N$17,ar6_r10!$M$2:$M$999,Veda!$G38) -> 1.33 | O38: =SUMIFS(ar6_r10!$F$2:$F$999,ar6_r10!$A$2:$A$999,Veda!$G$36,ar6_r10!$C$2:$C$999,Veda!O$17,ar6_r10!$M$2:$M$999,Veda!$G38) -> 1.52 | AJ38: =AJ33+1 -> 6
A39: 5 | B39: =VLOOKUP(E39,$AK$9:$AL$15,2,FALSE)&"."&VLOOKUP(D39,$AH$9:$AI$24,2,FALSE) -> e 1.5 deg no OS.f97p50 | C39: =C38+1 -> 31 | D39: =VLOOKUP(AJ39,$AG$9:$AH$22,2,FALSE) -> ts_096P50 | E39: =E34 -> C1 | G39: Oil Price | I39: =SUMIFS(ar6_r10!$F$2:$F$999,ar6_r10!$A$2:$A$999,Veda!$G$36,ar6_r10!$C$2:$C$999,Veda!I$17,ar6_r10!$M$2:$M$999,Veda!$G39) -> 1 | J39: =SUMIFS(ar6_r10!$F$2:$F$999,ar6_r10!$A$2:$A$999,Veda!$G$36,ar6_r10!$C$2:$C$999,Veda!J$17,ar6_r10!$M$2:$M$999,Veda!$G39) -> 1.43 | K39: =SUMIFS(ar6_r10!$F$2:$F$999,ar6_r10!$A$2:$A$999,Veda!$G$36,ar6_r10!$C$2:$C$999,Veda!K$17,ar6_r10!$M$2:$M$999,Veda!$G39) -> 1.58 | L39: =SUMIFS(ar6_r10!$F$2:$F$999,ar6_r10!$A$2:$A$999,Veda!$G$36,ar6_r10!$C$2:$C$999,Veda!L$17,ar6_r10!$M$2:$M$999,Veda!$G39) -> 1.53 | M39: =SUMIFS(ar6_r10!$F$2:$F$999,ar6_r10!$A$2:$A$999,Veda!$G$36,ar6_r10!$C$2:$C$999,Veda!M$17,ar6_r10!$M$2:$M$999,Veda!$G39) -> 1.74 | N39: =SUMIFS(ar6_r10!$F$2:$F$999,ar6_r10!$A$2:$A$999,Veda!$G$36,ar6_r10!$C$2:$C$999,Veda!N$17,ar6_r10!$M$2:$M$999,Veda!$G39) -> 1.94 | O39: =SUMIFS(ar6_r10!$F$2:$F$999,ar6_r10!$A$2:$A$999,Veda!$G$36,ar6_r10!$C$2:$C$999,Veda!O$17,ar6_r10!$M$2:$M$999,Veda!$G39) -> 2.2 | AJ39: =AJ34+1 -> 7
A40: 5 | B40: =VLOOKUP(E40,$AK$9:$AL$15,2,FALSE)&"."&VLOOKUP(D40,$AH$9:$AI$24,2,FALSE) -> d 1.5 deg OS.f97p50 | C40: =C39+1 -> 32 | D40: =VLOOKUP(AJ40,$AG$9:$AH$22,2,FALSE) -> ts_096P50 | E40: =E35 -> C2 | G40: Biomass Price | I40: =SUMIFS(ar6_r10!$F$2:$F$999,ar6_r10!$A$2:$A$999,Veda!$G$36,ar6_r10!$C$2:$C$999,Veda!I$17,ar6_r10!$M$2:$M$999,Veda!$G40) -> 1 | J40: =SUMIFS(ar6_r10!$F$2:$F$999,ar6_r10!$A$2:$A$999,Veda!$G$36,ar6_r10!$C$2:$C$999,Veda!J$17,ar6_r10!$M$2:$M$999,Veda!$G40) -> 1.05 | K40: =SUMIFS(ar6_r10!$F$2:$F$999,ar6_r10!$A$2:$A$999,Veda!$G$36,ar6_r10!$C$2:$C$999,Veda!K$17,ar6_r10!$M$2:$M$999,Veda!$G40) -> 1.06 | L40: =SUMIFS(ar6_r10!$F$2:$F$999,ar6_r10!$A$2:$A$999,Veda!$G$36,ar6_r10!$C$2:$C$999,Veda!L$17,ar6_r10!$M$2:$M$999,Veda!$G40) -> 1.04 | M40: =SUMIFS(ar6_r10!$F$2:$F$999,ar6_r10!$A$2:$A$999,Veda!$G$36,ar6_r10!$C$2:$C$999,Veda!M$17,ar6_r10!$M$2:$M$999,Veda!$G40) -> 1 | N40: =SUMIFS(ar6_r10!$F$2:$F$999,ar6_r10!$A$2:$A$999,Veda!$G$36,ar6_r10!$C$2:$C$999,Veda!N$17,ar6_r10!$M$2:$M$999,Veda!$G40) -> 0.95 | O40: =SUMIFS(ar6_r10!$F$2:$F$999,ar6_r10!$A$2:$A$999,Veda!$G$36,ar6_r10!$C$2:$C$999,Veda!O$17,ar6_r10!$M$2:$M$999,Veda!$G40) -> 0.93 | AJ40: =AJ35+1 -> 7
A41: 5 | B41: =VLOOKUP(E41,$AK$9:$AL$15,2,FALSE)&"."&VLOOKUP(D41,$AH$9:$AI$24,2,FALSE) -> c 2 deg (67%).f97p50 | C41: =C40+1 -> 33 | D41: =VLOOKUP(AJ41,$AG$9:$AH$22,2,FALSE) -> ts_096P50 | E41: =E36 -> C3 | AJ41: =AJ36+1 -> 7
A42: 5 | B42: =VLOOKUP(E42,$AK$9:$AL$15,2,FALSE)&"."&VLOOKUP(D42,$AH$9:$AI$24,2,FALSE) -> b 2 deg (50%).f97p50 | C42: =C41+1 -> 34 | D42: =VLOOKUP(AJ42,$AG$9:$AH$22,2,FALSE) -> ts_096P50 | E42: =E37 -> C4 | AJ42: =AJ37+1 -> 7
...

Sheet fuel_prices
A9: Fuel Prices
A10: iso | B10: gas_low | C10: gas_high | D10: coal_low | E10: coal_high | F10: oil_low | G10: oil_high | H10: bioenergy_low | I10: bioenergy_high | J10: Notes
A11: IND | B11: 30.9 | C11: 41.1 | D11: 8.6 | E11: 11 | F11: 45 | G11: 55 | H11: 15 | I11: 22 | J11: Expensive LNG imports, cheap domestic coal

Sheet iea_data
A9: IEA Baseline Data
A10: iso | B10: year | C10: industry_twh | D10: buildings_agri_twh | E10: nonroad_transport_twh | F10: road_transport_twh | G10: imports_twh | H10: exports_twh | I10: total_production_twh
A11: IND | B11: 2000 | C11: 353.17 | D11: 183.05 | E11: 8.21 | F11: 0 | G11: 1.5 | H11: -0.2 | I11: 561.06
A12: IND | B12: 2001 | C12: 365.24 | D12: 185.84 | E12: 8.11 | F12: 0 | G12: 1.52 | H12: -0.23 | I12: 579.62
A13: IND | B13: 2002 | C13: 373.25 | D13: 197.43 | E13: 8.8 | F13: 0 | G13: 1.52 | H13: -0.17 | I13: 602.77
A14: IND | B14: 2003 | C14: 398.6 | D14: 209.74 | E14: 9.21 | F14: 0 | G14: 1.75 | H14: -0.06 | I14: 640.35
A15: IND | B15: 2004 | C15: 420.06 | D15: 219.17 | E15: 9.49 | F15: 0 | G15: 1.74 | H15: -0.04 | I15: 675.52
A16: IND | B16: 2005 | C16: 440.21 | D16: 233.64 | E16: 9.94 | F16: 0 | G16: 1.76 | H16: -0.21 | I16: 708.4
A17: IND | B17: 2006 | C17: 473.33 | D17: 260.14 | E17: 10.8 | F17: 0 | G17: 2.96 | H17: -0.22 | I17: 767.3
A18: IND | B18: 2007 | C18: 508.87 | D18: 274.29 | E18: 11.11 | F18: 0 | G18: 5.23 | H18: -0.29 | I18: 817.35
A19: IND | B19: 2008 | C19: 517.86 | D19: 293.74 | E19: 11.81 | F19: 0 | G19: 5.9 | H19: -0.06 | I19: 845.01
A20: IND | B20: 2009 | C20: 555.27 | D20: 322.23 | E20: 12.39 | F20: 0 | G20: 5.36 | H20: -0.06 | I20: 909.5
A21: IND | B21: 2010 | C21: 585.41 | D21: 349.52 | E21: 13.32 | F21: 0 | G21: 5.61 | H21: -0.06 | I21: 972.25
A22: IND | B22: 2011 | C22: 636.4 | D22: 378.48 | E22: 14.21 | F22: 0 | G22: 5.25 | H22: -0.13 | I22: 1059.16
... A33: IND | B33: 2022 | C33: 1016.7 | D33: 707.9 | E33: 25 | F33: 0 | G33: 7.84 | H33: -10.25 | I33: 1814.06

Sheet ar6_r10
A9: AR6 Scenario Drivers
A10: Category | B10: Region | C10: Year | D10: count | E10: mean | F10: median | G10: std | H10: min | I10: max | J10: q25 | K10: q75 | L10: category_description | M10: attribute
A11: C1 | B11: R10INDIA+ | C11: 2020 | D11: 60 | E11: 0.18 | F11: 0.28 | G11: 0.17 | H11: 0 | I11: 0.55 | J11: 0 | K11: 0.28 | L11: Limit warming to 1.5°C (>50%) with no or limited overshoot | M11: CO2 price
A12: C1 | B12: R10INDIA+ | C12: 2025 | D12: 60 | E12: 150.71 | F12: 133.67 | G12: 123.07 | H12: 25.7 | I12: 626.48 | J12: 63.83 | K12: 177.75 | L12: Limit warming to 1.5°C (>50%) with no or limited overshoot | M12: CO2 price
A13: C1 | B13: R10INDIA+ | C13: 2030 | D13: 60 | E13: 197.87 | F13: 176.95 | G13: 120.69 | H13: 43.04 | I13: 673.46 | J13: 103.13 | K13: 241.69 | L13: Limit warming to 1.5°C (>50%) with no or limited overshoot | M13: CO2 price
A14: C1 | B14: R10INDIA+ | C14: 2035 | D14: 60 | E14: 284.66 | F14: 242.69 | G14: 157.98 | H14: 72.05 | I14: 859.53 | J14: 152.72 | K14: 350.22 | L14: Limit warming to 1.5°C (>50%) with no or limited overshoot | M14: CO2 price
A15: C1 | B15: R10INDIA+ | C15: 2040 | D15: 60 | E15: 400.28 | F15: 325.37 | G15: 210.28 | H15: 130.36 | I15: 1097.01 | J15: 260.5 | K15: 499.12 | L15: Limit warming to 1.5°C (>50%) with no or limited overshoot | M15: CO2 price
A16: C1 | B16: R10INDIA+ | C16: 2045 | D16: 60 | E16: 522.47 | F16: 430.26 | G16: 244.97 | H16: 193.42 | I16: 1269.88 | J16: 352.78 | K16: 693.38 | L16: Limit warming to 1.5°C (>50%) with no or limited overshoot | M16: CO2 price
A17: C1 | B17: R10INDIA+ | C17: 2050 | D17: 60 | E17: 631.49 | F17: 592.32 | G17: 257.5 | H17: 209.76 | I17: 1170.26 | J17: 412.98 | K17: 815.96 | L17: Limit warming to 1.5°C (>50%) with no or limited overshoot | M17: CO2 price
A18: C2 | B18: R10INDIA+ | C18: 2020 | D18: 86 | E18: 0.16 | F18: 0 | G18: 0.22 | H18: 0 | I18: 0.55 | J18: 0 | K18: 0.28 | L18: Limit warming to 1.5°C (>67%) with high overshoot | M18: CO2 price
A19: C2 | B19: R10INDIA+ | C19: 2025 | D19: 75 | E19: 40.23 | F19: 23.04 | G19: 49.98 | H19: 0 | I19: 174.97 | J19: 1.11 | K19: 61.44 | L19: Limit warming to 1.5°C (>67%) with high overshoot | M19: CO2 price
A20: C2 | B20: R10INDIA+ | C20: 2030 | D20: 86 | E20: 50.96 | F20: 41.97 | G20: 56.05 | H20: 0 | I20: 221.93 | J20: 1.11 | K20: 78.09 | L20: Limit warming to 1.5°C (>67%) with high overshoot | M20: CO2 price
A21: C2 | B21: R10INDIA+ | C21: 2035 | D21: 75 | E21: 192.17 | F21: 129.57 | G21: 290.7 | H21: 38.3 | I21: 2037.12 | J21: 85.89 | K21: 200.38 | L21: Limit warming to 1.5°C (>67%) with high overshoot | M21: CO2 price
A22: C2 | B22: R10INDIA+ | C22: 2040 | D22: 86 | E22: 244.81 | F22: 165.64 | G22: 360.13 | H22: 0 | I22: 2600 | J22: 107.85 | K22: 256.54 | L22: Limit warming to 1.5°C (>67%) with high overshoot | M22: CO2 price
... A360: C7 | B360: R10INDIA+ | C360: 2050 | D360: 6 | E360: 0.94 | F360: 0.93 | G360: 0.04 | H360: 0.9 | I360: 1.01 | J360: 0.91 | K360: 0.96 | L360: Likely above 3°C warming with limited mitigation | M360: Biomass price

Sheet ev_charging_uc
A10: =IFERROR(Veda!D5,"ts_12t") -> ts_annual | C10: day_night | D10: s1p1v1_d | F10: day_night | G10: s3p3v3_d | I10: day_night | J10: s5p5v5_d | L10: day_night | M10: s2_w | O10: day_night | P10: s2_w_p2_d | R10: day_night | S10: ts_012 | U10: day_night | V10: ts_024 | X10: day_night | Y10: ts_048 | AA10: day_night | AB10: ts_064 | AD10: day_night | AE10: ts_096P50 | AG10: day_night | AH10: ts_096P10 | AJ10: day_night | AK10: ts_096P90 | AM10: day_night | AN10: ts_annual | AP10: day_night | AQ10: ts_12t
C11: D | D11: S01aH05,S03aH06,S06aH05,S09c0920h15,S09c0920h18,S10aH02,S10aH06,S11aH06,S12aH04,S12aH05,S02aH04,S02aH05,S08b0815h17,S10aH03,S10aH05,S03aH02,S07aH05,S04aH02,S09aH02,S09aH03,S11aH03,S11aH04,S04aH03,S07aH04,S08aH03,S08b0815h10,S09aH04,S09c0920h17,S11d1124h11,S12aH02,S08aH02,S08b0815h09,S08b0815h13,S08b0815h15,S09aH06,S09c0920h13,S03aH03,S08b0815h18,S09aH05,S09c0920h07,S09c0920h11,S11d1124h09,S11d1124h14,S04aH06,S05aH04,S06aH02,S06aH03,S08b0815h07,S08b0815h08,S08b0815h11,S09c0920h09,S10aH04,S12aH06,S01aH06,S02aH03,S07aH03,S08aH06,S11d1124h08,S01aH02,S04aH04,S11d1124h07,S02aH06,S03aH05,S05aH05,S06aH04,S08aH04,S09c0920h08,S09c0920h12,S11aH02,S04aH05,S11d1124h13,S11d1124h16,S11d1124h18,S01aH04,S07aH02,S07aH06,S08b0815h16,S09c0920h14,S11d1124h15,S02aH02,S06aH06,S08b0815h12,S11d1124h10,S11d1124h12,S03aH04,S08aH05,S08b0815h14,S09c0920h10,S11aH05,S11d1124h17,S12aH03,S01aH03,S05aH02,S05aH03,S05aH06,S09c0920h16 | F11: D | G11: S01aH04,S07aH02,S07aH06,S08b0812h17,S08c0814h09,S08c0814h14,S09f0920h09,S09f0920h12,S09g0921h07,S09g0921h09,S11h1124h07,S11h1124h09,S11h1124h17,S01aH03,S05aH02,S05aH03,S05aH06,S09e0919h17,S11h1124h12,S11h1124h18,S11i1125h10,S11i1125h14,S11j1126h08,S11j1126h17,S03aH02,S07aH05,S08b0812h09,S08b0812h11,S08b0812h13,S08c0814h15,S08d0815h08,S08d0815h10,S09e0919h11,S09e0919h15,S09g0921h12,S11i1125h09,S11j1126h18,S01aH05,S03aH06,S06aH05,S08c0814h07,S08c0814h10,S09e0919h08,S09g0921h18,S10aH02,S10aH06,S11aH06,S11h1124h15,S11i1125h07,S12aH04,S12aH05,S02aH06,S03aH05,S05aH05,S06aH04,S08aH04,S08c0814h17,S08d0815h07,S08d0815h13,S08d0815h15,S09e0919h07,S11aH02,S11h1124h11,S11h1124h16,S04aH03,S07aH04,S08aH03,S08b0812h07,S08c0814h18,S09aH04,S09f0920h13,S11j1126h14,S12aH02,S01aH06,S02aH03,S07aH03,S08aH06,S08c0814h11,S09e0919h10,S09e0919h16,S09f0920h15,S09g0921h08,S08aH02,S09aH06,S09f0920h08,S09g0921h16,S11h1124h08,S11h1124h14,S11i1125h18,S02aH04,S02aH05,S08c0814h08,S08c0814h13,S08d0815h14,S09g0921h10,S09g0921h14,S09g0921h17,S10aH03,S10aH05,S04aH06,S05aH04,S06aH02,S06aH03,S10aH04,S11i1125h08,S11j1126h13,S12aH06,S04aH05,S08d0815h11,S09e0919h09,S09e0919h13,S09f0920h07,S09f0920h14,S09f0920h18,S11i1125h13,S11j1126h12,S02aH02,S06aH06,S08b0812h12,S08b0812h15,S08d0815h17,S09e0919h12,S09e0919h18,S09f0920h10,S11i1125h17,S11j1126h15,S03aH04,S08aH05,S09g0921h11,S11aH05,S11i1125h11,S11j1126h07,S12aH03,S03aH03,S08b0812h14,S08c0814h16,S08d0815h12,S09aH05,S09e0919h14,S09f0920h17,S09g0921h13,S09g0921h15,S11i1125h12,S04aH02,S08b0812h10,S08b0812h16,S08c0814h12,S08d0815h09,S09aH02,S09aH03,S09f0920h11,S11aH03,S11aH04,S11i1125h16,S11j1126h10,S11j1126h16,S01aH02,S04aH04,S08b0812h08,S08b0812h18,S08d0815h16,S08d0815h18,S09f0920h16,S11h1124h10,S11h1124h13,S11i1125h15,S11j1126h09,S11j1126h11 | I11: D | J11: S01b0102h08,S01b0102h13,S01b0102h14,S01c0103h07,S01c0103h09,S01c0103h11,S02aH04,S02aH05,S08g0814h10,S08h0815h17,S08i0816h18,S09j0919h07,S09k0920h09,S09k0920h13,S09m0922h17,S10aH03,S10aH05,S11p1126h09,S01c0103h08,S08aH02,S08f0813h08,S08f0813h11,S08f0813h12,S08h0815h13,S08i0816h09,S09aH06,S09j0919h09,S09j0919h16,S09l0921h11,S09l0921h12,S09l0921h18,S09m0922h10,S09m0922h11,S11o1125h14,S01aH03,S01b0102h16,S05aH02,S05aH03,S05aH06,S05d0525h18,S08e0812h11,S08e0812h18,S08h0815h12,S08h0815h14,S08h0815h16,S09j0919h14,S11p1126h07,S11p1126h12,S01aH04,S01b0102h10,S01c0103h15,S05d0525h13,S07aH02,S07aH06,S08f0813h07,S08h0815h15,S08i0816h07,S09j0919h15,S09k0920h15,S09k0920h16,S09l0921h07,S09m0922h13,S11n1124h07,S11n1124h16,S11o1125h11,S11p1126h13,S01b0102h18,S01c0103h13,S01c0103h17,S04aH03,S05d0525h15,S07aH04,S08aH03,S08g0814h13,S08h0815h18,S09aH04,S09l0921h13,S09m0922h08,S09m0922h18,S11n1124h17,S11o1125h09,S11p1126h16,S12aH02,S01c0103h14,S04aH05,S05d0525h12,S05d0525h14,S08e0812h13,S08h0815h08,S08i0816h16,S09j0919h08,S09k0920h11,S09l0921h09,S11n1124h13,S01c0103h18,S02aH02,S05d0525h11,S06aH06,S08f0813h13,S09k0920h10,S09l0921h10,S11o1125h07,S11o1125h15,S11p1126h14,S01aH02,S04aH04,S05d0525h17,S08g0814h11,S08h0815h11,S08i0816h13,S09j0919h17,S09m0922h15,S11o1125h08,S01b0102h17,S01c0103h10,S04aH06,S05aH04,S06aH02,S06aH03,S08e0812h08,S08e0812h14,S08i0816h08,S08i0816h17,S10aH04,S11n1124h11,S11o1125h10,S11p1126h10,S12aH06,S01c0103h12,S03aH03,S08e0812h07,S08e0812h12,S08f0813h15,S08g0814h08,S09aH05,S09k0920h07,S09l0921h16,S09m0922h07,S09m0922h14,S11o1125h17,S11o1125h18,S11p1126h11,S11p1126h15,S11p1126h18,S01b0102h12,S03aH04,S08aH05,S08e0812h09,S08e0812h10,S08f0813h10,S08g0814h07,S08g0814h15,S08i0816h15,S09j0919h10,S09j0919h18,S09l0921h17,S11aH05,S11n1124h08,S11n1124h09,S11p1126h08,S12aH03,S03aH02,S07aH05,S08g0814h18,S08h0815h09,S09k0920h14,S09m0922h09,S11n1124h12,S02aH06,S03aH05,S05aH05,S05d0525h07,S05d0525h10,S05d0525h16,S06aH04,S08aH04,S08e0812h16,S08e0812h17,S08f0813h14,S08i0816h11,S09j0919h11,S09l0921h14,S11aH02,S11o1125h12,S11o1125h16,S04aH02,S08f0813h18,S08g0814h16,S08g0814h17,S08h0815h07,S08h0815h10,S08i0816h14,S09aH02,S09aH03,S09j0919h12,S09k0920h17,S09l0921h15,S11aH03,S11aH04,S11n1124h10,S11n1124h14,S11n1124h18,S01aH05,S01b0102h07,S01b0102h09,S01b0102h15,S03aH06,S05d0525h08,S05d0525h09,S06aH05,S08e0812h15,S08f0813h09,S08f0813h17,S09l0921h08,S09m0922h16,S10aH02,S10aH06,S11aH06,S11n1124h15,S11p1126h17,S12aH04,S12aH05,S01aH06,S01b0102h11,S01c0103h16,S02aH03,S07aH03,S08aH06,S08f0813h16,S08g0814h09,S08g0814h12,S08g0814h14,S08i0816h10,S08i0816h12,S09j0919h13,S09k0920h08,S09k0920h12,S09k0920h18,S09m0922h12,S11o1125h13 | L11: D | M11: S01b0129h12,S01b0131h17,S02b0201h18,S02b0202h13,S02b0202h18,S02b0203h10,S02b0203h11,S02b0203h18,S02b0204h10,S03aH04,S08aH05,S08c0809h08,S08c0809h10,S08c0811h07,S08c0811h15,S08c0811h16,S11aH05,S12aH03,S02b0201h13,S02b0202h10,S04aH02,S08c0811h08,S08c0812h18,S09aH02,S09aH03,S11aH03,S11aH04,S01aH02,S01b0129h08,S01b0129h10,S01b0131h11,S02b0203h07,S04aH04,S08c0806h11,S08c0808h07,S08c0808h08,S08c0808h11,S08c0811h11,S01b0129h15,S01b0130h07,S01b0130h08,S01b0130h11,S02b0202h11,S02b0204h15,S04aH05,S08c0806h07,S08c0806h18,S08c0812h08,S01b0129h13,S01b0131h13,S02aH06,S02b0202h15,S02b0204h16,S03aH05,S05aH05,S06aH04,S08aH04,S08c0806h08,S08c0806h14,S08c0806h16,S08c0806h17,S08c0808h14,S08c0810h08,S08c0810h15,S08c0811h10,S11aH02,S01b0129h07,S01b0129h17,S01b0130h15,S01b0130h18,S01b0131h16,S02aH02,S02b0202h09,S02b0203h14,S06aH06,S08c0807h08,S08c0807h10,S08c0807h14,S08c0808h18,S08c0809h14,S08c0810h14,S01aH03,S01b0129h14,S01b0130h13,S01b0131h18,S02b0201h15,S02b0202h14,S02b0203h15,S05aH02,S05aH03,S05aH06,S08c0809h11,S08c0809h13,S08c0809h16,S08c0810h09,S08c0810h18,S08c0812h14,S01aH06,S01b0129h11,S01b0131h09,S02aH03,S02b0201h16,S02b0203h08,S02b0203h16,S07aH03,S08aH06,S08c0808h17,S08c0809h09,S08c0810h16,S08c0812h10,S01b0131h07,S01b0131h15,S02b0203h13,S02b0204h14,S08aH02,S08c0807h09,S08c0807h16,S08c0809h18,S08c0810h10,S08c0810h11,S08c0811h12,S09aH06,S01b0131h12,S02aH04,S02aH05,S02b0201h09,S02b0201h12,S02b0203h17,S02b0204h11,S02b0204h12,S08c0806h13,S08c0806h15,S08c0807h18,S08c0808h13,S08c0809h15,S08c0810h07,S08c0811h18,S08c0812h09,S08c0812h13,S10aH03,S10aH05,S01b0130h10,S02b0204h08,S04aH03,S07aH04,S08aH03,S08c0807h07,S08c0807h13,S08c0808h09,S08c0808h10,S08c0808h16,S08c0810h13,S08c0810h17,S08c0811h09,S08c0811h14,S08c0812h07,S09aH04,S12aH02,S01b0130h09,S01b0130h12,S01b0131h08,S02b0201h14,S02b0202h08,S02b0203h09,S02b0204h09,S02b0204h13,S02b0204h17,S03aH03,S08c0811h13,S08c0812h11,S09aH05,S01b0129h16,S02b0201h08,S02b0201h11,S02b0201h17,S04aH06,S05aH04,S06aH02,S06aH03,S08c0809h17,S08c0810h12,S10aH04,S12aH06,S01aH04,S01b0129h09,S01b0129h18,S01b0130h16,S01b0130h17,S02b0201h07,S02b0202h07,S02b0202h12,S02b0203h12,S07aH02,S07aH06,S08c0806h09,S08c0807h12,S08c0809h12,S08c0812h16,S01b0131h10,S01b0131h14,S02b0201h10,S02b0202h16,S02b0204h07,S03aH02,S07aH05,S08c0806h12,S08c0807h11,S08c0807h17,S08c0808h12,S08c0811h17,S08c0812h17,S01aH05,S01b0130h14,S02b0202h17,S02b0204h18,S03aH06,S06aH05,S08c0806h10,S08c0807h15,S08c0808h15,S08c0809h07,S08c0812h12,S08c0812h15,S10aH02,S10aH06,S11aH06,S12aH04,S12aH05 | O11: D | P11: S01b0129h12,S01b0131h17,S02b0201h18,S02b0202h13,S02b0202h18,S02b0203h10,S02b0203h11,S02b0203h18,S02b0204h10,S03aH04,S08aH05,S08c0809h08,S08c0809h10,S08c0811h07,S08c0811h15,S08c0811h16,S09d0920h16,S09e0921h13,S11aH05,S12aH03,S02b0201h13,S02b0202h10,S04aH02,S08c0811h08,S08c0812h18,S09aH02,S09aH03,S09e0921h08,S11aH03,S11aH04,S01aH05,S01b0130h14,S02b0202h17,S02b0204h18,S03aH06,S06aH05,S08c0806h10,S08c0807h15,S08c0808h15,S08c0809h07,S08c0812h12,S08c0812h15,S09e0921h10,S09e0921h16,S10aH02,S10aH06,S11aH06,S12aH04,S12aH05,S01b0129h15,S01b0130h07,S01b0130h08,S01b0130h11,S02b0202h11,S02b0204h15,S04aH05,S08c0806h07,S08c0806h18,S08c0812h08,S01b0129h13,S01b0131h13,S02aH06,S02b0202h15,S02b0204h16,S03aH05,S05aH05,S06aH04,S08aH04,S08c0806h08,S08c0806h14,S08c0806h16,S08c0806h17,S08c0808h14,S08c0810h08,S08c0810h15,S08c0811h10,S09d0920h11,S11aH02,S01b0130h10,S02b0204h08,S04aH03,S07aH04,S08aH03,S08c0807h07,S08c0807h13,S08c0808h09,S08c0808h10,S08c0808h16,S08c0810h13,S08c0810h17,S08c0811h09,S08c0811h14,S08c0812h07,S09aH04,S09d0920h17,S12aH02,S01b0129h16,S02b0201h08,S02b0201h11,S02b0201h17,S04aH06,S05aH04,S06aH02,S06aH03,S08c0809h17,S08c0810h12,S09d0920h12,S09e0921h07,S09e0921h15,S10aH04,S12aH06,S01b0131h12,S02aH04,S02aH05,S02b0201h09,S02b0201h12,S02b0203h17,S02b0204h11,S02b0204h12,S08c0806h13,S08c0806h15,S08c0807h18,S08c0808h13,S08c0809h15,S08c0810h07,S08c0811h18,S08c0812h09,S08c0812h13,S09d0920h07,S09d0920h13,S10aH03,S10aH05,S01b0131h07,S01b0131h15,S02b0203h13,S02b0204h14,S08aH02,S08c0807h09,S08c0807h16,S08c0809h18,S08c0810h10,S08c0810h11,S08c0811h12,S09aH06,S09e0921h12,S09e0921h17,S01aH03,S01b0129h14,S01b0130h13,S01b0131h18,S02b0201h15,S02b0202h14,S02b0203h15,S05aH02,S05aH03,S05aH06,S08c0809h11,S08c0809h13,S08c0809h16,S08c0810h09,S08c0810h18,S08c0812h14,S09e0921h11,S01aH04,S01b0129h09,S01b0129h18,S01b0130h16,S01b0130h17,S02b0201h07,S02b0202h07,S02b0202h12,S02b0203h12,S07aH02,S07aH06,S08c0806h09,S08c0807h12,S08c0809h12,S08c0812h16,S09d0920h14,S09e0921h18,S01aH06,S01b0129h11,S01b0131h09,S02aH03,S02b0201h16,S02b0203h08,S02b0203h16,S07aH03,S08aH06,S08c0808h17,S08c0809h09,S08c0810h16,S08c0812h10,S09d0920h08,S09d0920h10,S09e0921h14,S01b0130h09,S01b0130h12,S01b0131h08,S02b0201h14,S02b0202h08,S02b0203h09,S02b0204h09,S02b0204h13,S02b0204h17,S03aH03,S08c0811h13,S08c0812h11,S09aH05,S01aH02,S01b0129h08,S01b0129h10,S01b0131h11,S02b0203h07,S04aH04,S08c0806h11,S08c0808h07,S08c0808h08,S08c0808h11,S08c0811h11,S09d0920h18,S01b0129h07,S01b0129h17,S01b0130h15,S01b0130h18,S01b0131h16,S02aH02,S02b0202h09,S02b0203h14,S06aH06,S08c0807h08,S08c0807h10,S08c0807h14,S08c0808h18,S08c0809h14,S08c0810h14,S09d0920h09,S09d0920h15,S09e0921h09,S01b0131h10,S01b0131h14,S02b0201h10,S02b0202h16,S02b0204h07,S03aH02,S07aH05,S08c0806h12,S08c0807h11,S08c0807h17,S08c0808h12,S08c0811h17,S08c0812h17 | R11: D | S11: S01aH02,S02aH02,S03aH02,S04aH02 | U11: D | V11: S02aH04,S02aH05,S04aH05,S02aH02,S03aH05,S01aH03,S03aH03,S03aH02,S01aH05,S01aH04,S04aH03,S02aH03,S01aH02,S04aH04,S03aH04,S04aH02 | X11: D | Y11: S01aH04,S07aH02,S03aH05,S05aH05,S06aH04,S01aH03,S05aH02,S05aH03,S01aH02,S04aH04,S02aH02,S02aH04,S02aH05,S04aH05,S03aH03,S05aH04,S06aH02,S06aH03,S03aH04,S03aH02,S07aH05,S04aH02,S01aH05,S06aH05,S02aH03,S07aH03,S04aH03,S07aH04 | AA11: D | AB11: S03aH04,S04aH02,S04aH03,S07aH04,S04aH06,S05aH04,S06aH02,S06aH03,S02aH06,S03aH05,S05aH05,S06aH04,S01aH04,S07aH02,S07aH06,S01aH03,S05aH02,S05aH03,S05aH06,S03aH02,S07aH05,S04aH05,S03aH03,S02aH04,S02aH05,S01aH02,S04aH04,S01aH05,S03aH06,S06aH05,S02aH02,S06aH06,S01aH06,S02aH03,S07aH03 | AD11: D | AE11: S01aH04,S07aH02,S07aH06,S02aH04,S02aH05,S10aH03,S10aH05,S03aH02,S07aH05,S01aH02,S04aH04,S02aH02,S06aH06,S04aH06,S05aH04,S06aH02,S06aH03,S10aH04,S12aH06,S03aH03,S09aH05,S04aH05,S03aH04,S08aH05,S11aH05,S12aH03,S04aH02,S09aH02,S09aH03,S11aH03,S11aH04,S08aH02,S09aH06,S01aH05,S03aH06,S06aH05,S10aH02,S10aH06,S11aH06,S12aH04,S12aH05,S04aH03,S07aH04,S08aH03,S09aH04,S12aH02,S01aH03,S05aH02,S05aH03,S05aH06,S02aH06,S03aH05,S05aH05,S06aH04,S08aH04,S11aH02,S01aH06,S02aH03,S07aH03,S08aH06 | AG11: D | AH11: S02aH06,S03aH05,S05aH05,S06aH04,S08aH04,S11aH02,S04aH02,S09aH02,S09aH03,S11aH03,S11aH04,S02aH02,S06aH06,S08aH02,S09aH06,S01aH03,S05aH02,S05aH03,S05aH06,S03aH04,S08aH05,S11aH05,S12aH03,S03aH03,S09aH05,S04aH05,S04aH03,S07aH04,S08aH03,S09aH04,S12aH02,S03aH02,S07aH05,S01aH04,S07aH02,S07aH06,S01aH06,S02aH03,S07aH03,S08aH06,S01aH05,S03aH06,S06aH05,S10aH02,S10aH06,S11aH06,S12aH04,S12aH05,S04aH06,S05aH04,S06aH02,S06aH03,S10aH04,S12aH06,S02aH04,S02aH05,S10aH03,S10aH05,S01aH02,S04aH04 | AJ11: D | AK11: S01aH04,S07aH02,S07aH06,S08aH02,S09aH06,S04aH03,S07aH04,S08aH03,S09aH04,S12aH02,S02aH02,S06aH06,S01aH02,S04aH04,S04aH02,S09aH02,S09aH03,S11aH03,S11aH04,S04aH06,S05aH04,S06aH02,S06aH03,S10aH04,S12aH06,S03aH03,S09aH05,S01aH06,S02aH03,S07aH03,S08aH06,S02aH06,S03aH05,S05aH05,S06aH04,S08aH04,S11aH02,S03aH02,S07aH05,S02aH04,S02aH05,S10aH03,S10aH05,S04aH05,S01aH03,S05aH02,S05aH03,S05aH06,S03aH04,S08aH05,S11aH05,S12aH03,S01aH05,S03aH06,S06aH05,S10aH02,S10aH06,S11aH06,S12aH04,S12aH05 | AM11: D | AN11: AllSaAllH | AP11: D | AQ11: SaD,WaD,FaP,SaP,WaP,FaD,RaD,RaP
C12: N | D12: S08b0815h02,S03aH08,S04aH07,S06aH08,S09c0920h02,S12aH01,S08aH07,S08b0815h20,S09c0920h04,S09c0920h19,S09c0920h22,S11d1124h06,S09c0920h20,S11d1124h24,S02aH01,S09c0920h03,S09c0920h05,S04aH08,S06aH01,S08b0815h03,S08b0815h04,S11d1124h05,S12aH08,S08b0815h21,S08b0815h23,S11aH08,S11d1124h02,S05aH07,S07aH01,S08b0815h19,S08b0815h22,S09c0920h01,S09c0920h24,S10aH07,S01aH01,S04aH01,S08b0815h01,S09aH08,S09c0920h06,S11aH01,S11d1124h01,S11d1124h20,S01aH08,S02aH08,S03aH07,S11d1124h21,S11d1124h22,S06aH07,S07aH07,S07aH08,S08aH08,S08b0815h06,S09c0920h21,S09c0920h23,S11d1124h23,S05aH08,S08b0815h05,S10aH08,S11d1124h03,S08aH01,S09aH07,S10aH01,S03aH01,S08b0815h24,S12aH07,S01aH07,S02aH07,S05aH01,S11d1124h19,S09aH01,S11aH07,S11d1124h04 | F12: N | G12: S08aH01,S08b0812h21,S08c0814h03,S09aH07,S09e0919h22,S09f0920h05,S10aH01,S11i1125h05,S11i1125h24,S08d0815h02,S08d0815h22,S08d0815h23,S09aH01,S09e0919h19,S09f0920h02,S09g0921h02,S11aH07,S11i1125h02,S08aH07,S08c0814h20,S08d0815h04,S09f0920h21,S09f0920h24,S11h1124h22,S11j1126h23,S08b0812h24,S08c0814h04,S08c0814h05,S08c0814h23,S08d0815h24,S09e0919h05,S09g0921h06,S11h1124h19,S11i1125h01,S11j1126h22,S06aH07,S07aH07,S07aH08,S08aH08,S08b0812h23,S08d0815h21,S09e0919h06,S09e0919h20,S09f0920h01,S09g0921h22,S11h1124h05,S11i1125h19,S11i1125h21,S02aH01,S08b0812h22,S08c0814h06,S08d0815h06,S08d0815h19,S09f0920h19,S11i1125h03,S11i1125h22,S01aH01,S04aH01,S08b0812h04,S08c0814h21,S08d0815h03,S09aH08,S09e0919h04,S09f0920h03,S09f0920h04,S09g0921h20,S11aH01,S11h1124h20,S11j1126h19,S04aH08,S06aH01,S08d0815h05,S09e0919h02,S09g0921h24,S11h1124h23,S11h1124h24,S11j1126h06,S12aH08,S03aH08,S04aH07,S06aH08,S08b0812h02,S09f0920h23,S09g0921h01,S09g0921h03,S09g0921h19,S11h1124h03,S11i1125h06,S11j1126h02,S12aH01,S05aH07,S07aH01,S08b0812h05,S08c0814h24,S09e0919h01,S09f0920h22,S09g0921h04,S10aH07,S05aH08,S08b0812h19,S08b0812h20,S08c0814h22,S08d0815h20,S09e0919h23,S09f0920h06,S09g0921h05,S10aH08,S11h1124h06,S11j1126h21,S03aH01,S08b0812h01,S09e0919h03,S11h1124h04,S12aH07,S01aH07,S02aH07,S05aH01,S08b0812h06,S08d0815h01,S09e0919h24,S09g0921h21,S11h1124h01,S11h1124h02,S11i1125h23,S11j1126h05,S08c0814h02,S11aH08,S11j1126h20,S11j1126h24,S08b0812h03,S09e0919h21,S11j1126h01,S11j1126h03,S01aH08,S02aH08,S03aH07,S08c0814h01,S08c0814h19,S09f0920h20,S09g0921h23,S11h1124h21,S11i1125h04,S11i1125h20,S11j1126h04 | I12: N | J12: S01b0102h24,S03aH08,S04aH07,S05d0525h06,S06aH08,S08i0816h19,S09j0919h04,S09k0920h03,S09l0921h02,S09l0921h05,S09l0921h20,S09m0922h06,S11o1125h02,S12aH01,S01b0102h04,S01b0102h19,S01c0103h03,S01c0103h23,S04aH08,S05d0525h23,S06aH01,S08e0812h02,S08f0813h04,S08g0814h01,S09l0921h06,S09l0921h19,S09m0922h01,S09m0922h05,S09m0922h20,S11n1124h02,S11o1125h05,S11o1125h20,S11o1125h24,S11p1126h23,S12aH08,S01b0102h03,S05d0525h05,S08e0812h01,S08e0812h23,S08f0813h05,S08f0813h19,S08h0815h21,S08i0816h22,S09aH01,S09j0919h21,S09m0922h04,S11aH07,S11o1125h06,S11p1126h03,S11p1126h05,S01b0102h05,S05d0525h03,S08aH01,S08h0815h05,S08h0815h23,S09aH07,S09j0919h23,S09m0922h23,S10aH01,S11n1124h24,S01b0102h23,S01c0103h05,S01c0103h06,S02aH01,S08e0812h24,S08f0813h20,S08i0816h02,S09k0920h19,S09l0921h22,S11p1126h04,S01b0102h20,S05aH08,S05d0525h04,S05d0525h21,S05d0525h22,S08f0813h01,S08f0813h23,S08g0814h21,S08h0815h02,S09j0919h05,S09k0920h05,S09l0921h03,S10aH08,S03aH01,S08f0813h03,S08g0814h05,S08h0815h01,S08h0815h22,S11n1124h05,S12aH07,S01aH08,S02aH08,S03aH07,S08e0812h20,S08f0813h06,S08g0814h06,S08h0815h20,S09j0919h19,S09j0919h20,S09l0921h04,S09m0922h02,S09m0922h22,S11n1124h06,S11o1125h22,S11p1126h21,S01b0102h02,S01b0102h06,S01c0103h02,S01c0103h19,S05aH07,S07aH01,S08e0812h06,S08e0812h22,S08g0814h24,S09j0919h02,S09j0919h06,S09j0919h22,S09k0920h22,S09l0921h23,S09m0922h21,S10aH07,S11o1125h19,S11p1126h02,S11p1126h22,S11p1126h24,S01c0103h04,S01c0103h20,S05d0525h24,S08e0812h19,S08g0814h20,S08g0814h23,S08h0815h04,S08i0816h06,S08i0816h24,S09j0919h01,S09j0919h24,S09k0920h06,S09k0920h21,S11aH08,S11n1124h03,S11n1124h20,S11o1125h04,S11o1125h21,S01aH07,S01c0103h01,S02aH07,S05aH01,S05d0525h19,S08g0814h02,S08h0815h24,S08i0816h04,S08i0816h21,S09k0920h02,S11p1126h06,S01c0103h22,S05d0525h01,S08aH07,S08e0812h03,S08e0812h04,S08g0814h19,S08h0815h03,S08i0816h05,S09k0920h04,S09k0920h20,S09k0920h23,S09m0922h03,S11o1125h23,S11p1126h19,S11p1126h20,S05d0525h02,S05d0525h20,S06aH07,S07aH07,S07aH08,S08aH08,S09l0921h01,S09m0922h19,S11n1124h19,S01b0102h21,S01c0103h21,S08g0814h03,S08i0816h01,S09k0920h01,S09k0920h24,S09l0921h21,S09l0921h24,S11n1124h01,S11n1124h21,S11o1125h01,S08e0812h21,S08f0813h02,S08h0815h19,S08i0816h03,S08i0816h23,S09j0919h03,S11n1124h04,S11n1124h22,S11o1125h03,S01aH01,S01b0102h01,S01b0102h22,S01c0103h24,S04aH01,S08e0812h05,S08f0813h21,S08f0813h22,S08f0813h24,S08g0814h04,S08g0814h22,S08h0815h06,S08i0816h20,S09aH08,S09m0922h24,S11aH01,S11n1124h23,S11p1126h01 | L12: N | M12: S01aH07,S01b0129h23,S02aH07,S02b0201h21,S02b0204h03,S05aH01,S08c0807h21,S08c0808h22,S08c0809h01,S08c0812h06,S01b0130h21,S01b0130h22,S01b0130h23,S02b0201h01,S02b0201h19,S02b0202h23,S02b0202h24,S08c0806h02,S08c0806h04,S08c0806h21,S08c0807h01,S08c0810h23,S08c0812h21,S01aH08,S01b0130h19,S01b0131h05,S02aH08,S02b0202h01,S02b0202h03,S02b0203h06,S02b0204h05,S03aH07,S08c0807h24,S08c0808h04,S08c0810h22,S01b0129h04,S01b0130h06,S02b0201h02,S02b0202h19,S02b0204h20,S05aH08,S08c0806h05,S08c0809h21,S08c0811h22,S08c0811h24,S10aH08,S01b0129h22,S01b0131h19,S02b0201h03,S02b0201h04,S02b0201h20,S02b0203h21,S06aH07,S07aH07,S07aH08,S08aH08,S08c0806h20,S08c0808h24,S08c0809h22,S08c0810h01,S08c0810h03,S08c0810h24,S08c0811h03,S08c0811h04,S08c0812h02,S01b0129h24,S01b0131h20,S02b0201h05,S02b0203h02,S02b0203h03,S02b0203h05,S02b0203h22,S02b0203h24,S02b0204h19,S03aH01,S08c0806h03,S08c0807h19,S08c0808h05,S08c0810h20,S12aH07,S01b0129h03,S02b0201h22,S02b0203h20,S08c0808h21,S08c0809h19,S08c0810h04,S08c0811h20,S08c0812h20,S09aH01,S11aH07,S01aH01,S01b0129h05,S01b0130h04,S01b0131h04,S01b0131h21,S01b0131h22,S02b0201h06,S02b0202h21,S02b0204h01,S04aH01,S08c0807h03,S08c0807h05,S08c0808h03,S08c0808h20,S08c0809h24,S08c0810h06,S08c0810h19,S08c0811h23,S08c0812h01,S08c0812h22,S09aH08,S11aH01,S01b0129h19,S01b0129h20,S02b0201h23,S02b0201h24,S02b0202h22,S04aH08,S06aH01,S08c0809h20,S08c0811h19,S12aH08,S01b0130h05,S03aH08,S04aH07,S06aH08,S08c0806h01,S08c0807h20,S08c0807h23,S08c0809h03,S08c0809h06,S12aH01,S01b0130h02,S01b0130h03,S01b0130h24,S01b0131h03,S02aH01,S02b0202h02,S02b0202h06,S02b0203h04,S08c0806h23,S08c0807h06,S08c0808h06,S08c0812h03,S01b0129h02,S01b0130h01,S01b0131h01,S02b0203h23,S08c0807h02,S08c0807h04,S08c0809h23,S08c0811h06,S08c0811h21,S11aH08,S01b0129h21,S01b0130h20,S01b0131h06,S02b0202h20,S02b0204h04,S02b0204h22,S05aH07,S07aH01,S08c0810h02,S08c0812h04,S08c0812h19,S08c0812h23,S08c0812h24,S10aH07,S01b0129h06,S02b0202h04,S02b0202h05,S02b0204h02,S02b0204h06,S02b0204h21,S08aH01,S08c0806h24,S08c0809h04,S08c0810h05,S08c0810h21,S08c0811h02,S08c0811h05,S09aH07,S10aH01,S01b0131h24,S02b0203h01,S02b0203h19,S08aH07,S08c0806h06,S08c0807h22,S08c0808h01,S01b0129h01,S01b0131h02,S01b0131h23,S02b0204h23,S02b0204h24,S08c0806h19,S08c0806h22,S08c0808h02,S08c0808h19,S08c0808h23,S08c0809h02,S08c0809h05,S08c0811h01,S08c0812h05 | O12: N | P12: S01aH07,S01b0129h23,S02aH07,S02b0201h21,S02b0204h03,S05aH01,S08c0807h21,S08c0808h22,S08c0809h01,S08c0812h06,S09e0921h03,S01b0130h21,S01b0130h22,S01b0130h23,S02b0201h01,S02b0201h19,S02b0202h23,S02b0202h24,S08c0806h02,S08c0806h04,S08c0806h21,S08c0807h01,S08c0810h23,S08c0812h21,S09d0920h02,S09d0920h19,S09e0921h01,S01b0129h01,S01b0131h02,S01b0131h23,S02b0204h23,S02b0204h24,S08c0806h19,S08c0806h22,S08c0808h02,S08c0808h19,S08c0808h23,S08c0809h02,S08c0809h05,S08c0811h01,S08c0812h05,S01b0129h04,S01b0130h06,S02b0201h02,S02b0202h19,S02b0204h20,S05aH08,S08c0806h05,S08c0809h21,S08c0811h22,S08c0811h24,S09d0920h01,S09e0921h20,S09e0921h22,S10aH08,S01b0129h22,S01b0131h19,S02b0201h03,S02b0201h04,S02b0201h20,S02b0203h21,S06aH07,S07aH07,S07aH08,S08aH08,S08c0806h20,S08c0808h24,S08c0809h22,S08c0810h01,S08c0810h03,S08c0810h24,S08c0811h03,S08c0811h04,S08c0812h02,S09d0920h06,S09e0921h02,S01b0130h02,S01b0130h03,S01b0130h24,S01b0131h03,S02aH01,S02b0202h02,S02b0202h06,S02b0203h04,S08c0806h23,S08c0807h06,S08c0808h06,S08c0812h03,S01b0129h21,S01b0130h20,S01b0131h06,S02b0202h20,S02b0204h04,S02b0204h22,S05aH07,S07aH01,S08c0810h02,S08c0812h04,S08c0812h19,S08c0812h23,S08c0812h24,S09d0920h03,S09e0921h06,S09e0921h19,S10aH07,S01b0130h05,S03aH08,S04aH07,S06aH08,S08c0806h01,S08c0807h20,S08c0807h23,S08c0809h03,S08c0809h06,S09e0921h04,S12aH01,S01b0129h19,S01b0129h20,S02b0201h23,S02b0201h24,S02b0202h22,S04aH08,S06aH01,S08c0809h20,S08c0811h19,S09d0920h23,S12aH08,S01b0129h03,S02b0201h22,S02b0203h20,S08c0808h21,S08c0809h19,S08c0810h04,S08c0811h20,S08c0812h20,S09aH01,S09e0921h05,S11aH07,S01b0129h06,S02b0202h04,S02b0202h05,S02b0204h02,S02b0204h06,S02b0204h21,S08aH01,S08c0806h24,S08c0809h04,S08c0810h05,S08c0810h21,S08c0811h02,S08c0811h05,S09aH07,S09d0920h21,S09e0921h24,S10aH01,S01aH01,S01b0129h05,S01b0130h04,S01b0131h04,S01b0131h21,S01b0131h22,S02b0201h06,S02b0202h21,S02b0204h01,S04aH01,S08c0807h03,S08c0807h05,S08c0808h03,S08c0808h20,S08c0809h24,S08c0810h06,S08c0810h19,S08c0811h23,S08c0812h01,S08c0812h22,S09aH08,S09e0921h21,S11aH01,S01b0129h02,S01b0130h01,S01b0131h01,S02b0203h23,S08c0807h02,S08c0807h04,S08c0809h23,S08c0811h06,S08c0811h21,S09d0920h20,S09d0920h24,S11aH08,S01aH08,S01b0130h19,S01b0131h05,S02aH08,S02b0202h01,S02b0202h03,S02b0203h06,S02b0204h05,S03aH07,S08c0807h24,S08c0808h04,S08c0810h22,S09d0920h05,S09e0921h23,S01b0129h24,S01b0131h20,S02b0201h05,S02b0203h02,S02b0203h03,S02b0203h05,S02b0203h22,S02b0203h24,S02b0204h19,S03aH01,S08c0806h03,S08c0807h19,S08c0808h05,S08c0810h20,S12aH07,S01b0131h24,S02b0203h01,S02b0203h19,S08aH07,S08c0806h06,S08c0807h22,S08c0808h01,S09d0920h04,S09d0920h22 | R12: N | S12: S04aH03,S03aH01,S03aH03,S02aH03,S01aH01,S04aH01,S01aH03,S02aH01 | U12: N | V12: S02aH06,S03aH01,S01aH06,S02aH01,S01aH01,S04aH01,S04aH06,S03aH06 | X12: N | Y12: S03aH06,S03aH01,S02aH06,S06aH06,S01aH06,S07aH01,S05aH01,S07aH06,S01aH01,S04aH01,S04aH06,S06aH01,S02aH01,S05aH06 | AA12: N | AB12: S01aH07,S02aH07,S05aH01,S02aH01,S04aH08,S06aH01,S05aH07,S07aH01,S06aH07,S07aH07,S07aH08,S05aH08,S03aH08,S04aH07,S06aH08,S01aH08,S02aH08,S03aH07,S03aH01,S01aH01,S04aH01 | AD12: N | AE12: S08aH01,S09aH07,S10aH01,S03aH08,S04aH07,S06aH08,S12aH01,S08aH07,S01aH08,S02aH08,S03aH07,S03aH01,S12aH07,S05aH07,S07aH01,S10aH07,S11aH08,S05aH08,S10aH08,S01aH07,S02aH07,S05aH01,S04aH08,S06aH01,S12aH08,S02aH01,S09aH01,S11aH07,S06aH07,S07aH07,S07aH08,S08aH08,S01aH01,S04aH01,S09aH08,S11aH01 | AG12: N | AH12: S06aH07,S07aH07,S07aH08,S08aH08,S03aH01,S12aH07,S04aH08,S06aH01,S12aH08,S09aH01,S11aH07,S01aH07,S02aH07,S05aH01,S11aH08,S05aH08,S10aH08,S02aH01,S08aH07,S08aH01,S09aH07,S10aH01,S01aH01,S04aH01,S09aH08,S11aH01,S05aH07,S07aH01,S10aH07,S03aH08,S04aH07,S06aH08,S12aH01,S01aH08,S02aH08,S03aH07 | AJ12: N | AK12: S08aH01,S09aH07,S10aH01,S04aH08,S06aH01,S12aH08,S02aH01,S03aH01,S12aH07,S01aH08,S02aH08,S03aH07,S05aH07,S07aH01,S10aH07,S11aH08,S01aH01,S04aH01,S09aH08,S11aH01,S06aH07,S07aH07,S07aH08,S08aH08,S08aH07,S03aH08,S04aH07,S06aH08,S12aH01,S05aH08,S10aH08,S09aH01,S11aH07,S01aH07,S02aH07,S05aH01 | AM12: N | AN12: AllSaAllH | AP12: N | AQ12: FaP,SaP,RaN,FaN,RaP,WaP,SaN,WaN
I17: 0.75 | K17: share of charging at night
C18: ~UC_Sets: R_E: AllRegions
H21: =IF(H23=H24,"Not Required!","~UC_T: LO") -> Not Required!
C22: UC_N | D22: Pset_CI | E22: Pset_CO | F22: pset_pn | G22: Cset_CN | H22: TimeSlice | I22: UC_FLO | J22: UC_RHSRT | K22: UC_RHSRT~0
C23: UC_bev night chg limit | D23: ELC | E23: =G23 -> AuxStoIN | F23: *EV* | G23: AuxStoIN | H23: =HLOOKUP($A$10,$D$10:$CU$12,3,FALSE) -> AllSaAllH | I23: =1+I24 -> 0.25 | J23: 0 | K23: 3 | M23: night
D24: ELC | E24: =G24 -> AuxStoIN | F24: *EV* | G24: AuxStoIN | H24: =HLOOKUP($A$10,$D$10:$CU$12,2,FALSE) -> AllSaAllH | I24: =-$I$17 -> -0.75 | M24: day

Sheet s1p1v1_d
C9: =IF(A11="x","DeActivated","~TimeSlices") -> DeActivated | I9: =IF(A11="x","DeActivated","~TFM_DINS-AT") -> DeActivated | N9: =IF(A11="x","DeActivated","~TFM_DINS-AT") -> DeActivated | S9: =IF(A11="x","DeActivated","~TFM_DINS-AT") -> DeActivated | X9: =IF(A11="x","DeActivated","~TFM_DINS-AT") -> DeActivated | AC9: =IF(A11="x","DeActivated","~TFM_DINS-AT") -> DeActivated | AG9: =IF(A11="x","DeActivated","~TFM_DINS-AT") -> DeActivated | AK9: =IF(A11="x","DeActivated","~TFM_INS-AT") -> DeActivated
A10: s1p1v1_d | C10: season | D10: weekly | E10: daynite | F10: wparent | G10: dparent | I10: commodity | J10: timeslice | K10: com_fr | L10: process | N10: commodity | O10: timeslice | P10: com_fr | Q10: process | S10: commodity | T10: timeslice | U10: com_fr | V10: process | X10: g_yrfr | Y10: com_fr | Z10: timeslice | AA10: commodity | AC10: commodity | AD10: timeslice | AE10: com_fr | AG10: commodity | AH10: timeslice | AI10: com_pkflx | AK10: Year | AL10: timeslice | AM10: ncap_afs | AN10: pset_ci
A11: =IFERROR(IF(Veda!D5=A10,"ok","x"),"") -> x | C11: S01 | D11: a | E11: 0815h01 | F11: S01,S02,S03,S04,S05,S06,S07,S08,S09,S10,S11,S12 | G11: b | I11: elc_spv-IND | J11: S01aH01 | K11: 0 | L11: IMPNRGZ | N11: elc_won-IND | O11: S01aH01 | P11: 0.017870836 | Q11: IMPNRGZ | S11: elc_wof-IND | T11: S01aH01 | U11: 0.018804923 | V11: IMPNRGZ | X11: 0.024771689 | Y11: 0.0097827943 | Z11: S01aH01 | AA11: elc_roadtransport | AC11: elc_buildings | AD11: S01aH01 | AE11: 0.019494529 | AG11: ELC | AH11: S01aH01 | AI11: 0.10127754 | AK11: 2020 | AL11: S01 | AM11: 0.26981109 | AN11: hydro
C12: S02 | D12: b | E12: 0815h02 | F12: S08 | G12: b | I12: elc_spv-IND | J12: S01aH02 | K12: 0.0015156644 | L12: IMPNRGZ | N12: elc_won-IND | O12: S01aH02 | P12: 0.0019241152 | Q12: IMPNRGZ | S12: elc_wof-IND | T12: S01aH02 | U12: 0.0024994659 | V12: IMPNRGZ | X12: 0.0035388128 | Y12: 0.0059087255 | Z12: S01aH02 | AA12: elc_roadtransport | AC12: elc_buildings | AD12: S01aH02 | AE12: 0.0031657926 | AG12: ELC | AH12: S01aH02 | AI12: 0.027713628 | AK12: 2020 | AL12: S02 | AM12: 0.28091924 | AN12: hydro
C13: S03 | D13: c | E13: 0815h03 | F13: S09 | G13: b | I13: elc_spv-IND | J13: S01aH03 | K13: 0.0060907787 | L13: IMPNRGZ | N13: elc_won-IND | O13: S01aH03 | P13: 0.0013264423 | Q13: IMPNRGZ | S13: elc_wof-IND | T13: S01aH03 | U13: 0.0024236393 | V13: IMPNRGZ | X13: 0.0035388128 | Y13: 0.0045214595 | Z13: S01aH03 | AA13: elc_roadtransport | AC13: elc_buildings | AD13: S01aH03 | AE13: 0.0032675077 | AG13: ELC | AH13: S01aH03 | AI13: 0.053468428 | AK13: 2020 | AL13: S03 | AM13: 0.2817962 | AN13: hydro
C14: S04 | D14: d | E14: 0815h04 | F14: S11 | G14: b | I14: elc_spv-IND | J14: S01aH04 | K14: 0.0088262465 | L14: IMPNRGZ | N14: elc_won-IND | O14: S01aH04 | P14: 0.0010431622 | Q14: IMPNRGZ | S14: elc_wof-IND | T14: S01aH04 | U14: 0.0023370907 | V14: IMPNRGZ | X14: 0.0035388128 | Y14: 0.0044803554 | Z14: S01aH04 | AA14: elc_roadtransport | AC14: elc_buildings | AD14: S01aH04 | AE14: 0.0033128609 | AG14: ELC | AH14: S01aH04 | AI14: 0.058480835 | AK14: 2020 | AL14: S04 | AM14: 0.32653086 | AN14: hydro
C15: S05 | E15: 0815h05 | G15: b | I15: elc_spv-IND | J15: S01aH05 | K15: 0.068054972 | L15: IMPNRGZ | N15: elc_won-IND | O15: S01aH05 | P15: 0.0064320848 | Q15: IMPNRGZ | S15: elc_wof-IND | T15: S01aH05 | U15: 0.014185336 | V15: IMPNRGZ | X15: 0.024771689 | Y15: 0.034650822 | Z15: S01aH05 | AA15: elc_roadtransport | AC15: elc_buildings | AD15: S01aH05 | AE15: 0.025061803 | AG15: ELC | AH15: S01aH05 | AI15: 0.085909955 | AK15: 2020 | AL15: S05 | AM15: 0.43263317 | AN15: hydro
C16: S06 | E16: 0815h06 | G16: b | I16: elc_spv-IND | J16: S01aH06 | K16: 0.0063045631 | L16: IMPNRGZ | N16: elc_won-IND | O16: S01aH06 | P16: 0.0011229787 | Q16: IMPNRGZ | S16: elc_wof-IND | T16: S01aH06 | U16: 0.0022277817 | V16: IMPNRGZ | X16: 0.0035388128 | Y16: 0.0068849497 | Z16: S01aH06 | AA16: elc_roadtransport | AC16: elc_buildings | AD16: S01aH06 | AE16: 0.0020364328 | AG16: ELC | AH16: S01aH06 | AI16: 0.13177807 | AK16: 2020 | AL16: S06 | AM16: 0.53857958 | AN16: hydro
C17: S07 | E17: 0815h07 | G17: b | I17: elc_spv-IND | J17: S01aH07 | K17: 0.0019471601 | L17: IMPNRGZ | N17: elc_won-IND | O17: S01aH07 | P17: 0.0017169266 | Q17: IMPNRGZ | S17: elc_wof-IND | T17: S01aH07 | U17: 0.0023637794 | V17: IMPNRGZ | X17: 0.0035388128 | Y17: 0.0053435431 | Z17: S01aH07 | AA17: elc_roadtransport | AC17: elc_buildings | AD17: S01aH07 | AE17: 0.00091182134 | AG17: ELC | AH17: S01aH07 | AI17: 0.025642556 | AK17: 2020 | AL17: S07 | AM17: 0.55540745 | AN17: hydro
C18: S08 | E18: 0815h08 | G18: b | I18: elc_spv-IND | J18: S01aH08 | K18: 0 | L18: IMPNRGZ | N18: elc_won-IND | O18: S01aH08 | P18: 0.014808899 | Q18: IMPNRGZ | S18: elc_wof-IND | T18: S01aH08 | U18: 0.01289408 | V18: IMPNRGZ | X18: 0.017694064 | Y18: 0.013358858 | Z18: S01aH08 | AA18: elc_roadtransport | AC18: elc_buildings | AD18: S01aH08 | AE18: 0.0048624804 | AG18: ELC | AH18: S01aH08 | AI18: 0.14420378 | AK18: 2020 | AL18: S08 | AM18: 0.59107045 | AN18: hydro
C19: S09 | E19: 0815h09 | G19: b | I19: elc_spv-IND | J19: S02aH01 | K19: 0 | L19: IMPNRGZ | N19: elc_won-IND | O19: S02aH01 | P19: 0.016839964 | Q19: IMPNRGZ | S19: elc_wof-IND | T19: S02aH01 | U19: 0.014357735 | V19: IMPNRGZ | X19: 0.022374429 | Y19: 0.0088360722 | Z19: S02aH01 | AA19: elc_roadtransport | AC19: elc_buildings | AD19: S02aH01 | AE19: 0.017740078 | AG19: ELC | AH19: S02aH01 | AI19: 0.14633377 | AK19: 2020 | AL19: S09 | AM19: 0.61228312 | AN19: hydro
C20: S10 | E20: 0815h10 | G20: b | I20: elc_spv-IND | J20: S02aH02 | K20: 0.001374473 | L20: IMPNRGZ | N20: elc_won-IND | O20: S02aH02 | P20: 0.0016754219 | Q20: IMPNRGZ | S20: elc_wof-IND | T20: S02aH02 | U20: 0.0020874895 | V20: IMPNRGZ | X20: 0.003196347 | Y20: 0.0053369134 | Z20: S02aH02 | AA20: elc_roadtransport | AC20: elc_buildings | AD20: S02aH02 | AE20: 0.0030869305 | AG20: ELC | AH20: S02aH02 | AI20: 0.050572918 | AK20: 2020 | AL20: S10 | AM20: 0.41918646 | AN20: hydro
C21: S11 | E21: 0815h11 | G21: b | I21: elc_spv-IND | J21: S02aH03 | K21: 0.0056351739 | L21: IMPNRGZ | N21: elc_won-IND | O21: S02aH03 | P21: 0.0011556557 | Q21: IMPNRGZ | S21: elc_wof-IND | T21: S02aH03 | U21: 0.0020457666 | V21: IMPNRGZ | X21: 0.003196347 | Y21: 0.0040838989 | Z21: S02aH03 | AA21: elc_roadtransport | AC21: elc_buildings | AD21: S02aH03 | AE21: 0.0031947187 | AG21: ELC | AH21: S02aH03 | AI21: 0.043209448 | AK21: 2020 | AL21: S11 | AM21: 0.28001305 | AN21: hydro
C22: S12 | E22: 0815h12 | G22: b | I22: elc_spv-IND | J22: S02aH04 | K22: 0.0080353933 | L22: IMPNRGZ | N22: elc_won-IND | O22: S02aH04 | P22: 0.0010616092 | Q22: IMPNRGZ | S22: elc_wof-IND | T22: S02aH04 | U22: 0.0019680907 | V22: IMPNRGZ | X22: 0.003196347 | Y22: 0.0040467726 | Z22: S02aH04 | AA22: elc_roadtransport | AC22: elc_buildings | AD22: S02aH04 | AE22: 0.0032472558 | AG22: ELC | AH22: S02aH04 | AI22: 0.053013612 | AK22: 2020 | AL22: S12 | AM22: 0.25899526 | AN22: hydro
E23: 0815h13 | G23: b | I23: elc_spv-IND | J23: S02aH05 | K23: 0.062216285 | L23: IMPNRGZ | N23: elc_won-IND | O23: S02aH05 | P23: 0.0081032721 | Q23: IMPNRGZ | S23: elc_wof-IND | T23: S02aH05 | U23: 0.011931276 | V23: IMPNRGZ | X23: 0.022374429 | Y23: 0.031297516 | Z23: S02aH05 | AA23: elc_roadtransport | AC23: elc_buildings | AD23: S02aH05 | AE23: 0.023621562 | AG23: ELC | AH23: S02aH05 | AI23: 0.18724621 | AK23: 2021 | AL23: S01 | AM23: 0.24537184 | AN23: hydro
E24: 0815h14 | G24: b | I24: elc_spv-IND | J24: S02aH06 | K24: 0.0058968814 | L24: IMPNRGZ | N24: elc_won-IND | O24: S02aH06 | P24: 0.0015021228 | Q24: IMPNRGZ | S24: elc_wof-IND | T24: S02aH06 | U24: 0.0018782053 | V24: IMPNRGZ | X24: 0.003196347 | Y24: 0.0062186643 | Z24: S02aH06 | AA24: elc_roadtransport | AC24: elc_buildings | AD24: S02aH06 | AE24: 0.0015505499 | AG24: ELC | AH24: S02aH06 | AI24: 0.038164786 | AK24: 2021 | AL24: S02 | AM24: 0.2474857 | AN24: hydro
E25: 0815h15 | G25: b | I25: elc_spv-IND | J25: S02aH07 | K25: 0.0025564716 | L25: IMPNRGZ | N25: elc_won-IND | O25: S02aH07 | P25: 0.0019679906 | Q25: IMPNRGZ | S25: elc_wof-IND | T25: S02aH07 | U25: 0.0019764556 | V25: IMPNRGZ | X25: 0.003196347 | Y25: 0.004826426 | Z25: S02aH07 | AA25: elc_roadtransport | AC25: elc_buildings | AD25: S02aH07 | AE25: 0.00086897921 | AG25: ELC | AH25: S02aH07 | AI25: 0.039400044 | AK25: 2021 | AL25: S03 | AM25: 0.25370414 | AN25: hydro
