Workbook

Sheet Veda
G1: 1-55
D2: ="~Inputcell: "&_xlfn.TEXTJOIN(",",TRUE,G1:EE1) -> ~Inputcell: 1-55
D3: 3
D5: =VLOOKUP(D3,$C$9:$E$1001,2,FALSE) -> s2_w | E5: =VLOOKUP(D3,$C$9:$E$1001,3,FALSE) -> C1
B7: ~Scenmap
A8: priority | B8: scen | C8: case_no | D8: timeslice | E8: climate
A9: 5 | B9: =VLOOKUP(E9,$AK$9:$AL$15,2,FALSE)&"."&VLOOKUP(D9,$AH$9:$AI$19,2,FALSE) -> e 1.5 deg no OS.e3d | C9: 1 | D9: s1p1v1_d | E9: C1 | G9: Limit warming to 1.5°C (>50%) with no or limited overshoot | AH9: s1p1v1_d | AI9: e3d | AK9: C1 | AL9: e 1.5 deg no OS
A10: 5 | B10: =VLOOKUP(E10,$AK$9:$AL$15,2,FALSE)&"."&VLOOKUP(D10,$AH$9:$AI$19,2,FALSE) -> e 1.5 deg no OS.d9d | C10: 2 | D10: s3p3v3_d | E10: C1 | G10: Limit warming to 1.5°C (>67%) with high overshoot | S10: IEA | AH10: s3p3v3_d | AI10: d9d | AK10: C2 | AL10: d 1.5 deg OS
A11: 5 | B11: =VLOOKUP(E11,$AK$9:$AL$15,2,FALSE)&"."&VLOOKUP(D11,$AH$9:$AI$19,2,FALSE) -> e 1.5 deg no OS.b2w | C11: 3 | D11: s2_w | E11: C1 | G11: Limit warming to 2°C (>67%) with higher action post-2030 | S11: 2022 | AH11: s2_w | AI11: b2w | AK11: C3 | AL11: c 2 deg (67%)
A12: 5 | B12: =VLOOKUP(E12,$AK$9:$AL$15,2,FALSE)&"."&VLOOKUP(D12,$AH$9:$AI$19,2,FALSE) -> e 1.5 deg no OS.a2w2d | C12: 4 | D12: s2_w_p2_d | E12: C1 | G12: Limit warming to 2°C (>50%) with immediate action | S12: =SUMIFS(iea_data!I3:I9999,iea_data!$B$3:$B$9999,Veda!$S$11)+T28-T29 -> 65.12 | T12: base-year generation (TWh) | AH12: s2_w_p2_d | AI12: a2w2d | AK12: C4 | AL12: b 2 deg (50%)
A13: 5 | B13: =VLOOKUP(E13,$AK$9:$AL$15,2,FALSE)&"."&VLOOKUP(D13,$AH$9:$AI$19,2,FALSE) -> e 1.5 deg no OS.hTS12c | C13: 5 | D13: ts12_clu | E13: C1 | G13: Likely above 3°C warming with limited mitigation | AH13: ts12_clu | AI13: hTS12c | AK13: C7 | AL13: a 3 deg
A14: 5 | B14: =VLOOKUP(E14,$AK$9:$AL$15,2,FALSE)&"."&VLOOKUP(D14,$AH$9:$AI$19,2,FALSE) -> e 1.5 deg no OS.gTS24c | C14: 6 | D14: ts24_clu | E14: =E13 -> C1 | T14: =S12 -> 65.12 | U14: =$S$12*J15 -> 67.0736 | V14: =$S$12*K15 -> 77.4928 | W14: =$S$12*L15 -> 93.1216 | X14: =$S$12*M15 -> 107.448 | Y14: =$S$12*N15 -> 117.8672 | Z14: =$S$12*O15 -> 125.6816 | AH14: ts24_clu | AI14: gTS24c
A15: 5 | B15: =VLOOKUP(E15,$AK$9:$AL$15,2,FALSE)&"."&VLOOKUP(D15,$AH$9:$AI$19,2,FALSE) -> e 1.5 deg no OS.fTS48c | C15: 7 | D15: ts48_clu | E15: =E14 -> C1 | G15: Electricity growth relative to 2020 | I15: =SUMIFS(ar6_r10!$F$2:$F$999,ar6_r10!$A$2:$A$999,Veda!$E$5,ar6_r10!$C$2:$C$999,Veda!I$17,ar6_r10!$M$2:$M$999,Veda!$G15) -> 1 | J15: =SUMIFS(ar6_r10!$F$2:$F$999,ar6_r10!$A$2:$A$999,Veda!$E$5,ar6_r10!$C$2:$C$999,Veda!J$17,ar6_r10!$M$2:$M$999,Veda!$G15) -> 1.03 | K15: =SUMIFS(ar6_r10!$F$2:$F$999,ar6_r10!$A$2:$A$999,Veda!$E$5,ar6_r10!$C$2:$C$999,Veda!K$17,ar6_r10!$M$2:$M$999,Veda!$G15) -> 1.19 | L15: =SUMIFS(ar6_r10!$F$2:$F$999,ar6_r10!$A$2:$A$999,Veda!$E$5,ar6_r10!$C$2:$C$999,Veda!L$17,ar6_r10!$M$2:$M$999,Veda!$G15) -> 1.43 | M15: =SUMIFS(ar6_r10!$F$2:$F$999,ar6_r10!$A$2:$A$999,Veda!$E$5,ar6_r10!$C$2:$C$999,Veda!M$17,ar6_r10!$M$2:$M$999,Veda!$G15) -> 1.65 | N15: =SUMIFS(ar6_r10!$F$2:$F$999,ar6_r10!$A$2:$A$999,Veda!$E$5,ar6_r10!$C$2:$C$999,Veda!N$17,ar6_r10!$M$2:$M$999,Veda!$G15) -> 1.81 | O15: =SUMIFS(ar6_r10!$F$2:$F$999,ar6_r10!$A$2:$A$999,Veda!$E$5,ar6_r10!$C$2:$C$999,Veda!O$17,ar6_r10!$M$2:$M$999,Veda!$G15) -> 1.93 | AH15: ts48_clu | AI15: fTS48c
A16: 5 | B16: =VLOOKUP(E16,$AK$9:$AL$15,2,FALSE)&"."&VLOOKUP(D16,$AH$9:$AI$19,2,FALSE) -> e 1.5 deg no OS.c15d | C16: 8 | D16: s5p5v5_d | E16: =E15 -> C1 | S16: ~TFM_INS-TS | AH16: s5p5v5_d | AI16: c15d
A17: 5 | B17: =VLOOKUP(E17,$AK$9:$AL$15,2,FALSE)&"."&VLOOKUP(D17,$AH$9:$AI$19,2,FALSE) -> e 1.5 deg no OS.f1d | C17: 9 | D17: s1_d | E17: =E16 -> C1 | I17: 2020 | J17: =U17 -> 2025 | K17: =V17 -> 2030 | L17: =W17 -> 2035 | M17: =X17 -> 2040 | N17: =Y17 -> 2045 | O17: =Z17 -> 2050 | S17: commodity | T17: 2022 | U17: 2025 | V17: 2030 | W17: 2035 | X17: 2040 | Y17: 2045 | Z17: 2050 | AA17: attribute | AH17: ts_12 | AI17: iTS12
A18: 5 | B18: =VLOOKUP(E18,$AK$9:$AL$15,2,FALSE)&"."&VLOOKUP(D18,$AH$9:$AI$19,2,FALSE) -> e 1.5 deg no OS.jAnn | C18: 10 | D18: ts_annual | E18: =E17 -> C1 | G18: Hydrogen as a share of electricity | I18: =SUMIFS(ar6_r10!$F$2:$F$999,ar6_r10!$A$2:$A$999,Veda!$E$5,ar6_r10!$C$2:$C$999,Veda!I$17,ar6_r10!$M$2:$M$999,Veda!$G18) -> 0.01 | J18: =SUMIFS(ar6_r10!$F$2:$F$999,ar6_r10!$A$2:$A$999,Veda!$E$5,ar6_r10!$C$2:$C$999,Veda!J$17,ar6_r10!$M$2:$M$999,Veda!$G18) -> 0.01 | K18: =SUMIFS(ar6_r10!$F$2:$F$999,ar6_r10!$A$2:$A$999,Veda!$E$5,ar6_r10!$C$2:$C$999,Veda!K$17,ar6_r10!$M$2:$M$999,Veda!$G18) -> 0.01 | L18: =SUMIFS(ar6_r10!$F$2:$F$999,ar6_r10!$A$2:$A$999,Veda!$E$5,ar6_r10!$C$2:$C$999,Veda!L$17,ar6_r10!$M$2:$M$999,Veda!$G18) -> 0.03 | M18: =SUMIFS(ar6_r10!$F$2:$F$999,ar6_r10!$A$2:$A$999,Veda!$E$5,ar6_r10!$C$2:$C$999,Veda!M$17,ar6_r10!$M$2:$M$999,Veda!$G18) -> 0.03 | N18: =SUMIFS(ar6_r10!$F$2:$F$999,ar6_r10!$A$2:$A$999,Veda!$E$5,ar6_r10!$C$2:$C$999,Veda!N$17,ar6_r10!$M$2:$M$999,Veda!$G18) -> 0.04 | O18: =SUMIFS(ar6_r10!$F$2:$F$999,ar6_r10!$A$2:$A$999,Veda!$E$5,ar6_r10!$C$2:$C$999,Veda!O$17,ar6_r10!$M$2:$M$999,Veda!$G18) -> 0.05 | S18: hydrogen_allsect | T18: =I18*T$14 -> 0.6512 | U18: =J18*U$14 -> 0.670736 | V18: =K18*V$14 -> 0.774928 | W18: =L18*W$14 -> 2.793648 | X18: =M18*X$14 -> 3.22344 | Y18: =N18*Y$14 -> 4.714688 | Z18: =O18*Z$14 -> 6.28408 | AA18: demand | AH18: ts_annual | AI18: jAnn
A19: 5 | B19: =VLOOKUP(E19,$AK$9:$AL$15,2,FALSE)&"."&VLOOKUP(D19,$AH$9:$AI$19,2,FALSE) -> e 1.5 deg no OS.iTS12 | C19: 11 | D19: ts_12 | E19: =E18 -> C1 | G19: Industry electricity share | I19: =SUMIFS(ar6_r10!$F$2:$F$999,ar6_r10!$A$2:$A$999,Veda!$E$5,ar6_r10!$C$2:$C$999,Veda!I$17,ar6_r10!$M$2:$M$999,Veda!$G19) -> 0.35 | J19: =SUMIFS(ar6_r10!$F$2:$F$999,ar6_r10!$A$2:$A$999,Veda!$E$5,ar6_r10!$C$2:$C$999,Veda!J$17,ar6_r10!$M$2:$M$999,Veda!$G19) -> 0.32 | K19: =SUMIFS(ar6_r10!$F$2:$F$999,ar6_r10!$A$2:$A$999,Veda!$E$5,ar6_r10!$C$2:$C$999,Veda!K$17,ar6_r10!$M$2:$M$999,Veda!$G19) -> 0.3 | L19: =SUMIFS(ar6_r10!$F$2:$F$999,ar6_r10!$A$2:$A$999,Veda!$E$5,ar6_r10!$C$2:$C$999,Veda!L$17,ar6_r10!$M$2:$M$999,Veda!$G19) -> 0.29 | M19: =SUMIFS(ar6_r10!$F$2:$F$999,ar6_r10!$A$2:$A$999,Veda!$E$5,ar6_r10!$C$2:$C$999,Veda!M$17,ar6_r10!$M$2:$M$999,Veda!$G19) -> 0.29 | N19: =SUMIFS(ar6_r10!$F$2:$F$999,ar6_r10!$A$2:$A$999,Veda!$E$5,ar6_r10!$C$2:$C$999,Veda!N$17,ar6_r10!$M$2:$M$999,Veda!$G19) -> 0.3 | O19: =SUMIFS(ar6_r10!$F$2:$F$999,ar6_r10!$A$2:$A$999,Veda!$E$5,ar6_r10!$C$2:$C$999,Veda!O$17,ar6_r10!$M$2:$M$999,Veda!$G19) -> 0.31 | S19: elc_industry | T19: =I19*T$14 -> 22.792 | U19: =J19*U$14 -> 21.463552 | V19: =K19*V$14 -> 23.24784 | W19: =L19*W$14 -> 27.005264 | X19: =M19*X$14 -> 31.15992 | Y19: =N19*Y$14 -> 35.36016 | Z19: =O19*Z$14 -> 38.961296 | AA19: demand | AH19: s1_d | AI19: f1d
A20: 5 | B20: =VLOOKUP(E20,$AK$9:$AL$15,2,FALSE)&"."&VLOOKUP(D20,$AH$9:$AI$19,2,FALSE) -> d 1.5 deg OS.e3d | C20: 12 | D20: =D9 -> s1p1v1_d | E20: C2 | G20: Residential and commercial electricity share | I20: =SUMIFS(ar6_r10!$F$2:$F$999,ar6_r10!$A$2:$A$999,Veda!$E$5,ar6_r10!$C$2:$C$999,Veda!I$17,ar6_r10!$M$2:$M$999,Veda!$G20) -> 0.61 | J20: =SUMIFS(ar6_r10!$F$2:$F$999,ar6_r10!$A$2:$A$999,Veda!$E$5,ar6_r10!$C$2:$C$999,Veda!J$17,ar6_r10!$M$2:$M$999,Veda!$G20) -> 0.62 | K20: =SUMIFS(ar6_r10!$F$2:$F$999,ar6_r10!$A$2:$A$999,Veda!$E$5,ar6_r10!$C$2:$C$999,Veda!K$17,ar6_r10!$M$2:$M$999,Veda!$G20) -> 0.59 | L20: =SUMIFS(ar6_r10!$F$2:$F$999,ar6_r10!$A$2:$A$999,Veda!$E$5,ar6_r10!$C$2:$C$999,Veda!L$17,ar6_r10!$M$2:$M$999,Veda!$G20) -> 0.56 | M20: =SUMIFS(ar6_r10!$F$2:$F$999,ar6_r10!$A$2:$A$999,Veda!$E$5,ar6_r10!$C$2:$C$999,Veda!M$17,ar6_r10!$M$2:$M$999,Veda!$G20) -> 0.54 | N20: =SUMIFS(ar6_r10!$F$2:$F$999,ar6_r10!$A$2:$A$999,Veda!$E$5,ar6_r10!$C$2:$C$999,Veda!N$17,ar6_r10!$M$2:$M$999,Veda!$G20) -> 0.53 | O20: =SUMIFS(ar6_r10!$F$2:$F$999,ar6_r10!$A$2:$A$999,Veda!$E$5,ar6_r10!$C$2:$C$999,Veda!O$17,ar6_r10!$M$2:$M$999,Veda!$G20) -> 0.53 | S20: elc_buildings | T20: =I20*T$14 -> 39.7232 | U20: =J20*U$14 -> 41.585632 | V20: =K20*V$14 -> 45.720752 | W20: =L20*W$14 -> 52.148096 | X20: =M20*X$14 -> 58.02192 | Y20: =N20*Y$14 -> 62.469616 | Z20: =O20*Z$14 -> 66.611248 | AA20: demand
A21: 5 | B21: =VLOOKUP(E21,$AK$9:$AL$15,2,FALSE)&"."&VLOOKUP(D21,$AH$9:$AI$19,2,FALSE) -> d 1.5 deg OS.d9d | C21: 13 | D21: =D10 -> s3p3v3_d | E21: =E20 -> C2 | G21: Transportation electricity share | I21: =SUMIFS(ar6_r10!$F$2:$F$999,ar6_r10!$A$2:$A$999,Veda!$E$5,ar6_r10!$C$2:$C$999,Veda!I$17,ar6_r10!$M$2:$M$999,Veda!$G21) -> 0.03 | J21: =SUMIFS(ar6_r10!$F$2:$F$999,ar6_r10!$A$2:$A$999,Veda!$E$5,ar6_r10!$C$2:$C$999,Veda!J$17,ar6_r10!$M$2:$M$999,Veda!$G21) -> 0.06 | K21: =SUMIFS(ar6_r10!$F$2:$F$999,ar6_r10!$A$2:$A$999,Veda!$E$5,ar6_r10!$C$2:$C$999,Veda!K$17,ar6_r10!$M$2:$M$999,Veda!$G21) -> 0.1 | L21: =SUMIFS(ar6_r10!$F$2:$F$999,ar6_r10!$A$2:$A$999,Veda!$E$5,ar6_r10!$C$2:$C$999,Veda!L$17,ar6_r10!$M$2:$M$999,Veda!$G21) -> 0.14 | M21: =SUMIFS(ar6_r10!$F$2:$F$999,ar6_r10!$A$2:$A$999,Veda!$E$5,ar6_r10!$C$2:$C$999,Veda!M$17,ar6_r10!$M$2:$M$999,Veda!$G21) -> 0.17 | N21: =SUMIFS(ar6_r10!$F$2:$F$999,ar6_r10!$A$2:$A$999,Veda!$E$5,ar6_r10!$C$2:$C$999,Veda!N$17,ar6_r10!$M$2:$M$999,Veda!$G21) -> 0.19 | O21: =SUMIFS(ar6_r10!$F$2:$F$999,ar6_r10!$A$2:$A$999,Veda!$E$5,ar6_r10!$C$2:$C$999,Veda!O$17,ar6_r10!$M$2:$M$999,Veda!$G21) -> 0.2 | S21: elc_transport | T21: =I21*T$14 -> 1.9536 | U21: =T21 -> 1.9536 | V21: =U21 -> 1.9536 | W21: =V21 -> 1.9536 | X21: =W21 -> 1.9536 | Y21: =X21 -> 1.9536 | Z21: =Y21 -> 1.9536 | AA21: demand | AC21: non-road transport demand assumed to be constant
A22: 5 | B22: =VLOOKUP(E22,$AK$9:$AL$15,2,FALSE)&"."&VLOOKUP(D22,$AH$9:$AI$19,2,FALSE) -> d 1.5 deg OS.b2w | C22: 14 | D22: =D11 -> s2_w | E22: =E21 -> C2 | S22: elc_roadtransport | T22: =T14-SUM(T19:T21) -> 0.6512 | U22: =U14-SUM(U19:U21) -> 2.070816 | V22: =V14-SUM(V19:V21) -> 6.570608 | W22: =W14-SUM(W19:W21) -> 12.01464 | X22: =X14-SUM(X19:X21) -> 16.31256 | Y22: =Y14-SUM(Y19:Y21) -> 18.083824 | Z22: =Z14-SUM(Z19:Z21) -> 18.155456 | AA22: demand
A23: 5 | B23: =VLOOKUP(E23,$AK$9:$AL$15,2,FALSE)&"."&VLOOKUP(D23,$AH$9:$AI$19,2,FALSE) -> d 1.5 deg OS.a2w2d | C23: 15 | D23: =D12 -> s2_w_p2_d | E23: =E22 -> C2 | S23: *
A24: 5 | B24: =VLOOKUP(E24,$AK$9:$AL$15,2,FALSE)&"."&VLOOKUP(D24,$AH$9:$AI$19,2,FALSE) -> d 1.5 deg OS.hTS12c | C24: 16 | D24: =D13 -> ts12_clu | E24: =E23 -> C2 | G24: CO2 price | I24: 0 | J24: 0 | K24: =SUMIFS(ar6_r10!$F$2:$F$999,ar6_r10!$A$2:$A$999,Veda!$E$5,ar6_r10!$C$2:$C$999,Veda!K$17,ar6_r10!$M$2:$M$999,Veda!$G24) -> 241.69 | L24: =SUMIFS(ar6_r10!$F$2:$F$999,ar6_r10!$A$2:$A$999,Veda!$E$5,ar6_r10!$C$2:$C$999,Veda!L$17,ar6_r10!$M$2:$M$999,Veda!$G24) -> 339.03 | M24: =SUMIFS(ar6_r10!$F$2:$F$999,ar6_r10!$A$2:$A$999,Veda!$E$5,ar6_r10!$C$2:$C$999,Veda!M$17,ar6_r10!$M$2:$M$999,Veda!$G24) -> 410.28 | N24: =SUMIFS(ar6_r10!$F$2:$F$999,ar6_r10!$A$2:$A$999,Veda!$E$5,ar6_r10!$C$2:$C$999,Veda!N$17,ar6_r10!$M$2:$M$999,Veda!$G24) -> 494.2 | O24: =SUMIFS(ar6_r10!$F$2:$F$999,ar6_r10!$A$2:$A$999,Veda!$E$5,ar6_r10!$C$2:$C$999,Veda!O$17,ar6_r10!$M$2:$M$999,Veda!$G24) -> 635.43 | S24: co2net | U24: 0 | V24: =K24/1000 -> 0.24169 | W24: =L24/1000 -> 0.33903 | X24: =M24/1000 -> 0.41028 | Y24: =N24/1000 -> 0.4942 | Z24: =O24/1000 -> 0.63543 | AA24: com_taxnet
A25: 5 | B25: =VLOOKUP(E25,$AK$9:$AL$15,2,FALSE)&"."&VLOOKUP(D25,$AH$9:$AI$19,2,FALSE) -> d 1.5 deg OS.gTS24c | C25: 17 | D25: =D14 -> ts24_clu | E25: =E24 -> C2
A26: 5 | B26: =VLOOKUP(E26,$AK$9:$AL$15,2,FALSE)&"."&VLOOKUP(D26,$AH$9:$AI$19,2,FALSE) -> d 1.5 deg OS.fTS48c | C26: 18 | D26: =D15 -> ts48_clu | E26: =E25 -> C2 | S26: ~TFM_INS-TS
A27: 5 | B27: =VLOOKUP(E27,$AK$9:$AL$15,2,FALSE)&"."&VLOOKUP(D27,$AH$9:$AI$19,2,FALSE) -> d 1.5 deg OS.c15d | C27: 19 | D27: =D16 -> s5p5v5_d | E27: =E26 -> C2 | S27: process | T27: =T17 -> 2022 | U27: =U17 -> 2025 | V27: =V17 -> 2030 | W27: =W17 -> 2035 | X27: =X17 -> 2040 | Y27: =Y17 -> 2045 | Z27: =Z17 -> 2050 | AA27: attribute | AB27: limtype
A28: 5 | B28: =VLOOKUP(E28,$AK$9:$AL$15,2,FALSE)&"."&VLOOKUP(D28,$AH$9:$AI$19,2,FALSE) -> d 1.5 deg OS.f1d | C28: 20 | D28: =D17 -> s1_d | E28: =E27 -> C2 | Q28: =SUMIFS(iea_data!G3:G9999,iea_data!$B$3:$B$9999,Veda!$S$11) -> 33.12 | S28: Trd_electricity import | T28: =Q28 -> 33.12 | AA28: ACT_BND | AB28: FX
A29: 5 | B29: =VLOOKUP(E29,$AK$9:$AL$15,2,FALSE)&"."&VLOOKUP(D29,$AH$9:$AI$19,2,FALSE) -> d 1.5 deg OS.jAnn | C29: 21 | D29: =D18 -> ts_annual | E29: =E28 -> C2 | Q29: =SUMIFS(iea_data!H3:H9999,iea_data!$B$3:$B$9999,Veda!$S$11) -> -29.73 | S29: Trd_electricity export | T29: =-1*Q29 -> 29.73 | AA29: ACT_BND | AB29: FX
A30: 5 | B30: =VLOOKUP(E30,$AK$9:$AL$15,2,FALSE)&"."&VLOOKUP(D30,$AH$9:$AI$19,2,FALSE) -> d 1.5 deg OS.iTS12 | C30: 22 | D30: =D19 -> ts_12 | E30: =E29 -> C2
A31: 5 | B31: =VLOOKUP(E31,$AK$9:$AL$15,2,FALSE)&"."&VLOOKUP(D31,$AH$9:$AI$19,2,FALSE) -> c 2 deg (67%).e3d | C31: 23 | D31: =D20 -> s1p1v1_d | E31: C3
A32: 5 | B32: =VLOOKUP(E32,$AK$9:$AL$15,2,FALSE)&"."&VLOOKUP(D32,$AH$9:$AI$19,2,FALSE) -> c 2 deg (67%).d9d | C32: 24 | D32: =D21 -> s3p3v3_d | E32: =E31 -> C3
A33: 5 | B33: =VLOOKUP(E33,$AK$9:$AL$15,2,FALSE)&"."&VLOOKUP(D33,$AH$9:$AI$19,2,FALSE) -> c 2 deg (67%).b2w | C33: 25 | D33: =D22 -> s2_w | E33: =E32 -> C3
A34: 5 | B34: =VLOOKUP(E34,$AK$9:$AL$15,2,FALSE)&"."&VLOOKUP(D34,$AH$9:$AI$19,2,FALSE) -> c 2 deg (67%).a2w2d | C34: 26 | D34: =D23 -> s2_w_p2_d | E34: =E33 -> C3
A35: 5 | B35: =VLOOKUP(E35,$AK$9:$AL$15,2,FALSE)&"."&VLOOKUP(D35,$AH$9:$AI$19,2,FALSE) -> c 2 deg (67%).hTS12c | C35: 27 | D35: =D24 -> ts12_clu | E35: =E34 -> C3
A36: 5 | B36: =VLOOKUP(E36,$AK$9:$AL$15,2,FALSE)&"."&VLOOKUP(D36,$AH$9:$AI$19,2,FALSE) -> c 2 deg (67%).gTS24c | C36: 28 | D36: =D25 -> ts24_clu | E36: =E35 -> C3 | G36: C7
A37: 5 | B37: =VLOOKUP(E37,$AK$9:$AL$15,2,FALSE)&"."&VLOOKUP(D37,$AH$9:$AI$19,2,FALSE) -> c 2 deg (67%).fTS48c | C37: 29 | D37: =D26 -> ts48_clu | E37: =E36 -> C3 | G37: Gas Price | I37: =SUMIFS(ar6_r10!$F$2:$F$999,ar6_r10!$A$2:$A$999,Veda!$G$36,ar6_r10!$C$2:$C$999,Veda!I$17,ar6_r10!$M$2:$M$999,Veda!$G37) -> 1 | J37: =SUMIFS(ar6_r10!$F$2:$F$999,ar6_r10!$A$2:$A$999,Veda!$G$36,ar6_r10!$C$2:$C$999,Veda!J$17,ar6_r10!$M$2:$M$999,Veda!$G37) -> 1.07 | K37: =SUMIFS(ar6_r10!$F$2:$F$999,ar6_r10!$A$2:$A$999,Veda!$G$36,ar6_r10!$C$2:$C$999,Veda!K$17,ar6_r10!$M$2:$M$999,Veda!$G37) -> 1.24 | L37: =SUMIFS(ar6_r10!$F$2:$F$999,ar6_r10!$A$2:$A$999,Veda!$G$36,ar6_r10!$C$2:$C$999,Veda!L$17,ar6_r10!$M$2:$M$999,Veda!$G37) -> 1.15 | M37: =SUMIFS(ar6_r10!$F$2:$F$999,ar6_r10!$A$2:$A$999,Veda!$G$36,ar6_r10!$C$2:$C$999,Veda!M$17,ar6_r10!$M$2:$M$999,Veda!$G37) -> 1.25 | N37: =SUMIFS(ar6_r10!$F$2:$F$999,ar6_r10!$A$2:$A$999,Veda!$G$36,ar6_r10!$C$2:$C$999,Veda!N$17,ar6_r10!$M$2:$M$999,Veda!$G37) -> 1.17 | O37: =SUMIFS(ar6_r10!$F$2:$F$999,ar6_r10!$A$2:$A$999,Veda!$G$36,ar6_r10!$C$2:$C$999,Veda!O$17,ar6_r10!$M$2:$M$999,Veda!$G37) -> 1.34
A38: 5 | B38: =VLOOKUP(E38,$AK$9:$AL$15,2,FALSE)&"."&VLOOKUP(D38,$AH$9:$AI$19,2,FALSE) -> c 2 deg (67%).c15d | C38: 30 | D38: =D27 -> s5p5v5_d | E38: =E37 -> C3 | G38: Coal Price | I38: =SUMIFS(ar6_r10!$F$2:$F$999,ar6_r10!$A$2:$A$999,Veda!$G$36,ar6_r10!$C$2:$C$999,Veda!I$17,ar6_r10!$M$2:$M$999,Veda!$G38) -> 1 | J38: =SUMIFS(ar6_r10!$F$2:$F$999,ar6_r10!$A$2:$A$999,Veda!$G$36,ar6_r10!$C$2:$C$999,Veda!J$17,ar6_r10!$M$2:$M$999,Veda!$G38) -> 1.02 | K38: =SUMIFS(ar6_r10!$F$2:$F$999,ar6_r10!$A$2:$A$999,Veda!$G$36,ar6_r10!$C$2:$C$999,Veda!K$17,ar6_r10!$M$2:$M$999,Veda!$G38) -> 1.06 | L38: =SUMIFS(ar6_r10!$F$2:$F$999,ar6_r10!$A$2:$A$999,Veda!$G$36,ar6_r10!$C$2:$C$999,Veda!L$17,ar6_r10!$M$2:$M$999,Veda!$G38) -> 1.07 | M38: =SUMIFS(ar6_r10!$F$2:$F$999,ar6_r10!$A$2:$A$999,Veda!$G$36,ar6_r10!$C$2:$C$999,Veda!M$17,ar6_r10!$M$2:$M$999,Veda!$G38) -> 1.08 | N38: =SUMIFS(ar6_r10!$F$2:$F$999,ar6_r10!$A$2:$A$999,Veda!$G$36,ar6_r10!$C$2:$C$999,Veda!N$17,ar6_r10!$M$2:$M$999,Veda!$G38) -> 1.1 | O38: =SUMIFS(ar6_r10!$F$2:$F$999,ar6_r10!$A$2:$A$999,Veda!$G$36,ar6_r10!$C$2:$C$999,Veda!O$17,ar6_r10!$M$2:$M$999,Veda!$G38) -> 1.12
A39: 5 | B39: =VLOOKUP(E39,$AK$9:$AL$15,2,FALSE)&"."&VLOOKUP(D39,$AH$9:$AI$19,2,FALSE) -> c 2 deg (67%).f1d | C39: 31 | D39: =D28 -> s1_d | E39: =E38 -> C3 | G39: Oil Price | I39: =SUMIFS(ar6_r10!$F$2:$F$999,ar6_r10!$A$2:$A$999,Veda!$G$36,ar6_r10!$C$2:$C$999,Veda!I$17,ar6_r10!$M$2:$M$999,Veda!$G39) -> 1 | J39: =SUMIFS(ar6_r10!$F$2:$F$999,ar6_r10!$A$2:$A$999,Veda!$G$36,ar6_r10!$C$2:$C$999,Veda!J$17,ar6_r10!$M$2:$M$999,Veda!$G39) -> 1.01 | K39: =SUMIFS(ar6_r10!$F$2:$F$999,ar6_r10!$A$2:$A$999,Veda!$G$36,ar6_r10!$C$2:$C$999,Veda!K$17,ar6_r10!$M$2:$M$999,Veda!$G39) -> 1.11 | L39: =SUMIFS(ar6_r10!$F$2:$F$999,ar6_r10!$A$2:$A$999,Veda!$G$36,ar6_r10!$C$2:$C$999,Veda!L$17,ar6_r10!$M$2:$M$999,Veda!$G39) -> 1.01 | M39: =SUMIFS(ar6_r10!$F$2:$F$999,ar6_r10!$A$2:$A$999,Veda!$G$36,ar6_r10!$C$2:$C$999,Veda!M$17,ar6_r10!$M$2:$M$999,Veda!$G39) -> 1.01 | N39: =SUMIFS(ar6_r10!$F$2:$F$999,ar6_r10!$A$2:$A$999,Veda!$G$36,ar6_r10!$C$2:$C$999,Veda!N$17,ar6_r10!$M$2:$M$999,Veda!$G39) -> 1.04 | O39: =SUMIFS(ar6_r10!$F$2:$F$999,ar6_r10!$A$2:$A$999,Veda!$G$36,ar6_r10!$C$2:$C$999,Veda!O$17,ar6_r10!$M$2:$M$999,Veda!$G39) -> 1.14
A40: 5 | B40: =VLOOKUP(E40,$AK$9:$AL$15,2,FALSE)&"."&VLOOKUP(D40,$AH$9:$AI$19,2,FALSE) -> c 2 deg (67%).jAnn | C40: 32 | D40: =D29 -> ts_annual | E40: =E39 -> C3 | G40: Biomass Price | I40: =SUMIFS(ar6_r10!$F$2:$F$999,ar6_r10!$A$2:$A$999,Veda!$G$36,ar6_r10!$C$2:$C$999,Veda!I$17,ar6_r10!$M$2:$M$999,Veda!$G40) -> 1 | J40: =SUMIFS(ar6_r10!$F$2:$F$999,ar6_r10!$A$2:$A$999,Veda!$G$36,ar6_r10!$C$2:$C$999,Veda!J$17,ar6_r10!$M$2:$M$999,Veda!$G40) -> 0.96 | K40: =SUMIFS(ar6_r10!$F$2:$F$999,ar6_r10!$A$2:$A$999,Veda!$G$36,ar6_r10!$C$2:$C$999,Veda!K$17,ar6_r10!$M$2:$M$999,Veda!$G40) -> 1.04 | L40: =SUMIFS(ar6_r10!$F$2:$F$999,ar6_r10!$A$2:$A$999,Veda!$G$36,ar6_r10!$C$2:$C$999,Veda!L$17,ar6_r10!$M$2:$M$999,Veda!$G40) -> 1.04 | M40: =SUMIFS(ar6_r10!$F$2:$F$999,ar6_r10!$A$2:$A$999,Veda!$G$36,ar6_r10!$C$2:$C$999,Veda!M$17,ar6_r10!$M$2:$M$999,Veda!$G40) -> 0.98 | N40: =SUMIFS(ar6_r10!$F$2:$F$999,ar6_r10!$A$2:$A$999,Veda!$G$36,ar6_r10!$C$2:$C$999,Veda!N$17,ar6_r10!$M$2:$M$999,Veda!$G40) -> 0.99 | O40: =SUMIFS(ar6_r10!$F$2:$F$999,ar6_r10!$A$2:$A$999,Veda!$G$36,ar6_r10!$C$2:$C$999,Veda!O$17,ar6_r10!$M$2:$M$999,Veda!$G40) -> 1
A41: 5 | B41: =VLOOKUP(E41,$AK$9:$AL$15,2,FALSE)&"."&VLOOKUP(D41,$AH$9:$AI$19,2,FALSE) -> c 2 deg (67%).iTS12 | C41: 33 | D41: =D30 -> ts_12 | E41: =E40 -> C3
A42: 5 | B42: =VLOOKUP(E42,$AK$9:$AL$15,2,FALSE)&"."&VLOOKUP(D42,$AH$9:$AI$19,2,FALSE) -> b 2 deg (50%).e3d | C42: 34 | D42: =D31 -> s1p1v1_d | E42: C4
...

Sheet fuel_prices
A9: Fuel Prices
A10: iso | B10: gas_low | C10: gas_high | D10: coal_low | E10: coal_high | F10: oil_low | G10: oil_high | H10: bioenergy_low | I10: bioenergy_high | J10: Notes
A11: CHE | B11: 29.1 | C11: 41.1 | D11: 15.2 | E11: 18.3 | F11: 50 | G11: 60 | H11: 28 | I11: 36 | J11: European pricing, forest resources

Sheet iea_data
A9: IEA Baseline Data
A10: iso | B10: year | C10: industry_twh | D10: buildings_agri_twh | E10: nonroad_transport_twh | F10: road_transport_twh | G10: imports_twh | H10: exports_twh | I10: total_production_twh
A11: CHE | B11: 2000 | C11: 24.13 | D11: 31.47 | E11: 2.64 | F11: 0 | G11: 24.33 | H11: -31.4 | I11: 66.12
A12: CHE | B12: 2001 | C12: 24.59 | D12: 32.51 | E12: 2.7 | F12: 0 | G12: 24.1 | H12: -34.54 | I12: 71.04
A13: CHE | B13: 2002 | C13: 24.31 | D13: 32.86 | E13: 2.8 | F13: 0 | G13: 27.8 | H13: -32.31 | I13: 65.41
A14: CHE | B14: 2003 | C14: 24.5 | D14: 33.66 | E14: 2.98 | F14: 0 | G14: 30.08 | H14: -33.2 | I14: 65.33
A15: CHE | B15: 2004 | C15: 24.87 | D15: 34.41 | E15: 2.94 | F15: 0 | G15: 27.06 | H15: -27.76 | I15: 63.86
A16: CHE | B16: 2005 | C16: 24.88 | D16: 35.27 | E16: 2.98 | F16: 0 | G16: 38.35 | H16: -32 | I16: 57.78
A17: CHE | B17: 2006 | C17: 25.2 | D17: 35.51 | E17: 3.09 | F17: 0 | G17: 33.8 | H17: -31.1 | I17: 62.13
A18: CHE | B18: 2007 | C18: 25.27 | D18: 35.18 | E18: 3.08 | F18: 0 | G18: 34.82 | H18: -36.88 | I18: 66.43
A19: CHE | B19: 2008 | C19: 25.62 | D19: 36.13 | E19: 3.14 | F19: 0 | G19: 31.6 | H19: -32.74 | I19: 67.03
A20: CHE | B20: 2009 | C20: 24.44 | D20: 36.04 | E20: 3.06 | F20: 0 | G20: 31.37 | H20: -33.52 | I20: 66.67
A21: CHE | B21: 2010 | C21: 25.27 | D21: 37.17 | E21: 3.16 | F21: 0 | G21: 33.4 | H21: -32.88 | I21: 66.04
A22: CHE | B22: 2011 | C22: 25.29 | D22: 36.14 | E22: 3.06 | F22: 0.02 | G22: 34.82 | H22: -32.24 | I22: 62.87
... A33: CHE | B33: 2022 | C33: 23.76 | D33: 36.15 | E33: 2.98 | F33: 0.35 | G33: 33.12 | H33: -29.73 | I33: 61.73

Sheet ar6_r10
A9: AR6 Scenario Drivers
A10: Category | B10: Region | C10: Year | D10: count | E10: mean | F10: median | G10: std | H10: min | I10: max | J10: q25 | K10: q75 | L10: category_description | M10: attribute
A11: C1 | B11: R10EUROPE | C11: 2020 | D11: 60 | E11: 8.68 | F11: 6.87 | G11: 10.43 | H11: 0 | I11: 55.17 | J11: 0 | K11: 13.64 | L11: Limit warming to 1.5°C (>50%) with no or limited overshoot | M11: CO2 price
A12: C1 | B12: R10EUROPE | C12: 2025 | D12: 60 | E12: 190.52 | F12: 181.51 | G12: 136.23 | H12: 1.81 | I12: 626.48 | J12: 115.48 | K12: 238.58 | L12: Limit warming to 1.5°C (>50%) with no or limited overshoot | M12: CO2 price
A13: C1 | B13: R10EUROPE | C13: 2030 | D13: 60 | E13: 268.18 | F13: 241.69 | G13: 134.29 | H13: 1.27 | I13: 673.46 | J13: 182.47 | K13: 329.7 | L13: Limit warming to 1.5°C (>50%) with no or limited overshoot | M13: CO2 price
A14: C1 | B14: R10EUROPE | C14: 2035 | D14: 60 | E14: 363.27 | F14: 339.03 | G14: 173.79 | H14: 14.37 | I14: 859.53 | J14: 227.05 | K14: 483.38 | L14: Limit warming to 1.5°C (>50%) with no or limited overshoot | M14: CO2 price
A15: C1 | B15: R10EUROPE | C15: 2040 | D15: 60 | E15: 471.65 | F15: 410.28 | G15: 224.31 | H15: 162.1 | I15: 1097.01 | J15: 298.63 | K15: 622.14 | L15: Limit warming to 1.5°C (>50%) with no or limited overshoot | M15: CO2 price
A16: C1 | B16: R10EUROPE | C16: 2045 | D16: 60 | E16: 565.69 | F16: 494.2 | G16: 256.15 | H16: 193.42 | I16: 1269.88 | J16: 352.78 | K16: 748.01 | L16: Limit warming to 1.5°C (>50%) with no or limited overshoot | M16: CO2 price
A17: C1 | B17: R10EUROPE | C17: 2050 | D17: 60 | E17: 647.44 | F17: 635.43 | G17: 273.56 | H17: 209.76 | I17: 1170.26 | J17: 409.79 | K17: 887.68 | L17: Limit warming to 1.5°C (>50%) with no or limited overshoot | M17: CO2 price
A18: C2 | B18: R10EUROPE | C18: 2020 | D18: 86 | E18: 6.44 | F18: 0 | G18: 8.34 | H18: 0 | I18: 24.5 | J18: 0 | K18: 12.68 | L18: Limit warming to 1.5°C (>67%) with high overshoot | M18: CO2 price
A19: C2 | B19: R10EUROPE | C19: 2025 | D19: 75 | E19: 63.21 | F19: 44.89 | G19: 56.62 | H19: 3.21 | I19: 273 | J19: 27.09 | K19: 77.31 | L19: Limit warming to 1.5°C (>67%) with high overshoot | M19: CO2 price
A20: C2 | B20: R10EUROPE | C20: 2030 | D20: 86 | E20: 85.48 | F20: 63.36 | G20: 73.46 | H20: 0 | I20: 409.5 | J20: 50 | K20: 111.1 | L20: Limit warming to 1.5°C (>67%) with high overshoot | M20: CO2 price
A21: C2 | B21: R10EUROPE | C21: 2035 | D21: 75 | E21: 208.71 | F21: 154.82 | G21: 291.78 | H21: 60.83 | I21: 2037.12 | J21: 93.79 | K21: 206.26 | L21: Limit warming to 1.5°C (>67%) with high overshoot | M21: CO2 price
A22: C2 | B22: R10EUROPE | C22: 2040 | D22: 86 | E22: 253.33 | F22: 172.09 | G22: 359.35 | H22: 0 | I22: 2600 | J22: 119.07 | K22: 259.4 | L22: Limit warming to 1.5°C (>67%) with high overshoot | M22: CO2 price
... A221: C1 | B221: R10EUROPE | C221: 2020 | D221: 33 | E221: 1 | F221: 1 | G221: 0 | H221: 1 | I221: 1 | J221: 1 | K221: 1 | L221: Limit warming to 1.5°C (>50%) with no or limited overshoot | M221: Gas price
A222: C1 | B222: R10EUROPE | C222: 2025 | D222: 34 | E222: 65535 | F222: 2.42 | H222: 1.18 | I222: 65535 | J222: 2.01 | K222: 2.75 | L222: Limit warming to 1.5°C (>50%) with no or limited overshoot | M222: Gas price
A223: C1 | B223: R10EUROPE | C223: 2030 | D223: 34 | E223: 65535 | F223: 3.1 | H223: 1.71 | I223: 65535 | J223: 2.38 | K223: 3.46 | L223: Limit warming to 1.5°C (>50%) with no or limited overshoot | M223: Gas price
A224: C1 | B224: R10EUROPE | C224: 2035 | D224: 34 | E224: 65535 | F224: 3.54 | H224: 1.91 | I224: 65535 | J224: 2.66 | K224: 4.16 | L224: Limit warming to 1.5°C (>50%) with no or limited overshoot | M224: Gas price
A225: C1 | B225: R10EUROPE | C225: 2040 | D225: 34 | E225: 65535 | F225: 4.1 | H225: 2.27 | I225: 65535 | J225: 2.96 | K225: 4.52 | L225: Limit warming to 1.5°C (>50%) with no or limited overshoot | M225: Gas price
A226: C1 | B226: R10EUROPE | C226: 2045 | D226: 34 | E226: 65535 | F226: 3.86 | H226: 2.54 | I226: 65535 | J226: 3.3 | K226: 4.89 | L226: Limit warming to 1.5°C (>50%) with no or limited overshoot | M226: Gas price
A227: C1 | B227: R10EUROPE | C227: 2050 | D227: 34 | E227: 65535 | F227: 3.59 | H227: 2.73 | I227: 65535 | J227: 3.07 | K227: 4.06 | L227: Limit warming to 1.5°C (>50%) with no or limited overshoot | M227: Gas price
A228: C2 | B228: R10EUROPE | C228: 2020 | D228: 43 | E228: 1 | F228: 1 | G228: 0 | H228: 1 | I228: 1 | J228: 1 | K228: 1 | L228: Limit warming to 1.5°C (>67%) with high overshoot | M228: Gas price
A229: C2 | B229: R10EUROPE | C229: 2025 | D229: 44 | E229: 65535 | F229: 1.22 | H229: 0 | I229: 65535 | J229: 1.13 | K229: 1.35 | L229: Limit warming to 1.5°C (>67%) with high overshoot | M229: Gas price
A230: C2 | B230: R10EUROPE | C230: 2030 | D230: 44 | E230: 65535 | F230: 1.5 | H230: 0 | I230: 65535 | J230: 1.31 | K230: 1.83 | L230: Limit warming to 1.5°C (>67%) with high overshoot | M230: Gas price
A231: C2 | B231: R10EUROPE | C231: 2035 | D231: 44 | E231: 65535 | F231: 2.12 | H231: 0 | I231: 65535 | J231: 1.68 | K231: 2.46 | L231: Limit warming to 1.5°C (>67%) with high overshoot | M231: Gas price
A232: C2 | B232: R10EUROPE | C232: 2040 | D232: 44 | E232: 65535 | F232: 2.5 | H232: 0 | I232: 65535 | J232: 2 | K232: 2.94 | L232: Limit warming to 1.5°C (>67%) with high overshoot | M232: Gas price
A233: C2 | B233: R10EUROPE | C233: 2045 | D233: 44 | E233: 65535 | F233: 2.79 | H233: 0 | I233: 65535 | J233: 2.08 | K233: 3.44 | L233: Limit warming to 1.5°C (>67%) with high overshoot | M233: Gas price
A234: C2 | B234: R10EUROPE | C234: 2050 | D234: 44 | E234: 65535 | F234: 2.95 | H234: 0 | I234: 65535 | J234: 2.49 | K234: 3.78 | L234: Limit warming to 1.5°C (>67%) with high overshoot | M234: Gas price
A235: C3 | B235: R10EUROPE | C235: 2020 | D235: 103 | E235: 1 | F235: 1 | G235: 0 | H235: 1 | I235: 1 | J235: 1 | K235: 1 | L235: Limit warming to 2°C (>67%) with higher action post-2030 | M235: Gas price
A236: C3 | B236: R10EUROPE | C236: 2025 | D236: 112 | E236: 65535 | F236: 1.41 | H236: 0.98 | I236: 65535 | J236: 1.23 | K236: 1.96 | L236: Limit warming to 2°C (>67%) with higher action post-2030 | M236: Gas price
A237: C3 | B237: R10EUROPE | C237: 2030 | D237: 112 | E237: 65535 | F237: 2.04 | H237: 1.05 | I237: 65535 | J237: 1.52 | K237: 2.55 | L237: Limit warming to 2°C (>67%) with higher action post-2030 | M237: Gas price
A238: C3 | B238: R10EUROPE | C238: 2035 | D238: 112 | E238: 65535 | F238: 2.4 | H238: 1.05 | I238: 65535 | J238: 1.71 | K238: 3.14 | L238: Limit warming to 2°C (>67%) with higher action post-2030 | M238: Gas price
A239: C3 | B239: R10EUROPE | C239: 2040 | D239: 112 | E239: 65535 | F239: 2.6 | H239: 1.06 | I239: 65535 | J239: 1.85 | K239: 3.74 | L239: Limit warming to 2°C (>67%) with higher action post-2030 | M239: Gas price
A240: C3 | B240: R10EUROPE | C240: 2045 | D240: 112 | E240: 65535 | F240: 2.85 | H240: 1.08 | I240: 65535 | J240: 2 | K240: 4.28 | L240: Limit warming to 2°C (>67%) with higher action post-2030 | M240: Gas price
A241: C3 | B241: R10EUROPE | C241: 2050 | D241: 112 | E241: 65535 | F241: 2.97 | H241: 0 | I241: 65535 | J241: 2.15 | K241: 4.51 | L241: Limit warming to 2°C (>67%) with higher action post-2030 | M241: Gas price
A242: C4 | B242: R10EUROPE | C242: 2020 | D242: 27 | E242: 1 | F242: 1 | G242: 0 | H242: 1 | I242: 1 | J242: 1 | K242: 1 | L242: Limit warming to 2°C (>50%) with immediate action | M242: Gas price
A243: C4 | B243: R10EUROPE | C243: 2025 | D243: 27 | E243: 1.33 | F243: 1.31 | G243: 0.18 | H243: 1.06 | I243: 1.66 | J243: 1.22 | K243: 1.45 | L243: Limit warming to 2°C (>50%) with immediate action | M243: Gas price
A244: C4 | B244: R10EUROPE | C244: 2030 | D244: 27 | E244: 1.84 | F244: 2.02 | G244: 0.28 | H244: 1.24 | I244: 2.17 | J244: 1.52 | K244: 2.07 | L244: Limit warming to 2°C (>50%) with immediate action | M244: Gas price
A245: C4 | B245: R10EUROPE | C245: 2035 | D245: 27 | E245: 1.84 | F245: 1.96 | G245: 0.41 | H245: 1.19 | I245: 2.46 | J245: 1.42 | K245: 2.11 | L245: Limit warming to 2°C (>50%) with immediate action | M245: Gas price
A246: C4 | B246: R10EUROPE | C246: 2040 | D246: 27 | E246: 2.12 | F246: 2.22 | G246: 0.47 | H246: 1.41 | I246: 2.78 | J246: 1.54 | K246: 2.43 | L246: Limit warming to 2°C (>50%) with immediate action | M246: Gas price
...

Sheet ev_charging_uc
A10: =IFERROR(Veda!D5,"ts_12") -> s2_w | C10: day_night | D10: ts12_clu | F10: day_night | G10: ts_annual | I10: day_night | J10: ts_12
C11: D | D11: S1aH2,S2aH3,S3aH3,S1aH4,S2aH2,S2aH4,S3aH4,S1aH3,S3aH2 | F11: D | G11: AllSaAllH | I11: D | J11: SaD,RaP,WaD,FaD,RaD,FaP,SaP,WaP
C12: N | D12: S1aH5,S2aH5,S1aH1,S3aH1,S3aH5,S2aH1 | F12: N | G12: AllSaAllH | I12: N | J12: FaP,SaP,FaN,RaP,SaN,WaN,RaN,WaP
I17: 0.75 | K17: share of charging at night
C18: ~UC_Sets: R_E: AllRegions
H21: =IF(H23=H24,"Not Required!","~UC_T: LO") -> #N/A
C22: UC_N | D22: Pset_CI | E22: Pset_CO | F22: pset_pn | G22: Cset_CN | H22: TimeSlice | I22: UC_FLO | J22: UC_RHSRT | K22: UC_RHSRT~0
C23: UC_bev night chg limit | D23: ELC | E23: =G23 -> AuxStoIN | F23: *EV* | G23: AuxStoIN | H23: =HLOOKUP($A$10,$D$10:$CU$12,3,FALSE) -> #N/A | I23: =1+I24 -> 0.25 | J23: 0 | K23: 3 | M23: night
D24: ELC | E24: =G24 -> AuxStoIN | F24: *EV* | G24: AuxStoIN | H24: =HLOOKUP($A$10,$D$10:$CU$12,2,FALSE) -> #N/A | I24: =-$I$17 -> -0.75 | M24: day

Sheet ts12_clu
C9: =IF(A11="x","DeActivated","~TimeSlices") -> DeActivated | I9: =IF(A11="x","DeActivated","~TFM_DINS-AT") -> DeActivated | N9: =IF(A11="x","DeActivated","~TFM_DINS-AT") -> DeActivated | S9: =IF(A11="x","DeActivated","~TFM_DINS-AT") -> DeActivated | X9: =IF(A11="x","DeActivated","~TFM_DINS-AT") -> DeActivated | AC9: =IF(A11="x","DeActivated","~TFM_DINS-AT") -> DeActivated | AG9: =IF(A11="x","DeActivated","~TFM_DINS-AT") -> DeActivated | AK9: =IF(A11="x","DeActivated","~TFM_INS-AT") -> DeActivated
A10: ts12_clu | C10: season | D10: weekly | E10: daynite | F10: wparent | G10: dparent | I10: commodity | J10: timeslice | K10: com_fr | L10: process | N10: commodity | O10: timeslice | P10: com_fr | Q10: process | S10: commodity | T10: timeslice | U10: com_fr | V10: process | X10: g_yrfr | Y10: com_fr | Z10: timeslice | AA10: commodity | AC10: commodity | AD10: timeslice | AE10: com_fr | AG10: commodity | AH10: timeslice | AI10: com_pkflx | AK10: timeslice | AL10: ncap_afs | AM10: pset_ci
A11: =IFERROR(IF(Veda!D5=A10,"ok","x"),"") -> x | C11: S1 | D11: a | E11: H1 | F11: S1,S2,S3 | G11: a | I11: elc_spv-CHE_0000 | J11: S1aH1 | K11: 0.00067007666 | L11: IMPNRGZ | N11: elc_won-CHE_0000 | O11: S1aH1 | P11: 0.055432041 | Q11: IMPNRGZ | X11: 0.053881279 | Y11: 0.029864505 | Z11: S1aH1 | AA11: elc_roadtransport | AC11: elc_buildings | AD11: S1aH1 | AE11: 0.058930625 | AG11: ELC | AH11: S1aH1 | AI11: 0.21542972 | AK11: S3 | AL11: 0.35506512 | AM11: hydro
C12: S2 | E12: H2 | G12: a | I12: elc_spv-CHE_0000 | J12: S1aH2 | K12: 0.029990333 | L12: IMPNRGZ | N12: elc_won-CHE_0000 | O12: S1aH2 | P12: 0.019174673 | Q12: IMPNRGZ | X12: 0.020205479 | Y12: 0.02544448 | Z12: S1aH2 | AA12: elc_roadtransport | AC12: elc_buildings | AD12: S1aH2 | AE12: 0.026521046 | AG12: ELC | AH12: S1aH2 | AI12: 0.064420394 | AK12: S2 | AL12: 0.66840316 | AM12: hydro
C13: S3 | E13: H3 | G13: a | I13: elc_spv-CHE_0000 | J13: S1aH3 | K13: 0.043836468 | L13: IMPNRGZ | N13: elc_won-CHE_0000 | O13: S1aH3 | P13: 0.021009139 | Q13: IMPNRGZ | X13: 0.020205479 | Y13: 0.025483596 | Z13: S1aH3 | AA13: elc_roadtransport | AC13: elc_buildings | AD13: S1aH3 | AE13: 0.026314982 | AG13: ELC | AH13: S1aH3 | AI13: 0.051447247 | AK13: S1 | AL13: 0.17653173 | AM13: hydro
E14: H4 | G14: a | I14: elc_spv-CHE_0000 | J14: S1aH4 | K14: 0.038946236 | L14: IMPNRGZ | N14: elc_won-CHE_0000 | O14: S1aH4 | P14: 0.037789687 | Q14: IMPNRGZ | X14: 0.026940639 | Y14: 0.045256362 | Z14: S1aH4 | AA14: elc_roadtransport | AC14: elc_buildings | AD14: S1aH4 | AE14: 0.035433128 | AG14: ELC | AH14: S1aH4 | AI14: 0.048779533
E15: H5 | G15: a | I15: elc_spv-CHE_0000 | J15: S1aH5 | K15: 0 | L15: IMPNRGZ | N15: elc_won-CHE_0000 | O15: S1aH5 | P15: 0.053435952 | Q15: IMPNRGZ | X15: 0.040410959 | Y15: 0.035594892 | Z15: S1aH5 | AA15: elc_roadtransport | AC15: elc_buildings | AD15: S1aH5 | AE15: 0.046056862 | AG15: ELC | AH15: S1aH5 | AI15: 0.16015462
I16: elc_spv-CHE_0000 | J16: S2aH1 | K16: 0.060767211 | L16: IMPNRGZ | N16: elc_won-CHE_0000 | O16: S2aH1 | P16: 0.08705557 | Q16: IMPNRGZ | X16: 0.16803653 | Y16: 0.093136763 | Z16: S2aH1 | AA16: elc_roadtransport | AC16: elc_buildings | AD16: S2aH1 | AE16: 0.1384382 | AG16: ELC | AH16: S2aH1 | AI16: 0.37286265
I17: elc_spv-CHE_0000 | J17: S2aH2 | K17: 0.17063044 | L17: IMPNRGZ | N17: elc_won-CHE_0000 | O17: S2aH2 | P17: 0.032364179 | Q17: IMPNRGZ | X17: 0.063013699 | Y17: 0.079352278 | Z17: S2aH2 | AA17: elc_roadtransport | AC17: elc_buildings | AD17: S2aH2 | AE17: 0.066587749 | AG17: ELC | AH17: S2aH2 | AI17: 0.17060427
I18: elc_spv-CHE_0000 | J18: S2aH3 | K18: 0.18794321 | L18: IMPNRGZ | N18: elc_won-CHE_0000 | O18: S2aH3 | P18: 0.054532875 | Q18: IMPNRGZ | X18: 0.063013699 | Y18: 0.079474264 | Z18: S2aH3 | AA18: elc_roadtransport | AC18: elc_buildings | AD18: S2aH3 | AE18: 0.066225447 | AG18: ELC | AH18: S2aH3 | AI18: 0.17476492
I19: elc_spv-CHE_0000 | J19: S2aH4 | K19: 0.19420736 | L19: IMPNRGZ | N19: elc_won-CHE_0000 | O19: S2aH4 | P19: 0.090500658 | Q19: IMPNRGZ | X19: 0.084018265 | Y19: 0.14113849 | Z19: S2aH4 | AA19: elc_roadtransport | AC19: elc_buildings | AD19: S2aH4 | AE19: 0.08730476 | AG19: ELC | AH19: S2aH4 | AI19: 0.19046175
I20: elc_spv-CHE_0000 | J20: S2aH5 | K20: 0.029348226 | L20: IMPNRGZ | N20: elc_won-CHE_0000 | O20: S2aH5 | P20: 0.095181324 | Q20: IMPNRGZ | X20: 0.1260274 | Y20: 0.1110078 | Z20: S2aH5 | AA20: elc_roadtransport | AC20: elc_buildings | AD20: S2aH5 | AE20: 0.11383459 | AG20: ELC | AH20: S2aH5 | AI20: 0.30418935
I21: elc_spv-CHE_0000 | J21: S3aH1 | K21: 0.0071220076 | L21: IMPNRGZ | N21: elc_won-CHE_0000 | O21: S3aH1 | P21: 0.1485 | Q21: IMPNRGZ | X21: 0.11141553 | Y21: 0.061753723 | Z21: S3aH1 | AA21: elc_roadtransport | AC21: elc_buildings | AD21: S3aH1 | AE21: 0.099006902 | AG21: ELC | AH21: S3aH1 | AI21: 0.30743928
I22: elc_spv-CHE_0000 | J22: S3aH2 | K22: 0.068865074 | L22: IMPNRGZ | N22: elc_won-CHE_0000 | O22: S3aH2 | P22: 0.056027698 | Q22: IMPNRGZ | X22: 0.041780822 | Y22: 0.05261401 | Z22: S3aH2 | AA22: elc_roadtransport | AC22: elc_buildings | AD22: S3aH2 | AE22: 0.046634519 | AG22: ELC | AH22: S3aH2 | AI22: 0.12898923
I23: elc_spv-CHE_0000 | J23: S3aH3 | K23: 0.086427805 | L23: IMPNRGZ | N23: elc_won-CHE_0000 | O23: S3aH3 | P23: 0.060057906 | Q23: IMPNRGZ | X23: 0.041780822 | Y23: 0.052694893 | Z23: S3aH3 | AA23: elc_roadtransport | AC23: elc_buildings | AD23: S3aH3 | AE23: 0.046088017 | AG23: ELC | AH23: S3aH3 | AI23: 0.13753499
I24: elc_spv-CHE_0000 | J24: S3aH4 | K24: 0.079856669 | L24: IMPNRGZ | N24: elc_won-CHE_0000 | O24: S3aH4 | P24: 0.078101475 | Q24: IMPNRGZ | X24: 0.055707763 | Y24: 0.093580953 | Z24: S3aH4 | AA24: elc_roadtransport | AC24: elc_buildings | AD24: S3aH4 | AE24: 0.061729031 | AG24: ELC | AH24: S3aH4 | AI24: 0.14100992
I25: elc_spv-CHE_0000 | J25: S3aH5 | K25: 0.0013888812 | L25: IMPNRGZ | N25: elc_won-CHE_0000 | O25: S3aH5 | P25: 0.11083683 | Q25: IMPNRGZ | X25: 0.083561644 | Y25: 0.073602997 | Z25: S3aH5 | AA25: elc_roadtransport | AC25: elc_buildings | AD25: S3aH5 | AE25: 0.080894143 | AG25: ELC | AH25: S3aH5 | AI25: 0.24743857
I26: elc_spv-CHE_0001 | J26: S1aH1 | K26: 0.00048391646 | L26: IMPNRGZ | N26: elc_won-CHE_0001 | O26: S1aH1 | P26: 0.058194255 | Q26: IMPNRGZ | AC26: elc_industry | AD26: S1aH1 | AE26: 0.053569944
I27: elc_spv-CHE_0001 | J27: S1aH2 | K27: 0.026689466 | L27: IMPNRGZ | N27: elc_won-CHE_0001 | O27: S1aH2 | P27: 0.020201824 | Q27: IMPNRGZ | AC27: elc_industry | AD27: S1aH2 | AE27: 0.020397038
I28: elc_spv-CHE_0001 | J28: S1aH3 | K28: 0.0415073 | L28: IMPNRGZ | N28: elc_won-CHE_0001 | O28: S1aH3 | P28: 0.01975062 | Q28: IMPNRGZ | AC28: elc_industry | AD28: S1aH3 | AE28: 0.020382671
I29: elc_spv-CHE_0001 | J29: S1aH4 | K29: 0.036386501 | L29: IMPNRGZ | N29: elc_won-CHE_0001 | O29: S1aH4 | P29: 0.034858104 | Q29: IMPNRGZ | AC29: elc_industry | AD29: S1aH4 | AE29: 0.027201051
I30: elc_spv-CHE_0001 | J30: S1aH5 | K30: 0 | L30: IMPNRGZ | N30: elc_won-CHE_0001 | O30: S1aH5 | P30: 0.054195893 | Q30: IMPNRGZ | AC30: elc_industry | AD30: S1aH5 | AE30: 0.040307061
I31: elc_spv-CHE_0001 | J31: S2aH1 | K31: 0.062641459 | L31: IMPNRGZ | N31: elc_won-CHE_0001 | O31: S2aH1 | P31: 0.097494843 | Q31: IMPNRGZ | AC31: elc_industry | AD31: S2aH1 | AE31: 0.16663852
I32: elc_spv-CHE_0001 | J32: S2aH2 | K32: 0.17210886 | L32: IMPNRGZ | N32: elc_won-CHE_0001 | O32: S2aH2 | P32: 0.030993155 | Q32: IMPNRGZ | AC32: elc_industry | AD32: S2aH2 | AE32: 0.063512485
I33: elc_spv-CHE_0001 | J33: S2aH3 | K33: 0.19185513 | L33: IMPNRGZ | N33: elc_won-CHE_0001 | O33: S2aH3 | P33: 0.039406895 | Q33: IMPNRGZ | AC33: elc_industry | AD33: S2aH3 | AE33: 0.063487225
I34: elc_spv-CHE_0001 | J34: S2aH4 | K34: 0.20153775 | L34: IMPNRGZ | N34: elc_won-CHE_0001 | O34: S2aH4 | P34: 0.066365385 | Q34: IMPNRGZ | AC34: elc_industry | AD34: S2aH4 | AE34: 0.084580203
I35: elc_spv-CHE_0001 | J35: S2aH5 | K35: 0.031261564 | L35: IMPNRGZ | N35: elc_won-CHE_0001 | O35: S2aH5 | P35: 0.089736846 | Q35: IMPNRGZ | AC35: elc_industry | AD35: S2aH5 | AE35: 0.12567651
I36: elc_spv-CHE_0001 | J36: S3aH1 | K36: 0.0066908511 | L36: IMPNRGZ | N36: elc_won-CHE_0001 | O36: S3aH1 | P36: 0.16843849 | Q36: IMPNRGZ | AC36: elc_industry | AD36: S3aH1 | AE36: 0.11054816
I37: elc_spv-CHE_0001 | J37: S3aH2 | K37: 0.063142803 | L37: IMPNRGZ | N37: elc_won-CHE_0001 | O37: S3aH2 | P37: 0.060692546 | Q37: IMPNRGZ | AC37: elc_industry | AD37: S3aH2 | AE37: 0.04211839
... I40: elc_spv-CHE_0001 | J40: S3aH5 | K40: 0.0015689149 | L40: IMPNRGZ | N40: elc_won-CHE_0001 | O40: S3aH5 | P40: 0.12194062 | Q40: IMPNRGZ | AC40: elc_industry | AD40: S3aH5 | AE40: 0.083373995
I41: elc_spv-CHE_0010 | J41: S1aH1 | K41: 0.00043570404 | L41: IMPNRGZ | N41: elc_won-CHE_0010 | O41: S1aH1 | P41: 0.072644617 | Q41: IMPNRGZ
I42: elc_spv-CHE_0010 | J42: S1aH2 | K42: 0.021642099 | L42: IMPNRGZ | N42: elc_won-CHE_0010 | O42: S1aH2 | P42: 0.027162043 | Q42: IMPNRGZ
I43: elc_spv-CHE_0010 | J43: S1aH3 | K43: 0.036402603 | L43: IMPNRGZ | N43: elc_won-CHE_0010 | O43: S1aH3 | P43: 0.029389902 | Q43: IMPNRGZ
I44: elc_spv-CHE_0010 | J44: S1aH4 | K44: 0.030950197 | L44: IMPNRGZ | N44: elc_won-CHE_0010 | O44: S1aH4 | P44: 0.041865775 | Q44: IMPNRGZ
I45: elc_spv-CHE_0010 | J45: S1aH5 | K45: 0 | L45: IMPNRGZ | N45: elc_won-CHE_0010 | O45: S1aH5 | P45: 0.06626448 | Q45: IMPNRGZ
I46: elc_spv-CHE_0010 | J46: S2aH1 | K46: 0.07453729 | L46: IMPNRGZ | N46: elc_won-CHE_0010 | O46: S2aH1 | P46: 0.10088247 | Q46: IMPNRGZ
I47: elc_spv-CHE_0010 | J47: S2aH2 | K47: 0.18000062 | L47: IMPNRGZ | N47: elc_won-CHE_0010 | O47: S2aH2 | P47: 0.03444835 | Q47: IMPNRGZ
I48: elc_spv-CHE_0010 | J48: S2aH3 | K48: 0.19433015 | L48: IMPNRGZ | N48: elc_won-CHE_0010 | O48: S2aH3 | P48: 0.045610597 | Q48: IMPNRGZ
I49: elc_spv-CHE_0010 | J49: S2aH4 | K49: 0.20211991 | L49: IMPNRGZ | N49: elc_won-CHE_0010 | O49: S2aH4 | P49: 0.068752639 | Q49: IMPNRGZ
I50: elc_spv-CHE_0010 | J50: S2aH5 | K50: 0.030918701 | L50: IMPNRGZ | N50: elc_won-CHE_0010 | O50: S2aH5 | P50: 0.095388522 | Q50: IMPNRGZ
...

Sheet ts_annual
C9: =IF(A11="x","DeActivated","~TimeSlices") -> DeActivated | I9: =IF(A11="x","DeActivated","~TFM_DINS-AT") -> DeActivated | N9: =IF(A11="x","DeActivated","~TFM_DINS-AT") -> DeActivated | S9: =IF(A11="x","DeActivated","~TFM_DINS-AT") -> DeActivated | X9: =IF(A11="x","DeActivated","~TFM_DINS-AT") -> DeActivated | AC9: =IF(A11="x","DeActivated","~TFM_DINS-AT") -> DeActivated | AG9: =IF(A11="x","DeActivated","~TFM_DINS-AT") -> DeActivated | AK9: =IF(A11="x","DeActivated","~TFM_INS-AT") -> DeActivated
A10: ts_annual | C10: season | D10: weekly | E10: daynite | F10: wparent | G10: dparent | I10: commodity | J10: timeslice | K10: com_fr | L10: process | N10: commodity | O10: timeslice | P10: com_fr | Q10: process | S10: commodity | T10: timeslice | U10: com_fr | V10: process | X10: g_yrfr | Y10: com_fr | Z10: timeslice | AA10: commodity | AC10: commodity | AD10: timeslice | AE10: com_fr | AG10: commodity | AH10: timeslice | AI10: com_pkflx | AK10: timeslice | AL10: ncap_afs | AM10: pset_ci
A11: =IFERROR(IF(Veda!D5=A10,"ok","x"),"") -> x | C11: AllS | D11: a | E11: AllH | F11: AllS | G11: a | I11: elc_spv-CHE_0000 | J11: AllSaAllH | K11: 1 | L11: IMPNRGZ | N11: elc_won-CHE_0000 | O11: AllSaAllH | P11: 1 | Q11: IMPNRGZ | X11: 1 | Y11: 1 | Z11: AllSaAllH | AA11: elc_roadtransport | AC11: elc_buildings | AD11: AllSaAllH | AE11: 1 | AG11: ELC | AH11: AllSaAllH | AI11: 0.29211718 | AK11: AllS | AL11: 1.2 | AM11: hydro
I12: elc_spv-CHE_0001 | J12: AllSaAllH | K12: 1 | L12: IMPNRGZ | N12: elc_won-CHE_0001 | O12: AllSaAllH | P12: 1 | Q12: IMPNRGZ | AC12: elc_industry | AD12: AllSaAllH | AE12: 1
I13: elc_spv-CHE_0010 | J13: AllSaAllH | K13: 1 | L13: IMPNRGZ | N13: elc_won-CHE_0010 | O13: AllSaAllH | P13: 1 | Q13: IMPNRGZ
I14: elc_spv-CHE_0011 | J14: AllSaAllH | K14: 1 | L14: IMPNRGZ | N14: elc_won-CHE_0011 | O14: AllSaAllH | P14: 1 | Q14: IMPNRGZ
I15: elc_spv-CHE_0012 | J15: AllSaAllH | K15: 1 | L15: IMPNRGZ | N15: elc_won-CHE_0012 | O15: AllSaAllH | P15: 1 | Q15: IMPNRGZ
I16: elc_spv-CHE_0013 | J16: AllSaAllH | K16: 1 | L16: IMPNRGZ | N16: elc_won-CHE_0013 | O16: AllSaAllH | P16: 1 | Q16: IMPNRGZ
I17: elc_spv-CHE_0014 | J17: AllSaAllH | K17: 1 | L17: IMPNRGZ | N17: elc_won-CHE_0014 | O17: AllSaAllH | P17: 1 | Q17: IMPNRGZ
I18: elc_spv-CHE_0015 | J18: AllSaAllH | K18: 1 | L18: IMPNRGZ | N18: elc_won-CHE_0015 | O18: AllSaAllH | P18: 1 | Q18: IMPNRGZ
I19: elc_spv-CHE_0017 | J19: AllSaAllH | K19: 1 | L19: IMPNRGZ | N19: elc_won-CHE_0016 | O19: AllSaAllH | P19: 1 | Q19: IMPNRGZ
I20: elc_spv-CHE_0018 | J20: AllSaAllH | K20: 1 | L20: IMPNRGZ | N20: elc_won-CHE_0017 | O20: AllSaAllH | P20: 1 | Q20: IMPNRGZ
I21: elc_spv-CHE_0019 | J21: AllSaAllH | K21: 1 | L21: IMPNRGZ | N21: elc_won-CHE_0018 | O21: AllSaAllH | P21: 1 | Q21: IMPNRGZ
I22: elc_spv-CHE_0002 | J22: AllSaAllH | K22: 1 | L22: IMPNRGZ | N22: elc_won-CHE_0019 | O22: AllSaAllH | P22: 1 | Q22: IMPNRGZ
I23: elc_spv-CHE_0020 | J23: AllSaAllH | K23: 1 | L23: IMPNRGZ | N23: elc_won-CHE_0002 | O23: AllSaAllH | P23: 1 | Q23: IMPNRGZ
I24: elc_spv-CHE_0021 | J24: AllSaAllH | K24: 1 | L24: IMPNRGZ | N24: elc_won-CHE_0020 | O24: AllSaAllH | P24: 1 | Q24: IMPNRGZ
... I35: elc_spv-CHE_0009 | J35: AllSaAllH | K35: 1 | L35: IMPNRGZ | N35: elc_won-CHE_0008 | O35: AllSaAllH | P35: 1 | Q35: IMPNRGZ
N36: elc_won-CHE_0009 | O36: AllSaAllH | P36: 1 | Q36: IMPNRGZ

Sheet ts_12
C9: =IF(A11="x","DeActivated","~TimeSlices") -> DeActivated | I9: =IF(A11="x","DeActivated","~TFM_DINS-AT") -> DeActivated | N9: =IF(A11="x","DeActivated","~TFM_DINS-AT") -> DeActivated | S9: =IF(A11="x","DeActivated","~TFM_DINS-AT") -> DeActivated | X9: =IF(A11="x","DeActivated","~TFM_DINS-AT") -> DeActivated | AC9: =IF(A11="x","DeActivated","~TFM_DINS-AT") -> DeActivated | AG9: =IF(A11="x","DeActivated","~TFM_DINS-AT") -> DeActivated | AK9: =IF(A11="x","DeActivated","~TFM_INS-AT") -> DeActivated
A10: ts_12 | C10: season | D10: weekly | E10: daynite | F10: wparent | G10: dparent | I10: commodity | J10: timeslice | K10: com_fr | L10: process | N10: commodity | O10: timeslice | P10: com_fr | Q10: process | S10: commodity | T10: timeslice | U10: com_fr | V10: process | X10: g_yrfr | Y10: com_fr | Z10: timeslice | AA10: commodity | AC10: commodity | AD10: timeslice | AE10: com_fr | AG10: commodity | AH10: timeslice | AI10: com_pkflx | AK10: timeslice | AL10: ncap_afs | AM10: pset_ci
A11: =IFERROR(IF(Veda!D5=A10,"ok","x"),"") -> x | C11: F | D11: a | E11: D | F11: W,R,S,F | G11: a | I11: elc_spv-CHE_0000 | J11: FaD | K11: 0.18164357 | L11: IMPNRGZ | N11: elc_won-CHE_0000 | O11: FaD | P11: 0.17758429 | Q11: IMPNRGZ | X11: 0.11426941 | Y11: 0.16087081 | Z11: FaD | AA11: elc_roadtransport | AC11: elc_buildings | AD11: FaD | AE11: 0.12090138 | AG11: ELC | AH11: FaD | AI11: 0.17617534 | AK11: F | AL11: 0.27553731 | AM11: hydro
C12: R | E12: N | G12: a | I12: elc_spv-CHE_0000 | J12: FaN | K12: 0 | L12: IMPNRGZ | N12: elc_won-CHE_0000 | O12: FaN | P12: 0.14676725 | Q12: IMPNRGZ | X12: 0.11426941 | Y12: 0.052547713 | Z12: FaN | AA12: elc_roadtransport | AC12: elc_buildings | AD12: FaN | AE12: 0.095242975 | AG12: ELC | AH12: FaN | AI12: 0.33306575 | AK12: S | AL12: 0.39690768 | AM12: hydro
C13: S | E13: P | G13: a | I13: elc_spv-CHE_0000 | J13: FaP | K13: 0.007171375 | L13: IMPNRGZ | N13: elc_won-CHE_0000 | O13: FaP | P13: 0.028949025 | Q13: IMPNRGZ | X13: 0.020776256 | Y13: 0.035896543 | Z13: FaP | AA13: elc_roadtransport | AC13: elc_buildings | AD13: FaP | AE13: 0.022069723 | AG13: ELC | AH13: FaP | AI13: 0.17286249 | AK13: W | AL13: 0.25605954 | AM13: hydro
C14: W | I14: elc_spv-CHE_0000 | J14: RaD | K14: 0.25400815 | L14: IMPNRGZ | N14: elc_won-CHE_0000 | O14: RaD | P14: 0.10877837 | Q14: IMPNRGZ | X14: 0.11552511 | Y14: 0.16263862 | Z14: RaD | AA14: elc_roadtransport | AC14: elc_buildings | AD14: RaD | AE14: 0.1274447 | AG14: ELC | AH14: RaD | AI14: 0.14227253 | AK14: R | AL14: 0.27149548 | AM14: hydro
I15: elc_spv-CHE_0000 | J15: RaN | K15: 0.0022366278 | L15: IMPNRGZ | N15: elc_won-CHE_0000 | O15: RaN | P15: 0.090126685 | Q15: IMPNRGZ | X15: 0.11552511 | Y15: 0.053125161 | Z15: RaN | AA15: elc_roadtransport | AC15: elc_buildings | AD15: RaN | AE15: 0.10132256 | AG15: ELC | AH15: RaN | AI15: 0.28994594
I16: elc_spv-CHE_0000 | J16: RaP | K16: 0.021755091 | L16: IMPNRGZ | N16: elc_won-CHE_0000 | O16: RaP | P16: 0.020067137 | Q16: IMPNRGZ | X16: 0.021004566 | Y16: 0.036291011 | Z16: RaP | AA16: elc_roadtransport | AC16: elc_buildings | AD16: RaP | AE16: 0.023070201 | AG16: ELC | AH16: RaP | AI16: 0.14528556
I17: elc_spv-CHE_0000 | J17: SaD | K17: 0.31909886 | L17: IMPNRGZ | N17: elc_won-CHE_0000 | O17: SaD | P17: 0.067885575 | Q17: IMPNRGZ | X17: 0.11552511 | Y17: 0.16263862 | Z17: SaD | AA17: elc_roadtransport | AC17: elc_buildings | AD17: SaD | AE17: 0.11289823 | AG17: ELC | AH17: SaD | AI17: 0.12685348
I18: elc_spv-CHE_0000 | J18: SaN | K18: 0.011865283 | L18: IMPNRGZ | N18: elc_won-CHE_0000 | O18: SaN | P18: 0.055965229 | Q18: IMPNRGZ | X18: 0.11552511 | Y18: 0.053125161 | Z18: SaN | AA18: elc_roadtransport | AC18: elc_buildings | AD18: SaN | AE18: 0.087639672 | AG18: ELC | AH18: SaN | AI18: 0.23017486
I19: elc_spv-CHE_0000 | J19: SaP | K19: 0.033932433 | L19: IMPNRGZ | N19: elc_won-CHE_0000 | O19: SaP | P19: 0.016811605 | Q19: IMPNRGZ | X19: 0.021004566 | Y19: 0.036291011 | Z19: SaP | AA19: elc_roadtransport | AC19: elc_buildings | AD19: SaP | AE19: 0.020015394 | AG19: ELC | AH19: SaP | AI19: 0.10493351
I20: elc_spv-CHE_0000 | J20: WaD | K20: 0.16456471 | L20: IMPNRGZ | N20: elc_won-CHE_0000 | O20: WaD | P20: 0.12026266 | Q20: IMPNRGZ | X20: 0.1130137 | Y20: 0.159103 | Z20: WaD | AA20: elc_roadtransport | AC20: elc_buildings | AD20: WaD | AE20: 0.14393901 | AG20: ELC | AH20: WaD | AI20: 0.088349266
I21: elc_spv-CHE_0000 | J21: WaN | K21: 0 | L21: IMPNRGZ | N21: elc_won-CHE_0000 | O21: WaN | P21: 0.13922391 | Q21: IMPNRGZ | X21: 0.1130137 | Y21: 0.051970266 | Z21: WaN | AA21: elc_roadtransport | AC21: elc_buildings | AD21: WaN | AE21: 0.11874699 | AG21: ELC | AH21: WaN | AI21: 0.18964787
I22: elc_spv-CHE_0000 | J22: WaP | K22: 0.0037238938 | L22: IMPNRGZ | N22: elc_won-CHE_0000 | O22: WaP | P22: 0.027578268 | Q22: IMPNRGZ | X22: 0.020547945 | Y22: 0.035502076 | Z22: WaP | AA22: elc_roadtransport | AC22: elc_buildings | AD22: WaP | AE22: 0.026709175 | AG22: ELC | AH22: WaP | AI22: 0.057719826
I23: elc_spv-CHE_0001 | J23: FaD | K23: 0.17843432 | L23: IMPNRGZ | N23: elc_won-CHE_0001 | O23: FaD | P23: 0.17722447 | Q23: IMPNRGZ | AC23: elc_industry | AD23: FaD | AE23: 0.1150521
I24: elc_spv-CHE_0001 | J24: FaN | K24: 0 | L24: IMPNRGZ | N24: elc_won-CHE_0001 | O24: FaN | P24: 0.16195698 | Q24: IMPNRGZ | AC24: elc_industry | AD24: FaN | AE24: 0.11326318
I25: elc_spv-CHE_0001 | J25: FaP | K25: 0.0074580991 | L25: IMPNRGZ | N25: elc_won-CHE_0001 | O25: FaP | P25: 0.028470882 | Q25: IMPNRGZ | AC25: elc_industry | AD25: FaP | AE25: 0.020924674
I26: elc_spv-CHE_0001 | J26: RaD | K26: 0.25084771 | L26: IMPNRGZ | N26: elc_won-CHE_0001 | O26: RaD | P26: 0.089917686 | Q26: IMPNRGZ | AC26: elc_industry | AD26: RaD | AE26: 0.11636243
I27: elc_spv-CHE_0001 | J27: RaN | K27: 0.0023971838 | L27: IMPNRGZ | N27: elc_won-CHE_0001 | O27: RaN | P27: 0.089879362 | Q27: IMPNRGZ | AC27: elc_industry | AD27: RaN | AE27: 0.11454117
I28: elc_spv-CHE_0001 | J28: RaP | K28: 0.022187844 | L28: IMPNRGZ | N28: elc_won-CHE_0001 | O28: RaP | P28: 0.017415077 | Q28: IMPNRGZ | AC28: elc_industry | AD28: RaP | AE28: 0.021149724
I29: elc_spv-CHE_0001 | J29: SaD | K29: 0.33411434 | L29: IMPNRGZ | N29: elc_won-CHE_0001 | O29: SaD | P29: 0.052401819 | Q29: IMPNRGZ | AC29: elc_industry | AD29: SaD | AE29: 0.1162509
I30: elc_spv-CHE_0001 | J30: SaN | K30: 0.012671913 | L30: IMPNRGZ | N30: elc_won-CHE_0001 | O30: SaN | P30: 0.06119235 | Q30: IMPNRGZ | AC30: elc_industry | AD30: SaN | AE30: 0.11448986
I31: elc_spv-CHE_0001 | J31: SaP | K31: 0.037185781 | L31: IMPNRGZ | N31: elc_won-CHE_0001 | O31: SaP | P31: 0.013190829 | Q31: IMPNRGZ | AC31: elc_industry | AD31: SaP | AE31: 0.021100861
I32: elc_spv-CHE_0001 | J32: WaD | K32: 0.15116071 | L32: IMPNRGZ | N32: elc_won-CHE_0001 | O32: WaD | P32: 0.12675399 | Q32: IMPNRGZ | AC32: elc_industry | AD32: WaD | AE32: 0.11393432
I33: elc_spv-CHE_0001 | J33: WaN | K33: 0 | L33: IMPNRGZ | N33: elc_won-CHE_0001 | O33: WaN | P33: 0.15250813 | Q33: IMPNRGZ | AC33: elc_industry | AD33: WaN | AE33: 0.11217792
I34: elc_spv-CHE_0001 | J34: WaP | K34: 0.0035420959 | L34: IMPNRGZ | N34: elc_won-CHE_0001 | O34: WaP | P34: 0.029088426 | Q34: IMPNRGZ | AC34: elc_industry | AD34: WaP | AE34: 0.020752872
I35: elc_spv-CHE_0010 | J35: FaD | K35: 0.17450142 | L35: IMPNRGZ | N35: elc_won-CHE_0010 | O35: FaD | P35: 0.15319618 | Q35: IMPNRGZ
I36: elc_spv-CHE_0010 | J36: FaN | K36: 0 | L36: IMPNRGZ | N36: elc_won-CHE_0010 | O36: FaN | P36: 0.14544024 | Q36: IMPNRGZ
I37: elc_spv-CHE_0010 | J37: FaP | K37: 0.0066107151 | L37: IMPNRGZ | N37: elc_won-CHE_0010 | O37: FaP | P37: 0.029654868 | Q37: IMPNRGZ
I38: elc_spv-CHE_0010 | J38: RaD | K38: 0.25745445 | L38: IMPNRGZ | N38: elc_won-CHE_0010 | O38: RaD | P38: 0.10046027 | Q38: IMPNRGZ
I39: elc_spv-CHE_0010 | J39: RaN | K39: 0.003112877 | L39: IMPNRGZ | N39: elc_won-CHE_0010 | O39: RaN | P39: 0.099610973 | Q39: IMPNRGZ
I40: elc_spv-CHE_0010 | J40: RaP | K40: 0.0207269 | L40: IMPNRGZ | N40: elc_won-CHE_0010 | O40: RaP | P40: 0.019152537 | Q40: IMPNRGZ
I41: elc_spv-CHE_0010 | J41: SaD | K41: 0.34874224 | L41: IMPNRGZ | N41: elc_won-CHE_0010 | O41: SaD | P41: 0.054937861 | Q41: IMPNRGZ
I42: elc_spv-CHE_0010 | J42: SaN | K42: 0.014155945 | L42: IMPNRGZ | N42: elc_won-CHE_0010 | O42: SaN | P42: 0.05844815 | Q42: IMPNRGZ
I43: elc_spv-CHE_0010 | J43: SaP | K43: 0.037714254 | L43: IMPNRGZ | N43: elc_won-CHE_0010 | O43: SaP | P43: 0.012472781 | Q43: IMPNRGZ
I44: elc_spv-CHE_0010 | J44: WaD | K44: 0.13431869 | L44: IMPNRGZ | N44: elc_won-CHE_0010 | O44: WaD | P44: 0.13971396 | Q44: IMPNRGZ
I45: elc_spv-CHE_0010 | J45: WaN | K45: 0 | L45: IMPNRGZ | N45: elc_won-CHE_0010 | O45: WaN | P45: 0.15799152 | Q45: IMPNRGZ
I46: elc_spv-CHE_0010 | J46: WaP | K46: 0.0026625066 | L46: IMPNRGZ | N46: elc_won-CHE_0010 | O46: WaP | P46: 0.028920658 | Q46: IMPNRGZ
... I310: elc_spv-CHE_0009 | J310: WaP | K310: 0.0029452861 | L310: IMPNRGZ | N310: elc_won-CHE_0008 | O310: WaP | P310: 0.025782697 | Q310: IMPNRGZ
N311: elc_won-CHE_0009 | O311: FaD | P311: 0.17789374 | Q311: IMPNRGZ
...
