Workbook

Sheet Veda
B2: ~Inputcell: 1-5
B3: 5
C5: =VLOOKUP(B3,$B$7:$C$14,2,FALSE) -> Current Policies
B7: 1 | C7: Delayed transition
B8: 2 | C8: Net Zero 2050 | Q8: EMBER
B9: 3 | C9: Nationally Determined Contributions (NDCs) | Q9: 2022
B10: 4 | C10: Below 2°C | Q10: =SUMIFS(historical_data_long!$D$3:$D$9999,historical_data_long!$B$3:$B$9999,Veda!Q9,historical_data_long!$C$3:$C$9999,"TWh")-R26+R27 -> 4318.49 | R10: base-year demand (TWh)
B11: 5 | C11: Current Policies
B12: 6 | C12: Low demand | R12: =SUM(R17:R20) -> 4318.49 | S12: =SUM(S17:S20) -> 4410.2968 | T12: =SUM(T17:T20) -> 4974.6626 | U12: =SUM(U17:U20) -> 5426.5369 | V12: =SUM(V17:V20) -> 5644.4825 | W12: =SUM(W17:W20) -> 5689.4547 | X12: =SUM(X17:X20) -> 5754.7453
B13: 7 | C13: Fragmented World
Q14: ~TFM_INS-TS
G15: 2020 | H15: =S15 -> 2025 | I15: =T15 -> 2030 | J15: =U15 -> 2035 | K15: =V15 -> 2040 | L15: =W15 -> 2045 | M15: =X15 -> 2050 | Q15: commodity | R15: 2022 | S15: 2025 | T15: 2030 | U15: 2035 | V15: 2040 | W15: 2045 | X15: 2050 | Y15: attribute
E16: =1000/3.6 -> 277.77778 | G16: =SUMIFS(ngfs_median!$J$2:$J$17119,ngfs_median!$B$2:$B$17119,Veda!$C$5,ngfs_median!$H$2:$H$17119,Veda!$Q16,ngfs_median!$I$2:$I$17119,Veda!G$15) -> 0.1113 | H16: =SUMIFS(ngfs_median!$J$2:$J$17119,ngfs_median!$B$2:$B$17119,Veda!$C$5,ngfs_median!$H$2:$H$17119,Veda!$Q16,ngfs_median!$I$2:$I$17119,Veda!H$15) -> 0.4942 | I16: =SUMIFS(ngfs_median!$J$2:$J$17119,ngfs_median!$B$2:$B$17119,Veda!$C$5,ngfs_median!$H$2:$H$17119,Veda!$Q16,ngfs_median!$I$2:$I$17119,Veda!I$15) -> 0.84895 | J16: =SUMIFS(ngfs_median!$J$2:$J$17119,ngfs_median!$B$2:$B$17119,Veda!$C$5,ngfs_median!$H$2:$H$17119,Veda!$Q16,ngfs_median!$I$2:$I$17119,Veda!J$15) -> 1.1212 | K16: =SUMIFS(ngfs_median!$J$2:$J$17119,ngfs_median!$B$2:$B$17119,Veda!$C$5,ngfs_median!$H$2:$H$17119,Veda!$Q16,ngfs_median!$I$2:$I$17119,Veda!K$15) -> 1.29225 | L16: =SUMIFS(ngfs_median!$J$2:$J$17119,ngfs_median!$B$2:$B$17119,Veda!$C$5,ngfs_median!$H$2:$H$17119,Veda!$Q16,ngfs_median!$I$2:$I$17119,Veda!L$15) -> 1.4059 | M16: =SUMIFS(ngfs_median!$J$2:$J$17119,ngfs_median!$B$2:$B$17119,Veda!$C$5,ngfs_median!$H$2:$H$17119,Veda!$Q16,ngfs_median!$I$2:$I$17119,Veda!M$15) -> 1.63395 | Q16: hydrogen_allsect | S16: =(H16-$H$16)*$E$16 -> 0 | T16: =(I16-$H$16)*$E$16 -> 98.541667 | U16: =(J16-$H$16)*$E$16 -> 174.16667 | V16: =(K16-$H$16)*$E$16 -> 221.68056 | W16: =(L16-$H$16)*$E$16 -> 253.25 | X16: =(M16-$H$16)*$E$16 -> 316.59722 | Y16: demand | AA16: assumption: incremental over 2025 is from electricity
G17: =SUMIFS(ngfs_median!$J$2:$J$17119,ngfs_median!$B$2:$B$17119,Veda!$C$5,ngfs_median!$H$2:$H$17119,Veda!$Q17,ngfs_median!$I$2:$I$17119,Veda!G$15) -> 0.2758 | H17: =SUMIFS(ngfs_median!$J$2:$J$17119,ngfs_median!$B$2:$B$17119,Veda!$C$5,ngfs_median!$H$2:$H$17119,Veda!$Q17,ngfs_median!$I$2:$I$17119,Veda!H$15) -> 0.68565 | I17: =SUMIFS(ngfs_median!$J$2:$J$17119,ngfs_median!$B$2:$B$17119,Veda!$C$5,ngfs_median!$H$2:$H$17119,Veda!$Q17,ngfs_median!$I$2:$I$17119,Veda!I$15) -> 1.4014 | J17: =SUMIFS(ngfs_median!$J$2:$J$17119,ngfs_median!$B$2:$B$17119,Veda!$C$5,ngfs_median!$H$2:$H$17119,Veda!$Q17,ngfs_median!$I$2:$I$17119,Veda!J$15) -> 2.2556 | K17: =SUMIFS(ngfs_median!$J$2:$J$17119,ngfs_median!$B$2:$B$17119,Veda!$C$5,ngfs_median!$H$2:$H$17119,Veda!$Q17,ngfs_median!$I$2:$I$17119,Veda!K$15) -> 2.9039 | L17: =SUMIFS(ngfs_median!$J$2:$J$17119,ngfs_median!$B$2:$B$17119,Veda!$C$5,ngfs_median!$H$2:$H$17119,Veda!$Q17,ngfs_median!$I$2:$I$17119,Veda!L$15) -> 3.20465 | M17: =SUMIFS(ngfs_median!$J$2:$J$17119,ngfs_median!$B$2:$B$17119,Veda!$C$5,ngfs_median!$H$2:$H$17119,Veda!$Q17,ngfs_median!$I$2:$I$17119,Veda!M$15) -> 3.42235 | Q17: elc_transport | R17: =$Q$10*G17/SUM($G$17:$G$19) -> 84.20454 | S17: =R17 -> 84.20454 | T17: =S17 -> 84.20454 | U17: =T17 -> 84.20454 | V17: =U17 -> 84.20454 | W17: =V17 -> 84.20454 | X17: =W17 -> 84.20454 | Y17: demand | AA17: non-road transport demand assumed to be constant
G18: =SUMIFS(ngfs_median!$J$2:$J$17119,ngfs_median!$B$2:$B$17119,Veda!$C$5,ngfs_median!$H$2:$H$17119,Veda!$Q18,ngfs_median!$I$2:$I$17119,Veda!G$15) -> 10.7132 | H18: =SUMIFS(ngfs_median!$J$2:$J$17119,ngfs_median!$B$2:$B$17119,Veda!$C$5,ngfs_median!$H$2:$H$17119,Veda!$Q18,ngfs_median!$I$2:$I$17119,Veda!H$15) -> 10.59785 | I18: =SUMIFS(ngfs_median!$J$2:$J$17119,ngfs_median!$B$2:$B$17119,Veda!$C$5,ngfs_median!$H$2:$H$17119,Veda!$Q18,ngfs_median!$I$2:$I$17119,Veda!I$15) -> 11.26485 | J18: =SUMIFS(ngfs_median!$J$2:$J$17119,ngfs_median!$B$2:$B$17119,Veda!$C$5,ngfs_median!$H$2:$H$17119,Veda!$Q18,ngfs_median!$I$2:$I$17119,Veda!J$15) -> 11.6105 | K18: =SUMIFS(ngfs_median!$J$2:$J$17119,ngfs_median!$B$2:$B$17119,Veda!$C$5,ngfs_median!$H$2:$H$17119,Veda!$Q18,ngfs_median!$I$2:$I$17119,Veda!K$15) -> 11.54585 | L18: =SUMIFS(ngfs_median!$J$2:$J$17119,ngfs_median!$B$2:$B$17119,Veda!$C$5,ngfs_median!$H$2:$H$17119,Veda!$Q18,ngfs_median!$I$2:$I$17119,Veda!L$15) -> 11.32115 | M18: =SUMIFS(ngfs_median!$J$2:$J$17119,ngfs_median!$B$2:$B$17119,Veda!$C$5,ngfs_median!$H$2:$H$17119,Veda!$Q18,ngfs_median!$I$2:$I$17119,Veda!M$15) -> 11.282 | Q18: elc_buildings | R18: =$Q$10*G18/SUM($G$17:$G$19) -> 3270.8487 | S18: =R18*H18/G18 -> 3235.6312 | T18: =S18*I18/H18 -> 3439.2731 | U18: =T18*J18/I18 -> 3544.8035 | V18: =U18*K18/J18 -> 3525.0652 | W18: =V18*L18/K18 -> 3456.462 | X18: =W18*M18/L18 -> 3444.5092 | Y18: demand
G19: =SUMIFS(ngfs_median!$J$2:$J$17119,ngfs_median!$B$2:$B$17119,Veda!$C$5,ngfs_median!$H$2:$H$17119,Veda!$Q19,ngfs_median!$I$2:$I$17119,Veda!G$15) -> 3.1556 | H19: =SUMIFS(ngfs_median!$J$2:$J$17119,ngfs_median!$B$2:$B$17119,Veda!$C$5,ngfs_median!$H$2:$H$17119,Veda!$Q19,ngfs_median!$I$2:$I$17119,Veda!H$15) -> 3.1618 | I19: =SUMIFS(ngfs_median!$J$2:$J$17119,ngfs_median!$B$2:$B$17119,Veda!$C$5,ngfs_median!$H$2:$H$17119,Veda!$Q19,ngfs_median!$I$2:$I$17119,Veda!I$15) -> 3.62755 | J19: =SUMIFS(ngfs_median!$J$2:$J$17119,ngfs_median!$B$2:$B$17119,Veda!$C$5,ngfs_median!$H$2:$H$17119,Veda!$Q19,ngfs_median!$I$2:$I$17119,Veda!J$15) -> 3.90775 | K19: =SUMIFS(ngfs_median!$J$2:$J$17119,ngfs_median!$B$2:$B$17119,Veda!$C$5,ngfs_median!$H$2:$H$17119,Veda!$Q19,ngfs_median!$I$2:$I$17119,Veda!K$15) -> 4.03795 | L19: =SUMIFS(ngfs_median!$J$2:$J$17119,ngfs_median!$B$2:$B$17119,Veda!$C$5,ngfs_median!$H$2:$H$17119,Veda!$Q19,ngfs_median!$I$2:$I$17119,Veda!L$15) -> 4.1092 | M19: =SUMIFS(ngfs_median!$J$2:$J$17119,ngfs_median!$B$2:$B$17119,Veda!$C$5,ngfs_median!$H$2:$H$17119,Veda!$Q19,ngfs_median!$I$2:$I$17119,Veda!M$15) -> 4.1445 | Q19: elc_industry | R19: =$Q$10*G19/SUM($G$17:$G$19) -> 963.43672 | S19: =R19*H19/G19 -> 965.32964 | T19: =S19*I19/H19 -> 1107.5278 | U19: =T19*J19/I19 -> 1193.0758 | V19: =U19*K19/J19 -> 1232.8271 | W19: =V19*L19/K19 -> 1254.5805 | X19: =W19*M19/L19 -> 1265.3579 | Y19: demand
B20: EMBER | Q20: elc_roadtransport | R20: =$Q$10*G17/SUM($G$17:$G$19)-R17 -> 0 | S20: =$Q$10*H17/SUM($G$17:$G$19)-S17 -> 125.13137 | T20: =$Q$10*I17/SUM($G$17:$G$19)-T17 -> 343.65711 | U20: =$Q$10*J17/SUM($G$17:$G$19)-U17 -> 604.45304 | V20: =$Q$10*K17/SUM($G$17:$G$19)-V17 -> 802.38561 | W20: =$Q$10*L17/SUM($G$17:$G$19)-W17 -> 894.20764 | X20: =$Q$10*M17/SUM($G$17:$G$19)-X17 -> 960.67366 | Y20: demand
B21: 2020 | Q21: *
B22: =SUMIFS(historical_data_long!$D$3:$D$9999,historical_data_long!$B$3:$B$9999,Veda!B21,historical_data_long!$C$3:$C$9999,"mtCO2") -> 1565.52 | D22: Emissions|CO2|Power (Estimated) | G22: =G35/$G$35*$B22 -> 1565.52 | H22: =H35/$G$35*$B22 -> 1700.5994 | I22: =I35/$G$35*$B22 -> 1771.2762 | J22: =J35/$G$35*$B22 -> 1667.9514 | K22: =K35/$G$35*$B22 -> 1406.3824 | L22: =L35/$G$35*$B22 -> 1542.9298 | M22: =M35/$G$35*$B22 -> 1670.3753 | Q22: co2net | T22: =I35*1000 -> 832908.7 | U22: =J35*1000 -> 784322.2 | V22: =K35*1000 -> 661324.4 | W22: =L35*1000 -> 725533.2 | X22: =M35*1000 -> 785462 | Y22: com_bndnet
Q24: ~TFM_INS-TS
Q25: process | R25: =R15 -> 2022 | S25: =S15 -> 2025 | T25: =T15 -> 2030 | U25: =U15 -> 2035 | V25: =V15 -> 2040 | W25: =W15 -> 2045 | X25: =X15 -> 2050 | Y25: attribute | Z25: limtype
O26: import | Q26: Trd_electricity import | R26: =SUMIFS(historical_data_long!$D$3:$D$9999,historical_data_long!$B$3:$B$9999,Veda!R$25,historical_data_long!$A$3:$A$9999,$O26) -> 57 | S26: =AVERAGEIFS(historical_data_long!$D$3:$D$9999,historical_data_long!$B$3:$B$9999,">2017",historical_data_long!$A$3:$A$9999,$O26) -> 54.65 | Y26: ACT_BND | Z26: FX
O27: export | Q27: Trd_electricity export | R27: =SUMIFS(historical_data_long!$D$3:$D$9999,historical_data_long!$B$3:$B$9999,Veda!R$25,historical_data_long!$A$3:$A$9999,$O27) -> 15.8 | S27: =AVERAGEIFS(historical_data_long!$D$3:$D$9999,historical_data_long!$B$3:$B$9999,">2017",historical_data_long!$A$3:$A$9999,$O27) -> 16.25 | Y27: ACT_BND | Z27: FX
G35: =SUMIFS(ngfs_median!$J$2:$J$17119,ngfs_median!$B$2:$B$17119,Veda!$C$5,ngfs_median!$D$2:$D$17119,Veda!$D22,ngfs_median!$I$2:$I$17119,Veda!G$15) -> 736.1558 | H35: =SUMIFS(ngfs_median!$J$2:$J$17119,ngfs_median!$B$2:$B$17119,Veda!$C$5,ngfs_median!$D$2:$D$17119,Veda!$D22,ngfs_median!$I$2:$I$17119,Veda!H$15) -> 799.6743 | I35: =SUMIFS(ngfs_median!$J$2:$J$17119,ngfs_median!$B$2:$B$17119,Veda!$C$5,ngfs_median!$D$2:$D$17119,Veda!$D22,ngfs_median!$I$2:$I$17119,Veda!I$15) -> 832.9087 | J35: =SUMIFS(ngfs_median!$J$2:$J$17119,ngfs_median!$B$2:$B$17119,Veda!$C$5,ngfs_median!$D$2:$D$17119,Veda!$D22,ngfs_median!$I$2:$I$17119,Veda!J$15) -> 784.3222 | K35: =SUMIFS(ngfs_median!$J$2:$J$17119,ngfs_median!$B$2:$B$17119,Veda!$C$5,ngfs_median!$D$2:$D$17119,Veda!$D22,ngfs_median!$I$2:$I$17119,Veda!K$15) -> 661.3244 | L35: =SUMIFS(ngfs_median!$J$2:$J$17119,ngfs_median!$B$2:$B$17119,Veda!$C$5,ngfs_median!$D$2:$D$17119,Veda!$D22,ngfs_median!$I$2:$I$17119,Veda!L$15) -> 725.5332 | M35: =SUMIFS(ngfs_median!$J$2:$J$17119,ngfs_median!$B$2:$B$17119,Veda!$C$5,ngfs_median!$D$2:$D$17119,Veda!$D22,ngfs_median!$I$2:$I$17119,Veda!M$15) -> 785.462

Sheet historical_data_long
A1: model_fuel | B1: Year | C1: Unit | D1: Value
A2: bioenergy | B2: 2000 | C2: TWh | D2: 60.73
A3: coal | B3: 2000 | C3: TWh | D3: 1966.27
A4: gas | B4: 2000 | C4: TWh | D4: 614.99
A5: hydro | B5: 2000 | C5: TWh | D5: 270.03
A6: nuclear | B6: 2000 | C6: TWh | D6: 753.89
A7: oil | B7: 2000 | C7: TWh | D7: 116.02
A8: bioenergy | B8: 2000 | C8: TWh | D8: 14.09
A9: solar | B9: 2000 | C9: TWh | D9: 0.49
A10: windon | B10: 2000 | C10: TWh | D10: 5.59
A11: bioenergy | B11: 2001 | C11: TWh | D11: 49.75
A12: coal | B12: 2001 | C12: TWh | D12: 1903.96
A13: gas | B13: 2001 | C13: TWh | D13: 639.13
... A697: Import | B697: 2023 | C697: TWh | D697: 38.9

Sheet ngfs_median
A1: Model | B1: Scenario | C1: Region | D1: Variable | E1: Unit | F1: variable_x | G1: potential_use | H1: commodity | I1: year | J1: value | K1: variable_y | L1: ej_to_mtco2
A2: Downscaling[MESSAGEix-GLOBIOM 1.1-M-R12] | B2: Below 2°C | C2: USA | D2: Emissions|CO2|Power (estimated) | E2: Mt CO2 | F2: Secondary Energy|Electricity|Coal | G2: elec_co2 | H2: na | I2: 2020 | J2: 448.7842 | K2: Secondary Energy|Electricity|Coal | L2: 94
A3: Downscaling[MESSAGEix-GLOBIOM 1.1-M-R12] | B3: Below 2°C | C3: USA | D3: Emissions|CO2|Power (estimated) | E3: Mt CO2 | F3: Secondary Energy|Electricity|Coal | G3: elec_co2 | H3: na | I3: 2025 | J3: 230.9298 | K3: Secondary Energy|Electricity|Coal | L3: 94
A4: Downscaling[MESSAGEix-GLOBIOM 1.1-M-R12] | B4: Below 2°C | C4: USA | D4: Emissions|CO2|Power (estimated) | E4: Mt CO2 | F4: Secondary Energy|Electricity|Coal | G4: elec_co2 | H4: na | I4: 2030 | J4: 69.795 | K4: Secondary Energy|Electricity|Coal | L4: 94
A5: Downscaling[MESSAGEix-GLOBIOM 1.1-M-R12] | B5: Below 2°C | C5: USA | D5: Emissions|CO2|Power (estimated) | E5: Mt CO2 | F5: Secondary Energy|Electricity|Coal | G5: elec_co2 | H5: na | I5: 2035 | J5: 36.143 | K5: Secondary Energy|Electricity|Coal | L5: 94
A6: Downscaling[MESSAGEix-GLOBIOM 1.1-M-R12] | B6: Below 2°C | C6: USA | D6: Emissions|CO2|Power (estimated) | E6: Mt CO2 | F6: Secondary Energy|Electricity|Coal | G6: elec_co2 | H6: na | I6: 2040 | J6: 15.5476 | K6: Secondary Energy|Electricity|Coal | L6: 94
A7: Downscaling[MESSAGEix-GLOBIOM 1.1-M-R12] | B7: Below 2°C | C7: USA | D7: Emissions|CO2|Power (estimated) | E7: Mt CO2 | F7: Secondary Energy|Electricity|Coal | G7: elec_co2 | H7: na | I7: 2045 | J7: 4.8786 | K7: Secondary Energy|Electricity|Coal | L7: 94
A8: Downscaling[MESSAGEix-GLOBIOM 1.1-M-R12] | B8: Below 2°C | C8: USA | D8: Emissions|CO2|Power (estimated) | E8: Mt CO2 | F8: Secondary Energy|Electricity|Coal | G8: elec_co2 | H8: na | I8: 2050 | J8: 0.5076 | K8: Secondary Energy|Electricity|Coal | L8: 94
A9: Downscaling[MESSAGEix-GLOBIOM 1.1-M-R12] | B9: Below 2°C | C9: USA | D9: Emissions|CO2|Power (estimated) | E9: Mt CO2 | F9: Secondary Energy|Electricity|Gas | G9: elec_co2 | H9: na | I9: 2020 | J9: 241.164 | K9: Secondary Energy|Electricity|Gas | L9: 55
A10: Downscaling[MESSAGEix-GLOBIOM 1.1-M-R12] | B10: Below 2°C | C10: USA | D10: Emissions|CO2|Power (estimated) | E10: Mt CO2 | F10: Secondary Energy|Electricity|Gas | G10: elec_co2 | H10: na | I10: 2025 | J10: 340.879 | K10: Secondary Energy|Electricity|Gas | L10: 55
A11: Downscaling[MESSAGEix-GLOBIOM 1.1-M-R12] | B11: Below 2°C | C11: USA | D11: Emissions|CO2|Power (estimated) | E11: Mt CO2 | F11: Secondary Energy|Electricity|Gas | G11: elec_co2 | H11: na | I11: 2030 | J11: 371.5855 | K11: Secondary Energy|Electricity|Gas | L11: 55
A12: Downscaling[MESSAGEix-GLOBIOM 1.1-M-R12] | B12: Below 2°C | C12: USA | D12: Emissions|CO2|Power (estimated) | E12: Mt CO2 | F12: Secondary Energy|Electricity|Gas | G12: elec_co2 | H12: na | I12: 2035 | J12: 438.0475 | K12: Secondary Energy|Electricity|Gas | L12: 55
A13: Downscaling[MESSAGEix-GLOBIOM 1.1-M-R12] | B13: Below 2°C | C13: USA | D13: Emissions|CO2|Power (estimated) | E13: Mt CO2 | F13: Secondary Energy|Electricity|Gas | G13: elec_co2 | H13: na | I13: 2040 | J13: 480.5075 | K13: Secondary Energy|Electricity|Gas | L13: 55
... A148: Downscaling[MESSAGEix-GLOBIOM 1.1-M-R12] | B148: Net Zero 2050 | C148: USA | D148: Emissions|CO2|Power (estimated) | E148: Mt CO2 | F148: Secondary Energy|Electricity|Oil | G148: elec_co2 | H148: na | I148: 2050 | J148: 0 | K148: Secondary Energy|Electricity|Oil | L148: 70
A149: Median | B149: Below 2°C | C149: USA | D149: Carbon Sequestration|CCS | E149: Mt CO2/yr | F149: Carbon Sequestration|CCS | G149: CCS potential | H149: na | I149: 2020 | J149: 2.2551 | K149: Carbon Sequestration|CCS
A150: Median | B150: Below 2°C | C150: USA | D150: Carbon Sequestration|CCS | E150: Mt CO2/yr | F150: Carbon Sequestration|CCS | G150: CCS potential | H150: na | I150: 2025 | J150: 28.1 | K150: Carbon Sequestration|CCS
A151: Median | B151: Below 2°C | C151: USA | D151: Carbon Sequestration|CCS | E151: Mt CO2/yr | F151: Carbon Sequestration|CCS | G151: CCS potential | H151: na | I151: 2030 | J151: 96.32805 | K151: Carbon Sequestration|CCS
A152: Median | B152: Below 2°C | C152: USA | D152: Carbon Sequestration|CCS | E152: Mt CO2/yr | F152: Carbon Sequestration|CCS | G152: CCS potential | H152: na | I152: 2035 | J152: 287.94645 | K152: Carbon Sequestration|CCS
A153: Median | B153: Below 2°C | C153: USA | D153: Carbon Sequestration|CCS | E153: Mt CO2/yr | F153: Carbon Sequestration|CCS | G153: CCS potential | H153: na | I153: 2040 | J153: 445.5077 | K153: Carbon Sequestration|CCS
A154: Median | B154: Below 2°C | C154: USA | D154: Carbon Sequestration|CCS | E154: Mt CO2/yr | F154: Carbon Sequestration|CCS | G154: CCS potential | H154: na | I154: 2045 | J154: 497.4268 | K154: Carbon Sequestration|CCS
A155: Median | B155: Below 2°C | C155: USA | D155: Carbon Sequestration|CCS | E155: Mt CO2/yr | F155: Carbon Sequestration|CCS | G155: CCS potential | H155: na | I155: 2050 | J155: 481.7295 | K155: Carbon Sequestration|CCS
A156: Median | B156: Below 2°C | C156: USA | D156: Carbon Sequestration|CCS | E156: Mt CO2/yr | F156: Carbon Sequestration|CCS | G156: CCS potential | H156: na | I156: 2055 | J156: 439.80395 | K156: Carbon Sequestration|CCS
A157: Median | B157: Below 2°C | C157: USA | D157: Carbon Sequestration|CCS | E157: Mt CO2/yr | F157: Carbon Sequestration|CCS | G157: CCS potential | H157: na | I157: 2060 | J157: 391.27895 | K157: Carbon Sequestration|CCS
A158: Median | B158: Below 2°C | C158: USA | D158: Carbon Sequestration|CCS | E158: Mt CO2/yr | F158: Carbon Sequestration|CCS | G158: CCS potential | H158: na | I158: 2065 | J158: 346.76305 | K158: Carbon Sequestration|CCS
A159: Median | B159: Below 2°C | C159: USA | D159: Carbon Sequestration|CCS | E159: Mt CO2/yr | F159: Carbon Sequestration|CCS | G159: CCS potential | H159: na | I159: 2070 | J159: 302.2469 | K159: Carbon Sequestration|CCS
A160: Median | B160: Below 2°C | C160: USA | D160: Carbon Sequestration|CCS | E160: Mt CO2/yr | F160: Carbon Sequestration|CCS | G160: CCS potential | H160: na | I160: 2075 | J160: 223.9902 | K160: Carbon Sequestration|CCS
... A1338: Median | B1338: Net Zero 2050 | C1338: USA | D1338: Price|Secondary Energy|Liquids|Oil | E1338: US$2010/GJ | F1338: Price|Secondary Energy|Liquids|Oil | G1338: fuel_supply | H1338: oil | I1338: 2100 | J1338: 510.43905 | K1338: Price|Secondary Energy|Liquids|Oil
A1339: Median | B1339: Below 2°C | C1339: USA | D1339: Secondary Energy|Electricity|Coal | E1339: EJ/yr | F1339: Secondary Energy|Electricity|Coal | G1339: elec_co2 | H1339: na | I1339: 2020 | J1339: 3.0137 | K1339: Secondary Energy|Electricity|Coal | L1339: 94
A1340: Median | B1340: Below 2°C | C1340: USA | D1340: Secondary Energy|Electricity|Coal | E1340: EJ/yr | F1340: Secondary Energy|Electricity|Coal | G1340: elec_co2 | H1340: na | I1340: 2025 | J1340: 1.2032 | K1340: Secondary Energy|Electricity|Coal | L1340: 94
A1341: Median | B1341: Below 2°C | C1341: USA | D1341: Secondary Energy|Electricity|Coal | E1341: EJ/yr | F1341: Secondary Energy|Electricity|Coal | G1341: elec_co2 | H1341: na | I1341: 2030 | J1341: 0.0065 | K1341: Secondary Energy|Electricity|Coal | L1341: 94
A1342: Median | B1342: Below 2°C | C1342: USA | D1342: Secondary Energy|Electricity|Coal | E1342: EJ/yr | F1342: Secondary Energy|Electricity|Coal | G1342: elec_co2 | H1342: na | I1342: 2035 | J1342: 0.0011 | K1342: Secondary Energy|Electricity|Coal | L1342: 94
A1343: Median | B1343: Below 2°C | C1343: USA | D1343: Secondary Energy|Electricity|Coal | E1343: EJ/yr | F1343: Secondary Energy|Electricity|Coal | G1343: elec_co2 | H1343: na | I1343: 2040 | J1343: 0.0009 | K1343: Secondary Energy|Electricity|Coal | L1343: 94
A1344: Median | B1344: Below 2°C | C1344: USA | D1344: Secondary Energy|Electricity|Coal | E1344: EJ/yr | F1344: Secondary Energy|Electricity|Coal | G1344: elec_co2 | H1344: na | I1344: 2045 | J1344: 0.0005 | K1344: Secondary Energy|Electricity|Coal | L1344: 94
A1345: Median | B1345: Below 2°C | C1345: USA | D1345: Secondary Energy|Electricity|Coal | E1345: EJ/yr | F1345: Secondary Energy|Electricity|Coal | G1345: elec_co2 | H1345: na | I1345: 2050 | J1345: 0.0002 | K1345: Secondary Energy|Electricity|Coal | L1345: 94
A1346: Median | B1346: Below 2°C | C1346: USA | D1346: Secondary Energy|Electricity|Coal | E1346: EJ/yr | F1346: Secondary Energy|Electricity|Coal | G1346: elec_co2 | H1346: na | I1346: 2055 | J1346: 0.0001 | K1346: Secondary Energy|Electricity|Coal | L1346: 94
A1347: Median | B1347: Below 2°C | C1347: USA | D1347: Secondary Energy|Electricity|Coal | E1347: EJ/yr | F1347: Secondary Energy|Electricity|Coal | G1347: elec_co2 | H1347: na | I1347: 2060 | J1347: 0 | K1347: Secondary Energy|Electricity|Coal | L1347: 94
A1348: Median | B1348: Below 2°C | C1348: USA | D1348: Secondary Energy|Electricity|Coal | E1348: EJ/yr | F1348: Secondary Energy|Electricity|Coal | G1348: elec_co2 | H1348: na | I1348: 2065 | J1348: 0 | K1348: Secondary Energy|Electricity|Coal | L1348: 94
A1349: Median | B1349: Below 2°C | C1349: USA | D1349: Secondary Energy|Electricity|Coal | E1349: EJ/yr | F1349: Secondary Energy|Electricity|Coal | G1349: elec_co2 | H1349: na | I1349: 2070 | J1349: 0 | K1349: Secondary Energy|Electricity|Coal | L1349: 94
A1350: Median | B1350: Below 2°C | C1350: USA | D1350: Secondary Energy|Electricity|Coal | E1350: EJ/yr | F1350: Secondary Energy|Electricity|Coal | G1350: elec_co2 | H1350: na | I1350: 2075 | J1350: 0 | K1350: Secondary Energy|Electricity|Coal | L1350: 94
... A1695: Median | B1695: Net Zero 2050 | C1695: USA | D1695: Secondary Energy|Electricity|Oil | E1695: EJ/yr | F1695: Secondary Energy|Electricity|Oil | G1695: elec_co2 | H1695: na | I1695: 2100 | J1695: 0 | K1695: Secondary Energy|Electricity|Oil | L1695: 70
...

Sheet ngfs_scenarios
A1: Model | B1: Scenario | C1: Region | D1: Variable | E1: Unit | F1: variable_x | G1: potential_use | H1: commodity | I1: year | J1: value | K1: variable_y | L1: ej_to_mtco2
A2: Downscaling[MESSAGEix-GLOBIOM 1.1-M-R12] | B2: Below 2°C | C2: USA | D2: Carbon Sequestration|CCS | E2: Mt CO2/yr | F2: Carbon Sequestration|CCS | G2: CCS potential | I2: 2020 | J2: 0 | K2: Carbon Sequestration|CCS
A3: Downscaling[MESSAGEix-GLOBIOM 1.1-M-R12] | B3: Below 2°C | C3: USA | D3: Carbon Sequestration|CCS | E3: Mt CO2/yr | F3: Carbon Sequestration|CCS | G3: CCS potential | I3: 2025 | J3: 0 | K3: Carbon Sequestration|CCS
A4: Downscaling[MESSAGEix-GLOBIOM 1.1-M-R12] | B4: Below 2°C | C4: USA | D4: Carbon Sequestration|CCS | E4: Mt CO2/yr | F4: Carbon Sequestration|CCS | G4: CCS potential | I4: 2030 | J4: 12.655 | K4: Carbon Sequestration|CCS
A5: Downscaling[MESSAGEix-GLOBIOM 1.1-M-R12] | B5: Below 2°C | C5: USA | D5: Carbon Sequestration|CCS | E5: Mt CO2/yr | F5: Carbon Sequestration|CCS | G5: CCS potential | I5: 2035 | J5: 50.7641 | K5: Carbon Sequestration|CCS
A6: Downscaling[MESSAGEix-GLOBIOM 1.1-M-R12] | B6: Below 2°C | C6: USA | D6: Carbon Sequestration|CCS | E6: Mt CO2/yr | F6: Carbon Sequestration|CCS | G6: CCS potential | I6: 2040 | J6: 87.3875 | K6: Carbon Sequestration|CCS
A7: Downscaling[MESSAGEix-GLOBIOM 1.1-M-R12] | B7: Below 2°C | C7: USA | D7: Carbon Sequestration|CCS | E7: Mt CO2/yr | F7: Carbon Sequestration|CCS | G7: CCS potential | I7: 2045 | J7: 168.4526 | K7: Carbon Sequestration|CCS
A8: Downscaling[MESSAGEix-GLOBIOM 1.1-M-R12] | B8: Below 2°C | C8: USA | D8: Carbon Sequestration|CCS | E8: Mt CO2/yr | F8: Carbon Sequestration|CCS | G8: CCS potential | I8: 2050 | J8: 277.5609 | K8: Carbon Sequestration|CCS
A9: Downscaling[MESSAGEix-GLOBIOM 1.1-M-R12] | B9: Below 2°C | C9: USA | D9: Final Energy|Industry|Electricity | E9: EJ/yr | F9: Final Energy|Industry|Electricity | G9: demand_projection | H9: elc_industry | I9: 2020 | J9: 2.0451 | K9: Final Energy|Industry|Electricity
A10: Downscaling[MESSAGEix-GLOBIOM 1.1-M-R12] | B10: Below 2°C | C10: USA | D10: Final Energy|Industry|Electricity | E10: EJ/yr | F10: Final Energy|Industry|Electricity | G10: demand_projection | H10: elc_industry | I10: 2025 | J10: 2.0757 | K10: Final Energy|Industry|Electricity
A11: Downscaling[MESSAGEix-GLOBIOM 1.1-M-R12] | B11: Below 2°C | C11: USA | D11: Final Energy|Industry|Electricity | E11: EJ/yr | F11: Final Energy|Industry|Electricity | G11: demand_projection | H11: elc_industry | I11: 2030 | J11: 2.1765 | K11: Final Energy|Industry|Electricity
A12: Downscaling[MESSAGEix-GLOBIOM 1.1-M-R12] | B12: Below 2°C | C12: USA | D12: Final Energy|Industry|Electricity | E12: EJ/yr | F12: Final Energy|Industry|Electricity | G12: demand_projection | H12: elc_industry | I12: 2035 | J12: 2.2477 | K12: Final Energy|Industry|Electricity
A13: Downscaling[MESSAGEix-GLOBIOM 1.1-M-R12] | B13: Below 2°C | C13: USA | D13: Final Energy|Industry|Electricity | E13: EJ/yr | F13: Final Energy|Industry|Electricity | G13: demand_projection | H13: elc_industry | I13: 2040 | J13: 2.3068 | K13: Final Energy|Industry|Electricity
A14: Downscaling[MESSAGEix-GLOBIOM 1.1-M-R12] | B14: Below 2°C | C14: USA | D14: Final Energy|Industry|Electricity | E14: EJ/yr | F14: Final Energy|Industry|Electricity | G14: demand_projection | H14: elc_industry | I14: 2045 | J14: 2.3565 | K14: Final Energy|Industry|Electricity
A15: Downscaling[MESSAGEix-GLOBIOM 1.1-M-R12] | B15: Below 2°C | C15: USA | D15: Final Energy|Industry|Electricity | E15: EJ/yr | F15: Final Energy|Industry|Electricity | G15: demand_projection | H15: elc_industry | I15: 2050 | J15: 2.5503 | K15: Final Energy|Industry|Electricity
A16: Downscaling[MESSAGEix-GLOBIOM 1.1-M-R12] | B16: Below 2°C | C16: USA | D16: Final Energy|Residential and Commercial|Electricity | E16: EJ/yr | F16: Final Energy|Residential and Commercial|Electricity | G16: demand_projection | H16: elc_buildings | I16: 2020 | J16: 11.8245 | K16: Final Energy|Residential and Commercial|Electricity
A17: Downscaling[MESSAGEix-GLOBIOM 1.1-M-R12] | B17: Below 2°C | C17: USA | D17: Final Energy|Residential and Commercial|Electricity | E17: EJ/yr | F17: Final Energy|Residential and Commercial|Electricity | G17: demand_projection | H17: elc_buildings | I17: 2025 | J17: 13.0774 | K17: Final Energy|Residential and Commercial|Electricity
A18: Downscaling[MESSAGEix-GLOBIOM 1.1-M-R12] | B18: Below 2°C | C18: USA | D18: Final Energy|Residential and Commercial|Electricity | E18: EJ/yr | F18: Final Energy|Residential and Commercial|Electricity | G18: demand_projection | H18: elc_buildings | I18: 2030 | J18: 13.197 | K18: Final Energy|Residential and Commercial|Electricity
A19: Downscaling[MESSAGEix-GLOBIOM 1.1-M-R12] | B19: Below 2°C | C19: USA | D19: Final Energy|Residential and Commercial|Electricity | E19: EJ/yr | F19: Final Energy|Residential and Commercial|Electricity | G19: demand_projection | H19: elc_buildings | I19: 2035 | J19: 13.4583 | K19: Final Energy|Residential and Commercial|Electricity
A20: Downscaling[MESSAGEix-GLOBIOM 1.1-M-R12] | B20: Below 2°C | C20: USA | D20: Final Energy|Residential and Commercial|Electricity | E20: EJ/yr | F20: Final Energy|Residential and Commercial|Electricity | G20: demand_projection | H20: elc_buildings | I20: 2040 | J20: 14.0802 | K20: Final Energy|Residential and Commercial|Electricity
... A36: Downscaling[MESSAGEix-GLOBIOM 1.1-M-R12] | B36: Below 2°C | C36: USA | D36: Secondary Energy|Hydrogen | E36: EJ/yr | F36: Secondary Energy|Hydrogen | G36: demand_projection | H36: hydrogen_allsect | I36: 2050 | J36: 0.4343 | K36: Secondary Energy|Hydrogen
A37: Downscaling[MESSAGEix-GLOBIOM 1.1-M-R12] | B37: Below 2°C | C37: USA | D37: Emissions|CO2|Power (estimated) | E37: Mt CO2 | F37: Secondary Energy|Electricity|Coal | G37: elec_co2 | I37: 2020 | J37: 448.7842 | K37: Secondary Energy|Electricity|Coal | L37: 94
A38: Downscaling[MESSAGEix-GLOBIOM 1.1-M-R12] | B38: Below 2°C | C38: USA | D38: Emissions|CO2|Power (estimated) | E38: Mt CO2 | F38: Secondary Energy|Electricity|Coal | G38: elec_co2 | I38: 2025 | J38: 230.9298 | K38: Secondary Energy|Electricity|Coal | L38: 94
A39: Downscaling[MESSAGEix-GLOBIOM 1.1-M-R12] | B39: Below 2°C | C39: USA | D39: Emissions|CO2|Power (estimated) | E39: Mt CO2 | F39: Secondary Energy|Electricity|Coal | G39: elec_co2 | I39: 2030 | J39: 69.795 | K39: Secondary Energy|Electricity|Coal | L39: 94
A40: Downscaling[MESSAGEix-GLOBIOM 1.1-M-R12] | B40: Below 2°C | C40: USA | D40: Emissions|CO2|Power (estimated) | E40: Mt CO2 | F40: Secondary Energy|Electricity|Coal | G40: elec_co2 | I40: 2035 | J40: 36.143 | K40: Secondary Energy|Electricity|Coal | L40: 94
A41: Downscaling[MESSAGEix-GLOBIOM 1.1-M-R12] | B41: Below 2°C | C41: USA | D41: Emissions|CO2|Power (estimated) | E41: Mt CO2 | F41: Secondary Energy|Electricity|Coal | G41: elec_co2 | I41: 2040 | J41: 15.5476 | K41: Secondary Energy|Electricity|Coal | L41: 94
A42: Downscaling[MESSAGEix-GLOBIOM 1.1-M-R12] | B42: Below 2°C | C42: USA | D42: Emissions|CO2|Power (estimated) | E42: Mt CO2 | F42: Secondary Energy|Electricity|Coal | G42: elec_co2 | I42: 2045 | J42: 4.8786 | K42: Secondary Energy|Electricity|Coal | L42: 94
A43: Downscaling[MESSAGEix-GLOBIOM 1.1-M-R12] | B43: Below 2°C | C43: USA | D43: Emissions|CO2|Power (estimated) | E43: Mt CO2 | F43: Secondary Energy|Electricity|Coal | G43: elec_co2 | I43: 2050 | J43: 0.5076 | K43: Secondary Energy|Electricity|Coal | L43: 94
A44: Downscaling[MESSAGEix-GLOBIOM 1.1-M-R12] | B44: Below 2°C | C44: USA | D44: Emissions|CO2|Power (estimated) | E44: Mt CO2 | F44: Secondary Energy|Electricity|Gas | G44: elec_co2 | I44: 2020 | J44: 241.164 | K44: Secondary Energy|Electricity|Gas | L44: 55
A45: Downscaling[MESSAGEix-GLOBIOM 1.1-M-R12] | B45: Below 2°C | C45: USA | D45: Emissions|CO2|Power (estimated) | E45: Mt CO2 | F45: Secondary Energy|Electricity|Gas | G45: elec_co2 | I45: 2025 | J45: 340.879 | K45: Secondary Energy|Electricity|Gas | L45: 55
A46: Downscaling[MESSAGEix-GLOBIOM 1.1-M-R12] | B46: Below 2°C | C46: USA | D46: Emissions|CO2|Power (estimated) | E46: Mt CO2 | F46: Secondary Energy|Electricity|Gas | G46: elec_co2 | I46: 2030 | J46: 371.5855 | K46: Secondary Energy|Electricity|Gas | L46: 55
A47: Downscaling[MESSAGEix-GLOBIOM 1.1-M-R12] | B47: Below 2°C | C47: USA | D47: Emissions|CO2|Power (estimated) | E47: Mt CO2 | F47: Secondary Energy|Electricity|Gas | G47: elec_co2 | I47: 2035 | J47: 438.0475 | K47: Secondary Energy|Electricity|Gas | L47: 55
A48: Downscaling[MESSAGEix-GLOBIOM 1.1-M-R12] | B48: Below 2°C | C48: USA | D48: Emissions|CO2|Power (estimated) | E48: Mt CO2 | F48: Secondary Energy|Electricity|Gas | G48: elec_co2 | I48: 2040 | J48: 480.5075 | K48: Secondary Energy|Electricity|Gas | L48: 55
... A57: Downscaling[MESSAGEix-GLOBIOM 1.1-M-R12] | B57: Below 2°C | C57: USA | D57: Emissions|CO2|Power (estimated) | E57: Mt CO2 | F57: Secondary Energy|Electricity|Oil | G57: elec_co2 | I57: 2050 | J57: 0 | K57: Secondary Energy|Electricity|Oil | L57: 70
A58: Downscaling[MESSAGEix-GLOBIOM 1.1-M-R12] | B58: Below 2°C | C58: USA | D58: Price|Primary Energy|Biomass | E58: US$2010/GJ | F58: Price|Primary Energy|Biomass | G58: fuel_supply | H58: bioenergy | I58: 2020 | J58: 4.4685 | K58: Price|Primary Energy|Biomass
A59: Downscaling[MESSAGEix-GLOBIOM 1.1-M-R12] | B59: Below 2°C | C59: USA | D59: Price|Primary Energy|Biomass | E59: US$2010/GJ | F59: Price|Primary Energy|Biomass | G59: fuel_supply | H59: bioenergy | I59: 2025 | J59: 3.3054 | K59: Price|Primary Energy|Biomass
A60: Downscaling[MESSAGEix-GLOBIOM 1.1-M-R12] | B60: Below 2°C | C60: USA | D60: Price|Primary Energy|Biomass | E60: US$2010/GJ | F60: Price|Primary Energy|Biomass | G60: fuel_supply | H60: bioenergy | I60: 2030 | J60: 6.8269 | K60: Price|Primary Energy|Biomass
A61: Downscaling[MESSAGEix-GLOBIOM 1.1-M-R12] | B61: Below 2°C | C61: USA | D61: Price|Primary Energy|Biomass | E61: US$2010/GJ | F61: Price|Primary Energy|Biomass | G61: fuel_supply | H61: bioenergy | I61: 2035 | J61: 4.957 | K61: Price|Primary Energy|Biomass
A62: Downscaling[MESSAGEix-GLOBIOM 1.1-M-R12] | B62: Below 2°C | C62: USA | D62: Price|Primary Energy|Biomass | E62: US$2010/GJ | F62: Price|Primary Energy|Biomass | G62: fuel_supply | H62: bioenergy | I62: 2040 | J62: 8.9973 | K62: Price|Primary Energy|Biomass
A63: Downscaling[MESSAGEix-GLOBIOM 1.1-M-R12] | B63: Below 2°C | C63: USA | D63: Price|Primary Energy|Biomass | E63: US$2010/GJ | F63: Price|Primary Energy|Biomass | G63: fuel_supply | H63: bioenergy | I63: 2045 | J63: 8.1872 | K63: Price|Primary Energy|Biomass
...
