Workbook

Sheet Veda
G1: 1-25,36-40 | H1: 8 | I1: 13 | J1: 18 | K1: 23 | L1: 28 | M1: 33 | N1: 38
D2: ="~Inputcell: "&_xlfn.TEXTJOIN(",",TRUE,G1:EE1) -> ~Inputcell: 1-25,36-40,8,13,18,23,28,33,38
D3: 3
D5: =VLOOKUP(D3,$C$9:$E$999,2,FALSE) -> ts_annual | E5: =VLOOKUP(D3,$C$9:$E$999,3,FALSE) -> C3
B7: ~Scenmap
A8: priority | B8: scen | C8: case_no | D8: timeslice | E8: climate | AM8: bio price multiplier
A9: 5 | B9: =VLOOKUP(E9,$AK$9:$AL$15,2,FALSE)&"."&VLOOKUP(D9,$AH$9:$AI$24,2,FALSE) -> e 1.5 deg no OS.xAnn | C9: 1 | D9: =VLOOKUP(AJ9,$AG$9:$AH$22,2,FALSE) -> ts_annual | E9: C1 | G9: Limit warming to 1.5°C (>50%) with no or limited overshoot | AG9: 1 | AH9: ts_annual | AI9: xAnn | AJ9: 1 | AK9: C1 | AL9: e 1.5 deg no OS | AM9: 5
A10: 5 | B10: =VLOOKUP(E10,$AK$9:$AL$15,2,FALSE)&"."&VLOOKUP(D10,$AH$9:$AI$24,2,FALSE) -> d 1.5 deg OS.xAnn | C10: =C9+1 -> 2 | D10: =VLOOKUP(AJ10,$AG$9:$AH$22,2,FALSE) -> ts_annual | E10: C2 | G10: Limit warming to 1.5°C (>67%) with high overshoot | S10: IEA | AG10: 2 | AH10: ts_12t | AI10: x12 | AJ10: 1 | AK10: C2 | AL10: d 1.5 deg OS | AM10: 4
A11: 5 | B11: =VLOOKUP(E11,$AK$9:$AL$15,2,FALSE)&"."&VLOOKUP(D11,$AH$9:$AI$24,2,FALSE) -> c 2 deg (67%).xAnn | C11: =C10+1 -> 3 | D11: =VLOOKUP(AJ11,$AG$9:$AH$22,2,FALSE) -> ts_annual | E11: C3 | G11: Limit warming to 2°C (>67%) with higher action post-2030 | S11: 2022 | AG11: 3 | AH11: ts_012 | AI11: =AH11 -> ts_012 | AJ11: 1 | AK11: C3 | AL11: c 2 deg (67%) | AM11: 3
A12: 5 | B12: =VLOOKUP(E12,$AK$9:$AL$15,2,FALSE)&"."&VLOOKUP(D12,$AH$9:$AI$24,2,FALSE) -> b 2 deg (50%).xAnn | C12: =C11+1 -> 4 | D12: =VLOOKUP(AJ12,$AG$9:$AH$22,2,FALSE) -> ts_annual | E12: C4 | G12: Limit warming to 2°C (>50%) with immediate action | S12: =SUMIFS(iea_data!I3:I9999,iea_data!$B$3:$B$9999,Veda!$S$11)+T28-T29 -> 44.72 | T12: base-year generation (TWh) | AG12: 4 | AH12: ts_030 | AI12: =AH12 -> ts_030 | AJ12: 1 | AK12: C4 | AL12: b 2 deg (50%) | AM12: 3
A13: 5 | B13: =VLOOKUP(E13,$AK$9:$AL$15,2,FALSE)&"."&VLOOKUP(D13,$AH$9:$AI$24,2,FALSE) -> a 3 deg.xAnn | C13: =C12+1 -> 5 | D13: =VLOOKUP(AJ13,$AG$9:$AH$22,2,FALSE) -> ts_annual | E13: C7 | G13: Likely above 3°C warming with limited mitigation | AG13: 5 | AH13: ts_048 | AI13: =AH13 -> ts_048 | AJ13: 1 | AK13: C7 | AL13: a 3 deg | AM13: 1.5
A14: 5 | B14: =VLOOKUP(E14,$AK$9:$AL$15,2,FALSE)&"."&VLOOKUP(D14,$AH$9:$AI$24,2,FALSE) -> e 1.5 deg no OS.x12 | C14: =C13+1 -> 6 | D14: =VLOOKUP(AJ14,$AG$9:$AH$22,2,FALSE) -> ts_12t | E14: =E9 -> C1 | T14: =S12 -> 44.72 | U14: =$S$12*J15 -> 44.2728 | V14: =$S$12*K15 -> 44.72 | W14: =$S$12*L15 -> 45.1672 | X14: =$S$12*M15 -> 50.5336 | Y14: =$S$12*N15 -> 53.664 | Z14: =$S$12*O15 -> 59.4776 | AG14: 6 | AH14: ts_072 | AI14: =AH14 -> ts_072 | AJ14: =AJ9+1 -> 2
A15: 5 | B15: =VLOOKUP(E15,$AK$9:$AL$15,2,FALSE)&"."&VLOOKUP(D15,$AH$9:$AI$24,2,FALSE) -> d 1.5 deg OS.x12 | C15: =C14+1 -> 7 | D15: =VLOOKUP(AJ15,$AG$9:$AH$22,2,FALSE) -> ts_12t | E15: =E10 -> C2 | G15: Electricity growth relative to 2020 | I15: =SUMIFS(ar6_r10!$F$2:$F$999,ar6_r10!$A$2:$A$999,Veda!$E$5,ar6_r10!$C$2:$C$999,Veda!I$17,ar6_r10!$M$2:$M$999,Veda!$G15) -> 1 | J15: =SUMIFS(ar6_r10!$F$2:$F$999,ar6_r10!$A$2:$A$999,Veda!$E$5,ar6_r10!$C$2:$C$999,Veda!J$17,ar6_r10!$M$2:$M$999,Veda!$G15) -> 0.99 | K15: =SUMIFS(ar6_r10!$F$2:$F$999,ar6_r10!$A$2:$A$999,Veda!$E$5,ar6_r10!$C$2:$C$999,Veda!K$17,ar6_r10!$M$2:$M$999,Veda!$G15) -> 1 | L15: =SUMIFS(ar6_r10!$F$2:$F$999,ar6_r10!$A$2:$A$999,Veda!$E$5,ar6_r10!$C$2:$C$999,Veda!L$17,ar6_r10!$M$2:$M$999,Veda!$G15) -> 1.01 | M15: =SUMIFS(ar6_r10!$F$2:$F$999,ar6_r10!$A$2:$A$999,Veda!$E$5,ar6_r10!$C$2:$C$999,Veda!M$17,ar6_r10!$M$2:$M$999,Veda!$G15) -> 1.13 | N15: =SUMIFS(ar6_r10!$F$2:$F$999,ar6_r10!$A$2:$A$999,Veda!$E$5,ar6_r10!$C$2:$C$999,Veda!N$17,ar6_r10!$M$2:$M$999,Veda!$G15) -> 1.2 | O15: =SUMIFS(ar6_r10!$F$2:$F$999,ar6_r10!$A$2:$A$999,Veda!$E$5,ar6_r10!$C$2:$C$999,Veda!O$17,ar6_r10!$M$2:$M$999,Veda!$G15) -> 1.33 | AG15: 7 | AH15: ts_144 | AI15: =AH15 -> ts_144 | AJ15: =AJ10+1 -> 2
A16: 5 | B16: =VLOOKUP(E16,$AK$9:$AL$15,2,FALSE)&"."&VLOOKUP(D16,$AH$9:$AI$24,2,FALSE) -> c 2 deg (67%).x12 | C16: =C15+1 -> 8 | D16: =VLOOKUP(AJ16,$AG$9:$AH$22,2,FALSE) -> ts_12t | E16: =E11 -> C3 | S16: ~TFM_INS-TS | AG16: 8 | AH16: ts_288 | AI16: =AH16 -> ts_288 | AJ16: =AJ11+1 -> 2
A17: 5 | B17: =VLOOKUP(E17,$AK$9:$AL$15,2,FALSE)&"."&VLOOKUP(D17,$AH$9:$AI$24,2,FALSE) -> b 2 deg (50%).x12 | C17: =C16+1 -> 9 | D17: =VLOOKUP(AJ17,$AG$9:$AH$22,2,FALSE) -> ts_12t | E17: =E12 -> C4 | I17: 2020 | J17: =U17 -> 2025 | K17: =V17 -> 2030 | L17: =W17 -> 2035 | M17: =X17 -> 2040 | N17: =Y17 -> 2045 | O17: =Z17 -> 2050 | S17: commodity | T17: 2022 | U17: 2025 | V17: 2030 | W17: 2035 | X17: 2040 | Y17: 2045 | Z17: 2050 | AA17: attribute | AG17: 9 | AH17: s1v1_d | AI17: f2d96 | AJ17: =AJ12+1 -> 2
A18: 5 | B18: =VLOOKUP(E18,$AK$9:$AL$15,2,FALSE)&"."&VLOOKUP(D18,$AH$9:$AI$24,2,FALSE) -> a 3 deg.x12 | C18: =C17+1 -> 10 | D18: =VLOOKUP(AJ18,$AG$9:$AH$22,2,FALSE) -> ts_12t | E18: =E13 -> C7 | G18: Hydrogen as a share of electricity | I18: =SUMIFS(ar6_r10!$F$2:$F$999,ar6_r10!$A$2:$A$999,Veda!$E$5,ar6_r10!$C$2:$C$999,Veda!I$17,ar6_r10!$M$2:$M$999,Veda!$G18) -> 0 | J18: =SUMIFS(ar6_r10!$F$2:$F$999,ar6_r10!$A$2:$A$999,Veda!$E$5,ar6_r10!$C$2:$C$999,Veda!J$17,ar6_r10!$M$2:$M$999,Veda!$G18) -> 0 | K18: =SUMIFS(ar6_r10!$F$2:$F$999,ar6_r10!$A$2:$A$999,Veda!$E$5,ar6_r10!$C$2:$C$999,Veda!K$17,ar6_r10!$M$2:$M$999,Veda!$G18) -> 0 | L18: =SUMIFS(ar6_r10!$F$2:$F$999,ar6_r10!$A$2:$A$999,Veda!$E$5,ar6_r10!$C$2:$C$999,Veda!L$17,ar6_r10!$M$2:$M$999,Veda!$G18) -> 0.01 | M18: =SUMIFS(ar6_r10!$F$2:$F$999,ar6_r10!$A$2:$A$999,Veda!$E$5,ar6_r10!$C$2:$C$999,Veda!M$17,ar6_r10!$M$2:$M$999,Veda!$G18) -> 0.01 | N18: =SUMIFS(ar6_r10!$F$2:$F$999,ar6_r10!$A$2:$A$999,Veda!$E$5,ar6_r10!$C$2:$C$999,Veda!N$17,ar6_r10!$M$2:$M$999,Veda!$G18) -> 0.02 | O18: =SUMIFS(ar6_r10!$F$2:$F$999,ar6_r10!$A$2:$A$999,Veda!$E$5,ar6_r10!$C$2:$C$999,Veda!O$17,ar6_r10!$M$2:$M$999,Veda!$G18) -> 0.03 | S18: hydrogen_allsect | T18: =I18*T$14 -> 0 | U18: =J18*U$14 -> 0 | V18: =K18*V$14 -> 0 | W18: =L18*W$14 -> 0.451672 | X18: =M18*X$14 -> 0.505336 | Y18: =N18*Y$14 -> 1.07328 | Z18: =O18*Z$14 -> 1.784328 | AA18: demand | AG18: 10 | AH18: ts_096 | AI18: e96 | AJ18: =AJ13+1 -> 2
A19: 5 | B19: =VLOOKUP(E19,$AK$9:$AL$15,2,FALSE)&"."&VLOOKUP(D19,$AH$9:$AI$24,2,FALSE) -> e 1.5 deg no OS.ts_012 | C19: =C18+1 -> 11 | D19: =VLOOKUP(AJ19,$AG$9:$AH$22,2,FALSE) -> ts_012 | E19: =E14 -> C1 | G19: Industry electricity share | I19: =SUMIFS(ar6_r10!$F$2:$F$999,ar6_r10!$A$2:$A$999,Veda!$E$5,ar6_r10!$C$2:$C$999,Veda!I$17,ar6_r10!$M$2:$M$999,Veda!$G19) -> 0.34 | J19: =SUMIFS(ar6_r10!$F$2:$F$999,ar6_r10!$A$2:$A$999,Veda!$E$5,ar6_r10!$C$2:$C$999,Veda!J$17,ar6_r10!$M$2:$M$999,Veda!$G19) -> 0.3 | K19: =SUMIFS(ar6_r10!$F$2:$F$999,ar6_r10!$A$2:$A$999,Veda!$E$5,ar6_r10!$C$2:$C$999,Veda!K$17,ar6_r10!$M$2:$M$999,Veda!$G19) -> 0.29 | L19: =SUMIFS(ar6_r10!$F$2:$F$999,ar6_r10!$A$2:$A$999,Veda!$E$5,ar6_r10!$C$2:$C$999,Veda!L$17,ar6_r10!$M$2:$M$999,Veda!$G19) -> 0.27 | M19: =SUMIFS(ar6_r10!$F$2:$F$999,ar6_r10!$A$2:$A$999,Veda!$E$5,ar6_r10!$C$2:$C$999,Veda!M$17,ar6_r10!$M$2:$M$999,Veda!$G19) -> 0.28 | N19: =SUMIFS(ar6_r10!$F$2:$F$999,ar6_r10!$A$2:$A$999,Veda!$E$5,ar6_r10!$C$2:$C$999,Veda!N$17,ar6_r10!$M$2:$M$999,Veda!$G19) -> 0.29 | O19: =SUMIFS(ar6_r10!$F$2:$F$999,ar6_r10!$A$2:$A$999,Veda!$E$5,ar6_r10!$C$2:$C$999,Veda!O$17,ar6_r10!$M$2:$M$999,Veda!$G19) -> 0.29 | S19: elc_industry | T19: =I19*T$14 -> 15.2048 | U19: =J19*U$14 -> 13.28184 | V19: =K19*V$14 -> 12.9688 | W19: =L19*W$14 -> 12.195144 | X19: =M19*X$14 -> 14.149408 | Y19: =N19*Y$14 -> 15.56256 | Z19: =O19*Z$14 -> 17.248504 | AA19: demand | AG19: 11 | AH19: s1p1v1_d | AI19: d9d | AJ19: =AJ14+1 -> 3
A20: 5 | B20: =VLOOKUP(E20,$AK$9:$AL$15,2,FALSE)&"."&VLOOKUP(D20,$AH$9:$AI$24,2,FALSE) -> d 1.5 deg OS.ts_012 | C20: =C19+1 -> 12 | D20: =VLOOKUP(AJ20,$AG$9:$AH$22,2,FALSE) -> ts_012 | E20: =E15 -> C2 | G20: Residential and commercial electricity share | I20: =SUMIFS(ar6_r10!$F$2:$F$999,ar6_r10!$A$2:$A$999,Veda!$E$5,ar6_r10!$C$2:$C$999,Veda!I$17,ar6_r10!$M$2:$M$999,Veda!$G20) -> 0.64 | J20: =SUMIFS(ar6_r10!$F$2:$F$999,ar6_r10!$A$2:$A$999,Veda!$E$5,ar6_r10!$C$2:$C$999,Veda!J$17,ar6_r10!$M$2:$M$999,Veda!$G20) -> 0.67 | K20: =SUMIFS(ar6_r10!$F$2:$F$999,ar6_r10!$A$2:$A$999,Veda!$E$5,ar6_r10!$C$2:$C$999,Veda!K$17,ar6_r10!$M$2:$M$999,Veda!$G20) -> 0.67 | L20: =SUMIFS(ar6_r10!$F$2:$F$999,ar6_r10!$A$2:$A$999,Veda!$E$5,ar6_r10!$C$2:$C$999,Veda!L$17,ar6_r10!$M$2:$M$999,Veda!$G20) -> 0.65 | M20: =SUMIFS(ar6_r10!$F$2:$F$999,ar6_r10!$A$2:$A$999,Veda!$E$5,ar6_r10!$C$2:$C$999,Veda!M$17,ar6_r10!$M$2:$M$999,Veda!$G20) -> 0.62 | N20: =SUMIFS(ar6_r10!$F$2:$F$999,ar6_r10!$A$2:$A$999,Veda!$E$5,ar6_r10!$C$2:$C$999,Veda!N$17,ar6_r10!$M$2:$M$999,Veda!$G20) -> 0.59 | O20: =SUMIFS(ar6_r10!$F$2:$F$999,ar6_r10!$A$2:$A$999,Veda!$E$5,ar6_r10!$C$2:$C$999,Veda!O$17,ar6_r10!$M$2:$M$999,Veda!$G20) -> 0.58 | S20: elc_buildings | T20: =I20*T$14 -> 28.6208 | U20: =J20*U$14 -> 29.662776 | V20: =K20*V$14 -> 29.9624 | W20: =L20*W$14 -> 29.35868 | X20: =M20*X$14 -> 31.330832 | Y20: =N20*Y$14 -> 31.66176 | Z20: =O20*Z$14 -> 34.497008 | AA20: demand | AG20: 12 | AH20: s5p5v5_d | AI20: c15d | AJ20: =AJ15+1 -> 3
A21: 5 | B21: =VLOOKUP(E21,$AK$9:$AL$15,2,FALSE)&"."&VLOOKUP(D21,$AH$9:$AI$24,2,FALSE) -> c 2 deg (67%).ts_012 | C21: =C20+1 -> 13 | D21: =VLOOKUP(AJ21,$AG$9:$AH$22,2,FALSE) -> ts_012 | E21: =E16 -> C3 | G21: Transportation electricity share | I21: =SUMIFS(ar6_r10!$F$2:$F$999,ar6_r10!$A$2:$A$999,Veda!$E$5,ar6_r10!$C$2:$C$999,Veda!I$17,ar6_r10!$M$2:$M$999,Veda!$G21) -> 0.02 | J21: =SUMIFS(ar6_r10!$F$2:$F$999,ar6_r10!$A$2:$A$999,Veda!$E$5,ar6_r10!$C$2:$C$999,Veda!J$17,ar6_r10!$M$2:$M$999,Veda!$G21) -> 0.03 | K21: =SUMIFS(ar6_r10!$F$2:$F$999,ar6_r10!$A$2:$A$999,Veda!$E$5,ar6_r10!$C$2:$C$999,Veda!K$17,ar6_r10!$M$2:$M$999,Veda!$G21) -> 0.03 | L21: =SUMIFS(ar6_r10!$F$2:$F$999,ar6_r10!$A$2:$A$999,Veda!$E$5,ar6_r10!$C$2:$C$999,Veda!L$17,ar6_r10!$M$2:$M$999,Veda!$G21) -> 0.05 | M21: =SUMIFS(ar6_r10!$F$2:$F$999,ar6_r10!$A$2:$A$999,Veda!$E$5,ar6_r10!$C$2:$C$999,Veda!M$17,ar6_r10!$M$2:$M$999,Veda!$G21) -> 0.08 | N21: =SUMIFS(ar6_r10!$F$2:$F$999,ar6_r10!$A$2:$A$999,Veda!$E$5,ar6_r10!$C$2:$C$999,Veda!N$17,ar6_r10!$M$2:$M$999,Veda!$G21) -> 0.11 | O21: =SUMIFS(ar6_r10!$F$2:$F$999,ar6_r10!$A$2:$A$999,Veda!$E$5,ar6_r10!$C$2:$C$999,Veda!O$17,ar6_r10!$M$2:$M$999,Veda!$G21) -> 0.12 | S21: elc_transport | T21: =I21*T$14 -> 0.8944 | U21: =T21 -> 0.8944 | V21: =U21 -> 0.8944 | W21: =V21 -> 0.8944 | X21: =W21 -> 0.8944 | Y21: =X21 -> 0.8944 | Z21: =Y21 -> 0.8944 | AA21: demand | AC21: non-road transport demand assumed to be constant | AJ21: =AJ16+1 -> 3
A22: 5 | B22: =VLOOKUP(E22,$AK$9:$AL$15,2,FALSE)&"."&VLOOKUP(D22,$AH$9:$AI$24,2,FALSE) -> b 2 deg (50%).ts_012 | C22: =C21+1 -> 14 | D22: =VLOOKUP(AJ22,$AG$9:$AH$22,2,FALSE) -> ts_012 | E22: =E17 -> C4 | S22: elc_roadtransport | T22: =T14-SUM(T19:T21) -> 0 | U22: =U14-SUM(U19:U21) -> 0.433784 | V22: =V14-SUM(V19:V21) -> 0.8944 | W22: =W14-SUM(W19:W21) -> 2.718976 | X22: =X14-SUM(X19:X21) -> 4.15896 | Y22: =Y14-SUM(Y19:Y21) -> 5.54528 | Z22: =Z14-SUM(Z19:Z21) -> 6.837688 | AA22: demand | AJ22: =AJ17+1 -> 3
A23: 5 | B23: =VLOOKUP(E23,$AK$9:$AL$15,2,FALSE)&"."&VLOOKUP(D23,$AH$9:$AI$24,2,FALSE) -> a 3 deg.ts_012 | C23: =C22+1 -> 15 | D23: =VLOOKUP(AJ23,$AG$9:$AH$22,2,FALSE) -> ts_012 | E23: =E18 -> C7 | S23: * | AJ23: =AJ18+1 -> 3
A24: 5 | B24: =VLOOKUP(E24,$AK$9:$AL$15,2,FALSE)&"."&VLOOKUP(D24,$AH$9:$AI$24,2,FALSE) -> e 1.5 deg no OS.ts_030 | C24: =C23+1 -> 16 | D24: =VLOOKUP(AJ24,$AG$9:$AH$22,2,FALSE) -> ts_030 | E24: =E19 -> C1 | G24: CO2 price | I24: 0 | J24: 0 | K24: =SUMIFS(ar6_r10!$F$2:$F$999,ar6_r10!$A$2:$A$999,Veda!$E$5,ar6_r10!$C$2:$C$999,Veda!K$17,ar6_r10!$M$2:$M$999,Veda!$G24) -> 56.33 | L24: =SUMIFS(ar6_r10!$F$2:$F$999,ar6_r10!$A$2:$A$999,Veda!$E$5,ar6_r10!$C$2:$C$999,Veda!L$17,ar6_r10!$M$2:$M$999,Veda!$G24) -> 104.42 | M24: =SUMIFS(ar6_r10!$F$2:$F$999,ar6_r10!$A$2:$A$999,Veda!$E$5,ar6_r10!$C$2:$C$999,Veda!M$17,ar6_r10!$M$2:$M$999,Veda!$G24) -> 134.85 | N24: =SUMIFS(ar6_r10!$F$2:$F$999,ar6_r10!$A$2:$A$999,Veda!$E$5,ar6_r10!$C$2:$C$999,Veda!N$17,ar6_r10!$M$2:$M$999,Veda!$G24) -> 178.1 | O24: =SUMIFS(ar6_r10!$F$2:$F$999,ar6_r10!$A$2:$A$999,Veda!$E$5,ar6_r10!$C$2:$C$999,Veda!O$17,ar6_r10!$M$2:$M$999,Veda!$G24) -> 209.45 | S24: co2net | U24: 0 | V24: =K24/1000 -> 0.05633 | W24: =L24/1000 -> 0.10442 | X24: =M24/1000 -> 0.13485 | Y24: =N24/1000 -> 0.1781 | Z24: =O24/1000 -> 0.20945 | AA24: com_taxnet | AJ24: =AJ19+1 -> 4
A25: 5 | B25: =VLOOKUP(E25,$AK$9:$AL$15,2,FALSE)&"."&VLOOKUP(D25,$AH$9:$AI$24,2,FALSE) -> d 1.5 deg OS.ts_030 | C25: =C24+1 -> 17 | D25: =VLOOKUP(AJ25,$AG$9:$AH$22,2,FALSE) -> ts_030 | E25: =E20 -> C2 | AJ25: =AJ20+1 -> 4
A26: 5 | B26: =VLOOKUP(E26,$AK$9:$AL$15,2,FALSE)&"."&VLOOKUP(D26,$AH$9:$AI$24,2,FALSE) -> c 2 deg (67%).ts_030 | C26: =C25+1 -> 18 | D26: =VLOOKUP(AJ26,$AG$9:$AH$22,2,FALSE) -> ts_030 | E26: =E21 -> C3 | S26: ~TFM_INS-TS | AJ26: =AJ21+1 -> 4
A27: 5 | B27: =VLOOKUP(E27,$AK$9:$AL$15,2,FALSE)&"."&VLOOKUP(D27,$AH$9:$AI$24,2,FALSE) -> b 2 deg (50%).ts_030 | C27: =C26+1 -> 19 | D27: =VLOOKUP(AJ27,$AG$9:$AH$22,2,FALSE) -> ts_030 | E27: =E22 -> C4 | S27: process | T27: =T17 -> 2022 | U27: =U17 -> 2025 | V27: =V17 -> 2030 | W27: =W17 -> 2035 | X27: =X17 -> 2040 | Y27: =Y17 -> 2045 | Z27: =Z17 -> 2050 | AA27: attribute | AB27: limtype | AJ27: =AJ22+1 -> 4
A28: 5 | B28: =VLOOKUP(E28,$AK$9:$AL$15,2,FALSE)&"."&VLOOKUP(D28,$AH$9:$AI$24,2,FALSE) -> a 3 deg.ts_030 | C28: =C27+1 -> 20 | D28: =VLOOKUP(AJ28,$AG$9:$AH$22,2,FALSE) -> ts_030 | E28: =E23 -> C7 | Q28: =SUMIFS(iea_data!G3:G9999,iea_data!$B$3:$B$9999,Veda!$S$11) -> 0 | S28: Trd_electricity import | T28: =Q28 -> 0 | AA28: ACT_BND | AB28: FX | AJ28: =AJ23+1 -> 4
A29: 5 | B29: =VLOOKUP(E29,$AK$9:$AL$15,2,FALSE)&"."&VLOOKUP(D29,$AH$9:$AI$24,2,FALSE) -> e 1.5 deg no OS.ts_048 | C29: =C28+1 -> 21 | D29: =VLOOKUP(AJ29,$AG$9:$AH$22,2,FALSE) -> ts_048 | E29: =E24 -> C1 | Q29: =SUMIFS(iea_data!H3:H9999,iea_data!$B$3:$B$9999,Veda!$S$11) -> 0 | S29: Trd_electricity export | T29: =-1*Q29 -> 0 | AA29: ACT_BND | AB29: FX | AJ29: =AJ24+1 -> 5
A30: 5 | B30: =VLOOKUP(E30,$AK$9:$AL$15,2,FALSE)&"."&VLOOKUP(D30,$AH$9:$AI$24,2,FALSE) -> d 1.5 deg OS.ts_048 | C30: =C29+1 -> 22 | D30: =VLOOKUP(AJ30,$AG$9:$AH$22,2,FALSE) -> ts_048 | E30: =E25 -> C2 | AJ30: =AJ25+1 -> 5
A31: 5 | B31: =VLOOKUP(E31,$AK$9:$AL$15,2,FALSE)&"."&VLOOKUP(D31,$AH$9:$AI$24,2,FALSE) -> c 2 deg (67%).ts_048 | C31: =C30+1 -> 23 | D31: =VLOOKUP(AJ31,$AG$9:$AH$22,2,FALSE) -> ts_048 | E31: =E26 -> C3 | AJ31: =AJ26+1 -> 5
A32: 5 | B32: =VLOOKUP(E32,$AK$9:$AL$15,2,FALSE)&"."&VLOOKUP(D32,$AH$9:$AI$24,2,FALSE) -> b 2 deg (50%).ts_048 | C32: =C31+1 -> 24 | D32: =VLOOKUP(AJ32,$AG$9:$AH$22,2,FALSE) -> ts_048 | E32: =E27 -> C4 | AJ32: =AJ27+1 -> 5
A33: 5 | B33: =VLOOKUP(E33,$AK$9:$AL$15,2,FALSE)&"."&VLOOKUP(D33,$AH$9:$AI$24,2,FALSE) -> a 3 deg.ts_048 | C33: =C32+1 -> 25 | D33: =VLOOKUP(AJ33,$AG$9:$AH$22,2,FALSE) -> ts_048 | E33: =E28 -> C7 | AJ33: =AJ28+1 -> 5
A34: 5 | B34: =VLOOKUP(E34,$AK$9:$AL$15,2,FALSE)&"."&VLOOKUP(D34,$AH$9:$AI$24,2,FALSE) -> e 1.5 deg no OS.ts_072 | C34: =C33+1 -> 26 | D34: =VLOOKUP(AJ34,$AG$9:$AH$22,2,FALSE) -> ts_072 | E34: =E29 -> C1 | AJ34: =AJ29+1 -> 6
A35: 5 | B35: =VLOOKUP(E35,$AK$9:$AL$15,2,FALSE)&"."&VLOOKUP(D35,$AH$9:$AI$24,2,FALSE) -> d 1.5 deg OS.ts_072 | C35: =C34+1 -> 27 | D35: =VLOOKUP(AJ35,$AG$9:$AH$22,2,FALSE) -> ts_072 | E35: =E30 -> C2 | AJ35: =AJ30+1 -> 6
A36: 5 | B36: =VLOOKUP(E36,$AK$9:$AL$15,2,FALSE)&"."&VLOOKUP(D36,$AH$9:$AI$24,2,FALSE) -> c 2 deg (67%).ts_072 | C36: =C35+1 -> 28 | D36: =VLOOKUP(AJ36,$AG$9:$AH$22,2,FALSE) -> ts_072 | E36: =E31 -> C3 | G36: C7 | AJ36: =AJ31+1 -> 6
A37: 5 | B37: =VLOOKUP(E37,$AK$9:$AL$15,2,FALSE)&"."&VLOOKUP(D37,$AH$9:$AI$24,2,FALSE) -> b 2 deg (50%).ts_072 | C37: =C36+1 -> 29 | D37: =VLOOKUP(AJ37,$AG$9:$AH$22,2,FALSE) -> ts_072 | E37: =E32 -> C4 | G37: Gas Price | I37: =SUMIFS(ar6_r10!$F$2:$F$999,ar6_r10!$A$2:$A$999,Veda!$G$36,ar6_r10!$C$2:$C$999,Veda!I$17,ar6_r10!$M$2:$M$999,Veda!$G37) -> 1 | J37: =SUMIFS(ar6_r10!$F$2:$F$999,ar6_r10!$A$2:$A$999,Veda!$G$36,ar6_r10!$C$2:$C$999,Veda!J$17,ar6_r10!$M$2:$M$999,Veda!$G37) -> 1.03 | K37: =SUMIFS(ar6_r10!$F$2:$F$999,ar6_r10!$A$2:$A$999,Veda!$G$36,ar6_r10!$C$2:$C$999,Veda!K$17,ar6_r10!$M$2:$M$999,Veda!$G37) -> 1.13 | L37: =SUMIFS(ar6_r10!$F$2:$F$999,ar6_r10!$A$2:$A$999,Veda!$G$36,ar6_r10!$C$2:$C$999,Veda!L$17,ar6_r10!$M$2:$M$999,Veda!$G37) -> 1.16 | M37: =SUMIFS(ar6_r10!$F$2:$F$999,ar6_r10!$A$2:$A$999,Veda!$G$36,ar6_r10!$C$2:$C$999,Veda!M$17,ar6_r10!$M$2:$M$999,Veda!$G37) -> 1.19 | N37: =SUMIFS(ar6_r10!$F$2:$F$999,ar6_r10!$A$2:$A$999,Veda!$G$36,ar6_r10!$C$2:$C$999,Veda!N$17,ar6_r10!$M$2:$M$999,Veda!$G37) -> 1.27 | O37: =SUMIFS(ar6_r10!$F$2:$F$999,ar6_r10!$A$2:$A$999,Veda!$G$36,ar6_r10!$C$2:$C$999,Veda!O$17,ar6_r10!$M$2:$M$999,Veda!$G37) -> 1.31 | AJ37: =AJ32+1 -> 6
A38: 5 | B38: =VLOOKUP(E38,$AK$9:$AL$15,2,FALSE)&"."&VLOOKUP(D38,$AH$9:$AI$24,2,FALSE) -> a 3 deg.ts_072 | C38: =C37+1 -> 30 | D38: =VLOOKUP(AJ38,$AG$9:$AH$22,2,FALSE) -> ts_072 | E38: =E33 -> C7 | G38: Coal Price | I38: =SUMIFS(ar6_r10!$F$2:$F$999,ar6_r10!$A$2:$A$999,Veda!$G$36,ar6_r10!$C$2:$C$999,Veda!I$17,ar6_r10!$M$2:$M$999,Veda!$G38) -> 1 | J38: =SUMIFS(ar6_r10!$F$2:$F$999,ar6_r10!$A$2:$A$999,Veda!$G$36,ar6_r10!$C$2:$C$999,Veda!J$17,ar6_r10!$M$2:$M$999,Veda!$G38) -> 1.03 | K38: =SUMIFS(ar6_r10!$F$2:$F$999,ar6_r10!$A$2:$A$999,Veda!$G$36,ar6_r10!$C$2:$C$999,Veda!K$17,ar6_r10!$M$2:$M$999,Veda!$G38) -> 1.09 | L38: =SUMIFS(ar6_r10!$F$2:$F$999,ar6_r10!$A$2:$A$999,Veda!$G$36,ar6_r10!$C$2:$C$999,Veda!L$17,ar6_r10!$M$2:$M$999,Veda!$G38) -> 1.18 | M38: =SUMIFS(ar6_r10!$F$2:$F$999,ar6_r10!$A$2:$A$999,Veda!$G$36,ar6_r10!$C$2:$C$999,Veda!M$17,ar6_r10!$M$2:$M$999,Veda!$G38) -> 1.27 | N38: =SUMIFS(ar6_r10!$F$2:$F$999,ar6_r10!$A$2:$A$999,Veda!$G$36,ar6_r10!$C$2:$C$999,Veda!N$17,ar6_r10!$M$2:$M$999,Veda!$G38) -> 1.35 | O38: =SUMIFS(ar6_r10!$F$2:$F$999,ar6_r10!$A$2:$A$999,Veda!$G$36,ar6_r10!$C$2:$C$999,Veda!O$17,ar6_r10!$M$2:$M$999,Veda!$G38) -> 1.41 | AJ38: =AJ33+1 -> 6
A39: 5 | B39: =VLOOKUP(E39,$AK$9:$AL$15,2,FALSE)&"."&VLOOKUP(D39,$AH$9:$AI$24,2,FALSE) -> e 1.5 deg no OS.ts_144 | C39: =C38+1 -> 31 | D39: =VLOOKUP(AJ39,$AG$9:$AH$22,2,FALSE) -> ts_144 | E39: =E34 -> C1 | G39: Oil Price | I39: =SUMIFS(ar6_r10!$F$2:$F$999,ar6_r10!$A$2:$A$999,Veda!$G$36,ar6_r10!$C$2:$C$999,Veda!I$17,ar6_r10!$M$2:$M$999,Veda!$G39) -> 1 | J39: =SUMIFS(ar6_r10!$F$2:$F$999,ar6_r10!$A$2:$A$999,Veda!$G$36,ar6_r10!$C$2:$C$999,Veda!J$17,ar6_r10!$M$2:$M$999,Veda!$G39) -> 1.04 | K39: =SUMIFS(ar6_r10!$F$2:$F$999,ar6_r10!$A$2:$A$999,Veda!$G$36,ar6_r10!$C$2:$C$999,Veda!K$17,ar6_r10!$M$2:$M$999,Veda!$G39) -> 1.05 | L39: =SUMIFS(ar6_r10!$F$2:$F$999,ar6_r10!$A$2:$A$999,Veda!$G$36,ar6_r10!$C$2:$C$999,Veda!L$17,ar6_r10!$M$2:$M$999,Veda!$G39) -> 1.04 | M39: =SUMIFS(ar6_r10!$F$2:$F$999,ar6_r10!$A$2:$A$999,Veda!$G$36,ar6_r10!$C$2:$C$999,Veda!M$17,ar6_r10!$M$2:$M$999,Veda!$G39) -> 1.04 | N39: =SUMIFS(ar6_r10!$F$2:$F$999,ar6_r10!$A$2:$A$999,Veda!$G$36,ar6_r10!$C$2:$C$999,Veda!N$17,ar6_r10!$M$2:$M$999,Veda!$G39) -> 1.17 | O39: =SUMIFS(ar6_r10!$F$2:$F$999,ar6_r10!$A$2:$A$999,Veda!$G$36,ar6_r10!$C$2:$C$999,Veda!O$17,ar6_r10!$M$2:$M$999,Veda!$G39) -> 1.25 | AJ39: =AJ34+1 -> 7
A40: 5 | B40: =VLOOKUP(E40,$AK$9:$AL$15,2,FALSE)&"."&VLOOKUP(D40,$AH$9:$AI$24,2,FALSE) -> d 1.5 deg OS.ts_144 | C40: =C39+1 -> 32 | D40: =VLOOKUP(AJ40,$AG$9:$AH$22,2,FALSE) -> ts_144 | E40: =E35 -> C2 | G40: Biomass Price | I40: =SUMIFS(ar6_r10!$F$2:$F$999,ar6_r10!$A$2:$A$999,Veda!$G$36,ar6_r10!$C$2:$C$999,Veda!I$17,ar6_r10!$M$2:$M$999,Veda!$G40) -> 1 | J40: =SUMIFS(ar6_r10!$F$2:$F$999,ar6_r10!$A$2:$A$999,Veda!$G$36,ar6_r10!$C$2:$C$999,Veda!J$17,ar6_r10!$M$2:$M$999,Veda!$G40) -> 1.01 | K40: =SUMIFS(ar6_r10!$F$2:$F$999,ar6_r10!$A$2:$A$999,Veda!$G$36,ar6_r10!$C$2:$C$999,Veda!K$17,ar6_r10!$M$2:$M$999,Veda!$G40) -> 0.99 | L40: =SUMIFS(ar6_r10!$F$2:$F$999,ar6_r10!$A$2:$A$999,Veda!$G$36,ar6_r10!$C$2:$C$999,Veda!L$17,ar6_r10!$M$2:$M$999,Veda!$G40) -> 0.97 | M40: =SUMIFS(ar6_r10!$F$2:$F$999,ar6_r10!$A$2:$A$999,Veda!$G$36,ar6_r10!$C$2:$C$999,Veda!M$17,ar6_r10!$M$2:$M$999,Veda!$G40) -> 0.92 | N40: =SUMIFS(ar6_r10!$F$2:$F$999,ar6_r10!$A$2:$A$999,Veda!$G$36,ar6_r10!$C$2:$C$999,Veda!N$17,ar6_r10!$M$2:$M$999,Veda!$G40) -> 0.95 | O40: =SUMIFS(ar6_r10!$F$2:$F$999,ar6_r10!$A$2:$A$999,Veda!$G$36,ar6_r10!$C$2:$C$999,Veda!O$17,ar6_r10!$M$2:$M$999,Veda!$G40) -> 1.02 | AJ40: =AJ35+1 -> 7
A41: 5 | B41: =VLOOKUP(E41,$AK$9:$AL$15,2,FALSE)&"."&VLOOKUP(D41,$AH$9:$AI$24,2,FALSE) -> c 2 deg (67%).ts_144 | C41: =C40+1 -> 33 | D41: =VLOOKUP(AJ41,$AG$9:$AH$22,2,FALSE) -> ts_144 | E41: =E36 -> C3 | AJ41: =AJ36+1 -> 7
A42: 5 | B42: =VLOOKUP(E42,$AK$9:$AL$15,2,FALSE)&"."&VLOOKUP(D42,$AH$9:$AI$24,2,FALSE) -> b 2 deg (50%).ts_144 | C42: =C41+1 -> 34 | D42: =VLOOKUP(AJ42,$AG$9:$AH$22,2,FALSE) -> ts_144 | E42: =E37 -> C4 | AJ42: =AJ37+1 -> 7
...

Sheet fuel_prices
A9: Fuel Prices
A10: iso | B10: gas_low | C10: gas_high | D10: coal_low | E10: coal_high | F10: oil_low | G10: oil_high | H10: bioenergy_low | I10: bioenergy_high | J10: Notes
A11: NZL | B11: 13.7 | C11: 20.6 | D11: 12.2 | E11: 16.7 | F11: 48 | G11: 58 | H11: 20 | I11: 28 | J11: Domestic gas fields, phasing out coal

Sheet iea_data
A9: IEA Baseline Data
A10: iso | B10: year | C10: industry_twh | D10: buildings_agri_twh | E10: nonroad_transport_twh | F10: road_transport_twh | G10: imports_twh | H10: exports_twh | I10: total_production_twh
A11: NZL | B11: 2000 | C11: 18.46 | D11: 19.34 | E11: 0.07 | F11: 0 | G11: 0 | H11: 0 | I11: 39.39
A12: NZL | B12: 2001 | C12: 18.78 | D12: 19.91 | E12: 0.06 | F12: 0.01 | G12: 0 | H12: 0 | I12: 39.71
A13: NZL | B13: 2002 | C13: 19.18 | D13: 20.04 | E13: 0.06 | F13: 0.01 | G13: 0 | H13: 0 | I13: 40.73
A14: NZL | B14: 2003 | C14: 18.73 | D14: 20.75 | E14: 0.06 | F14: 0.01 | G14: 0 | H14: 0 | I14: 40.86
A15: NZL | B15: 2004 | C15: 19.54 | D15: 21.4 | E15: 0.07 | F15: 0.01 | G15: 0 | H15: 0 | I15: 42.77
A16: NZL | B16: 2005 | C16: 20.06 | D16: 21.71 | E16: 0.06 | F16: 0.01 | G16: 0 | H16: 0 | I16: 42.98
A17: NZL | B17: 2006 | C17: 19.57 | D17: 22.99 | E17: 0.06 | F17: 0.01 | G17: 0 | H17: 0 | I17: 43.54
A18: NZL | B18: 2007 | C18: 19.55 | D18: 23.37 | E18: 0.06 | F18: 0.01 | G18: 0 | H18: 0 | I18: 43.9
A19: NZL | B19: 2008 | C19: 19.36 | D19: 23.35 | E19: 0.06 | F19: 0 | G19: 0 | H19: 0 | I19: 43.93
A20: NZL | B20: 2009 | C20: 18.72 | D20: 23.72 | E20: 0.05 | F20: 0.01 | G20: 0 | H20: 0 | I20: 43.55
A21: NZL | B21: 2010 | C21: 20.09 | D21: 23.61 | E21: 0.06 | F21: 0.01 | G21: 0 | H21: 0 | I21: 45
A22: NZL | B22: 2011 | C22: 19.64 | D22: 23.49 | E22: 0.06 | F22: 0.01 | G22: 0 | H22: 0 | I22: 44.63
... A33: NZL | B33: 2022 | C33: 17.88 | D33: 24.67 | E33: 0.06 | F33: 0.13 | G33: 0 | H33: 0 | I33: 44.72

Sheet ar6_r10
A9: AR6 Scenario Drivers
A10: Category | B10: Region | C10: Year | D10: count | E10: mean | F10: median | G10: std | H10: min | I10: max | J10: q25 | K10: q75 | L10: category_description | M10: attribute
A11: C1 | B11: R10PAC_OECD | C11: 2020 | D11: 60 | E11: 0.46 | F11: 0.28 | G11: 0.84 | H11: 0 | I11: 3.32 | J11: 0 | K11: 0.28 | L11: Limit warming to 1.5°C (>50%) with no or limited overshoot | M11: CO2 price
A12: C1 | B12: R10PAC_OECD | C12: 2025 | D12: 60 | E12: 197.76 | F12: 174.96 | G12: 126.47 | H12: 33.32 | I12: 626.48 | J12: 121.06 | K12: 238.58 | L12: Limit warming to 1.5°C (>50%) with no or limited overshoot | M12: CO2 price
A13: C1 | B13: R10PAC_OECD | C13: 2030 | D13: 60 | E13: 261.78 | F13: 241.69 | G13: 129.13 | H13: 27.52 | I13: 673.46 | J13: 173.6 | K13: 320.88 | L13: Limit warming to 1.5°C (>50%) with no or limited overshoot | M13: CO2 price
A14: C1 | B14: R10PAC_OECD | C14: 2035 | D14: 60 | E14: 354.71 | F14: 335.39 | G14: 164.48 | H14: 92.8 | I14: 859.53 | J14: 227.05 | K14: 451.85 | L14: Limit warming to 1.5°C (>50%) with no or limited overshoot | M14: CO2 price
A15: C1 | B15: R10PAC_OECD | C15: 2040 | D15: 60 | E15: 458.15 | F15: 407.27 | G15: 216.6 | H15: 162.1 | I15: 1097.01 | J15: 287.98 | K15: 574.94 | L15: Limit warming to 1.5°C (>50%) with no or limited overshoot | M15: CO2 price
A16: C1 | B16: R10PAC_OECD | C16: 2045 | D16: 60 | E16: 551.41 | F16: 479.16 | G16: 249.14 | H16: 190.36 | I16: 1269.88 | J16: 352.78 | K16: 713.93 | L16: Limit warming to 1.5°C (>50%) with no or limited overshoot | M16: CO2 price
A17: C1 | B17: R10PAC_OECD | C17: 2050 | D17: 60 | E17: 631.32 | F17: 604.24 | G17: 264.83 | H17: 194.32 | I17: 1170.26 | J17: 409.79 | K17: 827.36 | L17: Limit warming to 1.5°C (>50%) with no or limited overshoot | M17: CO2 price
A18: C2 | B18: R10PAC_OECD | C18: 2020 | D18: 86 | E18: 0.79 | F18: 0 | G18: 1.67 | H18: 0 | I18: 11.08 | J18: 0 | K18: 0.28 | L18: Limit warming to 1.5°C (>67%) with high overshoot | M18: CO2 price
A19: C2 | B19: R10PAC_OECD | C19: 2025 | D19: 75 | E19: 45 | F19: 24.75 | G19: 48.96 | H19: 1.11 | I19: 220.01 | J19: 10.72 | K19: 68.18 | L19: Limit warming to 1.5°C (>67%) with high overshoot | M19: CO2 price
A20: C2 | B20: R10PAC_OECD | C20: 2030 | D20: 86 | E20: 60.99 | F20: 46.2 | G20: 58.39 | H20: 0 | I20: 293.35 | J20: 15.43 | K20: 90.62 | L20: Limit warming to 1.5°C (>67%) with high overshoot | M20: CO2 price
A21: C2 | B21: R10PAC_OECD | C21: 2035 | D21: 75 | E21: 195.24 | F21: 129.57 | G21: 290.37 | H21: 26.47 | I21: 2037.12 | J21: 87.35 | K21: 200.38 | L21: Limit warming to 1.5°C (>67%) with high overshoot | M21: CO2 price
A22: C2 | B22: R10PAC_OECD | C22: 2040 | D22: 86 | E22: 250.65 | F22: 172.09 | G22: 359.95 | H22: 0 | I22: 2600 | J22: 112.15 | K22: 257.75 | L22: Limit warming to 1.5°C (>67%) with high overshoot | M22: CO2 price
... A360: C7 | B360: R10PAC_OECD | C360: 2050 | D360: 7 | E360: 1 | F360: 1.02 | G360: 0.15 | H360: 0.83 | I360: 1.21 | J360: 0.86 | K360: 1.1 | L360: Likely above 3°C warming with limited mitigation | M360: Biomass price

Sheet ev_charging_uc
A10: =IFERROR(Veda!D5,"ts_12t") -> ts_annual | C10: day_night | D10: ts_012 | F10: day_night | G10: ts_030 | I10: day_night | J10: ts_048 | L10: day_night | M10: ts_072 | O10: day_night | P10: ts_144 | R10: day_night | S10: ts_288 | U10: day_night | V10: ts_annual | X10: day_night | Y10: ts_12t
C11: D | D11: S01aH01,S04aH01,S02aH01,S03aH01 | F11: D | G11: S02aH03,S04aH03,S06aH02,S06aH03,S01aH03,S05aH02,S05aH03,S03aH03,S03aH02,S01aH02,S04aH02,S02aH02 | I11: D | J11: S02aH02,S06aH04,S04aH03,S07aH04,S02aH03,S07aH03,S03aH04,S03aH02,S01aH02,S04aH04,S01aH03,S05aH02,S05aH03,S01aH04,S07aH02,S03aH03,S05aH04,S06aH02,S06aH03,S04aH02,S02aH04 | L11: D | M11: S04aH02,S09aH02,S09aH03,S11aH03,S11aH04,S02aH03,S07aH03,S03aH03,S04aH03,S07aH04,S08aH03,S09aH04,S08aH02,S02aH04,S10aH03,S05aH04,S06aH02,S06aH03,S10aH04,S10aH02,S06aH04,S08aH04,S11aH02,S01aH03,S05aH02,S05aH03,S03aH04,S03aH02,S01aH04,S07aH02,S02aH02,S01aH02,S04aH04 | O11: D | P11: S04aH02,S09aH02,S09aH03,S11aH03,S11aH04,S14aH03,S15aH03,S02aH03,S07aH03,S03aH02,S14aH02,S01aH03,S05aH02,S05aH03,S17aH04,S01aH02,S04aH04,S16aH02,S17aH03,S01aH04,S07aH02,S10aH02,S12aH04,S15aH04,S08aH02,S02aH04,S10aH03,S06aH04,S08aH04,S11aH02,S13aH02,S13aH03,S03aH03,S15aH02,S13aH04,S02aH02,S14aH04,S03aH04,S12aH03,S05aH04,S06aH02,S06aH03,S10aH04,S16aH04,S17aH02,S04aH03,S07aH04,S08aH03,S09aH04,S12aH02,S16aH03 | R11: D | S11: S05aH04,S06aH02,S06aH03,S10aH04,S16aH04,S17aH02,S02aH03,S07aH03,S08aH02,S19aH04,S21aH02,S01aH04,S07aH02,S18aH02,S03aH02,S14aH02,S21aH04,S13aH04,S04aH03,S07aH04,S08aH03,S09aH04,S12aH02,S16aH03,S02aH02,S14aH04,S03aH04,S12aH03,S20aH04,S04aH02,S09aH02,S09aH03,S11aH03,S11aH04,S14aH03,S15aH03,S18aH03,S19aH02,S19aH03,S06aH04,S08aH04,S11aH02,S13aH02,S13aH03,S18aH04,S03aH03,S15aH02,S20aH02,S10aH02,S12aH04,S15aH04,S21aH03,S01aH03,S05aH02,S05aH03,S17aH04,S01aH02,S04aH04,S16aH02,S17aH03,S02aH04,S10aH03,S20aH03 | U11: D | V11: AllSaAllH | X11: D | Y11: SaD,WaP,RaP,FaP,SaP,FaD,WaD,RaD
C12: N | D12: S03aH02,S02aH02,S01aH02,S04aH02 | F12: N | G12: S01aH01,S04aH01,S05aH04,S04aH04,S06aH01,S06aH04,S02aH04,S02aH01,S03aH04,S01aH04,S05aH01,S03aH01 | I12: N | J12: S03aH01,S02aH05,S02aH01,S01aH01,S04aH01,S05aH01,S01aH05,S06aH05,S04aH05,S06aH01,S07aH01,S07aH05,S03aH05,S05aH05 | L12: N | M12: S07aH05,S01aH01,S04aH01,S11aH01,S02aH01,S04aH05,S06aH01,S03aH05,S05aH05,S07aH01,S02aH05,S10aH05,S09aH01,S05aH01,S08aH01,S08aH05,S10aH01,S11aH05,S03aH01,S09aH05,S01aH05,S06aH05 | O12: N | P12: S07aH05,S01aH01,S04aH01,S11aH01,S17aH05,S15aH01,S16aH01,S09aH01,S13aH01,S01aH05,S06aH05,S12aH05,S08aH01,S08aH05,S10aH01,S11aH05,S04aH05,S06aH01,S14aH01,S03aH05,S05aH05,S12aH01,S02aH05,S10aH05,S16aH05,S14aH05,S15aH05,S03aH01,S09aH05,S13aH05,S05aH01,S07aH01,S17aH01,S02aH01 | R12: N | S12: S01aH06,S05aH07,S07aH01,S08aH06,S10aH07,S17aH01,S18aH01,S01aH01,S04aH01,S04aH06,S11aH01,S12aH06,S13aH06,S15aH06,S17aH05,S04aH05,S06aH01,S14aH01,S08aH01,S08aH05,S09aH07,S10aH01,S11aH05,S20aH05,S08aH07,S15aH01,S16aH01,S09aH06,S14aH07,S17aH07,S19aH06,S20aH01,S02aH01,S05aH06,S16aH07,S19aH01,S03aH01,S09aH05,S12aH07,S13aH05,S01aH07,S02aH07,S05aH01,S07aH06,S13aH07,S18aH06,S07aH05,S18aH07,S19aH05,S21aH07,S02aH05,S06aH07,S07aH07,S10aH05,S16aH05,S21aH05,S06aH06,S14aH05,S15aH05,S18aH05,S21aH01,S15aH07,S16aH06,S17aH06,S20aH06,S09aH01,S11aH07,S13aH01,S14aH06,S20aH07,S21aH06,S01aH05,S03aH06,S03aH07,S06aH05,S10aH06,S11aH06,S12aH05,S02aH06,S03aH05,S04aH07,S05aH05,S12aH01,S19aH07 | U12: N | V12: AllSaAllH | X12: N | Y12: FaP,SaP,SaN,WaN,RaN,RaP,FaN,WaP
I17: 0.75 | K17: share of charging at night
C18: ~UC_Sets: R_E: AllRegions
H21: =IF(H23=H24,"Not Required!","~UC_T: LO") -> Not Required!
C22: UC_N | D22: Pset_CI | E22: Pset_CO | F22: pset_pn | G22: Cset_CN | H22: TimeSlice | I22: UC_FLO | J22: UC_RHSRT | K22: UC_RHSRT~0
C23: UC_bev night chg limit | D23: ELC | E23: =G23 -> AuxStoIN | F23: *EV* | G23: AuxStoIN | H23: =HLOOKUP($A$10,$D$10:$CU$12,3,FALSE) -> AllSaAllH | I23: =1+I24 -> 0.25 | J23: 0 | K23: 3 | M23: night
D24: ELC | E24: =G24 -> AuxStoIN | F24: *EV* | G24: AuxStoIN | H24: =HLOOKUP($A$10,$D$10:$CU$12,2,FALSE) -> AllSaAllH | I24: =-$I$17 -> -0.75 | M24: day

Sheet ts_012
C9: =IF(A11="x","DeActivated","~TimeSlices") -> DeActivated | I9: =IF(A11="x","DeActivated","~TFM_DINS-AT") -> DeActivated | N9: =IF(A11="x","DeActivated","~TFM_DINS-AT") -> DeActivated | S9: =IF(A11="x","DeActivated","~TFM_DINS-AT") -> DeActivated | X9: =IF(A11="x","DeActivated","~TFM_DINS-AT") -> DeActivated
A10: ts_012 | C10: season | D10: weekly | E10: daynite | F10: wparent | G10: dparent | I10: commodity | J10: timeslice | K10: com_fr | L10: process | N10: commodity | O10: timeslice | P10: com_fr | Q10: process | S10: commodity | T10: timeslice | U10: com_fr | V10: process | X10: g_yrfr | Y10: com_fr | Z10: timeslice | AA10: commodity
A11: =IFERROR(IF(Veda!D5=A10,"ok","x"),"") -> x | C11: S01 | D11: a | E11: H01 | F11: S01,S02,S03,S04 | G11: a | I11: elc_spv_NZL_001 | J11: S01aH01 | K11: 0.41591424 | L11: IMPNRGZ | N11: elc_won_NZL_001 | O11: S01aH01 | P11: 0.33754898 | Q11: IMPNRGZ | S11: elc_wof_NZL_001 | T11: S01aH01 | U11: 0.37764386 | V11: IMPNRGZ | X11: 0.36484018 | Y11: 0.35989359 | Z11: S01aH01 | AA11: elc_roadtransport
C12: S02 | E12: H02 | G12: a | I12: elc_spv_NZL_001 | J12: S01aH02 | K12: 0.080517817 | L12: IMPNRGZ | N12: elc_won_NZL_001 | O12: S01aH02 | P12: 0.141636 | Q12: IMPNRGZ | S12: elc_wof_NZL_001 | T12: S01aH02 | U12: 0.15382363 | V12: IMPNRGZ | X12: 0.15022831 | Y12: 0.1551749 | Z12: S01aH02 | AA12: elc_roadtransport
C13: S03 | I13: elc_spv_NZL_001 | J13: S02aH01 | K13: 0.21610204 | L13: IMPNRGZ | N13: elc_won_NZL_001 | O13: S02aH01 | P13: 0.25331983 | Q13: IMPNRGZ | S13: elc_wof_NZL_001 | T13: S02aH01 | U13: 0.24318339 | V13: IMPNRGZ | X13: 0.2173516 | Y13: 0.21440469 | Z13: S02aH01 | AA13: elc_roadtransport
C14: S04 | I14: elc_spv_NZL_001 | J14: S02aH02 | K14: 0.031985538 | L14: IMPNRGZ | N14: elc_won_NZL_001 | O14: S02aH02 | P14: 0.10267566 | Q14: IMPNRGZ | S14: elc_wof_NZL_001 | T14: S02aH02 | U14: 0.10168449 | V14: IMPNRGZ | X14: 0.089497717 | Y14: 0.092444621 | Z14: S02aH02 | AA14: elc_roadtransport
I15: elc_spv_NZL_001 | J15: S03aH01 | K15: 0.18149896 | L15: IMPNRGZ | N15: elc_won_NZL_001 | O15: S03aH01 | P15: 0.091825487 | Q15: IMPNRGZ | S15: elc_wof_NZL_001 | T15: S03aH01 | U15: 0.072532299 | V15: IMPNRGZ | X15: 0.10479452 | Y15: 0.10337369 | Z15: S03aH01 | AA15: elc_roadtransport
I16: elc_spv_NZL_001 | J16: S03aH02 | K16: 0.032735555 | L16: IMPNRGZ | N16: elc_won_NZL_001 | O16: S03aH02 | P16: 0.038194431 | Q16: IMPNRGZ | S16: elc_wof_NZL_001 | T16: S03aH02 | U16: 0.028919065 | V16: IMPNRGZ | X16: 0.043150685 | Y16: 0.044571514 | Z16: S03aH02 | AA16: elc_roadtransport
I17: elc_spv_NZL_001 | J17: S04aH01 | K17: 0.033934279 | L17: IMPNRGZ | N17: elc_won_NZL_001 | O17: S04aH01 | P17: 0.024613345 | Q17: IMPNRGZ | S17: elc_wof_NZL_001 | T17: S04aH01 | U17: 0.015852442 | V17: IMPNRGZ | X17: 0.021347032 | Y17: 0.021057604 | Z17: S04aH01 | AA17: elc_roadtransport
I18: elc_spv_NZL_001 | J18: S04aH02 | K18: 0.0073115721 | L18: IMPNRGZ | N18: elc_won_NZL_001 | O18: S04aH02 | P18: 0.010186278 | Q18: IMPNRGZ | S18: elc_wof_NZL_001 | T18: S04aH02 | U18: 0.0063608247 | V18: IMPNRGZ | X18: 0.0087899543 | Y18: 0.0090793824 | Z18: S04aH02 | AA18: elc_roadtransport
I19: elc_spv_NZL_002 | J19: S01aH01 | K19: 0.43912706 | L19: IMPNRGZ | N19: elc_won_NZL_002 | O19: S01aH01 | P19: 0.32250744 | Q19: IMPNRGZ | S19: elc_wof_NZL_002 | T19: S01aH01 | U19: 0.36096957 | V19: IMPNRGZ
I20: elc_spv_NZL_002 | J20: S01aH02 | K20: 0.042850834 | L20: IMPNRGZ | N20: elc_won_NZL_002 | O20: S01aH02 | P20: 0.1311202 | Q20: IMPNRGZ | S20: elc_wof_NZL_002 | T20: S01aH02 | U20: 0.15267252 | V20: IMPNRGZ
I21: elc_spv_NZL_002 | J21: S02aH01 | K21: 0.23721227 | L21: IMPNRGZ | N21: elc_won_NZL_002 | O21: S02aH01 | P21: 0.27845612 | Q21: IMPNRGZ | S21: elc_wof_NZL_002 | T21: S02aH01 | U21: 0.25375991 | V21: IMPNRGZ
I22: elc_spv_NZL_002 | J22: S02aH02 | K22: 0.01495872 | L22: IMPNRGZ | N22: elc_won_NZL_002 | O22: S02aH02 | P22: 0.1135651 | Q22: IMPNRGZ | S22: elc_wof_NZL_002 | T22: S02aH02 | U22: 0.10497475 | V22: IMPNRGZ
I23: elc_spv_NZL_002 | J23: S03aH01 | K23: 0.19904542 | L23: IMPNRGZ | N23: elc_won_NZL_002 | O23: S03aH01 | P23: 0.086721617 | Q23: IMPNRGZ | S23: elc_wof_NZL_002 | T23: S03aH01 | U23: 0.072177553 | V23: IMPNRGZ
I24: elc_spv_NZL_002 | J24: S03aH02 | K24: 0.019592947 | L24: IMPNRGZ | N24: elc_won_NZL_002 | O24: S03aH02 | P24: 0.033510695 | Q24: IMPNRGZ | S24: elc_wof_NZL_002 | T24: S03aH02 | U24: 0.033046462 | V24: IMPNRGZ
I25: elc_spv_NZL_002 | J25: S04aH01 | K25: 0.040939201 | L25: IMPNRGZ | N25: elc_won_NZL_002 | O25: S04aH01 | P25: 0.023983748 | Q25: IMPNRGZ | S25: elc_wof_NZL_002 | T25: S04aH01 | U25: 0.014615289 | V25: IMPNRGZ
I26: elc_spv_NZL_002 | J26: S04aH02 | K26: 0.0062735446 | L26: IMPNRGZ | N26: elc_won_NZL_002 | O26: S04aH02 | P26: 0.010135077 | Q26: IMPNRGZ | S26: elc_wof_NZL_002 | T26: S04aH02 | U26: 0.0077839396 | V26: IMPNRGZ
I27: elc_spv_NZL_003 | J27: S01aH01 | K27: 0.45183002 | L27: IMPNRGZ | N27: elc_won_NZL_003 | O27: S01aH01 | P27: 0.33245574 | Q27: IMPNRGZ | S27: elc_wof_NZL_003 | T27: S01aH01 | U27: 0.33918512 | V27: IMPNRGZ
I28: elc_spv_NZL_003 | J28: S01aH02 | K28: 0.043819723 | L28: IMPNRGZ | N28: elc_won_NZL_003 | O28: S01aH02 | P28: 0.14407638 | Q28: IMPNRGZ | S28: elc_wof_NZL_003 | T28: S01aH02 | U28: 0.15176266 | V28: IMPNRGZ
I29: elc_spv_NZL_003 | J29: S02aH01 | K29: 0.2275969 | L29: IMPNRGZ | N29: elc_won_NZL_003 | O29: S02aH01 | P29: 0.27314668 | Q29: IMPNRGZ | S29: elc_wof_NZL_003 | T29: S02aH01 | U29: 0.27039075 | V29: IMPNRGZ
I30: elc_spv_NZL_003 | J30: S02aH02 | K30: 0.012547169 | L30: IMPNRGZ | N30: elc_won_NZL_003 | O30: S02aH02 | P30: 0.1063184 | Q30: IMPNRGZ | S30: elc_wof_NZL_003 | T30: S02aH02 | U30: 0.10660699 | V30: IMPNRGZ
... I130: elc_spv_NZL_015 | J130: S04aH02 | K130: 0.0074184469 | L130: IMPNRGZ | N130: elc_won_NZL_015 | O130: S04aH02 | P130: 0.010229417 | Q130: IMPNRGZ | S130: elc_wof_NZL_015 | T130: S04aH02 | U130: 0.0097303004 | V130: IMPNRGZ
I131: elc_spv_NZL_016 | J131: S01aH01 | K131: 0.43868402 | L131: IMPNRGZ | S131: elc_wof_NZL_016 | T131: S01aH01 | U131: 0.36405387 | V131: IMPNRGZ
I132: elc_spv_NZL_016 | J132: S01aH02 | K132: 0.056471856 | L132: IMPNRGZ | S132: elc_wof_NZL_016 | T132: S01aH02 | U132: 0.1495267 | V132: IMPNRGZ
I133: elc_spv_NZL_016 | J133: S02aH01 | K133: 0.20491402 | L133: IMPNRGZ | S133: elc_wof_NZL_016 | T133: S02aH01 | U133: 0.22573223 | V133: IMPNRGZ
I134: elc_spv_NZL_016 | J134: S02aH02 | K134: 0.014333359 | L134: IMPNRGZ | S134: elc_wof_NZL_016 | T134: S02aH02 | U134: 0.090432115 | V134: IMPNRGZ
I135: elc_spv_NZL_016 | J135: S03aH01 | K135: 0.21052998 | L135: IMPNRGZ | S135: elc_wof_NZL_016 | T135: S03aH01 | U135: 0.095616358 | V135: IMPNRGZ
I136: elc_spv_NZL_016 | J136: S03aH02 | K136: 0.030165973 | L136: IMPNRGZ | S136: elc_wof_NZL_016 | T136: S03aH02 | U136: 0.038939736 | V136: IMPNRGZ
I137: elc_spv_NZL_016 | J137: S04aH01 | K137: 0.039217657 | L137: IMPNRGZ | S137: elc_wof_NZL_016 | T137: S04aH01 | U137: 0.025907032 | V137: IMPNRGZ
I138: elc_spv_NZL_016 | J138: S04aH02 | K138: 0.0056831301 | L138: IMPNRGZ | S138: elc_wof_NZL_016 | T138: S04aH02 | U138: 0.0097919612 | V138: IMPNRGZ
S139: elc_wof_NZL_017 | T139: S01aH01 | U139: 0.37420116 | V139: IMPNRGZ
S140: elc_wof_NZL_017 | T140: S01aH02 | U140: 0.14967899 | V140: IMPNRGZ
S141: elc_wof_NZL_017 | T141: S02aH01 | U141: 0.22199385 | V141: IMPNRGZ
S142: elc_wof_NZL_017 | T142: S02aH02 | U142: 0.090260477 | V142: IMPNRGZ
S143: elc_wof_NZL_017 | T143: S03aH01 | U143: 0.090087206 | V143: IMPNRGZ
S144: elc_wof_NZL_017 | T144: S03aH02 | U144: 0.035493476 | V144: IMPNRGZ
S145: elc_wof_NZL_017 | T145: S04aH01 | U145: 0.027548037 | V145: IMPNRGZ
S146: elc_wof_NZL_017 | T146: S04aH02 | U146: 0.010736799 | V146: IMPNRGZ
S147: elc_wof_NZL_018 | T147: S01aH01 | U147: 0.40209674 | V147: IMPNRGZ
...

Sheet ts_030
C9: =IF(A11="x","DeActivated","~TimeSlices") -> DeActivated | I9: =IF(A11="x","DeActivated","~TFM_DINS-AT") -> DeActivated | N9: =IF(A11="x","DeActivated","~TFM_DINS-AT") -> DeActivated | S9: =IF(A11="x","DeActivated","~TFM_DINS-AT") -> DeActivated | X9: =IF(A11="x","DeActivated","~TFM_DINS-AT") -> DeActivated
A10: ts_030 | C10: season | D10: weekly | E10: daynite | F10: wparent | G10: dparent | I10: commodity | J10: timeslice | K10: com_fr | L10: process | N10: commodity | O10: timeslice | P10: com_fr | Q10: process | S10: commodity | T10: timeslice | U10: com_fr | V10: process | X10: g_yrfr | Y10: com_fr | Z10: timeslice | AA10: commodity
A11: =IFERROR(IF(Veda!D5=A10,"ok","x"),"") -> x | C11: S01 | D11: a | E11: H01 | F11: S01,S02,S03,S04,S05,S06 | G11: a | I11: elc_spv_NZL_001 | J11: S01aH01 | K11: 0 | L11: IMPNRGZ | N11: elc_won_NZL_001 | O11: S01aH01 | P11: 0.07715855 | Q11: IMPNRGZ | S11: elc_wof_NZL_001 | T11: S01aH01 | U11: 0.081576707 | V11: IMPNRGZ | X11: 0.087671233 | Y11: 0.018754112 | Z11: S01aH01 | AA11: elc_roadtransport
C12: S02 | E12: H02 | G12: a | I12: elc_spv_NZL_001 | J12: S01aH02 | K12: 0.020498106 | L12: IMPNRGZ | N12: elc_won_NZL_001 | O12: S01aH02 | P12: 0.025635852 | Q12: IMPNRGZ | S12: elc_wof_NZL_001 | T12: S01aH02 | U12: 0.028033999 | V12: IMPNRGZ | X12: 0.029223744 | Y12: 0.046036679 | Z12: S01aH02 | AA12: elc_roadtransport
C13: S03 | E13: H03 | G13: a | I13: elc_spv_NZL_001 | J13: S01aH03 | K13: 0.33248401 | L13: IMPNRGZ | N13: elc_won_NZL_001 | O13: S01aH03 | P13: 0.11743905 | Q13: IMPNRGZ | S13: elc_wof_NZL_001 | T13: S01aH03 | U13: 0.12645707 | V13: IMPNRGZ | X13: 0.13150685 | Y13: 0.18024314 | Z13: S01aH03 | AA13: elc_roadtransport
C14: S04 | E14: H04 | G14: a | I14: elc_spv_NZL_001 | J14: S01aH04 | K14: 0.07468475 | L14: IMPNRGZ | N14: elc_won_NZL_001 | O14: S01aH04 | P14: 0.091434135 | Q14: IMPNRGZ | S14: elc_wof_NZL_001 | T14: S01aH04 | U14: 0.097824521 | V14: IMPNRGZ | X14: 0.10228311 | Y14: 0.105651 | Z14: S01aH04 | AA14: elc_roadtransport
C15: S05 | I15: elc_spv_NZL_001 | J15: S02aH01 | K15: 0 | L15: IMPNRGZ | N15: elc_won_NZL_001 | O15: S02aH01 | P15: 0.040348425 | Q15: IMPNRGZ | S15: elc_wof_NZL_001 | T15: S02aH01 | U15: 0.049076256 | V15: IMPNRGZ | X15: 0.04109589 | Y15: 0.0087909902 | Z15: S02aH01 | AA15: elc_roadtransport
C16: S06 | I16: elc_spv_NZL_001 | J16: S02aH02 | K16: 0 | L16: IMPNRGZ | N16: elc_won_NZL_001 | O16: S02aH02 | P16: 0.014068104 | Q16: IMPNRGZ | S16: elc_wof_NZL_001 | T16: S02aH02 | U16: 0.016783405 | V16: IMPNRGZ | X16: 0.01369863 | Y16: 0.021579693 | Z16: S02aH02 | AA16: elc_roadtransport
I17: elc_spv_NZL_001 | J17: S02aH03 | K17: 0.062932129 | L17: IMPNRGZ | N17: elc_won_NZL_001 | O17: S02aH03 | P17: 0.062899002 | Q17: IMPNRGZ | S17: elc_wof_NZL_001 | T17: S02aH03 | U17: 0.075716423 | V17: IMPNRGZ | X17: 0.061643836 | Y17: 0.084488974 | Z17: S02aH03 | AA17: elc_roadtransport
I18: elc_spv_NZL_001 | J18: S02aH04 | K18: 0.0058330666 | L18: IMPNRGZ | N18: elc_won_NZL_001 | O18: S02aH04 | P18: 0.05020186 | Q18: IMPNRGZ | S18: elc_wof_NZL_001 | T18: S02aH04 | U18: 0.055999109 | V18: IMPNRGZ | X18: 0.047945205 | Y18: 0.049523904 | Z18: S02aH04 | AA18: elc_roadtransport
I19: elc_spv_NZL_001 | J19: S03aH01 | K19: 0 | L19: IMPNRGZ | N19: elc_won_NZL_001 | O19: S03aH01 | P19: 0.087996666 | Q19: IMPNRGZ | S19: elc_wof_NZL_001 | T19: S03aH01 | U19: 0.087243868 | V19: IMPNRGZ | X19: 0.076712329 | Y19: 0.016409848 | Z19: S03aH01 | AA19: elc_roadtransport
I20: elc_spv_NZL_001 | J20: S03aH02 | K20: 0.0084323972 | L20: IMPNRGZ | N20: elc_won_NZL_001 | O20: S03aH02 | P20: 0.028642558 | Q20: IMPNRGZ | S20: elc_wof_NZL_001 | T20: S03aH02 | U20: 0.028180215 | V20: IMPNRGZ | X20: 0.025570776 | Y20: 0.040282094 | Z20: S03aH02 | AA20: elc_roadtransport
I21: elc_spv_NZL_001 | J21: S03aH03 | K21: 0.20766964 | L21: IMPNRGZ | N21: elc_won_NZL_001 | O21: S03aH03 | P21: 0.1366806 | Q21: IMPNRGZ | S21: elc_wof_NZL_001 | T21: S03aH03 | U21: 0.12775931 | V21: IMPNRGZ | X21: 0.11506849 | Y21: 0.15771275 | Z21: S03aH03 | AA21: elc_roadtransport
I22: elc_spv_NZL_001 | J22: S03aH04 | K22: 0.031985538 | L22: IMPNRGZ | N22: elc_won_NZL_001 | O22: S03aH04 | P22: 0.10267566 | Q22: IMPNRGZ | S22: elc_wof_NZL_001 | T22: S03aH04 | U22: 0.10168449 | V22: IMPNRGZ | X22: 0.089497717 | Y22: 0.092444621 | Z22: S03aH04 | AA22: elc_roadtransport
I23: elc_spv_NZL_001 | J23: S04aH01 | K23: 0 | L23: IMPNRGZ | N23: elc_won_NZL_001 | O23: S04aH01 | P23: 0.024195412 | Q23: IMPNRGZ | S23: elc_wof_NZL_001 | T23: S04aH01 | U23: 0.023243387 | V23: IMPNRGZ | X23: 0.028767123 | Y23: 0.0061536932 | Z23: S04aH01 | AA23: elc_roadtransport
I24: elc_spv_NZL_001 | J24: S04aH02 | K24: 0.014017692 | L24: IMPNRGZ | N24: elc_won_NZL_001 | O24: S04aH02 | P24: 0.0082406559 | Q24: IMPNRGZ | S24: elc_wof_NZL_001 | T24: S04aH02 | U24: 0.0075535439 | V24: IMPNRGZ | X24: 0.0095890411 | Y24: 0.015105785 | Z24: S04aH02 | AA24: elc_roadtransport
I25: elc_spv_NZL_001 | J25: S04aH03 | K25: 0.12178804 | L25: IMPNRGZ | N25: elc_won_NZL_001 | O25: S04aH03 | P25: 0.043272518 | Q25: IMPNRGZ | S25: elc_wof_NZL_001 | T25: S04aH03 | U25: 0.035242065 | V25: IMPNRGZ | X25: 0.043150685 | Y25: 0.059142282 | Z25: S04aH03 | AA25: elc_roadtransport
I26: elc_spv_NZL_001 | J26: S04aH04 | K26: 0.024057916 | L26: IMPNRGZ | N26: elc_won_NZL_001 | O26: S04aH04 | P26: 0.031065083 | Q26: IMPNRGZ | S26: elc_wof_NZL_001 | T26: S04aH04 | U26: 0.026106005 | V26: IMPNRGZ | X26: 0.033561644 | Y26: 0.034666733 | Z26: S04aH04 | AA26: elc_roadtransport
I27: elc_spv_NZL_001 | J27: S05aH01 | K27: 0 | L27: IMPNRGZ | N27: elc_won_NZL_001 | O27: S05aH01 | P27: 0.0056790192 | Q27: IMPNRGZ | S27: elc_wof_NZL_001 | T27: S05aH01 | U27: 0.002515924 | V27: IMPNRGZ | X27: 0.0082191781 | Y27: 0.001758198 | Z27: S05aH01 | AA27: elc_roadtransport
I28: elc_spv_NZL_001 | J28: S05aH02 | K28: 0.0047357192 | L28: IMPNRGZ | N28: elc_won_NZL_001 | O28: S05aH02 | P28: 0.001740504 | Q28: IMPNRGZ | S28: elc_wof_NZL_001 | T28: S05aH02 | U28: 0.00066840382 | V28: IMPNRGZ | X28: 0.002739726 | Y28: 0.0043159386 | Z28: S05aH02 | AA28: elc_roadtransport
... I34: elc_spv_NZL_001 | J34: S06aH04 | K34: 0.0073115721 | L34: IMPNRGZ | N34: elc_won_NZL_001 | O34: S06aH04 | P34: 0.010186278 | Q34: IMPNRGZ | S34: elc_wof_NZL_001 | T34: S06aH04 | U34: 0.0063608247 | V34: IMPNRGZ | X34: 0.0087899543 | Y34: 0.0090793824 | Z34: S06aH04 | AA34: elc_roadtransport
I35: elc_spv_NZL_002 | J35: S01aH01 | K35: 0.0015256507 | L35: IMPNRGZ | N35: elc_won_NZL_002 | O35: S01aH01 | P35: 0.068489094 | Q35: IMPNRGZ | S35: elc_wof_NZL_002 | T35: S01aH01 | U35: 0.081366218 | V35: IMPNRGZ
I36: elc_spv_NZL_002 | J36: S01aH02 | K36: 0.039667585 | L36: IMPNRGZ | N36: elc_won_NZL_002 | O36: S01aH02 | P36: 0.022480384 | Q36: IMPNRGZ | S36: elc_wof_NZL_002 | T36: S01aH02 | U36: 0.027197455 | V36: IMPNRGZ
I37: elc_spv_NZL_002 | J37: S01aH03 | K37: 0.32561194 | L37: IMPNRGZ | N37: elc_won_NZL_002 | O37: S01aH03 | P37: 0.11407721 | Q37: IMPNRGZ | S37: elc_wof_NZL_002 | T37: S01aH03 | U37: 0.12209908 | V37: IMPNRGZ
I38: elc_spv_NZL_002 | J38: S01aH04 | K38: 0.04284071 | L38: IMPNRGZ | N38: elc_won_NZL_002 | O38: S01aH04 | P38: 0.083131573 | Q38: IMPNRGZ | S38: elc_wof_NZL_002 | T38: S01aH04 | U38: 0.099144046 | V38: IMPNRGZ
I39: elc_spv_NZL_002 | J39: S02aH01 | K39: 0 | L39: IMPNRGZ | N39: elc_won_NZL_002 | O39: S02aH01 | P39: 0.039233533 | Q39: IMPNRGZ | S39: elc_wof_NZL_002 | T39: S02aH01 | U39: 0.045832568 | V39: IMPNRGZ
I40: elc_spv_NZL_002 | J40: S02aH02 | K40: 0.0022240125 | L40: IMPNRGZ | N40: elc_won_NZL_002 | O40: S02aH02 | P40: 0.012978761 | Q40: IMPNRGZ | S40: elc_wof_NZL_002 | T40: S02aH02 | U40: 0.014693975 | V40: IMPNRGZ
I41: elc_spv_NZL_002 | J41: S02aH03 | K41: 0.070097873 | L41: IMPNRGZ | N41: elc_won_NZL_002 | O41: S02aH03 | P41: 0.065248465 | Q41: IMPNRGZ | S41: elc_wof_NZL_002 | T41: S02aH03 | U41: 0.06978027 | V41: IMPNRGZ
I42: elc_spv_NZL_002 | J42: S02aH04 | K42: 1.01235e-05 | L42: IMPNRGZ | N42: elc_won_NZL_002 | O42: S02aH04 | P42: 0.047988629 | Q42: IMPNRGZ | S42: elc_wof_NZL_002 | T42: S02aH04 | U42: 0.053528478 | V42: IMPNRGZ
I43: elc_spv_NZL_002 | J43: S03aH01 | K43: 0 | L43: IMPNRGZ | N43: elc_won_NZL_002 | O43: S03aH01 | P43: 0.094642451 | Q43: IMPNRGZ | S43: elc_wof_NZL_002 | T43: S03aH01 | U43: 0.089895818 | V43: IMPNRGZ
I44: elc_spv_NZL_002 | J44: S03aH02 | K44: 0.021716519 | L44: IMPNRGZ | N44: elc_won_NZL_002 | O44: S03aH02 | P44: 0.028831175 | Q44: IMPNRGZ | S44: elc_wof_NZL_002 | T44: S03aH02 | U44: 0.029071637 | V44: IMPNRGZ
I45: elc_spv_NZL_002 | J45: S03aH03 | K45: 0.21549575 | L45: IMPNRGZ | N45: elc_won_NZL_002 | O45: S03aH03 | P45: 0.15498249 | Q45: IMPNRGZ | S45: elc_wof_NZL_002 | T45: S03aH03 | U45: 0.13479246 | V45: IMPNRGZ
I46: elc_spv_NZL_002 | J46: S03aH04 | K46: 0.01495872 | L46: IMPNRGZ | N46: elc_won_NZL_002 | O46: S03aH04 | P46: 0.1135651 | Q46: IMPNRGZ | S46: elc_wof_NZL_002 | T46: S03aH04 | U46: 0.10497475 | V46: IMPNRGZ
... I370: elc_spv_NZL_015 | J370: S06aH04 | K370: 0.0074184469 | L370: IMPNRGZ | N370: elc_won_NZL_015 | O370: S06aH04 | P370: 0.010229417 | Q370: IMPNRGZ | S370: elc_wof_NZL_015 | T370: S06aH04 | U370: 0.0097303004 | V370: IMPNRGZ
I371: elc_spv_NZL_016 | J371: S01aH01 | K371: 0.0012289316 | L371: IMPNRGZ | S371: elc_wof_NZL_016 | T371: S01aH01 | U371: 0.085606892 | V371: IMPNRGZ
I372: elc_spv_NZL_016 | J372: S01aH02 | K372: 0.032286493 | L372: IMPNRGZ | S372: elc_wof_NZL_016 | T372: S01aH02 | U372: 0.028050405 | V372: IMPNRGZ
I373: elc_spv_NZL_016 | J373: S01aH03 | K373: 0.34317687 | L373: IMPNRGZ | S373: elc_wof_NZL_016 | T373: S01aH03 | U373: 0.12839481 | V373: IMPNRGZ
I374: elc_spv_NZL_016 | J374: S01aH04 | K374: 0.056471856 | L374: IMPNRGZ | S374: elc_wof_NZL_016 | T374: S01aH04 | U374: 0.10006587 | V374: IMPNRGZ
I375: elc_spv_NZL_016 | J375: S02aH01 | K375: 0 | L375: IMPNRGZ | S375: elc_wof_NZL_016 | T375: S02aH01 | U375: 0.042543386 | V375: IMPNRGZ
I376: elc_spv_NZL_016 | J376: S02aH02 | K376: 0 | L376: IMPNRGZ | S376: elc_wof_NZL_016 | T376: S02aH02 | U376: 0.014287693 | V376: IMPNRGZ
...

Sheet ts_048
C9: =IF(A11="x","DeActivated","~TimeSlices") -> DeActivated | I9: =IF(A11="x","DeActivated","~TFM_DINS-AT") -> DeActivated | N9: =IF(A11="x","DeActivated","~TFM_DINS-AT") -> DeActivated | S9: =IF(A11="x","DeActivated","~TFM_DINS-AT") -> DeActivated | X9: =IF(A11="x","DeActivated","~TFM_DINS-AT") -> DeActivated
A10: ts_048 | C10: season | D10: weekly | E10: daynite | F10: wparent | G10: dparent | I10: commodity | J10: timeslice | K10: com_fr | L10: process | N10: commodity | O10: timeslice | P10: com_fr | Q10: process | S10: commodity | T10: timeslice | U10: com_fr | V10: process | X10: g_yrfr | Y10: com_fr | Z10: timeslice | AA10: commodity
A11: =IFERROR(IF(Veda!D5=A10,"ok","x"),"") -> x | C11: S01 | D11: a | E11: H01 | F11: S01,S02,S03,S04,S05,S06,S07 | G11: a | I11: elc_spv_NZL_001 | J11: S01aH01 | K11: 0 | L11: IMPNRGZ | N11: elc_won_NZL_001 | O11: S01aH01 | P11: 0.07715855 | Q11: IMPNRGZ | S11: elc_wof_NZL_001 | T11: S01aH01 | U11: 0.081576707 | V11: IMPNRGZ | X11: 0.087671233 | Y11: 0.018754112 | Z11: S01aH01 | AA11: elc_roadtransport
C12: S02 | E12: H02 | G12: a | I12: elc_spv_NZL_001 | J12: S01aH02 | K12: 0.020498106 | L12: IMPNRGZ | N12: elc_won_NZL_001 | O12: S01aH02 | P12: 0.025635852 | Q12: IMPNRGZ | S12: elc_wof_NZL_001 | T12: S01aH02 | U12: 0.028033999 | V12: IMPNRGZ | X12: 0.029223744 | Y12: 0.046036679 | Z12: S01aH02 | AA12: elc_roadtransport
C13: S03 | E13: H03 | G13: a | I13: elc_spv_NZL_001 | J13: S01aH03 | K13: 0.33248401 | L13: IMPNRGZ | N13: elc_won_NZL_001 | O13: S01aH03 | P13: 0.11743905 | Q13: IMPNRGZ | S13: elc_wof_NZL_001 | T13: S01aH03 | U13: 0.12645707 | V13: IMPNRGZ | X13: 0.13150685 | Y13: 0.18024314 | Z13: S01aH03 | AA13: elc_roadtransport
C14: S04 | E14: H04 | G14: a | I14: elc_spv_NZL_001 | J14: S01aH04 | K14: 0.032945228 | L14: IMPNRGZ | N14: elc_won_NZL_001 | O14: S01aH04 | P14: 0.013409985 | Q14: IMPNRGZ | S14: elc_wof_NZL_001 | T14: S01aH04 | U14: 0.014269789 | V14: IMPNRGZ | X14: 0.014611872 | Y14: 0.02842818 | Z14: S01aH04 | AA14: elc_roadtransport
C15: S05 | E15: H05 | G15: a | I15: elc_spv_NZL_001 | J15: S01aH05 | K15: 0.041739522 | L15: IMPNRGZ | N15: elc_won_NZL_001 | O15: S01aH05 | P15: 0.07802415 | Q15: IMPNRGZ | S15: elc_wof_NZL_001 | T15: S01aH05 | U15: 0.083554733 | V15: IMPNRGZ | X15: 0.087671233 | Y15: 0.077222816 | Z15: S01aH05 | AA15: elc_roadtransport
C16: S06 | I16: elc_spv_NZL_001 | J16: S02aH01 | K16: 0 | L16: IMPNRGZ | N16: elc_won_NZL_001 | O16: S02aH01 | P16: 0.040348425 | Q16: IMPNRGZ | S16: elc_wof_NZL_001 | T16: S02aH01 | U16: 0.049076256 | V16: IMPNRGZ | X16: 0.04109589 | Y16: 0.0087909902 | Z16: S02aH01 | AA16: elc_roadtransport
C17: S07 | I17: elc_spv_NZL_001 | J17: S02aH02 | K17: 0 | L17: IMPNRGZ | N17: elc_won_NZL_001 | O17: S02aH02 | P17: 0.014068104 | Q17: IMPNRGZ | S17: elc_wof_NZL_001 | T17: S02aH02 | U17: 0.016783405 | V17: IMPNRGZ | X17: 0.01369863 | Y17: 0.021579693 | Z17: S02aH02 | AA17: elc_roadtransport
I18: elc_spv_NZL_001 | J18: S02aH03 | K18: 0.062932129 | L18: IMPNRGZ | N18: elc_won_NZL_001 | O18: S02aH03 | P18: 0.062899002 | Q18: IMPNRGZ | S18: elc_wof_NZL_001 | T18: S02aH03 | U18: 0.075716423 | V18: IMPNRGZ | X18: 0.061643836 | Y18: 0.084488974 | Z18: S02aH03 | AA18: elc_roadtransport
I19: elc_spv_NZL_001 | J19: S02aH04 | K19: 0.0058330666 | L19: IMPNRGZ | N19: elc_won_NZL_001 | O19: S02aH04 | P19: 0.0071396514 | Q19: IMPNRGZ | S19: elc_wof_NZL_001 | T19: S02aH04 | U19: 0.0083303492 | V19: IMPNRGZ | X19: 0.0068493151 | Y19: 0.013325709 | Z19: S02aH04 | AA19: elc_roadtransport
I20: elc_spv_NZL_001 | J20: S02aH05 | K20: 0 | L20: IMPNRGZ | N20: elc_won_NZL_001 | O20: S02aH05 | P20: 0.043062209 | Q20: IMPNRGZ | S20: elc_wof_NZL_001 | T20: S02aH05 | U20: 0.04766876 | V20: IMPNRGZ | X20: 0.04109589 | Y20: 0.036198195 | Z20: S02aH05 | AA20: elc_roadtransport
I21: elc_spv_NZL_001 | J21: S03aH01 | K21: 0 | L21: IMPNRGZ | N21: elc_won_NZL_001 | O21: S03aH01 | P21: 0.091682725 | Q21: IMPNRGZ | S21: elc_wof_NZL_001 | T21: S03aH01 | U21: 0.088913474 | V21: IMPNRGZ | X21: 0.079452055 | Y21: 0.016995914 | Z21: S03aH01 | AA21: elc_roadtransport
I22: elc_spv_NZL_001 | J22: S03aH02 | K22: 0.0099556604 | L22: IMPNRGZ | N22: elc_won_NZL_001 | O22: S03aH02 | P22: 0.029867765 | Q22: IMPNRGZ | S22: elc_wof_NZL_001 | T22: S03aH02 | U22: 0.028928068 | V22: IMPNRGZ | X22: 0.026484018 | Y22: 0.04172074 | Z22: S03aH02 | AA22: elc_roadtransport
I23: elc_spv_NZL_001 | J23: S03aH03 | K23: 0.21914347 | L23: IMPNRGZ | N23: elc_won_NZL_001 | O23: S03aH03 | P23: 0.14191879 | Q23: IMPNRGZ | S23: elc_wof_NZL_001 | T23: S03aH03 | U23: 0.13124343 | V23: IMPNRGZ | X23: 0.11917808 | Y23: 0.16334535 | Z23: S03aH03 | AA23: elc_roadtransport
I24: elc_spv_NZL_001 | J24: S03aH04 | K24: 0.020982901 | L24: IMPNRGZ | N24: elc_won_NZL_001 | O24: S03aH04 | P24: 0.015013471 | Q24: IMPNRGZ | S24: elc_wof_NZL_001 | T24: S03aH04 | U24: 0.015299357 | V24: IMPNRGZ | X24: 0.013242009 | Y24: 0.025763038 | Z24: S03aH04 | AA24: elc_roadtransport
I25: elc_spv_NZL_001 | J25: S03aH05 | K25: 0.012857604 | L25: IMPNRGZ | N25: elc_won_NZL_001 | O25: S03aH05 | P25: 0.091184352 | Q25: IMPNRGZ | S25: elc_wof_NZL_001 | T25: S03aH05 | U25: 0.088778249 | V25: IMPNRGZ | X25: 0.079452055 | Y25: 0.069983177 | Z25: S03aH05 | AA25: elc_roadtransport
I26: elc_spv_NZL_001 | J26: S04aH01 | K26: 0 | L26: IMPNRGZ | N26: elc_won_NZL_001 | O26: S04aH01 | P26: 0.0075531849 | Q26: IMPNRGZ | S26: elc_wof_NZL_001 | T26: S04aH01 | U26: 0.006816585 | V26: IMPNRGZ | X26: 0.010958904 | Y26: 0.0023442641 | Z26: S04aH01 | AA26: elc_roadtransport
I27: elc_spv_NZL_001 | J27: S04aH02 | K27: 0.0055829338 | L27: IMPNRGZ | N27: elc_won_NZL_001 | O27: S04aH02 | P27: 0.0028380171 | Q27: IMPNRGZ | S27: elc_wof_NZL_001 | T27: S04aH02 | U27: 0.0021611653 | V27: IMPNRGZ | X27: 0.003652968 | Y27: 0.0057545849 | Z27: S04aH02 | AA27: elc_roadtransport
I28: elc_spv_NZL_001 | J28: S04aH03 | K28: 0.047298396 | L28: IMPNRGZ | N28: elc_won_NZL_001 | O28: S04aH03 | P28: 0.015155531 | Q28: IMPNRGZ | S28: elc_wof_NZL_001 | T28: S04aH03 | U28: 0.0095351435 | V28: IMPNRGZ | X28: 0.016438356 | Y28: 0.022530393 | Z28: S04aH03 | AA28: elc_roadtransport
I29: elc_spv_NZL_001 | J29: S04aH04 | K29: 0.0041093162 | L29: IMPNRGZ | N29: elc_won_NZL_001 | O29: S04aH04 | P29: 0.0016370193 | Q29: IMPNRGZ | S29: elc_wof_NZL_001 | T29: S04aH04 | U29: 0.0011241985 | V29: IMPNRGZ | X29: 0.001826484 | Y29: 0.0035535224 | Z29: S04aH04 | AA29: elc_roadtransport
... I45: elc_spv_NZL_001 | J45: S07aH05 | K45: 0.0044452585 | L45: IMPNRGZ | N45: elc_won_NZL_001 | O45: S07aH05 | P45: 0.0087497681 | Q45: IMPNRGZ | S45: elc_wof_NZL_001 | T45: S07aH05 | U45: 0.0053885626 | V45: IMPNRGZ | X45: 0.0075342466 | Y45: 0.0066363358 | Z45: S07aH05 | AA45: elc_roadtransport
I46: elc_spv_NZL_002 | J46: S01aH01 | K46: 0.0015256507 | L46: IMPNRGZ | N46: elc_won_NZL_002 | O46: S01aH01 | P46: 0.068489094 | Q46: IMPNRGZ | S46: elc_wof_NZL_002 | T46: S01aH01 | U46: 0.081366218 | V46: IMPNRGZ
I47: elc_spv_NZL_002 | J47: S01aH02 | K47: 0.039667585 | L47: IMPNRGZ | N47: elc_won_NZL_002 | O47: S01aH02 | P47: 0.022480384 | Q47: IMPNRGZ | S47: elc_wof_NZL_002 | T47: S01aH02 | U47: 0.027197455 | V47: IMPNRGZ
I48: elc_spv_NZL_002 | J48: S01aH03 | K48: 0.32561194 | L48: IMPNRGZ | N48: elc_won_NZL_002 | O48: S01aH03 | P48: 0.11407721 | Q48: IMPNRGZ | S48: elc_wof_NZL_002 | T48: S01aH03 | U48: 0.12209908 | V48: IMPNRGZ
I49: elc_spv_NZL_002 | J49: S01aH04 | K49: 0.025998765 | L49: IMPNRGZ | N49: elc_won_NZL_002 | O49: S01aH04 | P49: 0.01293317 | Q49: IMPNRGZ | S49: elc_wof_NZL_002 | T49: S01aH04 | U49: 0.01439496 | V49: IMPNRGZ
I50: elc_spv_NZL_002 | J50: S01aH05 | K50: 0.016841945 | L50: IMPNRGZ | N50: elc_won_NZL_002 | O50: S01aH05 | P50: 0.070198403 | Q50: IMPNRGZ | S50: elc_wof_NZL_002 | T50: S01aH05 | U50: 0.084749086 | V50: IMPNRGZ
I51: elc_spv_NZL_002 | J51: S02aH01 | K51: 0 | L51: IMPNRGZ | N51: elc_won_NZL_002 | O51: S02aH01 | P51: 0.039233533 | Q51: IMPNRGZ | S51: elc_wof_NZL_002 | T51: S02aH01 | U51: 0.045832568 | V51: IMPNRGZ
I52: elc_spv_NZL_002 | J52: S02aH02 | K52: 0.0022240125 | L52: IMPNRGZ | N52: elc_won_NZL_002 | O52: S02aH02 | P52: 0.012978761 | Q52: IMPNRGZ | S52: elc_wof_NZL_002 | T52: S02aH02 | U52: 0.014693975 | V52: IMPNRGZ
I53: elc_spv_NZL_002 | J53: S02aH03 | K53: 0.070097873 | L53: IMPNRGZ | N53: elc_won_NZL_002 | O53: S02aH03 | P53: 0.065248465 | Q53: IMPNRGZ | S53: elc_wof_NZL_002 | T53: S02aH03 | U53: 0.06978027 | V53: IMPNRGZ
I54: elc_spv_NZL_002 | J54: S02aH04 | K54: 1.01235e-05 | L54: IMPNRGZ | N54: elc_won_NZL_002 | O54: S02aH04 | P54: 0.0070173412 | Q54: IMPNRGZ | S54: elc_wof_NZL_002 | T54: S02aH04 | U54: 0.0078300293 | V54: IMPNRGZ
I55: elc_spv_NZL_002 | J55: S02aH05 | K55: 0 | L55: IMPNRGZ | N55: elc_won_NZL_002 | O55: S02aH05 | P55: 0.040971287 | Q55: IMPNRGZ | S55: elc_wof_NZL_002 | T55: S02aH05 | U55: 0.045698449 | V55: IMPNRGZ
I56: elc_spv_NZL_002 | J56: S03aH01 | K56: 4.7212499e-05 | L56: IMPNRGZ | N56: elc_won_NZL_002 | O56: S03aH01 | P56: 0.098115558 | Q56: IMPNRGZ | S56: elc_wof_NZL_002 | T56: S03aH01 | U56: 0.09178634 | V56: IMPNRGZ
I57: elc_spv_NZL_002 | J57: S03aH02 | K57: 0.023812062 | L57: IMPNRGZ | N57: elc_won_NZL_002 | O57: S03aH02 | P57: 0.030052807 | Q57: IMPNRGZ | S57: elc_wof_NZL_002 | T57: S03aH02 | U57: 0.029819569 | V57: IMPNRGZ
... I535: elc_spv_NZL_015 | J535: S07aH05 | K535: 0.004585783 | L535: IMPNRGZ | N535: elc_won_NZL_015 | O535: S07aH05 | P535: 0.0085206077 | Q535: IMPNRGZ | S535: elc_wof_NZL_015 | T535: S07aH05 | U535: 0.0083574119 | V535: IMPNRGZ
I536: elc_spv_NZL_016 | J536: S01aH01 | K536: 0.0012289316 | L536: IMPNRGZ | S536: elc_wof_NZL_016 | T536: S01aH01 | U536: 0.085606892 | V536: IMPNRGZ
I537: elc_spv_NZL_016 | J537: S01aH02 | K537: 0.032286493 | L537: IMPNRGZ | S537: elc_wof_NZL_016 | T537: S01aH02 | U537: 0.028050405 | V537: IMPNRGZ
I538: elc_spv_NZL_016 | J538: S01aH03 | K538: 0.34317687 | L538: IMPNRGZ | S538: elc_wof_NZL_016 | T538: S01aH03 | U538: 0.12839481 | V538: IMPNRGZ
I539: elc_spv_NZL_016 | J539: S01aH04 | K539: 0.029530911 | L539: IMPNRGZ | S539: elc_wof_NZL_016 | T539: S01aH04 | U539: 0.014758986 | V539: IMPNRGZ
I540: elc_spv_NZL_016 | J540: S01aH05 | K540: 0.026940945 | L540: IMPNRGZ | S540: elc_wof_NZL_016 | T540: S01aH05 | U540: 0.085306887 | V540: IMPNRGZ
...

Sheet ts_072
C9: =IF(A11="x","DeActivated","~TimeSlices") -> DeActivated | I9: =IF(A11="x","DeActivated","~TFM_DINS-AT") -> DeActivated | N9: =IF(A11="x","DeActivated","~TFM_DINS-AT") -> DeActivated | S9: =IF(A11="x","DeActivated","~TFM_DINS-AT") -> DeActivated | X9: =IF(A11="x","DeActivated","~TFM_DINS-AT") -> DeActivated
A10: ts_072 | C10: season | D10: weekly | E10: daynite | F10: wparent | G10: dparent | I10: commodity | J10: timeslice | K10: com_fr | L10: process | N10: commodity | O10: timeslice | P10: com_fr | Q10: process | S10: commodity | T10: timeslice | U10: com_fr | V10: process | X10: g_yrfr | Y10: com_fr | Z10: timeslice | AA10: commodity
A11: =IFERROR(IF(Veda!D5=A10,"ok","x"),"") -> x | C11: S01 | D11: a | E11: H01 | F11: S01,S02,S03,S04,S05,S06,S07,S08,S09,S10,S11 | G11: a | I11: elc_spv_NZL_001 | J11: S01aH01 | K11: 0 | L11: IMPNRGZ | N11: elc_won_NZL_001 | O11: S01aH01 | P11: 0.07715855 | Q11: IMPNRGZ | S11: elc_wof_NZL_001 | T11: S01aH01 | U11: 0.081576707 | V11: IMPNRGZ | X11: 0.087671233 | Y11: 0.018754112 | Z11: S01aH01 | AA11: elc_roadtransport
C12: S02 | E12: H02 | G12: a | I12: elc_spv_NZL_001 | J12: S01aH02 | K12: 0.020498106 | L12: IMPNRGZ | N12: elc_won_NZL_001 | O12: S01aH02 | P12: 0.025635852 | Q12: IMPNRGZ | S12: elc_wof_NZL_001 | T12: S01aH02 | U12: 0.028033999 | V12: IMPNRGZ | X12: 0.029223744 | Y12: 0.046036679 | Z12: S01aH02 | AA12: elc_roadtransport
C13: S03 | E13: H03 | G13: a | I13: elc_spv_NZL_001 | J13: S01aH03 | K13: 0.33248401 | L13: IMPNRGZ | N13: elc_won_NZL_001 | O13: S01aH03 | P13: 0.11743905 | Q13: IMPNRGZ | S13: elc_wof_NZL_001 | T13: S01aH03 | U13: 0.12645707 | V13: IMPNRGZ | X13: 0.13150685 | Y13: 0.18024314 | Z13: S01aH03 | AA13: elc_roadtransport
