Workbook

Sheet Veda
G1: 1-55
D2: ="~Inputcell: "&_xlfn.TEXTJOIN(",",TRUE,G1:EE1) -> ~Inputcell: 1-55
D3: 3
D5: =VLOOKUP(D3,$C$9:$E$1001,2,FALSE) -> s2_w | E5: =VLOOKUP(D3,$C$9:$E$1001,3,FALSE) -> C1
B7: ~Scenmap
A8: priority | B8: scen | C8: case_no | D8: timeslice | E8: climate
A9: 5 | B9: =VLOOKUP(E9,$AK$9:$AL$15,2,FALSE)&"."&VLOOKUP(D9,$AH$9:$AI$19,2,FALSE) -> e 1.5 deg no OS.e3d | C9: 1 | D9: s1p1v1_d | E9: C1 | G9: Limit warming to 1.5°C (>50%) with no or limited overshoot | AH9: s1p1v1_d | AI9: e3d | AK9: C1 | AL9: e 1.5 deg no OS
A10: 5 | B10: =VLOOKUP(E10,$AK$9:$AL$15,2,FALSE)&"."&VLOOKUP(D10,$AH$9:$AI$19,2,FALSE) -> e 1.5 deg no OS.d9d | C10: 2 | D10: s3p3v3_d | E10: C1 | G10: Limit warming to 1.5°C (>67%) with high overshoot | S10: IEA | AH10: s3p3v3_d | AI10: d9d | AK10: C2 | AL10: d 1.5 deg OS
A11: 5 | B11: =VLOOKUP(E11,$AK$9:$AL$15,2,FALSE)&"."&VLOOKUP(D11,$AH$9:$AI$19,2,FALSE) -> e 1.5 deg no OS.b2w | C11: 3 | D11: s2_w | E11: C1 | G11: Limit warming to 2°C (>67%) with higher action post-2030 | S11: 2022 | AH11: s2_w | AI11: b2w | AK11: C3 | AL11: c 2 deg (67%)
A12: 5 | B12: =VLOOKUP(E12,$AK$9:$AL$15,2,FALSE)&"."&VLOOKUP(D12,$AH$9:$AI$19,2,FALSE) -> e 1.5 deg no OS.a2w2d | C12: 4 | D12: s2_w_p2_d | E12: C1 | G12: Limit warming to 2°C (>50%) with immediate action | S12: =SUMIFS(iea_data!I3:I9999,iea_data!$B$3:$B$9999,Veda!$S$11)+T28-T29 -> 547.05 | T12: base-year generation (TWh) | AH12: s2_w_p2_d | AI12: a2w2d | AK12: C4 | AL12: b 2 deg (50%)
A13: 5 | B13: =VLOOKUP(E13,$AK$9:$AL$15,2,FALSE)&"."&VLOOKUP(D13,$AH$9:$AI$19,2,FALSE) -> e 1.5 deg no OS.hTS12c | C13: 5 | D13: ts12_clu | E13: C1 | G13: Likely above 3°C warming with limited mitigation | AH13: ts12_clu | AI13: hTS12c | AK13: C7 | AL13: a 3 deg
A14: 5 | B14: =VLOOKUP(E14,$AK$9:$AL$15,2,FALSE)&"."&VLOOKUP(D14,$AH$9:$AI$19,2,FALSE) -> e 1.5 deg no OS.gTS24c | C14: 6 | D14: ts24_clu | E14: =E13 -> C1 | T14: =S12 -> 547.05 | U14: =$S$12*J15 -> 563.4615 | V14: =$S$12*K15 -> 650.9895 | W14: =$S$12*L15 -> 782.2815 | X14: =$S$12*M15 -> 902.6325 | Y14: =$S$12*N15 -> 990.1605 | Z14: =$S$12*O15 -> 1055.8065 | AH14: ts24_clu | AI14: gTS24c
A15: 5 | B15: =VLOOKUP(E15,$AK$9:$AL$15,2,FALSE)&"."&VLOOKUP(D15,$AH$9:$AI$19,2,FALSE) -> e 1.5 deg no OS.fTS48c | C15: 7 | D15: ts48_clu | E15: =E14 -> C1 | G15: Electricity growth relative to 2020 | I15: =SUMIFS(ar6_r10!$F$2:$F$999,ar6_r10!$A$2:$A$999,Veda!$E$5,ar6_r10!$C$2:$C$999,Veda!I$17,ar6_r10!$M$2:$M$999,Veda!$G15) -> 1 | J15: =SUMIFS(ar6_r10!$F$2:$F$999,ar6_r10!$A$2:$A$999,Veda!$E$5,ar6_r10!$C$2:$C$999,Veda!J$17,ar6_r10!$M$2:$M$999,Veda!$G15) -> 1.03 | K15: =SUMIFS(ar6_r10!$F$2:$F$999,ar6_r10!$A$2:$A$999,Veda!$E$5,ar6_r10!$C$2:$C$999,Veda!K$17,ar6_r10!$M$2:$M$999,Veda!$G15) -> 1.19 | L15: =SUMIFS(ar6_r10!$F$2:$F$999,ar6_r10!$A$2:$A$999,Veda!$E$5,ar6_r10!$C$2:$C$999,Veda!L$17,ar6_r10!$M$2:$M$999,Veda!$G15) -> 1.43 | M15: =SUMIFS(ar6_r10!$F$2:$F$999,ar6_r10!$A$2:$A$999,Veda!$E$5,ar6_r10!$C$2:$C$999,Veda!M$17,ar6_r10!$M$2:$M$999,Veda!$G15) -> 1.65 | N15: =SUMIFS(ar6_r10!$F$2:$F$999,ar6_r10!$A$2:$A$999,Veda!$E$5,ar6_r10!$C$2:$C$999,Veda!N$17,ar6_r10!$M$2:$M$999,Veda!$G15) -> 1.81 | O15: =SUMIFS(ar6_r10!$F$2:$F$999,ar6_r10!$A$2:$A$999,Veda!$E$5,ar6_r10!$C$2:$C$999,Veda!O$17,ar6_r10!$M$2:$M$999,Veda!$G15) -> 1.93 | AH15: ts48_clu | AI15: fTS48c
A16: 5 | B16: =VLOOKUP(E16,$AK$9:$AL$15,2,FALSE)&"."&VLOOKUP(D16,$AH$9:$AI$19,2,FALSE) -> e 1.5 deg no OS.c15d | C16: 8 | D16: s5p5v5_d | E16: =E15 -> C1 | S16: ~TFM_INS-TS | AH16: s5p5v5_d | AI16: c15d
A17: 5 | B17: =VLOOKUP(E17,$AK$9:$AL$15,2,FALSE)&"."&VLOOKUP(D17,$AH$9:$AI$19,2,FALSE) -> e 1.5 deg no OS.f1d | C17: 9 | D17: s1_d | E17: =E16 -> C1 | I17: 2020 | J17: =U17 -> 2025 | K17: =V17 -> 2030 | L17: =W17 -> 2035 | M17: =X17 -> 2040 | N17: =Y17 -> 2045 | O17: =Z17 -> 2050 | S17: commodity | T17: 2022 | U17: 2025 | V17: 2030 | W17: 2035 | X17: 2040 | Y17: 2045 | Z17: 2050 | AA17: attribute | AH17: ts_12 | AI17: iTS12
A18: 5 | B18: =VLOOKUP(E18,$AK$9:$AL$15,2,FALSE)&"."&VLOOKUP(D18,$AH$9:$AI$19,2,FALSE) -> e 1.5 deg no OS.jAnn | C18: 10 | D18: ts_annual | E18: =E17 -> C1 | G18: Hydrogen as a share of electricity | I18: =SUMIFS(ar6_r10!$F$2:$F$999,ar6_r10!$A$2:$A$999,Veda!$E$5,ar6_r10!$C$2:$C$999,Veda!I$17,ar6_r10!$M$2:$M$999,Veda!$G18) -> 0.01 | J18: =SUMIFS(ar6_r10!$F$2:$F$999,ar6_r10!$A$2:$A$999,Veda!$E$5,ar6_r10!$C$2:$C$999,Veda!J$17,ar6_r10!$M$2:$M$999,Veda!$G18) -> 0.01 | K18: =SUMIFS(ar6_r10!$F$2:$F$999,ar6_r10!$A$2:$A$999,Veda!$E$5,ar6_r10!$C$2:$C$999,Veda!K$17,ar6_r10!$M$2:$M$999,Veda!$G18) -> 0.01 | L18: =SUMIFS(ar6_r10!$F$2:$F$999,ar6_r10!$A$2:$A$999,Veda!$E$5,ar6_r10!$C$2:$C$999,Veda!L$17,ar6_r10!$M$2:$M$999,Veda!$G18) -> 0.03 | M18: =SUMIFS(ar6_r10!$F$2:$F$999,ar6_r10!$A$2:$A$999,Veda!$E$5,ar6_r10!$C$2:$C$999,Veda!M$17,ar6_r10!$M$2:$M$999,Veda!$G18) -> 0.03 | N18: =SUMIFS(ar6_r10!$F$2:$F$999,ar6_r10!$A$2:$A$999,Veda!$E$5,ar6_r10!$C$2:$C$999,Veda!N$17,ar6_r10!$M$2:$M$999,Veda!$G18) -> 0.04 | O18: =SUMIFS(ar6_r10!$F$2:$F$999,ar6_r10!$A$2:$A$999,Veda!$E$5,ar6_r10!$C$2:$C$999,Veda!O$17,ar6_r10!$M$2:$M$999,Veda!$G18) -> 0.05 | S18: hydrogen_allsect | T18: =I18*T$14 -> 5.4705 | U18: =J18*U$14 -> 5.634615 | V18: =K18*V$14 -> 6.509895 | W18: =L18*W$14 -> 23.468445 | X18: =M18*X$14 -> 27.078975 | Y18: =N18*Y$14 -> 39.60642 | Z18: =O18*Z$14 -> 52.790325 | AA18: demand | AH18: ts_annual | AI18: jAnn
A19: 5 | B19: =VLOOKUP(E19,$AK$9:$AL$15,2,FALSE)&"."&VLOOKUP(D19,$AH$9:$AI$19,2,FALSE) -> e 1.5 deg no OS.iTS12 | C19: 11 | D19: ts_12 | E19: =E18 -> C1 | G19: Industry electricity share | I19: =SUMIFS(ar6_r10!$F$2:$F$999,ar6_r10!$A$2:$A$999,Veda!$E$5,ar6_r10!$C$2:$C$999,Veda!I$17,ar6_r10!$M$2:$M$999,Veda!$G19) -> 0.35 | J19: =SUMIFS(ar6_r10!$F$2:$F$999,ar6_r10!$A$2:$A$999,Veda!$E$5,ar6_r10!$C$2:$C$999,Veda!J$17,ar6_r10!$M$2:$M$999,Veda!$G19) -> 0.32 | K19: =SUMIFS(ar6_r10!$F$2:$F$999,ar6_r10!$A$2:$A$999,Veda!$E$5,ar6_r10!$C$2:$C$999,Veda!K$17,ar6_r10!$M$2:$M$999,Veda!$G19) -> 0.3 | L19: =SUMIFS(ar6_r10!$F$2:$F$999,ar6_r10!$A$2:$A$999,Veda!$E$5,ar6_r10!$C$2:$C$999,Veda!L$17,ar6_r10!$M$2:$M$999,Veda!$G19) -> 0.29 | M19: =SUMIFS(ar6_r10!$F$2:$F$999,ar6_r10!$A$2:$A$999,Veda!$E$5,ar6_r10!$C$2:$C$999,Veda!M$17,ar6_r10!$M$2:$M$999,Veda!$G19) -> 0.29 | N19: =SUMIFS(ar6_r10!$F$2:$F$999,ar6_r10!$A$2:$A$999,Veda!$E$5,ar6_r10!$C$2:$C$999,Veda!N$17,ar6_r10!$M$2:$M$999,Veda!$G19) -> 0.3 | O19: =SUMIFS(ar6_r10!$F$2:$F$999,ar6_r10!$A$2:$A$999,Veda!$E$5,ar6_r10!$C$2:$C$999,Veda!O$17,ar6_r10!$M$2:$M$999,Veda!$G19) -> 0.31 | S19: elc_industry | T19: =I19*T$14 -> 191.4675 | U19: =J19*U$14 -> 180.30768 | V19: =K19*V$14 -> 195.29685 | W19: =L19*W$14 -> 226.86163 | X19: =M19*X$14 -> 261.76342 | Y19: =N19*Y$14 -> 297.04815 | Z19: =O19*Z$14 -> 327.30001 | AA19: demand | AH19: s1_d | AI19: f1d
A20: 5 | B20: =VLOOKUP(E20,$AK$9:$AL$15,2,FALSE)&"."&VLOOKUP(D20,$AH$9:$AI$19,2,FALSE) -> d 1.5 deg OS.e3d | C20: 12 | D20: =D9 -> s1p1v1_d | E20: C2 | G20: Residential and commercial electricity share | I20: =SUMIFS(ar6_r10!$F$2:$F$999,ar6_r10!$A$2:$A$999,Veda!$E$5,ar6_r10!$C$2:$C$999,Veda!I$17,ar6_r10!$M$2:$M$999,Veda!$G20) -> 0.61 | J20: =SUMIFS(ar6_r10!$F$2:$F$999,ar6_r10!$A$2:$A$999,Veda!$E$5,ar6_r10!$C$2:$C$999,Veda!J$17,ar6_r10!$M$2:$M$999,Veda!$G20) -> 0.62 | K20: =SUMIFS(ar6_r10!$F$2:$F$999,ar6_r10!$A$2:$A$999,Veda!$E$5,ar6_r10!$C$2:$C$999,Veda!K$17,ar6_r10!$M$2:$M$999,Veda!$G20) -> 0.59 | L20: =SUMIFS(ar6_r10!$F$2:$F$999,ar6_r10!$A$2:$A$999,Veda!$E$5,ar6_r10!$C$2:$C$999,Veda!L$17,ar6_r10!$M$2:$M$999,Veda!$G20) -> 0.56 | M20: =SUMIFS(ar6_r10!$F$2:$F$999,ar6_r10!$A$2:$A$999,Veda!$E$5,ar6_r10!$C$2:$C$999,Veda!M$17,ar6_r10!$M$2:$M$999,Veda!$G20) -> 0.54 | N20: =SUMIFS(ar6_r10!$F$2:$F$999,ar6_r10!$A$2:$A$999,Veda!$E$5,ar6_r10!$C$2:$C$999,Veda!N$17,ar6_r10!$M$2:$M$999,Veda!$G20) -> 0.53 | O20: =SUMIFS(ar6_r10!$F$2:$F$999,ar6_r10!$A$2:$A$999,Veda!$E$5,ar6_r10!$C$2:$C$999,Veda!O$17,ar6_r10!$M$2:$M$999,Veda!$G20) -> 0.53 | S20: elc_buildings | T20: =I20*T$14 -> 333.7005 | U20: =J20*U$14 -> 349.34613 | V20: =K20*V$14 -> 384.0838 | W20: =L20*W$14 -> 438.07764 | X20: =M20*X$14 -> 487.42155 | Y20: =N20*Y$14 -> 524.78507 | Z20: =O20*Z$14 -> 559.57745 | AA20: demand
A21: 5 | B21: =VLOOKUP(E21,$AK$9:$AL$15,2,FALSE)&"."&VLOOKUP(D21,$AH$9:$AI$19,2,FALSE) -> d 1.5 deg OS.d9d | C21: 13 | D21: =D10 -> s3p3v3_d | E21: =E20 -> C2 | G21: Transportation electricity share | I21: =SUMIFS(ar6_r10!$F$2:$F$999,ar6_r10!$A$2:$A$999,Veda!$E$5,ar6_r10!$C$2:$C$999,Veda!I$17,ar6_r10!$M$2:$M$999,Veda!$G21) -> 0.03 | J21: =SUMIFS(ar6_r10!$F$2:$F$999,ar6_r10!$A$2:$A$999,Veda!$E$5,ar6_r10!$C$2:$C$999,Veda!J$17,ar6_r10!$M$2:$M$999,Veda!$G21) -> 0.06 | K21: =SUMIFS(ar6_r10!$F$2:$F$999,ar6_r10!$A$2:$A$999,Veda!$E$5,ar6_r10!$C$2:$C$999,Veda!K$17,ar6_r10!$M$2:$M$999,Veda!$G21) -> 0.1 | L21: =SUMIFS(ar6_r10!$F$2:$F$999,ar6_r10!$A$2:$A$999,Veda!$E$5,ar6_r10!$C$2:$C$999,Veda!L$17,ar6_r10!$M$2:$M$999,Veda!$G21) -> 0.14 | M21: =SUMIFS(ar6_r10!$F$2:$F$999,ar6_r10!$A$2:$A$999,Veda!$E$5,ar6_r10!$C$2:$C$999,Veda!M$17,ar6_r10!$M$2:$M$999,Veda!$G21) -> 0.17 | N21: =SUMIFS(ar6_r10!$F$2:$F$999,ar6_r10!$A$2:$A$999,Veda!$E$5,ar6_r10!$C$2:$C$999,Veda!N$17,ar6_r10!$M$2:$M$999,Veda!$G21) -> 0.19 | O21: =SUMIFS(ar6_r10!$F$2:$F$999,ar6_r10!$A$2:$A$999,Veda!$E$5,ar6_r10!$C$2:$C$999,Veda!O$17,ar6_r10!$M$2:$M$999,Veda!$G21) -> 0.2 | S21: elc_transport | T21: =I21*T$14 -> 16.4115 | U21: =T21 -> 16.4115 | V21: =U21 -> 16.4115 | W21: =V21 -> 16.4115 | X21: =W21 -> 16.4115 | Y21: =X21 -> 16.4115 | Z21: =Y21 -> 16.4115 | AA21: demand | AC21: non-road transport demand assumed to be constant
A22: 5 | B22: =VLOOKUP(E22,$AK$9:$AL$15,2,FALSE)&"."&VLOOKUP(D22,$AH$9:$AI$19,2,FALSE) -> d 1.5 deg OS.b2w | C22: 14 | D22: =D11 -> s2_w | E22: =E21 -> C2 | S22: elc_roadtransport | T22: =T14-SUM(T19:T21) -> 5.4705 | U22: =U14-SUM(U19:U21) -> 17.39619 | V22: =V14-SUM(V19:V21) -> 55.197345 | W22: =W14-SUM(W19:W21) -> 100.93072 | X22: =X14-SUM(X19:X21) -> 137.03602 | Y22: =Y14-SUM(Y19:Y21) -> 151.91578 | Z22: =Z14-SUM(Z19:Z21) -> 152.51754 | AA22: demand
A23: 5 | B23: =VLOOKUP(E23,$AK$9:$AL$15,2,FALSE)&"."&VLOOKUP(D23,$AH$9:$AI$19,2,FALSE) -> d 1.5 deg OS.a2w2d | C23: 15 | D23: =D12 -> s2_w_p2_d | E23: =E22 -> C2 | S23: *
A24: 5 | B24: =VLOOKUP(E24,$AK$9:$AL$15,2,FALSE)&"."&VLOOKUP(D24,$AH$9:$AI$19,2,FALSE) -> d 1.5 deg OS.hTS12c | C24: 16 | D24: =D13 -> ts12_clu | E24: =E23 -> C2 | G24: CO2 price | I24: 0 | J24: 0 | K24: =SUMIFS(ar6_r10!$F$2:$F$999,ar6_r10!$A$2:$A$999,Veda!$E$5,ar6_r10!$C$2:$C$999,Veda!K$17,ar6_r10!$M$2:$M$999,Veda!$G24) -> 241.69 | L24: =SUMIFS(ar6_r10!$F$2:$F$999,ar6_r10!$A$2:$A$999,Veda!$E$5,ar6_r10!$C$2:$C$999,Veda!L$17,ar6_r10!$M$2:$M$999,Veda!$G24) -> 339.03 | M24: =SUMIFS(ar6_r10!$F$2:$F$999,ar6_r10!$A$2:$A$999,Veda!$E$5,ar6_r10!$C$2:$C$999,Veda!M$17,ar6_r10!$M$2:$M$999,Veda!$G24) -> 410.28 | N24: =SUMIFS(ar6_r10!$F$2:$F$999,ar6_r10!$A$2:$A$999,Veda!$E$5,ar6_r10!$C$2:$C$999,Veda!N$17,ar6_r10!$M$2:$M$999,Veda!$G24) -> 494.2 | O24: =SUMIFS(ar6_r10!$F$2:$F$999,ar6_r10!$A$2:$A$999,Veda!$E$5,ar6_r10!$C$2:$C$999,Veda!O$17,ar6_r10!$M$2:$M$999,Veda!$G24) -> 635.43 | S24: co2net | U24: 0 | V24: =K24/1000 -> 0.24169 | W24: =L24/1000 -> 0.33903 | X24: =M24/1000 -> 0.41028 | Y24: =N24/1000 -> 0.4942 | Z24: =O24/1000 -> 0.63543 | AA24: com_taxnet
A25: 5 | B25: =VLOOKUP(E25,$AK$9:$AL$15,2,FALSE)&"."&VLOOKUP(D25,$AH$9:$AI$19,2,FALSE) -> d 1.5 deg OS.gTS24c | C25: 17 | D25: =D14 -> ts24_clu | E25: =E24 -> C2
A26: 5 | B26: =VLOOKUP(E26,$AK$9:$AL$15,2,FALSE)&"."&VLOOKUP(D26,$AH$9:$AI$19,2,FALSE) -> d 1.5 deg OS.fTS48c | C26: 18 | D26: =D15 -> ts48_clu | E26: =E25 -> C2 | S26: ~TFM_INS-TS
A27: 5 | B27: =VLOOKUP(E27,$AK$9:$AL$15,2,FALSE)&"."&VLOOKUP(D27,$AH$9:$AI$19,2,FALSE) -> d 1.5 deg OS.c15d | C27: 19 | D27: =D16 -> s5p5v5_d | E27: =E26 -> C2 | S27: process | T27: =T17 -> 2022 | U27: =U17 -> 2025 | V27: =V17 -> 2030 | W27: =W17 -> 2035 | X27: =X17 -> 2040 | Y27: =Y17 -> 2045 | Z27: =Z17 -> 2050 | AA27: attribute | AB27: limtype
A28: 5 | B28: =VLOOKUP(E28,$AK$9:$AL$15,2,FALSE)&"."&VLOOKUP(D28,$AH$9:$AI$19,2,FALSE) -> d 1.5 deg OS.f1d | C28: 20 | D28: =D17 -> s1_d | E28: =E27 -> C2 | Q28: =SUMIFS(iea_data!G3:G9999,iea_data!$B$3:$B$9999,Veda!$S$11) -> 49.33 | S28: Trd_electricity import | T28: =Q28 -> 49.33 | AA28: ACT_BND | AB28: FX
A29: 5 | B29: =VLOOKUP(E29,$AK$9:$AL$15,2,FALSE)&"."&VLOOKUP(D29,$AH$9:$AI$19,2,FALSE) -> d 1.5 deg OS.jAnn | C29: 21 | D29: =D18 -> ts_annual | E29: =E28 -> C2 | Q29: =SUMIFS(iea_data!H3:H9999,iea_data!$B$3:$B$9999,Veda!$S$11) -> -76.59 | S29: Trd_electricity export | T29: =-1*Q29 -> 76.59 | AA29: ACT_BND | AB29: FX
A30: 5 | B30: =VLOOKUP(E30,$AK$9:$AL$15,2,FALSE)&"."&VLOOKUP(D30,$AH$9:$AI$19,2,FALSE) -> d 1.5 deg OS.iTS12 | C30: 22 | D30: =D19 -> ts_12 | E30: =E29 -> C2
A31: 5 | B31: =VLOOKUP(E31,$AK$9:$AL$15,2,FALSE)&"."&VLOOKUP(D31,$AH$9:$AI$19,2,FALSE) -> c 2 deg (67%).e3d | C31: 23 | D31: =D20 -> s1p1v1_d | E31: C3
A32: 5 | B32: =VLOOKUP(E32,$AK$9:$AL$15,2,FALSE)&"."&VLOOKUP(D32,$AH$9:$AI$19,2,FALSE) -> c 2 deg (67%).d9d | C32: 24 | D32: =D21 -> s3p3v3_d | E32: =E31 -> C3
A33: 5 | B33: =VLOOKUP(E33,$AK$9:$AL$15,2,FALSE)&"."&VLOOKUP(D33,$AH$9:$AI$19,2,FALSE) -> c 2 deg (67%).b2w | C33: 25 | D33: =D22 -> s2_w | E33: =E32 -> C3
A34: 5 | B34: =VLOOKUP(E34,$AK$9:$AL$15,2,FALSE)&"."&VLOOKUP(D34,$AH$9:$AI$19,2,FALSE) -> c 2 deg (67%).a2w2d | C34: 26 | D34: =D23 -> s2_w_p2_d | E34: =E33 -> C3
A35: 5 | B35: =VLOOKUP(E35,$AK$9:$AL$15,2,FALSE)&"."&VLOOKUP(D35,$AH$9:$AI$19,2,FALSE) -> c 2 deg (67%).hTS12c | C35: 27 | D35: =D24 -> ts12_clu | E35: =E34 -> C3
A36: 5 | B36: =VLOOKUP(E36,$AK$9:$AL$15,2,FALSE)&"."&VLOOKUP(D36,$AH$9:$AI$19,2,FALSE) -> c 2 deg (67%).gTS24c | C36: 28 | D36: =D25 -> ts24_clu | E36: =E35 -> C3 | G36: C7
A37: 5 | B37: =VLOOKUP(E37,$AK$9:$AL$15,2,FALSE)&"."&VLOOKUP(D37,$AH$9:$AI$19,2,FALSE) -> c 2 deg (67%).fTS48c | C37: 29 | D37: =D26 -> ts48_clu | E37: =E36 -> C3 | G37: Gas Price | I37: =SUMIFS(ar6_r10!$F$2:$F$999,ar6_r10!$A$2:$A$999,Veda!$G$36,ar6_r10!$C$2:$C$999,Veda!I$17,ar6_r10!$M$2:$M$999,Veda!$G37) -> 1 | J37: =SUMIFS(ar6_r10!$F$2:$F$999,ar6_r10!$A$2:$A$999,Veda!$G$36,ar6_r10!$C$2:$C$999,Veda!J$17,ar6_r10!$M$2:$M$999,Veda!$G37) -> 1.07 | K37: =SUMIFS(ar6_r10!$F$2:$F$999,ar6_r10!$A$2:$A$999,Veda!$G$36,ar6_r10!$C$2:$C$999,Veda!K$17,ar6_r10!$M$2:$M$999,Veda!$G37) -> 1.24 | L37: =SUMIFS(ar6_r10!$F$2:$F$999,ar6_r10!$A$2:$A$999,Veda!$G$36,ar6_r10!$C$2:$C$999,Veda!L$17,ar6_r10!$M$2:$M$999,Veda!$G37) -> 1.15 | M37: =SUMIFS(ar6_r10!$F$2:$F$999,ar6_r10!$A$2:$A$999,Veda!$G$36,ar6_r10!$C$2:$C$999,Veda!M$17,ar6_r10!$M$2:$M$999,Veda!$G37) -> 1.25 | N37: =SUMIFS(ar6_r10!$F$2:$F$999,ar6_r10!$A$2:$A$999,Veda!$G$36,ar6_r10!$C$2:$C$999,Veda!N$17,ar6_r10!$M$2:$M$999,Veda!$G37) -> 1.17 | O37: =SUMIFS(ar6_r10!$F$2:$F$999,ar6_r10!$A$2:$A$999,Veda!$G$36,ar6_r10!$C$2:$C$999,Veda!O$17,ar6_r10!$M$2:$M$999,Veda!$G37) -> 1.34
A38: 5 | B38: =VLOOKUP(E38,$AK$9:$AL$15,2,FALSE)&"."&VLOOKUP(D38,$AH$9:$AI$19,2,FALSE) -> c 2 deg (67%).c15d | C38: 30 | D38: =D27 -> s5p5v5_d | E38: =E37 -> C3 | G38: Coal Price | I38: =SUMIFS(ar6_r10!$F$2:$F$999,ar6_r10!$A$2:$A$999,Veda!$G$36,ar6_r10!$C$2:$C$999,Veda!I$17,ar6_r10!$M$2:$M$999,Veda!$G38) -> 1 | J38: =SUMIFS(ar6_r10!$F$2:$F$999,ar6_r10!$A$2:$A$999,Veda!$G$36,ar6_r10!$C$2:$C$999,Veda!J$17,ar6_r10!$M$2:$M$999,Veda!$G38) -> 1.02 | K38: =SUMIFS(ar6_r10!$F$2:$F$999,ar6_r10!$A$2:$A$999,Veda!$G$36,ar6_r10!$C$2:$C$999,Veda!K$17,ar6_r10!$M$2:$M$999,Veda!$G38) -> 1.06 | L38: =SUMIFS(ar6_r10!$F$2:$F$999,ar6_r10!$A$2:$A$999,Veda!$G$36,ar6_r10!$C$2:$C$999,Veda!L$17,ar6_r10!$M$2:$M$999,Veda!$G38) -> 1.07 | M38: =SUMIFS(ar6_r10!$F$2:$F$999,ar6_r10!$A$2:$A$999,Veda!$G$36,ar6_r10!$C$2:$C$999,Veda!M$17,ar6_r10!$M$2:$M$999,Veda!$G38) -> 1.08 | N38: =SUMIFS(ar6_r10!$F$2:$F$999,ar6_r10!$A$2:$A$999,Veda!$G$36,ar6_r10!$C$2:$C$999,Veda!N$17,ar6_r10!$M$2:$M$999,Veda!$G38) -> 1.1 | O38: =SUMIFS(ar6_r10!$F$2:$F$999,ar6_r10!$A$2:$A$999,Veda!$G$36,ar6_r10!$C$2:$C$999,Veda!O$17,ar6_r10!$M$2:$M$999,Veda!$G38) -> 1.12
A39: 5 | B39: =VLOOKUP(E39,$AK$9:$AL$15,2,FALSE)&"."&VLOOKUP(D39,$AH$9:$AI$19,2,FALSE) -> c 2 deg (67%).f1d | C39: 31 | D39: =D28 -> s1_d | E39: =E38 -> C3 | G39: Oil Price | I39: =SUMIFS(ar6_r10!$F$2:$F$999,ar6_r10!$A$2:$A$999,Veda!$G$36,ar6_r10!$C$2:$C$999,Veda!I$17,ar6_r10!$M$2:$M$999,Veda!$G39) -> 1 | J39: =SUMIFS(ar6_r10!$F$2:$F$999,ar6_r10!$A$2:$A$999,Veda!$G$36,ar6_r10!$C$2:$C$999,Veda!J$17,ar6_r10!$M$2:$M$999,Veda!$G39) -> 1.01 | K39: =SUMIFS(ar6_r10!$F$2:$F$999,ar6_r10!$A$2:$A$999,Veda!$G$36,ar6_r10!$C$2:$C$999,Veda!K$17,ar6_r10!$M$2:$M$999,Veda!$G39) -> 1.11 | L39: =SUMIFS(ar6_r10!$F$2:$F$999,ar6_r10!$A$2:$A$999,Veda!$G$36,ar6_r10!$C$2:$C$999,Veda!L$17,ar6_r10!$M$2:$M$999,Veda!$G39) -> 1.01 | M39: =SUMIFS(ar6_r10!$F$2:$F$999,ar6_r10!$A$2:$A$999,Veda!$G$36,ar6_r10!$C$2:$C$999,Veda!M$17,ar6_r10!$M$2:$M$999,Veda!$G39) -> 1.01 | N39: =SUMIFS(ar6_r10!$F$2:$F$999,ar6_r10!$A$2:$A$999,Veda!$G$36,ar6_r10!$C$2:$C$999,Veda!N$17,ar6_r10!$M$2:$M$999,Veda!$G39) -> 1.04 | O39: =SUMIFS(ar6_r10!$F$2:$F$999,ar6_r10!$A$2:$A$999,Veda!$G$36,ar6_r10!$C$2:$C$999,Veda!O$17,ar6_r10!$M$2:$M$999,Veda!$G39) -> 1.14
A40: 5 | B40: =VLOOKUP(E40,$AK$9:$AL$15,2,FALSE)&"."&VLOOKUP(D40,$AH$9:$AI$19,2,FALSE) -> c 2 deg (67%).jAnn | C40: 32 | D40: =D29 -> ts_annual | E40: =E39 -> C3 | G40: Biomass Price | I40: =SUMIFS(ar6_r10!$F$2:$F$999,ar6_r10!$A$2:$A$999,Veda!$G$36,ar6_r10!$C$2:$C$999,Veda!I$17,ar6_r10!$M$2:$M$999,Veda!$G40) -> 1 | J40: =SUMIFS(ar6_r10!$F$2:$F$999,ar6_r10!$A$2:$A$999,Veda!$G$36,ar6_r10!$C$2:$C$999,Veda!J$17,ar6_r10!$M$2:$M$999,Veda!$G40) -> 0.96 | K40: =SUMIFS(ar6_r10!$F$2:$F$999,ar6_r10!$A$2:$A$999,Veda!$G$36,ar6_r10!$C$2:$C$999,Veda!K$17,ar6_r10!$M$2:$M$999,Veda!$G40) -> 1.04 | L40: =SUMIFS(ar6_r10!$F$2:$F$999,ar6_r10!$A$2:$A$999,Veda!$G$36,ar6_r10!$C$2:$C$999,Veda!L$17,ar6_r10!$M$2:$M$999,Veda!$G40) -> 1.04 | M40: =SUMIFS(ar6_r10!$F$2:$F$999,ar6_r10!$A$2:$A$999,Veda!$G$36,ar6_r10!$C$2:$C$999,Veda!M$17,ar6_r10!$M$2:$M$999,Veda!$G40) -> 0.98 | N40: =SUMIFS(ar6_r10!$F$2:$F$999,ar6_r10!$A$2:$A$999,Veda!$G$36,ar6_r10!$C$2:$C$999,Veda!N$17,ar6_r10!$M$2:$M$999,Veda!$G40) -> 0.99 | O40: =SUMIFS(ar6_r10!$F$2:$F$999,ar6_r10!$A$2:$A$999,Veda!$G$36,ar6_r10!$C$2:$C$999,Veda!O$17,ar6_r10!$M$2:$M$999,Veda!$G40) -> 1
A41: 5 | B41: =VLOOKUP(E41,$AK$9:$AL$15,2,FALSE)&"."&VLOOKUP(D41,$AH$9:$AI$19,2,FALSE) -> c 2 deg (67%).iTS12 | C41: 33 | D41: =D30 -> ts_12 | E41: =E40 -> C3
A42: 5 | B42: =VLOOKUP(E42,$AK$9:$AL$15,2,FALSE)&"."&VLOOKUP(D42,$AH$9:$AI$19,2,FALSE) -> b 2 deg (50%).e3d | C42: 34 | D42: =D31 -> s1p1v1_d | E42: C4
...

Sheet fuel_prices
A9: Fuel Prices
A10: iso | B10: gas_low | C10: gas_high | D10: coal_low | E10: coal_high | F10: oil_low | G10: oil_high | H10: bioenergy_low | I10: bioenergy_high | J10: Notes
A11: DEU | B11: 29.1 | C11: 41.1 | D11: 13.7 | E11: 16.7 | F11: 48 | G11: 58 | H11: 24 | I11: 32 | J11: TTF gas hub, imported coal via ARA

Sheet iea_data
A9: IEA Baseline Data
A10: iso | B10: year | C10: industry_twh | D10: buildings_agri_twh | E10: nonroad_transport_twh | F10: road_transport_twh | G10: imports_twh | H10: exports_twh | I10: total_production_twh
A11: DEU | B11: 2000 | C11: 296.72 | D11: 255.95 | E11: 15.91 | F11: 0 | G11: 45.13 | H11: -42.08 | I11: 572.31
A12: DEU | B12: 2001 | C12: 302.91 | D12: 259.64 | E12: 16.4 | F12: 0 | G12: 45.78 | H12: -42.12 | I12: 581.89
A13: DEU | B13: 2002 | C13: 297.21 | D13: 271.74 | E13: 16.19 | F13: 0 | G13: 48.37 | H13: -38.37 | I13: 581.95
A14: DEU | B14: 2003 | C14: 299.03 | D14: 281.33 | E14: 13.04 | F14: 0.02 | G14: 49.11 | H14: -52.38 | I14: 604.68
A15: DEU | B15: 2004 | C15: 306.79 | D15: 281.62 | E15: 12.88 | F15: 0.02 | G15: 48.19 | H15: -50.81 | I15: 612.36
A16: DEU | B16: 2005 | C16: 312.43 | D16: 278.71 | E16: 13.12 | F16: 0.02 | G16: 56.86 | H16: -61.43 | I16: 616.34
A17: DEU | B17: 2006 | C17: 312.93 | D17: 283.65 | E17: 12.67 | F17: 0.02 | G17: 48.46 | H17: -65.44 | I17: 633.35
A18: DEU | B18: 2007 | C18: 320.33 | D18: 277.98 | E18: 12.22 | F18: 0.02 | G18: 45.95 | H18: -62.51 | I18: 634.44
A19: DEU | B19: 2008 | C19: 315.16 | D19: 281.69 | E19: 11.09 | F19: 0.02 | G19: 41.67 | H19: -61.77 | I19: 635.2
A20: DEU | B20: 2009 | C20: 276.39 | D20: 283.85 | E20: 11.58 | F20: 0.02 | G20: 41.86 | H20: -54.13 | I20: 590.82
A21: DEU | B21: 2010 | C21: 301.16 | D21: 291.42 | E21: 12.06 | F21: 0.02 | G21: 42.96 | H21: -57.92 | I21: 626.72
A22: DEU | B22: 2011 | C22: 306.11 | D22: 278.54 | E22: 12.08 | F22: 0.02 | G22: 51 | H22: -54.77 | I22: 607.28
... A33: DEU | B33: 2022 | C33: 269.71 | D33: 256.96 | E33: 10.69 | F33: 2.45 | G33: 49.33 | H33: -76.59 | I33: 574.31

Sheet ar6_r10
A9: AR6 Scenario Drivers
A10: Category | B10: Region | C10: Year | D10: count | E10: mean | F10: median | G10: std | H10: min | I10: max | J10: q25 | K10: q75 | L10: category_description | M10: attribute
A11: C1 | B11: R10EUROPE | C11: 2020 | D11: 60 | E11: 8.68 | F11: 6.87 | G11: 10.43 | H11: 0 | I11: 55.17 | J11: 0 | K11: 13.64 | L11: Limit warming to 1.5°C (>50%) with no or limited overshoot | M11: CO2 price
A12: C1 | B12: R10EUROPE | C12: 2025 | D12: 60 | E12: 190.52 | F12: 181.51 | G12: 136.23 | H12: 1.81 | I12: 626.48 | J12: 115.48 | K12: 238.58 | L12: Limit warming to 1.5°C (>50%) with no or limited overshoot | M12: CO2 price
A13: C1 | B13: R10EUROPE | C13: 2030 | D13: 60 | E13: 268.18 | F13: 241.69 | G13: 134.29 | H13: 1.27 | I13: 673.46 | J13: 182.47 | K13: 329.7 | L13: Limit warming to 1.5°C (>50%) with no or limited overshoot | M13: CO2 price
A14: C1 | B14: R10EUROPE | C14: 2035 | D14: 60 | E14: 363.27 | F14: 339.03 | G14: 173.79 | H14: 14.37 | I14: 859.53 | J14: 227.05 | K14: 483.38 | L14: Limit warming to 1.5°C (>50%) with no or limited overshoot | M14: CO2 price
A15: C1 | B15: R10EUROPE | C15: 2040 | D15: 60 | E15: 471.65 | F15: 410.28 | G15: 224.31 | H15: 162.1 | I15: 1097.01 | J15: 298.63 | K15: 622.14 | L15: Limit warming to 1.5°C (>50%) with no or limited overshoot | M15: CO2 price
A16: C1 | B16: R10EUROPE | C16: 2045 | D16: 60 | E16: 565.69 | F16: 494.2 | G16: 256.15 | H16: 193.42 | I16: 1269.88 | J16: 352.78 | K16: 748.01 | L16: Limit warming to 1.5°C (>50%) with no or limited overshoot | M16: CO2 price
A17: C1 | B17: R10EUROPE | C17: 2050 | D17: 60 | E17: 647.44 | F17: 635.43 | G17: 273.56 | H17: 209.76 | I17: 1170.26 | J17: 409.79 | K17: 887.68 | L17: Limit warming to 1.5°C (>50%) with no or limited overshoot | M17: CO2 price
A18: C2 | B18: R10EUROPE | C18: 2020 | D18: 86 | E18: 6.44 | F18: 0 | G18: 8.34 | H18: 0 | I18: 24.5 | J18: 0 | K18: 12.68 | L18: Limit warming to 1.5°C (>67%) with high overshoot | M18: CO2 price
A19: C2 | B19: R10EUROPE | C19: 2025 | D19: 75 | E19: 63.21 | F19: 44.89 | G19: 56.62 | H19: 3.21 | I19: 273 | J19: 27.09 | K19: 77.31 | L19: Limit warming to 1.5°C (>67%) with high overshoot | M19: CO2 price
A20: C2 | B20: R10EUROPE | C20: 2030 | D20: 86 | E20: 85.48 | F20: 63.36 | G20: 73.46 | H20: 0 | I20: 409.5 | J20: 50 | K20: 111.1 | L20: Limit warming to 1.5°C (>67%) with high overshoot | M20: CO2 price
A21: C2 | B21: R10EUROPE | C21: 2035 | D21: 75 | E21: 208.71 | F21: 154.82 | G21: 291.78 | H21: 60.83 | I21: 2037.12 | J21: 93.79 | K21: 206.26 | L21: Limit warming to 1.5°C (>67%) with high overshoot | M21: CO2 price
A22: C2 | B22: R10EUROPE | C22: 2040 | D22: 86 | E22: 253.33 | F22: 172.09 | G22: 359.35 | H22: 0 | I22: 2600 | J22: 119.07 | K22: 259.4 | L22: Limit warming to 1.5°C (>67%) with high overshoot | M22: CO2 price
... A221: C1 | B221: R10EUROPE | C221: 2020 | D221: 33 | E221: 1 | F221: 1 | G221: 0 | H221: 1 | I221: 1 | J221: 1 | K221: 1 | L221: Limit warming to 1.5°C (>50%) with no or limited overshoot | M221: Gas price
A222: C1 | B222: R10EUROPE | C222: 2025 | D222: 34 | E222: 65535 | F222: 2.42 | H222: 1.18 | I222: 65535 | J222: 2.01 | K222: 2.75 | L222: Limit warming to 1.5°C (>50%) with no or limited overshoot | M222: Gas price
A223: C1 | B223: R10EUROPE | C223: 2030 | D223: 34 | E223: 65535 | F223: 3.1 | H223: 1.71 | I223: 65535 | J223: 2.38 | K223: 3.46 | L223: Limit warming to 1.5°C (>50%) with no or limited overshoot | M223: Gas price
A224: C1 | B224: R10EUROPE | C224: 2035 | D224: 34 | E224: 65535 | F224: 3.54 | H224: 1.91 | I224: 65535 | J224: 2.66 | K224: 4.16 | L224: Limit warming to 1.5°C (>50%) with no or limited overshoot | M224: Gas price
A225: C1 | B225: R10EUROPE | C225: 2040 | D225: 34 | E225: 65535 | F225: 4.1 | H225: 2.27 | I225: 65535 | J225: 2.96 | K225: 4.52 | L225: Limit warming to 1.5°C (>50%) with no or limited overshoot | M225: Gas price
A226: C1 | B226: R10EUROPE | C226: 2045 | D226: 34 | E226: 65535 | F226: 3.86 | H226: 2.54 | I226: 65535 | J226: 3.3 | K226: 4.89 | L226: Limit warming to 1.5°C (>50%) with no or limited overshoot | M226: Gas price
A227: C1 | B227: R10EUROPE | C227: 2050 | D227: 34 | E227: 65535 | F227: 3.59 | H227: 2.73 | I227: 65535 | J227: 3.07 | K227: 4.06 | L227: Limit warming to 1.5°C (>50%) with no or limited overshoot | M227: Gas price
A228: C2 | B228: R10EUROPE | C228: 2020 | D228: 43 | E228: 1 | F228: 1 | G228: 0 | H228: 1 | I228: 1 | J228: 1 | K228: 1 | L228: Limit warming to 1.5°C (>67%) with high overshoot | M228: Gas price
A229: C2 | B229: R10EUROPE | C229: 2025 | D229: 44 | E229: 65535 | F229: 1.22 | H229: 0 | I229: 65535 | J229: 1.13 | K229: 1.35 | L229: Limit warming to 1.5°C (>67%) with high overshoot | M229: Gas price
A230: C2 | B230: R10EUROPE | C230: 2030 | D230: 44 | E230: 65535 | F230: 1.5 | H230: 0 | I230: 65535 | J230: 1.31 | K230: 1.83 | L230: Limit warming to 1.5°C (>67%) with high overshoot | M230: Gas price
A231: C2 | B231: R10EUROPE | C231: 2035 | D231: 44 | E231: 65535 | F231: 2.12 | H231: 0 | I231: 65535 | J231: 1.68 | K231: 2.46 | L231: Limit warming to 1.5°C (>67%) with high overshoot | M231: Gas price
A232: C2 | B232: R10EUROPE | C232: 2040 | D232: 44 | E232: 65535 | F232: 2.5 | H232: 0 | I232: 65535 | J232: 2 | K232: 2.94 | L232: Limit warming to 1.5°C (>67%) with high overshoot | M232: Gas price
A233: C2 | B233: R10EUROPE | C233: 2045 | D233: 44 | E233: 65535 | F233: 2.79 | H233: 0 | I233: 65535 | J233: 2.08 | K233: 3.44 | L233: Limit warming to 1.5°C (>67%) with high overshoot | M233: Gas price
A234: C2 | B234: R10EUROPE | C234: 2050 | D234: 44 | E234: 65535 | F234: 2.95 | H234: 0 | I234: 65535 | J234: 2.49 | K234: 3.78 | L234: Limit warming to 1.5°C (>67%) with high overshoot | M234: Gas price
A235: C3 | B235: R10EUROPE | C235: 2020 | D235: 103 | E235: 1 | F235: 1 | G235: 0 | H235: 1 | I235: 1 | J235: 1 | K235: 1 | L235: Limit warming to 2°C (>67%) with higher action post-2030 | M235: Gas price
A236: C3 | B236: R10EUROPE | C236: 2025 | D236: 112 | E236: 65535 | F236: 1.41 | H236: 0.98 | I236: 65535 | J236: 1.23 | K236: 1.96 | L236: Limit warming to 2°C (>67%) with higher action post-2030 | M236: Gas price
A237: C3 | B237: R10EUROPE | C237: 2030 | D237: 112 | E237: 65535 | F237: 2.04 | H237: 1.05 | I237: 65535 | J237: 1.52 | K237: 2.55 | L237: Limit warming to 2°C (>67%) with higher action post-2030 | M237: Gas price
A238: C3 | B238: R10EUROPE | C238: 2035 | D238: 112 | E238: 65535 | F238: 2.4 | H238: 1.05 | I238: 65535 | J238: 1.71 | K238: 3.14 | L238: Limit warming to 2°C (>67%) with higher action post-2030 | M238: Gas price
A239: C3 | B239: R10EUROPE | C239: 2040 | D239: 112 | E239: 65535 | F239: 2.6 | H239: 1.06 | I239: 65535 | J239: 1.85 | K239: 3.74 | L239: Limit warming to 2°C (>67%) with higher action post-2030 | M239: Gas price
A240: C3 | B240: R10EUROPE | C240: 2045 | D240: 112 | E240: 65535 | F240: 2.85 | H240: 1.08 | I240: 65535 | J240: 2 | K240: 4.28 | L240: Limit warming to 2°C (>67%) with higher action post-2030 | M240: Gas price
A241: C3 | B241: R10EUROPE | C241: 2050 | D241: 112 | E241: 65535 | F241: 2.97 | H241: 0 | I241: 65535 | J241: 2.15 | K241: 4.51 | L241: Limit warming to 2°C (>67%) with higher action post-2030 | M241: Gas price
A242: C4 | B242: R10EUROPE | C242: 2020 | D242: 27 | E242: 1 | F242: 1 | G242: 0 | H242: 1 | I242: 1 | J242: 1 | K242: 1 | L242: Limit warming to 2°C (>50%) with immediate action | M242: Gas price
A243: C4 | B243: R10EUROPE | C243: 2025 | D243: 27 | E243: 1.33 | F243: 1.31 | G243: 0.18 | H243: 1.06 | I243: 1.66 | J243: 1.22 | K243: 1.45 | L243: Limit warming to 2°C (>50%) with immediate action | M243: Gas price
A244: C4 | B244: R10EUROPE | C244: 2030 | D244: 27 | E244: 1.84 | F244: 2.02 | G244: 0.28 | H244: 1.24 | I244: 2.17 | J244: 1.52 | K244: 2.07 | L244: Limit warming to 2°C (>50%) with immediate action | M244: Gas price
A245: C4 | B245: R10EUROPE | C245: 2035 | D245: 27 | E245: 1.84 | F245: 1.96 | G245: 0.41 | H245: 1.19 | I245: 2.46 | J245: 1.42 | K245: 2.11 | L245: Limit warming to 2°C (>50%) with immediate action | M245: Gas price
A246: C4 | B246: R10EUROPE | C246: 2040 | D246: 27 | E246: 2.12 | F246: 2.22 | G246: 0.47 | H246: 1.41 | I246: 2.78 | J246: 1.54 | K246: 2.43 | L246: Limit warming to 2°C (>50%) with immediate action | M246: Gas price
...

Sheet ev_charging_uc
A10: =IFERROR(Veda!D5,"ts_12") -> s2_w | C10: day_night | D10: s1p1v1_d | F10: day_night | G10: s3p3v3_d | I10: day_night | J10: s2_w | L10: day_night | M10: s2_w_p2_d | O10: day_night | P10: ts12_clu | R10: day_night | S10: ts24_clu | U10: day_night | V10: ts48_clu | X10: day_night | Y10: s5p5v5_d | AA10: day_night | AB10: s1_d | AD10: day_night | AE10: ts_annual | AG10: day_night | AH10: ts_12
C11: D | D11: S2b0314h09,S2b0314h15,S2c0316h14,S3aH3,S2b0314h10,S2d1006h16,S3aH2,S2b0314h13,S2c0316h15,S2c0316h17,S2d1006h08,S2b0314h17,S3aH8,S4aH5,S2aH8,S2c0316h10,S2d1006h10,S2d1006h11,S4aH2,S1aH6,S2d1006h17,S3aH7,S1aH4,S2aH2,S2c0316h08,S2d1006h07,S2d1006h09,S4aH6,S2aH7,S2b0314h14,S2d1006h13,S3aH4,S4aH3,S4aH4,S1aH3,S2b0314h08,S2c0316h11,S2c0316h16,S2d1006h18,S2c0316h18,S2d1006h12,S2aH6,S2b0314h07,S3aH5,S1aH5,S2aH4,S2aH5,S2b0314h12,S1aH2,S1aH7,S2aH3,S2c0316h09,S2c0316h13,S2d1006h14,S3aH6,S4aH7,S2b0314h11,S2b0314h16,S2c0316h12,S2d1006h15,S4aH8,S1aH8,S2b0314h18,S2c0316h07 | F11: D | G11: S1b0131h09,S2d0316h12,S3h0918h15,S4i1006h07,S5aH4,S6aH3,S6aH4,S1b0131h13,S2c0314h10,S2d0316h07,S2e0317h09,S3f0721h09,S3f0721h14,S3f0721h17,S3g0728h07,S3h0918h07,S3h0918h08,S4i1006h10,S5j1115h14,S6aH7,S1b0131h07,S1b0131h11,S2aH6,S2c0314h11,S2d0316h09,S3aH5,S3g0728h13,S3g0728h15,S4i1006h09,S5aH3,S1b0131h17,S2c0314h12,S2c0314h14,S2d0316h15,S2e0317h07,S3f0721h11,S3f0721h13,S3f0721h18,S4aH5,S4i1006h11,S5j1115h08,S5j1115h09,S1aH3,S1b0131h10,S1b0131h14,S2e0317h08,S3h0918h13,S3h0918h17,S1b0131h18,S2c0314h18,S2d0316h16,S2e0317h16,S3aH3,S3f0721h10,S4i1006h15,S5j1115h07,S5j1115h10,S2c0314h13,S2d0316h10,S2d0316h18,S2e0317h10,S2e0317h12,S3h0918h14,S1b0131h12,S2d0316h08,S2d0316h13,S2d0316h14,S3f0721h12,S4aH2,S4i1006h08,S4i1006h18,S5j1115h11,S5j1115h12,S5j1115h17,S1b0131h16,S2c0314h07,S2c0314h08,S3aH2,S4i1006h17,S5j1115h13,S1aH5,S1b0131h08,S2aH4,S2aH5,S2d0316h17,S3f0721h15,S3g0728h14,S3h0918h09,S5aH2,S5aH5,S5j1115h18,S6aH2,S2aH7,S2e0317h14,S3aH4,S3f0721h16,S3g0728h16,S3h0918h10,S4aH3,S4aH4,S4i1006h14,S1aH2,S1aH7,S2aH3,S2c0314h09,S2e0317h11,S2e0317h18,S3aH6,S3g0728h17,S3h0918h12,S4aH7,S4i1006h13,S5aH6,S5aH7,S6aH6,S2c0314h16,S2c0314h17,S2d0316h11,S2e0317h13,S2e0317h15,S3aH7,S3g0728h08,S3g0728h09,S3g0728h18,S3h0918h11,S5j1115h16,S1b0131h15,S2e0317h17,S3g0728h10,S3h0918h18,S4i1006h16,S6aH5,S1aH6,S2c0314h15,S3h0918h16,S4i1006h12,S5j1115h15,S1aH4,S2aH2,S3f0721h07,S3f0721h08,S3g0728h11,S3g0728h12,S4aH6 | I11: D | J11: S3b0910h13,S3b0910h14,S3b0911h16,S3b0912h18,S3b0913h16,S3b0915h11,S3b0916h14,S3b0916h18,S4aH5,S5c1122h08,S5c1122h18,S5c1124h08,S5c1124h11,S5c1124h12,S1aH2,S1aH7,S2aH3,S3aH6,S3b0910h12,S3b0911h10,S3b0914h18,S3b0915h10,S4aH7,S5aH6,S5aH7,S5c1119h15,S5c1119h17,S5c1122h10,S5c1122h11,S5c1124h10,S6aH6,S1aH5,S2aH4,S2aH5,S3b0910h11,S3b0913h13,S3b0914h14,S3b0916h15,S3b0916h17,S5aH2,S5aH5,S5c1119h13,S5c1125h12,S6aH2,S3aH3,S3b0910h16,S3b0911h07,S3b0914h10,S3b0915h15,S3b0915h17,S5c1119h08,S5c1119h18,S5c1120h18,S5c1121h11,S5c1121h15,S5c1122h07,S5c1123h16,S5c1125h17,S3b0911h17,S3b0912h09,S3b0913h14,S3b0914h07,S3b0916h08,S3b0916h10,S4aH2,S5c1119h10,S5c1122h15,S5c1123h12,S5c1123h18,S5c1125h08,S5c1125h18,S3b0913h15,S3b0915h14,S5c1119h16,S5c1120h11,S5c1121h12,S5c1121h13,S5c1121h16,S5c1122h14,S5c1124h15,S5c1124h17,S5c1125h10,S5c1125h15,S6aH5,S3b0911h12,S3b0912h11,S3b0912h12,S3b0912h13,S3b0915h18,S3b0916h16,S5aH4,S5c1121h09,S5c1122h09,S5c1123h17,S5c1125h13,S6aH3,S6aH4,S3aH2,S3b0911h13,S3b0913h11,S3b0914h13,S5c1120h10,S5c1124h09,S1aH3,S3b0911h09,S3b0911h14,S3b0912h07,S3b0915h09,S5c1120h08,S5c1122h13,S5c1123h11,S5c1125h07,S3b0910h15,S3b0912h15,S3b0913h18,S3b0914h08,S3b0914h11,S3b0915h16,S3b0916h11,S5c1119h12,S5c1120h15,S5c1120h17,S5c1121h10,S5c1123h13,S5c1125h11,S2aH7,S3aH4,S3b0910h10,S3b0911h08,S3b0911h15,S3b0912h10,S3b0912h16,S3b0913h09,S3b0914h09,S3b0914h12,S4aH3,S4aH4,S5c1119h09,S5c1120h16,S5c1121h14,S5c1123h09,S5c1123h10,S5c1124h13,S5c1125h09,S1aH6,S3b0910h09,S3b0910h18,S3b0912h08,S3b0912h17,S5c1119h11,S5c1120h07,S5c1121h07,S5c1121h08,S5c1122h12,S5c1122h17,S5c1123h08,S5c1124h07,S5c1124h14,S5c1125h16,S3aH7,S3b0913h07,S3b0915h08,S3b0916h12,S5c1119h07,S5c1120h13,S5c1125h14,S2aH6,S3aH5,S3b0910h17,S3b0912h14,S3b0913h17,S3b0914h16,S5aH3,S5c1120h14,S5c1122h16,S5c1123h15,S1aH4,S2aH2,S3b0910h07,S3b0913h08,S3b0913h12,S3b0914h15,S3b0914h17,S3b0915h07,S3b0915h12,S3b0915h13,S4aH6,S5c1119h14,S5c1120h09,S5c1120h12,S5c1121h17,S5c1123h14,S5c1124h16,S3b0910h08,S3b0911h11,S3b0911h18,S3b0913h10,S3b0916h07,S3b0916h09,S3b0916h13,S5c1121h18,S5c1123h07,S5c1124h18,S6aH7 | L11: D | M11: S2b0316h10,S2c0317h09,S3d0911h14,S3d0912h08,S3d0916h10,S4aH2,S5e1119h09,S5e1119h15,S5e1121h09,S5e1123h10,S5e1125h12,S2b0316h12,S3d0910h11,S3d0910h14,S3d0910h17,S3d0911h08,S3d0911h12,S3d0914h15,S3d0915h10,S3d0915h11,S3d0916h14,S5e1119h08,S5e1122h17,S5e1124h13,S5e1125h11,S5e1125h16,S6aH5,S2aH6,S2c0317h17,S3aH5,S3d0911h15,S3d0912h12,S3d0912h13,S3d0912h17,S3d0912h18,S3d0913h13,S3d0915h14,S3d0915h18,S5aH3,S5e1119h17,S5e1122h11,S5e1122h16,S5e1123h18,S5e1124h18,S2b0316h13,S2b0316h15,S2b0316h18,S2c0317h10,S3aH2,S3d0912h11,S3d0913h17,S3d0914h08,S5e1120h12,S5e1121h14,S5e1122h10,S5e1123h11,S5e1123h17,S5e1124h12,S2b0316h07,S2c0317h08,S3d0910h16,S3d0913h09,S3d0913h10,S3d0914h11,S3d0916h15,S3d0916h16,S5aH4,S5e1119h12,S5e1120h15,S5e1121h15,S5e1121h17,S5e1122h07,S5e1125h07,S6aH3,S6aH4,S2c0317h14,S2c0317h18,S3d0910h12,S3d0910h13,S3d0911h10,S3d0911h17,S3d0911h18,S3d0913h12,S3d0915h16,S4aH5,S5e1120h09,S5e1121h10,S5e1122h08,S5e1123h15,S5e1124h17,S5e1125h10,S2b0316h16,S3aH3,S3d0915h09,S3d0916h09,S5e1119h10,S5e1119h11,S5e1120h13,S5e1120h14,S5e1120h18,S5e1121h08,S5e1122h15,S5e1124h08,S5e1125h08,S1aH2,S1aH7,S2aH3,S3aH6,S3d0913h16,S3d0914h07,S3d0914h12,S3d0914h17,S3d0916h13,S3d0916h17,S3d0916h18,S4aH7,S5aH6,S5aH7,S5e1121h07,S5e1121h12,S5e1122h18,S5e1123h07,S5e1124h09,S6aH6,S2b0316h09,S3d0911h09,S3d0914h10,S3d0914h18,S3d0915h17,S5e1120h10,S5e1122h14,S1aH3,S3d0910h08,S3d0910h10,S3d0912h15,S3d0912h16,S3d0915h15,S3d0916h08,S3d0916h11,S5e1120h11,S5e1122h12,S5e1123h12,S1aH6,S2c0317h13,S2c0317h15,S3d0911h11,S3d0913h15,S3d0916h07,S3d0916h12,S5e1119h07,S5e1120h07,S5e1120h08,S5e1121h13,S5e1121h16,S5e1124h16,S5e1125h18,S3d0911h13,S3d0914h09,S5e1120h16,S5e1121h11,S5e1123h16,S5e1124h10,S6aH7,S1aH4,S2aH2,S2b0316h08,S3d0910h09,S3d0912h14,S3d0913h14,S3d0914h13,S3d0914h14,S4aH6,S5e1119h13,S5e1124h15,S2aH7,S2b0316h11,S2b0316h17,S2c0317h11,S3aH4,S3d0910h18,S3d0912h07,S3d0912h10,S3d0914h16,S4aH3,S4aH4,S5e1119h14,S5e1122h09,S5e1123h09,S5e1123h13,S5e1124h07,S5e1125h14,S2c0317h16,S3aH7,S3d0910h07,S3d0910h15,S3d0911h07,S3d0911h16,S3d0915h12,S3d0915h13,S5e1120h17,S5e1122h13,S5e1125h13,S1aH5,S2aH4,S2aH5,S2b0316h14,S2c0317h07,S2c0317h12,S3d0912h09,S3d0913h07,S3d0913h08,S3d0913h11,S3d0913h18,S3d0915h07,S3d0915h08,S5aH2,S5aH5,S5e1119h16,S5e1119h18,S5e1121h18,S5e1123h08,S5e1123h14,S5e1124h11,S5e1124h14,S5e1125h09,S5e1125h15,S5e1125h17,S6aH2 | O11: D | P11: S3aH2,S3aH4,S1aH3,S1aH2,S2aH3,S3aH3,S2aH4,S1aH4,S2aH2 | R11: D | S11: S2aH8,S4aH2,S2aH6,S3aH5,S3aH2,S3aH7,S1aH3,S3aH8,S4aH5,S1aH2,S1aH7,S2aH3,S3aH6,S4aH7,S4aH8,S3aH3,S1aH6,S1aH8,S1aH5,S2aH4,S2aH5,S1aH4,S2aH2,S4aH6,S2aH7,S3aH4,S4aH3,S4aH4 | U11: D | V11: S4aH5,S3aH7,S1aH6,S1aH2,S1aH7,S2aH3,S3aH6,S4aH7,S5aH6,S5aH7,S6aH6,S1aH4,S2aH2,S4aH6,S1aH5,S2aH4,S2aH5,S5aH2,S5aH5,S6aH2,S4aH2,S6aH7,S1aH3,S6aH5,S2aH7,S3aH4,S4aH3,S4aH4,S3aH2,S2aH6,S3aH5,S5aH3,S3aH3,S5aH4,S6aH3,S6aH4 | X11: D | Y11: S1b0107h09,S1c0131h09,S2e0308h15,S2f0314h08,S2f0314h13,S2i0401h07,S2i0401h18,S3aH7,S3j0721h11,S5o1115h09,S5o1115h12,S5o1115h15,S1c0131h15,S2d0307h16,S2e0308h08,S2g0316h08,S2g0316h11,S2h0317h16,S2i0401h13,S3aH2,S3j0721h07,S3k0722h07,S3k0722h13,S3k0722h14,S3l0728h09,S3l0728h12,S3m0918h08,S3m0918h10,S4n1006h07,S4n1006h10,S4n1006h12,S4n1006h13,S5o1115h13,S5p1123h14,S1b0107h07,S1c0131h08,S2e0308h12,S2f0314h07,S2f0314h14,S2g0316h12,S2h0317h08,S3aH3,S3k0722h15,S3m0918h11,S4n1006h11,S1aH2,S1aH7,S2aH3,S2e0308h13,S2f0314h15,S2g0316h15,S3aH6,S3j0721h16,S3l0728h14,S4aH7,S5aH6,S5aH7,S5o1115h07,S5p1123h13,S5p1123h15,S5p1123h18,S6aH6,S1b0107h10,S1c0131h12,S2d0307h07,S2g0316h18,S2h0317h18,S3j0721h17,S6aH7,S2aH7,S2d0307h09,S2d0307h10,S2d0307h14,S2e0308h16,S2i0401h12,S3aH4,S3k0722h10,S3k0722h16,S3m0918h15,S4aH3,S4aH4,S1b0107h15,S1c0131h07,S2f0314h18,S2i0401h16,S3k0722h12,S4aH5,S4n1006h09,S1c0131h11,S2d0307h08,S2f0314h17,S2g0316h17,S2h0317h10,S2h0317h15,S3j0721h14,S3k0722h18,S3l0728h07,S3l0728h10,S3l0728h17,S5p1123h08,S1aH5,S1b0107h17,S2aH4,S2aH5,S2e0308h10,S2f0314h10,S2g0316h09,S2g0316h14,S2h0317h13,S3k0722h17,S3l0728h11,S3l0728h13,S3l0728h15,S3m0918h12,S3m0918h17,S4n1006h16,S5aH2,S5aH5,S5o1115h08,S6aH2,S1aH4,S1c0131h10,S2aH2,S2h0317h09,S2h0317h17,S3l0728h18,S3m0918h09,S3m0918h16,S4aH6,S5p1123h12,S1aH3,S2d0307h12,S2e0308h14,S2f0314h09,S2f0314h12,S2f0314h16,S2i0401h11,S3j0721h18,S3k0722h09,S3m0918h18,S4n1006h15,S1aH6,S2e0308h09,S2g0316h07,S2i0401h14,S3k0722h11,S3m0918h07,S5p1123h11,S1c0131h14,S1c0131h17,S2aH6,S2h0317h11,S3aH5,S3j0721h09,S3k0722h08,S4n1006h14,S5aH3,S5o1115h11,S5p1123h07,S5p1123h17,S1b0107h12,S1b0107h13,S1c0131h18,S2d0307h17,S2e0308h07,S2g0316h13,S2h0317h07,S2h0317h14,S2i0401h17,S3j0721h10,S4n1006h08,S5o1115h10,S5o1115h17,S5o1115h18,S5p1123h09,S5p1123h10,S5p1123h16,S6aH5,S1b0107h18,S1c0131h16,S2d0307h13,S2e0308h11,S2e0308h18,S2f0314h11,S2h0317h12,S2i0401h10,S3j0721h13,S3l0728h08,S3l0728h16,S3m0918h14,S4aH2,S4n1006h18,S5o1115h14,S1b0107h08,S1b0107h11,S1b0107h14,S1b0107h16,S1c0131h13,S2d0307h11,S2d0307h15,S2d0307h18,S2e0308h17,S2g0316h10,S2g0316h16,S2i0401h08,S2i0401h09,S2i0401h15,S3j0721h08,S3j0721h12,S3j0721h15,S3m0918h13,S4n1006h17,S5aH4,S5o1115h16,S6aH3,S6aH4 | AA11: D | AB11: S1aH3,S2b1006h09,S2b1006h07,S3aH3,S1aH4,S2aH2,S2b1006h14,S4aH6,S1aH8,S2b1006h13,S2b1006h15,S2b1006h17,S4aH8,S3aH2,S2aH7,S3aH4,S4aH3,S4aH4,S2b1006h10,S2b1006h16,S3aH8,S4aH5,S2aH8,S4aH2,S1aH6,S2b1006h08,S2b1006h18,S1aH2,S1aH7,S2aH3,S2b1006h11,S3aH6,S4aH7,S2aH6,S3aH5,S2b1006h12,S3aH7,S1aH5,S2aH4,S2aH5 | AD11: D | AE11: AllSaAllH | AG11: D | AH11: SaD,FaD,FaP,SaP,RaP,RaD,WaP,WaD
C12: N | D12: S2b0314h05,S2c0316h01,S2d1006h05,S2c0316h24,S2c0316h21,S2c0316h22,S2b0314h19,S2aH1,S2aH9,S2b0314h21,S2b0314h23,S2d1006h20,S2c0316h03,S2c0316h06,S2d1006h22,S2d1006h21,S1aH9,S2b0314h01,S2b0314h24,S2c0316h04,S2c0316h05,S2d1006h06,S2d1006h19,S4aH1,S2b0314h22,S2c0316h19,S2d1006h02,S3aH9,S2b0314h04,S1aH1,S2b0314h02,S2b0314h06,S2b0314h20,S2c0316h20,S2d1006h03,S2d1006h24,S2d1006h01,S2d1006h23,S2c0316h23,S2d1006h04,S2b0314h03,S2c0316h02,S3aH1,S4aH9 | F12: N | G12: S2e0317h23,S3f0721h24,S3g0728h04,S3h0918h24,S1b0131h02,S2c0314h04,S2d0316h04,S2e0317h01,S3aH1,S3f0721h03,S3h0918h04,S3h0918h05,S3h0918h06,S4i1006h03,S1aH8,S3f0721h21,S5aH1,S1b0131h06,S2c0314h22,S2c0314h24,S2d0316h20,S3f0721h23,S3g0728h01,S5j1115h23,S1b0131h01,S1b0131h21,S2d0316h21,S3h0918h23,S2d0316h06,S2e0317h03,S2e0317h04,S3f0721h01,S3g0728h03,S3g0728h19,S3h0918h20,S3h0918h21,S5j1115h03,S5j1115h04,S1aH1,S1b0131h04,S2d0316h22,S2e0317h20,S3f0721h02,S3h0918h19,S3h0918h22,S5j1115h06,S5j1115h22,S1b0131h22,S1b0131h23,S2aH1,S2c0314h03,S2c0314h20,S4i1006h02,S4i1006h04,S4i1006h05,S5aH8,S1b0131h20,S3aH8,S3g0728h22,S4i1006h21,S4i1006h23,S1b0131h05,S2c0314h06,S2d0316h23,S3f0721h22,S4i1006h06,S4i1006h19,S4i1006h20,S1b0131h03,S2e0317h24,S3f0721h04,S3f0721h06,S3g0728h24,S5j1115h20,S1b0131h24,S2c0314h05,S2c0314h19,S2d0316h02,S2d0316h24,S2e0317h06,S2e0317h21,S3f0721h20,S3g0728h20,S3h0918h01,S3h0918h02,S3h0918h03,S5j1115h05,S5j1115h21,S1b0131h19,S2aH8,S2c0314h23,S2d0316h19,S3g0728h05,S3g0728h21,S5j1115h01,S2d0316h01,S2e0317h02,S2e0317h19,S2e0317h22,S4aH8,S4i1006h24,S5j1115h19,S2c0314h01,S2c0314h21,S3f0721h05,S4i1006h22,S6aH8,S2c0314h02,S2d0316h03,S2d0316h05,S2e0317h05,S3f0721h19,S3g0728h02,S3g0728h06,S3g0728h23,S4aH1,S4i1006h01,S5j1115h02,S5j1115h24,S6aH1 | I12: N | J12: S3b0910h03,S3b0910h21,S3b0914h01,S3b0915h06,S3b0916h21,S5c1119h23,S5c1121h03,S5c1122h22,S5c1124h03,S5c1124h06,S3b0910h06,S3b0914h03,S3b0914h19,S3b0915h21,S3b0916h01,S3b0916h06,S5c1119h05,S5c1119h24,S5c1120h19,S5c1121h05,S5c1121h23,S5c1123h01,S5c1124h02,S3b0911h04,S3b0914h02,S3b0914h21,S3b0915h03,S3b0915h23,S3b0916h02,S3b0916h23,S5c1120h21,S5c1122h01,S5c1122h24,S5c1125h03,S5c1125h23,S3b0910h01,S3b0912h02,S3b0912h24,S5c1119h20,S5c1120h01,S5c1122h04,S5c1123h06,S2aH1,S3b0911h05,S3b0911h23,S3b0912h22,S3b0913h19,S5aH8,S5c1120h03,S5c1120h04,S5c1121h02,S5c1123h23,S5c1125h05,S5c1125h19,S5c1125h21,S3b0912h19,S3b0914h04,S3b0915h04,S4aH8,S5c1119h19,S5c1119h21,S5c1120h24,S5c1122h05,S5c1122h21,S5c1123h02,S5c1123h22,S5c1124h24,S5c1125h20,S3b0910h04,S3b0910h20,S3b0911h01,S3b0911h20,S3b0912h03,S3b0912h05,S3b0912h21,S5c1120h22,S5c1122h03,S3aH8,S3b0910h19,S3b0911h06,S3b0913h02,S3b0914h05,S5c1119h02,S5c1119h06,S5c1121h01,S5c1121h20,S5c1124h20,S5c1125h06,S3b0912h06,S3b0914h24,S3b0915h02,S3b0916h04,S3b0916h19,S3b0916h24,S5c1120h05,S5c1122h02,S5c1122h19,S5c1123h03,S5c1123h20,S5c1125h02,S1aH1,S3b0910h24,S3b0911h02,S3b0912h04,S3b0913h20,S3b0916h03,S5c1120h20,S5c1121h04,S5c1122h06,S3b0911h19,S3b0912h01,S3b0912h23,S3b0913h23,S3b0914h06,S3b0915h24,S5c1122h20,S5c1124h23,S3b0910h23,S3b0911h21,S3b0913h03,S3b0913h22,S3b0914h23,S3b0915h20,S3b0915h22,S5c1120h06,S5c1123h04,S6aH8,S2aH8,S3b0910h22,S3b0911h24,S3b0913h21,S3b0913h24,S3b0914h20,S3b0916h05,S5c1119h04,S5c1119h22,S5c1123h24,S5c1125h24,S1aH8,S3b0912h20,S3b0915h01,S3b0916h22,S5aH1,S5c1119h01,S5c1120h23,S5c1121h21,S5c1123h19,S5c1124h01,S5c1125h01,S5c1125h04,S3b0913h04,S3b0913h06,S3b0914h22,S3b0915h05,S3b0915h19,S3b0916h20,S4aH1,S5c1121h19,S5c1122h23,S5c1123h05,S5c1125h22,S6aH1,S3aH1,S3b0910h02,S3b0910h05,S3b0911h03,S3b0911h22,S3b0913h01,S3b0913h05,S5c1119h03,S5c1120h02,S5c1121h06,S5c1121h22,S5c1121h24,S5c1123h21,S5c1124h04,S5c1124h05,S5c1124h19,S5c1124h21,S5c1124h22 | L12: N | M12: S2aH1,S3d0916h02,S3d0916h04,S3d0916h23,S5aH8,S5e1119h03,S5e1119h20,S5e1120h05,S5e1121h02,S2c0317h23,S2c0317h24,S3d0911h21,S3d0913h01,S3d0913h04,S3d0913h19,S3d0913h23,S3d0913h24,S3d0914h05,S4aH8,S5e1122h05,S5e1122h19,S5e1125h23,S1aH8,S3d0910h03,S3d0910h06,S3d0910h20,S3d0912h01,S3d0913h06,S3d0914h24,S3d0916h21,S5aH1,S5e1119h04,S5e1120h06,S5e1120h20,S5e1121h19,S5e1121h20,S5e1123h21,S5e1123h24,S5e1124h03,S5e1125h20,S2c0317h21,S3aH8,S3d0910h21,S3d0911h23,S3d0913h02,S3d0913h20,S3d0915h01,S3d0915h02,S3d0916h24,S2b0316h02,S2b0316h03,S2c0317h04,S2c0317h22,S3d0910h05,S3d0910h19,S3d0911h02,S3d0912h20,S3d0914h20,S3d0914h22,S3d0915h04,S3d0915h06,S3d0915h23,S3d0916h03,S3d0916h19,S5e1120h04,S5e1121h01,S5e1121h03,S5e1122h24,S5e1124h01,S5e1124h19,S5e1124h23,S2b0316h01,S2b0316h06,S3d0910h24,S3d0911h01,S3d0912h24,S3d0914h23,S3d0915h05,S5e1119h05,S5e1121h22,S5e1124h21,S5e1125h04,S3d0910h01,S3d0910h04,S3d0911h04,S3d0911h06,S3d0913h22,S3d0914h02,S3d0914h03,S5e1120h03,S5e1120h19,S5e1120h23,S5e1122h01,S5e1123h01,S5e1123h05,S2b0316h20,S2c0317h19,S3d0911h22,S3d0912h06,S3d0914h21,S5e1120h24,S5e1122h04,S5e1123h22,S5e1124h24,S1aH1,S2c0317h05,S3d0910h23,S3d0912h23,S3d0913h05,S3d0914h01,S3d0915h03,S3d0915h19,S5e1119h22,S5e1121h23,S5e1122h02,S5e1122h03,S5e1122h06,S5e1124h04,S5e1125h01,S2b0316h21,S2c0317h02,S3d0911h05,S3d0912h04,S3d0912h19,S3d0913h21,S3d0915h20,S3d0915h24,S3d0916h06,S5e1120h01,S5e1120h22,S5e1121h04,S5e1121h06,S5e1121h24,S5e1123h03,S5e1123h06,S5e1124h20,S5e1124h22,S3d0912h22,S3d0913h03,S3d0915h22,S5e1120h02,S5e1123h04,S5e1125h24,S6aH8,S2b0316h05,S2b0316h22,S2b0316h24,S2c0317h06,S3aH1,S3d0910h02,S3d0912h02,S3d0912h03,S3d0916h05,S5e1122h23,S5e1123h02,S5e1123h20,S5e1123h23,S5e1124h05,S5e1124h06,S5e1125h06,S5e1125h22,S2b0316h19,S2b0316h23,S2c0317h03,S3d0911h20,S3d0916h20,S4aH1,S5e1121h05,S5e1121h21,S5e1122h22,S6aH1,S3d0912h21,S3d0914h06,S3d0914h19,S3d0915h21,S5e1119h24,S5e1122h20,S5e1125h03,S5e1125h05,S2aH8,S2b0316h04,S3d0911h03,S3d0911h19,S3d0916h01,S5e1119h19,S5e1119h23,S5e1120h21,S5e1123h19,S5e1125h21,S2c0317h01,S2c0317h20,S3d0910h22,S3d0911h24,S3d0912h05,S3d0914h04,S3d0916h22,S5e1119h01,S5e1119h02,S5e1119h06,S5e1119h21,S5e1122h21,S5e1124h02,S5e1125h02,S5e1125h19 | O12: N | P12: S1aH5,S2aH5,S3aH1,S3aH5,S2aH1,S1aH1 | R12: N | S12: S2aH1,S2aH9,S1aH1,S3aH1,S4aH9,S1aH9,S4aH1,S3aH9 | U12: N | V12: S2aH8,S6aH8,S4aH1,S6aH1,S1aH1,S2aH1,S5aH8,S3aH1,S4aH8,S3aH8,S1aH8,S5aH1 | X12: N | Y12: S1b0107h02,S1b0107h06,S2aH8,S2d0307h02,S2d0307h04,S2g0316h03,S3l0728h06,S3m0918h06,S4n1006h03,S5p1123h06,S5p1123h20,S1c0131h01,S1c0131h19,S2d0307h24,S2e0308h20,S2f0314h21,S2g0316h20,S2h0317h01,S2h0317h02,S2h0317h20,S2h0317h21,S2h0317h24,S3aH8,S3k0722h02,S5o1115h05,S5o1115h19,S5p1123h03,S1c0131h23,S2f0314h05,S2i0401h02,S2i0401h19,S3l0728h01,S3l0728h02,S5o1115h04,S5o1115h06,S5p1123h04,S2e0308h21,S2h0317h22,S3l0728h22,S3m0918h01,S3m0918h20,S4n1006h22,S5o1115h21,S5o1115h22,S2d0307h05,S2d0307h19,S2e0308h19,S2f0314h03,S2f0314h22,S2g0316h22,S2i0401h21,S3aH1,S3j0721h06,S3k0722h01,S4n1006h24,S5o1115h01,S5o1115h20,S1b0107h19,S1b0107h22,S1b0107h24,S2d0307h21,S2e0308h02,S2e0308h05,S2f0314h06,S2f0314h23,S2g0316h23,S2h0317h04,S2i0401h06,S3j0721h21,S3k0722h05,S3k0722h19,S3l0728h21,S3m0918h22,S4n1006h05,S5p1123h24,S1c0131h21,S2e0308h06,S2g0316h02,S3j0721h03,S3j0721h05,S3j0721h22,S3k0722h04,S4n1006h21,S5p1123h01,S1aH1,S1b0107h04,S2e0308h03,S2f0314h04,S2i0401h03,S3j0721h02,S3k0722h03,S3k0722h20,S3k0722h22,S3k0722h23,S4n1006h20,S1b0107h20,S1c0131h03,S2d0307h03,S2g0316h06,S3j0721h01,S3l0728h03,S3l0728h23,S4n1006h01,S4n1006h19,S1b0107h05,S2d0307h06,S2g0316h01,S2i0401h22,S3j0721h24,S4aH1,S4n1006h04,S5p1123h22,S6aH1,S1c0131h22,S2d0307h01,S2g0316h05,S2g0316h24,S2h0317h05,S2i0401h01,S2i0401h20,S3j0721h20,S3j0721h23,S3l0728h20,S3m0918h21,S3m0918h23,S4n1006h02,S5o1115h24,S1b0107h03,S2e0308h04,S2e0308h23,S2f0314h02,S2f0314h24,S2g0316h04,S2h0317h03,S3j0721h04,S3k0722h06,S6aH8,S1aH8,S1b0107h01,S1c0131h05,S1c0131h20,S2d0307h20,S2d0307h23,S2g0316h19,S2i0401h04,S2i0401h05,S3j0721h19,S3k0722h24,S3l0728h24,S5aH1,S5p1123h05,S5p1123h21,S1b0107h21,S1c0131h02,S2e0308h22,S2e0308h24,S2f0314h01,S2f0314h19,S2h0317h06,S2h0317h19,S2h0317h23,S2i0401h23,S3l0728h04,S3m0918h02,S3m0918h04,S3m0918h19,S4aH8,S4n1006h06,S4n1006h23,S5o1115h02,S5o1115h03,S5p1123h19,S5p1123h23,S1b0107h23,S1c0131h06,S1c0131h24,S2aH1,S2d0307h22,S2f0314h20,S3l0728h05,S3l0728h19,S3m0918h05,S3m0918h24,S5aH8,S5o1115h23,S5p1123h02,S1c0131h04,S2e0308h01,S2g0316h21,S2i0401h24,S3k0722h21,S3m0918h03 | AA12: N | AB12: S2b1006h01,S2b1006h22,S2b1006h03,S1aH9,S2b1006h23,S4aH1,S2b1006h04,S2b1006h24,S3aH1,S4aH9,S1aH1,S2b1006h19,S2b1006h02,S2b1006h21,S2b1006h06,S3aH9,S2aH1,S2aH9,S2b1006h05,S2b1006h20 | AD12: N | AE12: AllSaAllH | AG12: N | AH12: FaP,SaP,FaN,RaP,WaP,SaN,WaN,RaN
I17: 0.75 | K17: share of charging at night
C18: ~UC_Sets: R_E: AllRegions
H21: =IF(H23=H24,"Not Required!","~UC_T: LO") -> ~UC_T: LO
C22: UC_N | D22: Pset_CI | E22: Pset_CO | F22: pset_pn | G22: Cset_CN | H22: TimeSlice | I22: UC_FLO | J22: UC_RHSRT | K22: UC_RHSRT~0
C23: UC_bev night chg limit | D23: ELC | E23: =G23 -> AuxStoIN | F23: *EV* | G23: AuxStoIN | H23: =HLOOKUP($A$10,$D$10:$CU$12,3,FALSE) -> S3b0910h03,S3b0910h21,S3b0914h01,S3b0915h06,S3b0916h21,S5c1119h23,S5c1121h03,S5c1122h22,S5c1124h03,S5c1124h06,S3b0910h06,S3b0914h03,S3b0914h19,S3b0915h21,S3b0916h01,S3b0916h06,S5c1119h05,S5c1119h24,S5c1120h19,S5c1121h05,S5c1121h23,S5c1123h01,S5c1124h02,S3b0911h04,S3b0914h02,S3b0914h21,S3b0915h03,S3b0915h23,S3b0916h02,S3b0916h23,S5c1120h21,S5c1122h01,S5c1122h24,S5c1125h03,S5c1125h23,S3b0910h01,S3b0912h02,S3b0912h24,S5c1119h20,S5c1120h01,S5c1122h04,S5c1123h06,S2aH1,S3b0911h05,S3b0911h23,S3b0912h22,S3b0913h19,S5aH8,S5c1120h03,S5c1120h04,S5c1121h02,S5c1123h23,S5c1125h05,S5c1125h19,S5c1125h21,S3b0912h19,S3b0914h04,S3b0915h04,S4aH8,S5c1119h19,S5c1119h21,S5c1120h24,S5c1122h05,S5c1122h21,S5c1123h02,S5c1123h22,S5c1124h24,S5c1125h20,S3b0910h04,S3b0910h20,S3b0911h01,S3b0911h20,S3b0912h03,S3b0912h05,S3b0912h21,S5c1120h22,S5c1122h03,S3aH8,S3b0910h19,S3b0911h06,S3b0913h02,S3b0914h05,S5c1119h02,S5c1119h06,S5c1121h01,S5c1121h20,S5c1124h20,S5c1125h06,S3b0912h06,S3b0914h24,S3b0915h02,S3b0916h04,S3b0916h19,S3b0916h24,S5c1120h05,S5c1122h02,S5c1122h19,S5c1123h03,S5c1123h20,S5c1125h02,S1aH1,S3b0910h24,S3b0911h02,S3b0912h04,S3b0913h20,S3b0916h03,S5c1120h20,S5c1121h04,S5c1122h06,S3b0911h19,S3b0912h01,S3b0912h23,S3b0913h23,S3b0914h06,S3b0915h24,S5c1122h20,S5c1124h23,S3b0910h23,S3b0911h21,S3b0913h03,S3b0913h22,S3b0914h23,S3b0915h20,S3b0915h22,S5c1120h06,S5c1123h04,S6aH8,S2aH8,S3b0910h22,S3b0911h24,S3b0913h21,S3b0913h24,S3b0914h20,S3b0916h05,S5c1119h04,S5c1119h22,S5c1123h24,S5c1125h24,S1aH8,S3b0912h20,S3b0915h01,S3b0916h22,S5aH1,S5c1119h01,S5c1120h23,S5c1121h21,S5c1123h19,S5c1124h01,S5c1125h01,S5c1125h04,S3b0913h04,S3b0913h06,S3b0914h22,S3b0915h05,S3b0915h19,S3b0916h20,S4aH1,S5c1121h19,S5c1122h23,S5c1123h05,S5c1125h22,S6aH1,S3aH1,S3b0910h02,S3b0910h05,S3b0911h03,S3b0911h22,S3b0913h01,S3b0913h05,S5c1119h03,S5c1120h02,S5c1121h06,S5c1121h22,S5c1121h24,S5c1123h21,S5c1124h04,S5c1124h05,S5c1124h19,S5c1124h21,S5c1124h22 | I23: =1+I24 -> 0.25 | J23: 0 | K23: 3 | M23: night
D24: ELC | E24: =G24 -> AuxStoIN | F24: *EV* | G24: AuxStoIN | H24: =HLOOKUP($A$10,$D$10:$CU$12,2,FALSE) -> S3b0910h13,S3b0910h14,S3b0911h16,S3b0912h18,S3b0913h16,S3b0915h11,S3b0916h14,S3b0916h18,S4aH5,S5c1122h08,S5c1122h18,S5c1124h08,S5c1124h11,S5c1124h12,S1aH2,S1aH7,S2aH3,S3aH6,S3b0910h12,S3b0911h10,S3b0914h18,S3b0915h10,S4aH7,S5aH6,S5aH7,S5c1119h15,S5c1119h17,S5c1122h10,S5c1122h11,S5c1124h10,S6aH6,S1aH5,S2aH4,S2aH5,S3b0910h11,S3b0913h13,S3b0914h14,S3b0916h15,S3b0916h17,S5aH2,S5aH5,S5c1119h13,S5c1125h12,S6aH2,S3aH3,S3b0910h16,S3b0911h07,S3b0914h10,S3b0915h15,S3b0915h17,S5c1119h08,S5c1119h18,S5c1120h18,S5c1121h11,S5c1121h15,S5c1122h07,S5c1123h16,S5c1125h17,S3b0911h17,S3b0912h09,S3b0913h14,S3b0914h07,S3b0916h08,S3b0916h10,S4aH2,S5c1119h10,S5c1122h15,S5c1123h12,S5c1123h18,S5c1125h08,S5c1125h18,S3b0913h15,S3b0915h14,S5c1119h16,S5c1120h11,S5c1121h12,S5c1121h13,S5c1121h16,S5c1122h14,S5c1124h15,S5c1124h17,S5c1125h10,S5c1125h15,S6aH5,S3b0911h12,S3b0912h11,S3b0912h12,S3b0912h13,S3b0915h18,S3b0916h16,S5aH4,S5c1121h09,S5c1122h09,S5c1123h17,S5c1125h13,S6aH3,S6aH4,S3aH2,S3b0911h13,S3b0913h11,S3b0914h13,S5c1120h10,S5c1124h09,S1aH3,S3b0911h09,S3b0911h14,S3b0912h07,S3b0915h09,S5c1120h08,S5c1122h13,S5c1123h11,S5c1125h07,S3b0910h15,S3b0912h15,S3b0913h18,S3b0914h08,S3b0914h11,S3b0915h16,S3b0916h11,S5c1119h12,S5c1120h15,S5c1120h17,S5c1121h10,S5c1123h13,S5c1125h11,S2aH7,S3aH4,S3b0910h10,S3b0911h08,S3b0911h15,S3b0912h10,S3b0912h16,S3b0913h09,S3b0914h09,S3b0914h12,S4aH3,S4aH4,S5c1119h09,S5c1120h16,S5c1121h14,S5c1123h09,S5c1123h10,S5c1124h13,S5c1125h09,S1aH6,S3b0910h09,S3b0910h18,S3b0912h08,S3b0912h17,S5c1119h11,S5c1120h07,S5c1121h07,S5c1121h08,S5c1122h12,S5c1122h17,S5c1123h08,S5c1124h07,S5c1124h14,S5c1125h16,S3aH7,S3b0913h07,S3b0915h08,S3b0916h12,S5c1119h07,S5c1120h13,S5c1125h14,S2aH6,S3aH5,S3b0910h17,S3b0912h14,S3b0913h17,S3b0914h16,S5aH3,S5c1120h14,S5c1122h16,S5c1123h15,S1aH4,S2aH2,S3b0910h07,S3b0913h08,S3b0913h12,S3b0914h15,S3b0914h17,S3b0915h07,S3b0915h12,S3b0915h13,S4aH6,S5c1119h14,S5c1120h09,S5c1120h12,S5c1121h17,S5c1123h14,S5c1124h16,S3b0910h08,S3b0911h11,S3b0911h18,S3b0913h10,S3b0916h07,S3b0916h09,S3b0916h13,S5c1121h18,S5c1123h07,S5c1124h18,S6aH7 | I24: =-$I$17 -> -0.75 | M24: day

Sheet s1p1v1_d
C9: =IF(A11="x","DeActivated","~TimeSlices") -> DeActivated | I9: =IF(A11="x","DeActivated","~TFM_DINS-AT") -> DeActivated | N9: =IF(A11="x","DeActivated","~TFM_DINS-AT") -> DeActivated | S9: =IF(A11="x","DeActivated","~TFM_DINS-AT") -> DeActivated | X9: =IF(A11="x","DeActivated","~TFM_DINS-AT") -> DeActivated | AC9: =IF(A11="x","DeActivated","~TFM_DINS-AT") -> DeActivated | AG9: =IF(A11="x","DeActivated","~TFM_DINS-AT") -> DeActivated | AK9: =IF(A11="x","DeActivated","~TFM_INS-AT") -> DeActivated
A10: s1p1v1_d | C10: season | D10: weekly | E10: daynite | F10: wparent | G10: dparent | I10: commodity | J10: timeslice | K10: com_fr | L10: process | N10: commodity | O10: timeslice | P10: com_fr | Q10: process | S10: commodity | T10: timeslice | U10: com_fr | V10: process | X10: g_yrfr | Y10: com_fr | Z10: timeslice | AA10: commodity | AC10: commodity | AD10: timeslice | AE10: com_fr | AG10: commodity | AH10: timeslice | AI10: com_pkflx | AK10: timeslice | AL10: ncap_afs | AM10: pset_ci
A11: =IFERROR(IF(Veda!D5=A10,"ok","x"),"") -> x | C11: S1 | D11: a | E11: 0314h01 | F11: S1,S2,S3,S4 | G11: b | I11: elc_spv-DEU | J11: S1aH1 | K11: 0 | L11: IMPNRGZ | N11: elc_won-DEU | O11: S1aH1 | P11: 0.044155048 | Q11: IMPNRGZ | S11: elc_wof-DEU | T11: S1aH1 | U11: 0.042330576 | V11: IMPNRGZ | X11: 0.040410959 | Y11: 0.0086444737 | Z11: S1aH1 | AA11: elc_roadtransport | AC11: elc_buildings | AD11: S1aH1 | AE11: 0.036138622 | AG11: ELC | AH11: S1aH1 | AI11: 0.20993759 | AK11: S4 | AL11: 0.084099425 | AM11: hydro
C12: S2 | D12: b | E12: 0314h02 | F12: S2 | G12: b | I12: elc_spv-DEU | J12: S1aH2 | K12: 0 | L12: IMPNRGZ | N12: elc_won-DEU | O12: S1aH2 | P12: 0.0074771969 | Q12: IMPNRGZ | S12: elc_wof-DEU | T12: S1aH2 | U12: 0.0070255051 | V12: IMPNRGZ | X12: 0.0067351598 | Y12: 0.0099743928 | Z12: S1aH2 | AA12: elc_roadtransport | AC12: elc_buildings | AD12: S1aH2 | AE12: 0.0085508495 | AG12: ELC | AH12: S1aH2 | AI12: 0.084513739 | AK12: S2 | AL12: 0.85866273 | AM12: hydro
C13: S3 | D13: c | E13: 0314h03 | F13: S2 | G13: b | I13: elc_spv-DEU | J13: S1aH3 | K13: 0.000212831 | L13: IMPNRGZ | N13: elc_won-DEU | O13: S1aH3 | P13: 0.0074860524 | Q13: IMPNRGZ | S13: elc_wof-DEU | T13: S1aH3 | U13: 0.0070289935 | V13: IMPNRGZ | X13: 0.0067351598 | Y13: 0.011245639 | Z13: S1aH3 | AA13: elc_roadtransport | AC13: elc_buildings | AD13: S1aH3 | AE13: 0.0089794169 | AG13: ELC | AH13: S1aH3 | AI13: 0.084639654 | AK13: S1 | AL13: 0.18244762 | AM13: hydro
C14: S4 | D14: d | E14: 0314h04 | F14: S2 | G14: b | I14: elc_spv-DEU | J14: S1aH4 | K14: 0.0025148697 | L14: IMPNRGZ | N14: elc_won-DEU | O14: S1aH4 | P14: 0.0074313732 | Q14: IMPNRGZ | S14: elc_wof-DEU | T14: S1aH4 | U14: 0.0070672308 | V14: IMPNRGZ | X14: 0.0067351598 | Y14: 0.0086053585 | Z14: S1aH4 | AA14: elc_roadtransport | AC14: elc_buildings | AD14: S1aH4 | AE14: 0.0093232259 | AG14: ELC | AH14: S1aH4 | AI14: 0.080333358 | AK14: S3 | AL14: 0.074790226 | AM14: hydro
E15: 0314h05 | G15: b | I15: elc_spv-DEU | J15: S1aH5 | K15: 0.054922726 | L15: IMPNRGZ | N15: elc_won-DEU | O15: S1aH5 | P15: 0.043114245 | Q15: IMPNRGZ | S15: elc_wof-DEU | T15: S1aH5 | U15: 0.042361322 | V15: IMPNRGZ | X15: 0.040410959 | Y15: 0.051201883 | Z15: S1aH5 | AA15: elc_roadtransport | AC15: elc_buildings | AD15: S1aH5 | AE15: 0.056354898 | AG15: ELC | AH15: S1aH5 | AI15: 0.085156904
E16: 0314h06 | G16: b | I16: elc_spv-DEU | J16: S1aH6 | K16: 0.0076359461 | L16: IMPNRGZ | N16: elc_won-DEU | O16: S1aH6 | P16: 0.0071388004 | Q16: IMPNRGZ | S16: elc_wof-DEU | T16: S1aH6 | U16: 0.0070873287 | V16: IMPNRGZ | X16: 0.0067351598 | Y16: 0.010169969 | Z16: S1aH6 | AA16: elc_roadtransport | AC16: elc_buildings | AD16: S1aH6 | AE16: 0.0094335916 | AG16: ELC | AH16: S1aH6 | AI16: 0.08311554
E17: 0314h07 | G17: b | I17: elc_spv-DEU | J17: S1aH7 | K17: 0.0048844499 | L17: IMPNRGZ | N17: elc_won-DEU | O17: S1aH7 | P17: 0.0071465471 | Q17: IMPNRGZ | S17: elc_wof-DEU | T17: S1aH7 | U17: 0.0071736353 | V17: IMPNRGZ | X17: 0.0067351598 | Y17: 0.013103614 | Z17: S1aH7 | AA17: elc_roadtransport | AC17: elc_buildings | AD17: S1aH7 | AE17: 0.0096263596 | AG17: ELC | AH17: S1aH7 | AI17: 0.079506795
E18: 0314h08 | G18: b | I18: elc_spv-DEU | J18: S1aH8 | K18: 0.0018062388 | L18: IMPNRGZ | N18: elc_won-DEU | O18: S1aH8 | P18: 0.0072770367 | Q18: IMPNRGZ | S18: elc_wof-DEU | T18: S1aH8 | U18: 0.0072869486 | V18: IMPNRGZ | X18: 0.0067351598 | Y18: 0.013103614 | Z18: S1aH8 | AA18: elc_roadtransport | AC18: elc_buildings | AD18: S1aH8 | AE18: 0.0096700817 | AG18: ELC | AH18: S1aH8 | AI18: 0.08056248
E19: 0314h09 | G19: b | I19: elc_spv-DEU | J19: S1aH9 | K19: 0.00012605487 | L19: IMPNRGZ | N19: elc_won-DEU | O19: S1aH9 | P19: 0.044361212 | Q19: IMPNRGZ | S19: elc_wof-DEU | T19: S1aH9 | U19: 0.043299573 | V19: IMPNRGZ | X19: 0.040410959 | Y19: 0.035594892 | Z19: S1aH9 | AA19: elc_roadtransport | AC19: elc_buildings | AD19: S1aH9 | AE19: 0.050177963 | AG19: ELC | AH19: S1aH9 | AI19: 0.18372288
E20: 0314h10 | G20: b | I20: elc_spv-DEU | J20: S2aH1 | K20: 0.008322983 | L20: IMPNRGZ | N20: elc_won-DEU | O20: S2aH1 | P20: 0.15112974 | Q20: IMPNRGZ | S20: elc_wof-DEU | T20: S2aH1 | U20: 0.15318679 | V20: IMPNRGZ | X20: 0.16575342 | Y20: 0.035456994 | Z20: S2aH1 | AA20: elc_roadtransport | AC20: elc_buildings | AD20: S2aH1 | AE20: 0.11031054 | AG20: ELC | AH20: S2aH1 | AI20: 0.42391859
E21: 0314h11 | G21: b | I21: elc_spv-DEU | J21: S2aH2 | K21: 0.024893195 | L21: IMPNRGZ | N21: elc_won-DEU | O21: S2aH2 | P21: 0.024420202 | Q21: IMPNRGZ | S21: elc_wof-DEU | T21: S2aH2 | U21: 0.025103081 | V21: IMPNRGZ | X21: 0.027625571 | Y21: 0.040911916 | Z21: S2aH2 | AA21: elc_roadtransport | AC21: elc_buildings | AD21: S2aH2 | AE21: 0.025949595 | AG21: ELC | AH21: S2aH2 | AI21: 0.30993023
E22: 0314h12 | G22: b | I22: elc_spv-DEU | J22: S2aH3 | K22: 0.044363807 | L22: IMPNRGZ | N22: elc_won-DEU | O22: S2aH3 | P22: 0.023848047 | Q22: IMPNRGZ | S22: elc_wof-DEU | T22: S2aH3 | U22: 0.025071265 | V22: IMPNRGZ | X22: 0.027625571 | Y22: 0.04612618 | Z22: S2aH3 | AA22: elc_roadtransport | AC22: elc_buildings | AD22: S2aH3 | AE22: 0.028476406 | AG22: ELC | AH22: S2aH3 | AI22: 0.28185593
E23: 0314h13 | G23: b | I23: elc_spv-DEU | J23: S2aH4 | K23: 0.061827369 | L23: IMPNRGZ | N23: elc_won-DEU | O23: S2aH4 | P23: 0.02349341 | Q23: IMPNRGZ | S23: elc_wof-DEU | T23: S2aH4 | U23: 0.025112709 | V23: IMPNRGZ | X23: 0.027625571 | Y23: 0.035296555 | Z23: S2aH4 | AA23: elc_roadtransport | AC23: elc_buildings | AD23: S2aH4 | AE23: 0.029894155 | AG23: ELC | AH23: S2aH4 | AI23: 0.26879431
E24: 0314h14 | G24: b | I24: elc_spv-DEU | J24: S2aH5 | K24: 0.49361831 | L24: IMPNRGZ | N24: elc_won-DEU | O24: S2aH5 | P24: 0.14336933 | Q24: IMPNRGZ | S24: elc_wof-DEU | T24: S2aH5 | U24: 0.14689469 | V24: IMPNRGZ | X24: 0.16575342 | Y24: 0.2100145 | Z24: S2aH5 | AA24: elc_roadtransport | AC24: elc_buildings | AD24: S2aH5 | AE24: 0.1787176 | AG24: ELC | AH24: S2aH5 | AI24: 0.26455734
E25: 0314h15 | G25: b | I25: elc_spv-DEU | J25: S2aH6 | K25: 0.073525463 | L25: IMPNRGZ | N25: elc_won-DEU | O25: S2aH6 | P25: 0.025172356 | Q25: IMPNRGZ | S25: elc_wof-DEU | T25: S2aH6 | U25: 0.025371782 | V25: IMPNRGZ | X25: 0.027625571 | Y25: 0.041714111 | Z25: S2aH6 | AA25: elc_roadtransport | AC25: elc_buildings | AD25: S2aH6 | AE25: 0.029447894 | AG25: ELC | AH25: S2aH6 | AI25: 0.27594163
E26: 0314h16 | G26: b | I26: elc_spv-DEU | J26: S2aH7 | K26: 0.061518167 | L26: IMPNRGZ | N26: elc_won-DEU | O26: S2aH7 | P26: 0.024779436 | Q26: IMPNRGZ | S26: elc_wof-DEU | T26: S2aH7 | U26: 0.025629966 | V26: IMPNRGZ | X26: 0.027625571 | Y26: 0.053747027 | Z26: S2aH7 | AA26: elc_roadtransport | AC26: elc_buildings | AD26: S2aH7 | AE26: 0.029559154 | AG26: ELC | AH26: S2aH7 | AI26: 0.28495403
... E91: H9 | G91: a | I91: elc_spv-DEU | J91: S2d1006h15 | K91: 0.00010325777 | L91: IMPNRGZ | N91: elc_won-DEU | O91: S2d1006h15 | P91: 1.8404622e-05 | Q91: IMPNRGZ | S91: elc_wof-DEU | T91: S2d1006h15 | U91: 2.61526e-05 | V91: IMPNRGZ | X91: 0.00011415525 | Y91: 0.00015049433 | Z91: S2d1006h15 | AA91: elc_roadtransport | AC91: elc_buildings | AD91: S2d1006h15 | AE91: 9.2876514e-05 | AG91: ELC | AH91: S2d1006h15 | AI91: 0
