Workbook

Sheet Controller
A1: Scenario Controller | H1: Scenario List | J1: Variable List
A2: Active Scenario | B2: =IFERROR(INDEX($B$13:$B$20,MATCH($D$7,$C$13:$C$20,0)),"") -> Mild | H2: Ref | J2: hydrogen_allsect
H3: Mild | J3: elc_industry
E4: 1-8 | H4: Mitig | J4: elc_buildings
H5: NZ | J5: elc_transport
D6: ~Inputcell: 1-4 | H6: Scenario 5 | J6: elc_roadtransport
D7: 2 | H7: Scenario 6 | J7: het_industry
H8: Scenario 7 | J8: het_buildings
D9: =VLOOKUP(D7,$C$13:$D$20,2,FALSE) -> 150 | H9: Scenario 8 | J9: co2net
H10: Scenario 9 | J10: Variable 9
B11: ~Scenmap | H11: Scenario 10 | J11: Variable 10
A12: priority | B12: scen | C12: case_no | D12: co2price
A13: 5 | B13: =$H2 -> Ref | C13: 1 | D13: 0
A14: 5 | B14: =$H3 -> Mild | C14: =C13+1 -> 2 | D14: 150
A15: 5 | B15: =$H4 -> Mitig | C15: =C14+1 -> 3 | D15: 250
A16: 5 | B16: =$H5 -> NZ | C16: =C15+1 -> 4 | D16: 450
A17: 5 | B17: =$H6 -> Scenario 5 | C17: =C16+1 -> 5
A18: 5 | B18: =$H7 -> Scenario 6 | C18: =C17+1 -> 6
A19: 5 | B19: =$H8 -> Scenario 7 | C19: =C18+1 -> 7
A20: 5 | B20: =$H9 -> Scenario 8 | C20: =C19+1 -> 8

Sheet VEDA
B3: ~TFM_INS-TS: region=POL
B4: commodity | C4: 2022 | D4: 2025 | E4: 2030 | F4: 2035 | G4: 2040 | H4: 2045 | I4: 2050 | J4: attribute
B5: hydrogen_allsect | C5: =Scenario_View!B4 -> 0 | D5: =Scenario_View!C4 -> 0 | E5: =Scenario_View!D4 -> 0 | F5: =Scenario_View!E4 -> 0 | G5: =Scenario_View!F4 -> 0 | H5: =Scenario_View!G4 -> 0 | I5: =Scenario_View!H4 -> 0 | J5: demand
B6: elc_industry | C6: =Scenario_View!B5 -> 65.4789 | D6: =Scenario_View!C5 -> 68.752845 | E6: =Scenario_View!D5 -> 72.190487 | F6: =Scenario_View!E5 -> 75.800012 | G6: =Scenario_View!F5 -> 79.590012 | H6: =Scenario_View!G5 -> 83.569513 | I6: =Scenario_View!H5 -> 87.747988 | J6: demand
B7: elc_buildings | C7: =Scenario_View!B6 -> 104.4123 | D7: =Scenario_View!C6 -> 109.63291 | E7: =Scenario_View!D6 -> 115.11456 | F7: =Scenario_View!E6 -> 120.87029 | G7: =Scenario_View!F6 -> 126.9138 | H7: =Scenario_View!G6 -> 133.25949 | I7: =Scenario_View!H6 -> 139.92247 | J7: demand
B8: elc_transport | C8: =Scenario_View!B7 -> 5.3091 | D8: =Scenario_View!C7 -> 5.574555 | E8: =Scenario_View!D7 -> 5.8532827 | F8: =Scenario_View!E7 -> 6.1459469 | G8: =Scenario_View!F7 -> 6.4532442 | H8: =Scenario_View!G7 -> 6.7759064 | I8: =Scenario_View!H7 -> 7.1147018 | J8: demand | L8: non-road transport demand assumed to be constant
B9: elc_roadtransport | C9: =Scenario_View!B8 -> 1.7697 | D9: =Scenario_View!C8 -> 1.858185 | E9: =Scenario_View!D8 -> 1.9510943 | F9: =Scenario_View!E8 -> 2.048649 | G9: =Scenario_View!F8 -> 2.1510814 | H9: =Scenario_View!G8 -> 2.2586355 | I9: =Scenario_View!H8 -> 2.3715673 | J9: demand
B10: het_industry | C10: =Scenario_View!B9 -> 9.769 | D10: =Scenario_View!C9 -> 10.25745 | E10: =Scenario_View!D9 -> 10.770323 | F10: =Scenario_View!E9 -> 11.308839 | G10: =Scenario_View!F9 -> 11.874281 | H10: =Scenario_View!G9 -> 12.467995 | I10: =Scenario_View!H9 -> 13.091394 | J10: demand
B11: het_buildings | C11: =Scenario_View!B10 -> 55.513 | D11: =Scenario_View!C10 -> 55.513 | E11: =Scenario_View!D10 -> 55.513 | F11: =Scenario_View!E10 -> 55.513 | G11: =Scenario_View!F10 -> 55.513 | H11: =Scenario_View!G10 -> 55.513 | I11: =Scenario_View!H10 -> 55.513 | J11: demand
B12: co2net | C12: =Scenario_View!B11/1000 -> 0 | D12: =Scenario_View!C11/1000 -> 0.016071429 | E12: =Scenario_View!D11/1000 -> 0.042857143 | F12: =Scenario_View!E11/1000 -> 0.069642857 | G12: =Scenario_View!F11/1000 -> 0.096428571 | H12: =Scenario_View!G11/1000 -> 0.12321429 | I12: =Scenario_View!H11/1000 -> 0.15 | J12: com_taxnet
B17: ~TFM_INS-TS: region=POL
B18: process | C18: 2022 | D18: 2025 | E18: 2030 | F18: 2035 | G18: 2040 | H18: 2045 | I18: 2050 | J18: attribute | K18: limtype
B19: Trd_electricity import | C19: 15.24 | J19: ACT_BND | K19: FX
B20: Trd_electricity export | C20: 16.91 | J20: ACT_BND | K20: FX
B23: ~tfm_ins-ts: region=POL
B24: process | C24: limtype | D24: 2024 | E24: 2030 | F24: 2040 | G24: attribute
B25: Trd_electricity export | C25: lo | D25: 1.455 | E25: 1.881 | F25: 1.881 | G25: cap_bnd
B26: Trd_electricity import | C26: lo | D26: 1.8 | E26: 3.3 | F26: 3.3 | G26: cap_bnd

Sheet Scenario_View
A1: ="Active Scenario: "&Controller!$B$2 -> Active Scenario: Mild
A3: Variable | B3: 2022 | C3: 2025 | D3: 2030 | E3: 2035 | F3: 2040 | G3: 2045 | H3: 2050
A4: =Controller!J2 -> hydrogen_allsect | B4: =IFERROR(IF(INDEX(Data!$D$2:$D$701,MATCH(Controller!$B$2&"|"&$A4&"|"&B$3,Data!$E$2:$E$701,0))="","",INDEX(Data!$D$2:$D$701,MATCH(Controller!$B$2&"|"&$A4&"|"&B$3,Data!$E$2:$E$701,0))),"") -> 0 | C4: =IFERROR(IF(INDEX(Data!$D$2:$D$701,MATCH(Controller!$B$2&"|"&$A4&"|"&C$3,Data!$E$2:$E$701,0))="","",INDEX(Data!$D$2:$D$701,MATCH(Controller!$B$2&"|"&$A4&"|"&C$3,Data!$E$2:$E$701,0))),"") -> 0 | D4: =IFERROR(IF(INDEX(Data!$D$2:$D$701,MATCH(Controller!$B$2&"|"&$A4&"|"&D$3,Data!$E$2:$E$701,0))="","",INDEX(Data!$D$2:$D$701,MATCH(Controller!$B$2&"|"&$A4&"|"&D$3,Data!$E$2:$E$701,0))),"") -> 0 | E4: =IFERROR(IF(INDEX(Data!$D$2:$D$701,MATCH(Controller!$B$2&"|"&$A4&"|"&E$3,Data!$E$2:$E$701,0))="","",INDEX(Data!$D$2:$D$701,MATCH(Controller!$B$2&"|"&$A4&"|"&E$3,Data!$E$2:$E$701,0))),"") -> 0 | F4: =IFERROR(IF(INDEX(Data!$D$2:$D$701,MATCH(Controller!$B$2&"|"&$A4&"|"&F$3,Data!$E$2:$E$701,0))="","",INDEX(Data!$D$2:$D$701,MATCH(Controller!$B$2&"|"&$A4&"|"&F$3,Data!$E$2:$E$701,0))),"") -> 0 | G4: =IFERROR(IF(INDEX(Data!$D$2:$D$701,MATCH(Controller!$B$2&"|"&$A4&"|"&G$3,Data!$E$2:$E$701,0))="","",INDEX(Data!$D$2:$D$701,MATCH(Controller!$B$2&"|"&$A4&"|"&G$3,Data!$E$2:$E$701,0))),"") -> 0 | H4: =IFERROR(IF(INDEX(Data!$D$2:$D$701,MATCH(Controller!$B$2&"|"&$A4&"|"&H$3,Data!$E$2:$E$701,0))="","",INDEX(Data!$D$2:$D$701,MATCH(Controller!$B$2&"|"&$A4&"|"&H$3,Data!$E$2:$E$701,0))),"") -> 0
A5: =Controller!J3 -> elc_industry | B5: =IFERROR(IF(INDEX(Data!$D$2:$D$701,MATCH(Controller!$B$2&"|"&$A5&"|"&B$3,Data!$E$2:$E$701,0))="","",INDEX(Data!$D$2:$D$701,MATCH(Controller!$B$2&"|"&$A5&"|"&B$3,Data!$E$2:$E$701,0))),"") -> 65.4789 | C5: =IFERROR(IF(INDEX(Data!$D$2:$D$701,MATCH(Controller!$B$2&"|"&$A5&"|"&C$3,Data!$E$2:$E$701,0))="","",INDEX(Data!$D$2:$D$701,MATCH(Controller!$B$2&"|"&$A5&"|"&C$3,Data!$E$2:$E$701,0))),"") -> 68.752845 | D5: =IFERROR(IF(INDEX(Data!$D$2:$D$701,MATCH(Controller!$B$2&"|"&$A5&"|"&D$3,Data!$E$2:$E$701,0))="","",INDEX(Data!$D$2:$D$701,MATCH(Controller!$B$2&"|"&$A5&"|"&D$3,Data!$E$2:$E$701,0))),"") -> 72.190487 | E5: =IFERROR(IF(INDEX(Data!$D$2:$D$701,MATCH(Controller!$B$2&"|"&$A5&"|"&E$3,Data!$E$2:$E$701,0))="","",INDEX(Data!$D$2:$D$701,MATCH(Controller!$B$2&"|"&$A5&"|"&E$3,Data!$E$2:$E$701,0))),"") -> 75.800012 | F5: =IFERROR(IF(INDEX(Data!$D$2:$D$701,MATCH(Controller!$B$2&"|"&$A5&"|"&F$3,Data!$E$2:$E$701,0))="","",INDEX(Data!$D$2:$D$701,MATCH(Controller!$B$2&"|"&$A5&"|"&F$3,Data!$E$2:$E$701,0))),"") -> 79.590012 | G5: =IFERROR(IF(INDEX(Data!$D$2:$D$701,MATCH(Controller!$B$2&"|"&$A5&"|"&G$3,Data!$E$2:$E$701,0))="","",INDEX(Data!$D$2:$D$701,MATCH(Controller!$B$2&"|"&$A5&"|"&G$3,Data!$E$2:$E$701,0))),"") -> 83.569513 | H5: =IFERROR(IF(INDEX(Data!$D$2:$D$701,MATCH(Controller!$B$2&"|"&$A5&"|"&H$3,Data!$E$2:$E$701,0))="","",INDEX(Data!$D$2:$D$701,MATCH(Controller!$B$2&"|"&$A5&"|"&H$3,Data!$E$2:$E$701,0))),"") -> 87.747988
A6: =Controller!J4 -> elc_buildings | B6: =IFERROR(IF(INDEX(Data!$D$2:$D$701,MATCH(Controller!$B$2&"|"&$A6&"|"&B$3,Data!$E$2:$E$701,0))="","",INDEX(Data!$D$2:$D$701,MATCH(Controller!$B$2&"|"&$A6&"|"&B$3,Data!$E$2:$E$701,0))),"") -> 104.4123 | C6: =IFERROR(IF(INDEX(Data!$D$2:$D$701,MATCH(Controller!$B$2&"|"&$A6&"|"&C$3,Data!$E$2:$E$701,0))="","",INDEX(Data!$D$2:$D$701,MATCH(Controller!$B$2&"|"&$A6&"|"&C$3,Data!$E$2:$E$701,0))),"") -> 109.63291 | D6: =IFERROR(IF(INDEX(Data!$D$2:$D$701,MATCH(Controller!$B$2&"|"&$A6&"|"&D$3,Data!$E$2:$E$701,0))="","",INDEX(Data!$D$2:$D$701,MATCH(Controller!$B$2&"|"&$A6&"|"&D$3,Data!$E$2:$E$701,0))),"") -> 115.11456 | E6: =IFERROR(IF(INDEX(Data!$D$2:$D$701,MATCH(Controller!$B$2&"|"&$A6&"|"&E$3,Data!$E$2:$E$701,0))="","",INDEX(Data!$D$2:$D$701,MATCH(Controller!$B$2&"|"&$A6&"|"&E$3,Data!$E$2:$E$701,0))),"") -> 120.87029 | F6: =IFERROR(IF(INDEX(Data!$D$2:$D$701,MATCH(Controller!$B$2&"|"&$A6&"|"&F$3,Data!$E$2:$E$701,0))="","",INDEX(Data!$D$2:$D$701,MATCH(Controller!$B$2&"|"&$A6&"|"&F$3,Data!$E$2:$E$701,0))),"") -> 126.9138 | G6: =IFERROR(IF(INDEX(Data!$D$2:$D$701,MATCH(Controller!$B$2&"|"&$A6&"|"&G$3,Data!$E$2:$E$701,0))="","",INDEX(Data!$D$2:$D$701,MATCH(Controller!$B$2&"|"&$A6&"|"&G$3,Data!$E$2:$E$701,0))),"") -> 133.25949 | H6: =IFERROR(IF(INDEX(Data!$D$2:$D$701,MATCH(Controller!$B$2&"|"&$A6&"|"&H$3,Data!$E$2:$E$701,0))="","",INDEX(Data!$D$2:$D$701,MATCH(Controller!$B$2&"|"&$A6&"|"&H$3,Data!$E$2:$E$701,0))),"") -> 139.92247
A7: =Controller!J5 -> elc_transport | B7: =IFERROR(IF(INDEX(Data!$D$2:$D$701,MATCH(Controller!$B$2&"|"&$A7&"|"&B$3,Data!$E$2:$E$701,0))="","",INDEX(Data!$D$2:$D$701,MATCH(Controller!$B$2&"|"&$A7&"|"&B$3,Data!$E$2:$E$701,0))),"") -> 5.3091 | C7: =IFERROR(IF(INDEX(Data!$D$2:$D$701,MATCH(Controller!$B$2&"|"&$A7&"|"&C$3,Data!$E$2:$E$701,0))="","",INDEX(Data!$D$2:$D$701,MATCH(Controller!$B$2&"|"&$A7&"|"&C$3,Data!$E$2:$E$701,0))),"") -> 5.574555 | D7: =IFERROR(IF(INDEX(Data!$D$2:$D$701,MATCH(Controller!$B$2&"|"&$A7&"|"&D$3,Data!$E$2:$E$701,0))="","",INDEX(Data!$D$2:$D$701,MATCH(Controller!$B$2&"|"&$A7&"|"&D$3,Data!$E$2:$E$701,0))),"") -> 5.8532827 | E7: =IFERROR(IF(INDEX(Data!$D$2:$D$701,MATCH(Controller!$B$2&"|"&$A7&"|"&E$3,Data!$E$2:$E$701,0))="","",INDEX(Data!$D$2:$D$701,MATCH(Controller!$B$2&"|"&$A7&"|"&E$3,Data!$E$2:$E$701,0))),"") -> 6.1459469 | F7: =IFERROR(IF(INDEX(Data!$D$2:$D$701,MATCH(Controller!$B$2&"|"&$A7&"|"&F$3,Data!$E$2:$E$701,0))="","",INDEX(Data!$D$2:$D$701,MATCH(Controller!$B$2&"|"&$A7&"|"&F$3,Data!$E$2:$E$701,0))),"") -> 6.4532442 | G7: =IFERROR(IF(INDEX(Data!$D$2:$D$701,MATCH(Controller!$B$2&"|"&$A7&"|"&G$3,Data!$E$2:$E$701,0))="","",INDEX(Data!$D$2:$D$701,MATCH(Controller!$B$2&"|"&$A7&"|"&G$3,Data!$E$2:$E$701,0))),"") -> 6.7759064 | H7: =IFERROR(IF(INDEX(Data!$D$2:$D$701,MATCH(Controller!$B$2&"|"&$A7&"|"&H$3,Data!$E$2:$E$701,0))="","",INDEX(Data!$D$2:$D$701,MATCH(Controller!$B$2&"|"&$A7&"|"&H$3,Data!$E$2:$E$701,0))),"") -> 7.1147018
A8: =Controller!J6 -> elc_roadtransport | B8: =IFERROR(IF(INDEX(Data!$D$2:$D$701,MATCH(Controller!$B$2&"|"&$A8&"|"&B$3,Data!$E$2:$E$701,0))="","",INDEX(Data!$D$2:$D$701,MATCH(Controller!$B$2&"|"&$A8&"|"&B$3,Data!$E$2:$E$701,0))),"") -> 1.7697 | C8: =IFERROR(IF(INDEX(Data!$D$2:$D$701,MATCH(Controller!$B$2&"|"&$A8&"|"&C$3,Data!$E$2:$E$701,0))="","",INDEX(Data!$D$2:$D$701,MATCH(Controller!$B$2&"|"&$A8&"|"&C$3,Data!$E$2:$E$701,0))),"") -> 1.858185 | D8: =IFERROR(IF(INDEX(Data!$D$2:$D$701,MATCH(Controller!$B$2&"|"&$A8&"|"&D$3,Data!$E$2:$E$701,0))="","",INDEX(Data!$D$2:$D$701,MATCH(Controller!$B$2&"|"&$A8&"|"&D$3,Data!$E$2:$E$701,0))),"") -> 1.9510943 | E8: =IFERROR(IF(INDEX(Data!$D$2:$D$701,MATCH(Controller!$B$2&"|"&$A8&"|"&E$3,Data!$E$2:$E$701,0))="","",INDEX(Data!$D$2:$D$701,MATCH(Controller!$B$2&"|"&$A8&"|"&E$3,Data!$E$2:$E$701,0))),"") -> 2.048649 | F8: =IFERROR(IF(INDEX(Data!$D$2:$D$701,MATCH(Controller!$B$2&"|"&$A8&"|"&F$3,Data!$E$2:$E$701,0))="","",INDEX(Data!$D$2:$D$701,MATCH(Controller!$B$2&"|"&$A8&"|"&F$3,Data!$E$2:$E$701,0))),"") -> 2.1510814 | G8: =IFERROR(IF(INDEX(Data!$D$2:$D$701,MATCH(Controller!$B$2&"|"&$A8&"|"&G$3,Data!$E$2:$E$701,0))="","",INDEX(Data!$D$2:$D$701,MATCH(Controller!$B$2&"|"&$A8&"|"&G$3,Data!$E$2:$E$701,0))),"") -> 2.2586355 | H8: =IFERROR(IF(INDEX(Data!$D$2:$D$701,MATCH(Controller!$B$2&"|"&$A8&"|"&H$3,Data!$E$2:$E$701,0))="","",INDEX(Data!$D$2:$D$701,MATCH(Controller!$B$2&"|"&$A8&"|"&H$3,Data!$E$2:$E$701,0))),"") -> 2.3715673
A9: =Controller!J7 -> het_industry | B9: =IFERROR(IF(INDEX(Data!$D$2:$D$701,MATCH(Controller!$B$2&"|"&$A9&"|"&B$3,Data!$E$2:$E$701,0))="","",INDEX(Data!$D$2:$D$701,MATCH(Controller!$B$2&"|"&$A9&"|"&B$3,Data!$E$2:$E$701,0))),"") -> 9.769 | C9: =IFERROR(IF(INDEX(Data!$D$2:$D$701,MATCH(Controller!$B$2&"|"&$A9&"|"&C$3,Data!$E$2:$E$701,0))="","",INDEX(Data!$D$2:$D$701,MATCH(Controller!$B$2&"|"&$A9&"|"&C$3,Data!$E$2:$E$701,0))),"") -> 10.25745 | D9: =IFERROR(IF(INDEX(Data!$D$2:$D$701,MATCH(Controller!$B$2&"|"&$A9&"|"&D$3,Data!$E$2:$E$701,0))="","",INDEX(Data!$D$2:$D$701,MATCH(Controller!$B$2&"|"&$A9&"|"&D$3,Data!$E$2:$E$701,0))),"") -> 10.770323 | E9: =IFERROR(IF(INDEX(Data!$D$2:$D$701,MATCH(Controller!$B$2&"|"&$A9&"|"&E$3,Data!$E$2:$E$701,0))="","",INDEX(Data!$D$2:$D$701,MATCH(Controller!$B$2&"|"&$A9&"|"&E$3,Data!$E$2:$E$701,0))),"") -> 11.308839 | F9: =IFERROR(IF(INDEX(Data!$D$2:$D$701,MATCH(Controller!$B$2&"|"&$A9&"|"&F$3,Data!$E$2:$E$701,0))="","",INDEX(Data!$D$2:$D$701,MATCH(Controller!$B$2&"|"&$A9&"|"&F$3,Data!$E$2:$E$701,0))),"") -> 11.874281 | G9: =IFERROR(IF(INDEX(Data!$D$2:$D$701,MATCH(Controller!$B$2&"|"&$A9&"|"&G$3,Data!$E$2:$E$701,0))="","",INDEX(Data!$D$2:$D$701,MATCH(Controller!$B$2&"|"&$A9&"|"&G$3,Data!$E$2:$E$701,0))),"") -> 12.467995 | H9: =IFERROR(IF(INDEX(Data!$D$2:$D$701,MATCH(Controller!$B$2&"|"&$A9&"|"&H$3,Data!$E$2:$E$701,0))="","",INDEX(Data!$D$2:$D$701,MATCH(Controller!$B$2&"|"&$A9&"|"&H$3,Data!$E$2:$E$701,0))),"") -> 13.091394
A10: =Controller!J8 -> het_buildings | B10: =IFERROR(IF(INDEX(Data!$D$2:$D$701,MATCH(Controller!$B$2&"|"&$A10&"|"&B$3,Data!$E$2:$E$701,0))="","",INDEX(Data!$D$2:$D$701,MATCH(Controller!$B$2&"|"&$A10&"|"&B$3,Data!$E$2:$E$701,0))),"") -> 55.513 | C10: =IFERROR(IF(INDEX(Data!$D$2:$D$701,MATCH(Controller!$B$2&"|"&$A10&"|"&C$3,Data!$E$2:$E$701,0))="","",INDEX(Data!$D$2:$D$701,MATCH(Controller!$B$2&"|"&$A10&"|"&C$3,Data!$E$2:$E$701,0))),"") -> 55.513 | D10: =IFERROR(IF(INDEX(Data!$D$2:$D$701,MATCH(Controller!$B$2&"|"&$A10&"|"&D$3,Data!$E$2:$E$701,0))="","",INDEX(Data!$D$2:$D$701,MATCH(Controller!$B$2&"|"&$A10&"|"&D$3,Data!$E$2:$E$701,0))),"") -> 55.513 | E10: =IFERROR(IF(INDEX(Data!$D$2:$D$701,MATCH(Controller!$B$2&"|"&$A10&"|"&E$3,Data!$E$2:$E$701,0))="","",INDEX(Data!$D$2:$D$701,MATCH(Controller!$B$2&"|"&$A10&"|"&E$3,Data!$E$2:$E$701,0))),"") -> 55.513 | F10: =IFERROR(IF(INDEX(Data!$D$2:$D$701,MATCH(Controller!$B$2&"|"&$A10&"|"&F$3,Data!$E$2:$E$701,0))="","",INDEX(Data!$D$2:$D$701,MATCH(Controller!$B$2&"|"&$A10&"|"&F$3,Data!$E$2:$E$701,0))),"") -> 55.513 | G10: =IFERROR(IF(INDEX(Data!$D$2:$D$701,MATCH(Controller!$B$2&"|"&$A10&"|"&G$3,Data!$E$2:$E$701,0))="","",INDEX(Data!$D$2:$D$701,MATCH(Controller!$B$2&"|"&$A10&"|"&G$3,Data!$E$2:$E$701,0))),"") -> 55.513 | H10: =IFERROR(IF(INDEX(Data!$D$2:$D$701,MATCH(Controller!$B$2&"|"&$A10&"|"&H$3,Data!$E$2:$E$701,0))="","",INDEX(Data!$D$2:$D$701,MATCH(Controller!$B$2&"|"&$A10&"|"&H$3,Data!$E$2:$E$701,0))),"") -> 55.513
A11: =Controller!J9 -> co2net | B11: =IFERROR(IF(INDEX(Data!$D$2:$D$701,MATCH(Controller!$B$2&"|"&$A11&"|"&B$3,Data!$E$2:$E$701,0))="","",INDEX(Data!$D$2:$D$701,MATCH(Controller!$B$2&"|"&$A11&"|"&B$3,Data!$E$2:$E$701,0))),"") -> 0 | C11: =IFERROR(IF(INDEX(Data!$D$2:$D$701,MATCH(Controller!$B$2&"|"&$A11&"|"&C$3,Data!$E$2:$E$701,0))="","",INDEX(Data!$D$2:$D$701,MATCH(Controller!$B$2&"|"&$A11&"|"&C$3,Data!$E$2:$E$701,0))),"") -> 16.071429 | D11: =IFERROR(IF(INDEX(Data!$D$2:$D$701,MATCH(Controller!$B$2&"|"&$A11&"|"&D$3,Data!$E$2:$E$701,0))="","",INDEX(Data!$D$2:$D$701,MATCH(Controller!$B$2&"|"&$A11&"|"&D$3,Data!$E$2:$E$701,0))),"") -> 42.857143 | E11: =IFERROR(IF(INDEX(Data!$D$2:$D$701,MATCH(Controller!$B$2&"|"&$A11&"|"&E$3,Data!$E$2:$E$701,0))="","",INDEX(Data!$D$2:$D$701,MATCH(Controller!$B$2&"|"&$A11&"|"&E$3,Data!$E$2:$E$701,0))),"") -> 69.642857 | F11: =IFERROR(IF(INDEX(Data!$D$2:$D$701,MATCH(Controller!$B$2&"|"&$A11&"|"&F$3,Data!$E$2:$E$701,0))="","",INDEX(Data!$D$2:$D$701,MATCH(Controller!$B$2&"|"&$A11&"|"&F$3,Data!$E$2:$E$701,0))),"") -> 96.428571 | G11: =IFERROR(IF(INDEX(Data!$D$2:$D$701,MATCH(Controller!$B$2&"|"&$A11&"|"&G$3,Data!$E$2:$E$701,0))="","",INDEX(Data!$D$2:$D$701,MATCH(Controller!$B$2&"|"&$A11&"|"&G$3,Data!$E$2:$E$701,0))),"") -> 123.21429 | H11: =IFERROR(IF(INDEX(Data!$D$2:$D$701,MATCH(Controller!$B$2&"|"&$A11&"|"&H$3,Data!$E$2:$E$701,0))="","",INDEX(Data!$D$2:$D$701,MATCH(Controller!$B$2&"|"&$A11&"|"&H$3,Data!$E$2:$E$701,0))),"") -> 150
A12: =Controller!J10 -> Variable 9 | B12: =IFERROR(IF(INDEX(Data!$D$2:$D$701,MATCH(Controller!$B$2&"|"&$A12&"|"&B$3,Data!$E$2:$E$701,0))="","",INDEX(Data!$D$2:$D$701,MATCH(Controller!$B$2&"|"&$A12&"|"&B$3,Data!$E$2:$E$701,0))),"") | C12: =IFERROR(IF(INDEX(Data!$D$2:$D$701,MATCH(Controller!$B$2&"|"&$A12&"|"&C$3,Data!$E$2:$E$701,0))="","",INDEX(Data!$D$2:$D$701,MATCH(Controller!$B$2&"|"&$A12&"|"&C$3,Data!$E$2:$E$701,0))),"") | D12: =IFERROR(IF(INDEX(Data!$D$2:$D$701,MATCH(Controller!$B$2&"|"&$A12&"|"&D$3,Data!$E$2:$E$701,0))="","",INDEX(Data!$D$2:$D$701,MATCH(Controller!$B$2&"|"&$A12&"|"&D$3,Data!$E$2:$E$701,0))),"") | E12: =IFERROR(IF(INDEX(Data!$D$2:$D$701,MATCH(Controller!$B$2&"|"&$A12&"|"&E$3,Data!$E$2:$E$701,0))="","",INDEX(Data!$D$2:$D$701,MATCH(Controller!$B$2&"|"&$A12&"|"&E$3,Data!$E$2:$E$701,0))),"") | F12: =IFERROR(IF(INDEX(Data!$D$2:$D$701,MATCH(Controller!$B$2&"|"&$A12&"|"&F$3,Data!$E$2:$E$701,0))="","",INDEX(Data!$D$2:$D$701,MATCH(Controller!$B$2&"|"&$A12&"|"&F$3,Data!$E$2:$E$701,0))),"") | G12: =IFERROR(IF(INDEX(Data!$D$2:$D$701,MATCH(Controller!$B$2&"|"&$A12&"|"&G$3,Data!$E$2:$E$701,0))="","",INDEX(Data!$D$2:$D$701,MATCH(Controller!$B$2&"|"&$A12&"|"&G$3,Data!$E$2:$E$701,0))),"") | H12: =IFERROR(IF(INDEX(Data!$D$2:$D$701,MATCH(Controller!$B$2&"|"&$A12&"|"&H$3,Data!$E$2:$E$701,0))="","",INDEX(Data!$D$2:$D$701,MATCH(Controller!$B$2&"|"&$A12&"|"&H$3,Data!$E$2:$E$701,0))),"")
A13: =Controller!J11 -> Variable 10 | B13: =IFERROR(IF(INDEX(Data!$D$2:$D$701,MATCH(Controller!$B$2&"|"&$A13&"|"&B$3,Data!$E$2:$E$701,0))="","",INDEX(Data!$D$2:$D$701,MATCH(Controller!$B$2&"|"&$A13&"|"&B$3,Data!$E$2:$E$701,0))),"") | C13: =IFERROR(IF(INDEX(Data!$D$2:$D$701,MATCH(Controller!$B$2&"|"&$A13&"|"&C$3,Data!$E$2:$E$701,0))="","",INDEX(Data!$D$2:$D$701,MATCH(Controller!$B$2&"|"&$A13&"|"&C$3,Data!$E$2:$E$701,0))),"") | D13: =IFERROR(IF(INDEX(Data!$D$2:$D$701,MATCH(Controller!$B$2&"|"&$A13&"|"&D$3,Data!$E$2:$E$701,0))="","",INDEX(Data!$D$2:$D$701,MATCH(Controller!$B$2&"|"&$A13&"|"&D$3,Data!$E$2:$E$701,0))),"") | E13: =IFERROR(IF(INDEX(Data!$D$2:$D$701,MATCH(Controller!$B$2&"|"&$A13&"|"&E$3,Data!$E$2:$E$701,0))="","",INDEX(Data!$D$2:$D$701,MATCH(Controller!$B$2&"|"&$A13&"|"&E$3,Data!$E$2:$E$701,0))),"") | F13: =IFERROR(IF(INDEX(Data!$D$2:$D$701,MATCH(Controller!$B$2&"|"&$A13&"|"&F$3,Data!$E$2:$E$701,0))="","",INDEX(Data!$D$2:$D$701,MATCH(Controller!$B$2&"|"&$A13&"|"&F$3,Data!$E$2:$E$701,0))),"") | G13: =IFERROR(IF(INDEX(Data!$D$2:$D$701,MATCH(Controller!$B$2&"|"&$A13&"|"&G$3,Data!$E$2:$E$701,0))="","",INDEX(Data!$D$2:$D$701,MATCH(Controller!$B$2&"|"&$A13&"|"&G$3,Data!$E$2:$E$701,0))),"") | H13: =IFERROR(IF(INDEX(Data!$D$2:$D$701,MATCH(Controller!$B$2&"|"&$A13&"|"&H$3,Data!$E$2:$E$701,0))="","",INDEX(Data!$D$2:$D$701,MATCH(Controller!$B$2&"|"&$A13&"|"&H$3,Data!$E$2:$E$701,0))),"")
A15: Scenario names and variable names are controlled centrally from the Controller lists. The active scenario is driven by Controller!D18; B2 shows 'Scenario name - X'. This view uses the Data helper key to retrieve the selected scenario values while preserving blanks and real zeros.

Sheet CO2_t
B2: =[1]Veda!N26 -> ~TFM_INS-TS: region=POL
B3: process | C3: 2025 | D3: 2030 | E3: 2035 | F3: 2040 | G3: 2045 | H3: 2050 | I3: attribute
B4: biofuels_Swidnica_POL | C4: 319.327 | D4: =C4*1.05 -> 335.29335 | E4: =D4*1.05 -> 352.05802 | F4: =E4*1.05 -> 369.66092 | G4: =F4*1.05 -> 388.14396 | H4: =G4*1.05 -> 407.55116 | I4: Stock
B5: cement_Bydgoszcz_POL | C5: 882.439 | D5: =C5*1.05 -> 926.56095 | E5: =D5*1.05 -> 972.889 | F5: =E5*1.05 -> 1021.5334 | G5: =F5*1.05 -> 1072.6101 | H5: =G5*1.05 -> 1126.2406 | I5: Stock
B6: cement_Chelm_POL | C6: 1552.307 | D6: =C6*1.05 -> 1629.9224 | E6: =D6*1.05 -> 1711.4185 | F6: =E6*1.05 -> 1796.9894 | G6: =F6*1.05 -> 1886.8389 | H6: =G6*1.05 -> 1981.1808 | I6: Stock
B7: cement_Czestochowa_POL | C7: 861.259 | D7: =C7*1.05 -> 904.32195 | E7: =D7*1.05 -> 949.53805 | F7: =E7*1.05 -> 997.01495 | G7: =F7*1.05 -> 1046.8657 | H7: =G7*1.05 -> 1099.209 | I7: Stock
B8: cement_KedzierzynKozle_POL | C8: 1600.077 | D8: =C8*1.05 -> 1680.0809 | E8: =D8*1.05 -> 1764.0849 | F8: =E8*1.05 -> 1852.2891 | G8: =F8*1.05 -> 1944.9036 | H8: =G8*1.05 -> 2042.1488 | I8: Stock
B9: cement_Kielce_POL | C9: 304.556 | D9: =C9*1.05 -> 319.7838 | E9: =D9*1.05 -> 335.77299 | F9: =E9*1.05 -> 352.56164 | G9: =F9*1.05 -> 370.18972 | H9: =G9*1.05 -> 388.69921 | I9: Stock
B10: cement_OstrowiecSwietokrz_POL | C10: 1623.857 | D10: =C10*1.05 -> 1705.0499 | E10: =D10*1.05 -> 1790.3023 | F10: =E10*1.05 -> 1879.8175 | G10: =F10*1.05 -> 1973.8083 | H10: =G10*1.05 -> 2072.4987 | I10: Stock
B11: cement_Radomsko_POL | C11: 3132.102 | D11: =C11*1.05 -> 3288.7071 | E11: =D11*1.05 -> 3453.1425 | F11: =E11*1.05 -> 3625.7996 | G11: =F11*1.05 -> 3807.0896 | H11: =G11*1.05 -> 3997.444 | I11: Stock
B12: chemicals_Katowice_POL | C12: 131.528 | D12: =C12*1.05 -> 138.1044 | E12: =D12*1.05 -> 145.00962 | F12: =E12*1.05 -> 152.2601 | G12: =F12*1.05 -> 159.87311 | H12: =G12*1.05 -> 167.86676 | I12: Stock
B13: chemicals_Legnica_POL | C13: 493.099 | D13: =C13*1.05 -> 517.75395 | E13: =D13*1.05 -> 543.64165 | F13: =E13*1.05 -> 570.82373 | G13: =F13*1.05 -> 599.36492 | H13: =G13*1.05 -> 629.33316 | I13: Stock
B14: fertilizer_KedzierzynKozle_POL | C14: 974.393 | D14: =C14*1.05 -> 1023.1127 | E14: =D14*1.05 -> 1074.2683 | F14: =E14*1.05 -> 1127.9817 | G14: =F14*1.05 -> 1184.3808 | H14: =G14*1.05 -> 1243.5998 | I14: Stock
B15: fertilizer_Police_POL | C15: 831.856 | D15: =C15*1.05 -> 873.4488 | E15: =D15*1.05 -> 917.12124 | F15: =E15*1.05 -> 962.9773 | G15: =F15*1.05 -> 1011.1262 | H15: =G15*1.05 -> 1061.6825 | I15: Stock
... B51: wood_ZielonaGora_POL | C51: 214.361 | D51: =C51*1.05 -> 225.07905 | E51: =D51*1.05 -> 236.333 | F51: =E51*1.05 -> 248.14965 | G51: =F51*1.05 -> 260.55714 | H51: =G51*1.05 -> 273.58499 | I51: Stock

Sheet Prices
B2: ~TFM_INS-TS: region=POL; attribute=flo_cost;pset_pn=-IMP*Z
B3: commodity | C3: pset_co | D3: 2022 | E3: 2025 | F3: 2030 | G3: 2035 | H3: 2040 | I3: 2045 | J3: 2050
B4: Gas | C4: Gas | D4: 33.4 | E4: 35.738 | F4: 41.416 | G4: 38.41 | H4: 41.75 | I4: 39.078 | J4: 44.756
B5: Coal | C5: Coal | D5: 12.2 | E5: 12.444 | F5: 12.932 | G5: 13.054 | H5: 13.176 | I5: 13.42 | J5: 13.664
B6: Oil | C6: Oil | D6: 53 | E6: 53.53 | F6: 58.83 | G6: 53.53 | H6: 53.53 | I6: 55.12 | J6: 60.42
B7: Bioenergy | C7: Bioenergy | D7: 26 | J7: 78

Sheet Data
A1: Scenario | B1: Time Period | C1: Variable | D1: Value | E1: Key
A2: =INDEX(Controller!$H$2:$H$11,INT((ROW()-2)/70)+1) -> Ref | B2: 2022 | C2: =INDEX(Controller!$J$2:$J$11,MOD(INT((ROW()-2)/7),10)+1) -> hydrogen_allsect | D2: 0 | E2: =A2&"|"&C2&"|"&B2 -> Ref|hydrogen_allsect|2022
A3: =INDEX(Controller!$H$2:$H$11,INT((ROW()-2)/70)+1) -> Ref | B3: 2025 | C3: =INDEX(Controller!$J$2:$J$11,MOD(INT((ROW()-2)/7),10)+1) -> hydrogen_allsect | D3: =D2*2%+D2 -> 0 | E3: =A3&"|"&C3&"|"&B3 -> Ref|hydrogen_allsect|2025
A4: =INDEX(Controller!$H$2:$H$11,INT((ROW()-2)/70)+1) -> Ref | B4: 2030 | C4: =INDEX(Controller!$J$2:$J$11,MOD(INT((ROW()-2)/7),10)+1) -> hydrogen_allsect | D4: =D3*2%+D3 -> 0 | E4: =A4&"|"&C4&"|"&B4 -> Ref|hydrogen_allsect|2030
A5: =INDEX(Controller!$H$2:$H$11,INT((ROW()-2)/70)+1) -> Ref | B5: 2035 | C5: =INDEX(Controller!$J$2:$J$11,MOD(INT((ROW()-2)/7),10)+1) -> hydrogen_allsect | D5: =D4*2%+D4 -> 0 | E5: =A5&"|"&C5&"|"&B5 -> Ref|hydrogen_allsect|2035
A6: =INDEX(Controller!$H$2:$H$11,INT((ROW()-2)/70)+1) -> Ref | B6: 2040 | C6: =INDEX(Controller!$J$2:$J$11,MOD(INT((ROW()-2)/7),10)+1) -> hydrogen_allsect | D6: =D5*2%+D5 -> 0 | E6: =A6&"|"&C6&"|"&B6 -> Ref|hydrogen_allsect|2040
A7: =INDEX(Controller!$H$2:$H$11,INT((ROW()-2)/70)+1) -> Ref | B7: 2045 | C7: =INDEX(Controller!$J$2:$J$11,MOD(INT((ROW()-2)/7),10)+1) -> hydrogen_allsect | D7: =D6*2%+D6 -> 0 | E7: =A7&"|"&C7&"|"&B7 -> Ref|hydrogen_allsect|2045
A8: =INDEX(Controller!$H$2:$H$11,INT((ROW()-2)/70)+1) -> Ref | B8: 2050 | C8: =INDEX(Controller!$J$2:$J$11,MOD(INT((ROW()-2)/7),10)+1) -> hydrogen_allsect | D8: =D7*2%+D7 -> 0 | E8: =A8&"|"&C8&"|"&B8 -> Ref|hydrogen_allsect|2050
A9: =INDEX(Controller!$H$2:$H$11,INT((ROW()-2)/70)+1) -> Ref | B9: 2022 | C9: =INDEX(Controller!$J$2:$J$11,MOD(INT((ROW()-2)/7),10)+1) -> elc_industry | D9: 65.4789 | E9: =A9&"|"&C9&"|"&B9 -> Ref|elc_industry|2022
A10: =INDEX(Controller!$H$2:$H$11,INT((ROW()-2)/70)+1) -> Ref | B10: 2025 | C10: =INDEX(Controller!$J$2:$J$11,MOD(INT((ROW()-2)/7),10)+1) -> elc_industry | D10: =D9*2%+D9 -> 66.788478 | E10: =A10&"|"&C10&"|"&B10 -> Ref|elc_industry|2025
A11: =INDEX(Controller!$H$2:$H$11,INT((ROW()-2)/70)+1) -> Ref | B11: 2030 | C11: =INDEX(Controller!$J$2:$J$11,MOD(INT((ROW()-2)/7),10)+1) -> elc_industry | D11: =D10*2%+D10 -> 68.124248 | E11: =A11&"|"&C11&"|"&B11 -> Ref|elc_industry|2030
A12: =INDEX(Controller!$H$2:$H$11,INT((ROW()-2)/70)+1) -> Ref | B12: 2035 | C12: =INDEX(Controller!$J$2:$J$11,MOD(INT((ROW()-2)/7),10)+1) -> elc_industry | D12: =D11*2%+D11 -> 69.486733 | E12: =A12&"|"&C12&"|"&B12 -> Ref|elc_industry|2035
A13: =INDEX(Controller!$H$2:$H$11,INT((ROW()-2)/70)+1) -> Ref | B13: 2040 | C13: =INDEX(Controller!$J$2:$J$11,MOD(INT((ROW()-2)/7),10)+1) -> elc_industry | D13: =D12*2%+D12 -> 70.876467 | E13: =A13&"|"&C13&"|"&B13 -> Ref|elc_industry|2040
A14: =INDEX(Controller!$H$2:$H$11,INT((ROW()-2)/70)+1) -> Ref | B14: 2045 | C14: =INDEX(Controller!$J$2:$J$11,MOD(INT((ROW()-2)/7),10)+1) -> elc_industry | D14: =D13*2%+D13 -> 72.293997 | E14: =A14&"|"&C14&"|"&B14 -> Ref|elc_industry|2045
A15: =INDEX(Controller!$H$2:$H$11,INT((ROW()-2)/70)+1) -> Ref | B15: 2050 | C15: =INDEX(Controller!$J$2:$J$11,MOD(INT((ROW()-2)/7),10)+1) -> elc_industry | D15: =D14*2%+D14 -> 73.739876 | E15: =A15&"|"&C15&"|"&B15 -> Ref|elc_industry|2050
A16: =INDEX(Controller!$H$2:$H$11,INT((ROW()-2)/70)+1) -> Ref | B16: 2022 | C16: =INDEX(Controller!$J$2:$J$11,MOD(INT((ROW()-2)/7),10)+1) -> elc_buildings | D16: 104.4123 | E16: =A16&"|"&C16&"|"&B16 -> Ref|elc_buildings|2022
A17: =INDEX(Controller!$H$2:$H$11,INT((ROW()-2)/70)+1) -> Ref | B17: 2025 | C17: =INDEX(Controller!$J$2:$J$11,MOD(INT((ROW()-2)/7),10)+1) -> elc_buildings | D17: =D16*2%+D16 -> 106.50055 | E17: =A17&"|"&C17&"|"&B17 -> Ref|elc_buildings|2025
A18: =INDEX(Controller!$H$2:$H$11,INT((ROW()-2)/70)+1) -> Ref | B18: 2030 | C18: =INDEX(Controller!$J$2:$J$11,MOD(INT((ROW()-2)/7),10)+1) -> elc_buildings | D18: =D17*2%+D17 -> 108.63056 | E18: =A18&"|"&C18&"|"&B18 -> Ref|elc_buildings|2030
A19: =INDEX(Controller!$H$2:$H$11,INT((ROW()-2)/70)+1) -> Ref | B19: 2035 | C19: =INDEX(Controller!$J$2:$J$11,MOD(INT((ROW()-2)/7),10)+1) -> elc_buildings | D19: =D18*2%+D18 -> 110.80317 | E19: =A19&"|"&C19&"|"&B19 -> Ref|elc_buildings|2035
A20: =INDEX(Controller!$H$2:$H$11,INT((ROW()-2)/70)+1) -> Ref | B20: 2040 | C20: =INDEX(Controller!$J$2:$J$11,MOD(INT((ROW()-2)/7),10)+1) -> elc_buildings | D20: =D19*2%+D19 -> 113.01923 | E20: =A20&"|"&C20&"|"&B20 -> Ref|elc_buildings|2040
A21: =INDEX(Controller!$H$2:$H$11,INT((ROW()-2)/70)+1) -> Ref | B21: 2045 | C21: =INDEX(Controller!$J$2:$J$11,MOD(INT((ROW()-2)/7),10)+1) -> elc_buildings | D21: =D20*2%+D20 -> 115.27962 | E21: =A21&"|"&C21&"|"&B21 -> Ref|elc_buildings|2045
A22: =INDEX(Controller!$H$2:$H$11,INT((ROW()-2)/70)+1) -> Ref | B22: 2050 | C22: =INDEX(Controller!$J$2:$J$11,MOD(INT((ROW()-2)/7),10)+1) -> elc_buildings | D22: =D21*2%+D21 -> 117.58521 | E22: =A22&"|"&C22&"|"&B22 -> Ref|elc_buildings|2050
A23: =INDEX(Controller!$H$2:$H$11,INT((ROW()-2)/70)+1) -> Ref | B23: 2022 | C23: =INDEX(Controller!$J$2:$J$11,MOD(INT((ROW()-2)/7),10)+1) -> elc_transport | D23: 5.3091 | E23: =A23&"|"&C23&"|"&B23 -> Ref|elc_transport|2022
A24: =INDEX(Controller!$H$2:$H$11,INT((ROW()-2)/70)+1) -> Ref | B24: 2025 | C24: =INDEX(Controller!$J$2:$J$11,MOD(INT((ROW()-2)/7),10)+1) -> elc_transport | D24: =D23*2%+D23 -> 5.415282 | E24: =A24&"|"&C24&"|"&B24 -> Ref|elc_transport|2025
A25: =INDEX(Controller!$H$2:$H$11,INT((ROW()-2)/70)+1) -> Ref | B25: 2030 | C25: =INDEX(Controller!$J$2:$J$11,MOD(INT((ROW()-2)/7),10)+1) -> elc_transport | D25: =D24*2%+D24 -> 5.5235876 | E25: =A25&"|"&C25&"|"&B25 -> Ref|elc_transport|2030
A26: =INDEX(Controller!$H$2:$H$11,INT((ROW()-2)/70)+1) -> Ref | B26: 2035 | C26: =INDEX(Controller!$J$2:$J$11,MOD(INT((ROW()-2)/7),10)+1) -> elc_transport | D26: =D25*2%+D25 -> 5.6340594 | E26: =A26&"|"&C26&"|"&B26 -> Ref|elc_transport|2035
A27: =INDEX(Controller!$H$2:$H$11,INT((ROW()-2)/70)+1) -> Ref | B27: 2040 | C27: =INDEX(Controller!$J$2:$J$11,MOD(INT((ROW()-2)/7),10)+1) -> elc_transport | D27: =D26*2%+D26 -> 5.7467406 | E27: =A27&"|"&C27&"|"&B27 -> Ref|elc_transport|2040
A28: =INDEX(Controller!$H$2:$H$11,INT((ROW()-2)/70)+1) -> Ref | B28: 2045 | C28: =INDEX(Controller!$J$2:$J$11,MOD(INT((ROW()-2)/7),10)+1) -> elc_transport | D28: =D27*2%+D27 -> 5.8616754 | E28: =A28&"|"&C28&"|"&B28 -> Ref|elc_transport|2045
A29: =INDEX(Controller!$H$2:$H$11,INT((ROW()-2)/70)+1) -> Ref | B29: 2050 | C29: =INDEX(Controller!$J$2:$J$11,MOD(INT((ROW()-2)/7),10)+1) -> elc_transport | D29: =D28*2%+D28 -> 5.9789089 | E29: =A29&"|"&C29&"|"&B29 -> Ref|elc_transport|2050
A30: =INDEX(Controller!$H$2:$H$11,INT((ROW()-2)/70)+1) -> Ref | B30: 2022 | C30: =INDEX(Controller!$J$2:$J$11,MOD(INT((ROW()-2)/7),10)+1) -> elc_roadtransport | D30: 1.7697 | E30: =A30&"|"&C30&"|"&B30 -> Ref|elc_roadtransport|2022
A31: =INDEX(Controller!$H$2:$H$11,INT((ROW()-2)/70)+1) -> Ref | B31: 2025 | C31: =INDEX(Controller!$J$2:$J$11,MOD(INT((ROW()-2)/7),10)+1) -> elc_roadtransport | D31: =D30*2%+D30 -> 1.805094 | E31: =A31&"|"&C31&"|"&B31 -> Ref|elc_roadtransport|2025
A32: =INDEX(Controller!$H$2:$H$11,INT((ROW()-2)/70)+1) -> Ref | B32: 2030 | C32: =INDEX(Controller!$J$2:$J$11,MOD(INT((ROW()-2)/7),10)+1) -> elc_roadtransport | D32: =D31*2%+D31 -> 1.8411959 | E32: =A32&"|"&C32&"|"&B32 -> Ref|elc_roadtransport|2030
A33: =INDEX(Controller!$H$2:$H$11,INT((ROW()-2)/70)+1) -> Ref | B33: 2035 | C33: =INDEX(Controller!$J$2:$J$11,MOD(INT((ROW()-2)/7),10)+1) -> elc_roadtransport | D33: =D32*2%+D32 -> 1.8780198 | E33: =A33&"|"&C33&"|"&B33 -> Ref|elc_roadtransport|2035
A34: =INDEX(Controller!$H$2:$H$11,INT((ROW()-2)/70)+1) -> Ref | B34: 2040 | C34: =INDEX(Controller!$J$2:$J$11,MOD(INT((ROW()-2)/7),10)+1) -> elc_roadtransport | D34: =D33*2%+D33 -> 1.9155802 | E34: =A34&"|"&C34&"|"&B34 -> Ref|elc_roadtransport|2040
A35: =INDEX(Controller!$H$2:$H$11,INT((ROW()-2)/70)+1) -> Ref | B35: 2045 | C35: =INDEX(Controller!$J$2:$J$11,MOD(INT((ROW()-2)/7),10)+1) -> elc_roadtransport | D35: =D34*2%+D34 -> 1.9538918 | E35: =A35&"|"&C35&"|"&B35 -> Ref|elc_roadtransport|2045
A36: =INDEX(Controller!$H$2:$H$11,INT((ROW()-2)/70)+1) -> Ref | B36: 2050 | C36: =INDEX(Controller!$J$2:$J$11,MOD(INT((ROW()-2)/7),10)+1) -> elc_roadtransport | D36: =D35*2%+D35 -> 1.9929696 | E36: =A36&"|"&C36&"|"&B36 -> Ref|elc_roadtransport|2050
A37: =INDEX(Controller!$H$2:$H$11,INT((ROW()-2)/70)+1) -> Ref | B37: 2022 | C37: =INDEX(Controller!$J$2:$J$11,MOD(INT((ROW()-2)/7),10)+1) -> het_industry | D37: 9.769 | E37: =A37&"|"&C37&"|"&B37 -> Ref|het_industry|2022
A38: =INDEX(Controller!$H$2:$H$11,INT((ROW()-2)/70)+1) -> Ref | B38: 2025 | C38: =INDEX(Controller!$J$2:$J$11,MOD(INT((ROW()-2)/7),10)+1) -> het_industry | D38: =D37*2%+D37 -> 9.96438 | E38: =A38&"|"&C38&"|"&B38 -> Ref|het_industry|2025
A39: =INDEX(Controller!$H$2:$H$11,INT((ROW()-2)/70)+1) -> Ref | B39: 2030 | C39: =INDEX(Controller!$J$2:$J$11,MOD(INT((ROW()-2)/7),10)+1) -> het_industry | D39: =D38*2%+D38 -> 10.163668 | E39: =A39&"|"&C39&"|"&B39 -> Ref|het_industry|2030
A40: =INDEX(Controller!$H$2:$H$11,INT((ROW()-2)/70)+1) -> Ref | B40: 2035 | C40: =INDEX(Controller!$J$2:$J$11,MOD(INT((ROW()-2)/7),10)+1) -> het_industry | D40: =D39*2%+D39 -> 10.366941 | E40: =A40&"|"&C40&"|"&B40 -> Ref|het_industry|2035
...

Sheet Sheet4
A3: ~TFM_INS
A4: Attribute | B4: value | C4: pset_pn
A5: START | B5: 2100 | C5: *_ogc*
