Workbook

Sheet controller
G1: 1-8
D2: ="~Inputcell: "&_xlfn.TEXTJOIN(",",TRUE,B1:DZ1) -> ~Inputcell: 1-8
D3: 3
D5: =VLOOKUP(D3,$C$9:$E$16,2,FALSE) -> base | E5: =VLOOKUP(D3,$C$9:$E$16,3,FALSE) -> 200
B7: ~Scenmap
A8: priority | B8: scen | C8: case_no | D8: demand | E8: co2price
A9: 5 | B9: =_xlfn.TEXTJOIN(CHAR(183),TRUE,D9,TEXT(E9,"$000")) -> base·$000 | C9: 1 | D9: base | E9: 0
A10: 5 | B10: =_xlfn.TEXTJOIN(CHAR(183),TRUE,D10,TEXT(E10,"$000")) -> base·$100 | C10: =C9+1 -> 2 | D10: base | E10: 100
A11: 5 | B11: =_xlfn.TEXTJOIN(CHAR(183),TRUE,D11,TEXT(E11,"$000")) -> base·$200 | C11: =C10+1 -> 3 | D11: base | E11: 200
A12: 5 | B12: =_xlfn.TEXTJOIN(CHAR(183),TRUE,D12,TEXT(E12,"$000")) -> base·$300 | C12: =C11+1 -> 4 | D12: base | E12: 300
A13: 5 | B13: =_xlfn.TEXTJOIN(CHAR(183),TRUE,D13,TEXT(E13,"$000")) -> high·$000 | C13: =C12+1 -> 5 | D13: high | E13: =E9 -> 0
A14: 5 | B14: =_xlfn.TEXTJOIN(CHAR(183),TRUE,D14,TEXT(E14,"$000")) -> high·$100 | C14: =C13+1 -> 6 | D14: high | E14: =E10 -> 100
A15: 5 | B15: =_xlfn.TEXTJOIN(CHAR(183),TRUE,D15,TEXT(E15,"$000")) -> high·$200 | C15: =C14+1 -> 7 | D15: high | E15: =E11 -> 200
A16: 5 | B16: =_xlfn.TEXTJOIN(CHAR(183),TRUE,D16,TEXT(E16,"$000")) -> high·$300 | C16: =C15+1 -> 8 | D16: high | E16: =E12 -> 300
A17: 5

Sheet Veda
A1: POL
A2: R10EUROPE | F2: CO2 price | I2: demand
F3: 300 | G3: C2 | I3: base | J3: C4
F4: 200 | G4: C3 | I4: high | J4: C1
F5: 100 | G5: C4
F6: 0 | G6: C7
AH8: bio price multiplier
N9: IEA | AF9: C1 | AG9: e 1.5 deg no OS | AH9: 5
N10: 2022 | AF10: C2 | AG10: d 1.5 deg OS | AH10: 4
N11: =SUMIFS(iea_data!I3:I9999,iea_data!$B$3:$B$9999,$N$10,iea_data!$A$3:A$9999,$A$1)+O30-O31 -> 176.97 | O11: base-year generation (TWh) | AF11: C3 | AG11: c 2 deg (67%) | AH11: 3
N12: =SUMIFS(iea_data!L3:L9999,iea_data!$B$3:$B$9999,$N$10,iea_data!$A$3:A$9999,$A$1) -> 9.769 | AF12: C4 | AG12: b 2 deg (50%) | AH12: 3
N13: =SUMIFS(iea_data!M3:M9999,iea_data!$B$3:$B$9999,$N$10,iea_data!$A$3:A$9999,$A$1) -> 55.513 | AF13: C7 | AG13: a 3 deg | AH13: 1.5
B15: Electricity growth relative to 2020 | C15: =VLOOKUP(controller!$D$5,$I$3:$J$5,2,FALSE) -> C4 | D15: =SUMIFS(ar6_r10!$F$2:$F$99999,ar6_r10!$A$2:$A$99999,$C$15,ar6_r10!$C$2:$C$99999,D$18,ar6_r10!$M$2:$M$99999,$B15,ar6_r10!$B$2:$B$99999,$A$2) -> 1 | E15: =SUMIFS(ar6_r10!$F$2:$F$99999,ar6_r10!$A$2:$A$99999,$C$15,ar6_r10!$C$2:$C$99999,E$18,ar6_r10!$M$2:$M$99999,$B15,ar6_r10!$B$2:$B$99999,$A$2) -> 1.05 | F15: =SUMIFS(ar6_r10!$F$2:$F$99999,ar6_r10!$A$2:$A$99999,$C$15,ar6_r10!$C$2:$C$99999,F$18,ar6_r10!$M$2:$M$99999,$B15,ar6_r10!$B$2:$B$99999,$A$2) -> 1.17 | G15: =SUMIFS(ar6_r10!$F$2:$F$99999,ar6_r10!$A$2:$A$99999,$C$15,ar6_r10!$C$2:$C$99999,G$18,ar6_r10!$M$2:$M$99999,$B15,ar6_r10!$B$2:$B$99999,$A$2) -> 1.29 | H15: =SUMIFS(ar6_r10!$F$2:$F$99999,ar6_r10!$A$2:$A$99999,$C$15,ar6_r10!$C$2:$C$99999,H$18,ar6_r10!$M$2:$M$99999,$B15,ar6_r10!$B$2:$B$99999,$A$2) -> 1.42 | I15: =SUMIFS(ar6_r10!$F$2:$F$99999,ar6_r10!$A$2:$A$99999,$C$15,ar6_r10!$C$2:$C$99999,I$18,ar6_r10!$M$2:$M$99999,$B15,ar6_r10!$B$2:$B$99999,$A$2) -> 1.59 | J15: =SUMIFS(ar6_r10!$F$2:$F$99999,ar6_r10!$A$2:$A$99999,$C$15,ar6_r10!$C$2:$C$99999,J$18,ar6_r10!$M$2:$M$99999,$B15,ar6_r10!$B$2:$B$99999,$A$2) -> 1.73 | O15: =N11 -> 176.97 | P15: =$N$11*E15 -> 185.8185 | Q15: =$N$11*F15 -> 207.0549 | R15: =$N$11*G15 -> 228.2913 | S15: =$N$11*H15 -> 251.2974 | T15: =$N$11*I15 -> 281.3823 | U15: =$N$11*J15 -> 306.1581
B16: Heat growth relative to 2020 | D16: =SUMIFS(ar6_r10!$F$2:$F$99999,ar6_r10!$A$2:$A$99999,$C$15,ar6_r10!$C$2:$C$99999,D$18,ar6_r10!$M$2:$M$99999,$B16,ar6_r10!$B$2:$B$99999,$A$2) -> 1 | E16: =SUMIFS(ar6_r10!$F$2:$F$99999,ar6_r10!$A$2:$A$99999,$C$15,ar6_r10!$C$2:$C$99999,E$18,ar6_r10!$M$2:$M$99999,$B16,ar6_r10!$B$2:$B$99999,$A$2) -> 0.98 | F16: =SUMIFS(ar6_r10!$F$2:$F$99999,ar6_r10!$A$2:$A$99999,$C$15,ar6_r10!$C$2:$C$99999,F$18,ar6_r10!$M$2:$M$99999,$B16,ar6_r10!$B$2:$B$99999,$A$2) -> 0.96 | G16: =SUMIFS(ar6_r10!$F$2:$F$99999,ar6_r10!$A$2:$A$99999,$C$15,ar6_r10!$C$2:$C$99999,G$18,ar6_r10!$M$2:$M$99999,$B16,ar6_r10!$B$2:$B$99999,$A$2) -> 0.92 | H16: =SUMIFS(ar6_r10!$F$2:$F$99999,ar6_r10!$A$2:$A$99999,$C$15,ar6_r10!$C$2:$C$99999,H$18,ar6_r10!$M$2:$M$99999,$B16,ar6_r10!$B$2:$B$99999,$A$2) -> 0.84 | I16: =SUMIFS(ar6_r10!$F$2:$F$99999,ar6_r10!$A$2:$A$99999,$C$15,ar6_r10!$C$2:$C$99999,I$18,ar6_r10!$M$2:$M$99999,$B16,ar6_r10!$B$2:$B$99999,$A$2) -> 0.83 | J16: =SUMIFS(ar6_r10!$F$2:$F$99999,ar6_r10!$A$2:$A$99999,$C$15,ar6_r10!$C$2:$C$99999,J$18,ar6_r10!$M$2:$M$99999,$B16,ar6_r10!$B$2:$B$99999,$A$2) -> 0.8
N17: ="~TFM_INS-TS: region="&$A$1 -> ~TFM_INS-TS: region=POL
D18: 2020 | E18: =P18 -> 2025 | F18: =Q18 -> 2030 | G18: =R18 -> 2035 | H18: =S18 -> 2040 | I18: =T18 -> 2045 | J18: =U18 -> 2050 | N18: commodity | O18: 2022 | P18: 2025 | Q18: 2030 | R18: 2035 | S18: 2040 | T18: 2045 | U18: 2050 | V18: attribute
B19: Hydrogen as a share of electricity | D19: =SUMIFS(ar6_r10!$F$2:$F$99999,ar6_r10!$A$2:$A$99999,$C$15,ar6_r10!$C$2:$C$99999,D$18,ar6_r10!$M$2:$M$99999,$B19,ar6_r10!$B$2:$B$99999,$A$2) -> 0 | E19: =SUMIFS(ar6_r10!$F$2:$F$99999,ar6_r10!$A$2:$A$99999,$C$15,ar6_r10!$C$2:$C$99999,E$18,ar6_r10!$M$2:$M$99999,$B19,ar6_r10!$B$2:$B$99999,$A$2) -> 0 | F19: =SUMIFS(ar6_r10!$F$2:$F$99999,ar6_r10!$A$2:$A$99999,$C$15,ar6_r10!$C$2:$C$99999,F$18,ar6_r10!$M$2:$M$99999,$B19,ar6_r10!$B$2:$B$99999,$A$2) -> 0 | G19: =SUMIFS(ar6_r10!$F$2:$F$99999,ar6_r10!$A$2:$A$99999,$C$15,ar6_r10!$C$2:$C$99999,G$18,ar6_r10!$M$2:$M$99999,$B19,ar6_r10!$B$2:$B$99999,$A$2) -> 0 | H19: =SUMIFS(ar6_r10!$F$2:$F$99999,ar6_r10!$A$2:$A$99999,$C$15,ar6_r10!$C$2:$C$99999,H$18,ar6_r10!$M$2:$M$99999,$B19,ar6_r10!$B$2:$B$99999,$A$2) -> 0 | I19: =SUMIFS(ar6_r10!$F$2:$F$99999,ar6_r10!$A$2:$A$99999,$C$15,ar6_r10!$C$2:$C$99999,I$18,ar6_r10!$M$2:$M$99999,$B19,ar6_r10!$B$2:$B$99999,$A$2) -> 0 | J19: =SUMIFS(ar6_r10!$F$2:$F$99999,ar6_r10!$A$2:$A$99999,$C$15,ar6_r10!$C$2:$C$99999,J$18,ar6_r10!$M$2:$M$99999,$B19,ar6_r10!$B$2:$B$99999,$A$2) -> 0 | N19: hydrogen_allsect | O19: =D19*O$15 -> 0 | P19: =E19*P$15 -> 0 | Q19: =F19*Q$15 -> 0 | R19: =G19*R$15 -> 0 | S19: =H19*S$15 -> 0 | T19: =I19*T$15 -> 0 | U19: =J19*U$15 -> 0 | V19: demand
B20: Industry electricity share | D20: =SUMIFS(ar6_r10!$F$2:$F$99999,ar6_r10!$A$2:$A$99999,$C$15,ar6_r10!$C$2:$C$99999,D$18,ar6_r10!$M$2:$M$99999,$B20,ar6_r10!$B$2:$B$99999,$A$2) -> 0.37 | E20: =SUMIFS(ar6_r10!$F$2:$F$99999,ar6_r10!$A$2:$A$99999,$C$15,ar6_r10!$C$2:$C$99999,E$18,ar6_r10!$M$2:$M$99999,$B20,ar6_r10!$B$2:$B$99999,$A$2) -> 0.35 | F20: =SUMIFS(ar6_r10!$F$2:$F$99999,ar6_r10!$A$2:$A$99999,$C$15,ar6_r10!$C$2:$C$99999,F$18,ar6_r10!$M$2:$M$99999,$B20,ar6_r10!$B$2:$B$99999,$A$2) -> 0.34 | G20: =SUMIFS(ar6_r10!$F$2:$F$99999,ar6_r10!$A$2:$A$99999,$C$15,ar6_r10!$C$2:$C$99999,G$18,ar6_r10!$M$2:$M$99999,$B20,ar6_r10!$B$2:$B$99999,$A$2) -> 0.33 | H20: =SUMIFS(ar6_r10!$F$2:$F$99999,ar6_r10!$A$2:$A$99999,$C$15,ar6_r10!$C$2:$C$99999,H$18,ar6_r10!$M$2:$M$99999,$B20,ar6_r10!$B$2:$B$99999,$A$2) -> 0.3 | I20: =SUMIFS(ar6_r10!$F$2:$F$99999,ar6_r10!$A$2:$A$99999,$C$15,ar6_r10!$C$2:$C$99999,I$18,ar6_r10!$M$2:$M$99999,$B20,ar6_r10!$B$2:$B$99999,$A$2) -> 0.29 | J20: =SUMIFS(ar6_r10!$F$2:$F$99999,ar6_r10!$A$2:$A$99999,$C$15,ar6_r10!$C$2:$C$99999,J$18,ar6_r10!$M$2:$M$99999,$B20,ar6_r10!$B$2:$B$99999,$A$2) -> 0.3 | N20: elc_industry | O20: =D20*O$15 -> 65.4789 | P20: =E20*P$15 -> 65.036475 | Q20: =F20*Q$15 -> 70.398666 | R20: =G20*R$15 -> 75.336129 | S20: =H20*S$15 -> 75.38922 | T20: =I20*T$15 -> 81.600867 | U20: =J20*U$15 -> 91.84743 | V20: demand
B21: Residential and commercial electricity share | D21: =SUMIFS(ar6_r10!$F$2:$F$99999,ar6_r10!$A$2:$A$99999,$C$15,ar6_r10!$C$2:$C$99999,D$18,ar6_r10!$M$2:$M$99999,$B21,ar6_r10!$B$2:$B$99999,$A$2) -> 0.59 | E21: =SUMIFS(ar6_r10!$F$2:$F$99999,ar6_r10!$A$2:$A$99999,$C$15,ar6_r10!$C$2:$C$99999,E$18,ar6_r10!$M$2:$M$99999,$B21,ar6_r10!$B$2:$B$99999,$A$2) -> 0.59 | F21: =SUMIFS(ar6_r10!$F$2:$F$99999,ar6_r10!$A$2:$A$99999,$C$15,ar6_r10!$C$2:$C$99999,F$18,ar6_r10!$M$2:$M$99999,$B21,ar6_r10!$B$2:$B$99999,$A$2) -> 0.59 | G21: =SUMIFS(ar6_r10!$F$2:$F$99999,ar6_r10!$A$2:$A$99999,$C$15,ar6_r10!$C$2:$C$99999,G$18,ar6_r10!$M$2:$M$99999,$B21,ar6_r10!$B$2:$B$99999,$A$2) -> 0.58 | H21: =SUMIFS(ar6_r10!$F$2:$F$99999,ar6_r10!$A$2:$A$99999,$C$15,ar6_r10!$C$2:$C$99999,H$18,ar6_r10!$M$2:$M$99999,$B21,ar6_r10!$B$2:$B$99999,$A$2) -> 0.58 | I21: =SUMIFS(ar6_r10!$F$2:$F$99999,ar6_r10!$A$2:$A$99999,$C$15,ar6_r10!$C$2:$C$99999,I$18,ar6_r10!$M$2:$M$99999,$B21,ar6_r10!$B$2:$B$99999,$A$2) -> 0.56 | J21: =SUMIFS(ar6_r10!$F$2:$F$99999,ar6_r10!$A$2:$A$99999,$C$15,ar6_r10!$C$2:$C$99999,J$18,ar6_r10!$M$2:$M$99999,$B21,ar6_r10!$B$2:$B$99999,$A$2) -> 0.54 | N21: elc_buildings | O21: =D21*O$15 -> 104.4123 | P21: =E21*P$15 -> 109.63291 | Q21: =F21*Q$15 -> 122.16239 | R21: =G21*R$15 -> 132.40895 | S21: =H21*S$15 -> 145.75249 | T21: =I21*T$15 -> 157.57409 | U21: =J21*U$15 -> 165.32537 | V21: demand
B22: Transportation electricity share | D22: =SUMIFS(ar6_r10!$F$2:$F$99999,ar6_r10!$A$2:$A$99999,$C$15,ar6_r10!$C$2:$C$99999,D$18,ar6_r10!$M$2:$M$99999,$B22,ar6_r10!$B$2:$B$99999,$A$2) -> 0.03 | E22: =SUMIFS(ar6_r10!$F$2:$F$99999,ar6_r10!$A$2:$A$99999,$C$15,ar6_r10!$C$2:$C$99999,E$18,ar6_r10!$M$2:$M$99999,$B22,ar6_r10!$B$2:$B$99999,$A$2) -> 0.05 | F22: =SUMIFS(ar6_r10!$F$2:$F$99999,ar6_r10!$A$2:$A$99999,$C$15,ar6_r10!$C$2:$C$99999,F$18,ar6_r10!$M$2:$M$99999,$B22,ar6_r10!$B$2:$B$99999,$A$2) -> 0.04 | G22: =SUMIFS(ar6_r10!$F$2:$F$99999,ar6_r10!$A$2:$A$99999,$C$15,ar6_r10!$C$2:$C$99999,G$18,ar6_r10!$M$2:$M$99999,$B22,ar6_r10!$B$2:$B$99999,$A$2) -> 0.06 | H22: =SUMIFS(ar6_r10!$F$2:$F$99999,ar6_r10!$A$2:$A$99999,$C$15,ar6_r10!$C$2:$C$99999,H$18,ar6_r10!$M$2:$M$99999,$B22,ar6_r10!$B$2:$B$99999,$A$2) -> 0.07 | I22: =SUMIFS(ar6_r10!$F$2:$F$99999,ar6_r10!$A$2:$A$99999,$C$15,ar6_r10!$C$2:$C$99999,I$18,ar6_r10!$M$2:$M$99999,$B22,ar6_r10!$B$2:$B$99999,$A$2) -> 0.08 | J22: =SUMIFS(ar6_r10!$F$2:$F$99999,ar6_r10!$A$2:$A$99999,$C$15,ar6_r10!$C$2:$C$99999,J$18,ar6_r10!$M$2:$M$99999,$B22,ar6_r10!$B$2:$B$99999,$A$2) -> 0.08 | N22: elc_transport | O22: =D22*O$15 -> 5.3091 | P22: =O22 -> 5.3091 | Q22: =P22 -> 5.3091 | R22: =Q22 -> 5.3091 | S22: =R22 -> 5.3091 | T22: =S22 -> 5.3091 | U22: =T22 -> 5.3091 | V22: demand | X22: non-road transport demand assumed to be constant
N23: elc_roadtransport | O23: =O15-SUM(O20:O22) -> 1.7697 | P23: =P15-SUM(P20:P22) -> 5.84001 | Q23: =Q15-SUM(Q20:Q22) -> 9.184743 | R23: =R15-SUM(R20:R22) -> 15.237117 | S23: =S15-SUM(S20:S22) -> 24.846588 | T23: =T15-SUM(T20:T22) -> 36.898245 | U23: =U15-SUM(U20:U22) -> 43.676196 | V23: demand
N24: het_industry | O24: =N12 -> 9.769 | P24: =$N$12*E16 -> 9.57362 | Q24: =$N$12*F16 -> 9.37824 | R24: =$N$12*G16 -> 8.98748 | S24: =$N$12*H16 -> 8.20596 | T24: =$N$12*I16 -> 8.10827 | U24: =$N$12*J16 -> 7.8152 | V24: demand
N25: het_buildings | O25: =N13 -> 55.513 | P25: =$N$13*E16 -> 54.40274 | Q25: =$N$13*F16 -> 53.29248 | R25: =$N$13*G16 -> 51.07196 | S25: =$N$13*H16 -> 46.63092 | T25: =$N$13*I16 -> 46.07579 | U25: =$N$13*J16 -> 44.4104 | V25: demand
B26: CO2 price | C26: =VLOOKUP(controller!E5,$F$3:$G$6,2,FALSE) -> C3 | D26: 0 | E26: 0 | F26: =SUMIFS(ar6_r10!$F$2:$F$99999,ar6_r10!$A$2:$A$99999,$C$26,ar6_r10!$C$2:$C$99999,F$18,ar6_r10!$M$2:$M$99999,$B26,ar6_r10!$B$2:$B$99999,$A$2) -> 71.48 | G26: =SUMIFS(ar6_r10!$F$2:$F$99999,ar6_r10!$A$2:$A$99999,$C$26,ar6_r10!$C$2:$C$99999,G$18,ar6_r10!$M$2:$M$99999,$B26,ar6_r10!$B$2:$B$99999,$A$2) -> 104.42 | H26: =SUMIFS(ar6_r10!$F$2:$F$99999,ar6_r10!$A$2:$A$99999,$C$26,ar6_r10!$C$2:$C$99999,H$18,ar6_r10!$M$2:$M$99999,$B26,ar6_r10!$B$2:$B$99999,$A$2) -> 134.85 | I26: =SUMIFS(ar6_r10!$F$2:$F$99999,ar6_r10!$A$2:$A$99999,$C$26,ar6_r10!$C$2:$C$99999,I$18,ar6_r10!$M$2:$M$99999,$B26,ar6_r10!$B$2:$B$99999,$A$2) -> 178.1 | J26: =SUMIFS(ar6_r10!$F$2:$F$99999,ar6_r10!$A$2:$A$99999,$C$26,ar6_r10!$C$2:$C$99999,J$18,ar6_r10!$M$2:$M$99999,$B26,ar6_r10!$B$2:$B$99999,$A$2) -> 209.45 | N26: co2net | P26: 0 | Q26: =F26/1000 -> 0.07148 | R26: =G26/1000 -> 0.10442 | S26: =H26/1000 -> 0.13485 | T26: =I26/1000 -> 0.1781 | U26: =J26/1000 -> 0.20945 | V26: com_taxnet
N28: ="~TFM_INS-TS: region="&$A$1 -> ~TFM_INS-TS: region=POL
N29: process | O29: =O18 -> 2022 | P29: =P18 -> 2025 | Q29: =Q18 -> 2030 | R29: =R18 -> 2035 | S29: =S18 -> 2040 | T29: =T18 -> 2045 | U29: =U18 -> 2050 | V29: attribute | W29: limtype
L30: =SUMIFS(iea_data!G3:G9999,iea_data!$B$3:$B$9999,$N$10,iea_data!$A$3:A$9999,$A$1) -> 15.24 | N30: Trd_electricity import | O30: =L30 -> 15.24 | V30: ACT_BND | W30: FX
L31: =SUMIFS(iea_data!H3:H9999,iea_data!$B$3:$B$9999,$N$10,iea_data!$A$3:A$9999,$A$1) -> 16.91 | N31: Trd_electricity export | O31: =ABS(L31) -> 16.91 | V31: ACT_BND | W31: FX
B38: C7
B39: Gas Price | D39: =SUMIFS(ar6_r10!$F$2:$F$99999,ar6_r10!$A$2:$A$99999,$B$38,ar6_r10!$C$2:$C$99999,D$18,ar6_r10!$M$2:$M$99999,$B39,ar6_r10!$B$2:$B$99999,$A$2) -> 1 | E39: =SUMIFS(ar6_r10!$F$2:$F$99999,ar6_r10!$A$2:$A$99999,$B$38,ar6_r10!$C$2:$C$99999,E$18,ar6_r10!$M$2:$M$99999,$B39,ar6_r10!$B$2:$B$99999,$A$2) -> 1.07 | F39: =SUMIFS(ar6_r10!$F$2:$F$99999,ar6_r10!$A$2:$A$99999,$B$38,ar6_r10!$C$2:$C$99999,F$18,ar6_r10!$M$2:$M$99999,$B39,ar6_r10!$B$2:$B$99999,$A$2) -> 1.24 | G39: =SUMIFS(ar6_r10!$F$2:$F$99999,ar6_r10!$A$2:$A$99999,$B$38,ar6_r10!$C$2:$C$99999,G$18,ar6_r10!$M$2:$M$99999,$B39,ar6_r10!$B$2:$B$99999,$A$2) -> 1.15 | H39: =SUMIFS(ar6_r10!$F$2:$F$99999,ar6_r10!$A$2:$A$99999,$B$38,ar6_r10!$C$2:$C$99999,H$18,ar6_r10!$M$2:$M$99999,$B39,ar6_r10!$B$2:$B$99999,$A$2) -> 1.25 | I39: =SUMIFS(ar6_r10!$F$2:$F$99999,ar6_r10!$A$2:$A$99999,$B$38,ar6_r10!$C$2:$C$99999,I$18,ar6_r10!$M$2:$M$99999,$B39,ar6_r10!$B$2:$B$99999,$A$2) -> 1.17 | J39: =SUMIFS(ar6_r10!$F$2:$F$99999,ar6_r10!$A$2:$A$99999,$B$38,ar6_r10!$C$2:$C$99999,J$18,ar6_r10!$M$2:$M$99999,$B39,ar6_r10!$B$2:$B$99999,$A$2) -> 1.34
B40: Coal Price | D40: =SUMIFS(ar6_r10!$F$2:$F$99999,ar6_r10!$A$2:$A$99999,$B$38,ar6_r10!$C$2:$C$99999,D$18,ar6_r10!$M$2:$M$99999,$B40,ar6_r10!$B$2:$B$99999,$A$2) -> 1 | E40: =SUMIFS(ar6_r10!$F$2:$F$99999,ar6_r10!$A$2:$A$99999,$B$38,ar6_r10!$C$2:$C$99999,E$18,ar6_r10!$M$2:$M$99999,$B40,ar6_r10!$B$2:$B$99999,$A$2) -> 1.02 | F40: =SUMIFS(ar6_r10!$F$2:$F$99999,ar6_r10!$A$2:$A$99999,$B$38,ar6_r10!$C$2:$C$99999,F$18,ar6_r10!$M$2:$M$99999,$B40,ar6_r10!$B$2:$B$99999,$A$2) -> 1.06 | G40: =SUMIFS(ar6_r10!$F$2:$F$99999,ar6_r10!$A$2:$A$99999,$B$38,ar6_r10!$C$2:$C$99999,G$18,ar6_r10!$M$2:$M$99999,$B40,ar6_r10!$B$2:$B$99999,$A$2) -> 1.07 | H40: =SUMIFS(ar6_r10!$F$2:$F$99999,ar6_r10!$A$2:$A$99999,$B$38,ar6_r10!$C$2:$C$99999,H$18,ar6_r10!$M$2:$M$99999,$B40,ar6_r10!$B$2:$B$99999,$A$2) -> 1.08 | I40: =SUMIFS(ar6_r10!$F$2:$F$99999,ar6_r10!$A$2:$A$99999,$B$38,ar6_r10!$C$2:$C$99999,I$18,ar6_r10!$M$2:$M$99999,$B40,ar6_r10!$B$2:$B$99999,$A$2) -> 1.1 | J40: =SUMIFS(ar6_r10!$F$2:$F$99999,ar6_r10!$A$2:$A$99999,$B$38,ar6_r10!$C$2:$C$99999,J$18,ar6_r10!$M$2:$M$99999,$B40,ar6_r10!$B$2:$B$99999,$A$2) -> 1.12
B41: Oil Price | D41: =SUMIFS(ar6_r10!$F$2:$F$99999,ar6_r10!$A$2:$A$99999,$B$38,ar6_r10!$C$2:$C$99999,D$18,ar6_r10!$M$2:$M$99999,$B41,ar6_r10!$B$2:$B$99999,$A$2) -> 1 | E41: =SUMIFS(ar6_r10!$F$2:$F$99999,ar6_r10!$A$2:$A$99999,$B$38,ar6_r10!$C$2:$C$99999,E$18,ar6_r10!$M$2:$M$99999,$B41,ar6_r10!$B$2:$B$99999,$A$2) -> 1.01 | F41: =SUMIFS(ar6_r10!$F$2:$F$99999,ar6_r10!$A$2:$A$99999,$B$38,ar6_r10!$C$2:$C$99999,F$18,ar6_r10!$M$2:$M$99999,$B41,ar6_r10!$B$2:$B$99999,$A$2) -> 1.11 | G41: =SUMIFS(ar6_r10!$F$2:$F$99999,ar6_r10!$A$2:$A$99999,$B$38,ar6_r10!$C$2:$C$99999,G$18,ar6_r10!$M$2:$M$99999,$B41,ar6_r10!$B$2:$B$99999,$A$2) -> 1.01 | H41: =SUMIFS(ar6_r10!$F$2:$F$99999,ar6_r10!$A$2:$A$99999,$B$38,ar6_r10!$C$2:$C$99999,H$18,ar6_r10!$M$2:$M$99999,$B41,ar6_r10!$B$2:$B$99999,$A$2) -> 1.01 | I41: =SUMIFS(ar6_r10!$F$2:$F$99999,ar6_r10!$A$2:$A$99999,$B$38,ar6_r10!$C$2:$C$99999,I$18,ar6_r10!$M$2:$M$99999,$B41,ar6_r10!$B$2:$B$99999,$A$2) -> 1.04 | J41: =SUMIFS(ar6_r10!$F$2:$F$99999,ar6_r10!$A$2:$A$99999,$B$38,ar6_r10!$C$2:$C$99999,J$18,ar6_r10!$M$2:$M$99999,$B41,ar6_r10!$B$2:$B$99999,$A$2) -> 1.14
B42: Biomass Price | D42: =SUMIFS(ar6_r10!$F$2:$F$99999,ar6_r10!$A$2:$A$99999,$B$38,ar6_r10!$C$2:$C$99999,D$18,ar6_r10!$M$2:$M$99999,$B42,ar6_r10!$B$2:$B$99999,$A$2) -> 1 | E42: =SUMIFS(ar6_r10!$F$2:$F$99999,ar6_r10!$A$2:$A$99999,$B$38,ar6_r10!$C$2:$C$99999,E$18,ar6_r10!$M$2:$M$99999,$B42,ar6_r10!$B$2:$B$99999,$A$2) -> 0.96 | F42: =SUMIFS(ar6_r10!$F$2:$F$99999,ar6_r10!$A$2:$A$99999,$B$38,ar6_r10!$C$2:$C$99999,F$18,ar6_r10!$M$2:$M$99999,$B42,ar6_r10!$B$2:$B$99999,$A$2) -> 1.04 | G42: =SUMIFS(ar6_r10!$F$2:$F$99999,ar6_r10!$A$2:$A$99999,$B$38,ar6_r10!$C$2:$C$99999,G$18,ar6_r10!$M$2:$M$99999,$B42,ar6_r10!$B$2:$B$99999,$A$2) -> 1.04 | H42: =SUMIFS(ar6_r10!$F$2:$F$99999,ar6_r10!$A$2:$A$99999,$B$38,ar6_r10!$C$2:$C$99999,H$18,ar6_r10!$M$2:$M$99999,$B42,ar6_r10!$B$2:$B$99999,$A$2) -> 0.98 | I42: =SUMIFS(ar6_r10!$F$2:$F$99999,ar6_r10!$A$2:$A$99999,$B$38,ar6_r10!$C$2:$C$99999,I$18,ar6_r10!$M$2:$M$99999,$B42,ar6_r10!$B$2:$B$99999,$A$2) -> 0.99 | J42: =SUMIFS(ar6_r10!$F$2:$F$99999,ar6_r10!$A$2:$A$99999,$B$38,ar6_r10!$C$2:$C$99999,J$18,ar6_r10!$M$2:$M$99999,$B42,ar6_r10!$B$2:$B$99999,$A$2) -> 1
B45: ="~TFM_INS-TS: region="&$A$1&"; attribute=flo_cost;pset_pn=-IMP*Z" -> ~TFM_INS-TS: region=POL; attribute=flo_cost;pset_pn=-IMP*Z
B46: commodity | C46: pset_co | D46: 2022 | E46: =E18 -> 2025 | F46: =F18 -> 2030 | G46: =G18 -> 2035 | H46: =H18 -> 2040 | I46: =I18 -> 2045 | J46: =J18 -> 2050 | M46: low | N46: high
B47: Gas | C47: =B47 -> Gas | D47: =AVERAGE($M47:$N47)*D39 -> 33.4 | E47: =AVERAGE($M47:$N47)*E39 -> 35.738 | F47: =AVERAGE($M47:$N47)*F39 -> 41.416 | G47: =AVERAGE($M47:$N47)*G39 -> 38.41 | H47: =AVERAGE($M47:$N47)*H39 -> 41.75 | I47: =AVERAGE($M47:$N47)*I39 -> 39.078 | J47: =AVERAGE($M47:$N47)*J39 -> 44.756 | M47: =HLOOKUP($B47&"_"&M$46,fuel_prices!$B$10:$I$100,MATCH($A$1,fuel_prices!$A$10:$A$100,0),FALSE) -> 27.4 | N47: =HLOOKUP($B47&"_"&N$46,fuel_prices!$B$10:$I$100,MATCH($A$1,fuel_prices!$A$10:$A$100,0),FALSE) -> 39.4
B48: Coal | C48: =B48 -> Coal | D48: =AVERAGE($M48:$N48)*D40 -> 12.2 | E48: =AVERAGE($M48:$N48)*E40 -> 12.444 | F48: =AVERAGE($M48:$N48)*F40 -> 12.932 | G48: =AVERAGE($M48:$N48)*G40 -> 13.054 | H48: =AVERAGE($M48:$N48)*H40 -> 13.176 | I48: =AVERAGE($M48:$N48)*I40 -> 13.42 | J48: =AVERAGE($M48:$N48)*J40 -> 13.664 | M48: =HLOOKUP($B48&"_"&M$46,fuel_prices!$B$10:$I$100,MATCH($A$1,fuel_prices!$A$10:$A$100,0),FALSE) -> 10.7 | N48: =HLOOKUP($B48&"_"&N$46,fuel_prices!$B$10:$I$100,MATCH($A$1,fuel_prices!$A$10:$A$100,0),FALSE) -> 13.7
B49: Oil | C49: =B49 -> Oil | D49: =AVERAGE($M49:$N49)*D41 -> 53 | E49: =AVERAGE($M49:$N49)*E41 -> 53.53 | F49: =AVERAGE($M49:$N49)*F41 -> 58.83 | G49: =AVERAGE($M49:$N49)*G41 -> 53.53 | H49: =AVERAGE($M49:$N49)*H41 -> 53.53 | I49: =AVERAGE($M49:$N49)*I41 -> 55.12 | J49: =AVERAGE($M49:$N49)*J41 -> 60.42 | M49: =HLOOKUP($B49&"_"&M$46,fuel_prices!$B$10:$I$100,MATCH($A$1,fuel_prices!$A$10:$A$100,0),FALSE) -> 48 | N49: =HLOOKUP($B49&"_"&N$46,fuel_prices!$B$10:$I$100,MATCH($A$1,fuel_prices!$A$10:$A$100,0),FALSE) -> 58
B50: Bioenergy | C50: =B50 -> Bioenergy | D50: =AVERAGE($M50:$N50)*D42 -> 26 | J50: =VLOOKUP($C$15,$AF$9:$AH$16,3,FALSE)*D50 -> 78 | M50: =HLOOKUP($B50&"_"&M$46,fuel_prices!$B$10:$I$100,MATCH($A$1,fuel_prices!$A$10:$A$100,0),FALSE) -> 22 | N50: =HLOOKUP($B50&"_"&N$46,fuel_prices!$B$10:$I$100,MATCH($A$1,fuel_prices!$A$10:$A$100,0),FALSE) -> 30
A54: ~tfm_ins-ts: region=POL
...

Sheet fuel_prices
A9: Fuel Prices
A10: iso | B10: gas_low | C10: gas_high | D10: coal_low | E10: coal_high | F10: oil_low | G10: oil_high | H10: bioenergy_low | I10: bioenergy_high | J10: Notes
A11: POL | B11: 27.4 | C11: 39.4 | D11: 10.7 | E11: 13.7 | F11: 48 | G11: 58 | H11: 22 | I11: 30 | J11: Pipeline gas, coal & forest resources

Sheet iea_data
A9: IEA Baseline Data
A10: iso | B10: year | C10: industry_twh | D10: buildings_agri_twh | E10: nonroad_transport_twh | F10: road_transport_twh | G10: imports_twh | H10: exports_twh | I10: total_production_twh | J10: chp_heat_twh | K10: heat_tfc_twh | L10: heat_industry_twh | M10: heat_buildings_twh
A11: POL | B11: 2015 | C11: 58.76 | D11: 75.23 | E11: 3.09 | F11: 0.02 | G11: 14.46 | H11: 14.79 | I11: 164.23 | J11: 51.51 | K11: 63.417 | L11: 7.577 | M11: 55.84
A12: POL | B12: 2016 | C12: 61.61 | D12: 78.34 | E12: 3.26 | F12: 0.02 | G12: 14.02 | H12: 12.02 | I12: 166.1 | J12: 52.508 | K12: 65.776 | L12: 7.808 | M12: 57.968
A13: POL | B13: 2017 | C13: 66.4 | D13: 77.92 | E13: 3.3 | F13: 0.03 | G13: 13.27 | H13: 10.98 | I13: 169.94 | J13: 54.638 | K13: 67.507 | L13: 8.249 | M13: 59.258
A14: POL | B14: 2018 | C14: 71.21 | D14: 80.58 | E14: 3.44 | F14: 0.03 | G14: 13.82 | H14: 8.12 | I14: 169.56 | J14: 53.701 | K14: 65.034 | L14: 9.587 | M14: 55.447
A15: POL | B15: 2019 | C15: 73.83 | D15: 80.32 | E15: 3.38 | F15: 0.03 | G15: 17.87 | H15: 7.25 | I15: 163.22 | J15: 52.757 | K15: 64.43 | L15: 9.652 | M15: 54.778
A16: POL | B16: 2020 | C16: 73.01 | D16: 79.84 | E16: 3.1 | F16: 0.07 | G16: 20.62 | H16: 7.36 | I16: 157.13 | J16: 51.827 | K16: 65.027 | L16: 9.819 | M16: 55.208
A17: POL | B17: 2021 | C17: 75.22 | D17: 83.99 | E17: 3.33 | F17: 0.06 | G17: 15.1 | H17: 14.21 | I17: 178.79 | J17: 54.496 | K17: 69.338 | L17: 10.542 | M17: 58.796
A18: POL | B18: 2022 | C18: 75.18 | D18: 83.17 | E18: 3.34 | F18: 0.17 | G18: 15.24 | H18: 16.91 | I18: 178.64 | J18: 50.324 | K18: 65.282 | L18: 9.769 | M18: 55.513
A19: POL | B19: 2023 | C19: 76.92 | D19: 79.83 | E19: 3.5 | F19: 0.23 | G19: 15.14 | H19: 11.4 | I19: 165.99 | J19: 49.043 | K19: 60.381 | L19: 8.346 | M19: 52.035
A20: POL | B20: 2024 | C20: 84.11 | D20: 82.19 | E20: 3.57 | F20: 0.37 | G20: 15.21 | H20: 13.25 | I20: 171.32 | J20: 47.503 | K20: 57.614 | L20: 8.082 | M20: 49.532

Sheet ar6_r10
A9: AR6 Scenario Drivers
A10: Category | B10: Region | C10: Year | D10: count | E10: mean | F10: median | G10: std | H10: min | I10: max | J10: q25 | K10: q75 | L10: category_description | M10: attribute
A11: C1 | B11: R10EUROPE | C11: 2020 | D11: 60 | E11: 8.68 | F11: 6.87 | G11: 10.43 | H11: 0 | I11: 55.17 | J11: 0 | K11: 13.64 | L11: Limit warming to 1.5°C (>50%) with no or limited overshoot | M11: CO2 price
A12: C1 | B12: R10EUROPE | C12: 2025 | D12: 60 | E12: 190.52 | F12: 181.51 | G12: 136.23 | H12: 1.81 | I12: 626.48 | J12: 115.48 | K12: 238.58 | L12: Limit warming to 1.5°C (>50%) with no or limited overshoot | M12: CO2 price
A13: C1 | B13: R10EUROPE | C13: 2030 | D13: 60 | E13: 268.18 | F13: 241.69 | G13: 134.29 | H13: 1.27 | I13: 673.46 | J13: 182.47 | K13: 329.7 | L13: Limit warming to 1.5°C (>50%) with no or limited overshoot | M13: CO2 price
A14: C1 | B14: R10EUROPE | C14: 2035 | D14: 60 | E14: 363.27 | F14: 339.03 | G14: 173.79 | H14: 14.37 | I14: 859.53 | J14: 227.05 | K14: 483.38 | L14: Limit warming to 1.5°C (>50%) with no or limited overshoot | M14: CO2 price
A15: C1 | B15: R10EUROPE | C15: 2040 | D15: 60 | E15: 471.65 | F15: 410.28 | G15: 224.31 | H15: 162.1 | I15: 1097.01 | J15: 298.63 | K15: 622.14 | L15: Limit warming to 1.5°C (>50%) with no or limited overshoot | M15: CO2 price
A16: C1 | B16: R10EUROPE | C16: 2045 | D16: 60 | E16: 565.69 | F16: 494.2 | G16: 256.15 | H16: 193.42 | I16: 1269.88 | J16: 352.78 | K16: 748.01 | L16: Limit warming to 1.5°C (>50%) with no or limited overshoot | M16: CO2 price
A17: C1 | B17: R10EUROPE | C17: 2050 | D17: 60 | E17: 647.44 | F17: 635.43 | G17: 273.56 | H17: 209.76 | I17: 1170.26 | J17: 409.79 | K17: 887.68 | L17: Limit warming to 1.5°C (>50%) with no or limited overshoot | M17: CO2 price
A18: C2 | B18: R10EUROPE | C18: 2020 | D18: 86 | E18: 6.44 | F18: 0 | G18: 8.34 | H18: 0 | I18: 24.5 | J18: 0 | K18: 12.68 | L18: Limit warming to 1.5°C (>67%) with high overshoot | M18: CO2 price
A19: C2 | B19: R10EUROPE | C19: 2025 | D19: 75 | E19: 63.21 | F19: 44.89 | G19: 56.62 | H19: 3.21 | I19: 273 | J19: 27.09 | K19: 77.31 | L19: Limit warming to 1.5°C (>67%) with high overshoot | M19: CO2 price
A20: C2 | B20: R10EUROPE | C20: 2030 | D20: 86 | E20: 85.48 | F20: 63.36 | G20: 73.46 | H20: 0 | I20: 409.5 | J20: 50 | K20: 111.1 | L20: Limit warming to 1.5°C (>67%) with high overshoot | M20: CO2 price
A21: C2 | B21: R10EUROPE | C21: 2035 | D21: 75 | E21: 208.71 | F21: 154.82 | G21: 291.78 | H21: 60.83 | I21: 2037.12 | J21: 93.79 | K21: 206.26 | L21: Limit warming to 1.5°C (>67%) with high overshoot | M21: CO2 price
A22: C2 | B22: R10EUROPE | C22: 2040 | D22: 86 | E22: 253.33 | F22: 172.09 | G22: 359.35 | H22: 0 | I22: 2600 | J22: 119.07 | K22: 259.4 | L22: Limit warming to 1.5°C (>67%) with high overshoot | M22: CO2 price
... A256: C1 | B256: R10EUROPE | C256: 2020 | D256: 33 | E256: 1 | F256: 1 | G256: 0 | H256: 1 | I256: 1 | J256: 1 | K256: 1 | L256: Limit warming to 1.5°C (>50%) with no or limited overshoot | M256: Gas price
A257: C1 | B257: R10EUROPE | C257: 2025 | D257: 34 | E257: #NUM! | F257: 2.42 | H257: 1.18 | I257: #NUM! | J257: 2.01 | K257: 2.75 | L257: Limit warming to 1.5°C (>50%) with no or limited overshoot | M257: Gas price
A258: C1 | B258: R10EUROPE | C258: 2030 | D258: 34 | E258: #NUM! | F258: 3.1 | H258: 1.71 | I258: #NUM! | J258: 2.38 | K258: 3.46 | L258: Limit warming to 1.5°C (>50%) with no or limited overshoot | M258: Gas price
A259: C1 | B259: R10EUROPE | C259: 2035 | D259: 34 | E259: #NUM! | F259: 3.54 | H259: 1.91 | I259: #NUM! | J259: 2.66 | K259: 4.16 | L259: Limit warming to 1.5°C (>50%) with no or limited overshoot | M259: Gas price
A260: C1 | B260: R10EUROPE | C260: 2040 | D260: 34 | E260: #NUM! | F260: 4.1 | H260: 2.27 | I260: #NUM! | J260: 2.96 | K260: 4.52 | L260: Limit warming to 1.5°C (>50%) with no or limited overshoot | M260: Gas price
A261: C1 | B261: R10EUROPE | C261: 2045 | D261: 34 | E261: #NUM! | F261: 3.86 | H261: 2.54 | I261: #NUM! | J261: 3.3 | K261: 4.89 | L261: Limit warming to 1.5°C (>50%) with no or limited overshoot | M261: Gas price
A262: C1 | B262: R10EUROPE | C262: 2050 | D262: 34 | E262: #NUM! | F262: 3.59 | H262: 2.73 | I262: #NUM! | J262: 3.07 | K262: 4.06 | L262: Limit warming to 1.5°C (>50%) with no or limited overshoot | M262: Gas price
A263: C2 | B263: R10EUROPE | C263: 2020 | D263: 43 | E263: 1 | F263: 1 | G263: 0 | H263: 1 | I263: 1 | J263: 1 | K263: 1 | L263: Limit warming to 1.5°C (>67%) with high overshoot | M263: Gas price
A264: C2 | B264: R10EUROPE | C264: 2025 | D264: 44 | E264: #NUM! | F264: 1.22 | H264: 0 | I264: #NUM! | J264: 1.13 | K264: 1.35 | L264: Limit warming to 1.5°C (>67%) with high overshoot | M264: Gas price
A265: C2 | B265: R10EUROPE | C265: 2030 | D265: 44 | E265: #NUM! | F265: 1.5 | H265: 0 | I265: #NUM! | J265: 1.31 | K265: 1.83 | L265: Limit warming to 1.5°C (>67%) with high overshoot | M265: Gas price
A266: C2 | B266: R10EUROPE | C266: 2035 | D266: 44 | E266: #NUM! | F266: 2.12 | H266: 0 | I266: #NUM! | J266: 1.68 | K266: 2.46 | L266: Limit warming to 1.5°C (>67%) with high overshoot | M266: Gas price
A267: C2 | B267: R10EUROPE | C267: 2040 | D267: 44 | E267: #NUM! | F267: 2.5 | H267: 0 | I267: #NUM! | J267: 2 | K267: 2.94 | L267: Limit warming to 1.5°C (>67%) with high overshoot | M267: Gas price
A268: C2 | B268: R10EUROPE | C268: 2045 | D268: 44 | E268: #NUM! | F268: 2.79 | H268: 0 | I268: #NUM! | J268: 2.08 | K268: 3.44 | L268: Limit warming to 1.5°C (>67%) with high overshoot | M268: Gas price
A269: C2 | B269: R10EUROPE | C269: 2050 | D269: 44 | E269: #NUM! | F269: 2.95 | H269: 0 | I269: #NUM! | J269: 2.49 | K269: 3.78 | L269: Limit warming to 1.5°C (>67%) with high overshoot | M269: Gas price
A270: C3 | B270: R10EUROPE | C270: 2020 | D270: 103 | E270: 1 | F270: 1 | G270: 0 | H270: 1 | I270: 1 | J270: 1 | K270: 1 | L270: Limit warming to 2°C (>67%) with higher action post-2030 | M270: Gas price
A271: C3 | B271: R10EUROPE | C271: 2025 | D271: 112 | E271: #NUM! | F271: 1.41 | H271: 0.98 | I271: #NUM! | J271: 1.23 | K271: 1.96 | L271: Limit warming to 2°C (>67%) with higher action post-2030 | M271: Gas price
A272: C3 | B272: R10EUROPE | C272: 2030 | D272: 112 | E272: #NUM! | F272: 2.04 | H272: 1.05 | I272: #NUM! | J272: 1.52 | K272: 2.55 | L272: Limit warming to 2°C (>67%) with higher action post-2030 | M272: Gas price
A273: C3 | B273: R10EUROPE | C273: 2035 | D273: 112 | E273: #NUM! | F273: 2.4 | H273: 1.05 | I273: #NUM! | J273: 1.71 | K273: 3.14 | L273: Limit warming to 2°C (>67%) with higher action post-2030 | M273: Gas price
A274: C3 | B274: R10EUROPE | C274: 2040 | D274: 112 | E274: #NUM! | F274: 2.6 | H274: 1.06 | I274: #NUM! | J274: 1.85 | K274: 3.74 | L274: Limit warming to 2°C (>67%) with higher action post-2030 | M274: Gas price
A275: C3 | B275: R10EUROPE | C275: 2045 | D275: 112 | E275: #NUM! | F275: 2.85 | H275: 1.08 | I275: #NUM! | J275: 2 | K275: 4.28 | L275: Limit warming to 2°C (>67%) with higher action post-2030 | M275: Gas price
A276: C3 | B276: R10EUROPE | C276: 2050 | D276: 112 | E276: #NUM! | F276: 2.97 | H276: 0 | I276: #NUM! | J276: 2.15 | K276: 4.51 | L276: Limit warming to 2°C (>67%) with higher action post-2030 | M276: Gas price
A277: C4 | B277: R10EUROPE | C277: 2020 | D277: 27 | E277: 1 | F277: 1 | G277: 0 | H277: 1 | I277: 1 | J277: 1 | K277: 1 | L277: Limit warming to 2°C (>50%) with immediate action | M277: Gas price
A278: C4 | B278: R10EUROPE | C278: 2025 | D278: 27 | E278: 1.33 | F278: 1.31 | G278: 0.18 | H278: 1.06 | I278: 1.66 | J278: 1.22 | K278: 1.45 | L278: Limit warming to 2°C (>50%) with immediate action | M278: Gas price
A279: C4 | B279: R10EUROPE | C279: 2030 | D279: 27 | E279: 1.84 | F279: 2.02 | G279: 0.28 | H279: 1.24 | I279: 2.17 | J279: 1.52 | K279: 2.07 | L279: Limit warming to 2°C (>50%) with immediate action | M279: Gas price
A280: C4 | B280: R10EUROPE | C280: 2035 | D280: 27 | E280: 1.84 | F280: 1.96 | G280: 0.41 | H280: 1.19 | I280: 2.46 | J280: 1.42 | K280: 2.11 | L280: Limit warming to 2°C (>50%) with immediate action | M280: Gas price
A281: C4 | B281: R10EUROPE | C281: 2040 | D281: 27 | E281: 2.12 | F281: 2.22 | G281: 0.47 | H281: 1.41 | I281: 2.78 | J281: 1.54 | K281: 2.43 | L281: Limit warming to 2°C (>50%) with immediate action | M281: Gas price
...
