Workbook

Sheet controller
G1: 1-8
D2: ="~Inputcell: "&_xlfn.TEXTJOIN(",",TRUE,B1:DZ1) -> ~Inputcell: 1-8
D3: 3
D5: =VLOOKUP(D3,$C$9:$E$16,2,FALSE) -> base | E5: =VLOOKUP(D3,$C$9:$E$16,3,FALSE) -> 200
B7: ~Scenmap
A8: priority | B8: scen | C8: case_no | D8: demand | E8: co2price
A9: 5 | B9: =_xlfn.TEXTJOIN(CHAR(183),TRUE,D9,TEXT(E9,"$000")) -> base·$000 | C9: 1 | D9: base | E9: 0
A10: 5 | B10: =_xlfn.TEXTJOIN(CHAR(183),TRUE,D10,TEXT(E10,"$000")) -> base·$100 | C10: =C9+1 -> 2 | D10: base | E10: 100
A11: 5 | B11: =_xlfn.TEXTJOIN(CHAR(183),TRUE,D11,TEXT(E11,"$000")) -> base·$200 | C11: =C10+1 -> 3 | D11: base | E11: 200
A12: 5 | B12: =_xlfn.TEXTJOIN(CHAR(183),TRUE,D12,TEXT(E12,"$000")) -> base·$300 | C12: =C11+1 -> 4 | D12: base | E12: 300
A13: 5 | B13: =_xlfn.TEXTJOIN(CHAR(183),TRUE,D13,TEXT(E13,"$000")) -> high·$000 | C13: =C12+1 -> 5 | D13: high | E13: =E9 -> 0
A14: 5 | B14: =_xlfn.TEXTJOIN(CHAR(183),TRUE,D14,TEXT(E14,"$000")) -> high·$100 | C14: =C13+1 -> 6 | D14: high | E14: =E10 -> 100
A15: 5 | B15: =_xlfn.TEXTJOIN(CHAR(183),TRUE,D15,TEXT(E15,"$000")) -> high·$200 | C15: =C14+1 -> 7 | D15: high | E15: =E11 -> 200
A16: 5 | B16: =_xlfn.TEXTJOIN(CHAR(183),TRUE,D16,TEXT(E16,"$000")) -> high·$300 | C16: =C15+1 -> 8 | D16: high | E16: =E12 -> 300
A17: 5

Sheet Veda
A1: FRA
A2: R10EUROPE | F2: CO2 price | I2: demand
F3: 300 | G3: C2 | I3: base | J3: C4
F4: 200 | G4: C3 | I4: high | J4: C1
F5: 100 | G5: C4
F6: 0 | G6: C7
AH8: bio price multiplier
N9: IEA | AB9: 1 | AC9: ts_annual | AD9: xAnn | AE9: 1 | AF9: C1 | AG9: e 1.5 deg no OS | AH9: 5
N10: 2022 | AB10: 2 | AC10: ts_12t | AD10: x12 | AE10: 1 | AF10: C2 | AG10: d 1.5 deg OS | AH10: 4
N11: =SUMIFS(iea_data!I3:I9999,iea_data!$B$3:$B$9999,$N$10,iea_data!$A$3:A$9999,$A$1)+O28-O29 -> 483.99 | O11: base-year generation (TWh) | AB11: 3 | AC11: ts_012 | AD11: =AC11 -> ts_012 | AE11: 1 | AF11: C3 | AG11: c 2 deg (67%) | AH11: 3
N12: =SUMIFS(iea_data!J3:J9999,iea_data!$B$3:$B$9999,$N$10,iea_data!$A$3:A$9999,$A$1) -> 30.378 | AB12: 4 | AC12: ts_030 | AD12: =AC12 -> ts_030 | AE12: 1 | AF12: C4 | AG12: b 2 deg (50%) | AH12: 3
AB13: 5 | AC13: ts_048 | AD13: =AC13 -> ts_048 | AE13: 1 | AF13: C7 | AG13: a 3 deg | AH13: 1.5
B14: Electricity growth relative to 2020 | C14: =VLOOKUP(controller!$D$5,$I$3:$J$5,2,FALSE) -> C4 | D14: =SUMIFS(ar6_r10!$F$2:$F$99999,ar6_r10!$A$2:$A$99999,$C$14,ar6_r10!$C$2:$C$99999,D$17,ar6_r10!$M$2:$M$99999,$B14,ar6_r10!$B$2:$B$99999,$A$2) -> 1 | E14: =SUMIFS(ar6_r10!$F$2:$F$99999,ar6_r10!$A$2:$A$99999,$C$14,ar6_r10!$C$2:$C$99999,E$17,ar6_r10!$M$2:$M$99999,$B14,ar6_r10!$B$2:$B$99999,$A$2) -> 1.05 | F14: =SUMIFS(ar6_r10!$F$2:$F$99999,ar6_r10!$A$2:$A$99999,$C$14,ar6_r10!$C$2:$C$99999,F$17,ar6_r10!$M$2:$M$99999,$B14,ar6_r10!$B$2:$B$99999,$A$2) -> 1.17 | G14: =SUMIFS(ar6_r10!$F$2:$F$99999,ar6_r10!$A$2:$A$99999,$C$14,ar6_r10!$C$2:$C$99999,G$17,ar6_r10!$M$2:$M$99999,$B14,ar6_r10!$B$2:$B$99999,$A$2) -> 1.29 | H14: =SUMIFS(ar6_r10!$F$2:$F$99999,ar6_r10!$A$2:$A$99999,$C$14,ar6_r10!$C$2:$C$99999,H$17,ar6_r10!$M$2:$M$99999,$B14,ar6_r10!$B$2:$B$99999,$A$2) -> 1.42 | I14: =SUMIFS(ar6_r10!$F$2:$F$99999,ar6_r10!$A$2:$A$99999,$C$14,ar6_r10!$C$2:$C$99999,I$17,ar6_r10!$M$2:$M$99999,$B14,ar6_r10!$B$2:$B$99999,$A$2) -> 1.59 | J14: =SUMIFS(ar6_r10!$F$2:$F$99999,ar6_r10!$A$2:$A$99999,$C$14,ar6_r10!$C$2:$C$99999,J$17,ar6_r10!$M$2:$M$99999,$B14,ar6_r10!$B$2:$B$99999,$A$2) -> 1.73 | O14: =N11 -> 483.99 | P14: =$N$11*E14 -> 508.1895 | Q14: =$N$11*F14 -> 566.2683 | R14: =$N$11*G14 -> 624.3471 | S14: =$N$11*H14 -> 687.2658 | T14: =$N$11*I14 -> 769.5441 | U14: =$N$11*J14 -> 837.3027 | AB14: 6 | AC14: ts_072 | AD14: =AC14 -> ts_072 | AE14: =AE9+1 -> 2
B15: Heat growth relative to 2020 | D15: =SUMIFS(ar6_r10!$F$2:$F$99999,ar6_r10!$A$2:$A$99999,$C$14,ar6_r10!$C$2:$C$99999,D$17,ar6_r10!$M$2:$M$99999,$B15,ar6_r10!$B$2:$B$99999,$A$2) -> 1 | E15: =SUMIFS(ar6_r10!$F$2:$F$99999,ar6_r10!$A$2:$A$99999,$C$14,ar6_r10!$C$2:$C$99999,E$17,ar6_r10!$M$2:$M$99999,$B15,ar6_r10!$B$2:$B$99999,$A$2) -> 0.98 | F15: =SUMIFS(ar6_r10!$F$2:$F$99999,ar6_r10!$A$2:$A$99999,$C$14,ar6_r10!$C$2:$C$99999,F$17,ar6_r10!$M$2:$M$99999,$B15,ar6_r10!$B$2:$B$99999,$A$2) -> 0.96 | G15: =SUMIFS(ar6_r10!$F$2:$F$99999,ar6_r10!$A$2:$A$99999,$C$14,ar6_r10!$C$2:$C$99999,G$17,ar6_r10!$M$2:$M$99999,$B15,ar6_r10!$B$2:$B$99999,$A$2) -> 0.92 | H15: =SUMIFS(ar6_r10!$F$2:$F$99999,ar6_r10!$A$2:$A$99999,$C$14,ar6_r10!$C$2:$C$99999,H$17,ar6_r10!$M$2:$M$99999,$B15,ar6_r10!$B$2:$B$99999,$A$2) -> 0.84 | I15: =SUMIFS(ar6_r10!$F$2:$F$99999,ar6_r10!$A$2:$A$99999,$C$14,ar6_r10!$C$2:$C$99999,I$17,ar6_r10!$M$2:$M$99999,$B15,ar6_r10!$B$2:$B$99999,$A$2) -> 0.83 | J15: =SUMIFS(ar6_r10!$F$2:$F$99999,ar6_r10!$A$2:$A$99999,$C$14,ar6_r10!$C$2:$C$99999,J$17,ar6_r10!$M$2:$M$99999,$B15,ar6_r10!$B$2:$B$99999,$A$2) -> 0.8 | AB15: 7 | AC15: ts_144 | AD15: =AC15 -> ts_144 | AE15: =AE10+1 -> 2
N16: ="~TFM_INS-TS: region="&$A$1 -> ~TFM_INS-TS: region=FRA | AB16: 8 | AC16: ts_288 | AD16: =AC16 -> ts_288 | AE16: =AE11+1 -> 2
D17: 2020 | E17: =P17 -> 2025 | F17: =Q17 -> 2030 | G17: =R17 -> 2035 | H17: =S17 -> 2040 | I17: =T17 -> 2045 | J17: =U17 -> 2050 | N17: commodity | O17: 2022 | P17: 2025 | Q17: 2030 | R17: 2035 | S17: 2040 | T17: 2045 | U17: 2050 | V17: attribute | AB17: 9 | AC17: s1v1_d | AD17: f2d96 | AE17: =AE12+1 -> 2
B18: Hydrogen as a share of electricity | D18: =SUMIFS(ar6_r10!$F$2:$F$99999,ar6_r10!$A$2:$A$99999,$C$14,ar6_r10!$C$2:$C$99999,D$17,ar6_r10!$M$2:$M$99999,$B18,ar6_r10!$B$2:$B$99999,$A$2) -> 0 | E18: =SUMIFS(ar6_r10!$F$2:$F$99999,ar6_r10!$A$2:$A$99999,$C$14,ar6_r10!$C$2:$C$99999,E$17,ar6_r10!$M$2:$M$99999,$B18,ar6_r10!$B$2:$B$99999,$A$2) -> 0 | F18: =SUMIFS(ar6_r10!$F$2:$F$99999,ar6_r10!$A$2:$A$99999,$C$14,ar6_r10!$C$2:$C$99999,F$17,ar6_r10!$M$2:$M$99999,$B18,ar6_r10!$B$2:$B$99999,$A$2) -> 0 | G18: =SUMIFS(ar6_r10!$F$2:$F$99999,ar6_r10!$A$2:$A$99999,$C$14,ar6_r10!$C$2:$C$99999,G$17,ar6_r10!$M$2:$M$99999,$B18,ar6_r10!$B$2:$B$99999,$A$2) -> 0 | H18: =SUMIFS(ar6_r10!$F$2:$F$99999,ar6_r10!$A$2:$A$99999,$C$14,ar6_r10!$C$2:$C$99999,H$17,ar6_r10!$M$2:$M$99999,$B18,ar6_r10!$B$2:$B$99999,$A$2) -> 0 | I18: =SUMIFS(ar6_r10!$F$2:$F$99999,ar6_r10!$A$2:$A$99999,$C$14,ar6_r10!$C$2:$C$99999,I$17,ar6_r10!$M$2:$M$99999,$B18,ar6_r10!$B$2:$B$99999,$A$2) -> 0 | J18: =SUMIFS(ar6_r10!$F$2:$F$99999,ar6_r10!$A$2:$A$99999,$C$14,ar6_r10!$C$2:$C$99999,J$17,ar6_r10!$M$2:$M$99999,$B18,ar6_r10!$B$2:$B$99999,$A$2) -> 0 | N18: hydrogen_allsect | O18: =D18*O$14 -> 0 | P18: =E18*P$14 -> 0 | Q18: =F18*Q$14 -> 0 | R18: =G18*R$14 -> 0 | S18: =H18*S$14 -> 0 | T18: =I18*T$14 -> 0 | U18: =J18*U$14 -> 0 | V18: demand | AB18: 10 | AC18: ts_096 | AD18: e96 | AE18: =AE13+1 -> 2
B19: Industry electricity share | D19: =SUMIFS(ar6_r10!$F$2:$F$99999,ar6_r10!$A$2:$A$99999,$C$14,ar6_r10!$C$2:$C$99999,D$17,ar6_r10!$M$2:$M$99999,$B19,ar6_r10!$B$2:$B$99999,$A$2) -> 0.37 | E19: =SUMIFS(ar6_r10!$F$2:$F$99999,ar6_r10!$A$2:$A$99999,$C$14,ar6_r10!$C$2:$C$99999,E$17,ar6_r10!$M$2:$M$99999,$B19,ar6_r10!$B$2:$B$99999,$A$2) -> 0.35 | F19: =SUMIFS(ar6_r10!$F$2:$F$99999,ar6_r10!$A$2:$A$99999,$C$14,ar6_r10!$C$2:$C$99999,F$17,ar6_r10!$M$2:$M$99999,$B19,ar6_r10!$B$2:$B$99999,$A$2) -> 0.34 | G19: =SUMIFS(ar6_r10!$F$2:$F$99999,ar6_r10!$A$2:$A$99999,$C$14,ar6_r10!$C$2:$C$99999,G$17,ar6_r10!$M$2:$M$99999,$B19,ar6_r10!$B$2:$B$99999,$A$2) -> 0.33 | H19: =SUMIFS(ar6_r10!$F$2:$F$99999,ar6_r10!$A$2:$A$99999,$C$14,ar6_r10!$C$2:$C$99999,H$17,ar6_r10!$M$2:$M$99999,$B19,ar6_r10!$B$2:$B$99999,$A$2) -> 0.3 | I19: =SUMIFS(ar6_r10!$F$2:$F$99999,ar6_r10!$A$2:$A$99999,$C$14,ar6_r10!$C$2:$C$99999,I$17,ar6_r10!$M$2:$M$99999,$B19,ar6_r10!$B$2:$B$99999,$A$2) -> 0.29 | J19: =SUMIFS(ar6_r10!$F$2:$F$99999,ar6_r10!$A$2:$A$99999,$C$14,ar6_r10!$C$2:$C$99999,J$17,ar6_r10!$M$2:$M$99999,$B19,ar6_r10!$B$2:$B$99999,$A$2) -> 0.3 | N19: elc_industry | O19: =D19*O$14 -> 179.0763 | P19: =E19*P$14 -> 177.86632 | Q19: =F19*Q$14 -> 192.53122 | R19: =G19*R$14 -> 206.03454 | S19: =H19*S$14 -> 206.17974 | T19: =I19*T$14 -> 223.16779 | U19: =J19*U$14 -> 251.19081 | V19: demand | AB19: 11 | AC19: s1p1v1_d | AD19: d9d | AE19: =AE14+1 -> 3
B20: Residential and commercial electricity share | D20: =SUMIFS(ar6_r10!$F$2:$F$99999,ar6_r10!$A$2:$A$99999,$C$14,ar6_r10!$C$2:$C$99999,D$17,ar6_r10!$M$2:$M$99999,$B20,ar6_r10!$B$2:$B$99999,$A$2) -> 0.59 | E20: =SUMIFS(ar6_r10!$F$2:$F$99999,ar6_r10!$A$2:$A$99999,$C$14,ar6_r10!$C$2:$C$99999,E$17,ar6_r10!$M$2:$M$99999,$B20,ar6_r10!$B$2:$B$99999,$A$2) -> 0.59 | F20: =SUMIFS(ar6_r10!$F$2:$F$99999,ar6_r10!$A$2:$A$99999,$C$14,ar6_r10!$C$2:$C$99999,F$17,ar6_r10!$M$2:$M$99999,$B20,ar6_r10!$B$2:$B$99999,$A$2) -> 0.59 | G20: =SUMIFS(ar6_r10!$F$2:$F$99999,ar6_r10!$A$2:$A$99999,$C$14,ar6_r10!$C$2:$C$99999,G$17,ar6_r10!$M$2:$M$99999,$B20,ar6_r10!$B$2:$B$99999,$A$2) -> 0.58 | H20: =SUMIFS(ar6_r10!$F$2:$F$99999,ar6_r10!$A$2:$A$99999,$C$14,ar6_r10!$C$2:$C$99999,H$17,ar6_r10!$M$2:$M$99999,$B20,ar6_r10!$B$2:$B$99999,$A$2) -> 0.58 | I20: =SUMIFS(ar6_r10!$F$2:$F$99999,ar6_r10!$A$2:$A$99999,$C$14,ar6_r10!$C$2:$C$99999,I$17,ar6_r10!$M$2:$M$99999,$B20,ar6_r10!$B$2:$B$99999,$A$2) -> 0.56 | J20: =SUMIFS(ar6_r10!$F$2:$F$99999,ar6_r10!$A$2:$A$99999,$C$14,ar6_r10!$C$2:$C$99999,J$17,ar6_r10!$M$2:$M$99999,$B20,ar6_r10!$B$2:$B$99999,$A$2) -> 0.54 | N20: elc_buildings | O20: =D20*O$14 -> 285.5541 | P20: =E20*P$14 -> 299.8318 | Q20: =F20*Q$14 -> 334.0983 | R20: =G20*R$14 -> 362.12132 | S20: =H20*S$14 -> 398.61416 | T20: =I20*T$14 -> 430.9447 | U20: =J20*U$14 -> 452.14346 | V20: demand | AB20: 12 | AC20: s5p5v5_d | AD20: c15d | AE20: =AE15+1 -> 3
B21: Transportation electricity share | D21: =SUMIFS(ar6_r10!$F$2:$F$99999,ar6_r10!$A$2:$A$99999,$C$14,ar6_r10!$C$2:$C$99999,D$17,ar6_r10!$M$2:$M$99999,$B21,ar6_r10!$B$2:$B$99999,$A$2) -> 0.03 | E21: =SUMIFS(ar6_r10!$F$2:$F$99999,ar6_r10!$A$2:$A$99999,$C$14,ar6_r10!$C$2:$C$99999,E$17,ar6_r10!$M$2:$M$99999,$B21,ar6_r10!$B$2:$B$99999,$A$2) -> 0.05 | F21: =SUMIFS(ar6_r10!$F$2:$F$99999,ar6_r10!$A$2:$A$99999,$C$14,ar6_r10!$C$2:$C$99999,F$17,ar6_r10!$M$2:$M$99999,$B21,ar6_r10!$B$2:$B$99999,$A$2) -> 0.04 | G21: =SUMIFS(ar6_r10!$F$2:$F$99999,ar6_r10!$A$2:$A$99999,$C$14,ar6_r10!$C$2:$C$99999,G$17,ar6_r10!$M$2:$M$99999,$B21,ar6_r10!$B$2:$B$99999,$A$2) -> 0.06 | H21: =SUMIFS(ar6_r10!$F$2:$F$99999,ar6_r10!$A$2:$A$99999,$C$14,ar6_r10!$C$2:$C$99999,H$17,ar6_r10!$M$2:$M$99999,$B21,ar6_r10!$B$2:$B$99999,$A$2) -> 0.07 | I21: =SUMIFS(ar6_r10!$F$2:$F$99999,ar6_r10!$A$2:$A$99999,$C$14,ar6_r10!$C$2:$C$99999,I$17,ar6_r10!$M$2:$M$99999,$B21,ar6_r10!$B$2:$B$99999,$A$2) -> 0.08 | J21: =SUMIFS(ar6_r10!$F$2:$F$99999,ar6_r10!$A$2:$A$99999,$C$14,ar6_r10!$C$2:$C$99999,J$17,ar6_r10!$M$2:$M$99999,$B21,ar6_r10!$B$2:$B$99999,$A$2) -> 0.08 | N21: elc_transport | O21: =D21*O$14 -> 14.5197 | P21: =O21 -> 14.5197 | Q21: =P21 -> 14.5197 | R21: =Q21 -> 14.5197 | S21: =R21 -> 14.5197 | T21: =S21 -> 14.5197 | U21: =T21 -> 14.5197 | V21: demand | X21: non-road transport demand assumed to be constant | AE21: =AE16+1 -> 3
N22: elc_roadtransport | O22: =O14-SUM(O19:O21) -> 4.8399 | P22: =P14-SUM(P19:P21) -> 15.97167 | Q22: =Q14-SUM(Q19:Q21) -> 25.119081 | R22: =R14-SUM(R19:R21) -> 41.671539 | S22: =S14-SUM(S19:S21) -> 67.952196 | T22: =T14-SUM(T19:T21) -> 100.91191 | U22: =U14-SUM(U19:U21) -> 119.44873 | V22: demand | AE22: =AE17+1 -> 3
N23: HET | O23: =N12 -> 30.378 | P23: =$N$12*E15 -> 29.77044 | Q23: =$N$12*F15 -> 29.16288 | R23: =$N$12*G15 -> 27.94776 | S23: =$N$12*H15 -> 25.51752 | T23: =$N$12*I15 -> 25.21374 | U23: =$N$12*J15 -> 24.3024 | V23: demand | AE23: =AE18+1 -> 3
B24: CO2 price | C24: =VLOOKUP(controller!E5,$F$3:$G$6,2,FALSE) -> C3 | D24: 0 | E24: 0 | F24: =SUMIFS(ar6_r10!$F$2:$F$99999,ar6_r10!$A$2:$A$99999,$C$24,ar6_r10!$C$2:$C$99999,F$17,ar6_r10!$M$2:$M$99999,$B24,ar6_r10!$B$2:$B$99999,$A$2) -> 71.48 | G24: =SUMIFS(ar6_r10!$F$2:$F$99999,ar6_r10!$A$2:$A$99999,$C$24,ar6_r10!$C$2:$C$99999,G$17,ar6_r10!$M$2:$M$99999,$B24,ar6_r10!$B$2:$B$99999,$A$2) -> 104.42 | H24: =SUMIFS(ar6_r10!$F$2:$F$99999,ar6_r10!$A$2:$A$99999,$C$24,ar6_r10!$C$2:$C$99999,H$17,ar6_r10!$M$2:$M$99999,$B24,ar6_r10!$B$2:$B$99999,$A$2) -> 134.85 | I24: =SUMIFS(ar6_r10!$F$2:$F$99999,ar6_r10!$A$2:$A$99999,$C$24,ar6_r10!$C$2:$C$99999,I$17,ar6_r10!$M$2:$M$99999,$B24,ar6_r10!$B$2:$B$99999,$A$2) -> 178.1 | J24: =SUMIFS(ar6_r10!$F$2:$F$99999,ar6_r10!$A$2:$A$99999,$C$24,ar6_r10!$C$2:$C$99999,J$17,ar6_r10!$M$2:$M$99999,$B24,ar6_r10!$B$2:$B$99999,$A$2) -> 209.45 | N24: co2net | P24: 0 | Q24: =F24/1000 -> 0.07148 | R24: =G24/1000 -> 0.10442 | S24: =H24/1000 -> 0.13485 | T24: =I24/1000 -> 0.1781 | U24: =J24/1000 -> 0.20945 | V24: com_taxnet | AE24: =AE19+1 -> 4
AE25: =AE20+1 -> 4
N26: ="~TFM_INS-TS: region="&$A$1 -> ~TFM_INS-TS: region=FRA | AE26: =AE21+1 -> 4
N27: process | O27: =O17 -> 2022 | P27: =P17 -> 2025 | Q27: =Q17 -> 2030 | R27: =R17 -> 2035 | S27: =S17 -> 2040 | T27: =T17 -> 2045 | U27: =U17 -> 2050 | V27: attribute | W27: limtype | AE27: =AE22+1 -> 4
L28: =SUMIFS(iea_data!G3:G9999,iea_data!$B$3:$B$9999,$N$10,iea_data!$A$3:A$9999,$A$1) -> 52.44 | N28: Trd_electricity import | O28: =L28 -> 52.44 | V28: ACT_BND | W28: FX | AE28: =AE23+1 -> 4
L29: =SUMIFS(iea_data!H3:H9999,iea_data!$B$3:$B$9999,$N$10,iea_data!$A$3:A$9999,$A$1) -> -37.49 | N29: Trd_electricity export | O29: =-1*L29 -> 37.49 | V29: ACT_BND | W29: FX | AE29: =AE24+1 -> 5
AE30: =AE25+1 -> 5
AE31: =AE26+1 -> 5
AE32: =AE27+1 -> 5
AE33: =AE28+1 -> 5
AE34: =AE29+1 -> 6
AE35: =AE30+1 -> 6
B36: C7 | AE36: =AE31+1 -> 6
B37: Gas Price | D37: =SUMIFS(ar6_r10!$F$2:$F$99999,ar6_r10!$A$2:$A$99999,$B$36,ar6_r10!$C$2:$C$99999,D$17,ar6_r10!$M$2:$M$99999,$B37,ar6_r10!$B$2:$B$99999,$A$2) -> 1 | E37: =SUMIFS(ar6_r10!$F$2:$F$99999,ar6_r10!$A$2:$A$99999,$B$36,ar6_r10!$C$2:$C$99999,E$17,ar6_r10!$M$2:$M$99999,$B37,ar6_r10!$B$2:$B$99999,$A$2) -> 1.07 | F37: =SUMIFS(ar6_r10!$F$2:$F$99999,ar6_r10!$A$2:$A$99999,$B$36,ar6_r10!$C$2:$C$99999,F$17,ar6_r10!$M$2:$M$99999,$B37,ar6_r10!$B$2:$B$99999,$A$2) -> 1.24 | G37: =SUMIFS(ar6_r10!$F$2:$F$99999,ar6_r10!$A$2:$A$99999,$B$36,ar6_r10!$C$2:$C$99999,G$17,ar6_r10!$M$2:$M$99999,$B37,ar6_r10!$B$2:$B$99999,$A$2) -> 1.15 | H37: =SUMIFS(ar6_r10!$F$2:$F$99999,ar6_r10!$A$2:$A$99999,$B$36,ar6_r10!$C$2:$C$99999,H$17,ar6_r10!$M$2:$M$99999,$B37,ar6_r10!$B$2:$B$99999,$A$2) -> 1.25 | I37: =SUMIFS(ar6_r10!$F$2:$F$99999,ar6_r10!$A$2:$A$99999,$B$36,ar6_r10!$C$2:$C$99999,I$17,ar6_r10!$M$2:$M$99999,$B37,ar6_r10!$B$2:$B$99999,$A$2) -> 1.17 | J37: =SUMIFS(ar6_r10!$F$2:$F$99999,ar6_r10!$A$2:$A$99999,$B$36,ar6_r10!$C$2:$C$99999,J$17,ar6_r10!$M$2:$M$99999,$B37,ar6_r10!$B$2:$B$99999,$A$2) -> 1.34 | AE37: =AE32+1 -> 6
B38: Coal Price | D38: =SUMIFS(ar6_r10!$F$2:$F$99999,ar6_r10!$A$2:$A$99999,$B$36,ar6_r10!$C$2:$C$99999,D$17,ar6_r10!$M$2:$M$99999,$B38,ar6_r10!$B$2:$B$99999,$A$2) -> 1 | E38: =SUMIFS(ar6_r10!$F$2:$F$99999,ar6_r10!$A$2:$A$99999,$B$36,ar6_r10!$C$2:$C$99999,E$17,ar6_r10!$M$2:$M$99999,$B38,ar6_r10!$B$2:$B$99999,$A$2) -> 1.02 | F38: =SUMIFS(ar6_r10!$F$2:$F$99999,ar6_r10!$A$2:$A$99999,$B$36,ar6_r10!$C$2:$C$99999,F$17,ar6_r10!$M$2:$M$99999,$B38,ar6_r10!$B$2:$B$99999,$A$2) -> 1.06 | G38: =SUMIFS(ar6_r10!$F$2:$F$99999,ar6_r10!$A$2:$A$99999,$B$36,ar6_r10!$C$2:$C$99999,G$17,ar6_r10!$M$2:$M$99999,$B38,ar6_r10!$B$2:$B$99999,$A$2) -> 1.07 | H38: =SUMIFS(ar6_r10!$F$2:$F$99999,ar6_r10!$A$2:$A$99999,$B$36,ar6_r10!$C$2:$C$99999,H$17,ar6_r10!$M$2:$M$99999,$B38,ar6_r10!$B$2:$B$99999,$A$2) -> 1.08 | I38: =SUMIFS(ar6_r10!$F$2:$F$99999,ar6_r10!$A$2:$A$99999,$B$36,ar6_r10!$C$2:$C$99999,I$17,ar6_r10!$M$2:$M$99999,$B38,ar6_r10!$B$2:$B$99999,$A$2) -> 1.1 | J38: =SUMIFS(ar6_r10!$F$2:$F$99999,ar6_r10!$A$2:$A$99999,$B$36,ar6_r10!$C$2:$C$99999,J$17,ar6_r10!$M$2:$M$99999,$B38,ar6_r10!$B$2:$B$99999,$A$2) -> 1.12 | AE38: =AE33+1 -> 6
B39: Oil Price | D39: =SUMIFS(ar6_r10!$F$2:$F$99999,ar6_r10!$A$2:$A$99999,$B$36,ar6_r10!$C$2:$C$99999,D$17,ar6_r10!$M$2:$M$99999,$B39,ar6_r10!$B$2:$B$99999,$A$2) -> 1 | E39: =SUMIFS(ar6_r10!$F$2:$F$99999,ar6_r10!$A$2:$A$99999,$B$36,ar6_r10!$C$2:$C$99999,E$17,ar6_r10!$M$2:$M$99999,$B39,ar6_r10!$B$2:$B$99999,$A$2) -> 1.01 | F39: =SUMIFS(ar6_r10!$F$2:$F$99999,ar6_r10!$A$2:$A$99999,$B$36,ar6_r10!$C$2:$C$99999,F$17,ar6_r10!$M$2:$M$99999,$B39,ar6_r10!$B$2:$B$99999,$A$2) -> 1.11 | G39: =SUMIFS(ar6_r10!$F$2:$F$99999,ar6_r10!$A$2:$A$99999,$B$36,ar6_r10!$C$2:$C$99999,G$17,ar6_r10!$M$2:$M$99999,$B39,ar6_r10!$B$2:$B$99999,$A$2) -> 1.01 | H39: =SUMIFS(ar6_r10!$F$2:$F$99999,ar6_r10!$A$2:$A$99999,$B$36,ar6_r10!$C$2:$C$99999,H$17,ar6_r10!$M$2:$M$99999,$B39,ar6_r10!$B$2:$B$99999,$A$2) -> 1.01 | I39: =SUMIFS(ar6_r10!$F$2:$F$99999,ar6_r10!$A$2:$A$99999,$B$36,ar6_r10!$C$2:$C$99999,I$17,ar6_r10!$M$2:$M$99999,$B39,ar6_r10!$B$2:$B$99999,$A$2) -> 1.04 | J39: =SUMIFS(ar6_r10!$F$2:$F$99999,ar6_r10!$A$2:$A$99999,$B$36,ar6_r10!$C$2:$C$99999,J$17,ar6_r10!$M$2:$M$99999,$B39,ar6_r10!$B$2:$B$99999,$A$2) -> 1.14 | AE39: =AE34+1 -> 7
B40: Biomass Price | D40: =SUMIFS(ar6_r10!$F$2:$F$99999,ar6_r10!$A$2:$A$99999,$B$36,ar6_r10!$C$2:$C$99999,D$17,ar6_r10!$M$2:$M$99999,$B40,ar6_r10!$B$2:$B$99999,$A$2) -> 1 | E40: =SUMIFS(ar6_r10!$F$2:$F$99999,ar6_r10!$A$2:$A$99999,$B$36,ar6_r10!$C$2:$C$99999,E$17,ar6_r10!$M$2:$M$99999,$B40,ar6_r10!$B$2:$B$99999,$A$2) -> 0.96 | F40: =SUMIFS(ar6_r10!$F$2:$F$99999,ar6_r10!$A$2:$A$99999,$B$36,ar6_r10!$C$2:$C$99999,F$17,ar6_r10!$M$2:$M$99999,$B40,ar6_r10!$B$2:$B$99999,$A$2) -> 1.04 | G40: =SUMIFS(ar6_r10!$F$2:$F$99999,ar6_r10!$A$2:$A$99999,$B$36,ar6_r10!$C$2:$C$99999,G$17,ar6_r10!$M$2:$M$99999,$B40,ar6_r10!$B$2:$B$99999,$A$2) -> 1.04 | H40: =SUMIFS(ar6_r10!$F$2:$F$99999,ar6_r10!$A$2:$A$99999,$B$36,ar6_r10!$C$2:$C$99999,H$17,ar6_r10!$M$2:$M$99999,$B40,ar6_r10!$B$2:$B$99999,$A$2) -> 0.98 | I40: =SUMIFS(ar6_r10!$F$2:$F$99999,ar6_r10!$A$2:$A$99999,$B$36,ar6_r10!$C$2:$C$99999,I$17,ar6_r10!$M$2:$M$99999,$B40,ar6_r10!$B$2:$B$99999,$A$2) -> 0.99 | J40: =SUMIFS(ar6_r10!$F$2:$F$99999,ar6_r10!$A$2:$A$99999,$B$36,ar6_r10!$C$2:$C$99999,J$17,ar6_r10!$M$2:$M$99999,$B40,ar6_r10!$B$2:$B$99999,$A$2) -> 1 | AE40: =AE35+1 -> 7
AE41: =AE36+1 -> 7
...

Sheet fuel_prices
A9: Fuel Prices
A10: iso | B10: gas_low | C10: gas_high | D10: coal_low | E10: coal_high | F10: oil_low | G10: oil_high | H10: bioenergy_low | I10: bioenergy_high | J10: Notes
A11: FRA | B11: 29.1 | C11: 41.1 | D11: 13.7 | E11: 16.7 | F11: 48 | G11: 58 | H11: 24 | I11: 32 | J11: TTF-linked, forest resources

Sheet iea_data
A9: IEA Baseline Data
A10: iso | B10: year | C10: industry_twh | D10: buildings_agri_twh | E10: nonroad_transport_twh | F10: road_transport_twh | G10: imports_twh | H10: exports_twh | I10: total_production_twh | J10: chp_heat_twh | K10: heat_tfc_twh
A11: FRA | B11: 2000 | C11: 194.06 | D11: 237.76 | E11: 9.38 | F11: 0 | G11: 3.69 | H11: -73.17 | I11: 533.6 | J11: 35.914 | K11: 37.631
A12: FRA | B12: 2001 | C12: 194.58 | D12: 245.54 | E12: 9.55 | F12: 0 | G12: 4.47 | H12: -72.86 | I12: 543.64 | J12: 43.832 | K12: 45.607
A13: FRA | B13: 2002 | C13: 193.99 | D13: 244.71 | E13: 9.67 | F13: 0 | G13: 3.71 | H13: -80.74 | I13: 552.11 | J13: 45.672 | K13: 47.503
A14: FRA | B14: 2003 | C14: 195.87 | D14: 261.02 | E14: 9.79 | F14: 0 | G14: 6.96 | H14: -73.37 | I14: 559.91 | J14: 44.272 | K14: 46.07
A15: FRA | B15: 2004 | C15: 198.37 | D15: 270.62 | E15: 10.02 | F15: 0 | G15: 6.57 | H15: -68.48 | I15: 567.2 | J15: 44.985 | K15: 46.722
A16: FRA | B16: 2005 | C16: 202.39 | D16: 271 | E16: 9.86 | F16: 0 | G16: 8.06 | H16: -68.39 | I16: 569.87 | J16: 47.009 | K16: 48.418
A17: FRA | B17: 2006 | C17: 196.17 | D17: 280.74 | E17: 9.98 | F17: 0 | G17: 8.52 | H17: -71.86 | I17: 568.01 | J17: 43.725 | K17: 45.486
A18: FRA | B18: 2007 | C18: 193.97 | D18: 281.71 | E18: 10.03 | F18: 0 | G18: 10.78 | H18: -67.59 | I18: 562.48 | J18: 37.177 | K18: 38.771
A19: FRA | B19: 2008 | C19: 192.61 | D19: 291.74 | E19: 10.42 | F19: 0 | G19: 10.75 | H19: -58.74 | I19: 567.56 | J19: 37.622 | K19: 42.32
A20: FRA | B20: 2009 | C20: 175.21 | D20: 293.16 | E20: 10.08 | F20: 0 | G20: 18.52 | H20: -44.45 | I20: 529.43 | J20: 26.555 | K20: 37.185
A21: FRA | B21: 2010 | C21: 181.68 | D21: 313.8 | E21: 10.04 | F21: 0 | G21: 19.48 | H21: -50.19 | I21: 562.94 | J21: 24.475 | K21: 33.141
A22: FRA | B22: 2011 | C22: 186.46 | D22: 293.82 | E22: 9.14 | F22: 0.03 | G22: 9.5 | H22: -65.91 | I22: 567.95 | J22: 25.579 | K22: 33.526
... A33: FRA | B33: 2022 | C33: 165.91 | D33: 294.72 | E33: 8.24 | F33: 1.41 | G33: 52.44 | H33: -37.49 | I33: 469.04 | J33: 30.378 | K33: 46.09

Sheet ar6_r10
A9: AR6 Scenario Drivers
A10: Category | B10: Region | C10: Year | D10: count | E10: mean | F10: median | G10: std | H10: min | I10: max | J10: q25 | K10: q75 | L10: category_description | M10: attribute
A11: C1 | B11: R10EUROPE | C11: 2020 | D11: 60 | E11: 8.68 | F11: 6.87 | G11: 10.43 | H11: 0 | I11: 55.17 | J11: 0 | K11: 13.64 | L11: Limit warming to 1.5°C (>50%) with no or limited overshoot | M11: CO2 price
A12: C1 | B12: R10EUROPE | C12: 2025 | D12: 60 | E12: 190.52 | F12: 181.51 | G12: 136.23 | H12: 1.81 | I12: 626.48 | J12: 115.48 | K12: 238.58 | L12: Limit warming to 1.5°C (>50%) with no or limited overshoot | M12: CO2 price
A13: C1 | B13: R10EUROPE | C13: 2030 | D13: 60 | E13: 268.18 | F13: 241.69 | G13: 134.29 | H13: 1.27 | I13: 673.46 | J13: 182.47 | K13: 329.7 | L13: Limit warming to 1.5°C (>50%) with no or limited overshoot | M13: CO2 price
A14: C1 | B14: R10EUROPE | C14: 2035 | D14: 60 | E14: 363.27 | F14: 339.03 | G14: 173.79 | H14: 14.37 | I14: 859.53 | J14: 227.05 | K14: 483.38 | L14: Limit warming to 1.5°C (>50%) with no or limited overshoot | M14: CO2 price
A15: C1 | B15: R10EUROPE | C15: 2040 | D15: 60 | E15: 471.65 | F15: 410.28 | G15: 224.31 | H15: 162.1 | I15: 1097.01 | J15: 298.63 | K15: 622.14 | L15: Limit warming to 1.5°C (>50%) with no or limited overshoot | M15: CO2 price
A16: C1 | B16: R10EUROPE | C16: 2045 | D16: 60 | E16: 565.69 | F16: 494.2 | G16: 256.15 | H16: 193.42 | I16: 1269.88 | J16: 352.78 | K16: 748.01 | L16: Limit warming to 1.5°C (>50%) with no or limited overshoot | M16: CO2 price
A17: C1 | B17: R10EUROPE | C17: 2050 | D17: 60 | E17: 647.44 | F17: 635.43 | G17: 273.56 | H17: 209.76 | I17: 1170.26 | J17: 409.79 | K17: 887.68 | L17: Limit warming to 1.5°C (>50%) with no or limited overshoot | M17: CO2 price
A18: C2 | B18: R10EUROPE | C18: 2020 | D18: 86 | E18: 6.44 | F18: 0 | G18: 8.34 | H18: 0 | I18: 24.5 | J18: 0 | K18: 12.68 | L18: Limit warming to 1.5°C (>67%) with high overshoot | M18: CO2 price
A19: C2 | B19: R10EUROPE | C19: 2025 | D19: 75 | E19: 63.21 | F19: 44.89 | G19: 56.62 | H19: 3.21 | I19: 273 | J19: 27.09 | K19: 77.31 | L19: Limit warming to 1.5°C (>67%) with high overshoot | M19: CO2 price
A20: C2 | B20: R10EUROPE | C20: 2030 | D20: 86 | E20: 85.48 | F20: 63.36 | G20: 73.46 | H20: 0 | I20: 409.5 | J20: 50 | K20: 111.1 | L20: Limit warming to 1.5°C (>67%) with high overshoot | M20: CO2 price
A21: C2 | B21: R10EUROPE | C21: 2035 | D21: 75 | E21: 208.71 | F21: 154.82 | G21: 291.78 | H21: 60.83 | I21: 2037.12 | J21: 93.79 | K21: 206.26 | L21: Limit warming to 1.5°C (>67%) with high overshoot | M21: CO2 price
A22: C2 | B22: R10EUROPE | C22: 2040 | D22: 86 | E22: 253.33 | F22: 172.09 | G22: 359.35 | H22: 0 | I22: 2600 | J22: 119.07 | K22: 259.4 | L22: Limit warming to 1.5°C (>67%) with high overshoot | M22: CO2 price
... A256: C1 | B256: R10EUROPE | C256: 2020 | D256: 33 | E256: 1 | F256: 1 | G256: 0 | H256: 1 | I256: 1 | J256: 1 | K256: 1 | L256: Limit warming to 1.5°C (>50%) with no or limited overshoot | M256: Gas price
A257: C1 | B257: R10EUROPE | C257: 2025 | D257: 34 | E257: #NUM! | F257: 2.42 | H257: 1.18 | I257: #NUM! | J257: 2.01 | K257: 2.75 | L257: Limit warming to 1.5°C (>50%) with no or limited overshoot | M257: Gas price
A258: C1 | B258: R10EUROPE | C258: 2030 | D258: 34 | E258: #NUM! | F258: 3.1 | H258: 1.71 | I258: #NUM! | J258: 2.38 | K258: 3.46 | L258: Limit warming to 1.5°C (>50%) with no or limited overshoot | M258: Gas price
A259: C1 | B259: R10EUROPE | C259: 2035 | D259: 34 | E259: #NUM! | F259: 3.54 | H259: 1.91 | I259: #NUM! | J259: 2.66 | K259: 4.16 | L259: Limit warming to 1.5°C (>50%) with no or limited overshoot | M259: Gas price
A260: C1 | B260: R10EUROPE | C260: 2040 | D260: 34 | E260: #NUM! | F260: 4.1 | H260: 2.27 | I260: #NUM! | J260: 2.96 | K260: 4.52 | L260: Limit warming to 1.5°C (>50%) with no or limited overshoot | M260: Gas price
A261: C1 | B261: R10EUROPE | C261: 2045 | D261: 34 | E261: #NUM! | F261: 3.86 | H261: 2.54 | I261: #NUM! | J261: 3.3 | K261: 4.89 | L261: Limit warming to 1.5°C (>50%) with no or limited overshoot | M261: Gas price
A262: C1 | B262: R10EUROPE | C262: 2050 | D262: 34 | E262: #NUM! | F262: 3.59 | H262: 2.73 | I262: #NUM! | J262: 3.07 | K262: 4.06 | L262: Limit warming to 1.5°C (>50%) with no or limited overshoot | M262: Gas price
A263: C2 | B263: R10EUROPE | C263: 2020 | D263: 43 | E263: 1 | F263: 1 | G263: 0 | H263: 1 | I263: 1 | J263: 1 | K263: 1 | L263: Limit warming to 1.5°C (>67%) with high overshoot | M263: Gas price
A264: C2 | B264: R10EUROPE | C264: 2025 | D264: 44 | E264: #NUM! | F264: 1.22 | H264: 0 | I264: #NUM! | J264: 1.13 | K264: 1.35 | L264: Limit warming to 1.5°C (>67%) with high overshoot | M264: Gas price
A265: C2 | B265: R10EUROPE | C265: 2030 | D265: 44 | E265: #NUM! | F265: 1.5 | H265: 0 | I265: #NUM! | J265: 1.31 | K265: 1.83 | L265: Limit warming to 1.5°C (>67%) with high overshoot | M265: Gas price
A266: C2 | B266: R10EUROPE | C266: 2035 | D266: 44 | E266: #NUM! | F266: 2.12 | H266: 0 | I266: #NUM! | J266: 1.68 | K266: 2.46 | L266: Limit warming to 1.5°C (>67%) with high overshoot | M266: Gas price
A267: C2 | B267: R10EUROPE | C267: 2040 | D267: 44 | E267: #NUM! | F267: 2.5 | H267: 0 | I267: #NUM! | J267: 2 | K267: 2.94 | L267: Limit warming to 1.5°C (>67%) with high overshoot | M267: Gas price
A268: C2 | B268: R10EUROPE | C268: 2045 | D268: 44 | E268: #NUM! | F268: 2.79 | H268: 0 | I268: #NUM! | J268: 2.08 | K268: 3.44 | L268: Limit warming to 1.5°C (>67%) with high overshoot | M268: Gas price
A269: C2 | B269: R10EUROPE | C269: 2050 | D269: 44 | E269: #NUM! | F269: 2.95 | H269: 0 | I269: #NUM! | J269: 2.49 | K269: 3.78 | L269: Limit warming to 1.5°C (>67%) with high overshoot | M269: Gas price
A270: C3 | B270: R10EUROPE | C270: 2020 | D270: 103 | E270: 1 | F270: 1 | G270: 0 | H270: 1 | I270: 1 | J270: 1 | K270: 1 | L270: Limit warming to 2°C (>67%) with higher action post-2030 | M270: Gas price
A271: C3 | B271: R10EUROPE | C271: 2025 | D271: 112 | E271: #NUM! | F271: 1.41 | H271: 0.98 | I271: #NUM! | J271: 1.23 | K271: 1.96 | L271: Limit warming to 2°C (>67%) with higher action post-2030 | M271: Gas price
A272: C3 | B272: R10EUROPE | C272: 2030 | D272: 112 | E272: #NUM! | F272: 2.04 | H272: 1.05 | I272: #NUM! | J272: 1.52 | K272: 2.55 | L272: Limit warming to 2°C (>67%) with higher action post-2030 | M272: Gas price
A273: C3 | B273: R10EUROPE | C273: 2035 | D273: 112 | E273: #NUM! | F273: 2.4 | H273: 1.05 | I273: #NUM! | J273: 1.71 | K273: 3.14 | L273: Limit warming to 2°C (>67%) with higher action post-2030 | M273: Gas price
A274: C3 | B274: R10EUROPE | C274: 2040 | D274: 112 | E274: #NUM! | F274: 2.6 | H274: 1.06 | I274: #NUM! | J274: 1.85 | K274: 3.74 | L274: Limit warming to 2°C (>67%) with higher action post-2030 | M274: Gas price
A275: C3 | B275: R10EUROPE | C275: 2045 | D275: 112 | E275: #NUM! | F275: 2.85 | H275: 1.08 | I275: #NUM! | J275: 2 | K275: 4.28 | L275: Limit warming to 2°C (>67%) with higher action post-2030 | M275: Gas price
A276: C3 | B276: R10EUROPE | C276: 2050 | D276: 112 | E276: #NUM! | F276: 2.97 | H276: 0 | I276: #NUM! | J276: 2.15 | K276: 4.51 | L276: Limit warming to 2°C (>67%) with higher action post-2030 | M276: Gas price
A277: C4 | B277: R10EUROPE | C277: 2020 | D277: 27 | E277: 1 | F277: 1 | G277: 0 | H277: 1 | I277: 1 | J277: 1 | K277: 1 | L277: Limit warming to 2°C (>50%) with immediate action | M277: Gas price
A278: C4 | B278: R10EUROPE | C278: 2025 | D278: 27 | E278: 1.33 | F278: 1.31 | G278: 0.18 | H278: 1.06 | I278: 1.66 | J278: 1.22 | K278: 1.45 | L278: Limit warming to 2°C (>50%) with immediate action | M278: Gas price
A279: C4 | B279: R10EUROPE | C279: 2030 | D279: 27 | E279: 1.84 | F279: 2.02 | G279: 0.28 | H279: 1.24 | I279: 2.17 | J279: 1.52 | K279: 2.07 | L279: Limit warming to 2°C (>50%) with immediate action | M279: Gas price
A280: C4 | B280: R10EUROPE | C280: 2035 | D280: 27 | E280: 1.84 | F280: 1.96 | G280: 0.41 | H280: 1.19 | I280: 2.46 | J280: 1.42 | K280: 2.11 | L280: Limit warming to 2°C (>50%) with immediate action | M280: Gas price
A281: C4 | B281: R10EUROPE | C281: 2040 | D281: 27 | E281: 2.12 | F281: 2.22 | G281: 0.47 | H281: 1.41 | I281: 2.78 | J281: 1.54 | K281: 2.43 | L281: Limit warming to 2°C (>50%) with immediate action | M281: Gas price
...
