Workbook

Sheet Veda
G1: 1-25,36-60
D2: ="~Inputcell: "&_xlfn.TEXTJOIN(",",TRUE,G1:EE1) -> ~Inputcell: 1-25,36-60 | G2: 5 | H2: 6 | I2: 7 | J2: 9 | K2: 10 | L2: 11 | M2: 16 | N2: 17 | O2: 18 | P2: 20 | Q2: 21 | R2: 22 | S2: 27 | T2: 28 | U2: 29 | V2: 31 | W2: 32 | X2: 33 | Y2: 38 | Z2: 39 | AA2: 40 | AB2: 42 | AC2: 43 | AD2: 44 | AE2: 49 | AF2: 50 | AG2: 51 | AH2: 53 | AI2: 54 | AJ2: 55
D3: 3
D5: =VLOOKUP(D3,$C$9:$E$999,2,FALSE) -> ts_annual | E5: =VLOOKUP(D3,$C$9:$E$999,3,FALSE) -> C3
B7: ~Scenmap
A8: priority | B8: scen | C8: case_no | D8: timeslice | E8: climate | AM8: bio price multiplier
A9: 5 | B9: =VLOOKUP(E9,$AK$9:$AL$15,2,FALSE)&"."&VLOOKUP(D9,$AH$9:$AI$24,2,FALSE) -> e 1.5 deg no OS.kAnn | C9: 1 | D9: =VLOOKUP(AJ9,$AG$9:$AH$22,2,FALSE) -> ts_annual | E9: C1 | G9: Limit warming to 1.5°C (>50%) with no or limited overshoot | AG9: 1 | AH9: ts_annual | AI9: kAnn | AJ9: 1 | AK9: C1 | AL9: e 1.5 deg no OS | AM9: 5
A10: 5 | B10: =VLOOKUP(E10,$AK$9:$AL$15,2,FALSE)&"."&VLOOKUP(D10,$AH$9:$AI$24,2,FALSE) -> d 1.5 deg OS.kAnn | C10: =C9+1 -> 2 | D10: =VLOOKUP(AJ10,$AG$9:$AH$22,2,FALSE) -> ts_annual | E10: C2 | G10: Limit warming to 1.5°C (>67%) with high overshoot | S10: IEA | AG10: 2 | AH10: ts_12t | AI10: k12 | AJ10: 1 | AK10: C2 | AL10: d 1.5 deg OS | AM10: 4
A11: 5 | B11: =VLOOKUP(E11,$AK$9:$AL$15,2,FALSE)&"."&VLOOKUP(D11,$AH$9:$AI$24,2,FALSE) -> c 2 deg (67%).kAnn | C11: =C10+1 -> 3 | D11: =VLOOKUP(AJ11,$AG$9:$AH$22,2,FALSE) -> ts_annual | E11: C3 | G11: Limit warming to 2°C (>67%) with higher action post-2030 | S11: 2022 | AG11: 3 | AH11: ts_012 | AI11: j12 | AJ11: 1 | AK11: C3 | AL11: c 2 deg (67%) | AM11: 3
A12: 5 | B12: =VLOOKUP(E12,$AK$9:$AL$15,2,FALSE)&"."&VLOOKUP(D12,$AH$9:$AI$24,2,FALSE) -> b 2 deg (50%).kAnn | C12: =C11+1 -> 4 | D12: =VLOOKUP(AJ12,$AG$9:$AH$22,2,FALSE) -> ts_annual | E12: C4 | G12: Limit warming to 2°C (>50%) with immediate action | S12: =SUMIFS(iea_data!I3:I9999,iea_data!$B$3:$B$9999,Veda!$S$11)+T28-T29 -> 13.23 | T12: base-year generation (TWh) | AG12: 4 | AH12: ts_030 | AI12: i30 | AJ12: 1 | AK12: C4 | AL12: b 2 deg (50%) | AM12: 3
A13: 5 | B13: =VLOOKUP(E13,$AK$9:$AL$15,2,FALSE)&"."&VLOOKUP(D13,$AH$9:$AI$24,2,FALSE) -> a 3 deg.kAnn | C13: =C12+1 -> 5 | D13: =VLOOKUP(AJ13,$AG$9:$AH$22,2,FALSE) -> ts_annual | E13: C7 | G13: Likely above 3°C warming with limited mitigation | AG13: 5 | AH13: ts_048 | AI13: h48 | AJ13: 1 | AK13: C7 | AL13: a 3 deg | AM13: 1.5
A14: 5 | B14: =VLOOKUP(E14,$AK$9:$AL$15,2,FALSE)&"."&VLOOKUP(D14,$AH$9:$AI$24,2,FALSE) -> e 1.5 deg no OS.k12 | C14: =C13+1 -> 6 | D14: =VLOOKUP(AJ14,$AG$9:$AH$22,2,FALSE) -> ts_12t | E14: =E9 -> C1 | T14: =S12 -> 13.23 | U14: =$S$12*J15 -> 16.8021 | V14: =$S$12*K15 -> 22.2264 | W14: =$S$12*L15 -> 29.8998 | X14: =$S$12*M15 -> 38.6316 | Y14: =$S$12*N15 -> 59.2704 | Z14: =$S$12*O15 -> 79.5123 | AG14: 6 | AH14: ts_048P10 | AI14: h48P10 | AJ14: =AJ9+1 -> 2
A15: 5 | B15: =VLOOKUP(E15,$AK$9:$AL$15,2,FALSE)&"."&VLOOKUP(D15,$AH$9:$AI$24,2,FALSE) -> d 1.5 deg OS.k12 | C15: =C14+1 -> 7 | D15: =VLOOKUP(AJ15,$AG$9:$AH$22,2,FALSE) -> ts_12t | E15: =E10 -> C2 | G15: Electricity growth relative to 2020 | I15: =SUMIFS(ar6_r10!$F$2:$F$999,ar6_r10!$A$2:$A$999,Veda!$E$5,ar6_r10!$C$2:$C$999,Veda!I$17,ar6_r10!$M$2:$M$999,Veda!$G15) -> 1 | J15: =SUMIFS(ar6_r10!$F$2:$F$999,ar6_r10!$A$2:$A$999,Veda!$E$5,ar6_r10!$C$2:$C$999,Veda!J$17,ar6_r10!$M$2:$M$999,Veda!$G15) -> 1.27 | K15: =SUMIFS(ar6_r10!$F$2:$F$999,ar6_r10!$A$2:$A$999,Veda!$E$5,ar6_r10!$C$2:$C$999,Veda!K$17,ar6_r10!$M$2:$M$999,Veda!$G15) -> 1.68 | L15: =SUMIFS(ar6_r10!$F$2:$F$999,ar6_r10!$A$2:$A$999,Veda!$E$5,ar6_r10!$C$2:$C$999,Veda!L$17,ar6_r10!$M$2:$M$999,Veda!$G15) -> 2.26 | M15: =SUMIFS(ar6_r10!$F$2:$F$999,ar6_r10!$A$2:$A$999,Veda!$E$5,ar6_r10!$C$2:$C$999,Veda!M$17,ar6_r10!$M$2:$M$999,Veda!$G15) -> 2.92 | N15: =SUMIFS(ar6_r10!$F$2:$F$999,ar6_r10!$A$2:$A$999,Veda!$E$5,ar6_r10!$C$2:$C$999,Veda!N$17,ar6_r10!$M$2:$M$999,Veda!$G15) -> 4.48 | O15: =SUMIFS(ar6_r10!$F$2:$F$999,ar6_r10!$A$2:$A$999,Veda!$E$5,ar6_r10!$C$2:$C$999,Veda!O$17,ar6_r10!$M$2:$M$999,Veda!$G15) -> 6.01 | AG15: 7 | AH15: ts_048P90 | AI15: h48P90 | AJ15: =AJ10+1 -> 2
A16: 5 | B16: =VLOOKUP(E16,$AK$9:$AL$15,2,FALSE)&"."&VLOOKUP(D16,$AH$9:$AI$24,2,FALSE) -> c 2 deg (67%).k12 | C16: =C15+1 -> 8 | D16: =VLOOKUP(AJ16,$AG$9:$AH$22,2,FALSE) -> ts_12t | E16: =E11 -> C3 | S16: ~TFM_INS-TS | AG16: 8 | AH16: s1_d | AI16: g1d72 | AJ16: =AJ11+1 -> 2
A17: 5 | B17: =VLOOKUP(E17,$AK$9:$AL$15,2,FALSE)&"."&VLOOKUP(D17,$AH$9:$AI$24,2,FALSE) -> b 2 deg (50%).k12 | C17: =C16+1 -> 9 | D17: =VLOOKUP(AJ17,$AG$9:$AH$22,2,FALSE) -> ts_12t | E17: =E12 -> C4 | I17: 2020 | J17: =U17 -> 2025 | K17: =V17 -> 2030 | L17: =W17 -> 2035 | M17: =X17 -> 2040 | N17: =Y17 -> 2045 | O17: =Z17 -> 2050 | S17: commodity | T17: 2022 | U17: 2025 | V17: 2030 | W17: 2035 | X17: 2040 | Y17: 2045 | Z17: 2050 | AA17: attribute | AG17: 9 | AH17: s1v1_d | AI17: f2d96 | AJ17: =AJ12+1 -> 2
A18: 5 | B18: =VLOOKUP(E18,$AK$9:$AL$15,2,FALSE)&"."&VLOOKUP(D18,$AH$9:$AI$24,2,FALSE) -> a 3 deg.k12 | C18: =C17+1 -> 10 | D18: =VLOOKUP(AJ18,$AG$9:$AH$22,2,FALSE) -> ts_12t | E18: =E13 -> C7 | G18: Hydrogen as a share of electricity | I18: =SUMIFS(ar6_r10!$F$2:$F$999,ar6_r10!$A$2:$A$999,Veda!$E$5,ar6_r10!$C$2:$C$999,Veda!I$17,ar6_r10!$M$2:$M$999,Veda!$G18) -> 0 | J18: =SUMIFS(ar6_r10!$F$2:$F$999,ar6_r10!$A$2:$A$999,Veda!$E$5,ar6_r10!$C$2:$C$999,Veda!J$17,ar6_r10!$M$2:$M$999,Veda!$G18) -> 0 | K18: =SUMIFS(ar6_r10!$F$2:$F$999,ar6_r10!$A$2:$A$999,Veda!$E$5,ar6_r10!$C$2:$C$999,Veda!K$17,ar6_r10!$M$2:$M$999,Veda!$G18) -> 0 | L18: =SUMIFS(ar6_r10!$F$2:$F$999,ar6_r10!$A$2:$A$999,Veda!$E$5,ar6_r10!$C$2:$C$999,Veda!L$17,ar6_r10!$M$2:$M$999,Veda!$G18) -> 0.01 | M18: =SUMIFS(ar6_r10!$F$2:$F$999,ar6_r10!$A$2:$A$999,Veda!$E$5,ar6_r10!$C$2:$C$999,Veda!M$17,ar6_r10!$M$2:$M$999,Veda!$G18) -> 0.02 | N18: =SUMIFS(ar6_r10!$F$2:$F$999,ar6_r10!$A$2:$A$999,Veda!$E$5,ar6_r10!$C$2:$C$999,Veda!N$17,ar6_r10!$M$2:$M$999,Veda!$G18) -> 0.02 | O18: =SUMIFS(ar6_r10!$F$2:$F$999,ar6_r10!$A$2:$A$999,Veda!$E$5,ar6_r10!$C$2:$C$999,Veda!O$17,ar6_r10!$M$2:$M$999,Veda!$G18) -> 0.03 | S18: hydrogen_allsect | T18: =I18*T$14 -> 0 | U18: =J18*U$14 -> 0 | V18: =K18*V$14 -> 0 | W18: =L18*W$14 -> 0.298998 | X18: =M18*X$14 -> 0.772632 | Y18: =N18*Y$14 -> 1.185408 | Z18: =O18*Z$14 -> 2.385369 | AA18: demand | AG18: 10 | AH18: ts_096 | AI18: e96 | AJ18: =AJ13+1 -> 2
A19: 5 | B19: =VLOOKUP(E19,$AK$9:$AL$15,2,FALSE)&"."&VLOOKUP(D19,$AH$9:$AI$24,2,FALSE) -> e 1.5 deg no OS.j12 | C19: =C18+1 -> 11 | D19: =VLOOKUP(AJ19,$AG$9:$AH$22,2,FALSE) -> ts_012 | E19: =E14 -> C1 | G19: Industry electricity share | I19: =SUMIFS(ar6_r10!$F$2:$F$999,ar6_r10!$A$2:$A$999,Veda!$E$5,ar6_r10!$C$2:$C$999,Veda!I$17,ar6_r10!$M$2:$M$999,Veda!$G19) -> 0.49 | J19: =SUMIFS(ar6_r10!$F$2:$F$999,ar6_r10!$A$2:$A$999,Veda!$E$5,ar6_r10!$C$2:$C$999,Veda!J$17,ar6_r10!$M$2:$M$999,Veda!$G19) -> 0.45 | K19: =SUMIFS(ar6_r10!$F$2:$F$999,ar6_r10!$A$2:$A$999,Veda!$E$5,ar6_r10!$C$2:$C$999,Veda!K$17,ar6_r10!$M$2:$M$999,Veda!$G19) -> 0.43 | L19: =SUMIFS(ar6_r10!$F$2:$F$999,ar6_r10!$A$2:$A$999,Veda!$E$5,ar6_r10!$C$2:$C$999,Veda!L$17,ar6_r10!$M$2:$M$999,Veda!$G19) -> 0.42 | M19: =SUMIFS(ar6_r10!$F$2:$F$999,ar6_r10!$A$2:$A$999,Veda!$E$5,ar6_r10!$C$2:$C$999,Veda!M$17,ar6_r10!$M$2:$M$999,Veda!$G19) -> 0.4 | N19: =SUMIFS(ar6_r10!$F$2:$F$999,ar6_r10!$A$2:$A$999,Veda!$E$5,ar6_r10!$C$2:$C$999,Veda!N$17,ar6_r10!$M$2:$M$999,Veda!$G19) -> 0.41 | O19: =SUMIFS(ar6_r10!$F$2:$F$999,ar6_r10!$A$2:$A$999,Veda!$E$5,ar6_r10!$C$2:$C$999,Veda!O$17,ar6_r10!$M$2:$M$999,Veda!$G19) -> 0.38 | S19: elc_industry | T19: =I19*T$14 -> 6.4827 | U19: =J19*U$14 -> 7.560945 | V19: =K19*V$14 -> 9.557352 | W19: =L19*W$14 -> 12.557916 | X19: =M19*X$14 -> 15.45264 | Y19: =N19*Y$14 -> 24.300864 | Z19: =O19*Z$14 -> 30.214674 | AA19: demand | AG19: 11 | AH19: s1p1v1_d | AI19: d9d | AJ19: =AJ14+1 -> 3
A20: 5 | B20: =VLOOKUP(E20,$AK$9:$AL$15,2,FALSE)&"."&VLOOKUP(D20,$AH$9:$AI$24,2,FALSE) -> d 1.5 deg OS.j12 | C20: =C19+1 -> 12 | D20: =VLOOKUP(AJ20,$AG$9:$AH$22,2,FALSE) -> ts_012 | E20: =E15 -> C2 | G20: Residential and commercial electricity share | I20: =SUMIFS(ar6_r10!$F$2:$F$999,ar6_r10!$A$2:$A$999,Veda!$E$5,ar6_r10!$C$2:$C$999,Veda!I$17,ar6_r10!$M$2:$M$999,Veda!$G20) -> 0.49 | J20: =SUMIFS(ar6_r10!$F$2:$F$999,ar6_r10!$A$2:$A$999,Veda!$E$5,ar6_r10!$C$2:$C$999,Veda!J$17,ar6_r10!$M$2:$M$999,Veda!$G20) -> 0.52 | K20: =SUMIFS(ar6_r10!$F$2:$F$999,ar6_r10!$A$2:$A$999,Veda!$E$5,ar6_r10!$C$2:$C$999,Veda!K$17,ar6_r10!$M$2:$M$999,Veda!$G20) -> 0.54 | L20: =SUMIFS(ar6_r10!$F$2:$F$999,ar6_r10!$A$2:$A$999,Veda!$E$5,ar6_r10!$C$2:$C$999,Veda!L$17,ar6_r10!$M$2:$M$999,Veda!$G20) -> 0.51 | M20: =SUMIFS(ar6_r10!$F$2:$F$999,ar6_r10!$A$2:$A$999,Veda!$E$5,ar6_r10!$C$2:$C$999,Veda!M$17,ar6_r10!$M$2:$M$999,Veda!$G20) -> 0.51 | N20: =SUMIFS(ar6_r10!$F$2:$F$999,ar6_r10!$A$2:$A$999,Veda!$E$5,ar6_r10!$C$2:$C$999,Veda!N$17,ar6_r10!$M$2:$M$999,Veda!$G20) -> 0.48 | O20: =SUMIFS(ar6_r10!$F$2:$F$999,ar6_r10!$A$2:$A$999,Veda!$E$5,ar6_r10!$C$2:$C$999,Veda!O$17,ar6_r10!$M$2:$M$999,Veda!$G20) -> 0.47 | S20: elc_buildings | T20: =I20*T$14 -> 6.4827 | U20: =J20*U$14 -> 8.737092 | V20: =K20*V$14 -> 12.002256 | W20: =L20*W$14 -> 15.248898 | X20: =M20*X$14 -> 19.702116 | Y20: =N20*Y$14 -> 28.449792 | Z20: =O20*Z$14 -> 37.370781 | AA20: demand | AG20: 12 | AH20: s5p5v5_d | AI20: c15d | AJ20: =AJ15+1 -> 3
A21: 5 | B21: =VLOOKUP(E21,$AK$9:$AL$15,2,FALSE)&"."&VLOOKUP(D21,$AH$9:$AI$24,2,FALSE) -> c 2 deg (67%).j12 | C21: =C20+1 -> 13 | D21: =VLOOKUP(AJ21,$AG$9:$AH$22,2,FALSE) -> ts_012 | E21: =E16 -> C3 | G21: Transportation electricity share | I21: =SUMIFS(ar6_r10!$F$2:$F$999,ar6_r10!$A$2:$A$999,Veda!$E$5,ar6_r10!$C$2:$C$999,Veda!I$17,ar6_r10!$M$2:$M$999,Veda!$G21) -> 0.01 | J21: =SUMIFS(ar6_r10!$F$2:$F$999,ar6_r10!$A$2:$A$999,Veda!$E$5,ar6_r10!$C$2:$C$999,Veda!J$17,ar6_r10!$M$2:$M$999,Veda!$G21) -> 0.01 | K21: =SUMIFS(ar6_r10!$F$2:$F$999,ar6_r10!$A$2:$A$999,Veda!$E$5,ar6_r10!$C$2:$C$999,Veda!K$17,ar6_r10!$M$2:$M$999,Veda!$G21) -> 0.02 | L21: =SUMIFS(ar6_r10!$F$2:$F$999,ar6_r10!$A$2:$A$999,Veda!$E$5,ar6_r10!$C$2:$C$999,Veda!L$17,ar6_r10!$M$2:$M$999,Veda!$G21) -> 0.02 | M21: =SUMIFS(ar6_r10!$F$2:$F$999,ar6_r10!$A$2:$A$999,Veda!$E$5,ar6_r10!$C$2:$C$999,Veda!M$17,ar6_r10!$M$2:$M$999,Veda!$G21) -> 0.03 | N21: =SUMIFS(ar6_r10!$F$2:$F$999,ar6_r10!$A$2:$A$999,Veda!$E$5,ar6_r10!$C$2:$C$999,Veda!N$17,ar6_r10!$M$2:$M$999,Veda!$G21) -> 0.05 | O21: =SUMIFS(ar6_r10!$F$2:$F$999,ar6_r10!$A$2:$A$999,Veda!$E$5,ar6_r10!$C$2:$C$999,Veda!O$17,ar6_r10!$M$2:$M$999,Veda!$G21) -> 0.05 | S21: elc_transport | T21: =I21*T$14 -> 0.1323 | U21: =T21 -> 0.1323 | V21: =U21 -> 0.1323 | W21: =V21 -> 0.1323 | X21: =W21 -> 0.1323 | Y21: =X21 -> 0.1323 | Z21: =Y21 -> 0.1323 | AA21: demand | AC21: non-road transport demand assumed to be constant | AJ21: =AJ16+1 -> 3
A22: 5 | B22: =VLOOKUP(E22,$AK$9:$AL$15,2,FALSE)&"."&VLOOKUP(D22,$AH$9:$AI$24,2,FALSE) -> b 2 deg (50%).j12 | C22: =C21+1 -> 14 | D22: =VLOOKUP(AJ22,$AG$9:$AH$22,2,FALSE) -> ts_012 | E22: =E17 -> C4 | S22: elc_roadtransport | T22: =T14-SUM(T19:T21) -> 0.1323 | U22: =U14-SUM(U19:U21) -> 0.371763 | V22: =V14-SUM(V19:V21) -> 0.534492 | W22: =W14-SUM(W19:W21) -> 1.960686 | X22: =X14-SUM(X19:X21) -> 3.344544 | Y22: =Y14-SUM(Y19:Y21) -> 6.387444 | Z22: =Z14-SUM(Z19:Z21) -> 11.794545 | AA22: demand | AJ22: =AJ17+1 -> 3
A23: 5 | B23: =VLOOKUP(E23,$AK$9:$AL$15,2,FALSE)&"."&VLOOKUP(D23,$AH$9:$AI$24,2,FALSE) -> a 3 deg.j12 | C23: =C22+1 -> 15 | D23: =VLOOKUP(AJ23,$AG$9:$AH$22,2,FALSE) -> ts_012 | E23: =E18 -> C7 | S23: * | AJ23: =AJ18+1 -> 3
A24: 5 | B24: =VLOOKUP(E24,$AK$9:$AL$15,2,FALSE)&"."&VLOOKUP(D24,$AH$9:$AI$24,2,FALSE) -> e 1.5 deg no OS.i30 | C24: =C23+1 -> 16 | D24: =VLOOKUP(AJ24,$AG$9:$AH$22,2,FALSE) -> ts_030 | E24: =E19 -> C1 | G24: CO2 price | I24: 0 | J24: 0 | K24: =SUMIFS(ar6_r10!$F$2:$F$999,ar6_r10!$A$2:$A$999,Veda!$E$5,ar6_r10!$C$2:$C$999,Veda!K$17,ar6_r10!$M$2:$M$999,Veda!$G24) -> 48.97 | L24: =SUMIFS(ar6_r10!$F$2:$F$999,ar6_r10!$A$2:$A$999,Veda!$E$5,ar6_r10!$C$2:$C$999,Veda!L$17,ar6_r10!$M$2:$M$999,Veda!$G24) -> 87.7 | M24: =SUMIFS(ar6_r10!$F$2:$F$999,ar6_r10!$A$2:$A$999,Veda!$E$5,ar6_r10!$C$2:$C$999,Veda!M$17,ar6_r10!$M$2:$M$999,Veda!$G24) -> 122.55 | N24: =SUMIFS(ar6_r10!$F$2:$F$999,ar6_r10!$A$2:$A$999,Veda!$E$5,ar6_r10!$C$2:$C$999,Veda!N$17,ar6_r10!$M$2:$M$999,Veda!$G24) -> 179.54 | O24: =SUMIFS(ar6_r10!$F$2:$F$999,ar6_r10!$A$2:$A$999,Veda!$E$5,ar6_r10!$C$2:$C$999,Veda!O$17,ar6_r10!$M$2:$M$999,Veda!$G24) -> 211.71 | S24: co2net | U24: 0 | V24: =K24/1000 -> 0.04897 | W24: =L24/1000 -> 0.0877 | X24: =M24/1000 -> 0.12255 | Y24: =N24/1000 -> 0.17954 | Z24: =O24/1000 -> 0.21171 | AA24: com_taxnet | AJ24: =AJ19+1 -> 4
A25: 5 | B25: =VLOOKUP(E25,$AK$9:$AL$15,2,FALSE)&"."&VLOOKUP(D25,$AH$9:$AI$24,2,FALSE) -> d 1.5 deg OS.i30 | C25: =C24+1 -> 17 | D25: =VLOOKUP(AJ25,$AG$9:$AH$22,2,FALSE) -> ts_030 | E25: =E20 -> C2 | AJ25: =AJ20+1 -> 4
A26: 5 | B26: =VLOOKUP(E26,$AK$9:$AL$15,2,FALSE)&"."&VLOOKUP(D26,$AH$9:$AI$24,2,FALSE) -> c 2 deg (67%).i30 | C26: =C25+1 -> 18 | D26: =VLOOKUP(AJ26,$AG$9:$AH$22,2,FALSE) -> ts_030 | E26: =E21 -> C3 | S26: ~TFM_INS-TS | AJ26: =AJ21+1 -> 4
A27: 5 | B27: =VLOOKUP(E27,$AK$9:$AL$15,2,FALSE)&"."&VLOOKUP(D27,$AH$9:$AI$24,2,FALSE) -> b 2 deg (50%).i30 | C27: =C26+1 -> 19 | D27: =VLOOKUP(AJ27,$AG$9:$AH$22,2,FALSE) -> ts_030 | E27: =E22 -> C4 | S27: process | T27: =T17 -> 2022 | U27: =U17 -> 2025 | V27: =V17 -> 2030 | W27: =W17 -> 2035 | X27: =X17 -> 2040 | Y27: =Y17 -> 2045 | Z27: =Z17 -> 2050 | AA27: attribute | AB27: limtype | AJ27: =AJ22+1 -> 4
A28: 5 | B28: =VLOOKUP(E28,$AK$9:$AL$15,2,FALSE)&"."&VLOOKUP(D28,$AH$9:$AI$24,2,FALSE) -> a 3 deg.i30 | C28: =C27+1 -> 20 | D28: =VLOOKUP(AJ28,$AG$9:$AH$22,2,FALSE) -> ts_030 | E28: =E23 -> C7 | Q28: =SUMIFS(iea_data!G3:G9999,iea_data!$B$3:$B$9999,Veda!$S$11) -> 0.32 | S28: Trd_electricity import | T28: =Q28 -> 0.32 | AA28: ACT_BND | AB28: FX | AJ28: =AJ23+1 -> 4
A29: 5 | B29: =VLOOKUP(E29,$AK$9:$AL$15,2,FALSE)&"."&VLOOKUP(D29,$AH$9:$AI$24,2,FALSE) -> e 1.5 deg no OS.h48 | C29: =C28+1 -> 21 | D29: =VLOOKUP(AJ29,$AG$9:$AH$22,2,FALSE) -> ts_048 | E29: =E24 -> C1 | Q29: =SUMIFS(iea_data!H3:H9999,iea_data!$B$3:$B$9999,Veda!$S$11) -> -0.02 | S29: Trd_electricity export | T29: =-1*Q29 -> 0.02 | AA29: ACT_BND | AB29: FX | AJ29: =AJ24+1 -> 5
A30: 5 | B30: =VLOOKUP(E30,$AK$9:$AL$15,2,FALSE)&"."&VLOOKUP(D30,$AH$9:$AI$24,2,FALSE) -> d 1.5 deg OS.h48 | C30: =C29+1 -> 22 | D30: =VLOOKUP(AJ30,$AG$9:$AH$22,2,FALSE) -> ts_048 | E30: =E25 -> C2 | AJ30: =AJ25+1 -> 5
A31: 5 | B31: =VLOOKUP(E31,$AK$9:$AL$15,2,FALSE)&"."&VLOOKUP(D31,$AH$9:$AI$24,2,FALSE) -> c 2 deg (67%).h48 | C31: =C30+1 -> 23 | D31: =VLOOKUP(AJ31,$AG$9:$AH$22,2,FALSE) -> ts_048 | E31: =E26 -> C3 | AJ31: =AJ26+1 -> 5
A32: 5 | B32: =VLOOKUP(E32,$AK$9:$AL$15,2,FALSE)&"."&VLOOKUP(D32,$AH$9:$AI$24,2,FALSE) -> b 2 deg (50%).h48 | C32: =C31+1 -> 24 | D32: =VLOOKUP(AJ32,$AG$9:$AH$22,2,FALSE) -> ts_048 | E32: =E27 -> C4 | AJ32: =AJ27+1 -> 5
A33: 5 | B33: =VLOOKUP(E33,$AK$9:$AL$15,2,FALSE)&"."&VLOOKUP(D33,$AH$9:$AI$24,2,FALSE) -> a 3 deg.h48 | C33: =C32+1 -> 25 | D33: =VLOOKUP(AJ33,$AG$9:$AH$22,2,FALSE) -> ts_048 | E33: =E28 -> C7 | AJ33: =AJ28+1 -> 5
A34: 5 | B34: =VLOOKUP(E34,$AK$9:$AL$15,2,FALSE)&"."&VLOOKUP(D34,$AH$9:$AI$24,2,FALSE) -> e 1.5 deg no OS.h48P10 | C34: =C33+1 -> 26 | D34: =VLOOKUP(AJ34,$AG$9:$AH$22,2,FALSE) -> ts_048P10 | E34: =E29 -> C1 | AJ34: =AJ29+1 -> 6
A35: 5 | B35: =VLOOKUP(E35,$AK$9:$AL$15,2,FALSE)&"."&VLOOKUP(D35,$AH$9:$AI$24,2,FALSE) -> d 1.5 deg OS.h48P10 | C35: =C34+1 -> 27 | D35: =VLOOKUP(AJ35,$AG$9:$AH$22,2,FALSE) -> ts_048P10 | E35: =E30 -> C2 | AJ35: =AJ30+1 -> 6
A36: 5 | B36: =VLOOKUP(E36,$AK$9:$AL$15,2,FALSE)&"."&VLOOKUP(D36,$AH$9:$AI$24,2,FALSE) -> c 2 deg (67%).h48P10 | C36: =C35+1 -> 28 | D36: =VLOOKUP(AJ36,$AG$9:$AH$22,2,FALSE) -> ts_048P10 | E36: =E31 -> C3 | G36: C7 | AJ36: =AJ31+1 -> 6
A37: 5 | B37: =VLOOKUP(E37,$AK$9:$AL$15,2,FALSE)&"."&VLOOKUP(D37,$AH$9:$AI$24,2,FALSE) -> b 2 deg (50%).h48P10 | C37: =C36+1 -> 29 | D37: =VLOOKUP(AJ37,$AG$9:$AH$22,2,FALSE) -> ts_048P10 | E37: =E32 -> C4 | G37: Gas Price | I37: =SUMIFS(ar6_r10!$F$2:$F$999,ar6_r10!$A$2:$A$999,Veda!$G$36,ar6_r10!$C$2:$C$999,Veda!I$17,ar6_r10!$M$2:$M$999,Veda!$G37) -> 1 | J37: =SUMIFS(ar6_r10!$F$2:$F$999,ar6_r10!$A$2:$A$999,Veda!$G$36,ar6_r10!$C$2:$C$999,Veda!J$17,ar6_r10!$M$2:$M$999,Veda!$G37) -> 1.04 | K37: =SUMIFS(ar6_r10!$F$2:$F$999,ar6_r10!$A$2:$A$999,Veda!$G$36,ar6_r10!$C$2:$C$999,Veda!K$17,ar6_r10!$M$2:$M$999,Veda!$G37) -> 1.37 | L37: =SUMIFS(ar6_r10!$F$2:$F$999,ar6_r10!$A$2:$A$999,Veda!$G$36,ar6_r10!$C$2:$C$999,Veda!L$17,ar6_r10!$M$2:$M$999,Veda!$G37) -> 1.3 | M37: =SUMIFS(ar6_r10!$F$2:$F$999,ar6_r10!$A$2:$A$999,Veda!$G$36,ar6_r10!$C$2:$C$999,Veda!M$17,ar6_r10!$M$2:$M$999,Veda!$G37) -> 1.55 | N37: =SUMIFS(ar6_r10!$F$2:$F$999,ar6_r10!$A$2:$A$999,Veda!$G$36,ar6_r10!$C$2:$C$999,Veda!N$17,ar6_r10!$M$2:$M$999,Veda!$G37) -> 1.63 | O37: =SUMIFS(ar6_r10!$F$2:$F$999,ar6_r10!$A$2:$A$999,Veda!$G$36,ar6_r10!$C$2:$C$999,Veda!O$17,ar6_r10!$M$2:$M$999,Veda!$G37) -> 1.71 | AJ37: =AJ32+1 -> 6
A38: 5 | B38: =VLOOKUP(E38,$AK$9:$AL$15,2,FALSE)&"."&VLOOKUP(D38,$AH$9:$AI$24,2,FALSE) -> a 3 deg.h48P10 | C38: =C37+1 -> 30 | D38: =VLOOKUP(AJ38,$AG$9:$AH$22,2,FALSE) -> ts_048P10 | E38: =E33 -> C7 | G38: Coal Price | I38: =SUMIFS(ar6_r10!$F$2:$F$999,ar6_r10!$A$2:$A$999,Veda!$G$36,ar6_r10!$C$2:$C$999,Veda!I$17,ar6_r10!$M$2:$M$999,Veda!$G38) -> 1 | J38: =SUMIFS(ar6_r10!$F$2:$F$999,ar6_r10!$A$2:$A$999,Veda!$G$36,ar6_r10!$C$2:$C$999,Veda!J$17,ar6_r10!$M$2:$M$999,Veda!$G38) -> 1.08 | K38: =SUMIFS(ar6_r10!$F$2:$F$999,ar6_r10!$A$2:$A$999,Veda!$G$36,ar6_r10!$C$2:$C$999,Veda!K$17,ar6_r10!$M$2:$M$999,Veda!$G38) -> 1.2 | L38: =SUMIFS(ar6_r10!$F$2:$F$999,ar6_r10!$A$2:$A$999,Veda!$G$36,ar6_r10!$C$2:$C$999,Veda!L$17,ar6_r10!$M$2:$M$999,Veda!$G38) -> 1.34 | M38: =SUMIFS(ar6_r10!$F$2:$F$999,ar6_r10!$A$2:$A$999,Veda!$G$36,ar6_r10!$C$2:$C$999,Veda!M$17,ar6_r10!$M$2:$M$999,Veda!$G38) -> 1.52 | N38: =SUMIFS(ar6_r10!$F$2:$F$999,ar6_r10!$A$2:$A$999,Veda!$G$36,ar6_r10!$C$2:$C$999,Veda!N$17,ar6_r10!$M$2:$M$999,Veda!$G38) -> 1.46 | O38: =SUMIFS(ar6_r10!$F$2:$F$999,ar6_r10!$A$2:$A$999,Veda!$G$36,ar6_r10!$C$2:$C$999,Veda!O$17,ar6_r10!$M$2:$M$999,Veda!$G38) -> 1.57 | AJ38: =AJ33+1 -> 6
A39: 5 | B39: =VLOOKUP(E39,$AK$9:$AL$15,2,FALSE)&"."&VLOOKUP(D39,$AH$9:$AI$24,2,FALSE) -> e 1.5 deg no OS.h48P90 | C39: =C38+1 -> 31 | D39: =VLOOKUP(AJ39,$AG$9:$AH$22,2,FALSE) -> ts_048P90 | E39: =E34 -> C1 | G39: Oil Price | I39: =SUMIFS(ar6_r10!$F$2:$F$999,ar6_r10!$A$2:$A$999,Veda!$G$36,ar6_r10!$C$2:$C$999,Veda!I$17,ar6_r10!$M$2:$M$999,Veda!$G39) -> 1 | J39: =SUMIFS(ar6_r10!$F$2:$F$999,ar6_r10!$A$2:$A$999,Veda!$G$36,ar6_r10!$C$2:$C$999,Veda!J$17,ar6_r10!$M$2:$M$999,Veda!$G39) -> 1.15 | K39: =SUMIFS(ar6_r10!$F$2:$F$999,ar6_r10!$A$2:$A$999,Veda!$G$36,ar6_r10!$C$2:$C$999,Veda!K$17,ar6_r10!$M$2:$M$999,Veda!$G39) -> 1.6 | L39: =SUMIFS(ar6_r10!$F$2:$F$999,ar6_r10!$A$2:$A$999,Veda!$G$36,ar6_r10!$C$2:$C$999,Veda!L$17,ar6_r10!$M$2:$M$999,Veda!$G39) -> 1.33 | M39: =SUMIFS(ar6_r10!$F$2:$F$999,ar6_r10!$A$2:$A$999,Veda!$G$36,ar6_r10!$C$2:$C$999,Veda!M$17,ar6_r10!$M$2:$M$999,Veda!$G39) -> 1.47 | N39: =SUMIFS(ar6_r10!$F$2:$F$999,ar6_r10!$A$2:$A$999,Veda!$G$36,ar6_r10!$C$2:$C$999,Veda!N$17,ar6_r10!$M$2:$M$999,Veda!$G39) -> 1.61 | O39: =SUMIFS(ar6_r10!$F$2:$F$999,ar6_r10!$A$2:$A$999,Veda!$G$36,ar6_r10!$C$2:$C$999,Veda!O$17,ar6_r10!$M$2:$M$999,Veda!$G39) -> 1.77 | AJ39: =AJ34+1 -> 7
A40: 5 | B40: =VLOOKUP(E40,$AK$9:$AL$15,2,FALSE)&"."&VLOOKUP(D40,$AH$9:$AI$24,2,FALSE) -> d 1.5 deg OS.h48P90 | C40: =C39+1 -> 32 | D40: =VLOOKUP(AJ40,$AG$9:$AH$22,2,FALSE) -> ts_048P90 | E40: =E35 -> C2 | G40: Biomass Price | I40: =SUMIFS(ar6_r10!$F$2:$F$999,ar6_r10!$A$2:$A$999,Veda!$G$36,ar6_r10!$C$2:$C$999,Veda!I$17,ar6_r10!$M$2:$M$999,Veda!$G40) -> 1 | J40: =SUMIFS(ar6_r10!$F$2:$F$999,ar6_r10!$A$2:$A$999,Veda!$G$36,ar6_r10!$C$2:$C$999,Veda!J$17,ar6_r10!$M$2:$M$999,Veda!$G40) -> 0.84 | K40: =SUMIFS(ar6_r10!$F$2:$F$999,ar6_r10!$A$2:$A$999,Veda!$G$36,ar6_r10!$C$2:$C$999,Veda!K$17,ar6_r10!$M$2:$M$999,Veda!$G40) -> 0.79 | L40: =SUMIFS(ar6_r10!$F$2:$F$999,ar6_r10!$A$2:$A$999,Veda!$G$36,ar6_r10!$C$2:$C$999,Veda!L$17,ar6_r10!$M$2:$M$999,Veda!$G40) -> 0.82 | M40: =SUMIFS(ar6_r10!$F$2:$F$999,ar6_r10!$A$2:$A$999,Veda!$G$36,ar6_r10!$C$2:$C$999,Veda!M$17,ar6_r10!$M$2:$M$999,Veda!$G40) -> 0.86 | N40: =SUMIFS(ar6_r10!$F$2:$F$999,ar6_r10!$A$2:$A$999,Veda!$G$36,ar6_r10!$C$2:$C$999,Veda!N$17,ar6_r10!$M$2:$M$999,Veda!$G40) -> 0.88 | O40: =SUMIFS(ar6_r10!$F$2:$F$999,ar6_r10!$A$2:$A$999,Veda!$G$36,ar6_r10!$C$2:$C$999,Veda!O$17,ar6_r10!$M$2:$M$999,Veda!$G40) -> 0.9 | AJ40: =AJ35+1 -> 7
A41: 5 | B41: =VLOOKUP(E41,$AK$9:$AL$15,2,FALSE)&"."&VLOOKUP(D41,$AH$9:$AI$24,2,FALSE) -> c 2 deg (67%).h48P90 | C41: =C40+1 -> 33 | D41: =VLOOKUP(AJ41,$AG$9:$AH$22,2,FALSE) -> ts_048P90 | E41: =E36 -> C3 | AJ41: =AJ36+1 -> 7
A42: 5 | B42: =VLOOKUP(E42,$AK$9:$AL$15,2,FALSE)&"."&VLOOKUP(D42,$AH$9:$AI$24,2,FALSE) -> b 2 deg (50%).h48P90 | C42: =C41+1 -> 34 | D42: =VLOOKUP(AJ42,$AG$9:$AH$22,2,FALSE) -> ts_048P90 | E42: =E37 -> C4 | AJ42: =AJ37+1 -> 7
...

Sheet fuel_prices
A9: Fuel Prices
A10: iso | B10: gas_low | C10: gas_high | D10: coal_low | E10: coal_high | F10: oil_low | G10: oil_high | H10: bioenergy_low | I10: bioenergy_high | J10: Notes
A11: KEN | B11: 24 | C11: 34.3 | D11: 12.2 | E11: 16.7 | F11: 45 | G11: 55 | H11: 12 | I11: 20 | J11: Geothermal, agricultural residues

Sheet iea_data
A9: IEA Baseline Data
A10: iso | B10: year | C10: industry_twh | D10: buildings_agri_twh | E10: nonroad_transport_twh | F10: road_transport_twh | G10: imports_twh | H10: exports_twh | I10: total_production_twh
A11: KEN | B11: 2000 | C11: 3 | D11: 1.57 | E11: 0 | F11: 0 | G11: 0.2 | H11: 0 | I11: 4.01
A12: KEN | B12: 2001 | C12: 3.3 | D12: 1.67 | E12: 0 | F12: 0 | G12: 0.17 | H12: 0 | I12: 4.51
A13: KEN | B13: 2002 | C13: 3.54 | D13: 1.75 | E13: 0 | F13: 0 | G13: 0.22 | H13: 0 | I13: 4.67
A14: KEN | B14: 2003 | C14: 3.48 | D14: 1.49 | E14: 0 | F14: 0 | G14: 0.19 | H14: 0 | I14: 4.99
A15: KEN | B15: 2004 | C15: 3.74 | D15: 1.58 | E15: 0 | F15: 0 | G15: 0.16 | H15: 0 | I15: 5.34
A16: KEN | B16: 2005 | C16: 3.98 | D16: 1.69 | E16: 0 | F16: 0 | G16: 0.03 | H16: -0.02 | I16: 5.71
A17: KEN | B17: 2006 | C17: 4.22 | D17: 1.79 | E17: 0 | F17: 0 | G17: 0.01 | H17: -0.05 | I17: 6.05
A18: KEN | B18: 2007 | C18: 4.47 | D18: 1.88 | E18: 0 | F18: 0 | G18: 0.02 | H18: -0.06 | I18: 6.49
A19: KEN | B19: 2008 | C19: 4.3 | D19: 2.28 | E19: 0 | F19: 0 | G19: 0.02 | H19: -0.04 | I19: 6.62
A20: KEN | B20: 2009 | C20: 4.35 | D20: 2.33 | E20: 0 | F20: 0 | G20: 0.04 | H20: -0.03 | I20: 6.74
A21: KEN | B21: 2010 | C21: 4.51 | D21: 2.51 | E21: 0 | F21: 0 | G21: 0.03 | H21: -0.03 | I21: 7.16
A22: KEN | B22: 2011 | C22: 4.85 | D22: 2.8 | E22: 0 | F22: 0 | G22: 0.03 | H22: -0.04 | I22: 7.72
... A33: KEN | B33: 2022 | C33: 8.28 | D33: 5.05 | E33: 0 | F33: 0 | G33: 0.32 | H33: -0.02 | I33: 12.93

Sheet ar6_r10
A9: AR6 Scenario Drivers
A10: Category | B10: Region | C10: Year | D10: count | E10: mean | F10: median | G10: std | H10: min | I10: max | J10: q25 | K10: q75 | L10: category_description | M10: attribute
A11: C1 | B11: R10AFRICA | C11: 2020 | D11: 58 | E11: 4.4 | F11: 0.43 | G11: 5.71 | H11: 0 | I11: 15.58 | J11: 0 | K11: 8.31 | L11: Limit warming to 1.5°C (>50%) with no or limited overshoot | M11: CO2 price
A12: C1 | B12: R10AFRICA | C12: 2025 | D12: 58 | E12: 132.94 | F12: 113.94 | G12: 135.33 | H12: 13.36 | I12: 626.48 | J12: 28.22 | K12: 179.27 | L12: Limit warming to 1.5°C (>50%) with no or limited overshoot | M12: CO2 price
A13: C1 | B13: R10AFRICA | C13: 2030 | D13: 58 | E13: 191.57 | F13: 180.17 | G13: 130.46 | H13: 3.02 | I13: 673.46 | J13: 89.49 | K13: 241.69 | L13: Limit warming to 1.5°C (>50%) with no or limited overshoot | M13: CO2 price
A14: C1 | B14: R10AFRICA | C14: 2035 | D14: 58 | E14: 278.86 | F14: 243.45 | G14: 167.16 | H14: 9.51 | I14: 859.53 | J14: 142.95 | K14: 358.71 | L14: Limit warming to 1.5°C (>50%) with no or limited overshoot | M14: CO2 price
A15: C1 | B15: R10AFRICA | C15: 2040 | D15: 58 | E15: 397.63 | F15: 326.01 | G15: 215.59 | H15: 115.55 | I15: 1097.01 | J15: 239.53 | K15: 539.74 | L15: Limit warming to 1.5°C (>50%) with no or limited overshoot | M15: CO2 price
A16: C1 | B16: R10AFRICA | C16: 2045 | D16: 58 | E16: 527.26 | F16: 415.81 | G16: 250.01 | H16: 193.42 | I16: 1269.88 | J16: 353.85 | K16: 714.5 | L16: Limit warming to 1.5°C (>50%) with no or limited overshoot | M16: CO2 price
A17: C1 | B17: R10AFRICA | C17: 2050 | D17: 58 | E17: 649.79 | F17: 605.23 | G17: 268.91 | H17: 209.76 | I17: 1271.76 | J17: 451.31 | K17: 863.42 | L17: Limit warming to 1.5°C (>50%) with no or limited overshoot | M17: CO2 price
A18: C2 | B18: R10AFRICA | C18: 2020 | D18: 76 | E18: 1.95 | F18: 0 | G18: 3.61 | H18: 0 | I18: 15.58 | J18: 0 | K18: 0.55 | L18: Limit warming to 1.5°C (>67%) with high overshoot | M18: CO2 price
A19: C2 | B19: R10AFRICA | C19: 2025 | D19: 65 | E19: 42.95 | F19: 32.69 | G19: 45.96 | H19: 0 | I19: 174.97 | J19: 5.54 | K19: 61.39 | L19: Limit warming to 1.5°C (>67%) with high overshoot | M19: CO2 price
A20: C2 | B20: R10AFRICA | C20: 2030 | D20: 76 | E20: 55.8 | F20: 49.85 | G20: 54.52 | H20: 0 | I20: 221.93 | J20: 10.8 | K20: 78.77 | L20: Limit warming to 1.5°C (>67%) with high overshoot | M20: CO2 price
A21: C2 | B21: R10AFRICA | C21: 2035 | D21: 65 | E21: 217.07 | F21: 152.99 | G21: 316.2 | H21: 29.98 | I21: 2037.12 | J21: 95.06 | K21: 208.88 | L21: Limit warming to 1.5°C (>67%) with high overshoot | M21: CO2 price
A22: C2 | B22: R10AFRICA | C22: 2040 | D22: 76 | E22: 257.11 | F22: 191.71 | G22: 381.8 | H22: 0 | I22: 2600 | J22: 106.05 | K22: 261.57 | L22: Limit warming to 1.5°C (>67%) with high overshoot | M22: CO2 price
... A360: C7 | B360: R10AFRICA | C360: 2050 | D360: 7 | E360: 0.94 | F360: 0.9 | G360: 0.15 | H360: 0.84 | I360: 1.28 | J360: 0.87 | K360: 0.92 | L360: Likely above 3°C warming with limited mitigation | M360: Biomass price

Sheet ev_charging_uc
A10: =IFERROR(Veda!D5,"ts_12t") -> ts_annual | C10: day_night | D10: ts_012 | F10: day_night | G10: ts_030 | I10: day_night | J10: ts_048 | L10: day_night | M10: ts_048P10 | O10: day_night | P10: ts_048P90 | R10: day_night | S10: s1_d | U10: day_night | V10: s1v1_d | X10: day_night | Y10: ts_096 | AA10: day_night | AB10: s1p1v1_d | AD10: day_night | AE10: s5p5v5_d | AG10: day_night | AH10: ts_annual | AJ10: day_night | AK10: ts_12t
C11: D | D11: S01aH01,S02aH01,S03aH01 | F11: D | G11: S03aH03,S04aH02,S03aH02,S02aH03,S01aH02,S02aH02,S04aH03,S01aH03,S05aH02,S05aH03 | I11: D | J11: S02aH02,S03aH04,S06aH04,S02aH04,S01aH03,S05aH02,S05aH03,S02aH03,S03aH02,S05aH04,S06aH02,S06aH03,S04aH03,S04aH02,S01aH02,S04aH04,S01aH04,S03aH03 | L11: D | M11: S03aH03,S01aH04,S05aH04,S06aH02,S06aH03,S06aH04,S02aH03,S04aH03,S02aH02,S01aH02,S04aH04,S02aH04,S03aH02,S03aH04,S04aH02,S01aH03,S05aH02,S05aH03 | O11: D | P11: S06aH04,S03aH03,S01aH03,S05aH02,S05aH03,S02aH04,S02aH02,S02aH03,S01aH02,S04aH04,S03aH04,S04aH03,S03aH02,S04aH02,S01aH04,S05aH04,S06aH02,S06aH03 | R11: D | S11: S04b0620h15,S06aH04,S02aH04,S04b0620h13,S04b0620h16,S04aH02,S04aH03,S04b0620h10,S02aH02,S04b0620h14,S02aH03,S03aH04,S04b0620h09,S01aH03,S04b0620h11,S04b0620h12,S05aH02,S05aH03,S03aH02,S04b0620h08,S04b0620h17,S05aH04,S06aH02,S06aH03,S01aH04,S04b0620h18,S03aH03,S04b0620h07,S01aH02,S04aH04 | U11: D | V11: S03aH04,S04b0620h09,S03aH02,S02aH02,S04b0620h14,S04b0620h08,S04b0620h17,S04c1119h18,S05aH04,S06aH02,S06aH03,S04aH03,S04b0620h10,S04c1119h08,S03aH03,S04b0620h07,S04c1119h07,S01aH04,S04b0620h18,S04c1119h10,S04c1119h17,S01aH02,S04aH04,S02aH04,S04b0620h13,S04b0620h16,S02aH03,S04b0620h15,S04c1119h09,S06aH04,S04aH02,S04c1119h11,S04c1119h16,S04c1119h13,S04c1119h15,S01aH03,S04b0620h11,S04b0620h12,S04c1119h14,S05aH02,S05aH03,S04c1119h12 | X11: D | Y11: S02aH06,S03aH05,S05aH05,S06aH04,S03aH02,S07aH05,S04aH05,S02aH02,S06aH06,S01aH04,S07aH02,S07aH06,S04aH02,S01aH02,S04aH04,S03aH03,S02aH04,S02aH05,S01aH06,S02aH03,S07aH03,S01aH05,S03aH06,S06aH05,S04aH03,S07aH04,S01aH03,S05aH02,S05aH03,S05aH06,S04aH06,S05aH04,S06aH02,S06aH03,S03aH04 | AA11: D | AB11: S01aH02,S04aH04,S05d1119h07,S05d1119h10,S04aH03,S07aH04,S02aH02,S05c0620h09,S06aH06,S01aH06,S02aH03,S02b0223h12,S07aH03,S02aH04,S02aH05,S05c0620h11,S05c0620h15,S05d1119h12,S05d1119h14,S02b0223h18,S04aH06,S05aH04,S05d1119h13,S06aH02,S06aH03,S02b0223h11,S02b0223h16,S03aH03,S05c0620h10,S05c0620h14,S05c0620h17,S03aH02,S05c0620h18,S05d1119h18,S07aH05,S01aH03,S05aH02,S05aH03,S05aH06,S02b0223h07,S02b0223h14,S02b0223h15,S04aH02,S05d1119h17,S02aH06,S02b0223h08,S02b0223h13,S03aH05,S05aH05,S05d1119h15,S06aH04,S02b0223h09,S02b0223h10,S03aH04,S05c0620h12,S05d1119h08,S01aH05,S03aH06,S05c0620h07,S06aH05,S01aH04,S05c0620h13,S05d1119h09,S05d1119h16,S07aH02,S07aH06,S02b0223h17,S04aH05,S05c0620h08,S05c0620h16,S05d1119h11 | AD11: D | AE11: S02b0223h11,S02b0223h16,S02d0225h17,S02e0226h13,S02e0226h15,S03aH03,S03f0306h11,S03f0306h18,S04g0319h08,S05i0325h17,S05k0617h11,S05k0617h15,S05n0924h07,S05n0924h12,S06p1126h15,S02aH02,S02d0225h11,S04g0319h09,S04h0320h11,S05i0325h08,S05i0325h18,S05l0618h09,S05l0618h17,S05m0620h18,S05n0924h10,S06aH06,S02b0223h09,S02b0223h10,S02c0224h09,S02c0224h11,S02c0224h12,S02e0226h12,S03aH04,S03f0306h10,S03f0306h15,S04h0320h18,S05i0325h09,S05j0512h10,S05k0617h07,S05l0618h16,S05m0620h14,S05n0924h08,S05o1119h08,S05o1119h15,S02c0224h13,S02e0226h17,S03aH02,S04h0320h09,S04h0320h13,S04h0320h14,S05i0325h12,S05j0512h08,S05j0512h15,S05k0617h09,S05l0618h14,S05m0620h12,S05n0924h11,S05n0924h15,S05n0924h16,S05n0924h18,S07aH05,S02aH04,S02aH05,S02c0224h07,S02c0224h17,S02d0225h13,S02e0226h14,S04g0319h12,S04g0319h16,S04h0320h12,S05i0325h11,S05i0325h16,S05o1119h11,S06p1126h12,S01aH02,S02e0226h18,S03f0306h16,S04aH04,S05i0325h15,S05m0620h11,S05m0620h17,S06p1126h08,S01aH03,S02c0224h16,S02d0225h15,S02e0226h10,S03f0306h12,S04h0320h15,S05aH02,S05aH03,S05aH06,S05i0325h07,S05o1119h13,S05o1119h18,S01aH05,S02c0224h15,S02d0225h16,S02d0225h18,S02e0226h09,S03aH06,S03f0306h13,S04g0319h14,S04h0320h17,S05j0512h13,S05j0512h14,S05k0617h08,S05l0618h11,S05l0618h18,S05o1119h14,S06aH05,S06p1126h14,S06p1126h17,S02aH06,S02b0223h08,S02b0223h13,S02c0224h10,S03aH05,S03f0306h14,S04g0319h07,S05aH05,S05k0617h14,S05n0924h14,S05o1119h09,S06aH04,S06p1126h10,S02b0223h07,S02b0223h14,S02b0223h15,S04aH02,S04h0320h16,S05j0512h07,S05l0618h12,S05m0620h09,S05n0924h17,S05o1119h17,S06p1126h16,S06p1126h18,S01aH06,S02aH03,S02b0223h12,S02e0226h08,S04g0319h11,S04g0319h17,S05k0617h13,S05k0617h17,S05m0620h13,S05m0620h15,S05o1119h07,S07aH03,S02b0223h17,S02d0225h08,S02e0226h07,S04aH05,S04g0319h13,S05i0325h10,S05k0617h12,S05k0617h18,S05m0620h08,S05m0620h10,S05m0620h16,S06p1126h11,S02c0224h18,S02d0225h07,S02d0225h09,S02d0225h10,S02d0225h12,S02d0225h14,S02e0226h11,S03f0306h07,S03f0306h17,S04aH03,S04h0320h08,S05j0512h11,S05n0924h09,S05o1119h12,S05o1119h16,S06p1126h07,S06p1126h09,S07aH04,S02c0224h08,S02e0226h16,S04h0320h10,S05k0617h10,S05l0618h08,S05l0618h10,S05m0620h07,S05n0924h13,S01aH04,S03f0306h08,S04g0319h10,S04g0319h18,S04h0320h07,S05j0512h09,S05j0512h16,S05j0512h17,S05j0512h18,S05k0617h16,S05l0618h13,S06p1126h13,S07aH02,S07aH06,S02b0223h18,S02c0224h14,S03f0306h09,S04aH06,S04g0319h15,S05aH04,S05i0325h13,S05i0325h14,S05j0512h12,S05l0618h07,S05l0618h15,S05o1119h10,S06aH02,S06aH03 | AG11: D | AH11: AllSaAllH | AJ11: D | AK11: FaP,SaP,RaP,RaD,WaD,SaD,WaP,FaD
C12: N | D12: S01aH02,S03aH02,S02aH03,S02aH02,S01aH03,S03aH03 | F12: N | G12: S03aH05,S05aH05,S04aH04,S01aH01,S04aH01,S05aH04,S01aH04,S05aH01,S01aH05,S03aH01,S02aH04,S02aH05,S02aH01,S03aH04,S04aH05 | I12: N | J12: S03aH01,S05aH01,S02aH05,S02aH06,S03aH05,S05aH05,S01aH01,S04aH01,S04aH06,S01aH06,S02aH01,S05aH06,S01aH05,S03aH06,S06aH05,S04aH05,S06aH01,S06aH06 | L12: N | M12: S06aH06,S01aH06,S02aH05,S01aH01,S04aH01,S04aH06,S02aH01,S05aH06,S03aH01,S01aH05,S03aH06,S06aH05,S02aH06,S03aH05,S05aH05,S04aH05,S06aH01,S05aH01 | O12: N | P12: S02aH05,S06aH06,S02aH06,S03aH05,S05aH05,S03aH01,S01aH01,S04aH01,S04aH06,S01aH05,S03aH06,S06aH05,S04aH05,S06aH01,S05aH01,S02aH01,S05aH06,S01aH06 | R12: N | S12: S02aH05,S04b0620h04,S04b0620h05,S04b0620h20,S02aH06,S03aH05,S04b0620h01,S04b0620h02,S05aH05,S02aH01,S04b0620h22,S04b0620h24,S05aH06,S03aH01,S01aH01,S04aH01,S04aH06,S04aH05,S04b0620h03,S06aH01,S05aH01,S01aH06,S04b0620h21,S04b0620h23,S04b0620h06,S06aH06,S01aH05,S03aH06,S04b0620h19,S06aH05 | U12: N | V12: S05aH01,S04c1119h23,S03aH01,S04c1119h20,S01aH06,S04c1119h02,S04c1119h04,S02aH01,S04b0620h22,S04b0620h24,S05aH06,S04b0620h23,S04c1119h24,S04b0620h06,S04c1119h03,S04c1119h19,S04c1119h21,S06aH06,S04b0620h21,S04c1119h01,S01aH05,S03aH06,S04b0620h19,S06aH05,S02aH06,S03aH05,S04b0620h01,S04b0620h02,S04c1119h05,S05aH05,S01aH01,S04aH01,S04aH06,S02aH05,S04b0620h04,S04b0620h05,S04b0620h20,S04c1119h06,S04c1119h22,S04aH05,S04b0620h03,S06aH01 | X12: N | Y12: S06aH07,S07aH07,S07aH08,S05aH08,S03aH01,S01aH08,S02aH08,S03aH07,S03aH08,S04aH07,S06aH08,S01aH01,S04aH01,S02aH01,S04aH08,S06aH01,S05aH07,S07aH01,S01aH07,S02aH07,S05aH01 | AA12: N | AB12: S01aH08,S02aH08,S02b0223h03,S02b0223h22,S03aH07,S05d1119h02,S05d1119h06,S02aH01,S02b0223h06,S05c0620h01,S05d1119h01,S05d1119h22,S05d1119h24,S02b0223h05,S02b0223h21,S04aH08,S05c0620h03,S05c0620h23,S06aH01,S03aH01,S01aH01,S02b0223h19,S04aH01,S05c0620h21,S05d1119h20,S02b0223h01,S03aH08,S04aH07,S05c0620h06,S06aH08,S02b0223h02,S05aH07,S05c0620h19,S07aH01,S02b0223h20,S05d1119h05,S02b0223h24,S05c0620h04,S05c0620h05,S05d1119h21,S02b0223h23,S02b0223h04,S06aH07,S07aH07,S07aH08,S01aH07,S02aH07,S05aH01,S05c0620h22,S05c0620h24,S05c0620h02,S05d1119h03,S05d1119h04,S05d1119h19,S05c0620h20,S05d1119h23,S05aH08 | AD12: N | AE12: S02c0224h02,S02e0226h21,S04h0320h21,S04h0320h24,S05k0617h04,S05k0617h21,S05l0618h03,S05m0620h20,S05n0924h01,S06p1126h02,S02c0224h01,S02c0224h23,S02d0225h21,S02e0226h01,S02e0226h20,S03aH01,S04h0320h23,S05i0325h23,S05j0512h01,S05j0512h05,S05l0618h01,S05l0618h19,S05o1119h01,S01aH07,S02aH07,S02c0224h19,S04h0320h02,S05aH01,S05k0617h23,S05o1119h19,S02b0223h20,S02c0224h05,S02e0226h02,S02e0226h19,S04g0319h06,S04g0319h24,S05j0512h20,S05k0617h24,S05n0924h02,S05o1119h22,S02b0223h01,S02d0225h06,S02d0225h19,S03aH08,S03f0306h24,S04aH07,S05i0325h22,S05j0512h21,S05k0617h03,S05l0618h05,S05l0618h06,S05l0618h24,S05n0924h23,S05o1119h04,S06aH08,S06p1126h03,S01aH08,S02aH08,S02b0223h03,S02b0223h22,S02d0225h02,S03aH07,S03f0306h21,S04g0319h21,S04g0319h23,S04h0320h20,S05i0325h02,S05k0617h01,S05l0618h02,S05l0618h20,S05m0620h01,S05m0620h24,S05n0924h03,S05n0924h06,S05n0924h19,S05o1119h06,S05o1119h21,S06p1126h24,S02b0223h24,S02d0225h20,S02e0226h03,S02e0226h05,S03f0306h22,S04h0320h05,S05k0617h05,S05m0620h06,S05n0924h22,S06p1126h05,S02c0224h24,S02e0226h06,S04g0319h02,S05i0325h03,S05j0512h02,S05k0617h06,S05m0620h03,S05m0620h22,S05m0620h23,S05n0924h05,S05o1119h24,S06p1126h20,S06p1126h21,S02b0223h04,S02d0225h04,S02d0225h05,S02d0225h22,S02e0226h04,S02e0226h24,S03f0306h05,S03f0306h20,S04h0320h03,S05j0512h03,S05j0512h06,S05j0512h22,S05l0618h23,S06aH07,S06p1126h06,S07aH07,S07aH08,S02b0223h23,S02c0224h06,S02c0224h21,S02e0226h22,S04g0319h03,S04g0319h20,S04h0320h22,S05i0325h04,S05i0325h20,S06p1126h04,S01aH01,S02b0223h19,S04aH01,S04g0319h04,S05i0325h01,S05l0618h21,S05l0618h22,S05o1119h05,S05o1119h23,S02d0225h01,S04g0319h22,S04h0320h19,S05aH08,S05i0325h05,S05i0325h21,S05j0512h24,S05m0620h05,S06p1126h19,S02aH01,S02b0223h06,S02c0224h20,S02d0225h03,S03f0306h01,S03f0306h03,S05i0325h06,S05j0512h23,S05k0617h02,S05k0617h19,S05m0620h04,S05n0924h21,S05n0924h24,S02b0223h05,S02b0223h21,S03f0306h19,S04aH08,S04g0319h05,S05i0325h19,S05i0325h24,S05j0512h04,S05o1119h20,S06aH01,S06p1126h23,S02c0224h22,S02d0225h23,S02d0225h24,S03f0306h02,S03f0306h04,S03f0306h06,S03f0306h23,S04h0320h04,S04h0320h06,S05k0617h20,S05o1119h03,S06p1126h22,S02b0223h02,S02c0224h03,S02c0224h04,S02e0226h23,S04g0319h01,S04g0319h19,S04h0320h01,S05aH07,S05j0512h19,S05k0617h22,S05l0618h04,S05m0620h02,S05m0620h19,S05m0620h21,S05n0924h04,S05n0924h20,S05o1119h02,S06p1126h01,S07aH01 | AG12: N | AH12: AllSaAllH | AJ12: N | AK12: SaN,WaN,WaP,FaP,SaP,RaN,FaN,RaP
I17: 0.75 | K17: share of charging at night
C18: ~UC_Sets: R_E: AllRegions
H21: =IF(H23=H24,"Not Required!","~UC_T: LO") -> Not Required!
C22: UC_N | D22: Pset_CI | E22: Pset_CO | F22: pset_pn | G22: Cset_CN | H22: TimeSlice | I22: UC_FLO | J22: UC_RHSRT | K22: UC_RHSRT~0
C23: UC_bev night chg limit | D23: ELC | E23: =G23 -> AuxStoIN | F23: *EV* | G23: AuxStoIN | H23: =HLOOKUP($A$10,$D$10:$CU$12,3,FALSE) -> AllSaAllH | I23: =1+I24 -> 0.25 | J23: 0 | K23: 3 | M23: night
D24: ELC | E24: =G24 -> AuxStoIN | F24: *EV* | G24: AuxStoIN | H24: =HLOOKUP($A$10,$D$10:$CU$12,2,FALSE) -> AllSaAllH | I24: =-$I$17 -> -0.75 | M24: day

Sheet ts_012
C9: =IF(A11="x","DeActivated","~TimeSlices") -> DeActivated | I9: =IF(A11="x","DeActivated","~TFM_DINS-AT") -> DeActivated | N9: =IF(A11="x","DeActivated","~TFM_DINS-AT") -> DeActivated | S9: =IF(A11="x","DeActivated","~TFM_DINS-AT") -> DeActivated | X9: =IF(A11="x","DeActivated","~TFM_DINS-AT") -> DeActivated | AC9: =IF(A11="x","DeActivated","~TFM_DINS-AT") -> DeActivated | AG9: =IF(A11="x","DeActivated","~TFM_DINS-AT") -> DeActivated | AK9: =IF(A11="x","DeActivated","~TFM_INS-AT") -> DeActivated
A10: ts_012 | C10: season | D10: weekly | E10: daynite | F10: wparent | G10: dparent | I10: commodity | J10: timeslice | K10: com_fr | L10: process | N10: commodity | O10: timeslice | P10: com_fr | Q10: process | S10: commodity | T10: timeslice | U10: com_fr | V10: process | X10: g_yrfr | Y10: com_fr | Z10: timeslice | AA10: commodity | AC10: commodity | AD10: timeslice | AE10: com_fr | AG10: commodity | AH10: timeslice | AI10: com_pkflx | AK10: Year | AL10: timeslice | AM10: ncap_afs | AN10: pset_ci
A11: =IFERROR(IF(Veda!D5=A10,"ok","x"),"") -> x | C11: S01 | D11: a | E11: H01 | F11: S01,S02,S03 | G11: a | I11: elc_spv_001 | J11: S01aH01 | K11: 0.10807766 | L11: IMPNRGZ | N11: elc_won_001 | O11: S01aH01 | P11: 0.028664177 | Q11: IMPNRGZ | S11: elc_wof_001 | T11: S01aH01 | U11: 0.067482345 | V11: IMPNRGZ | X11: 0.069863014 | Y11: 0.072638374 | Z11: S01aH01 | AA11: elc_roadtransport | AC11: elc_buildings | AD11: S01aH01 | AE11: 0.074351894 | AG11: ELC | AH11: S01aH01 | AI11: 0.17947483 | AK11: 2020 | AL11: S01 | AM11: 0.5719863 | AN11: hydro
C12: S02 | E12: H02 | G12: a | I12: elc_spv_001 | J12: S01aH02 | K12: 0.0065486123 | L12: IMPNRGZ | N12: elc_won_001 | O12: S01aH02 | P12: 0.0034366421 | Q12: IMPNRGZ | S12: elc_wof_001 | T12: S01aH02 | U12: 0.0065508266 | V12: IMPNRGZ | X12: 0.0038812785 | Y12: 0.0058606602 | Z12: S01aH02 | AA12: elc_roadtransport | AC12: elc_buildings | AD12: S01aH02 | AE12: 0.0048100278 | AG12: ELC | AH12: S01aH02 | AI12: 0.006243625 | AK12: 2020 | AL12: S02 | AM12: 0.57471264 | AN12: hydro
C13: S03 | E13: H03 | G13: a | I13: elc_spv_001 | J13: S01aH03 | K13: 0 | L13: IMPNRGZ | N13: elc_won_001 | O13: S01aH03 | P13: 0.013920381 | Q13: IMPNRGZ | S13: elc_wof_001 | T13: S01aH03 | U13: 0.030651623 | V13: IMPNRGZ | X13: 0.019406393 | Y13: 0.01465165 | Z13: S01aH03 | AA13: elc_roadtransport | AC13: elc_buildings | AD13: S01aH03 | AE13: 0.015236281 | AG13: ELC | AH13: S01aH03 | AI13: 0.16229552 | AK13: 2020 | AL13: S03 | AM13: 0.56918065 | AN13: hydro
I14: elc_spv_001 | J14: S02aH01 | K14: 0.075906011 | L14: IMPNRGZ | N14: elc_won_001 | O14: S02aH01 | P14: 0.022164691 | Q14: IMPNRGZ | S14: elc_wof_001 | T14: S02aH01 | U14: 0.035307132 | V14: IMPNRGZ | X14: 0.047260274 | Y14: 0.049137724 | Z14: S02aH01 | AA14: elc_roadtransport | AC14: elc_buildings | AD14: S02aH01 | AE14: 0.049582988 | AG14: ELC | AH14: S02aH01 | AI14: 0.18637012 | AK14: 2021 | AL14: S01 | AM14: 0.50012503 | AN14: hydro
I15: elc_spv_001 | J15: S02aH02 | K15: 0.0048689097 | L15: IMPNRGZ | N15: elc_won_001 | O15: S02aH02 | P15: 0.0044843119 | Q15: IMPNRGZ | S15: elc_wof_001 | T15: S02aH02 | U15: 0.004541889 | V15: IMPNRGZ | X15: 0.0026255708 | Y15: 0.0039645642 | Z15: S02aH02 | AA15: elc_roadtransport | AC15: elc_buildings | AD15: S02aH02 | AE15: 0.0032027536 | AG15: ELC | AH15: S02aH02 | AI15: 0.016639012 | AK15: 2021 | AL15: S02 | AM15: 0.48449612 | AN15: hydro
I16: elc_spv_001 | J16: S02aH03 | K16: 0 | L16: IMPNRGZ | N16: elc_won_001 | O16: S02aH03 | P16: 0.018637868 | Q16: IMPNRGZ | S16: elc_wof_001 | T16: S02aH03 | U16: 0.019759126 | V16: IMPNRGZ | X16: 0.013127854 | Y16: 0.0099114106 | Z16: S02aH03 | AA16: elc_roadtransport | AC16: elc_buildings | AD16: S02aH03 | AE16: 0.010264171 | AG16: ELC | AH16: S02aH03 | AI16: 0.16609113 | AK16: 2021 | AL16: S03 | AM16: 0.48582221 | AN16: hydro
I17: elc_spv_001 | J17: S03aH01 | K17: 0.77209388 | L17: IMPNRGZ | N17: elc_won_001 | O17: S03aH01 | P17: 0.5310438 | Q17: IMPNRGZ | S17: elc_wof_001 | T17: S03aH01 | U17: 0.57403575 | V17: IMPNRGZ | X17: 0.63287671 | Y17: 0.65801822 | Z17: S03aH01 | AA17: elc_roadtransport | AC17: elc_buildings | AD17: S03aH01 | AE17: 0.6641539 | AG17: ELC | AH17: S03aH01 | AI17: 0.19709248 | AK17: 2022 | AL17: S01 | AM17: 0.45770371 | AN17: hydro
I18: elc_spv_001 | J18: S03aH02 | K18: 0.032504926 | L18: IMPNRGZ | N18: elc_won_001 | O18: S03aH02 | P18: 0.096681634 | Q18: IMPNRGZ | S18: elc_wof_001 | T18: S03aH02 | U18: 0.041956317 | V18: IMPNRGZ | X18: 0.035159817 | Y18: 0.053090686 | Z18: S03aH02 | AA18: elc_roadtransport | AC18: elc_buildings | AD18: S03aH02 | AE18: 0.043035047 | AG18: ELC | AH18: S03aH02 | AI18: 0.019935866 | AK18: 2022 | AL18: S02 | AM18: 0.41528239 | AN18: hydro
I19: elc_spv_001 | J19: S03aH03 | K19: 0 | L19: IMPNRGZ | N19: elc_won_001 | O19: S03aH03 | P19: 0.28096649 | Q19: IMPNRGZ | S19: elc_wof_001 | T19: S03aH03 | U19: 0.21971499 | V19: IMPNRGZ | X19: 0.17579909 | Y19: 0.13272672 | Z19: S03aH03 | AA19: elc_roadtransport | AC19: elc_buildings | AD19: S03aH03 | AE19: 0.13536294 | AG19: ELC | AH19: S03aH03 | AI19: 0.18620847 | AK19: 2022 | AL19: S03 | AM19: 0.39181873 | AN19: hydro
I20: elc_spv_002 | J20: S01aH01 | K20: 0.099362755 | L20: IMPNRGZ | N20: elc_won_002 | O20: S01aH01 | P20: 0.013917036 | Q20: IMPNRGZ | S20: elc_wof_002 | T20: S01aH01 | U20: 0.064476472 | V20: IMPNRGZ | AC20: elc_industry | AD20: S01aH01 | AE20: 0.070051808 | AK20: 2025 | AL20: S01 | AM20: 0.38775 | AN20: hydro
I21: elc_spv_002 | J21: S01aH02 | K21: 0.0065900518 | L21: IMPNRGZ | N21: elc_won_002 | O21: S01aH02 | P21: 0.0011537261 | Q21: IMPNRGZ | S21: elc_wof_002 | T21: S01aH02 | U21: 0.0075925805 | V21: IMPNRGZ | AC21: elc_industry | AD21: S01aH02 | AE21: 0.0039268602 | AK21: 2025 | AL21: S02 | AM21: 0.3435 | AN21: hydro
I22: elc_spv_002 | J22: S01aH03 | K22: 0 | L22: IMPNRGZ | N22: elc_won_002 | O22: S01aH03 | P22: 0.0069677739 | Q22: IMPNRGZ | S22: elc_wof_002 | T22: S01aH03 | U22: 0.028928468 | V22: IMPNRGZ | AC22: elc_industry | AD22: S01aH03 | AE22: 0.019179016 | AK22: 2025 | AL22: S03 | AM22: 0.37402727 | AN22: hydro
I23: elc_spv_002 | J23: S02aH01 | K23: 0.065234417 | L23: IMPNRGZ | N23: elc_won_002 | O23: S02aH01 | P23: 0.013947581 | Q23: IMPNRGZ | S23: elc_wof_002 | T23: S02aH01 | U23: 0.038860714 | V23: IMPNRGZ | AC23: elc_industry | AD23: S02aH01 | AE23: 0.047379575 | AK23: 2026 | AL23: S01 | AM23: 0.46615 | AN23: hydro
I24: elc_spv_002 | J24: S02aH02 | K24: 0.0047860789 | L24: IMPNRGZ | N24: elc_won_002 | O24: S02aH02 | P24: 0.002011143 | Q24: IMPNRGZ | S24: elc_wof_002 | T24: S02aH02 | U24: 0.0058884786 | V24: IMPNRGZ | AC24: elc_industry | AD24: S02aH02 | AE24: 0.0026553477 | AK24: 2026 | AL24: S02 | AM24: 0.4533 | AN24: hydro
I25: elc_spv_002 | J25: S02aH03 | K25: 0 | L25: IMPNRGZ | N25: elc_won_002 | O25: S02aH03 | P25: 0.011633486 | Q25: IMPNRGZ | S25: elc_wof_002 | T25: S02aH03 | U25: 0.018761422 | V25: IMPNRGZ | AC25: elc_industry | AD25: S02aH03 | AE25: 0.01297974 | AK25: 2026 | AL25: S03 | AM25: 0.44836364 | AN25: hydro
I26: elc_spv_002 | J26: S03aH01 | K26: 0.78140618 | L26: IMPNRGZ | N26: elc_won_002 | O26: S03aH01 | P26: 0.59081334 | Q26: IMPNRGZ | S26: elc_wof_002 | T26: S03aH01 | U26: 0.58781749 | V26: IMPNRGZ | AC26: elc_industry | AD26: S03aH01 | AE26: 0.63453612 | AK26: 2027 | AL26: S01 | AM26: 0.5 | AN26: hydro
I27: elc_spv_002 | J27: S03aH02 | K27: 0.042620519 | L27: IMPNRGZ | N27: elc_won_002 | O27: S03aH02 | P27: 0.062845786 | Q27: IMPNRGZ | S27: elc_wof_002 | T27: S03aH02 | U27: 0.042505344 | V27: IMPNRGZ | AC27: elc_industry | AD27: S03aH02 | AE27: 0.035569048 | AK27: 2027 | AL27: S02 | AM27: 0.4404 | AN27: hydro
I28: elc_spv_002 | J28: S03aH03 | K28: 0 | L28: IMPNRGZ | N28: elc_won_002 | O28: S03aH03 | P28: 0.29671013 | Q28: IMPNRGZ | S28: elc_wof_002 | T28: S03aH03 | U28: 0.20516903 | V28: IMPNRGZ | AC28: elc_industry | AD28: S03aH03 | AE28: 0.17372249 | AK28: 2027 | AL28: S03 | AM28: 0.50137273 | AN28: hydro
I29: elc_spv_003 | J29: S01aH01 | K29: 0.10071622 | L29: IMPNRGZ | N29: elc_won_003 | O29: S01aH01 | P29: 0.053710075 | Q29: IMPNRGZ | S29: elc_wof_003 | T29: S01aH01 | U29: 0.045982469 | V29: IMPNRGZ | AK29: 2028 | AL29: S01 | AM29: 0.5176 | AN29: hydro
I30: elc_spv_003 | J30: S01aH02 | K30: 0.0033038511 | L30: IMPNRGZ | N30: elc_won_003 | O30: S01aH02 | P30: 0.0060226857 | Q30: IMPNRGZ | S30: elc_wof_003 | T30: S01aH02 | U30: 0.0055421997 | V30: IMPNRGZ | AK30: 2028 | AL30: S02 | AM30: 0.4516 | AN30: hydro
I31: elc_spv_003 | J31: S01aH03 | K31: 0 | L31: IMPNRGZ | N31: elc_won_003 | O31: S01aH03 | P31: 0.025678341 | Q31: IMPNRGZ | S31: elc_wof_003 | T31: S01aH03 | U31: 0.023766074 | V31: IMPNRGZ | AK31: 2028 | AL31: S03 | AM31: 0.50320909 | AN31: hydro
I32: elc_spv_003 | J32: S02aH01 | K32: 0.071829742 | L32: IMPNRGZ | N32: elc_won_003 | O32: S02aH01 | P32: 0.032912332 | Q32: IMPNRGZ | S32: elc_wof_003 | T32: S02aH01 | U32: 0.026230371 | V32: IMPNRGZ | AK32: 2029 | AL32: S01 | AM32: 0.49625 | AN32: hydro
I33: elc_spv_003 | J33: S02aH02 | K33: 0.0026420832 | L33: IMPNRGZ | N33: elc_won_003 | O33: S02aH02 | P33: 0.004338549 | Q33: IMPNRGZ | S33: elc_wof_003 | T33: S02aH02 | U33: 0.0038354233 | V33: IMPNRGZ | AK33: 2029 | AL33: S02 | AM33: 0.486 | AN33: hydro
I34: elc_spv_003 | J34: S02aH03 | K34: 0 | L34: IMPNRGZ | N34: elc_won_003 | O34: S02aH03 | P34: 0.016820205 | Q34: IMPNRGZ | S34: elc_wof_003 | T34: S02aH03 | U34: 0.014800439 | V34: IMPNRGZ | AK34: 2029 | AL34: S03 | AM34: 0.51837273 | AN34: hydro
I35: elc_spv_003 | J35: S03aH01 | K35: 0.80860366 | L35: IMPNRGZ | N35: elc_won_003 | O35: S03aH01 | P35: 0.60671398 | Q35: IMPNRGZ | S35: elc_wof_003 | T35: S03aH01 | U35: 0.61614448 | V35: IMPNRGZ | AK35: 2030 | AL35: S01 | AM35: 0.51685 | AN35: hydro
I36: elc_spv_003 | J36: S03aH02 | K36: 0.012904448 | L36: IMPNRGZ | N36: elc_won_003 | O36: S03aH02 | P36: 0.044190619 | Q36: IMPNRGZ | S36: elc_wof_003 | T36: S03aH02 | U36: 0.045565156 | V36: IMPNRGZ | AK36: 2030 | AL36: S02 | AM36: 0.4944 | AN36: hydro
I37: elc_spv_003 | J37: S03aH03 | K37: 0 | L37: IMPNRGZ | N37: elc_won_003 | O37: S03aH03 | P37: 0.20961321 | Q37: IMPNRGZ | S37: elc_wof_003 | T37: S03aH03 | U37: 0.21813339 | V37: IMPNRGZ | AK37: 2030 | AL37: S03 | AM37: 0.51977273 | AN37: hydro
I38: elc_spv_004 | J38: S01aH01 | K38: 0.097668244 | L38: IMPNRGZ | N38: elc_won_004 | O38: S01aH01 | P38: 0.014212469 | Q38: IMPNRGZ | S38: elc_wof_004 | T38: S01aH01 | U38: 0.037011482 | V38: IMPNRGZ | AK38: 2031 | AL38: S01 | AM38: 0.45355 | AN38: hydro
I39: elc_spv_004 | J39: S01aH02 | K39: 0.0040787707 | L39: IMPNRGZ | N39: elc_won_004 | O39: S01aH02 | P39: 0.0032882191 | Q39: IMPNRGZ | S39: elc_wof_004 | T39: S01aH02 | U39: 0.0057504799 | V39: IMPNRGZ | AK39: 2031 | AL39: S02 | AM39: 0.4057 | AN39: hydro
I40: elc_spv_004 | J40: S01aH03 | K40: 0 | L40: IMPNRGZ | N40: elc_won_004 | O40: S01aH03 | P40: 0.018204428 | Q40: IMPNRGZ | S40: elc_wof_004 | T40: S01aH03 | U40: 0.024727632 | V40: IMPNRGZ | AK40: 2031 | AL40: S03 | AM40: 0.44169091 | AN40: hydro
... I97: elc_spv_010 | J97: S02aH03 | K97: 0 | L97: IMPNRGZ | N97: elc_won_010 | O97: S02aH03 | P97: 0.01326621 | Q97: IMPNRGZ | S97: elc_wof_010 | T97: S02aH03 | U97: 0.019346287 | V97: IMPNRGZ | AK97: 2050 | AL97: S03 | AM97: 0.37511818 | AN97: hydro
I98: elc_spv_010 | J98: S03aH01 | K98: 0.79185008 | L98: IMPNRGZ | N98: elc_won_010 | O98: S03aH01 | P98: 0.61994835 | Q98: IMPNRGZ | S98: elc_wof_010 | T98: S03aH01 | U98: 0.56920264 | V98: IMPNRGZ
I99: elc_spv_010 | J99: S03aH02 | K99: 0.014709913 | L99: IMPNRGZ | N99: elc_won_010 | O99: S03aH02 | P99: 0.031331137 | Q99: IMPNRGZ | S99: elc_wof_010 | T99: S03aH02 | U99: 0.041691104 | V99: IMPNRGZ
I100: elc_spv_010 | J100: S03aH03 | K100: 0 | L100: IMPNRGZ | N100: elc_won_010 | O100: S03aH03 | P100: 0.23253131 | Q100: IMPNRGZ | S100: elc_wof_010 | T100: S03aH03 | U100: 0.22364445 | V100: IMPNRGZ
I101: elc_spv_011 | J101: S01aH01 | K101: 0.099465467 | L101: IMPNRGZ | N101: elc_won_011 | O101: S01aH01 | P101: 0.042907053 | Q101: IMPNRGZ
I102: elc_spv_011 | J102: S01aH02 | K102: 0.0032504077 | L102: IMPNRGZ | N102: elc_won_011 | O102: S01aH02 | P102: 0.0029872882 | Q102: IMPNRGZ
I103: elc_spv_011 | J103: S01aH03 | K103: 0 | L103: IMPNRGZ | N103: elc_won_011 | O103: S01aH03 | P103: 0.018419096 | Q103: IMPNRGZ
I104: elc_spv_011 | J104: S02aH01 | K104: 0.074212678 | L104: IMPNRGZ | N104: elc_won_011 | O104: S02aH01 | P104: 0.044288078 | Q104: IMPNRGZ
...

Sheet ts_030
C9: =IF(A11="x","DeActivated","~TimeSlices") -> DeActivated | I9: =IF(A11="x","DeActivated","~TFM_DINS-AT") -> DeActivated | N9: =IF(A11="x","DeActivated","~TFM_DINS-AT") -> DeActivated | S9: =IF(A11="x","DeActivated","~TFM_DINS-AT") -> DeActivated | X9: =IF(A11="x","DeActivated","~TFM_DINS-AT") -> DeActivated | AC9: =IF(A11="x","DeActivated","~TFM_DINS-AT") -> DeActivated | AG9: =IF(A11="x","DeActivated","~TFM_DINS-AT") -> DeActivated | AK9: =IF(A11="x","DeActivated","~TFM_INS-AT") -> DeActivated
A10: ts_030 | C10: season | D10: weekly | E10: daynite | F10: wparent | G10: dparent | I10: commodity | J10: timeslice | K10: com_fr | L10: process | N10: commodity | O10: timeslice | P10: com_fr | Q10: process | S10: commodity | T10: timeslice | U10: com_fr | V10: process | X10: g_yrfr | Y10: com_fr | Z10: timeslice | AA10: commodity | AC10: commodity | AD10: timeslice | AE10: com_fr | AG10: commodity | AH10: timeslice | AI10: com_pkflx | AK10: Year | AL10: timeslice | AM10: ncap_afs | AN10: pset_ci
A11: =IFERROR(IF(Veda!D5=A10,"ok","x"),"") -> x | C11: S01 | D11: a | E11: H01 | F11: S01,S02,S03,S04,S05 | G11: a | I11: elc_spv_001 | J11: S01aH01 | K11: 0.0086115512 | L11: IMPNRGZ | N11: elc_won_001 | O11: S01aH01 | P11: 0.0041054165 | Q11: IMPNRGZ | S11: elc_wof_001 | T11: S01aH01 | U11: 0.026323444 | V11: IMPNRGZ | X11: 0.034931507 | Y11: 0.022169074 | Z11: S01aH01 | AA11: elc_roadtransport | AC11: elc_buildings | AD11: S01aH01 | AE11: 0.031922668 | AG11: ELC | AH11: S01aH01 | AI11: 0.15119597 | AK11: 2020 | AL11: S01 | AM11: 0.5719863 | AN11: hydro
C12: S02 | E12: H02 | G12: a | I12: elc_spv_001 | J12: S01aH02 | K12: 0.0099742728 | L12: IMPNRGZ | N12: elc_won_001 | O12: S01aH02 | P12: 0.0011465929 | Q12: IMPNRGZ | S12: elc_wof_001 | T12: S01aH02 | U12: 0.0029778699 | V12: IMPNRGZ | X12: 0.0038812785 | Y12: 0.0049139381 | Z12: S01aH02 | AA12: elc_roadtransport | AC12: elc_buildings | AD12: S01aH02 | AE12: 0.0044686703 | AG12: ELC | AH12: S01aH02 | AI12: 0.017442703 | AK12: 2020 | AL12: S02 | AM12: 0.57471264 | AN12: hydro
C13: S03 | E13: H03 | G13: a | I13: elc_spv_001 | J13: S01aH03 | K13: 0.089491835 | L13: IMPNRGZ | N13: elc_won_001 | O13: S01aH03 | P13: 0.023412168 | Q13: IMPNRGZ | S13: elc_wof_001 | T13: S01aH03 | U13: 0.03818103 | V13: IMPNRGZ | X13: 0.031050228 | Y13: 0.045555362 | Z13: S01aH03 | AA13: elc_roadtransport | AC13: elc_buildings | AD13: S01aH03 | AE13: 0.037960556 | AG13: ELC | AH13: S01aH03 | AI13: 0.092947919 | AK13: 2020 | AL13: S03 | AM13: 0.56284761 | AN13: hydro
C14: S04 | E14: H04 | G14: a | I14: elc_spv_001 | J14: S01aH04 | K14: 0.0065486123 | L14: IMPNRGZ | N14: elc_won_001 | O14: S01aH04 | P14: 0.0034366421 | Q14: IMPNRGZ | S14: elc_wof_001 | T14: S01aH04 | U14: 0.0065508266 | V14: IMPNRGZ | X14: 0.0038812785 | Y14: 0.0058606602 | Z14: S01aH04 | AA14: elc_roadtransport | AC14: elc_buildings | AD14: S01aH04 | AE14: 0.0048100278 | AG14: ELC | AH14: S01aH04 | AI14: 0.006243625 | AK14: 2020 | AL14: S04 | AM14: 0.63488299 | AN14: hydro
C15: S05 | E15: H05 | G15: a | I15: elc_spv_001 | J15: S01aH05 | K15: 0 | L15: IMPNRGZ | N15: elc_won_001 | O15: S01aH05 | P15: 0.013920381 | Q15: IMPNRGZ | S15: elc_wof_001 | T15: S01aH05 | U15: 0.030651623 | V15: IMPNRGZ | X15: 0.019406393 | Y15: 0.01465165 | Z15: S01aH05 | AA15: elc_roadtransport | AC15: elc_buildings | AD15: S01aH05 | AE15: 0.015236281 | AG15: ELC | AH15: S01aH05 | AI15: 0.16229552 | AK15: 2020 | AL15: S05 | AM15: 0.63251107 | AN15: hydro
I16: elc_spv_001 | J16: S02aH01 | K16: 0.0053920995 | L16: IMPNRGZ | N16: elc_won_001 | O16: S02aH01 | P16: 0.0014738265 | Q16: IMPNRGZ | S16: elc_wof_001 | T16: S02aH01 | U16: 0.01209963 | V16: IMPNRGZ | X16: 0.023630137 | Y16: 0.014996727 | Z16: S02aH01 | AA16: elc_roadtransport | AC16: elc_buildings | AD16: S02aH01 | AE16: 0.021319483 | AG16: ELC | AH16: S02aH01 | AI16: 0.13947007 | AK16: 2021 | AL16: S01 | AM16: 0.50012503 | AN16: hydro
I17: elc_spv_001 | J17: S02aH02 | K17: 0.0071635028 | L17: IMPNRGZ | N17: elc_won_001 | O17: S02aH02 | P17: 0.00047205602 | Q17: IMPNRGZ | S17: elc_wof_001 | T17: S02aH02 | U17: 0.001050741 | V17: IMPNRGZ | X17: 0.0026255708 | Y17: 0.0033241346 | Z17: S02aH02 | AA17: elc_roadtransport | AC17: elc_buildings | AD17: S02aH02 | AE17: 0.0029670512 | AG17: ELC | AH17: S02aH02 | AI17: 0.0055067933 | AK17: 2021 | AL17: S02 | AM17: 0.48449612 | AN17: hydro
I18: elc_spv_001 | J18: S02aH03 | K18: 0.063350408 | L18: IMPNRGZ | N18: elc_won_001 | O18: S02aH03 | P18: 0.020218808 | Q18: IMPNRGZ | S18: elc_wof_001 | T18: S02aH03 | U18: 0.022156761 | V18: IMPNRGZ | X18: 0.021004566 | Y18: 0.030816863 | Z18: S02aH03 | AA18: elc_roadtransport | AC18: elc_buildings | AD18: S02aH03 | AE18: 0.025296454 | AG18: ELC | AH18: S02aH03 | AI18: 0.10034819 | AK18: 2021 | AL18: S03 | AM18: 0.48126615 | AN18: hydro
I19: elc_spv_001 | J19: S02aH04 | K19: 0.0048689097 | L19: IMPNRGZ | N19: elc_won_001 | O19: S02aH04 | P19: 0.0044843119 | Q19: IMPNRGZ | S19: elc_wof_001 | T19: S02aH04 | U19: 0.004541889 | V19: IMPNRGZ | X19: 0.0026255708 | Y19: 0.0039645642 | Z19: S02aH04 | AA19: elc_roadtransport | AC19: elc_buildings | AD19: S02aH04 | AE19: 0.0032027536 | AG19: ELC | AH19: S02aH04 | AI19: 0.016639012 | AK19: 2021 | AL19: S04 | AM19: 0.49986455 | AN19: hydro
I20: elc_spv_001 | J20: S02aH05 | K20: 0 | L20: IMPNRGZ | N20: elc_won_001 | O20: S02aH05 | P20: 0.018637868 | Q20: IMPNRGZ | S20: elc_wof_001 | T20: S02aH05 | U20: 0.019759126 | V20: IMPNRGZ | X20: 0.013127854 | Y20: 0.0099114106 | Z20: S02aH05 | AA20: elc_roadtransport | AC20: elc_buildings | AD20: S02aH05 | AE20: 0.010264171 | AG20: ELC | AH20: S02aH05 | AI20: 0.16609113 | AK20: 2021 | AL20: S05 | AM20: 0.53138285 | AN20: hydro
I21: elc_spv_001 | J21: S03aH01 | K21: 0.068533942 | L21: IMPNRGZ | N21: elc_won_001 | O21: S03aH01 | P21: 0.084198002 | Q21: IMPNRGZ | S21: elc_wof_001 | T21: S03aH01 | U21: 0.2625732 | V21: IMPNRGZ | X21: 0.27842466 | Y21: 0.17670056 | Z21: S03aH01 | AA21: elc_roadtransport | AC21: elc_buildings | AD21: S03aH01 | AE21: 0.25139219 | AG21: ELC | AH21: S03aH01 | AI21: 0.16199877 | AK21: 2022 | AL21: S01 | AM21: 0.45770371 | AN21: hydro
I22: elc_spv_001 | J22: S03aH02 | K22: 0.057470568 | L22: IMPNRGZ | N22: elc_won_001 | O22: S03aH02 | P22: 0.026615458 | Q22: IMPNRGZ | S22: elc_wof_001 | T22: S03aH02 | U22: 0.026876549 | V22: IMPNRGZ | X22: 0.030936073 | Y22: 0.039166977 | Z22: S03aH02 | AA22: elc_roadtransport | AC22: elc_buildings | AD22: S03aH02 | AE22: 0.035184424 | AG22: ELC | AH22: S03aH02 | AI22: 0.027859577 | AK22: 2022 | AL22: S02 | AM22: 0.41528239 | AN22: hydro
I23: elc_spv_001 | J23: S03aH03 | K23: 0.52627535 | L23: IMPNRGZ | N23: elc_won_001 | O23: S03aH03 | P23: 0.38712103 | Q23: IMPNRGZ | S23: elc_wof_001 | T23: S03aH03 | U23: 0.24788968 | V23: IMPNRGZ | X23: 0.24748858 | Y23: 0.36310303 | Z23: S03aH03 | AA23: elc_roadtransport | AC23: elc_buildings | AD23: S03aH03 | AE23: 0.29797638 | AG23: ELC | AH23: S03aH03 | AI23: 0.11063604 | AK23: 2022 | AL23: S03 | AM23: 0.39661701 | AN23: hydro
I24: elc_spv_001 | J24: S03aH04 | K24: 0.026604329 | L24: IMPNRGZ | N24: elc_won_001 | O24: S03aH04 | P24: 0.092983355 | Q24: IMPNRGZ | S24: elc_wof_001 | T24: S03aH04 | U24: 0.038013842 | V24: IMPNRGZ | X24: 0.030936073 | Y24: 0.046712909 | Z24: S03aH04 | AA24: elc_roadtransport | AC24: elc_buildings | AD24: S03aH04 | AE24: 0.03786363 | AG24: ELC | AH24: S03aH04 | AI24: 0.019974388 | AK24: 2022 | AL24: S04 | AM24: 0.35764149 | AN24: hydro
I25: elc_spv_001 | J25: S03aH05 | K25: 0 | L25: IMPNRGZ | N25: elc_won_001 | O25: S03aH05 | P25: 0.27158053 | Q25: IMPNRGZ | S25: elc_wof_001 | T25: S03aH05 | U25: 0.20208471 | V25: IMPNRGZ | X25: 0.15468037 | Y25: 0.11678227 | Z25: S03aH05 | AA25: elc_roadtransport | AC25: elc_buildings | AD25: S03aH05 | AE25: 0.11932031 | AG25: ELC | AH25: S03aH05 | AI25: 0.18524729 | AK25: 2022 | AL25: S05 | AM25: 0.34383596 | AN25: hydro
I26: elc_spv_001 | J26: S04aH01 | K26: 0.011489434 | L26: IMPNRGZ | N26: elc_won_001 | O26: S04aH01 | P26: 0.0023177459 | Q26: IMPNRGZ | S26: elc_wof_001 | T26: S04aH01 | U26: 0.0084587063 | V26: IMPNRGZ | X26: 0.030821918 | Y26: 0.019560948 | Z26: S04aH01 | AA26: elc_roadtransport | AC26: elc_buildings | AD26: S04aH01 | AE26: 0.027854169 | AG26: ELC | AH26: S04aH01 | AI26: 0.16011501 | AK26: 2025 | AL26: S01 | AM26: 0.38775 | AN26: hydro
I27: elc_spv_001 | J27: S04aH02 | K27: 0.0090021299 | L27: IMPNRGZ | N27: elc_won_001 | O27: S04aH02 | P27: 0.00051044249 | Q27: IMPNRGZ | S27: elc_wof_001 | T27: S04aH02 | U27: 0.00074439126 | V27: IMPNRGZ | X27: 0.0034246575 | Y27: 0.0043358278 | Z27: S04aH02 | AA27: elc_roadtransport | AC27: elc_buildings | AD27: S04aH02 | AE27: 0.0038811182 | AG27: ELC | AH27: S04aH02 | AI27: 0.029760919 | AK27: 2025 | AL27: S02 | AM27: 0.3435 | AN27: hydro
... I35: elc_spv_001 | J35: S05aH05 | K35: 0 | L35: IMPNRGZ | N35: elc_won_001 | O35: S05aH05 | P35: 0.002937415 | Q35: IMPNRGZ | S35: elc_wof_001 | T35: S05aH05 | U35: 0.0063770729 | V35: IMPNRGZ | X35: 0.0039954338 | Y35: 0.0030165163 | Z35: S05aH05 | AA35: elc_roadtransport | AC35: elc_buildings | AD35: S05aH05 | AE35: 0.0030397428 | AG35: ELC | AH35: S05aH05 | AI35: 0.1721876 | AK35: 2026 | AL35: S05 | AM35: 0.5032 | AN35: hydro
I36: elc_spv_002 | J36: S01aH01 | K36: 0.010240022 | L36: IMPNRGZ | N36: elc_won_002 | O36: S01aH01 | P36: 0.0079867119 | Q36: IMPNRGZ | S36: elc_wof_002 | T36: S01aH01 | U36: 0.02027061 | V36: IMPNRGZ | AC36: elc_industry | AD36: S01aH01 | AE36: 0.034754543 | AK36: 2027 | AL36: S01 | AM36: 0.5 | AN36: hydro
I37: elc_spv_002 | J37: S01aH02 | K37: 0.0081538515 | L37: IMPNRGZ | N37: elc_won_002 | O37: S01aH02 | P37: 0.00014434437 | Q37: IMPNRGZ | S37: elc_wof_002 | T37: S01aH02 | U37: 0.002473831 | V37: IMPNRGZ | AC37: elc_industry | AD37: S01aH02 | AE37: 0.0039092272 | AK37: 2027 | AL37: S02 | AM37: 0.4404 | AN37: hydro
I38: elc_spv_002 | J38: S01aH03 | K38: 0.080968882 | L38: IMPNRGZ | N38: elc_won_002 | O38: S01aH03 | P38: 0.0057859794 | Q38: IMPNRGZ | S38: elc_wof_002 | T38: S01aH03 | U38: 0.041732031 | V38: IMPNRGZ | AC38: elc_industry | AD38: S01aH03 | AE38: 0.031388038 | AK38: 2027 | AL38: S03 | AM38: 0.49982 | AN38: hydro
I39: elc_spv_002 | J39: S01aH04 | K39: 0.0065900518 | L39: IMPNRGZ | N39: elc_won_002 | O39: S01aH04 | P39: 0.0011537261 | Q39: IMPNRGZ | S39: elc_wof_002 | T39: S01aH04 | U39: 0.0075925805 | V39: IMPNRGZ | AC39: elc_industry | AD39: S01aH04 | AE39: 0.0039268602 | AK39: 2027 | AL39: S04 | AM39: 0.52365 | AN39: hydro
I40: elc_spv_002 | J40: S01aH05 | K40: 0 | L40: IMPNRGZ | N40: elc_won_002 | O40: S01aH05 | P40: 0.0069677739 | Q40: IMPNRGZ | S40: elc_wof_002 | T40: S01aH05 | U40: 0.028928468 | V40: IMPNRGZ | AC40: elc_industry | AD40: S01aH05 | AE40: 0.019179016 | AK40: 2027 | AL40: S05 | AM40: 0.5169 | AN40: hydro
