Workbook

Sheet Veda
G1: 1,2,3,4,5,6,7,8,9,10,11,12,13,14,15,21,22,23,24,25,31,32,33,34,35,36,37,38,39,40,41,42,43,44,45,46,47,48,49,50,56,57,58,59,60,66,67,68,69,70
D2: ="~Inputcell: "&_xlfn.TEXTJOIN(",",TRUE,G1:EE1) -> ~Inputcell: 1,2,3,4,5,6,7,8,9,10,11,12,13,14,15,21,22,23,24,25,31,32,33,34,35,36,37,38,39,40,41,42,43,44,45,46,47,48,49,50,56,57,58,59,60,66,67,68,69,70 | G2: 5 | H2: 6 | I2: 7 | J2: 9 | K2: 10 | L2: 11 | M2: 16 | N2: 17 | O2: 18 | P2: 20 | Q2: 21 | R2: 22 | S2: 27 | T2: 28 | U2: 29 | V2: 31 | W2: 32 | X2: 33 | Y2: 38 | Z2: 39 | AA2: 40 | AB2: 42 | AC2: 43 | AD2: 44 | AE2: 49 | AF2: 50 | AG2: 51 | AH2: 53 | AI2: 54 | AJ2: 55
D3: 3
D5: =VLOOKUP(D3,$C$9:$E$999,2,FALSE) -> ts_annual | E5: =VLOOKUP(D3,$C$9:$E$999,3,FALSE) -> C3
B7: ~Scenmap
A8: priority | B8: scen | C8: case_no | D8: timeslice | E8: climate
A9: 5 | B9: =VLOOKUP(E9,$AK$9:$AL$15,2,FALSE)&"."&VLOOKUP(D9,$AH$9:$AI$24,2,FALSE) -> e 1.5 deg no OS.kAnn | C9: 1 | D9: =VLOOKUP(AJ9,$AG$9:$AH$22,2,FALSE) -> ts_annual | E9: C1 | G9: Limit warming to 1.5°C (>50%) with no or limited overshoot | AG9: 1 | AH9: ts_annual | AI9: kAnn | AJ9: 1 | AK9: C1 | AL9: e 1.5 deg no OS
A10: 5 | B10: =VLOOKUP(E10,$AK$9:$AL$15,2,FALSE)&"."&VLOOKUP(D10,$AH$9:$AI$24,2,FALSE) -> d 1.5 deg OS.kAnn | C10: =C9+1 -> 2 | D10: =VLOOKUP(AJ10,$AG$9:$AH$22,2,FALSE) -> ts_annual | E10: C2 | G10: Limit warming to 1.5°C (>67%) with high overshoot | S10: IEA | AG10: 2 | AH10: ts_12t | AI10: k12 | AJ10: 1 | AK10: C2 | AL10: d 1.5 deg OS
A11: 5 | B11: =VLOOKUP(E11,$AK$9:$AL$15,2,FALSE)&"."&VLOOKUP(D11,$AH$9:$AI$24,2,FALSE) -> c 2 deg (67%).kAnn | C11: =C10+1 -> 3 | D11: =VLOOKUP(AJ11,$AG$9:$AH$22,2,FALSE) -> ts_annual | E11: C3 | G11: Limit warming to 2°C (>67%) with higher action post-2030 | S11: 2022 | AG11: 3 | AH11: ts_012 | AI11: j12 | AJ11: 1 | AK11: C3 | AL11: c 2 deg (67%)
A12: 5 | B12: =VLOOKUP(E12,$AK$9:$AL$15,2,FALSE)&"."&VLOOKUP(D12,$AH$9:$AI$24,2,FALSE) -> b 2 deg (50%).kAnn | C12: =C11+1 -> 4 | D12: =VLOOKUP(AJ12,$AG$9:$AH$22,2,FALSE) -> ts_annual | E12: C4 | G12: Limit warming to 2°C (>50%) with immediate action | S12: =SUMIFS(iea_data!I3:I9999,iea_data!$B$3:$B$9999,Veda!$S$11)+T28-T29 -> 325.04 | T12: base-year generation (TWh) | AG12: 4 | AH12: ts_024 | AI12: i24 | AJ12: 1 | AK12: C4 | AL12: b 2 deg (50%)
A13: 5 | B13: =VLOOKUP(E13,$AK$9:$AL$15,2,FALSE)&"."&VLOOKUP(D13,$AH$9:$AI$24,2,FALSE) -> a 3 deg.kAnn | C13: =C12+1 -> 5 | D13: =VLOOKUP(AJ13,$AG$9:$AH$22,2,FALSE) -> ts_annual | E13: C7 | G13: Likely above 3°C warming with limited mitigation | AG13: 5 | AH13: ts_048 | AI13: h48 | AJ13: 1 | AK13: C7 | AL13: a 3 deg
A14: 5 | B14: =VLOOKUP(E14,$AK$9:$AL$15,2,FALSE)&"."&VLOOKUP(D14,$AH$9:$AI$24,2,FALSE) -> e 1.5 deg no OS.k12 | C14: =C13+1 -> 6 | D14: =VLOOKUP(AJ14,$AG$9:$AH$22,2,FALSE) -> ts_12t | E14: =E9 -> C1 | T14: =S12 -> 325.04 | U14: =$S$12*J15 -> 341.292 | V14: =$S$12*K15 -> 380.2968 | W14: =$S$12*L15 -> 429.0528 | X14: =$S$12*M15 -> 487.56 | Y14: =$S$12*N15 -> 546.0672 | Z14: =$S$12*O15 -> 588.3224 | AG14: 6 | AH14: ts_064 | AI14: g64 | AJ14: =AJ9+1 -> 2
A15: 5 | B15: =VLOOKUP(E15,$AK$9:$AL$15,2,FALSE)&"."&VLOOKUP(D15,$AH$9:$AI$24,2,FALSE) -> d 1.5 deg OS.k12 | C15: =C14+1 -> 7 | D15: =VLOOKUP(AJ15,$AG$9:$AH$22,2,FALSE) -> ts_12t | E15: =E10 -> C2 | G15: Electricity growth relative to 2020 | I15: =SUMIFS(ar6_r10!$F$2:$F$999,ar6_r10!$A$2:$A$999,Veda!$E$5,ar6_r10!$C$2:$C$999,Veda!I$17,ar6_r10!$M$2:$M$999,Veda!$G15) -> 1 | J15: =SUMIFS(ar6_r10!$F$2:$F$999,ar6_r10!$A$2:$A$999,Veda!$E$5,ar6_r10!$C$2:$C$999,Veda!J$17,ar6_r10!$M$2:$M$999,Veda!$G15) -> 1.05 | K15: =SUMIFS(ar6_r10!$F$2:$F$999,ar6_r10!$A$2:$A$999,Veda!$E$5,ar6_r10!$C$2:$C$999,Veda!K$17,ar6_r10!$M$2:$M$999,Veda!$G15) -> 1.17 | L15: =SUMIFS(ar6_r10!$F$2:$F$999,ar6_r10!$A$2:$A$999,Veda!$E$5,ar6_r10!$C$2:$C$999,Veda!L$17,ar6_r10!$M$2:$M$999,Veda!$G15) -> 1.32 | M15: =SUMIFS(ar6_r10!$F$2:$F$999,ar6_r10!$A$2:$A$999,Veda!$E$5,ar6_r10!$C$2:$C$999,Veda!M$17,ar6_r10!$M$2:$M$999,Veda!$G15) -> 1.5 | N15: =SUMIFS(ar6_r10!$F$2:$F$999,ar6_r10!$A$2:$A$999,Veda!$E$5,ar6_r10!$C$2:$C$999,Veda!N$17,ar6_r10!$M$2:$M$999,Veda!$G15) -> 1.68 | O15: =SUMIFS(ar6_r10!$F$2:$F$999,ar6_r10!$A$2:$A$999,Veda!$E$5,ar6_r10!$C$2:$C$999,Veda!O$17,ar6_r10!$M$2:$M$999,Veda!$G15) -> 1.81 | AG15: 7 | AH15: ts_096P50 | AI15: f96p50 | AJ15: =AJ10+1 -> 2
A16: 5 | B16: =VLOOKUP(E16,$AK$9:$AL$15,2,FALSE)&"."&VLOOKUP(D16,$AH$9:$AI$24,2,FALSE) -> c 2 deg (67%).k12 | C16: =C15+1 -> 8 | D16: =VLOOKUP(AJ16,$AG$9:$AH$22,2,FALSE) -> ts_12t | E16: =E11 -> C3 | S16: ~TFM_INS-TS | AG16: 8 | AH16: ts_096P10 | AI16: f96p10 | AJ16: =AJ11+1 -> 2
A17: 5 | B17: =VLOOKUP(E17,$AK$9:$AL$15,2,FALSE)&"."&VLOOKUP(D17,$AH$9:$AI$24,2,FALSE) -> b 2 deg (50%).k12 | C17: =C16+1 -> 9 | D17: =VLOOKUP(AJ17,$AG$9:$AH$22,2,FALSE) -> ts_12t | E17: =E12 -> C4 | I17: 2020 | J17: =U17 -> 2025 | K17: =V17 -> 2030 | L17: =W17 -> 2035 | M17: =X17 -> 2040 | N17: =Y17 -> 2045 | O17: =Z17 -> 2050 | S17: commodity | T17: 2022 | U17: 2025 | V17: 2030 | W17: 2035 | X17: 2040 | Y17: 2045 | Z17: 2050 | AA17: attribute | AG17: 9 | AH17: ts_096P90 | AI17: f96p90 | AJ17: =AJ12+1 -> 2
A18: 5 | B18: =VLOOKUP(E18,$AK$9:$AL$15,2,FALSE)&"."&VLOOKUP(D18,$AH$9:$AI$24,2,FALSE) -> a 3 deg.k12 | C18: =C17+1 -> 10 | D18: =VLOOKUP(AJ18,$AG$9:$AH$22,2,FALSE) -> ts_12t | E18: =E13 -> C7 | G18: Hydrogen as a share of electricity | I18: =SUMIFS(ar6_r10!$F$2:$F$999,ar6_r10!$A$2:$A$999,Veda!$E$5,ar6_r10!$C$2:$C$999,Veda!I$17,ar6_r10!$M$2:$M$999,Veda!$G18) -> 0 | J18: =SUMIFS(ar6_r10!$F$2:$F$999,ar6_r10!$A$2:$A$999,Veda!$E$5,ar6_r10!$C$2:$C$999,Veda!J$17,ar6_r10!$M$2:$M$999,Veda!$G18) -> 0 | K18: =SUMIFS(ar6_r10!$F$2:$F$999,ar6_r10!$A$2:$A$999,Veda!$E$5,ar6_r10!$C$2:$C$999,Veda!K$17,ar6_r10!$M$2:$M$999,Veda!$G18) -> 0.01 | L18: =SUMIFS(ar6_r10!$F$2:$F$999,ar6_r10!$A$2:$A$999,Veda!$E$5,ar6_r10!$C$2:$C$999,Veda!L$17,ar6_r10!$M$2:$M$999,Veda!$G18) -> 0.01 | M18: =SUMIFS(ar6_r10!$F$2:$F$999,ar6_r10!$A$2:$A$999,Veda!$E$5,ar6_r10!$C$2:$C$999,Veda!M$17,ar6_r10!$M$2:$M$999,Veda!$G18) -> 0.01 | N18: =SUMIFS(ar6_r10!$F$2:$F$999,ar6_r10!$A$2:$A$999,Veda!$E$5,ar6_r10!$C$2:$C$999,Veda!N$17,ar6_r10!$M$2:$M$999,Veda!$G18) -> 0.02 | O18: =SUMIFS(ar6_r10!$F$2:$F$999,ar6_r10!$A$2:$A$999,Veda!$E$5,ar6_r10!$C$2:$C$999,Veda!O$17,ar6_r10!$M$2:$M$999,Veda!$G18) -> 0.03 | S18: hydrogen_allsect | T18: =I18*T$14 -> 0 | U18: =J18*U$14 -> 0 | V18: =K18*V$14 -> 3.802968 | W18: =L18*W$14 -> 4.290528 | X18: =M18*X$14 -> 4.8756 | Y18: =N18*Y$14 -> 10.921344 | Z18: =O18*Z$14 -> 17.649672 | AA18: demand | AG18: 10 | AH18: s1p1v1_d | AI18: e3d | AJ18: =AJ13+1 -> 2
A19: 5 | B19: =VLOOKUP(E19,$AK$9:$AL$15,2,FALSE)&"."&VLOOKUP(D19,$AH$9:$AI$24,2,FALSE) -> e 1.5 deg no OS.j12 | C19: =C18+1 -> 11 | D19: =VLOOKUP(AJ19,$AG$9:$AH$22,2,FALSE) -> ts_012 | E19: =E14 -> C1 | G19: Industry electricity share | I19: =SUMIFS(ar6_r10!$F$2:$F$999,ar6_r10!$A$2:$A$999,Veda!$E$5,ar6_r10!$C$2:$C$999,Veda!I$17,ar6_r10!$M$2:$M$999,Veda!$G19) -> 0.36 | J19: =SUMIFS(ar6_r10!$F$2:$F$999,ar6_r10!$A$2:$A$999,Veda!$E$5,ar6_r10!$C$2:$C$999,Veda!J$17,ar6_r10!$M$2:$M$999,Veda!$G19) -> 0.32 | K19: =SUMIFS(ar6_r10!$F$2:$F$999,ar6_r10!$A$2:$A$999,Veda!$E$5,ar6_r10!$C$2:$C$999,Veda!K$17,ar6_r10!$M$2:$M$999,Veda!$G19) -> 0.31 | L19: =SUMIFS(ar6_r10!$F$2:$F$999,ar6_r10!$A$2:$A$999,Veda!$E$5,ar6_r10!$C$2:$C$999,Veda!L$17,ar6_r10!$M$2:$M$999,Veda!$G19) -> 0.29 | M19: =SUMIFS(ar6_r10!$F$2:$F$999,ar6_r10!$A$2:$A$999,Veda!$E$5,ar6_r10!$C$2:$C$999,Veda!M$17,ar6_r10!$M$2:$M$999,Veda!$G19) -> 0.29 | N19: =SUMIFS(ar6_r10!$F$2:$F$999,ar6_r10!$A$2:$A$999,Veda!$E$5,ar6_r10!$C$2:$C$999,Veda!N$17,ar6_r10!$M$2:$M$999,Veda!$G19) -> 0.29 | O19: =SUMIFS(ar6_r10!$F$2:$F$999,ar6_r10!$A$2:$A$999,Veda!$E$5,ar6_r10!$C$2:$C$999,Veda!O$17,ar6_r10!$M$2:$M$999,Veda!$G19) -> 0.3 | S19: elc_industry | T19: =I19*T$14 -> 117.0144 | U19: =J19*U$14 -> 109.21344 | V19: =K19*V$14 -> 117.89201 | W19: =L19*W$14 -> 124.42531 | X19: =M19*X$14 -> 141.3924 | Y19: =N19*Y$14 -> 158.35949 | Z19: =O19*Z$14 -> 176.49672 | AA19: demand | AG19: 11 | AH19: s3p3v3_d | AI19: d9d | AJ19: =AJ14+1 -> 3
A20: 5 | B20: =VLOOKUP(E20,$AK$9:$AL$15,2,FALSE)&"."&VLOOKUP(D20,$AH$9:$AI$24,2,FALSE) -> d 1.5 deg OS.j12 | C20: =C19+1 -> 12 | D20: =VLOOKUP(AJ20,$AG$9:$AH$22,2,FALSE) -> ts_012 | E20: =E15 -> C2 | G20: Residential and commercial electricity share | I20: =SUMIFS(ar6_r10!$F$2:$F$999,ar6_r10!$A$2:$A$999,Veda!$E$5,ar6_r10!$C$2:$C$999,Veda!I$17,ar6_r10!$M$2:$M$999,Veda!$G20) -> 0.6 | J20: =SUMIFS(ar6_r10!$F$2:$F$999,ar6_r10!$A$2:$A$999,Veda!$E$5,ar6_r10!$C$2:$C$999,Veda!J$17,ar6_r10!$M$2:$M$999,Veda!$G20) -> 0.6 | K20: =SUMIFS(ar6_r10!$F$2:$F$999,ar6_r10!$A$2:$A$999,Veda!$E$5,ar6_r10!$C$2:$C$999,Veda!K$17,ar6_r10!$M$2:$M$999,Veda!$G20) -> 0.6 | L20: =SUMIFS(ar6_r10!$F$2:$F$999,ar6_r10!$A$2:$A$999,Veda!$E$5,ar6_r10!$C$2:$C$999,Veda!L$17,ar6_r10!$M$2:$M$999,Veda!$G20) -> 0.57 | M20: =SUMIFS(ar6_r10!$F$2:$F$999,ar6_r10!$A$2:$A$999,Veda!$E$5,ar6_r10!$C$2:$C$999,Veda!M$17,ar6_r10!$M$2:$M$999,Veda!$G20) -> 0.54 | N20: =SUMIFS(ar6_r10!$F$2:$F$999,ar6_r10!$A$2:$A$999,Veda!$E$5,ar6_r10!$C$2:$C$999,Veda!N$17,ar6_r10!$M$2:$M$999,Veda!$G20) -> 0.52 | O20: =SUMIFS(ar6_r10!$F$2:$F$999,ar6_r10!$A$2:$A$999,Veda!$E$5,ar6_r10!$C$2:$C$999,Veda!O$17,ar6_r10!$M$2:$M$999,Veda!$G20) -> 0.53 | S20: elc_buildings | T20: =I20*T$14 -> 195.024 | U20: =J20*U$14 -> 204.7752 | V20: =K20*V$14 -> 228.17808 | W20: =L20*W$14 -> 244.5601 | X20: =M20*X$14 -> 263.2824 | Y20: =N20*Y$14 -> 283.95494 | Z20: =O20*Z$14 -> 311.81087 | AA20: demand | AG20: 12 | AH20: s5p5v5_d | AI20: c15d | AJ20: =AJ15+1 -> 3
A21: 5 | B21: =VLOOKUP(E21,$AK$9:$AL$15,2,FALSE)&"."&VLOOKUP(D21,$AH$9:$AI$24,2,FALSE) -> c 2 deg (67%).j12 | C21: =C20+1 -> 13 | D21: =VLOOKUP(AJ21,$AG$9:$AH$22,2,FALSE) -> ts_012 | E21: =E16 -> C3 | G21: Transportation electricity share | I21: =SUMIFS(ar6_r10!$F$2:$F$999,ar6_r10!$A$2:$A$999,Veda!$E$5,ar6_r10!$C$2:$C$999,Veda!I$17,ar6_r10!$M$2:$M$999,Veda!$G21) -> 0.03 | J21: =SUMIFS(ar6_r10!$F$2:$F$999,ar6_r10!$A$2:$A$999,Veda!$E$5,ar6_r10!$C$2:$C$999,Veda!J$17,ar6_r10!$M$2:$M$999,Veda!$G21) -> 0.06 | K21: =SUMIFS(ar6_r10!$F$2:$F$999,ar6_r10!$A$2:$A$999,Veda!$E$5,ar6_r10!$C$2:$C$999,Veda!K$17,ar6_r10!$M$2:$M$999,Veda!$G21) -> 0.08 | L21: =SUMIFS(ar6_r10!$F$2:$F$999,ar6_r10!$A$2:$A$999,Veda!$E$5,ar6_r10!$C$2:$C$999,Veda!L$17,ar6_r10!$M$2:$M$999,Veda!$G21) -> 0.11 | M21: =SUMIFS(ar6_r10!$F$2:$F$999,ar6_r10!$A$2:$A$999,Veda!$E$5,ar6_r10!$C$2:$C$999,Veda!M$17,ar6_r10!$M$2:$M$999,Veda!$G21) -> 0.12 | N21: =SUMIFS(ar6_r10!$F$2:$F$999,ar6_r10!$A$2:$A$999,Veda!$E$5,ar6_r10!$C$2:$C$999,Veda!N$17,ar6_r10!$M$2:$M$999,Veda!$G21) -> 0.18 | O21: =SUMIFS(ar6_r10!$F$2:$F$999,ar6_r10!$A$2:$A$999,Veda!$E$5,ar6_r10!$C$2:$C$999,Veda!O$17,ar6_r10!$M$2:$M$999,Veda!$G21) -> 0.19 | S21: elc_transport | T21: =I21*T$14 -> 9.7512 | U21: =T21 -> 9.7512 | V21: =U21 -> 9.7512 | W21: =V21 -> 9.7512 | X21: =W21 -> 9.7512 | Y21: =X21 -> 9.7512 | Z21: =Y21 -> 9.7512 | AA21: demand | AC21: non-road transport demand assumed to be constant | AG21: 13 | AH21: s2_w | AI21: b2w | AJ21: =AJ16+1 -> 3
A22: 5 | B22: =VLOOKUP(E22,$AK$9:$AL$15,2,FALSE)&"."&VLOOKUP(D22,$AH$9:$AI$24,2,FALSE) -> b 2 deg (50%).j12 | C22: =C21+1 -> 14 | D22: =VLOOKUP(AJ22,$AG$9:$AH$22,2,FALSE) -> ts_012 | E22: =E17 -> C4 | S22: elc_roadtransport | T22: =T14-SUM(T19:T21) -> 3.2504 | U22: =U14-SUM(U19:U21) -> 17.55216 | V22: =V14-SUM(V19:V21) -> 24.475512 | W22: =W14-SUM(W19:W21) -> 50.316192 | X22: =X14-SUM(X19:X21) -> 73.134 | Y22: =Y14-SUM(Y19:Y21) -> 94.001568 | Z22: =Z14-SUM(Z19:Z21) -> 90.263608 | AA22: demand | AG22: 14 | AH22: s2_w_p2_d | AI22: a2w2d | AJ22: =AJ17+1 -> 3
A23: 5 | B23: =VLOOKUP(E23,$AK$9:$AL$15,2,FALSE)&"."&VLOOKUP(D23,$AH$9:$AI$24,2,FALSE) -> a 3 deg.j12 | C23: =C22+1 -> 15 | D23: =VLOOKUP(AJ23,$AG$9:$AH$22,2,FALSE) -> ts_012 | E23: =E18 -> C7 | S23: * | AJ23: =AJ18+1 -> 3
A24: 5 | B24: =VLOOKUP(E24,$AK$9:$AL$15,2,FALSE)&"."&VLOOKUP(D24,$AH$9:$AI$24,2,FALSE) -> e 1.5 deg no OS.i24 | C24: =C23+1 -> 16 | D24: =VLOOKUP(AJ24,$AG$9:$AH$22,2,FALSE) -> ts_024 | E24: =E19 -> C1 | G24: CO2 price | I24: 0 | J24: 0 | K24: =SUMIFS(ar6_r10!$F$2:$F$999,ar6_r10!$A$2:$A$999,Veda!$E$5,ar6_r10!$C$2:$C$999,Veda!K$17,ar6_r10!$M$2:$M$999,Veda!$G24) -> 71.48 | L24: =SUMIFS(ar6_r10!$F$2:$F$999,ar6_r10!$A$2:$A$999,Veda!$E$5,ar6_r10!$C$2:$C$999,Veda!L$17,ar6_r10!$M$2:$M$999,Veda!$G24) -> 104.42 | M24: =SUMIFS(ar6_r10!$F$2:$F$999,ar6_r10!$A$2:$A$999,Veda!$E$5,ar6_r10!$C$2:$C$999,Veda!M$17,ar6_r10!$M$2:$M$999,Veda!$G24) -> 134.85 | N24: =SUMIFS(ar6_r10!$F$2:$F$999,ar6_r10!$A$2:$A$999,Veda!$E$5,ar6_r10!$C$2:$C$999,Veda!N$17,ar6_r10!$M$2:$M$999,Veda!$G24) -> 178.1 | O24: =SUMIFS(ar6_r10!$F$2:$F$999,ar6_r10!$A$2:$A$999,Veda!$E$5,ar6_r10!$C$2:$C$999,Veda!O$17,ar6_r10!$M$2:$M$999,Veda!$G24) -> 209.45 | S24: co2net | U24: 0 | V24: =K24/1000 -> 0.07148 | W24: =L24/1000 -> 0.10442 | X24: =M24/1000 -> 0.13485 | Y24: =N24/1000 -> 0.1781 | Z24: =O24/1000 -> 0.20945 | AA24: com_taxnet | AJ24: =AJ19+1 -> 4
A25: 5 | B25: =VLOOKUP(E25,$AK$9:$AL$15,2,FALSE)&"."&VLOOKUP(D25,$AH$9:$AI$24,2,FALSE) -> d 1.5 deg OS.i24 | C25: =C24+1 -> 17 | D25: =VLOOKUP(AJ25,$AG$9:$AH$22,2,FALSE) -> ts_024 | E25: =E20 -> C2 | AJ25: =AJ20+1 -> 4
A26: 5 | B26: =VLOOKUP(E26,$AK$9:$AL$15,2,FALSE)&"."&VLOOKUP(D26,$AH$9:$AI$24,2,FALSE) -> c 2 deg (67%).i24 | C26: =C25+1 -> 18 | D26: =VLOOKUP(AJ26,$AG$9:$AH$22,2,FALSE) -> ts_024 | E26: =E21 -> C3 | S26: ~TFM_INS-TS | AJ26: =AJ21+1 -> 4
A27: 5 | B27: =VLOOKUP(E27,$AK$9:$AL$15,2,FALSE)&"."&VLOOKUP(D27,$AH$9:$AI$24,2,FALSE) -> b 2 deg (50%).i24 | C27: =C26+1 -> 19 | D27: =VLOOKUP(AJ27,$AG$9:$AH$22,2,FALSE) -> ts_024 | E27: =E22 -> C4 | S27: process | T27: =T17 -> 2022 | U27: =U17 -> 2025 | V27: =V17 -> 2030 | W27: =W17 -> 2035 | X27: =X17 -> 2040 | Y27: =Y17 -> 2045 | Z27: =Z17 -> 2050 | AA27: attribute | AB27: limtype | AJ27: =AJ22+1 -> 4
A28: 5 | B28: =VLOOKUP(E28,$AK$9:$AL$15,2,FALSE)&"."&VLOOKUP(D28,$AH$9:$AI$24,2,FALSE) -> a 3 deg.i24 | C28: =C27+1 -> 20 | D28: =VLOOKUP(AJ28,$AG$9:$AH$22,2,FALSE) -> ts_024 | E28: =E23 -> C7 | Q28: =SUMIFS(iea_data!G3:G9999,iea_data!$B$3:$B$9999,Veda!$S$11) -> 47.39 | S28: Trd_electricity import | T28: =Q28 -> 47.39 | AA28: ACT_BND | AB28: FX | AJ28: =AJ23+1 -> 4
A29: 5 | B29: =VLOOKUP(E29,$AK$9:$AL$15,2,FALSE)&"."&VLOOKUP(D29,$AH$9:$AI$24,2,FALSE) -> e 1.5 deg no OS.h48 | C29: =C28+1 -> 21 | D29: =VLOOKUP(AJ29,$AG$9:$AH$22,2,FALSE) -> ts_048 | E29: =E24 -> C1 | Q29: =SUMIFS(iea_data!H3:H9999,iea_data!$B$3:$B$9999,Veda!$S$11) -> -4.4 | S29: Trd_electricity export | T29: =-1*Q29 -> 4.4 | AA29: ACT_BND | AB29: FX | AJ29: =AJ24+1 -> 5
A30: 5 | B30: =VLOOKUP(E30,$AK$9:$AL$15,2,FALSE)&"."&VLOOKUP(D30,$AH$9:$AI$24,2,FALSE) -> d 1.5 deg OS.h48 | C30: =C29+1 -> 22 | D30: =VLOOKUP(AJ30,$AG$9:$AH$22,2,FALSE) -> ts_048 | E30: =E25 -> C2 | AJ30: =AJ25+1 -> 5
A31: 5 | B31: =VLOOKUP(E31,$AK$9:$AL$15,2,FALSE)&"."&VLOOKUP(D31,$AH$9:$AI$24,2,FALSE) -> c 2 deg (67%).h48 | C31: =C30+1 -> 23 | D31: =VLOOKUP(AJ31,$AG$9:$AH$22,2,FALSE) -> ts_048 | E31: =E26 -> C3 | AJ31: =AJ26+1 -> 5
A32: 5 | B32: =VLOOKUP(E32,$AK$9:$AL$15,2,FALSE)&"."&VLOOKUP(D32,$AH$9:$AI$24,2,FALSE) -> b 2 deg (50%).h48 | C32: =C31+1 -> 24 | D32: =VLOOKUP(AJ32,$AG$9:$AH$22,2,FALSE) -> ts_048 | E32: =E27 -> C4 | AJ32: =AJ27+1 -> 5
A33: 5 | B33: =VLOOKUP(E33,$AK$9:$AL$15,2,FALSE)&"."&VLOOKUP(D33,$AH$9:$AI$24,2,FALSE) -> a 3 deg.h48 | C33: =C32+1 -> 25 | D33: =VLOOKUP(AJ33,$AG$9:$AH$22,2,FALSE) -> ts_048 | E33: =E28 -> C7 | AJ33: =AJ28+1 -> 5
A34: 5 | B34: =VLOOKUP(E34,$AK$9:$AL$15,2,FALSE)&"."&VLOOKUP(D34,$AH$9:$AI$24,2,FALSE) -> e 1.5 deg no OS.g64 | C34: =C33+1 -> 26 | D34: =VLOOKUP(AJ34,$AG$9:$AH$22,2,FALSE) -> ts_064 | E34: =E29 -> C1 | AJ34: =AJ29+1 -> 6
A35: 5 | B35: =VLOOKUP(E35,$AK$9:$AL$15,2,FALSE)&"."&VLOOKUP(D35,$AH$9:$AI$24,2,FALSE) -> d 1.5 deg OS.g64 | C35: =C34+1 -> 27 | D35: =VLOOKUP(AJ35,$AG$9:$AH$22,2,FALSE) -> ts_064 | E35: =E30 -> C2 | AJ35: =AJ30+1 -> 6
A36: 5 | B36: =VLOOKUP(E36,$AK$9:$AL$15,2,FALSE)&"."&VLOOKUP(D36,$AH$9:$AI$24,2,FALSE) -> c 2 deg (67%).g64 | C36: =C35+1 -> 28 | D36: =VLOOKUP(AJ36,$AG$9:$AH$22,2,FALSE) -> ts_064 | E36: =E31 -> C3 | G36: C7 | AJ36: =AJ31+1 -> 6
A37: 5 | B37: =VLOOKUP(E37,$AK$9:$AL$15,2,FALSE)&"."&VLOOKUP(D37,$AH$9:$AI$24,2,FALSE) -> b 2 deg (50%).g64 | C37: =C36+1 -> 29 | D37: =VLOOKUP(AJ37,$AG$9:$AH$22,2,FALSE) -> ts_064 | E37: =E32 -> C4 | G37: Gas Price | I37: =SUMIFS(ar6_r10!$F$2:$F$999,ar6_r10!$A$2:$A$999,Veda!$G$36,ar6_r10!$C$2:$C$999,Veda!I$17,ar6_r10!$M$2:$M$999,Veda!$G37) -> 1 | J37: =SUMIFS(ar6_r10!$F$2:$F$999,ar6_r10!$A$2:$A$999,Veda!$G$36,ar6_r10!$C$2:$C$999,Veda!J$17,ar6_r10!$M$2:$M$999,Veda!$G37) -> 1.07 | K37: =SUMIFS(ar6_r10!$F$2:$F$999,ar6_r10!$A$2:$A$999,Veda!$G$36,ar6_r10!$C$2:$C$999,Veda!K$17,ar6_r10!$M$2:$M$999,Veda!$G37) -> 1.24 | L37: =SUMIFS(ar6_r10!$F$2:$F$999,ar6_r10!$A$2:$A$999,Veda!$G$36,ar6_r10!$C$2:$C$999,Veda!L$17,ar6_r10!$M$2:$M$999,Veda!$G37) -> 1.15 | M37: =SUMIFS(ar6_r10!$F$2:$F$999,ar6_r10!$A$2:$A$999,Veda!$G$36,ar6_r10!$C$2:$C$999,Veda!M$17,ar6_r10!$M$2:$M$999,Veda!$G37) -> 1.25 | N37: =SUMIFS(ar6_r10!$F$2:$F$999,ar6_r10!$A$2:$A$999,Veda!$G$36,ar6_r10!$C$2:$C$999,Veda!N$17,ar6_r10!$M$2:$M$999,Veda!$G37) -> 1.17 | O37: =SUMIFS(ar6_r10!$F$2:$F$999,ar6_r10!$A$2:$A$999,Veda!$G$36,ar6_r10!$C$2:$C$999,Veda!O$17,ar6_r10!$M$2:$M$999,Veda!$G37) -> 1.34 | AJ37: =AJ32+1 -> 6
A38: 5 | B38: =VLOOKUP(E38,$AK$9:$AL$15,2,FALSE)&"."&VLOOKUP(D38,$AH$9:$AI$24,2,FALSE) -> a 3 deg.g64 | C38: =C37+1 -> 30 | D38: =VLOOKUP(AJ38,$AG$9:$AH$22,2,FALSE) -> ts_064 | E38: =E33 -> C7 | G38: Coal Price | I38: =SUMIFS(ar6_r10!$F$2:$F$999,ar6_r10!$A$2:$A$999,Veda!$G$36,ar6_r10!$C$2:$C$999,Veda!I$17,ar6_r10!$M$2:$M$999,Veda!$G38) -> 1 | J38: =SUMIFS(ar6_r10!$F$2:$F$999,ar6_r10!$A$2:$A$999,Veda!$G$36,ar6_r10!$C$2:$C$999,Veda!J$17,ar6_r10!$M$2:$M$999,Veda!$G38) -> 1.02 | K38: =SUMIFS(ar6_r10!$F$2:$F$999,ar6_r10!$A$2:$A$999,Veda!$G$36,ar6_r10!$C$2:$C$999,Veda!K$17,ar6_r10!$M$2:$M$999,Veda!$G38) -> 1.06 | L38: =SUMIFS(ar6_r10!$F$2:$F$999,ar6_r10!$A$2:$A$999,Veda!$G$36,ar6_r10!$C$2:$C$999,Veda!L$17,ar6_r10!$M$2:$M$999,Veda!$G38) -> 1.07 | M38: =SUMIFS(ar6_r10!$F$2:$F$999,ar6_r10!$A$2:$A$999,Veda!$G$36,ar6_r10!$C$2:$C$999,Veda!M$17,ar6_r10!$M$2:$M$999,Veda!$G38) -> 1.08 | N38: =SUMIFS(ar6_r10!$F$2:$F$999,ar6_r10!$A$2:$A$999,Veda!$G$36,ar6_r10!$C$2:$C$999,Veda!N$17,ar6_r10!$M$2:$M$999,Veda!$G38) -> 1.1 | O38: =SUMIFS(ar6_r10!$F$2:$F$999,ar6_r10!$A$2:$A$999,Veda!$G$36,ar6_r10!$C$2:$C$999,Veda!O$17,ar6_r10!$M$2:$M$999,Veda!$G38) -> 1.12 | AJ38: =AJ33+1 -> 6
A39: 5 | B39: =VLOOKUP(E39,$AK$9:$AL$15,2,FALSE)&"."&VLOOKUP(D39,$AH$9:$AI$24,2,FALSE) -> e 1.5 deg no OS.f96p50 | C39: =C38+1 -> 31 | D39: =VLOOKUP(AJ39,$AG$9:$AH$22,2,FALSE) -> ts_096P50 | E39: =E34 -> C1 | G39: Oil Price | I39: =SUMIFS(ar6_r10!$F$2:$F$999,ar6_r10!$A$2:$A$999,Veda!$G$36,ar6_r10!$C$2:$C$999,Veda!I$17,ar6_r10!$M$2:$M$999,Veda!$G39) -> 1 | J39: =SUMIFS(ar6_r10!$F$2:$F$999,ar6_r10!$A$2:$A$999,Veda!$G$36,ar6_r10!$C$2:$C$999,Veda!J$17,ar6_r10!$M$2:$M$999,Veda!$G39) -> 1.01 | K39: =SUMIFS(ar6_r10!$F$2:$F$999,ar6_r10!$A$2:$A$999,Veda!$G$36,ar6_r10!$C$2:$C$999,Veda!K$17,ar6_r10!$M$2:$M$999,Veda!$G39) -> 1.11 | L39: =SUMIFS(ar6_r10!$F$2:$F$999,ar6_r10!$A$2:$A$999,Veda!$G$36,ar6_r10!$C$2:$C$999,Veda!L$17,ar6_r10!$M$2:$M$999,Veda!$G39) -> 1.01 | M39: =SUMIFS(ar6_r10!$F$2:$F$999,ar6_r10!$A$2:$A$999,Veda!$G$36,ar6_r10!$C$2:$C$999,Veda!M$17,ar6_r10!$M$2:$M$999,Veda!$G39) -> 1.01 | N39: =SUMIFS(ar6_r10!$F$2:$F$999,ar6_r10!$A$2:$A$999,Veda!$G$36,ar6_r10!$C$2:$C$999,Veda!N$17,ar6_r10!$M$2:$M$999,Veda!$G39) -> 1.04 | O39: =SUMIFS(ar6_r10!$F$2:$F$999,ar6_r10!$A$2:$A$999,Veda!$G$36,ar6_r10!$C$2:$C$999,Veda!O$17,ar6_r10!$M$2:$M$999,Veda!$G39) -> 1.14 | AJ39: =AJ34+1 -> 7
A40: 5 | B40: =VLOOKUP(E40,$AK$9:$AL$15,2,FALSE)&"."&VLOOKUP(D40,$AH$9:$AI$24,2,FALSE) -> d 1.5 deg OS.f96p50 | C40: =C39+1 -> 32 | D40: =VLOOKUP(AJ40,$AG$9:$AH$22,2,FALSE) -> ts_096P50 | E40: =E35 -> C2 | G40: Biomass Price | I40: =SUMIFS(ar6_r10!$F$2:$F$999,ar6_r10!$A$2:$A$999,Veda!$G$36,ar6_r10!$C$2:$C$999,Veda!I$17,ar6_r10!$M$2:$M$999,Veda!$G40) -> 1 | J40: =SUMIFS(ar6_r10!$F$2:$F$999,ar6_r10!$A$2:$A$999,Veda!$G$36,ar6_r10!$C$2:$C$999,Veda!J$17,ar6_r10!$M$2:$M$999,Veda!$G40) -> 0.96 | K40: =SUMIFS(ar6_r10!$F$2:$F$999,ar6_r10!$A$2:$A$999,Veda!$G$36,ar6_r10!$C$2:$C$999,Veda!K$17,ar6_r10!$M$2:$M$999,Veda!$G40) -> 1.04 | L40: =SUMIFS(ar6_r10!$F$2:$F$999,ar6_r10!$A$2:$A$999,Veda!$G$36,ar6_r10!$C$2:$C$999,Veda!L$17,ar6_r10!$M$2:$M$999,Veda!$G40) -> 1.04 | M40: =SUMIFS(ar6_r10!$F$2:$F$999,ar6_r10!$A$2:$A$999,Veda!$G$36,ar6_r10!$C$2:$C$999,Veda!M$17,ar6_r10!$M$2:$M$999,Veda!$G40) -> 0.98 | N40: =SUMIFS(ar6_r10!$F$2:$F$999,ar6_r10!$A$2:$A$999,Veda!$G$36,ar6_r10!$C$2:$C$999,Veda!N$17,ar6_r10!$M$2:$M$999,Veda!$G40) -> 0.99 | O40: =SUMIFS(ar6_r10!$F$2:$F$999,ar6_r10!$A$2:$A$999,Veda!$G$36,ar6_r10!$C$2:$C$999,Veda!O$17,ar6_r10!$M$2:$M$999,Veda!$G40) -> 1 | AJ40: =AJ35+1 -> 7
A41: 5 | B41: =VLOOKUP(E41,$AK$9:$AL$15,2,FALSE)&"."&VLOOKUP(D41,$AH$9:$AI$24,2,FALSE) -> c 2 deg (67%).f96p50 | C41: =C40+1 -> 33 | D41: =VLOOKUP(AJ41,$AG$9:$AH$22,2,FALSE) -> ts_096P50 | E41: =E36 -> C3 | AJ41: =AJ36+1 -> 7
A42: 5 | B42: =VLOOKUP(E42,$AK$9:$AL$15,2,FALSE)&"."&VLOOKUP(D42,$AH$9:$AI$24,2,FALSE) -> b 2 deg (50%).f96p50 | C42: =C41+1 -> 34 | D42: =VLOOKUP(AJ42,$AG$9:$AH$22,2,FALSE) -> ts_096P50 | E42: =E37 -> C4 | AJ42: =AJ37+1 -> 7
...

Sheet fuel_prices
A9: Fuel Prices
A10: iso | B10: gas_low | C10: gas_high | D10: coal_low | E10: coal_high | F10: oil_low | G10: oil_high | H10: bioenergy_low | I10: bioenergy_high | J10: Notes
A11: ITA | B11: 29.1 | C11: 41.1 | D11: 15.2 | E11: 18.3 | F11: 50 | G11: 60 | H11: 25 | I11: 33 | J11: Pipeline gas, Mediterranean pellet imports

Sheet iea_data
A9: IEA Baseline Data
A10: iso | B10: year | C10: industry_twh | D10: buildings_agri_twh | E10: nonroad_transport_twh | F10: road_transport_twh | G10: imports_twh | H10: exports_twh | I10: total_production_twh
A11: ITA | B11: 2000 | C11: 179.49 | D11: 122.61 | E11: 4.5 | F11: 0 | G11: 44.83 | H11: -0.48 | I11: 269.94
A12: ITA | B12: 2001 | C12: 181.93 | D12: 125.95 | E12: 4.39 | F12: 0 | G12: 48.93 | H12: -0.55 | I12: 271.89
A13: ITA | B13: 2002 | C13: 183.71 | D13: 130.68 | E13: 4.44 | F13: 0 | G13: 51.52 | H13: -0.92 | I13: 277.53
A14: ITA | B14: 2003 | C14: 185.3 | D14: 137.6 | E14: 4.53 | F14: 0 | G14: 51.49 | H14: -0.52 | I14: 286.28
A15: ITA | B15: 2004 | C15: 185.28 | D15: 141.66 | E15: 4.47 | F15: 0 | G15: 46.43 | H15: -0.79 | I15: 295.78
A16: ITA | B16: 2005 | C16: 185.44 | D16: 146.13 | E16: 4.58 | F16: 0 | G16: 50.26 | H16: -1.11 | I16: 296.84
A17: ITA | B17: 2006 | C17: 186.96 | D17: 151.12 | E17: 4.38 | F17: 0 | G17: 46.6 | H17: -1.61 | I17: 307.69
A18: ITA | B18: 2007 | C18: 186.6 | D18: 152.67 | E18: 4.41 | F18: 0 | G18: 48.93 | H18: -2.65 | I18: 308.22
A19: ITA | B19: 2008 | C19: 181.03 | D19: 156.76 | E19: 4.55 | F19: 0 | G19: 43.43 | H19: -3.4 | I19: 313.53
A20: ITA | B20: 2009 | C20: 159.32 | D20: 158.8 | E20: 4.46 | F20: 0 | G20: 47.07 | H20: -2.11 | I20: 288.33
A21: ITA | B21: 2010 | C21: 166.69 | D21: 160.71 | E21: 4.58 | F21: 0.06 | G21: 45.99 | H21: -1.83 | I21: 298.77
A22: ITA | B22: 2011 | C22: 167 | D22: 162.89 | E22: 4.7 | F22: 0.06 | G22: 47.52 | H22: -1.79 | I22: 300.65
... A33: ITA | B33: 2022 | C33: 146.43 | D33: 165.99 | E33: 5.58 | F33: 0.6 | G33: 47.39 | H33: -4.4 | I33: 282.05

Sheet ar6_r10
A9: AR6 Scenario Drivers
A10: Category | B10: Region | C10: Year | D10: count | E10: mean | F10: median | G10: std | H10: min | I10: max | J10: q25 | K10: q75 | L10: category_description | M10: attribute
A11: C1 | B11: R10EUROPE | C11: 2020 | D11: 60 | E11: 8.68 | F11: 6.87 | G11: 10.43 | H11: 0 | I11: 55.17 | J11: 0 | K11: 13.64 | L11: Limit warming to 1.5°C (>50%) with no or limited overshoot | M11: CO2 price
A12: C1 | B12: R10EUROPE | C12: 2025 | D12: 60 | E12: 190.52 | F12: 181.51 | G12: 136.23 | H12: 1.81 | I12: 626.48 | J12: 115.48 | K12: 238.58 | L12: Limit warming to 1.5°C (>50%) with no or limited overshoot | M12: CO2 price
A13: C1 | B13: R10EUROPE | C13: 2030 | D13: 60 | E13: 268.18 | F13: 241.69 | G13: 134.29 | H13: 1.27 | I13: 673.46 | J13: 182.47 | K13: 329.7 | L13: Limit warming to 1.5°C (>50%) with no or limited overshoot | M13: CO2 price
A14: C1 | B14: R10EUROPE | C14: 2035 | D14: 60 | E14: 363.27 | F14: 339.03 | G14: 173.79 | H14: 14.37 | I14: 859.53 | J14: 227.05 | K14: 483.38 | L14: Limit warming to 1.5°C (>50%) with no or limited overshoot | M14: CO2 price
A15: C1 | B15: R10EUROPE | C15: 2040 | D15: 60 | E15: 471.65 | F15: 410.28 | G15: 224.31 | H15: 162.1 | I15: 1097.01 | J15: 298.63 | K15: 622.14 | L15: Limit warming to 1.5°C (>50%) with no or limited overshoot | M15: CO2 price
A16: C1 | B16: R10EUROPE | C16: 2045 | D16: 60 | E16: 565.69 | F16: 494.2 | G16: 256.15 | H16: 193.42 | I16: 1269.88 | J16: 352.78 | K16: 748.01 | L16: Limit warming to 1.5°C (>50%) with no or limited overshoot | M16: CO2 price
A17: C1 | B17: R10EUROPE | C17: 2050 | D17: 60 | E17: 647.44 | F17: 635.43 | G17: 273.56 | H17: 209.76 | I17: 1170.26 | J17: 409.79 | K17: 887.68 | L17: Limit warming to 1.5°C (>50%) with no or limited overshoot | M17: CO2 price
A18: C2 | B18: R10EUROPE | C18: 2020 | D18: 86 | E18: 6.44 | F18: 0 | G18: 8.34 | H18: 0 | I18: 24.5 | J18: 0 | K18: 12.68 | L18: Limit warming to 1.5°C (>67%) with high overshoot | M18: CO2 price
A19: C2 | B19: R10EUROPE | C19: 2025 | D19: 75 | E19: 63.21 | F19: 44.89 | G19: 56.62 | H19: 3.21 | I19: 273 | J19: 27.09 | K19: 77.31 | L19: Limit warming to 1.5°C (>67%) with high overshoot | M19: CO2 price
A20: C2 | B20: R10EUROPE | C20: 2030 | D20: 86 | E20: 85.48 | F20: 63.36 | G20: 73.46 | H20: 0 | I20: 409.5 | J20: 50 | K20: 111.1 | L20: Limit warming to 1.5°C (>67%) with high overshoot | M20: CO2 price
A21: C2 | B21: R10EUROPE | C21: 2035 | D21: 75 | E21: 208.71 | F21: 154.82 | G21: 291.78 | H21: 60.83 | I21: 2037.12 | J21: 93.79 | K21: 206.26 | L21: Limit warming to 1.5°C (>67%) with high overshoot | M21: CO2 price
A22: C2 | B22: R10EUROPE | C22: 2040 | D22: 86 | E22: 253.33 | F22: 172.09 | G22: 359.35 | H22: 0 | I22: 2600 | J22: 119.07 | K22: 259.4 | L22: Limit warming to 1.5°C (>67%) with high overshoot | M22: CO2 price
... A221: C1 | B221: R10EUROPE | C221: 2020 | D221: 33 | E221: 1 | F221: 1 | G221: 0 | H221: 1 | I221: 1 | J221: 1 | K221: 1 | L221: Limit warming to 1.5°C (>50%) with no or limited overshoot | M221: Gas price
A222: C1 | B222: R10EUROPE | C222: 2025 | D222: 34 | E222: 65535 | F222: 2.42 | H222: 1.18 | I222: 65535 | J222: 2.01 | K222: 2.75 | L222: Limit warming to 1.5°C (>50%) with no or limited overshoot | M222: Gas price
A223: C1 | B223: R10EUROPE | C223: 2030 | D223: 34 | E223: 65535 | F223: 3.1 | H223: 1.71 | I223: 65535 | J223: 2.38 | K223: 3.46 | L223: Limit warming to 1.5°C (>50%) with no or limited overshoot | M223: Gas price
A224: C1 | B224: R10EUROPE | C224: 2035 | D224: 34 | E224: 65535 | F224: 3.54 | H224: 1.91 | I224: 65535 | J224: 2.66 | K224: 4.16 | L224: Limit warming to 1.5°C (>50%) with no or limited overshoot | M224: Gas price
A225: C1 | B225: R10EUROPE | C225: 2040 | D225: 34 | E225: 65535 | F225: 4.1 | H225: 2.27 | I225: 65535 | J225: 2.96 | K225: 4.52 | L225: Limit warming to 1.5°C (>50%) with no or limited overshoot | M225: Gas price
A226: C1 | B226: R10EUROPE | C226: 2045 | D226: 34 | E226: 65535 | F226: 3.86 | H226: 2.54 | I226: 65535 | J226: 3.3 | K226: 4.89 | L226: Limit warming to 1.5°C (>50%) with no or limited overshoot | M226: Gas price
A227: C1 | B227: R10EUROPE | C227: 2050 | D227: 34 | E227: 65535 | F227: 3.59 | H227: 2.73 | I227: 65535 | J227: 3.07 | K227: 4.06 | L227: Limit warming to 1.5°C (>50%) with no or limited overshoot | M227: Gas price
A228: C2 | B228: R10EUROPE | C228: 2020 | D228: 43 | E228: 1 | F228: 1 | G228: 0 | H228: 1 | I228: 1 | J228: 1 | K228: 1 | L228: Limit warming to 1.5°C (>67%) with high overshoot | M228: Gas price
A229: C2 | B229: R10EUROPE | C229: 2025 | D229: 44 | E229: 65535 | F229: 1.22 | H229: 0 | I229: 65535 | J229: 1.13 | K229: 1.35 | L229: Limit warming to 1.5°C (>67%) with high overshoot | M229: Gas price
A230: C2 | B230: R10EUROPE | C230: 2030 | D230: 44 | E230: 65535 | F230: 1.5 | H230: 0 | I230: 65535 | J230: 1.31 | K230: 1.83 | L230: Limit warming to 1.5°C (>67%) with high overshoot | M230: Gas price
A231: C2 | B231: R10EUROPE | C231: 2035 | D231: 44 | E231: 65535 | F231: 2.12 | H231: 0 | I231: 65535 | J231: 1.68 | K231: 2.46 | L231: Limit warming to 1.5°C (>67%) with high overshoot | M231: Gas price
A232: C2 | B232: R10EUROPE | C232: 2040 | D232: 44 | E232: 65535 | F232: 2.5 | H232: 0 | I232: 65535 | J232: 2 | K232: 2.94 | L232: Limit warming to 1.5°C (>67%) with high overshoot | M232: Gas price
A233: C2 | B233: R10EUROPE | C233: 2045 | D233: 44 | E233: 65535 | F233: 2.79 | H233: 0 | I233: 65535 | J233: 2.08 | K233: 3.44 | L233: Limit warming to 1.5°C (>67%) with high overshoot | M233: Gas price
A234: C2 | B234: R10EUROPE | C234: 2050 | D234: 44 | E234: 65535 | F234: 2.95 | H234: 0 | I234: 65535 | J234: 2.49 | K234: 3.78 | L234: Limit warming to 1.5°C (>67%) with high overshoot | M234: Gas price
A235: C3 | B235: R10EUROPE | C235: 2020 | D235: 103 | E235: 1 | F235: 1 | G235: 0 | H235: 1 | I235: 1 | J235: 1 | K235: 1 | L235: Limit warming to 2°C (>67%) with higher action post-2030 | M235: Gas price
A236: C3 | B236: R10EUROPE | C236: 2025 | D236: 112 | E236: 65535 | F236: 1.41 | H236: 0.98 | I236: 65535 | J236: 1.23 | K236: 1.96 | L236: Limit warming to 2°C (>67%) with higher action post-2030 | M236: Gas price
A237: C3 | B237: R10EUROPE | C237: 2030 | D237: 112 | E237: 65535 | F237: 2.04 | H237: 1.05 | I237: 65535 | J237: 1.52 | K237: 2.55 | L237: Limit warming to 2°C (>67%) with higher action post-2030 | M237: Gas price
A238: C3 | B238: R10EUROPE | C238: 2035 | D238: 112 | E238: 65535 | F238: 2.4 | H238: 1.05 | I238: 65535 | J238: 1.71 | K238: 3.14 | L238: Limit warming to 2°C (>67%) with higher action post-2030 | M238: Gas price
A239: C3 | B239: R10EUROPE | C239: 2040 | D239: 112 | E239: 65535 | F239: 2.6 | H239: 1.06 | I239: 65535 | J239: 1.85 | K239: 3.74 | L239: Limit warming to 2°C (>67%) with higher action post-2030 | M239: Gas price
A240: C3 | B240: R10EUROPE | C240: 2045 | D240: 112 | E240: 65535 | F240: 2.85 | H240: 1.08 | I240: 65535 | J240: 2 | K240: 4.28 | L240: Limit warming to 2°C (>67%) with higher action post-2030 | M240: Gas price
A241: C3 | B241: R10EUROPE | C241: 2050 | D241: 112 | E241: 65535 | F241: 2.97 | H241: 0 | I241: 65535 | J241: 2.15 | K241: 4.51 | L241: Limit warming to 2°C (>67%) with higher action post-2030 | M241: Gas price
A242: C4 | B242: R10EUROPE | C242: 2020 | D242: 27 | E242: 1 | F242: 1 | G242: 0 | H242: 1 | I242: 1 | J242: 1 | K242: 1 | L242: Limit warming to 2°C (>50%) with immediate action | M242: Gas price
A243: C4 | B243: R10EUROPE | C243: 2025 | D243: 27 | E243: 1.33 | F243: 1.31 | G243: 0.18 | H243: 1.06 | I243: 1.66 | J243: 1.22 | K243: 1.45 | L243: Limit warming to 2°C (>50%) with immediate action | M243: Gas price
A244: C4 | B244: R10EUROPE | C244: 2030 | D244: 27 | E244: 1.84 | F244: 2.02 | G244: 0.28 | H244: 1.24 | I244: 2.17 | J244: 1.52 | K244: 2.07 | L244: Limit warming to 2°C (>50%) with immediate action | M244: Gas price
A245: C4 | B245: R10EUROPE | C245: 2035 | D245: 27 | E245: 1.84 | F245: 1.96 | G245: 0.41 | H245: 1.19 | I245: 2.46 | J245: 1.42 | K245: 2.11 | L245: Limit warming to 2°C (>50%) with immediate action | M245: Gas price
A246: C4 | B246: R10EUROPE | C246: 2040 | D246: 27 | E246: 2.12 | F246: 2.22 | G246: 0.47 | H246: 1.41 | I246: 2.78 | J246: 1.54 | K246: 2.43 | L246: Limit warming to 2°C (>50%) with immediate action | M246: Gas price
...

Sheet ev_charging_uc
A10: =IFERROR(Veda!D5,"ts_12t") -> ts_annual | C10: day_night | D10: s1p1v1_d | F10: day_night | G10: s5p5v5_d | I10: day_night | J10: s2_w_p2_d | L10: day_night | M10: ts_064 | O10: day_night | P10: ts_096P50 | R10: day_night | S10: ts_096P10 | U10: day_night | V10: ts_096P90 | X10: day_night | Y10: ts_annual | AA10: day_night | AB10: ts_12t
C11: D | D11: S02b0202h08,S03aH03,S09aH05,S12aH07,S02b0202h11,S04aH05,S12d1209h07,S04aH06,S05aH04,S06aH02,S06aH03,S10aH04,S12aH06,S12d1209h10,S02b0202h10,S04aH02,S08aH07,S09aH02,S09aH03,S11aH03,S11aH04,S12d1209h13,S12d1209h18,S01aH03,S02b0202h14,S05aH02,S05aH03,S05aH06,S01aH05,S02b0202h17,S03aH06,S03aH07,S06aH05,S08c0807h15,S10aH02,S10aH06,S11aH06,S12aH04,S12aH05,S01aH02,S04aH04,S02aH04,S02aH05,S06aH07,S07aH07,S08c0807h18,S10aH03,S10aH05,S02b0202h16,S03aH02,S07aH05,S08c0807h11,S08c0807h17,S12d1209h14,S04aH03,S07aH04,S08aH03,S08c0807h07,S08c0807h13,S09aH04,S11aH07,S12aH02,S12d1209h08,S12d1209h12,S12d1209h15,S02aH06,S02b0202h15,S03aH05,S04aH07,S05aH05,S06aH04,S08aH04,S11aH02,S01aH06,S02aH03,S05aH07,S07aH03,S08aH06,S10aH07,S12d1209h09,S01aH04,S01aH07,S02aH07,S02b0202h07,S02b0202h12,S07aH02,S07aH06,S08c0807h12,S12d1209h16,S02b0202h13,S02b0202h18,S03aH04,S08aH05,S09aH07,S11aH05,S12aH03,S02aH02,S02b0202h09,S06aH06,S08c0807h08,S08c0807h10,S08c0807h14,S12d1209h11,S12d1209h17,S08aH02,S08c0807h09,S08c0807h16,S09aH06 | F11: D | G11: S02aH02,S02b0202h09,S02c0225h07,S02c0225h14,S02c0225h16,S03d0315h12,S03f0321h15,S03g0331h18,S06aH06,S06i0620h08,S06i0620h18,S11m1129h13,S12o1209h12,S12o1209h13,S12o1209h14,S12p1223h11,S02b0202h16,S02c0225h08,S03aH02,S03d0315h11,S03e0318h10,S03e0318h14,S03e0318h17,S03f0321h13,S03f0321h16,S03f0321h18,S03g0331h07,S03g0331h13,S07aH05,S07j0726h07,S08k0807h14,S10l1015h18,S11m1129h07,S11m1129h10,S12n1208h15,S12p1223h10,S02b0202h11,S02c0225h09,S03e0318h12,S03f0321h10,S03g0331h16,S04aH05,S06i0620h07,S10l1015h11,S11m1129h17,S12n1208h08,S12n1208h09,S12n1208h13,S12o1209h17,S12p1223h13,S02aH06,S02b0202h15,S02c0225h13,S03aH05,S04aH07,S05aH05,S05h0509h12,S06aH04,S06i0620h09,S06i0620h13,S08aH04,S10l1015h09,S10l1015h13,S11aH02,S11m1129h11,S12p1223h08,S03d0315h07,S03d0315h13,S03e0318h07,S03e0318h18,S04aH03,S06i0620h11,S07aH04,S07j0726h12,S08aH03,S08k0807h08,S08k0807h09,S09aH04,S10l1015h08,S10l1015h10,S10l1015h14,S11aH07,S11m1129h12,S12aH02,S12o1209h15,S12o1209h16,S12p1223h15,S02b0202h10,S02c0225h15,S03d0315h10,S03e0318h08,S03f0321h09,S03g0331h12,S04aH02,S07j0726h17,S08aH07,S09aH02,S09aH03,S11aH03,S11aH04,S12p1223h14,S12p1223h16,S01aH05,S02b0202h17,S03aH06,S03aH07,S05h0509h11,S06aH05,S06i0620h10,S06i0620h16,S08k0807h13,S08k0807h18,S10aH02,S10aH06,S10l1015h12,S11aH06,S11m1129h18,S12aH04,S12aH05,S12o1209h11,S12p1223h12,S02aH04,S02aH05,S02c0225h11,S03d0315h16,S03e0318h09,S03e0318h15,S03g0331h08,S03g0331h14,S05h0509h13,S05h0509h15,S06aH07,S06i0620h14,S07aH07,S07j0726h09,S10aH03,S10aH05,S11m1129h08,S12n1208h12,S12p1223h17,S01aH06,S02aH03,S02c0225h10,S02c0225h17,S02c0225h18,S03d0315h14,S03e0318h11,S03f0321h07,S03f0321h08,S05aH07,S05h0509h18,S07aH03,S07j0726h16,S08aH06,S08k0807h17,S10aH07,S11m1129h09,S11m1129h14,S12n1208h11,S03f0321h14,S04aH06,S05aH04,S05h0509h16,S06aH02,S06aH03,S06i0620h17,S07j0726h11,S10aH04,S10l1015h16,S12aH06,S12n1208h14,S01aH04,S01aH07,S02aH07,S02b0202h07,S02b0202h12,S03d0315h15,S03e0318h16,S05h0509h09,S07aH02,S07aH06,S10l1015h07,S10l1015h15,S03e0318h13,S06i0620h12,S07j0726h10,S07j0726h13,S07j0726h15,S08aH02,S09aH06,S12n1208h17,S12n1208h18,S12o1209h08,S12p1223h18,S01aH03,S02b0202h14,S03d0315h08,S03g0331h15,S03g0331h17,S05aH02,S05aH03,S05aH06,S05h0509h07,S05h0509h14,S05h0509h17,S08k0807h07,S08k0807h10,S08k0807h15,S10l1015h17,S11m1129h16,S12n1208h16,S12p1223h07,S01aH02,S02c0225h12,S04aH04,S05h0509h08,S06i0620h15,S08k0807h12,S11m1129h15,S12n1208h10,S02b0202h13,S02b0202h18,S03aH04,S03d0315h09,S03d0315h18,S03f0321h11,S03f0321h12,S03f0321h17,S03g0331h11,S07j0726h08,S07j0726h14,S07j0726h18,S08aH05,S09aH07,S11aH05,S12aH03,S12o1209h07,S12o1209h18,S12p1223h09,S02b0202h08,S03aH03,S03d0315h17,S03g0331h09,S03g0331h10,S05h0509h10,S08k0807h11,S08k0807h16,S09aH05,S12aH07,S12n1208h07,S12o1209h09,S12o1209h10 | I11: D | J11: S02aH06,S02b0202h15,S03aH05,S04aH07,S05aH05,S06aH04,S08aH04,S10d1025h18,S10d1026h07,S10d1027h13,S10d1028h10,S11aH02,S12e1219h11,S12e1219h17,S12e1222h12,S02b0202h10,S04aH02,S08aH07,S09aH02,S09aH03,S10d1022h17,S10d1023h12,S10d1024h08,S10d1025h09,S10d1026h13,S11aH03,S11aH04,S12e1218h08,S12e1219h09,S12e1219h15,S12e1221h12,S12e1221h18,S12e1222h11,S12e1223h11,S12e1223h18,S02b0202h16,S03aH02,S03c0331h07,S03c0331h08,S03c0331h09,S03c0331h15,S07aH05,S10d1022h07,S10d1023h07,S10d1023h13,S10d1023h16,S10d1026h15,S10d1028h15,S12e1217h11,S12e1218h18,S12e1219h12,S12e1222h13,S12e1223h13,S04aH03,S07aH04,S08aH03,S09aH04,S10d1022h12,S10d1025h17,S11aH07,S12aH02,S12e1217h09,S12e1217h13,S12e1219h07,S12e1220h15,S12e1220h17,S12e1221h08,S12e1223h16,S01aH02,S03c0331h14,S04aH04,S10d1022h11,S10d1023h11,S10d1026h09,S12e1220h08,S12e1220h16,S12e1221h10,S01aH05,S02b0202h17,S03aH06,S03aH07,S03c0331h12,S06aH05,S10aH02,S10aH06,S10d1022h14,S10d1023h14,S10d1023h15,S10d1023h18,S10d1026h12,S10d1028h14,S11aH06,S12aH04,S12aH05,S12e1217h10,S12e1218h16,S12e1220h14,S12e1221h16,S12e1222h08,S12e1222h15,S03c0331h13,S03c0331h16,S08aH02,S09aH06,S10d1022h09,S12e1219h16,S12e1221h13,S12e1221h17,S12e1222h17,S01aH03,S02b0202h14,S03c0331h11,S05aH02,S05aH03,S05aH06,S10d1022h18,S10d1023h08,S10d1024h13,S10d1025h13,S10d1027h18,S12e1217h16,S12e1219h10,S12e1219h18,S12e1220h12,S12e1220h13,S12e1220h18,S12e1221h15,S12e1222h07,S02b0202h13,S02b0202h18,S03aH04,S03c0331h10,S08aH05,S09aH07,S10d1024h16,S10d1025h14,S10d1027h11,S10d1028h12,S10d1028h17,S11aH05,S12aH03,S12e1217h18,S12e1218h09,S12e1218h11,S12e1220h07,S12e1221h07,S12e1222h09,S12e1222h18,S01aH06,S02aH03,S05aH07,S07aH03,S08aH06,S10aH07,S10d1022h10,S10d1022h13,S10d1023h09,S10d1024h07,S10d1024h15,S10d1025h12,S10d1026h11,S10d1026h18,S10d1027h12,S10d1028h07,S12e1217h08,S12e1218h15,S12e1221h09,S12e1222h10,S12e1223h10,S02b0202h08,S03aH03,S09aH05,S10d1024h17,S10d1025h10,S10d1026h16,S10d1027h16,S10d1028h09,S10d1028h16,S12aH07,S12e1217h07,S12e1218h07,S12e1219h08,S12e1219h13,S12e1219h14,S12e1223h07,S01aH04,S01aH07,S02aH07,S02b0202h07,S02b0202h12,S03c0331h18,S07aH02,S07aH06,S10d1024h11,S10d1025h07,S10d1026h17,S10d1027h08,S12e1217h14,S12e1218h12,S12e1218h13,S02b0202h11,S03c0331h17,S04aH05,S10d1022h08,S10d1022h16,S10d1024h10,S10d1026h10,S10d1027h17,S12e1217h15,S12e1218h17,S12e1220h09,S12e1220h11,S12e1222h14,S12e1222h16,S12e1223h08,S12e1223h12,S12e1223h14,S12e1223h15,S02aH02,S02b0202h09,S06aH06,S10d1023h17,S10d1024h14,S10d1024h18,S10d1025h11,S10d1025h16,S10d1027h07,S10d1028h08,S10d1028h13,S12e1220h10,S04aH06,S05aH04,S06aH02,S06aH03,S10aH04,S10d1023h10,S10d1024h12,S10d1025h15,S10d1027h09,S10d1027h14,S10d1028h11,S10d1028h18,S12aH06,S12e1217h12,S12e1217h17,S12e1218h10,S12e1218h14,S12e1221h11,S02aH04,S02aH05,S06aH07,S07aH07,S10aH03,S10aH05,S10d1022h15,S10d1024h09,S10d1025h08,S10d1026h08,S10d1026h14,S10d1027h10,S10d1027h15,S12e1221h14,S12e1223h09,S12e1223h17 | L11: D | M11: S01aH04,S01aH07,S02aH07,S07aH02,S07aH06,S04aH02,S02aH02,S06aH06,S01aH05,S03aH06,S03aH07,S06aH05,S03aH04,S01aH06,S02aH03,S05aH07,S07aH03,S01aH02,S04aH04,S02aH04,S02aH05,S06aH07,S07aH07,S04aH06,S05aH04,S06aH02,S06aH03,S04aH03,S07aH04,S04aH05,S01aH03,S05aH02,S05aH03,S05aH06,S03aH02,S07aH05,S02aH06,S03aH05,S04aH07,S05aH05,S06aH04,S03aH03 | O11: D | P11: S02aH06,S03aH05,S04aH07,S05aH05,S06aH04,S08aH04,S11aH02,S04aH03,S07aH04,S08aH03,S09aH04,S11aH07,S12aH02,S01aH02,S04aH04,S02aH02,S06aH06,S04aH06,S05aH04,S06aH02,S06aH03,S10aH04,S12aH06,S03aH04,S08aH05,S09aH07,S11aH05,S12aH03,S01aH06,S02aH03,S05aH07,S07aH03,S08aH06,S10aH07,S01aH04,S01aH07,S02aH07,S07aH02,S07aH06,S03aH03,S09aH05,S12aH07,S03aH02,S07aH05,S01aH05,S03aH06,S03aH07,S06aH05,S10aH02,S10aH06,S11aH06,S12aH04,S12aH05,S01aH03,S05aH02,S05aH03,S05aH06,S08aH02,S09aH06,S04aH05,S02aH04,S02aH05,S06aH07,S07aH07,S10aH03,S10aH05,S04aH02,S08aH07,S09aH02,S09aH03,S11aH03,S11aH04 | R11: D | S11: S01aH04,S01aH07,S02aH07,S07aH02,S07aH06,S03aH02,S07aH05,S04aH05,S04aH03,S07aH04,S08aH03,S09aH04,S11aH07,S12aH02,S02aH06,S03aH05,S04aH07,S05aH05,S06aH04,S08aH04,S11aH02,S01aH03,S05aH02,S05aH03,S05aH06,S04aH02,S08aH07,S09aH02,S09aH03,S11aH03,S11aH04,S01aH05,S03aH06,S03aH07,S06aH05,S10aH02,S10aH06,S11aH06,S12aH04,S12aH05,S02aH02,S06aH06,S08aH02,S09aH06,S02aH04,S02aH05,S06aH07,S07aH07,S10aH03,S10aH05,S04aH06,S05aH04,S06aH02,S06aH03,S10aH04,S12aH06,S01aH06,S02aH03,S05aH07,S07aH03,S08aH06,S10aH07,S03aH04,S08aH05,S09aH07,S11aH05,S12aH03,S03aH03,S09aH05,S12aH07,S01aH02,S04aH04 | U11: D | V11: S02aH04,S02aH05,S06aH07,S07aH07,S10aH03,S10aH05,S03aH02,S07aH05,S02aH06,S03aH05,S04aH07,S05aH05,S06aH04,S08aH04,S11aH02,S01aH05,S03aH06,S03aH07,S06aH05,S10aH02,S10aH06,S11aH06,S12aH04,S12aH05,S03aH03,S09aH05,S12aH07,S04aH02,S08aH07,S09aH02,S09aH03,S11aH03,S11aH04,S04aH03,S07aH04,S08aH03,S09aH04,S11aH07,S12aH02,S04aH05,S01aH04,S01aH07,S02aH07,S07aH02,S07aH06,S04aH06,S05aH04,S06aH02,S06aH03,S10aH04,S12aH06,S03aH04,S08aH05,S09aH07,S11aH05,S12aH03,S01aH06,S02aH03,S05aH07,S07aH03,S08aH06,S10aH07,S08aH02,S09aH06,S01aH03,S05aH02,S05aH03,S05aH06,S01aH02,S04aH04,S02aH02,S06aH06 | X11: D | Y11: AllSaAllH | AA11: D | AB11: WaD,RaD,FaD,SaD,FaP,SaP,WaP,RaP
C12: N | D12: S08c0807h02,S08c0807h04,S11aH08,S02b0202h19,S05aH08,S10aH08,S12d1209h22,S02b0202h20,S07aH01,S02b0202h23,S02b0202h24,S08c0807h01,S12d1209h23,S09aH01,S12d1209h02,S12d1209h06,S12d1209h01,S01aH08,S02aH08,S02b0202h01,S02b0202h03,S08c0807h24,S03aH08,S06aH08,S08c0807h20,S08c0807h23,S12aH01,S08c0807h22,S12d1209h03,S02aH01,S02b0202h02,S02b0202h06,S08c0807h06,S12d1209h19,S12d1209h21,S12d1209h24,S07aH08,S08aH08,S01aH01,S02b0202h21,S04aH01,S08c0807h03,S08c0807h05,S09aH08,S11aH01,S12d1209h20,S02b0202h04,S02b0202h05,S08aH01,S10aH01,S12d1209h04,S05aH01,S08c0807h21,S03aH01,S08c0807h19,S02b0202h22,S04aH08,S06aH01,S12aH08,S12d1209h05 | F12: N | G12: S02c0225h05,S03aH01,S03e0318h20,S03g0331h24,S05h0509h02,S07j0726h05,S08k0807h23,S11m1129h03,S11m1129h24,S12n1208h22,S12o1209h01,S02c0225h04,S03d0315h04,S03g0331h02,S03g0331h22,S06i0620h19,S10l1015h06,S12n1208h19,S12o1209h20,S12p1223h21,S12p1223h24,S02b0202h19,S03d0315h06,S03g0331h06,S05aH08,S05h0509h06,S05h0509h23,S07j0726h02,S08k0807h06,S08k0807h21,S10aH08,S12o1209h03,S03f0321h21,S07aH08,S07j0726h01,S07j0726h23,S08aH08,S08k0807h05,S10l1015h23,S11m1129h06,S12n1208h21,S12o1209h04,S12o1209h21,S02aH01,S02b0202h02,S02b0202h06,S02c0225h21,S03d0315h20,S03e0318h02,S03e0318h24,S03f0321h01,S03f0321h05,S03f0321h23,S03f0321h24,S03g0331h19,S05h0509h05,S05h0509h24,S10l1015h01,S11m1129h04,S12n1208h04,S12n1208h05,S12o1209h02,S02b0202h23,S02b0202h24,S03e0318h21,S06i0620h02,S06i0620h05,S06i0620h21,S06i0620h22,S08k0807h02,S02c0225h03,S02c0225h19,S02c0225h24,S03g0331h05,S10l1015h05,S12o1209h05,S12p1223h03,S03aH08,S03d0315h02,S03d0315h03,S03d0315h05,S03e0318h01,S03g0331h01,S03g0331h03,S03g0331h21,S06aH08,S07j0726h03,S12aH01,S12n1208h23,S12n1208h24,S01aH01,S02b0202h21,S03e0318h04,S03e0318h22,S04aH01,S05h0509h03,S06i0620h20,S09aH08,S11aH01,S11m1129h21,S12p1223h01,S12p1223h22,S12p1223h23,S02b0202h20,S02c0225h06,S02c0225h22,S03f0321h19,S03g0331h04,S05h0509h04,S05h0509h19,S06i0620h03,S07aH01,S07j0726h20,S10l1015h04,S12n1208h02,S12p1223h04,S02b0202h04,S02b0202h05,S03d0315h01,S03f0321h22,S06i0620h06,S07j0726h04,S07j0726h19,S08aH01,S10aH01,S10l1015h24,S12n1208h03,S12n1208h06,S12o1209h23,S02b0202h22,S03g0331h23,S04aH08,S06aH01,S07j0726h24,S08k0807h22,S08k0807h24,S11m1129h22,S12aH08,S12n1208h01,S12o1209h24,S03d0315h23,S03d0315h24,S03e0318h19,S03f0321h02,S03f0321h04,S05h0509h01,S06i0620h01,S07j0726h06,S07j0726h21,S08k0807h01,S08k0807h19,S08k0807h20,S09aH01,S11m1129h05,S11m1129h19,S12o1209h19,S12o1209h22,S01aH08,S02aH08,S02b0202h01,S02b0202h03,S02c0225h01,S02c0225h02,S02c0225h23,S03d0315h19,S03d0315h22,S03e0318h06,S03f0321h06,S05h0509h21,S10l1015h02,S10l1015h03,S10l1015h20,S10l1015h22,S11m1129h01,S11m1129h20,S02c0225h20,S03e0318h03,S03e0318h05,S03e0318h23,S03f0321h03,S05aH01,S05h0509h20,S06i0620h24,S10l1015h21,S12p1223h06,S03d0315h21,S03f0321h20,S03g0331h20,S05h0509h22,S06i0620h04,S06i0620h23,S07j0726h22,S08k0807h03,S08k0807h04,S10l1015h19,S11aH08,S11m1129h02,S11m1129h23,S12n1208h20,S12o1209h06,S12p1223h02,S12p1223h05,S12p1223h19,S12p1223h20 | I12: N | J12: S03c0331h02,S07aH08,S08aH08,S10d1024h05,S10d1025h23,S10d1026h05,S10d1027h04,S10d1027h19,S12e1217h22,S12e1217h23,S12e1219h01,S12e1219h20,S12e1222h19,S12e1223h22,S02b0202h23,S02b0202h24,S03c0331h05,S10d1022h02,S10d1023h24,S10d1025h05,S10d1026h01,S10d1026h02,S10d1026h19,S10d1027h02,S10d1027h05,S12e1220h20,S12e1221h04,S03c0331h23,S10d1022h03,S10d1025h01,S10d1025h19,S10d1026h21,S10d1026h24,S10d1027h21,S12e1218h24,S12e1219h22,S12e1220h23,S12e1220h24,S12e1223h02,S12e1223h03,S02aH01,S02b0202h02,S02b0202h06,S03c0331h06,S10d1022h01,S10d1022h06,S10d1022h22,S10d1022h24,S10d1023h01,S10d1027h20,S10d1028h02,S10d1028h06,S12e1217h20,S12e1217h21,S12e1218h05,S12e1218h20,S12e1221h19,S12e1221h22,S12e1222h02,S12e1222h22,S12e1223h05,S01aH08,S02aH08,S02b0202h01,S02b0202h03,S10d1024h02,S10d1024h04,S10d1025h22,S10d1027h06,S10d1027h23,S12e1220h01,S12e1221h06,S10d1022h23,S10d1023h21,S10d1025h06,S10d1028h01,S10d1028h04,S10d1028h21,S12e1218h06,S12e1219h04,S12e1219h19,S12e1220h02,S12e1222h03,S12e1222h24,S02b0202h22,S03c0331h01,S04aH08,S06aH01,S10d1024h01,S10d1024h22,S10d1025h04,S10d1026h06,S10d1026h20,S10d1027h01,S10d1028h03,S12aH08,S12e1219h21,S12e1222h01,S12e1223h01,S12e1223h24,S03c0331h20,S03c0331h22,S09aH01,S10d1023h04,S10d1023h05,S10d1023h19,S10d1026h04,S10d1028h20,S12e1217h05,S12e1218h01,S12e1219h06,S12e1221h02,S12e1221h03,S12e1221h23,S12e1222h04,S12e1222h21,S12e1223h04,S03c0331h04,S03c0331h21,S05aH01,S10d1022h05,S10d1023h20,S10d1026h23,S12e1218h19,S12e1219h02,S12e1219h23,S12e1220h19,S12e1221h24,S12e1222h06,S01aH01,S02b0202h21,S03c0331h24,S04aH01,S09aH08,S10d1022h20,S10d1023h03,S10d1023h06,S10d1024h23,S10d1024h24,S10d1025h20,S10d1025h21,S10d1025h24,S11aH01,S12e1217h06,S12e1217h19,S12e1218h02,S12e1218h03,S12e1220h05,S12e1221h05,S12e1222h23,S10d1023h02,S10d1024h06,S10d1027h22,S10d1028h19,S11aH08,S12e1217h02,S12e1218h21,S12e1218h23,S12e1223h06,S12e1223h21,S02b0202h04,S02b0202h05,S03c0331h03,S08aH01,S10aH01,S10d1022h04,S10d1022h19,S10d1023h22,S10d1026h03,S10d1027h03,S10d1027h24,S10d1028h05,S12e1217h24,S12e1218h22,S12e1220h21,S12e1220h22,S12e1223h19,S02b0202h19,S05aH08,S10aH08,S10d1024h20,S10d1028h22,S12e1217h03,S12e1218h04,S12e1220h04,S03aH01,S10d1022h21,S10d1028h23,S12e1217h01,S12e1219h03,S12e1219h05,S12e1221h21,S02b0202h20,S03c0331h19,S07aH01,S10d1024h19,S10d1024h21,S10d1025h02,S10d1026h22,S10d1028h24,S12e1217h04,S12e1220h03,S12e1220h06,S12e1221h01,S12e1221h20,S12e1222h05,S12e1223h20,S12e1223h23,S03aH08,S06aH08,S10d1023h23,S10d1024h03,S10d1025h03,S12aH01,S12e1219h24,S12e1222h20 | L12: N | M12: S03aH01,S05aH01,S01aH01,S04aH01,S01aH08,S02aH08,S03aH08,S06aH08,S07aH01,S02aH01,S05aH08,S07aH08,S04aH08,S06aH01 | O12: N | P12: S07aH08,S08aH08,S02aH01,S01aH08,S02aH08,S03aH01,S07aH01,S05aH01,S01aH01,S04aH01,S09aH08,S11aH01,S08aH01,S10aH01,S11aH08,S09aH01,S04aH08,S06aH01,S12aH08,S05aH08,S10aH08,S03aH08,S06aH08,S12aH01 | R12: N | S12: S08aH01,S10aH01,S05aH08,S10aH08,S02aH01,S07aH08,S08aH08,S09aH01,S03aH01,S04aH08,S06aH01,S12aH08,S03aH08,S06aH08,S12aH01,S07aH01,S01aH01,S04aH01,S09aH08,S11aH01,S05aH01,S11aH08,S01aH08,S02aH08 | U12: N | V12: S03aH08,S06aH08,S12aH01,S07aH08,S08aH08,S11aH08,S02aH01,S05aH08,S10aH08,S08aH01,S10aH01,S07aH01,S05aH01,S01aH01,S04aH01,S09aH08,S11aH01,S04aH08,S06aH01,S12aH08,S09aH01,S01aH08,S02aH08,S03aH01 | X12: N | Y12: AllSaAllH | AA12: N | AB12: SaN,WaN,FaN,RaP,FaP,SaP,WaP,RaN
I17: 0.75 | K17: share of charging at night
C18: ~UC_Sets: R_E: AllRegions
H21: =IF(H23=H24,"Not Required!","~UC_T: LO") -> Not Required!
C22: UC_N | D22: Pset_CI | E22: Pset_CO | F22: pset_pn | G22: Cset_CN | H22: TimeSlice | I22: UC_FLO | J22: UC_RHSRT | K22: UC_RHSRT~0
C23: UC_bev night chg limit | D23: ELC | E23: =G23 -> AuxStoIN | F23: *EV* | G23: AuxStoIN | H23: =HLOOKUP($A$10,$D$10:$CU$12,3,FALSE) -> AllSaAllH | I23: =1+I24 -> 0.25 | J23: 0 | K23: 3 | M23: night
D24: ELC | E24: =G24 -> AuxStoIN | F24: *EV* | G24: AuxStoIN | H24: =HLOOKUP($A$10,$D$10:$CU$12,2,FALSE) -> AllSaAllH | I24: =-$I$17 -> -0.75 | M24: day

Sheet s1p1v1_d
C9: =IF(A11="x","DeActivated","~TimeSlices") -> DeActivated | I9: =IF(A11="x","DeActivated","~TFM_DINS-AT") -> DeActivated | N9: =IF(A11="x","DeActivated","~TFM_DINS-AT") -> DeActivated | S9: =IF(A11="x","DeActivated","~TFM_DINS-AT") -> DeActivated | X9: =IF(A11="x","DeActivated","~TFM_DINS-AT") -> DeActivated | AC9: =IF(A11="x","DeActivated","~TFM_DINS-AT") -> DeActivated | AG9: =IF(A11="x","DeActivated","~TFM_DINS-AT") -> DeActivated | AK9: =IF(A11="x","DeActivated","~TFM_INS-AT") -> DeActivated
A10: s1p1v1_d | C10: season | D10: weekly | E10: daynite | F10: wparent | G10: dparent | I10: commodity | J10: timeslice | K10: com_fr | L10: process | N10: commodity | O10: timeslice | P10: com_fr | Q10: process | S10: commodity | T10: timeslice | U10: com_fr | V10: process | X10: g_yrfr | Y10: com_fr | Z10: timeslice | AA10: commodity | AC10: commodity | AD10: timeslice | AE10: com_fr | AG10: commodity | AH10: timeslice | AI10: com_pkflx | AK10: Year | AL10: timeslice | AM10: ncap_afs | AN10: pset_ci
A11: =IFERROR(IF(Veda!D5=A10,"ok","x"),"") -> x | C11: S01 | D11: a | E11: 0202h01 | F11: S01,S02,S03,S04,S05,S06,S07,S08,S09,S10,S11,S12 | G11: b | I11: elc_spv_001 | J11: S01aH01 | K11: 0 | L11: IMPNRGZ | N11: elc_won_001 | O11: S01aH01 | P11: 0.026254969 | Q11: IMPNRGZ | S11: elc_wof_001 | T11: S01aH01 | U11: 0.030999277 | V11: IMPNRGZ | X11: 0.024771689 | Y11: 0.0097827943 | Z11: S01aH01 | AA11: elc_roadtransport | AC11: elc_buildings | AD11: S01aH01 | AE11: 0.021406128 | AG11: ELC | AH11: S01aH01 | AI11: 0.29051279 | AK11: 2020 | AL11: S01 | AM11: 0.2265233 | AN11: hydro
C12: S02 | D12: b | E12: 0202h02 | F12: S02 | G12: b | I12: elc_spv_001 | J12: S01aH02 | K12: 0 | L12: IMPNRGZ | N12: elc_won_001 | O12: S01aH02 | P12: 0.0036180271 | Q12: IMPNRGZ | S12: elc_wof_001 | T12: S01aH02 | U12: 0.0042247837 | V12: IMPNRGZ | X12: 0.0035388128 | Y12: 0.0059087255 | Z12: S01aH02 | AA12: elc_roadtransport | AC12: elc_buildings | AD12: S01aH02 | AE12: 0.0042466859 | AG12: ELC | AH12: S01aH02 | AI12: 0.043835338 | AK12: 2020 | AL12: S02 | AM12: 0.18237548 | AN12: hydro
C13: S03 | D13: c | E13: 0202h03 | F13: S08 | G13: b | I13: elc_spv_001 | J13: S01aH03 | K13: 0.0027186497 | L13: IMPNRGZ | N13: elc_won_001 | O13: S01aH03 | P13: 0.0035272665 | Q13: IMPNRGZ | S13: elc_wof_001 | T13: S01aH03 | U13: 0.0043738353 | V13: IMPNRGZ | X13: 0.0035388128 | Y13: 0.0045214595 | Z13: S01aH03 | AA13: elc_roadtransport | AC13: elc_buildings | AD13: S01aH03 | AE13: 0.0044051999 | AG13: ELC | AH13: S01aH03 | AI13: 0.047390752 | AK13: 2020 | AL13: S03 | AM13: 0.18207885 | AN13: hydro
C14: S04 | D14: d | E14: 0202h04 | F14: S12 | G14: b | I14: elc_spv_001 | J14: S01aH04 | K14: 0.0050405901 | L14: IMPNRGZ | N14: elc_won_001 | O14: S01aH04 | P14: 0.0034559881 | Q14: IMPNRGZ | S14: elc_wof_001 | T14: S01aH04 | U14: 0.0044837047 | V14: IMPNRGZ | X14: 0.0035388128 | Y14: 0.0044803554 | Z14: S01aH04 | AA14: elc_roadtransport | AC14: elc_buildings | AD14: S01aH04 | AE14: 0.0044733956 | AG14: ELC | AH14: S01aH04 | AI14: 0.04500612 | AK14: 2020 | AL14: S04 | AM14: 0.24814815 | AN14: hydro
C15: S05 | E15: 0202h05 | G15: b | I15: elc_spv_001 | J15: S01aH05 | K15: 0.041974402 | L15: IMPNRGZ | N15: elc_won_001 | O15: S01aH05 | P15: 0.016552433 | Q15: IMPNRGZ | S15: elc_wof_001 | T15: S01aH05 | U15: 0.027340431 | V15: IMPNRGZ | X15: 0.021232877 | Y15: 0.027765872 | Z15: S01aH05 | AA15: elc_roadtransport | AC15: elc_buildings | AD15: S01aH05 | AE15: 0.026378195 | AG15: ELC | AH15: S01aH05 | AI15: 0.056535021 | AK15: 2020 | AL15: S05 | AM15: 0.35483871 | AN15: hydro
C16: S06 | E16: 0202h06 | G16: b | I16: elc_spv_001 | J16: S01aH06 | K16: 0.0035998388 | L16: IMPNRGZ | N16: elc_won_001 | O16: S01aH06 | P16: 0.0029731668 | Q16: IMPNRGZ | S16: elc_wof_001 | T16: S01aH06 | U16: 0.0044991124 | V16: IMPNRGZ | X16: 0.0035388128 | Y16: 0.0068849497 | Z16: S01aH06 | AA16: elc_roadtransport | AC16: elc_buildings | AD16: S01aH06 | AE16: 0.0045428868 | AG16: ELC | AH16: S01aH06 | AI16: 0.048485566 | AK16: 2020 | AL16: S06 | AM16: 0.38074074 | AN16: hydro
C17: S07 | E17: 0202h07 | G17: b | I17: elc_spv_001 | J17: S01aH07 | K17: 0 | L17: IMPNRGZ | N17: elc_won_001 | O17: S01aH07 | P17: 0.0031199516 | Q17: IMPNRGZ | S17: elc_wof_001 | T17: S01aH07 | U17: 0.0044215051 | V17: IMPNRGZ | X17: 0.0035388128 | Y17: 0.0068849497 | Z17: S01aH07 | AA17: elc_roadtransport | AC17: elc_buildings | AD17: S01aH07 | AE17: 0.0046130613 | AG17: ELC | AH17: S01aH07 | AI17: 0.044392857 | AK17: 2020 | AL17: S07 | AM17: 0.31541219 | AN17: hydro
C18: S08 | E18: 0202h08 | G18: b | I18: elc_spv_001 | J18: S01aH08 | K18: 0 | L18: IMPNRGZ | N18: elc_won_001 | O18: S01aH08 | P18: 0.022475735 | Q18: IMPNRGZ | S18: elc_wof_001 | T18: S01aH08 | U18: 0.027122878 | V18: IMPNRGZ | X18: 0.021232877 | Y18: 0.018702401 | Z18: S01aH08 | AA18: elc_roadtransport | AC18: elc_buildings | AD18: S01aH08 | AE18: 0.02408234 | AG18: ELC | AH18: S01aH08 | AI18: 0.17169254 | AK18: 2020 | AL18: S08 | AM18: 0.28172043 | AN18: hydro
C19: S09 | E19: 0202h09 | G19: b | I19: elc_spv_001 | J19: S02aH01 | K19: 0 | L19: IMPNRGZ | N19: elc_won_001 | O19: S02aH01 | P19: 0.030662171 | Q19: IMPNRGZ | S19: elc_wof_001 | T19: S02aH01 | U19: 0.026969863 | V19: IMPNRGZ | X19: 0.021575342 | Y19: 0.0085204982 | Z19: S02aH01 | AA19: elc_roadtransport | AC19: elc_buildings | AD19: S02aH01 | AE19: 0.019279749 | AG19: ELC | AH19: S02aH01 | AI19: 0.27606878 | AK19: 2020 | AL19: S09 | AM19: 0.26814815 | AN19: hydro
C20: S10 | E20: 0202h10 | G20: b | I20: elc_spv_001 | J20: S02aH02 | K20: 0.00063754206 | L20: IMPNRGZ | N20: elc_won_001 | O20: S02aH02 | P20: 0.0039701699 | Q20: IMPNRGZ | S20: elc_wof_001 | T20: S02aH02 | U20: 0.0035039165 | V20: IMPNRGZ | X20: 0.0030821918 | Y20: 0.0051463093 | Z20: S02aH02 | AA20: elc_roadtransport | AC20: elc_buildings | AD20: S02aH02 | AE20: 0.0037231056 | AG20: ELC | AH20: S02aH02 | AI20: 0.041805 | AK20: 2020 | AL20: S10 | AM20: 0.28387097 | AN20: hydro
C21: S11 | E21: 0202h11 | G21: b | I21: elc_spv_001 | J21: S02aH03 | K21: 0.0045098958 | L21: IMPNRGZ | N21: elc_won_001 | O21: S02aH03 | P21: 0.0038281094 | Q21: IMPNRGZ | S21: elc_wof_001 | T21: S02aH03 | U21: 0.0032995834 | V21: IMPNRGZ | X21: 0.0030821918 | Y21: 0.0039380454 | Z21: S02aH03 | AA21: elc_roadtransport | AC21: elc_buildings | AD21: S02aH03 | AE21: 0.0038687411 | AG21: ELC | AH21: S02aH03 | AI21: 0.04139704 | AK21: 2020 | AL21: S11 | AM21: 0.22666667 | AN21: hydro
C22: S12 | E22: 0202h12 | G22: b | I22: elc_spv_001 | J22: S02aH04 | K22: 0.0070170723 | L22: IMPNRGZ | N22: elc_won_001 | O22: S02aH04 | P22: 0.0033212782 | Q22: IMPNRGZ | S22: elc_wof_001 | T22: S02aH04 | U22: 0.0031972431 | V22: IMPNRGZ | X22: 0.0030821918 | Y22: 0.003902245 | Z22: S02aH04 | AA22: elc_roadtransport | AC22: elc_buildings | AD22: S02aH04 | AE22: 0.0039276066 | AG22: ELC | AH22: S02aH04 | AI22: 0.039243327 | AK22: 2020 | AL22: S12 | AM22: 0.23154122 | AN22: hydro
E23: 0202h13 | G23: b | I23: elc_spv_001 | J23: S02aH05 | K23: 0.047376693 | L23: IMPNRGZ | N23: elc_won_001 | O23: S02aH05 | P23: 0.018107647 | Q23: IMPNRGZ | S23: elc_wof_001 | T23: S02aH05 | U23: 0.019843625 | V23: IMPNRGZ | X23: 0.018493151 | Y23: 0.024183179 | Z23: S02aH05 | AA23: elc_roadtransport | AC23: elc_buildings | AD23: S02aH05 | AE23: 0.023140954 | AG23: ELC | AH23: S02aH05 | AI23: 0.059236362 | AK23: 2021 | AL23: S01 | AM23: 0.24366472 | AN23: hydro
E24: 0202h14 | G24: b | I24: elc_spv_001 | J24: S02aH06 | K24: 0.0054671533 | L24: IMPNRGZ | N24: elc_won_001 | O24: S02aH06 | P24: 0.0034686282 | Q24: IMPNRGZ | S24: elc_wof_001 | T24: S02aH06 | U24: 0.0038327945 | V24: IMPNRGZ | X24: 0.0030821918 | Y24: 0.0059965691 | Z24: S02aH06 | AA24: elc_roadtransport | AC24: elc_buildings | AD24: S02aH06 | AE24: 0.0039624835 | AG24: ELC | AH24: S02aH06 | AI24: 0.059386897 | AK24: 2021 | AL24: S02 | AM24: 0.24841143 | AN24: hydro
E25: 0202h15 | G25: b | I25: elc_spv_001 | J25: S02aH07 | K25: 0.0028447176 | L25: IMPNRGZ | N25: elc_won_001 | O25: S02aH07 | P25: 0.0035403844 | Q25: IMPNRGZ | S25: elc_wof_001 | T25: S02aH07 | U25: 0.0039029275 | V25: IMPNRGZ | X25: 0.0030821918 | Y25: 0.0059965691 | Z25: S02aH07 | AA25: elc_roadtransport | AC25: elc_buildings | AD25: S02aH07 | AE25: 0.0040535339 | AG25: ELC | AH25: S02aH07 | AI25: 0.039581327 | AK25: 2021 | AL25: S03 | AM25: 0.20436396 | AN25: hydro
E26: 0202h16 | G26: b | I26: elc_spv_001 | J26: S02aH08 | K26: 0 | L26: IMPNRGZ | N26: elc_won_001 | O26: S02aH08 | P26: 0.02501924 | Q26: IMPNRGZ | S26: elc_wof_001 | T26: S02aH08 | U26: 0.02448048 | V26: IMPNRGZ | X26: 0.018493151 | Y26: 0.016289188 | Z26: S02aH08 | AA26: elc_roadtransport | AC26: elc_buildings | AD26: S02aH08 | AE26: 0.021132042 | AG26: ELC | AH26: S02aH08 | AI26: 0.16756075 | AK26: 2021 | AL26: S04 | AM26: 0.20896095 | AN26: hydro
E27: 0202h17 | G27: b | I27: elc_spv_001 | J27: S02b0202h01 | K27: 0 | L27: IMPNRGZ | N27: elc_won_001 | O27: S02b0202h01 | P27: 3.6345216e-05 | Q27: IMPNRGZ | S27: elc_wof_001 | T27: S02b0202h01 | U27: 0.00030621002 | V27: IMPNRGZ | X27: 0.00011415525 | Y27: 2.1546545e-05 | Z27: S02b0202h01 | AA27: elc_roadtransport | AC27: elc_buildings | AD27: S02b0202h01 | AE27: 9.4838184e-05 | AG27: ELC | AH27: S02b0202h01 | AI27: 0 | AK27: 2021 | AL27: S05 | AM27: 0.29511299 | AN27: hydro
E28: 0202h18 | G28: b | I28: elc_spv_001 | J28: S02b0202h02 | K28: 0 | L28: IMPNRGZ | N28: elc_won_001 | O28: S02b0202h02 | P28: 3.9047846e-05 | Q28: IMPNRGZ | S28: elc_wof_001 | T28: S02b0202h02 | U28: 0.00030563629 | V28: IMPNRGZ | X28: 0.00011415525 | Y28: 1.4916839e-05 | Z28: S02b0202h02 | AA28: elc_roadtransport | AC28: elc_buildings | AD28: S02b0202h02 | AE28: 8.8624232e-05 | AG28: ELC | AH28: S02b0202h02 | AI28: 0 | AK28: 2021 | AL28: S06 | AM28: 0.36845059 | AN28: hydro
E29: 0202h19 | G29: b | I29: elc_spv_001 | J29: S02b0202h03 | K29: 0 | L29: IMPNRGZ | N29: elc_won_001 | O29: S02b0202h03 | P29: 3.4120995e-05 | Q29: IMPNRGZ | S29: elc_wof_001 | T29: S02b0202h03 | U29: 0.00030157663 | V29: IMPNRGZ | X29: 0.00011415525 | Y29: 1.6574265e-05 | Z29: S02b0202h03 | AA29: elc_roadtransport | AC29: elc_buildings | AD29: S02b0202h03 | AE29: 8.5582962e-05 | AG29: ELC | AH29: S02b0202h03 | AI29: 0 | AK29: 2021 | AL29: S07 | AM29: 0.33584287 | AN29: hydro
E30: 0202h20 | G30: b | I30: elc_spv_001 | J30: S02b0202h04 | K30: 0 | L30: IMPNRGZ | N30: elc_won_001 | O30: S02b0202h04 | P30: 4.4727446e-05 | Q30: IMPNRGZ | S30: elc_wof_001 | T30: S02b0202h04 | U30: 0.00034998146 | V30: IMPNRGZ | X30: 0.00011415525 | Y30: 1.4585353e-05 | Z30: S02b0202h04 | AA30: elc_roadtransport | AC30: elc_buildings | AD30: S02b0202h04 | AE30: 8.5710621e-05 | AG30: ELC | AH30: S02b0202h04 | AI30: 0 | AK30: 2021 | AL30: S08 | AM30: 0.30726049 | AN30: hydro
E31: 0202h21 | G31: b | I31: elc_spv_001 | J31: S02b0202h05 | K31: 0 | L31: IMPNRGZ | N31: elc_won_001 | O31: S02b0202h05 | P31: 4.832878e-05 | Q31: IMPNRGZ | S31: elc_wof_001 | T31: S02b0202h05 | U31: 0.00039516204 | V31: IMPNRGZ | X31: 0.00011415525 | Y31: 2.1215059e-05 | Z31: S02b0202h05 | AA31: elc_roadtransport | AC31: elc_buildings | AD31: S02b0202h05 | AE31: 8.6251291e-05 | AG31: ELC | AH31: S02b0202h05 | AI31: 0 | AK31: 2021 | AL31: S09 | AM31: 0.20010042 | AN31: hydro
E32: 0202h22 | G32: b | I32: elc_spv_001 | J32: S02b0202h06 | K32: 0 | L32: IMPNRGZ | N32: elc_won_001 | O32: S02b0202h06 | P32: 4.1652789e-05 | Q32: IMPNRGZ | S32: elc_wof_001 | T32: S02b0202h06 | U32: 0.00041938355 | V32: IMPNRGZ | X32: 0.00011415525 | Y32: 5.7678443e-05 | Z32: S02b0202h06 | AA32: elc_roadtransport | AC32: elc_buildings | AD32: S02b0202h06 | AE32: 9.7616628e-05 | AG32: ELC | AH32: S02b0202h06 | AI32: 0 | AK32: 2021 | AL32: S10 | AM32: 0.19293101 | AN32: hydro
E33: 0202h23 | G33: b | I33: elc_spv_001 | J33: S02b0202h07 | K33: 0 | L33: IMPNRGZ | N33: elc_won_001 | O33: S02b0202h07 | P33: 3.8205011e-05 | Q33: IMPNRGZ | S33: elc_wof_001 | T33: S02b0202h07 | U33: 0.00043927519 | V33: IMPNRGZ | X33: 0.00011415525 | Y33: 0.0001690575 | Z33: S02b0202h07 | AA33: elc_roadtransport | AC33: elc_buildings | AD33: S02b0202h07 | AE33: 0.00010350017 | AG33: ELC | AH33: S02b0202h07 | AI33: 0 | AK33: 2021 | AL33: S11 | AM33: 0.19123988 | AN33: hydro
