Workbook

Sheet ScenMap
I1: C
I2: ar6_r10 | J2: timeslice
B4: ~ScenMap | H4: ~ScenG | O4: ~Scenmap
B5: Oname | C5: Name | D5: Desc | E5: Ldesc | H5: Scen | I5: ="sg_"&I2 -> sg_ar6_r10 | J5: ="sg_"&J2 -> sg_timeslice | N5: priority | O5: scen | P5: case_no | Q5: timeslice | R5: climate
B6: ="vs~"&TEXT(P6,"0000") -> vs~0001 | C6: =H6 -> e 1.5 deg no OS.kAnn | H6: =_xlfn.TEXTJOIN(".",TRUE,I6:J6) -> e 1.5 deg no OS.kAnn | I6: =VLOOKUP(R6,$W$6:$X$12,2,FALSE) -> e 1.5 deg no OS | J6: =VLOOKUP(Q6,$T$6:$U$20,2,FALSE) -> kAnn | L6: Limit warming to 1.5°C (>50%) with no or limited overshoot | N6: 5 | O6: e 1.5 deg no OS.kAnn | P6: 1 | Q6: ts_annual | R6: C1 | T6: ts_annual | U6: kAnn | W6: C1 | X6: e 1.5 deg no OS
B7: ="vs~"&TEXT(P7,"0000") -> vs~0002 | C7: =H7 -> d 1.5 deg OS.kAnn | H7: =_xlfn.TEXTJOIN(".",TRUE,I7:J7) -> d 1.5 deg OS.kAnn | I7: =VLOOKUP(R7,$W$6:$X$12,2,FALSE) -> d 1.5 deg OS | J7: =VLOOKUP(Q7,$T$6:$U$20,2,FALSE) -> kAnn | L7: Limit warming to 1.5°C (>67%) with high overshoot | N7: 5 | O7: d 1.5 deg OS.kAnn | P7: 2 | Q7: ts_annual | R7: C2 | T7: ts_12t | U7: k12 | W7: C2 | X7: d 1.5 deg OS
B8: ="vs~"&TEXT(P8,"0000") -> vs~0003 | C8: =H8 -> c 2 deg (67%).kAnn | H8: =_xlfn.TEXTJOIN(".",TRUE,I8:J8) -> c 2 deg (67%).kAnn | I8: =VLOOKUP(R8,$W$6:$X$12,2,FALSE) -> c 2 deg (67%) | J8: =VLOOKUP(Q8,$T$6:$U$20,2,FALSE) -> kAnn | L8: Limit warming to 2°C (>67%) with higher action post-2030 | N8: 5 | O8: c 2 deg (67%).kAnn | P8: 3 | Q8: ts_annual | R8: C3 | T8: ts_012 | U8: j12 | W8: C3 | X8: c 2 deg (67%)
B9: ="vs~"&TEXT(P9,"0000") -> vs~0004 | C9: =H9 -> b 2 deg (50%).kAnn | H9: =_xlfn.TEXTJOIN(".",TRUE,I9:J9) -> b 2 deg (50%).kAnn | I9: =VLOOKUP(R9,$W$6:$X$12,2,FALSE) -> b 2 deg (50%) | J9: =VLOOKUP(Q9,$T$6:$U$20,2,FALSE) -> kAnn | L9: Limit warming to 2°C (>50%) with immediate action | N9: 5 | O9: b 2 deg (50%).kAnn | P9: 4 | Q9: ts_annual | R9: C4 | T9: ts_024 | U9: i24 | W9: C4 | X9: b 2 deg (50%)
B10: ="vs~"&TEXT(P10,"0000") -> vs~0005 | C10: =H10 -> a 3 deg.kAnn | H10: =_xlfn.TEXTJOIN(".",TRUE,I10:J10) -> a 3 deg.kAnn | I10: =VLOOKUP(R10,$W$6:$X$12,2,FALSE) -> a 3 deg | J10: =VLOOKUP(Q10,$T$6:$U$20,2,FALSE) -> kAnn | L10: Likely above 3°C warming with limited mitigation | N10: 5 | O10: a 3 deg.kAnn | P10: 5 | Q10: ts_annual | R10: C7 | T10: ts_048 | U10: h48 | W10: C7 | X10: a 3 deg
B11: ="vs~"&TEXT(P11,"0000") -> vs~0006 | C11: =H11 -> e 1.5 deg no OS.k12 | H11: =_xlfn.TEXTJOIN(".",TRUE,I11:J11) -> e 1.5 deg no OS.k12 | I11: =VLOOKUP(R11,$W$6:$X$12,2,FALSE) -> e 1.5 deg no OS | J11: =VLOOKUP(Q11,$T$6:$U$20,2,FALSE) -> k12 | N11: 5 | O11: e 1.5 deg no OS.k12 | P11: 6 | Q11: ts_12t | R11: C1 | T11: ts_064 | U11: g64
B12: ="vs~"&TEXT(P12,"0000") -> vs~0007 | C12: =H12 -> d 1.5 deg OS.k12 | H12: =_xlfn.TEXTJOIN(".",TRUE,I12:J12) -> d 1.5 deg OS.k12 | I12: =VLOOKUP(R12,$W$6:$X$12,2,FALSE) -> d 1.5 deg OS | J12: =VLOOKUP(Q12,$T$6:$U$20,2,FALSE) -> k12 | N12: 5 | O12: d 1.5 deg OS.k12 | P12: 7 | Q12: ts_12t | R12: C2 | T12: ts_096P50 | U12: f96p50
B13: ="vs~"&TEXT(P13,"0000") -> vs~0008 | C13: =H13 -> c 2 deg (67%).k12 | H13: =_xlfn.TEXTJOIN(".",TRUE,I13:J13) -> c 2 deg (67%).k12 | I13: =VLOOKUP(R13,$W$6:$X$12,2,FALSE) -> c 2 deg (67%) | J13: =VLOOKUP(Q13,$T$6:$U$20,2,FALSE) -> k12 | N13: 5 | O13: c 2 deg (67%).k12 | P13: 8 | Q13: ts_12t | R13: C3 | T13: ts_096P10 | U13: f96p10
B14: ="vs~"&TEXT(P14,"0000") -> vs~0009 | C14: =H14 -> b 2 deg (50%).k12 | H14: =_xlfn.TEXTJOIN(".",TRUE,I14:J14) -> b 2 deg (50%).k12 | I14: =VLOOKUP(R14,$W$6:$X$12,2,FALSE) -> b 2 deg (50%) | J14: =VLOOKUP(Q14,$T$6:$U$20,2,FALSE) -> k12 | N14: 5 | O14: b 2 deg (50%).k12 | P14: 9 | Q14: ts_12t | R14: C4 | T14: ts_096P90 | U14: f96p90
B15: ="vs~"&TEXT(P15,"0000") -> vs~0010 | C15: =H15 -> a 3 deg.k12 | H15: =_xlfn.TEXTJOIN(".",TRUE,I15:J15) -> a 3 deg.k12 | I15: =VLOOKUP(R15,$W$6:$X$12,2,FALSE) -> a 3 deg | J15: =VLOOKUP(Q15,$T$6:$U$20,2,FALSE) -> k12 | N15: 5 | O15: a 3 deg.k12 | P15: 10 | Q15: ts_12t | R15: C7 | T15: s1p1v1_d | U15: e3d
B16: ="vs~"&TEXT(P16,"0000") -> vs~0011 | C16: =H16 -> e 1.5 deg no OS.j12 | H16: =_xlfn.TEXTJOIN(".",TRUE,I16:J16) -> e 1.5 deg no OS.j12 | I16: =VLOOKUP(R16,$W$6:$X$12,2,FALSE) -> e 1.5 deg no OS | J16: =VLOOKUP(Q16,$T$6:$U$20,2,FALSE) -> j12 | N16: 5 | O16: e 1.5 deg no OS.j12 | P16: 11 | Q16: ts_012 | R16: C1 | T16: s3p3v3_d | U16: d9d
B17: ="vs~"&TEXT(P17,"0000") -> vs~0012 | C17: =H17 -> d 1.5 deg OS.j12 | H17: =_xlfn.TEXTJOIN(".",TRUE,I17:J17) -> d 1.5 deg OS.j12 | I17: =VLOOKUP(R17,$W$6:$X$12,2,FALSE) -> d 1.5 deg OS | J17: =VLOOKUP(Q17,$T$6:$U$20,2,FALSE) -> j12 | N17: 5 | O17: d 1.5 deg OS.j12 | P17: 12 | Q17: ts_012 | R17: C2 | T17: s5p5v5_d | U17: c15d
B18: ="vs~"&TEXT(P18,"0000") -> vs~0013 | C18: =H18 -> c 2 deg (67%).j12 | H18: =_xlfn.TEXTJOIN(".",TRUE,I18:J18) -> c 2 deg (67%).j12 | I18: =VLOOKUP(R18,$W$6:$X$12,2,FALSE) -> c 2 deg (67%) | J18: =VLOOKUP(Q18,$T$6:$U$20,2,FALSE) -> j12 | N18: 5 | O18: c 2 deg (67%).j12 | P18: 13 | Q18: ts_012 | R18: C3 | T18: s2_w | U18: b2w
B19: ="vs~"&TEXT(P19,"0000") -> vs~0014 | C19: =H19 -> b 2 deg (50%).j12 | H19: =_xlfn.TEXTJOIN(".",TRUE,I19:J19) -> b 2 deg (50%).j12 | I19: =VLOOKUP(R19,$W$6:$X$12,2,FALSE) -> b 2 deg (50%) | J19: =VLOOKUP(Q19,$T$6:$U$20,2,FALSE) -> j12 | N19: 5 | O19: b 2 deg (50%).j12 | P19: 14 | Q19: ts_012 | R19: C4 | T19: s2_w_p2_d | U19: a2w2d
B20: ="vs~"&TEXT(P20,"0000") -> vs~0015 | C20: =H20 -> a 3 deg.j12 | H20: =_xlfn.TEXTJOIN(".",TRUE,I20:J20) -> a 3 deg.j12 | I20: =VLOOKUP(R20,$W$6:$X$12,2,FALSE) -> a 3 deg | J20: =VLOOKUP(Q20,$T$6:$U$20,2,FALSE) -> j12 | N20: 5 | O20: a 3 deg.j12 | P20: 15 | Q20: ts_012 | R20: C7
B21: ="vs~"&TEXT(P21,"0000") -> vs~0016 | C21: =H21 -> e 1.5 deg no OS.i24 | H21: =_xlfn.TEXTJOIN(".",TRUE,I21:J21) -> e 1.5 deg no OS.i24 | I21: =VLOOKUP(R21,$W$6:$X$12,2,FALSE) -> e 1.5 deg no OS | J21: =VLOOKUP(Q21,$T$6:$U$20,2,FALSE) -> i24 | N21: 5 | O21: e 1.5 deg no OS.i24 | P21: 16 | Q21: ts_024 | R21: C1
B22: ="vs~"&TEXT(P22,"0000") -> vs~0017 | C22: =H22 -> d 1.5 deg OS.i24 | H22: =_xlfn.TEXTJOIN(".",TRUE,I22:J22) -> d 1.5 deg OS.i24 | I22: =VLOOKUP(R22,$W$6:$X$12,2,FALSE) -> d 1.5 deg OS | J22: =VLOOKUP(Q22,$T$6:$U$20,2,FALSE) -> i24 | N22: 5 | O22: d 1.5 deg OS.i24 | P22: 17 | Q22: ts_024 | R22: C2
B23: ="vs~"&TEXT(P23,"0000") -> vs~0018 | C23: =H23 -> c 2 deg (67%).i24 | H23: =_xlfn.TEXTJOIN(".",TRUE,I23:J23) -> c 2 deg (67%).i24 | I23: =VLOOKUP(R23,$W$6:$X$12,2,FALSE) -> c 2 deg (67%) | J23: =VLOOKUP(Q23,$T$6:$U$20,2,FALSE) -> i24 | N23: 5 | O23: c 2 deg (67%).i24 | P23: 18 | Q23: ts_024 | R23: C3
B24: ="vs~"&TEXT(P24,"0000") -> vs~0019 | C24: =H24 -> b 2 deg (50%).i24 | H24: =_xlfn.TEXTJOIN(".",TRUE,I24:J24) -> b 2 deg (50%).i24 | I24: =VLOOKUP(R24,$W$6:$X$12,2,FALSE) -> b 2 deg (50%) | J24: =VLOOKUP(Q24,$T$6:$U$20,2,FALSE) -> i24 | N24: 5 | O24: b 2 deg (50%).i24 | P24: 19 | Q24: ts_024 | R24: C4
B25: ="vs~"&TEXT(P25,"0000") -> vs~0020 | C25: =H25 -> a 3 deg.i24 | H25: =_xlfn.TEXTJOIN(".",TRUE,I25:J25) -> a 3 deg.i24 | I25: =VLOOKUP(R25,$W$6:$X$12,2,FALSE) -> a 3 deg | J25: =VLOOKUP(Q25,$T$6:$U$20,2,FALSE) -> i24 | N25: 5 | O25: a 3 deg.i24 | P25: 20 | Q25: ts_024 | R25: C7
B26: ="vs~"&TEXT(P26,"0000") -> vs~0021 | C26: =H26 -> e 1.5 deg no OS.h48 | H26: =_xlfn.TEXTJOIN(".",TRUE,I26:J26) -> e 1.5 deg no OS.h48 | I26: =VLOOKUP(R26,$W$6:$X$12,2,FALSE) -> e 1.5 deg no OS | J26: =VLOOKUP(Q26,$T$6:$U$20,2,FALSE) -> h48 | N26: 5 | O26: e 1.5 deg no OS.h48 | P26: 21 | Q26: ts_048 | R26: C1
B27: ="vs~"&TEXT(P27,"0000") -> vs~0022 | C27: =H27 -> d 1.5 deg OS.h48 | H27: =_xlfn.TEXTJOIN(".",TRUE,I27:J27) -> d 1.5 deg OS.h48 | I27: =VLOOKUP(R27,$W$6:$X$12,2,FALSE) -> d 1.5 deg OS | J27: =VLOOKUP(Q27,$T$6:$U$20,2,FALSE) -> h48 | N27: 5 | O27: d 1.5 deg OS.h48 | P27: 22 | Q27: ts_048 | R27: C2
B28: ="vs~"&TEXT(P28,"0000") -> vs~0023 | C28: =H28 -> c 2 deg (67%).h48 | H28: =_xlfn.TEXTJOIN(".",TRUE,I28:J28) -> c 2 deg (67%).h48 | I28: =VLOOKUP(R28,$W$6:$X$12,2,FALSE) -> c 2 deg (67%) | J28: =VLOOKUP(Q28,$T$6:$U$20,2,FALSE) -> h48 | N28: 5 | O28: c 2 deg (67%).h48 | P28: 23 | Q28: ts_048 | R28: C3
B29: ="vs~"&TEXT(P29,"0000") -> vs~0024 | C29: =H29 -> b 2 deg (50%).h48 | H29: =_xlfn.TEXTJOIN(".",TRUE,I29:J29) -> b 2 deg (50%).h48 | I29: =VLOOKUP(R29,$W$6:$X$12,2,FALSE) -> b 2 deg (50%) | J29: =VLOOKUP(Q29,$T$6:$U$20,2,FALSE) -> h48 | N29: 5 | O29: b 2 deg (50%).h48 | P29: 24 | Q29: ts_048 | R29: C4
B30: ="vs~"&TEXT(P30,"0000") -> vs~0025 | C30: =H30 -> a 3 deg.h48 | H30: =_xlfn.TEXTJOIN(".",TRUE,I30:J30) -> a 3 deg.h48 | I30: =VLOOKUP(R30,$W$6:$X$12,2,FALSE) -> a 3 deg | J30: =VLOOKUP(Q30,$T$6:$U$20,2,FALSE) -> h48 | N30: 5 | O30: a 3 deg.h48 | P30: 25 | Q30: ts_048 | R30: C7
B31: ="vs~"&TEXT(P31,"0000") -> vs~0026 | C31: =H31 -> e 1.5 deg no OS.g64 | H31: =_xlfn.TEXTJOIN(".",TRUE,I31:J31) -> e 1.5 deg no OS.g64 | I31: =VLOOKUP(R31,$W$6:$X$12,2,FALSE) -> e 1.5 deg no OS | J31: =VLOOKUP(Q31,$T$6:$U$20,2,FALSE) -> g64 | N31: 5 | O31: e 1.5 deg no OS.g64 | P31: 26 | Q31: ts_064 | R31: C1
... B75: ="vs~"&TEXT(P75,"0000") -> vs~0070 | C75: =H75 -> a 3 deg.a2w2d | H75: =_xlfn.TEXTJOIN(".",TRUE,I75:J75) -> a 3 deg.a2w2d | I75: =VLOOKUP(R75,$W$6:$X$12,2,FALSE) -> a 3 deg | J75: =VLOOKUP(Q75,$T$6:$U$20,2,FALSE) -> a2w2d | N75: 5 | O75: a 3 deg.a2w2d | P75: 70 | Q75: s2_w_p2_d | R75: C7

Sheet geolocation
B9: ~geolocation | F9: ~geolocation
B10: region | C10: lat | D10: lng | F10: region | G10: lat | H10: lng
B11: p_w5065566 | C11: 44.14948 | D11: -76.848576 | F11: CAN-e_w5065566-500 | G11: 44.14948 | H11: -76.848576
B12: p_w24364552 | C12: 45.436365 | D12: -73.424143 | F12: CAN-e_w24364552-315 | G12: 45.436365 | H12: -73.424143
B13: p_w25154845 | C13: 49.176397 | D13: -121.77571 | F13: CAN-e_w25154845-360 | G13: 49.176397 | H13: -121.77571
B14: p_w25164969 | C14: 49.236843 | D14: -121.67995 | F14: CAN-e_w25164969-360 | G14: 49.236843 | H14: -121.67995
B15: p_w25495523 | C15: 49.068502 | D15: -122.29729 | F15: CAN-e_w25495523-500 | G15: 49.068502 | H15: -122.29729
B16: p_w25500667 | C16: 49.158412 | D16: -122.87454 | F16: CAN-e_w25500667-500 | G16: 49.158412 | H16: -122.87454
B17: p_w26103715 | C17: 49.309716 | D17: -122.80675 | F17: CAN-e_w26103715-500 | G17: 49.309716 | H17: -122.80675
B18: p_w26296871 | C18: 45.460221 | D18: -73.439844 | F18: CAN-e_w26296871-315 | G18: 45.460221 | H18: -73.439844
B19: p_w27736159 | C19: 46.859212 | D19: -71.315634 | F19: CAN-e_w27736159-735 | G19: 46.859212 | H19: -71.315634
B20: p_w29999719 | C20: 49.993359 | D20: -97.429046 | F20: CAN-e_w27736159-315 | G20: 46.859086 | H20: -71.315381
B21: p_w32963410 | C21: 43.85239 | D21: -79.113085 | F21: CAN-e_w29999719-500 | G21: 49.993359 | H21: -97.429046
B22: p_w33144100 | C22: 45.409882 | D22: -73.428304 | F22: CAN-e_w32963410-500 | G22: 43.85239 | H22: -79.113085
... B805: rez_wof_107 | C805: 45.838916 | D805: -58.218726 | F805: CAN-elc_wof_079 | G805: 59.689668 | H805: -67.305397
F806: CAN-elc_wof_080 | G806: 60.499728 | H806: -62.492669
F807: CAN-elc_wof_081 | G807: 61.224082 | H807: -66.084357
F808: CAN-elc_wof_082 | G808: 64.410218 | H808: -63.646741
F809: CAN-elc_wof_083 | G809: 65.522022 | H809: -66.31428
F810: CAN-elc_wof_084 | G810: 62.999437 | H810: -66.964173
F811: CAN-elc_wof_085 | G811: 67.554937 | H811: -59.261506
F812: CAN-elc_wof_086 | G812: 65.641092 | H812: -58.908723
F813: CAN-elc_wof_087 | G813: 65.313994 | H813: -61.291744
F814: CAN-elc_wof_088 | G814: 62.99571 | H814: -61.720241
F815: CAN-elc_wof_089 | G815: 62.247175 | H815: -64.03442
F816: CAN-elc_wof_090 | G816: 48.937488 | H816: -126.34614
F817: CAN-elc_wof_091 | G817: 54.025899 | H817: -132.20739
... F833: CAN-elc_wof_107 | G833: 45.838916 | H833: -58.218726

Sheet process_map_geo
B9: ~process_map | F9: ~process_map | J9: ~commodity_map
B10: dimension | C10: description | D10: pset_set | F10: pset_set | G10: dimension | H10: description | J10: dimension | K10: name | L10: description
B11: grid_node | C11: p_w5065566 | D11: p_w5065566 | F11: p_w5065566 | G11: admin_1 | H11: Ontario | J11: region_com | K11: e_w5065566-500 | L11: e_w5065566-500
B12: grid_node | C12: p_w24364552 | D12: p_w24364552 | F12: p_w24364552 | G12: admin_1 | H12: Québec | J12: region_com | K12: e_w24364552-315 | L12: e_w24364552-315
B13: grid_node | C13: p_w25154845 | D13: p_w25154845 | F13: p_w25154845 | G13: admin_1 | H13: British Columbia | J13: region_com | K13: e_w25154845-360 | L13: e_w25154845-360
B14: grid_node | C14: p_w25164969 | D14: p_w25164969 | F14: p_w25164969 | G14: admin_1 | H14: British Columbia | J14: region_com | K14: e_w25164969-360 | L14: e_w25164969-360
B15: grid_node | C15: p_w25495523 | D15: p_w25495523 | F15: p_w25495523 | G15: admin_1 | H15: British Columbia | J15: region_com | K15: e_w25495523-500 | L15: e_w25495523-500
B16: grid_node | C16: p_w25500667 | D16: p_w25500667 | F16: p_w25500667 | G16: admin_1 | H16: British Columbia | J16: region_com | K16: e_w25500667-500 | L16: e_w25500667-500
B17: grid_node | C17: p_w26103715 | D17: p_w26103715 | F17: p_w26103715 | G17: admin_1 | H17: British Columbia | J17: region_com | K17: e_w26103715-500 | L17: e_w26103715-500
B18: grid_node | C18: p_w26296871 | D18: p_w26296871 | F18: p_w26296871 | G18: admin_1 | H18: Québec | J18: region_com | K18: e_w26296871-315 | L18: e_w26296871-315
B19: grid_node | C19: p_w27736159 | D19: p_w27736159 | F19: p_w27736159 | G19: admin_1 | H19: Québec | J19: region_com | K19: e_w27736159-735 | L19: e_w27736159-735
B20: grid_node | C20: p_w29999719 | D20: p_w29999719 | F20: p_w29999719 | G20: admin_1 | H20: Manitoba | J20: region_com | K20: e_w27736159-315 | L20: e_w27736159-315
B21: grid_node | C21: p_w32963410 | D21: p_w32963410 | F21: p_w32963410 | G21: admin_1 | H21: Ontario | J21: region_com | K21: e_w29999719-500 | L21: e_w29999719-500
... B805: grid_node | C805: rez_wof_107 | D805: rez_wof_107 | F805: rez_wof_107 | G805: admin_1 | H805: Unknown | J805: region_com | K805: elc_wof_079 | L805: elc_wof_079
J806: region_com | K806: elc_wof_080 | L806: elc_wof_080
J807: region_com | K807: elc_wof_081 | L807: elc_wof_081
J808: region_com | K808: elc_wof_082 | L808: elc_wof_082
J809: region_com | K809: elc_wof_083 | L809: elc_wof_083
J810: region_com | K810: elc_wof_084 | L810: elc_wof_084
J811: region_com | K811: elc_wof_085 | L811: elc_wof_085
J812: region_com | K812: elc_wof_086 | L812: elc_wof_086
J813: region_com | K813: elc_wof_087 | L813: elc_wof_087
J814: region_com | K814: elc_wof_088 | L814: elc_wof_088
J815: region_com | K815: elc_wof_089 | L815: elc_wof_089
J816: region_com | K816: elc_wof_090 | L816: elc_wof_090
J817: region_com | K817: elc_wof_091 | L817: elc_wof_091
... J833: region_com | K833: elc_wof_107 | L833: elc_wof_107

Sheet TS_Defs
A1: ~TS_Defs
A2: Attribute | B2: WAttribute | C2: PSET_Set | D2: PSET_PN | E2: PSET_PD | F2: PSET_CI | G2: PSET_CO | H2: CSET_Set | I2: CSET_CN | J2: CSET_CD | K2: Unit | L2: TS | M2: UC_N | N2: Name | O2: Desc | P2: Ldesc | Q2: show_me | R2: discard
A3: VAR_CAP | C3: ELE,STG,IRE | D3: -ElcAgg*,-*EV*,-g[_]* | K3: GW | N3: Elec Capacity
A4: VAR_NCAP | C4: ELE,STG,IRE | D4: -ElcAgg*,-*EV*,-g[_]* | K4: GW | N4: Elec New Capacity | T4: group_by
A5: VAR_FOUT | C5: ELE,IRE | D5: -ElcAgg*,-*EV*,-g[_]* | I5: ELC,ELC_???[_]???*,e[_]* | K5: TWh | N5: Elec Production | T5: p | U5: process
A6: VAR_POUT | C6: ELE,STG,IRE,-Grid | H6: NRG | I6: -elc_roadtransport | K6: TWh2GW | N6: Power | Q6: t
A7: VAR_FOUT | I7: CO2 | K7: kt | N7: CO2_emission
A8: VAR_FOUT | I8: CO2Captured | K8: ktneg | N8: CO2_captured
A9: Cost_Inv | C9: ELE,STG,IRE | D9: -ElcAgg*,-*EV* | K9: m$2020 | N9: Cost_Investment
A10: Cost_Dec | C10: ELE,STG,IRE | D10: -ElcAgg*,-*EV* | K10: m$2020 | N10: Cost_Investment
A11: Cost_Act | C11: ELE,STG,IRE | D11: -ElcAgg*,-*EV* | K11: m$2020 | N11: Cost_Variable
A12: Cost_Flo | C12: ELE,STG,IRE | D12: -ElcAgg*,-*EV* | K12: m$2020 | N12: Cost_Variable
A13: Cost_Fom | C13: ELE,STG,IRE | D13: -ElcAgg*,-*EV* | K13: m$2020 | N13: Cost_Fixed
A14: Val_Flo | C14: ELE | I14: coal,gas,oil,bioenergy | K14: m$2020 | N14: Cost_Fuel
A15: EQ_COMBALM | B15: VAR_COMPRD | H15: NRG | K15: $/MWh | N15: Price_NRG | P15: Prices of all NRG - native TS | Q15: ct
A16: EQ_COMBALM | B16: VAR_COMPRD | I16: co2net | K16: 000$/t | N16: Price_CO2
A17: User_conFXM | K17: m$/UCU | N17: UC_shadowprice | P17: shadow prices of all Ucs | Q17: u
A18: VAR_NCAPR | B18: VAR_NCAP | K18: $/MWh | N18: LCOE | Q18: p
A19: Reg_wobj | K19: m$2020 | N19: SysCost_NPV | Q19: u
A20: Reg_ACost | K20: m$2020 | N20: SysCost_Annual | Q20: u
A21: VAR_CAP | C21: IRE | D21: g[_]* | K21: GW | N21: Grid Capacity
A22: VAR_NCAP | C22: IRE | D22: g[_]* | K22: GW | N22: Grid New Capacity
A23: VAR_FIN | D23: e_dem*,ev_bat*,H2Prd* | I23: e* | K23: TWh | N23: Demand
A24: VAR_FIN | I24: ELC_???[_]???*,e[_]* | K24: TWh | N24: ~tradeflow_exp | P24: internal variable to enable grid flows visualization | Q24: p,c
A25: VAR_FOUT | I25: ELC_???[_]???*,e[_]* | K25: TWh | N25: ~tradeflow_imp | P25: internal variable to enable grid flows visualization | Q25: p,c
A26: VAR_CAP | F26: e[_]* | G26: e[_]* | K26: GW | N26: ~tradeflow_cap | P26: internal variable to enable grid capacity visualization | Q26: p
A27: VAR_NCAP | F27: e[_]* | G27: e[_]* | K27: GW | N27: ~tradeflow_ncap | P27: internal variable to enable grid new capacity visualization | Q27: p

Sheet TS_ratios
C1: ~TS_Ratios
C2: var_num | D2: var_den | E2: Name | F2: Unit | G2: show_me | H2: ignore | I2: include_null | J2: include_dim | K2: Ldesc
C3: Elec Production | D3: Elec Capacity | E3: Capacity_factor | F3: Twh/GW | G3: p | I3: y | J3: p

Sheet Sankey
A3: DeACT TS_Defs: Snk_attr=SANKEY Grid Flows
A4: Attribute | B4: PSET_Set | C4: PSET_PN | D4: PSET_PD | E4: PSET_CI | F4: PSET_CO | G4: CSET_Set | H4: CSET_CN | I4: CSET_CD | J4: Unit | K4: TS | L4: UC_N | M4: Name | N4: Desc | O4: Ldesc | P4: show_me | Q4: ignore | R4: T_neg_andor | S4: downscale_option
A5: VAR_FOUT | B5: =_xlfn.TEXTJOIN(",",TRUE,PSet_MAP!$A$3:$A$49) -> CCGT,Int Comb,Gas_Oil Steam,OCGT (Peaker),Subcritical Coal,Supercritical Coal,IGCC,Bio Power,Solar Util,Wind onshore,Wind offshore,Geothermal P,Hydro Dam,Hydro RoR,Nuclear P,Nuclear SMR,Hydro pumped stg,Util Batt Stg,EV Batt,Demand,Transformers Dn,Transformers Up,Grid-220V,Grid-400V,Grid-380V,Grid-225V,Grid-330V,Grid-275V,Grid-420V,Grid-300V,Grid-500V,Grid-750V,Grid-450V,Grid-515V,Grid-525V,Grid-320V,Grid-150V,Grid-270V,Grid-350V,Grid-250V,Grid-200V,Grid-236V,Grid-600V,Aggregators,DUMMY_IMP | G5: =_xlfn.TEXTJOIN(",",TRUE,CSET_MAP!$A$3:$A$43) -> Elec-220V,Elec-400V,Elec-380V,Elec-225V,Elec-330V,Elec-275V,Elec-420V,Elec-300V,Elec-500V,Elec-750V,Elec-450V,Elec-515V,Elec-525V,Elec-320V,Elec-150V,Elec-270V,Elec-350V,Elec-250V,Elec-200V,Elec-236V,Elec-600V,Solar elec,Wind elec,hydrogen,ELC,buildings,industry,transport,EVs,fossil,renewable,bioenergy,nuclear | J5: TWh | M5: <cset>_Src_<pset> | S5: -1
A6: VAR_FIN | B6: =_xlfn.TEXTJOIN(",",TRUE,PSet_MAP!$A$3:$A$49) -> CCGT,Int Comb,Gas_Oil Steam,OCGT (Peaker),Subcritical Coal,Supercritical Coal,IGCC,Bio Power,Solar Util,Wind onshore,Wind offshore,Geothermal P,Hydro Dam,Hydro RoR,Nuclear P,Nuclear SMR,Hydro pumped stg,Util Batt Stg,EV Batt,Demand,Transformers Dn,Transformers Up,Grid-220V,Grid-400V,Grid-380V,Grid-225V,Grid-330V,Grid-275V,Grid-420V,Grid-300V,Grid-500V,Grid-750V,Grid-450V,Grid-515V,Grid-525V,Grid-320V,Grid-150V,Grid-270V,Grid-350V,Grid-250V,Grid-200V,Grid-236V,Grid-600V,Aggregators,DUMMY_IMP | G6: =_xlfn.TEXTJOIN(",",TRUE,CSET_MAP!$A$3:$A$43) -> Elec-220V,Elec-400V,Elec-380V,Elec-225V,Elec-330V,Elec-275V,Elec-420V,Elec-300V,Elec-500V,Elec-750V,Elec-450V,Elec-515V,Elec-525V,Elec-320V,Elec-150V,Elec-270V,Elec-350V,Elec-250V,Elec-200V,Elec-236V,Elec-600V,Solar elec,Wind elec,hydrogen,ELC,buildings,industry,transport,EVs,fossil,renewable,bioenergy,nuclear | J6: TWh | M6: <cset>_Snk_<pset> | S6: -1
A10: ~TS_Defs: Snk_attr=SANKEY whole system
A11: Attribute | B11: PSET_Set | C11: PSET_PN | D11: PSET_PD | E11: PSET_CI | F11: PSET_CO | G11: CSET_Set | H11: CSET_CN | I11: CSET_CD | J11: Unit | K11: TS | L11: UC_N | M11: Name | N11: Desc | O11: Ldesc | P11: show_me | Q11: ignore | R11: T_neg_andor | S11: downscale_option
A12: * | B12: Fuels
A13: VAR_FOUT | F13: =H13 -> bioenergy,coal,gas,geothermal,hydro,hydrogen,nuclear,oil,solar,windon,windoff | H13: =_xlfn.TEXTJOIN(",",TRUE,CName_MAP!$A$3:$A$16) -> bioenergy,coal,gas,geothermal,hydro,hydrogen,nuclear,oil,solar,windon,windoff | J13: TWh | M13: <gen_cname>_src_<gen_pname> | S13: -1
A14: VAR_FIN | B14: =B5 -> CCGT,Int Comb,Gas_Oil Steam,OCGT (Peaker),Subcritical Coal,Supercritical Coal,IGCC,Bio Power,Solar Util,Wind onshore,Wind offshore,Geothermal P,Hydro Dam,Hydro RoR,Nuclear P,Nuclear SMR,Hydro pumped stg,Util Batt Stg,EV Batt,Demand,Transformers Dn,Transformers Up,Grid-220V,Grid-400V,Grid-380V,Grid-225V,Grid-330V,Grid-275V,Grid-420V,Grid-300V,Grid-500V,Grid-750V,Grid-450V,Grid-515V,Grid-525V,Grid-320V,Grid-150V,Grid-270V,Grid-350V,Grid-250V,Grid-200V,Grid-236V,Grid-600V,Aggregators,DUMMY_IMP | H14: =_xlfn.TEXTJOIN(",",TRUE,CName_MAP!$A$3:$A$16) -> bioenergy,coal,gas,geothermal,hydro,hydrogen,nuclear,oil,solar,windon,windoff | J14: TWh | M14: <gen_cname>_snk_<pset> | S14: -1
A15: * | B15: Electricity
A16: VAR_FOUT | B16: =_xlfn.TEXTJOIN(",",TRUE,PSet_MAP!$A$3:$A$49) -> CCGT,Int Comb,Gas_Oil Steam,OCGT (Peaker),Subcritical Coal,Supercritical Coal,IGCC,Bio Power,Solar Util,Wind onshore,Wind offshore,Geothermal P,Hydro Dam,Hydro RoR,Nuclear P,Nuclear SMR,Hydro pumped stg,Util Batt Stg,EV Batt,Demand,Transformers Dn,Transformers Up,Grid-220V,Grid-400V,Grid-380V,Grid-225V,Grid-330V,Grid-275V,Grid-420V,Grid-300V,Grid-500V,Grid-750V,Grid-450V,Grid-515V,Grid-525V,Grid-320V,Grid-150V,Grid-270V,Grid-350V,Grid-250V,Grid-200V,Grid-236V,Grid-600V,Aggregators,DUMMY_IMP | G16: =_xlfn.TEXTJOIN(",",TRUE,CSET_MAP!$A$3:$A$31) -> Elec-220V,Elec-400V,Elec-380V,Elec-225V,Elec-330V,Elec-275V,Elec-420V,Elec-300V,Elec-500V,Elec-750V,Elec-450V,Elec-515V,Elec-525V,Elec-320V,Elec-150V,Elec-270V,Elec-350V,Elec-250V,Elec-200V,Elec-236V,Elec-600V,Solar elec,Wind elec,hydrogen,ELC,buildings,industry,transport,EVs | J16: TWh | M16: <cset>_src_<pset> | S16: -1
A17: VAR_FIN | B17: =_xlfn.TEXTJOIN(",",TRUE,PSet_MAP!$A$3:$A$49) -> CCGT,Int Comb,Gas_Oil Steam,OCGT (Peaker),Subcritical Coal,Supercritical Coal,IGCC,Bio Power,Solar Util,Wind onshore,Wind offshore,Geothermal P,Hydro Dam,Hydro RoR,Nuclear P,Nuclear SMR,Hydro pumped stg,Util Batt Stg,EV Batt,Demand,Transformers Dn,Transformers Up,Grid-220V,Grid-400V,Grid-380V,Grid-225V,Grid-330V,Grid-275V,Grid-420V,Grid-300V,Grid-500V,Grid-750V,Grid-450V,Grid-515V,Grid-525V,Grid-320V,Grid-150V,Grid-270V,Grid-350V,Grid-250V,Grid-200V,Grid-236V,Grid-600V,Aggregators,DUMMY_IMP | G17: =_xlfn.TEXTJOIN(",",TRUE,CSET_MAP!$A$3:$A$31) -> Elec-220V,Elec-400V,Elec-380V,Elec-225V,Elec-330V,Elec-275V,Elec-420V,Elec-300V,Elec-500V,Elec-750V,Elec-450V,Elec-515V,Elec-525V,Elec-320V,Elec-150V,Elec-270V,Elec-350V,Elec-250V,Elec-200V,Elec-236V,Elec-600V,Solar elec,Wind elec,hydrogen,ELC,buildings,industry,transport,EVs | J17: TWh | M17: <cset>_snk_<pset> | S17: -1
A18: * | B18: Hydrogen
A19: VAR_FOUT | F19: =H19 -> hydrogen | H19: hydrogen | J19: TWh | M19: <gen_cname>_src_<gen_pname> | S19: -1
A20: VAR_FIN | F20: hydrogen | G20: =_xlfn.TEXTJOIN(",",TRUE,CSET_MAP!$A$3:$A$43) -> Elec-220V,Elec-400V,Elec-380V,Elec-225V,Elec-330V,Elec-275V,Elec-420V,Elec-300V,Elec-500V,Elec-750V,Elec-450V,Elec-515V,Elec-525V,Elec-320V,Elec-150V,Elec-270V,Elec-350V,Elec-250V,Elec-200V,Elec-236V,Elec-600V,Solar elec,Wind elec,hydrogen,ELC,buildings,industry,transport,EVs,fossil,renewable,bioenergy,nuclear | J20: TWh | M20: <cset>_snk_<gen_pname> | S20: -1
A23: VAR_FIN | E23: hydrogen | H23: hydrogen | J23: TWh | M23: <gen_cname>_snk_<gen_pname> | S23: -1

Sheet PSet_MAP
A1: ~Pset_Map
A2: Pset | B2: Desc | C2: Ldesc
A3: CCGT | B3: =A3 -> CCGT
A4: Int Comb | B4: =A4 -> Int Comb
A5: Gas_Oil Steam | B5: =A5 -> Gas_Oil Steam
A6: OCGT (Peaker) | B6: =A6 -> OCGT (Peaker)
A7: Subcritical Coal | B7: =A7 -> Subcritical Coal
A8: Supercritical Coal | B8: =A8 -> Supercritical Coal
A9: IGCC | B9: =A9 -> IGCC
A10: Bio Power | B10: =A10 -> Bio Power
A11: Solar Util | B11: =A11 -> Solar Util
A12: Wind onshore | B12: Onshore Wind
A13: Wind offshore | B13: Offshore Wind
A14: Geothermal P | B14: =A14 -> Geothermal P
A15: Hydro Dam | B15: =A15 -> Hydro Dam
A16: Hydro RoR | B16: =A16 -> Hydro RoR
A17: Nuclear P | B17: =A17 -> Nuclear P
A18: Nuclear SMR | B18: =A18 -> Nuclear SMR
A19: Hydro pumped stg | B19: =A19 -> Hydro pumped stg
A20: Util Batt Stg | B20: =A20 -> Util Batt Stg
A21: EV Batt | B21: =A21 -> EV Batt
A22: Demand | B22: =A22 -> Demand
A23: Transformers Dn | B23: =A23 -> Transformers Dn
A24: Transformers Up | B24: =A24 -> Transformers Up
A25: Grid-220V | B25: =A25 -> Grid-220V
... A47: DUMMY_IMP | B47: =A47 -> DUMMY_IMP

Sheet CSET_MAP
A1: ~Cset_Map
A2: Cset | B2: Desc | C2: Ldesc
A3: Elec-220V | B3: =A3 -> Elec-220V
A4: Elec-400V | B4: =A4 -> Elec-400V
A5: Elec-380V | B5: =A5 -> Elec-380V
A6: Elec-225V | B6: =A6 -> Elec-225V
A7: Elec-330V | B7: =A7 -> Elec-330V
A8: Elec-275V | B8: =A8 -> Elec-275V
A9: Elec-420V | B9: =A9 -> Elec-420V
A10: Elec-300V | B10: =A10 -> Elec-300V
A11: Elec-500V | B11: =A11 -> Elec-500V
A12: Elec-750V | B12: =A12 -> Elec-750V
A13: Elec-450V | B13: =A13 -> Elec-450V
A14: Elec-515V | B14: =A14 -> Elec-515V
... A23: Elec-600V | B23: =A23 -> Elec-600V
A24: Solar elec | B24: Electricity
A25: Wind elec | B25: Electricity
A26: hydrogen | B26: =A26 -> hydrogen
A27: ELC | B27: Electricity
A28: buildings | B28: =A28 -> buildings
A29: industry | B29: =A29 -> industry
A30: transport | B30: =A30 -> transport
A31: EVs | B31: =A31 -> EVs
A32: fossil | B32: =A32 -> fossil
A33: renewable | B33: =A33 -> renewable
A34: bioenergy | B34: =A34 -> bioenergy
A35: nuclear | B35: =A35 -> nuclear

Sheet CName_MAP
A1: ~CName_Map
A2: CName | B2: Desc | C2: Ldesc
A3: bioenergy | B3: =A3 -> bioenergy
A4: coal | B4: =A4 -> coal
A5: gas | B5: =A5 -> gas
A6: geothermal | B6: =A6 -> geothermal
A7: hydro | B7: =A7 -> hydro
A8: hydrogen | B8: =A8 -> hydrogen
A9: nuclear | B9: =A9 -> nuclear
A10: oil | B10: =A10 -> oil
A11: solar | B11: =A11 -> solar
A12: windon | B12: wind onshore
A13: windoff | B13: wind offshore

Sheet timeslice map
A1: ~Timeslice_Map
A2: dimension | B2: name | C2: description
A3: ts_type | B3: *,-s?a* | C3: hourly
A4: ts_type | B4: s?a* | C4: aggregated
A5: ts_season | B5: S1* | C5: =LEFT(B5,2) -> S1
A6: ts_season | B6: S2* | C6: =LEFT(B6,2) -> S2
A7: ts_season | B7: S3* | C7: =LEFT(B7,2) -> S3
A8: ts_season | B8: S4* | C8: =LEFT(B8,2) -> S4
A9: ts_season | B9: S5* | C9: =LEFT(B9,2) -> S5
A10: ts_season | B10: S6* | C10: =LEFT(B10,2) -> S6

Sheet process map
A1: ~process_map
A2: dimension | B2: name | C2: description | D2: pset_set | E2: pset_ci | F2: pset_co | G2: pset_pd
A3: old_new | B3: * | C3: new
A4: old_new | B4: ep* | C4: old
A5: Tech | C5: =D5 -> CCGT | D5: CCGT
A6: Tech | C6: =D6 -> Int Comb | D6: Int Comb
A7: Tech | C7: =D7 -> Gas_Oil Steam | D7: Gas_Oil Steam
A8: Tech | C8: =D8 -> OCGT (Peaker) | D8: OCGT (Peaker)
A9: Tech | C9: =D9 -> Subcritical Coal | D9: Subcritical Coal
A10: Tech | C10: =D10 -> Supercritical Coal | D10: Supercritical Coal
A11: Tech | C11: =D11 -> IGCC | D11: IGCC
A12: Tech | C12: =D12 -> Bio Power | D12: Bio Power
A13: Tech | C13: =D13 -> Solar Util | D13: Solar Util
A14: Tech | C14: =D14 -> Wind onshore | D14: Wind onshore
A15: Tech | C15: =D15 -> Wind offshore | D15: Wind offshore
A16: Tech | C16: =D16 -> Geothermal P | D16: Geothermal P
... A49: Tech | C49: =D49 -> DUMMY_IMP | D49: DUMMY_IMP
A50: Tech | B50: *ccs | C50: Coal CCS | E50: coal
A51: Tech | B51: *ccs | C51: Gas CCS | E51: gas
A52: Tech | B52: *ccs-rf | C52: Coal CCS Retrofit | E52: coal
A53: Tech | B53: *ccs-rf | C53: Gas CCS Retrofit | E53: gas
A54: Tech | B54: ElcAgg_Solar | C54: Solar
A55: Tech | B55: ElcAgg_Wind | C55: Wind
A56: Tech | B56: Trd* | C56: Trade
A57: Sector | B57: e_dem* | C57: Industry and Buildings
A58: Sector | B58: ev_bat* | C58: EV Batt
A59: Sector | B59: H2Prd* | C59: Hydrogen
A60: Tech_origin | B60: * | C60: VerveStacks
A61: Tech_origin | B61: ep_* | C61: GEM_operating
A62: Tech_origin | B62: en_pc_* | C62: GEM_pre-constr
A63: Tech_origin | B63: ep_m_* | C63: GEM_mothballed
A64: Tech_origin | B64: en_a_* | C64: GEM_announced
A65: Tech_origin | B65: en_can_* | C65: GEM_cancelled
A66: Tech_origin | B66: en_she_* | C66: GEM_shelved
A67: Tech_by_fuel | C67: =E67 -> bioenergy | E67: bioenergy
A68: Tech_by_fuel | C68: =E68 -> coal | E68: coal
A69: Tech_by_fuel | C69: =E69 -> gas | E69: gas
A70: Tech_by_fuel | C70: =E70 -> hydro | E70: hydro
A71: Tech_by_fuel | C71: =E71 -> nuclear | E71: nuclear
A72: Tech_by_fuel | C72: =E72 -> oil | E72: oil
...

Sheet commodity map
A1: ~commodity_map
A2: dimension | B2: name | C2: description | D2: cset_set | E2: cset_cd | F2: c_set_andor | G2: c_pos_andor | H2: c_neg_andor

Sheet ATS
A1: ~ATS_final
A2: Tech_by_fuel | B2: Year | C2: Unit | D2: val | E2: scen | F2: varbl | G2: model | H2: region
A3: bioenergy | B3: 2000 | C3: TWh | D3: 8.92 | E3: History | F3: Elec Production | G3: EMBER | H3: CAN
A4: coal | B4: 2000 | C4: TWh | D4: 116.23 | E4: History | F4: Elec Production | G4: EMBER | H4: CAN
A5: gas | B5: 2000 | C5: TWh | D5: 35.83 | E5: History | F5: Elec Production | G5: EMBER | H5: CAN
A6: hydro | B6: 2000 | C6: TWh | D6: 356.76 | E6: History | F6: Elec Production | G6: EMBER | H6: CAN
A7: nuclear | B7: 2000 | C7: TWh | D7: 72.29 | E7: History | F7: Elec Production | G7: EMBER | H7: CAN
A8: oil | B8: 2000 | C8: TWh | D8: 13.51 | E8: History | F8: Elec Production | G8: EMBER | H8: CAN
A9: bioenergy | B9: 2001 | C9: TWh | D9: 9.67 | E9: History | F9: Elec Production | G9: EMBER | H9: CAN
A10: coal | B10: 2001 | C10: TWh | D10: 111.69 | E10: History | F10: Elec Production | G10: EMBER | H10: CAN
A11: gas | B11: 2001 | C11: TWh | D11: 42.29 | E11: History | F11: Elec Production | G11: EMBER | H11: CAN
A12: hydro | B12: 2001 | C12: TWh | D12: 331.52 | E12: History | F12: Elec Production | G12: EMBER | H12: CAN
A13: nuclear | B13: 2001 | C13: TWh | D13: 76.16 | E13: History | F13: Elec Production | G13: EMBER | H13: CAN
A14: oil | B14: 2001 | C14: TWh | D14: 16.08 | E14: History | F14: Elec Production | G14: EMBER | H14: CAN
... A617: Import | B617: 2023 | C617: TWh | D617: 21.7 | E617: History | F617: Elec Production | G617: EMBER | H617: CAN

Sheet UnitConv
A1: ~UnitConv
A2: Model | B2: Unit1 | C2: Unit2 | D2: MultFact
A3: VS | B3: Twh2GW | C3: GW | D3: =1/8.76 -> 0.11415525
A4: VS | B4: Twh/GW | C4: % | D4: =1/8.76*100 -> 11.415525
A5: VS | B5: kt | C5: mtCO2 | D5: 0.001
A6: VS | B6: ktneg | C6: mtCO2 | D6: -0.001
A7: VS | B7: 000$/t | C7: $/tCO2 | D7: -1000
