Workbook

Sheet Veda
G1: 1-25,36-40 | H1: 8 | I1: 13 | J1: 18 | K1: 23 | L1: 28 | M1: 33 | N1: 38
D2: ="~Inputcell: "&_xlfn.TEXTJOIN(",",TRUE,G1:EE1) -> ~Inputcell: 1-25,36-40,8,13,18,23,28,33,38
D3: 3
D5: =VLOOKUP(D3,$C$9:$E$999,2,FALSE) -> ts_annual | E5: =VLOOKUP(D3,$C$9:$E$999,3,FALSE) -> C3
B7: ~Scenmap
A8: priority | B8: scen | C8: case_no | D8: timeslice | E8: climate | AM8: bio price multiplier
A9: 5 | B9: =VLOOKUP(E9,$AK$9:$AL$15,2,FALSE)&"."&VLOOKUP(D9,$AH$9:$AI$24,2,FALSE) -> e 1.5 deg no OS.xAnn | C9: 1 | D9: =VLOOKUP(AJ9,$AG$9:$AH$22,2,FALSE) -> ts_annual | E9: C1 | G9: Limit warming to 1.5°C (>50%) with no or limited overshoot | AG9: 1 | AH9: ts_annual | AI9: xAnn | AJ9: 1 | AK9: C1 | AL9: e 1.5 deg no OS | AM9: 5
A10: 5 | B10: =VLOOKUP(E10,$AK$9:$AL$15,2,FALSE)&"."&VLOOKUP(D10,$AH$9:$AI$24,2,FALSE) -> d 1.5 deg OS.xAnn | C10: =C9+1 -> 2 | D10: =VLOOKUP(AJ10,$AG$9:$AH$22,2,FALSE) -> ts_annual | E10: C2 | G10: Limit warming to 1.5°C (>67%) with high overshoot | S10: IEA | AG10: 2 | AH10: ts_12t | AI10: x12 | AJ10: 1 | AK10: C2 | AL10: d 1.5 deg OS | AM10: 4
A11: 5 | B11: =VLOOKUP(E11,$AK$9:$AL$15,2,FALSE)&"."&VLOOKUP(D11,$AH$9:$AI$24,2,FALSE) -> c 2 deg (67%).xAnn | C11: =C10+1 -> 3 | D11: =VLOOKUP(AJ11,$AG$9:$AH$22,2,FALSE) -> ts_annual | E11: C3 | G11: Limit warming to 2°C (>67%) with higher action post-2030 | S11: 2022 | AG11: 3 | AH11: ts_012 | AI11: =AH11 -> ts_012 | AJ11: 1 | AK11: C3 | AL11: c 2 deg (67%) | AM11: 3
A12: 5 | B12: =VLOOKUP(E12,$AK$9:$AL$15,2,FALSE)&"."&VLOOKUP(D12,$AH$9:$AI$24,2,FALSE) -> b 2 deg (50%).xAnn | C12: =C11+1 -> 4 | D12: =VLOOKUP(AJ12,$AG$9:$AH$22,2,FALSE) -> ts_annual | E12: C4 | G12: Limit warming to 2°C (>50%) with immediate action | S12: =SUMIFS(iea_data!I3:I9999,iea_data!$B$3:$B$9999,Veda!$S$11)+T28-T29 -> 229.26 | T12: base-year generation (TWh) | AG12: 4 | AH12: ts_030 | AI12: =AH12 -> ts_030 | AJ12: 1 | AK12: C4 | AL12: b 2 deg (50%) | AM12: 3
A13: 5 | B13: =VLOOKUP(E13,$AK$9:$AL$15,2,FALSE)&"."&VLOOKUP(D13,$AH$9:$AI$24,2,FALSE) -> a 3 deg.xAnn | C13: =C12+1 -> 5 | D13: =VLOOKUP(AJ13,$AG$9:$AH$22,2,FALSE) -> ts_annual | E13: C7 | G13: Likely above 3°C warming with limited mitigation | AG13: 5 | AH13: ts_048 | AI13: =AH13 -> ts_048 | AJ13: 1 | AK13: C7 | AL13: a 3 deg | AM13: 1.5
A14: 5 | B14: =VLOOKUP(E14,$AK$9:$AL$15,2,FALSE)&"."&VLOOKUP(D14,$AH$9:$AI$24,2,FALSE) -> e 1.5 deg no OS.x12 | C14: =C13+1 -> 6 | D14: =VLOOKUP(AJ14,$AG$9:$AH$22,2,FALSE) -> ts_12t | E14: =E9 -> C1 | T14: =S12 -> 229.26 | U14: =$S$12*J15 -> 291.1602 | V14: =$S$12*K15 -> 385.1568 | W14: =$S$12*L15 -> 518.1276 | X14: =$S$12*M15 -> 669.4392 | Y14: =$S$12*N15 -> 1027.0848 | Z14: =$S$12*O15 -> 1377.8526 | AG14: 6 | AH14: ts_072 | AI14: =AH14 -> ts_072 | AJ14: =AJ9+1 -> 2
A15: 5 | B15: =VLOOKUP(E15,$AK$9:$AL$15,2,FALSE)&"."&VLOOKUP(D15,$AH$9:$AI$24,2,FALSE) -> d 1.5 deg OS.x12 | C15: =C14+1 -> 7 | D15: =VLOOKUP(AJ15,$AG$9:$AH$22,2,FALSE) -> ts_12t | E15: =E10 -> C2 | G15: Electricity growth relative to 2020 | I15: =SUMIFS(ar6_r10!$F$2:$F$999,ar6_r10!$A$2:$A$999,Veda!$E$5,ar6_r10!$C$2:$C$999,Veda!I$17,ar6_r10!$M$2:$M$999,Veda!$G15) -> 1 | J15: =SUMIFS(ar6_r10!$F$2:$F$999,ar6_r10!$A$2:$A$999,Veda!$E$5,ar6_r10!$C$2:$C$999,Veda!J$17,ar6_r10!$M$2:$M$999,Veda!$G15) -> 1.27 | K15: =SUMIFS(ar6_r10!$F$2:$F$999,ar6_r10!$A$2:$A$999,Veda!$E$5,ar6_r10!$C$2:$C$999,Veda!K$17,ar6_r10!$M$2:$M$999,Veda!$G15) -> 1.68 | L15: =SUMIFS(ar6_r10!$F$2:$F$999,ar6_r10!$A$2:$A$999,Veda!$E$5,ar6_r10!$C$2:$C$999,Veda!L$17,ar6_r10!$M$2:$M$999,Veda!$G15) -> 2.26 | M15: =SUMIFS(ar6_r10!$F$2:$F$999,ar6_r10!$A$2:$A$999,Veda!$E$5,ar6_r10!$C$2:$C$999,Veda!M$17,ar6_r10!$M$2:$M$999,Veda!$G15) -> 2.92 | N15: =SUMIFS(ar6_r10!$F$2:$F$999,ar6_r10!$A$2:$A$999,Veda!$E$5,ar6_r10!$C$2:$C$999,Veda!N$17,ar6_r10!$M$2:$M$999,Veda!$G15) -> 4.48 | O15: =SUMIFS(ar6_r10!$F$2:$F$999,ar6_r10!$A$2:$A$999,Veda!$E$5,ar6_r10!$C$2:$C$999,Veda!O$17,ar6_r10!$M$2:$M$999,Veda!$G15) -> 6.01 | AG15: 7 | AH15: ts_144 | AI15: =AH15 -> ts_144 | AJ15: =AJ10+1 -> 2
A16: 5 | B16: =VLOOKUP(E16,$AK$9:$AL$15,2,FALSE)&"."&VLOOKUP(D16,$AH$9:$AI$24,2,FALSE) -> c 2 deg (67%).x12 | C16: =C15+1 -> 8 | D16: =VLOOKUP(AJ16,$AG$9:$AH$22,2,FALSE) -> ts_12t | E16: =E11 -> C3 | S16: ~TFM_INS-TS | AG16: 8 | AH16: ts_288 | AI16: =AH16 -> ts_288 | AJ16: =AJ11+1 -> 2
A17: 5 | B17: =VLOOKUP(E17,$AK$9:$AL$15,2,FALSE)&"."&VLOOKUP(D17,$AH$9:$AI$24,2,FALSE) -> b 2 deg (50%).x12 | C17: =C16+1 -> 9 | D17: =VLOOKUP(AJ17,$AG$9:$AH$22,2,FALSE) -> ts_12t | E17: =E12 -> C4 | I17: 2020 | J17: =U17 -> 2025 | K17: =V17 -> 2030 | L17: =W17 -> 2035 | M17: =X17 -> 2040 | N17: =Y17 -> 2045 | O17: =Z17 -> 2050 | S17: commodity | T17: 2022 | U17: 2025 | V17: 2030 | W17: 2035 | X17: 2040 | Y17: 2045 | Z17: 2050 | AA17: attribute | AG17: 9 | AH17: s1v1_d | AI17: f2d96 | AJ17: =AJ12+1 -> 2
A18: 5 | B18: =VLOOKUP(E18,$AK$9:$AL$15,2,FALSE)&"."&VLOOKUP(D18,$AH$9:$AI$24,2,FALSE) -> a 3 deg.x12 | C18: =C17+1 -> 10 | D18: =VLOOKUP(AJ18,$AG$9:$AH$22,2,FALSE) -> ts_12t | E18: =E13 -> C7 | G18: Hydrogen as a share of electricity | I18: =SUMIFS(ar6_r10!$F$2:$F$999,ar6_r10!$A$2:$A$999,Veda!$E$5,ar6_r10!$C$2:$C$999,Veda!I$17,ar6_r10!$M$2:$M$999,Veda!$G18) -> 0 | J18: =SUMIFS(ar6_r10!$F$2:$F$999,ar6_r10!$A$2:$A$999,Veda!$E$5,ar6_r10!$C$2:$C$999,Veda!J$17,ar6_r10!$M$2:$M$999,Veda!$G18) -> 0 | K18: =SUMIFS(ar6_r10!$F$2:$F$999,ar6_r10!$A$2:$A$999,Veda!$E$5,ar6_r10!$C$2:$C$999,Veda!K$17,ar6_r10!$M$2:$M$999,Veda!$G18) -> 0 | L18: =SUMIFS(ar6_r10!$F$2:$F$999,ar6_r10!$A$2:$A$999,Veda!$E$5,ar6_r10!$C$2:$C$999,Veda!L$17,ar6_r10!$M$2:$M$999,Veda!$G18) -> 0.01 | M18: =SUMIFS(ar6_r10!$F$2:$F$999,ar6_r10!$A$2:$A$999,Veda!$E$5,ar6_r10!$C$2:$C$999,Veda!M$17,ar6_r10!$M$2:$M$999,Veda!$G18) -> 0.02 | N18: =SUMIFS(ar6_r10!$F$2:$F$999,ar6_r10!$A$2:$A$999,Veda!$E$5,ar6_r10!$C$2:$C$999,Veda!N$17,ar6_r10!$M$2:$M$999,Veda!$G18) -> 0.02 | O18: =SUMIFS(ar6_r10!$F$2:$F$999,ar6_r10!$A$2:$A$999,Veda!$E$5,ar6_r10!$C$2:$C$999,Veda!O$17,ar6_r10!$M$2:$M$999,Veda!$G18) -> 0.03 | S18: hydrogen_allsect | T18: =I18*T$14 -> 0 | U18: =J18*U$14 -> 0 | V18: =K18*V$14 -> 0 | W18: =L18*W$14 -> 5.181276 | X18: =M18*X$14 -> 13.388784 | Y18: =N18*Y$14 -> 20.541696 | Z18: =O18*Z$14 -> 41.335578 | AA18: demand | AG18: 10 | AH18: ts_096 | AI18: e96 | AJ18: =AJ13+1 -> 2
A19: 5 | B19: =VLOOKUP(E19,$AK$9:$AL$15,2,FALSE)&"."&VLOOKUP(D19,$AH$9:$AI$24,2,FALSE) -> e 1.5 deg no OS.ts_012 | C19: =C18+1 -> 11 | D19: =VLOOKUP(AJ19,$AG$9:$AH$22,2,FALSE) -> ts_012 | E19: =E14 -> C1 | G19: Industry electricity share | I19: =SUMIFS(ar6_r10!$F$2:$F$999,ar6_r10!$A$2:$A$999,Veda!$E$5,ar6_r10!$C$2:$C$999,Veda!I$17,ar6_r10!$M$2:$M$999,Veda!$G19) -> 0.49 | J19: =SUMIFS(ar6_r10!$F$2:$F$999,ar6_r10!$A$2:$A$999,Veda!$E$5,ar6_r10!$C$2:$C$999,Veda!J$17,ar6_r10!$M$2:$M$999,Veda!$G19) -> 0.45 | K19: =SUMIFS(ar6_r10!$F$2:$F$999,ar6_r10!$A$2:$A$999,Veda!$E$5,ar6_r10!$C$2:$C$999,Veda!K$17,ar6_r10!$M$2:$M$999,Veda!$G19) -> 0.43 | L19: =SUMIFS(ar6_r10!$F$2:$F$999,ar6_r10!$A$2:$A$999,Veda!$E$5,ar6_r10!$C$2:$C$999,Veda!L$17,ar6_r10!$M$2:$M$999,Veda!$G19) -> 0.42 | M19: =SUMIFS(ar6_r10!$F$2:$F$999,ar6_r10!$A$2:$A$999,Veda!$E$5,ar6_r10!$C$2:$C$999,Veda!M$17,ar6_r10!$M$2:$M$999,Veda!$G19) -> 0.4 | N19: =SUMIFS(ar6_r10!$F$2:$F$999,ar6_r10!$A$2:$A$999,Veda!$E$5,ar6_r10!$C$2:$C$999,Veda!N$17,ar6_r10!$M$2:$M$999,Veda!$G19) -> 0.41 | O19: =SUMIFS(ar6_r10!$F$2:$F$999,ar6_r10!$A$2:$A$999,Veda!$E$5,ar6_r10!$C$2:$C$999,Veda!O$17,ar6_r10!$M$2:$M$999,Veda!$G19) -> 0.38 | S19: elc_industry | T19: =I19*T$14 -> 112.3374 | U19: =J19*U$14 -> 131.02209 | V19: =K19*V$14 -> 165.61742 | W19: =L19*W$14 -> 217.61359 | X19: =M19*X$14 -> 267.77568 | Y19: =N19*Y$14 -> 421.10477 | Z19: =O19*Z$14 -> 523.58399 | AA19: demand | AG19: 11 | AH19: s1p1v1_d | AI19: d9d | AJ19: =AJ14+1 -> 3
A20: 5 | B20: =VLOOKUP(E20,$AK$9:$AL$15,2,FALSE)&"."&VLOOKUP(D20,$AH$9:$AI$24,2,FALSE) -> d 1.5 deg OS.ts_012 | C20: =C19+1 -> 12 | D20: =VLOOKUP(AJ20,$AG$9:$AH$22,2,FALSE) -> ts_012 | E20: =E15 -> C2 | G20: Residential and commercial electricity share | I20: =SUMIFS(ar6_r10!$F$2:$F$999,ar6_r10!$A$2:$A$999,Veda!$E$5,ar6_r10!$C$2:$C$999,Veda!I$17,ar6_r10!$M$2:$M$999,Veda!$G20) -> 0.49 | J20: =SUMIFS(ar6_r10!$F$2:$F$999,ar6_r10!$A$2:$A$999,Veda!$E$5,ar6_r10!$C$2:$C$999,Veda!J$17,ar6_r10!$M$2:$M$999,Veda!$G20) -> 0.52 | K20: =SUMIFS(ar6_r10!$F$2:$F$999,ar6_r10!$A$2:$A$999,Veda!$E$5,ar6_r10!$C$2:$C$999,Veda!K$17,ar6_r10!$M$2:$M$999,Veda!$G20) -> 0.54 | L20: =SUMIFS(ar6_r10!$F$2:$F$999,ar6_r10!$A$2:$A$999,Veda!$E$5,ar6_r10!$C$2:$C$999,Veda!L$17,ar6_r10!$M$2:$M$999,Veda!$G20) -> 0.51 | M20: =SUMIFS(ar6_r10!$F$2:$F$999,ar6_r10!$A$2:$A$999,Veda!$E$5,ar6_r10!$C$2:$C$999,Veda!M$17,ar6_r10!$M$2:$M$999,Veda!$G20) -> 0.51 | N20: =SUMIFS(ar6_r10!$F$2:$F$999,ar6_r10!$A$2:$A$999,Veda!$E$5,ar6_r10!$C$2:$C$999,Veda!N$17,ar6_r10!$M$2:$M$999,Veda!$G20) -> 0.48 | O20: =SUMIFS(ar6_r10!$F$2:$F$999,ar6_r10!$A$2:$A$999,Veda!$E$5,ar6_r10!$C$2:$C$999,Veda!O$17,ar6_r10!$M$2:$M$999,Veda!$G20) -> 0.47 | S20: elc_buildings | T20: =I20*T$14 -> 112.3374 | U20: =J20*U$14 -> 151.4033 | V20: =K20*V$14 -> 207.98467 | W20: =L20*W$14 -> 264.24508 | X20: =M20*X$14 -> 341.41399 | Y20: =N20*Y$14 -> 493.0007 | Z20: =O20*Z$14 -> 647.59072 | AA20: demand | AG20: 12 | AH20: s5p5v5_d | AI20: c15d | AJ20: =AJ15+1 -> 3
A21: 5 | B21: =VLOOKUP(E21,$AK$9:$AL$15,2,FALSE)&"."&VLOOKUP(D21,$AH$9:$AI$24,2,FALSE) -> c 2 deg (67%).ts_012 | C21: =C20+1 -> 13 | D21: =VLOOKUP(AJ21,$AG$9:$AH$22,2,FALSE) -> ts_012 | E21: =E16 -> C3 | G21: Transportation electricity share | I21: =SUMIFS(ar6_r10!$F$2:$F$999,ar6_r10!$A$2:$A$999,Veda!$E$5,ar6_r10!$C$2:$C$999,Veda!I$17,ar6_r10!$M$2:$M$999,Veda!$G21) -> 0.01 | J21: =SUMIFS(ar6_r10!$F$2:$F$999,ar6_r10!$A$2:$A$999,Veda!$E$5,ar6_r10!$C$2:$C$999,Veda!J$17,ar6_r10!$M$2:$M$999,Veda!$G21) -> 0.01 | K21: =SUMIFS(ar6_r10!$F$2:$F$999,ar6_r10!$A$2:$A$999,Veda!$E$5,ar6_r10!$C$2:$C$999,Veda!K$17,ar6_r10!$M$2:$M$999,Veda!$G21) -> 0.02 | L21: =SUMIFS(ar6_r10!$F$2:$F$999,ar6_r10!$A$2:$A$999,Veda!$E$5,ar6_r10!$C$2:$C$999,Veda!L$17,ar6_r10!$M$2:$M$999,Veda!$G21) -> 0.02 | M21: =SUMIFS(ar6_r10!$F$2:$F$999,ar6_r10!$A$2:$A$999,Veda!$E$5,ar6_r10!$C$2:$C$999,Veda!M$17,ar6_r10!$M$2:$M$999,Veda!$G21) -> 0.03 | N21: =SUMIFS(ar6_r10!$F$2:$F$999,ar6_r10!$A$2:$A$999,Veda!$E$5,ar6_r10!$C$2:$C$999,Veda!N$17,ar6_r10!$M$2:$M$999,Veda!$G21) -> 0.05 | O21: =SUMIFS(ar6_r10!$F$2:$F$999,ar6_r10!$A$2:$A$999,Veda!$E$5,ar6_r10!$C$2:$C$999,Veda!O$17,ar6_r10!$M$2:$M$999,Veda!$G21) -> 0.05 | S21: elc_transport | T21: =I21*T$14 -> 2.2926 | U21: =T21 -> 2.2926 | V21: =U21 -> 2.2926 | W21: =V21 -> 2.2926 | X21: =W21 -> 2.2926 | Y21: =X21 -> 2.2926 | Z21: =Y21 -> 2.2926 | AA21: demand | AC21: non-road transport demand assumed to be constant | AJ21: =AJ16+1 -> 3
A22: 5 | B22: =VLOOKUP(E22,$AK$9:$AL$15,2,FALSE)&"."&VLOOKUP(D22,$AH$9:$AI$24,2,FALSE) -> b 2 deg (50%).ts_012 | C22: =C21+1 -> 14 | D22: =VLOOKUP(AJ22,$AG$9:$AH$22,2,FALSE) -> ts_012 | E22: =E17 -> C4 | S22: elc_roadtransport | T22: =T14-SUM(T19:T21) -> 2.2926 | U22: =U14-SUM(U19:U21) -> 6.442206 | V22: =V14-SUM(V19:V21) -> 9.262104 | W22: =W14-SUM(W19:W21) -> 33.976332 | X22: =X14-SUM(X19:X21) -> 57.956928 | Y22: =Y14-SUM(Y19:Y21) -> 110.68673 | Z22: =Z14-SUM(Z19:Z21) -> 204.38529 | AA22: demand | AJ22: =AJ17+1 -> 3
A23: 5 | B23: =VLOOKUP(E23,$AK$9:$AL$15,2,FALSE)&"."&VLOOKUP(D23,$AH$9:$AI$24,2,FALSE) -> a 3 deg.ts_012 | C23: =C22+1 -> 15 | D23: =VLOOKUP(AJ23,$AG$9:$AH$22,2,FALSE) -> ts_012 | E23: =E18 -> C7 | S23: * | AJ23: =AJ18+1 -> 3
A24: 5 | B24: =VLOOKUP(E24,$AK$9:$AL$15,2,FALSE)&"."&VLOOKUP(D24,$AH$9:$AI$24,2,FALSE) -> e 1.5 deg no OS.ts_030 | C24: =C23+1 -> 16 | D24: =VLOOKUP(AJ24,$AG$9:$AH$22,2,FALSE) -> ts_030 | E24: =E19 -> C1 | G24: CO2 price | I24: 0 | J24: 0 | K24: =SUMIFS(ar6_r10!$F$2:$F$999,ar6_r10!$A$2:$A$999,Veda!$E$5,ar6_r10!$C$2:$C$999,Veda!K$17,ar6_r10!$M$2:$M$999,Veda!$G24) -> 48.97 | L24: =SUMIFS(ar6_r10!$F$2:$F$999,ar6_r10!$A$2:$A$999,Veda!$E$5,ar6_r10!$C$2:$C$999,Veda!L$17,ar6_r10!$M$2:$M$999,Veda!$G24) -> 87.7 | M24: =SUMIFS(ar6_r10!$F$2:$F$999,ar6_r10!$A$2:$A$999,Veda!$E$5,ar6_r10!$C$2:$C$999,Veda!M$17,ar6_r10!$M$2:$M$999,Veda!$G24) -> 122.55 | N24: =SUMIFS(ar6_r10!$F$2:$F$999,ar6_r10!$A$2:$A$999,Veda!$E$5,ar6_r10!$C$2:$C$999,Veda!N$17,ar6_r10!$M$2:$M$999,Veda!$G24) -> 179.54 | O24: =SUMIFS(ar6_r10!$F$2:$F$999,ar6_r10!$A$2:$A$999,Veda!$E$5,ar6_r10!$C$2:$C$999,Veda!O$17,ar6_r10!$M$2:$M$999,Veda!$G24) -> 211.71 | S24: co2net | U24: 0 | V24: =K24/1000 -> 0.04897 | W24: =L24/1000 -> 0.0877 | X24: =M24/1000 -> 0.12255 | Y24: =N24/1000 -> 0.17954 | Z24: =O24/1000 -> 0.21171 | AA24: com_taxnet | AJ24: =AJ19+1 -> 4
A25: 5 | B25: =VLOOKUP(E25,$AK$9:$AL$15,2,FALSE)&"."&VLOOKUP(D25,$AH$9:$AI$24,2,FALSE) -> d 1.5 deg OS.ts_030 | C25: =C24+1 -> 17 | D25: =VLOOKUP(AJ25,$AG$9:$AH$22,2,FALSE) -> ts_030 | E25: =E20 -> C2 | AJ25: =AJ20+1 -> 4
A26: 5 | B26: =VLOOKUP(E26,$AK$9:$AL$15,2,FALSE)&"."&VLOOKUP(D26,$AH$9:$AI$24,2,FALSE) -> c 2 deg (67%).ts_030 | C26: =C25+1 -> 18 | D26: =VLOOKUP(AJ26,$AG$9:$AH$22,2,FALSE) -> ts_030 | E26: =E21 -> C3 | S26: ~TFM_INS-TS | AJ26: =AJ21+1 -> 4
A27: 5 | B27: =VLOOKUP(E27,$AK$9:$AL$15,2,FALSE)&"."&VLOOKUP(D27,$AH$9:$AI$24,2,FALSE) -> b 2 deg (50%).ts_030 | C27: =C26+1 -> 19 | D27: =VLOOKUP(AJ27,$AG$9:$AH$22,2,FALSE) -> ts_030 | E27: =E22 -> C4 | S27: process | T27: =T17 -> 2022 | U27: =U17 -> 2025 | V27: =V17 -> 2030 | W27: =W17 -> 2035 | X27: =X17 -> 2040 | Y27: =Y17 -> 2045 | Z27: =Z17 -> 2050 | AA27: attribute | AB27: limtype | AJ27: =AJ22+1 -> 4
A28: 5 | B28: =VLOOKUP(E28,$AK$9:$AL$15,2,FALSE)&"."&VLOOKUP(D28,$AH$9:$AI$24,2,FALSE) -> a 3 deg.ts_030 | C28: =C27+1 -> 20 | D28: =VLOOKUP(AJ28,$AG$9:$AH$22,2,FALSE) -> ts_030 | E28: =E23 -> C7 | Q28: =SUMIFS(iea_data!G3:G9999,iea_data!$B$3:$B$9999,Veda!$S$11) -> 10.76 | S28: Trd_electricity import | T28: =Q28 -> 10.76 | AA28: ACT_BND | AB28: FX | AJ28: =AJ23+1 -> 4
A29: 5 | B29: =VLOOKUP(E29,$AK$9:$AL$15,2,FALSE)&"."&VLOOKUP(D29,$AH$9:$AI$24,2,FALSE) -> e 1.5 deg no OS.ts_048 | C29: =C28+1 -> 21 | D29: =VLOOKUP(AJ29,$AG$9:$AH$22,2,FALSE) -> ts_048 | E29: =E24 -> C1 | Q29: =SUMIFS(iea_data!H3:H9999,iea_data!$B$3:$B$9999,Veda!$S$11) -> -12.27 | S29: Trd_electricity export | T29: =-1*Q29 -> 12.27 | AA29: ACT_BND | AB29: FX | AJ29: =AJ24+1 -> 5
A30: 5 | B30: =VLOOKUP(E30,$AK$9:$AL$15,2,FALSE)&"."&VLOOKUP(D30,$AH$9:$AI$24,2,FALSE) -> d 1.5 deg OS.ts_048 | C30: =C29+1 -> 22 | D30: =VLOOKUP(AJ30,$AG$9:$AH$22,2,FALSE) -> ts_048 | E30: =E25 -> C2 | AJ30: =AJ25+1 -> 5
A31: 5 | B31: =VLOOKUP(E31,$AK$9:$AL$15,2,FALSE)&"."&VLOOKUP(D31,$AH$9:$AI$24,2,FALSE) -> c 2 deg (67%).ts_048 | C31: =C30+1 -> 23 | D31: =VLOOKUP(AJ31,$AG$9:$AH$22,2,FALSE) -> ts_048 | E31: =E26 -> C3 | AJ31: =AJ26+1 -> 5
A32: 5 | B32: =VLOOKUP(E32,$AK$9:$AL$15,2,FALSE)&"."&VLOOKUP(D32,$AH$9:$AI$24,2,FALSE) -> b 2 deg (50%).ts_048 | C32: =C31+1 -> 24 | D32: =VLOOKUP(AJ32,$AG$9:$AH$22,2,FALSE) -> ts_048 | E32: =E27 -> C4 | AJ32: =AJ27+1 -> 5
A33: 5 | B33: =VLOOKUP(E33,$AK$9:$AL$15,2,FALSE)&"."&VLOOKUP(D33,$AH$9:$AI$24,2,FALSE) -> a 3 deg.ts_048 | C33: =C32+1 -> 25 | D33: =VLOOKUP(AJ33,$AG$9:$AH$22,2,FALSE) -> ts_048 | E33: =E28 -> C7 | AJ33: =AJ28+1 -> 5
A34: 5 | B34: =VLOOKUP(E34,$AK$9:$AL$15,2,FALSE)&"."&VLOOKUP(D34,$AH$9:$AI$24,2,FALSE) -> e 1.5 deg no OS.ts_072 | C34: =C33+1 -> 26 | D34: =VLOOKUP(AJ34,$AG$9:$AH$22,2,FALSE) -> ts_072 | E34: =E29 -> C1 | AJ34: =AJ29+1 -> 6
A35: 5 | B35: =VLOOKUP(E35,$AK$9:$AL$15,2,FALSE)&"."&VLOOKUP(D35,$AH$9:$AI$24,2,FALSE) -> d 1.5 deg OS.ts_072 | C35: =C34+1 -> 27 | D35: =VLOOKUP(AJ35,$AG$9:$AH$22,2,FALSE) -> ts_072 | E35: =E30 -> C2 | AJ35: =AJ30+1 -> 6
A36: 5 | B36: =VLOOKUP(E36,$AK$9:$AL$15,2,FALSE)&"."&VLOOKUP(D36,$AH$9:$AI$24,2,FALSE) -> c 2 deg (67%).ts_072 | C36: =C35+1 -> 28 | D36: =VLOOKUP(AJ36,$AG$9:$AH$22,2,FALSE) -> ts_072 | E36: =E31 -> C3 | G36: C7 | AJ36: =AJ31+1 -> 6
A37: 5 | B37: =VLOOKUP(E37,$AK$9:$AL$15,2,FALSE)&"."&VLOOKUP(D37,$AH$9:$AI$24,2,FALSE) -> b 2 deg (50%).ts_072 | C37: =C36+1 -> 29 | D37: =VLOOKUP(AJ37,$AG$9:$AH$22,2,FALSE) -> ts_072 | E37: =E32 -> C4 | G37: Gas Price | I37: =SUMIFS(ar6_r10!$F$2:$F$999,ar6_r10!$A$2:$A$999,Veda!$G$36,ar6_r10!$C$2:$C$999,Veda!I$17,ar6_r10!$M$2:$M$999,Veda!$G37) -> 1 | J37: =SUMIFS(ar6_r10!$F$2:$F$999,ar6_r10!$A$2:$A$999,Veda!$G$36,ar6_r10!$C$2:$C$999,Veda!J$17,ar6_r10!$M$2:$M$999,Veda!$G37) -> 1.04 | K37: =SUMIFS(ar6_r10!$F$2:$F$999,ar6_r10!$A$2:$A$999,Veda!$G$36,ar6_r10!$C$2:$C$999,Veda!K$17,ar6_r10!$M$2:$M$999,Veda!$G37) -> 1.37 | L37: =SUMIFS(ar6_r10!$F$2:$F$999,ar6_r10!$A$2:$A$999,Veda!$G$36,ar6_r10!$C$2:$C$999,Veda!L$17,ar6_r10!$M$2:$M$999,Veda!$G37) -> 1.3 | M37: =SUMIFS(ar6_r10!$F$2:$F$999,ar6_r10!$A$2:$A$999,Veda!$G$36,ar6_r10!$C$2:$C$999,Veda!M$17,ar6_r10!$M$2:$M$999,Veda!$G37) -> 1.55 | N37: =SUMIFS(ar6_r10!$F$2:$F$999,ar6_r10!$A$2:$A$999,Veda!$G$36,ar6_r10!$C$2:$C$999,Veda!N$17,ar6_r10!$M$2:$M$999,Veda!$G37) -> 1.63 | O37: =SUMIFS(ar6_r10!$F$2:$F$999,ar6_r10!$A$2:$A$999,Veda!$G$36,ar6_r10!$C$2:$C$999,Veda!O$17,ar6_r10!$M$2:$M$999,Veda!$G37) -> 1.71 | AJ37: =AJ32+1 -> 6
A38: 5 | B38: =VLOOKUP(E38,$AK$9:$AL$15,2,FALSE)&"."&VLOOKUP(D38,$AH$9:$AI$24,2,FALSE) -> a 3 deg.ts_072 | C38: =C37+1 -> 30 | D38: =VLOOKUP(AJ38,$AG$9:$AH$22,2,FALSE) -> ts_072 | E38: =E33 -> C7 | G38: Coal Price | I38: =SUMIFS(ar6_r10!$F$2:$F$999,ar6_r10!$A$2:$A$999,Veda!$G$36,ar6_r10!$C$2:$C$999,Veda!I$17,ar6_r10!$M$2:$M$999,Veda!$G38) -> 1 | J38: =SUMIFS(ar6_r10!$F$2:$F$999,ar6_r10!$A$2:$A$999,Veda!$G$36,ar6_r10!$C$2:$C$999,Veda!J$17,ar6_r10!$M$2:$M$999,Veda!$G38) -> 1.08 | K38: =SUMIFS(ar6_r10!$F$2:$F$999,ar6_r10!$A$2:$A$999,Veda!$G$36,ar6_r10!$C$2:$C$999,Veda!K$17,ar6_r10!$M$2:$M$999,Veda!$G38) -> 1.2 | L38: =SUMIFS(ar6_r10!$F$2:$F$999,ar6_r10!$A$2:$A$999,Veda!$G$36,ar6_r10!$C$2:$C$999,Veda!L$17,ar6_r10!$M$2:$M$999,Veda!$G38) -> 1.34 | M38: =SUMIFS(ar6_r10!$F$2:$F$999,ar6_r10!$A$2:$A$999,Veda!$G$36,ar6_r10!$C$2:$C$999,Veda!M$17,ar6_r10!$M$2:$M$999,Veda!$G38) -> 1.52 | N38: =SUMIFS(ar6_r10!$F$2:$F$999,ar6_r10!$A$2:$A$999,Veda!$G$36,ar6_r10!$C$2:$C$999,Veda!N$17,ar6_r10!$M$2:$M$999,Veda!$G38) -> 1.46 | O38: =SUMIFS(ar6_r10!$F$2:$F$999,ar6_r10!$A$2:$A$999,Veda!$G$36,ar6_r10!$C$2:$C$999,Veda!O$17,ar6_r10!$M$2:$M$999,Veda!$G38) -> 1.57 | AJ38: =AJ33+1 -> 6
A39: 5 | B39: =VLOOKUP(E39,$AK$9:$AL$15,2,FALSE)&"."&VLOOKUP(D39,$AH$9:$AI$24,2,FALSE) -> e 1.5 deg no OS.ts_144 | C39: =C38+1 -> 31 | D39: =VLOOKUP(AJ39,$AG$9:$AH$22,2,FALSE) -> ts_144 | E39: =E34 -> C1 | G39: Oil Price | I39: =SUMIFS(ar6_r10!$F$2:$F$999,ar6_r10!$A$2:$A$999,Veda!$G$36,ar6_r10!$C$2:$C$999,Veda!I$17,ar6_r10!$M$2:$M$999,Veda!$G39) -> 1 | J39: =SUMIFS(ar6_r10!$F$2:$F$999,ar6_r10!$A$2:$A$999,Veda!$G$36,ar6_r10!$C$2:$C$999,Veda!J$17,ar6_r10!$M$2:$M$999,Veda!$G39) -> 1.15 | K39: =SUMIFS(ar6_r10!$F$2:$F$999,ar6_r10!$A$2:$A$999,Veda!$G$36,ar6_r10!$C$2:$C$999,Veda!K$17,ar6_r10!$M$2:$M$999,Veda!$G39) -> 1.6 | L39: =SUMIFS(ar6_r10!$F$2:$F$999,ar6_r10!$A$2:$A$999,Veda!$G$36,ar6_r10!$C$2:$C$999,Veda!L$17,ar6_r10!$M$2:$M$999,Veda!$G39) -> 1.33 | M39: =SUMIFS(ar6_r10!$F$2:$F$999,ar6_r10!$A$2:$A$999,Veda!$G$36,ar6_r10!$C$2:$C$999,Veda!M$17,ar6_r10!$M$2:$M$999,Veda!$G39) -> 1.47 | N39: =SUMIFS(ar6_r10!$F$2:$F$999,ar6_r10!$A$2:$A$999,Veda!$G$36,ar6_r10!$C$2:$C$999,Veda!N$17,ar6_r10!$M$2:$M$999,Veda!$G39) -> 1.61 | O39: =SUMIFS(ar6_r10!$F$2:$F$999,ar6_r10!$A$2:$A$999,Veda!$G$36,ar6_r10!$C$2:$C$999,Veda!O$17,ar6_r10!$M$2:$M$999,Veda!$G39) -> 1.77 | AJ39: =AJ34+1 -> 7
A40: 5 | B40: =VLOOKUP(E40,$AK$9:$AL$15,2,FALSE)&"."&VLOOKUP(D40,$AH$9:$AI$24,2,FALSE) -> d 1.5 deg OS.ts_144 | C40: =C39+1 -> 32 | D40: =VLOOKUP(AJ40,$AG$9:$AH$22,2,FALSE) -> ts_144 | E40: =E35 -> C2 | G40: Biomass Price | I40: =SUMIFS(ar6_r10!$F$2:$F$999,ar6_r10!$A$2:$A$999,Veda!$G$36,ar6_r10!$C$2:$C$999,Veda!I$17,ar6_r10!$M$2:$M$999,Veda!$G40) -> 1 | J40: =SUMIFS(ar6_r10!$F$2:$F$999,ar6_r10!$A$2:$A$999,Veda!$G$36,ar6_r10!$C$2:$C$999,Veda!J$17,ar6_r10!$M$2:$M$999,Veda!$G40) -> 0.84 | K40: =SUMIFS(ar6_r10!$F$2:$F$999,ar6_r10!$A$2:$A$999,Veda!$G$36,ar6_r10!$C$2:$C$999,Veda!K$17,ar6_r10!$M$2:$M$999,Veda!$G40) -> 0.79 | L40: =SUMIFS(ar6_r10!$F$2:$F$999,ar6_r10!$A$2:$A$999,Veda!$G$36,ar6_r10!$C$2:$C$999,Veda!L$17,ar6_r10!$M$2:$M$999,Veda!$G40) -> 0.82 | M40: =SUMIFS(ar6_r10!$F$2:$F$999,ar6_r10!$A$2:$A$999,Veda!$G$36,ar6_r10!$C$2:$C$999,Veda!M$17,ar6_r10!$M$2:$M$999,Veda!$G40) -> 0.86 | N40: =SUMIFS(ar6_r10!$F$2:$F$999,ar6_r10!$A$2:$A$999,Veda!$G$36,ar6_r10!$C$2:$C$999,Veda!N$17,ar6_r10!$M$2:$M$999,Veda!$G40) -> 0.88 | O40: =SUMIFS(ar6_r10!$F$2:$F$999,ar6_r10!$A$2:$A$999,Veda!$G$36,ar6_r10!$C$2:$C$999,Veda!O$17,ar6_r10!$M$2:$M$999,Veda!$G40) -> 0.9 | AJ40: =AJ35+1 -> 7
A41: 5 | B41: =VLOOKUP(E41,$AK$9:$AL$15,2,FALSE)&"."&VLOOKUP(D41,$AH$9:$AI$24,2,FALSE) -> c 2 deg (67%).ts_144 | C41: =C40+1 -> 33 | D41: =VLOOKUP(AJ41,$AG$9:$AH$22,2,FALSE) -> ts_144 | E41: =E36 -> C3 | AJ41: =AJ36+1 -> 7
A42: 5 | B42: =VLOOKUP(E42,$AK$9:$AL$15,2,FALSE)&"."&VLOOKUP(D42,$AH$9:$AI$24,2,FALSE) -> b 2 deg (50%).ts_144 | C42: =C41+1 -> 34 | D42: =VLOOKUP(AJ42,$AG$9:$AH$22,2,FALSE) -> ts_144 | E42: =E37 -> C4 | AJ42: =AJ37+1 -> 7
...

Sheet fuel_prices
A9: Fuel Prices
A10: iso | B10: gas_low | C10: gas_high | D10: coal_low | E10: coal_high | F10: oil_low | G10: oil_high | H10: bioenergy_low | I10: bioenergy_high | J10: Notes
A11: ZAF | B11: 20.6 | C11: 30.9 | D11: 7.6 | E11: 10.7 | F11: 45 | G11: 55 | H11: 18 | I11: 26 | J11: Limited gas, abundant cheap coal

Sheet iea_data
A9: IEA Baseline Data
A10: iso | B10: year | C10: industry_twh | D10: buildings_agri_twh | E10: nonroad_transport_twh | F10: road_transport_twh | G10: imports_twh | H10: exports_twh | I10: total_production_twh
A11: ZAF | B11: 2000 | C11: 142.39 | D11: 49.83 | E11: 3.43 | F11: 0.03 | G11: 15.72 | H11: -3.39 | I11: 207.84
A12: ZAF | B12: 2001 | C12: 146.94 | D12: 57.1 | E12: 3.48 | F12: 0.02 | G12: 9.2 | H12: -7 | I12: 208.17
A13: ZAF | B13: 2002 | C13: 154.36 | D13: 53.29 | E13: 3.3 | F13: 0.02 | G13: 9.5 | H13: -7.24 | I13: 218.56
A14: ZAF | B14: 2003 | C14: 149.14 | D14: 60.29 | E14: 3.27 | F14: 0.02 | G14: 8.19 | H14: -10.26 | I14: 231.25
A15: ZAF | B15: 2004 | C15: 161.48 | D15: 67.38 | E15: 3.29 | F15: 0.02 | G15: 9.82 | H15: -13.25 | I15: 240.93
A16: ZAF | B16: 2005 | C16: 155.32 | D16: 69.59 | E16: 3.28 | F16: 0.02 | G16: 11.08 | H16: -13.42 | I16: 242.06
A17: ZAF | B17: 2006 | C17: 161.09 | D17: 74.34 | E17: 3.28 | F17: 0.02 | G17: 10.62 | H17: -13.59 | I17: 250.85
A18: ZAF | B18: 2007 | C18: 165.17 | D18: 77.16 | E18: 3.15 | F18: 0.02 | G18: 11.35 | H18: -14.5 | I18: 260.5
A19: ZAF | B19: 2008 | C19: 166.07 | D19: 75.49 | E19: 3.09 | F19: 0.02 | G19: 10.57 | H19: -14.17 | I19: 255.52
A20: ZAF | B20: 2009 | C20: 165.68 | D20: 73.45 | E20: 2.9 | F20: 0.02 | G20: 12.3 | H20: -14.05 | I20: 246.82
A21: ZAF | B21: 2010 | C21: 171.41 | D21: 76.43 | E21: 2.94 | F21: 0.02 | G21: 12.19 | H21: -14.67 | I21: 256.65
A22: ZAF | B22: 2011 | C22: 171.22 | D22: 76.88 | E22: 3.12 | F22: 0.03 | G22: 11.89 | H22: -14.96 | I22: 259.58
... A33: ZAF | B33: 2022 | C33: 140.8 | D33: 85.66 | E33: 1.67 | F33: 0.05 | G33: 10.76 | H33: -12.27 | I33: 230.77

Sheet ar6_r10
A9: AR6 Scenario Drivers
A10: Category | B10: Region | C10: Year | D10: count | E10: mean | F10: median | G10: std | H10: min | I10: max | J10: q25 | K10: q75 | L10: category_description | M10: attribute
A11: C1 | B11: R10AFRICA | C11: 2020 | D11: 58 | E11: 4.4 | F11: 0.43 | G11: 5.71 | H11: 0 | I11: 15.58 | J11: 0 | K11: 8.31 | L11: Limit warming to 1.5°C (>50%) with no or limited overshoot | M11: CO2 price
A12: C1 | B12: R10AFRICA | C12: 2025 | D12: 58 | E12: 132.94 | F12: 113.94 | G12: 135.33 | H12: 13.36 | I12: 626.48 | J12: 28.22 | K12: 179.27 | L12: Limit warming to 1.5°C (>50%) with no or limited overshoot | M12: CO2 price
A13: C1 | B13: R10AFRICA | C13: 2030 | D13: 58 | E13: 191.57 | F13: 180.17 | G13: 130.46 | H13: 3.02 | I13: 673.46 | J13: 89.49 | K13: 241.69 | L13: Limit warming to 1.5°C (>50%) with no or limited overshoot | M13: CO2 price
A14: C1 | B14: R10AFRICA | C14: 2035 | D14: 58 | E14: 278.86 | F14: 243.45 | G14: 167.16 | H14: 9.51 | I14: 859.53 | J14: 142.95 | K14: 358.71 | L14: Limit warming to 1.5°C (>50%) with no or limited overshoot | M14: CO2 price
A15: C1 | B15: R10AFRICA | C15: 2040 | D15: 58 | E15: 397.63 | F15: 326.01 | G15: 215.59 | H15: 115.55 | I15: 1097.01 | J15: 239.53 | K15: 539.74 | L15: Limit warming to 1.5°C (>50%) with no or limited overshoot | M15: CO2 price
A16: C1 | B16: R10AFRICA | C16: 2045 | D16: 58 | E16: 527.26 | F16: 415.81 | G16: 250.01 | H16: 193.42 | I16: 1269.88 | J16: 353.85 | K16: 714.5 | L16: Limit warming to 1.5°C (>50%) with no or limited overshoot | M16: CO2 price
A17: C1 | B17: R10AFRICA | C17: 2050 | D17: 58 | E17: 649.79 | F17: 605.23 | G17: 268.91 | H17: 209.76 | I17: 1271.76 | J17: 451.31 | K17: 863.42 | L17: Limit warming to 1.5°C (>50%) with no or limited overshoot | M17: CO2 price
A18: C2 | B18: R10AFRICA | C18: 2020 | D18: 76 | E18: 1.95 | F18: 0 | G18: 3.61 | H18: 0 | I18: 15.58 | J18: 0 | K18: 0.55 | L18: Limit warming to 1.5°C (>67%) with high overshoot | M18: CO2 price
A19: C2 | B19: R10AFRICA | C19: 2025 | D19: 65 | E19: 42.95 | F19: 32.69 | G19: 45.96 | H19: 0 | I19: 174.97 | J19: 5.54 | K19: 61.39 | L19: Limit warming to 1.5°C (>67%) with high overshoot | M19: CO2 price
A20: C2 | B20: R10AFRICA | C20: 2030 | D20: 76 | E20: 55.8 | F20: 49.85 | G20: 54.52 | H20: 0 | I20: 221.93 | J20: 10.8 | K20: 78.77 | L20: Limit warming to 1.5°C (>67%) with high overshoot | M20: CO2 price
A21: C2 | B21: R10AFRICA | C21: 2035 | D21: 65 | E21: 217.07 | F21: 152.99 | G21: 316.2 | H21: 29.98 | I21: 2037.12 | J21: 95.06 | K21: 208.88 | L21: Limit warming to 1.5°C (>67%) with high overshoot | M21: CO2 price
A22: C2 | B22: R10AFRICA | C22: 2040 | D22: 76 | E22: 257.11 | F22: 191.71 | G22: 381.8 | H22: 0 | I22: 2600 | J22: 106.05 | K22: 261.57 | L22: Limit warming to 1.5°C (>67%) with high overshoot | M22: CO2 price
... A360: C7 | B360: R10AFRICA | C360: 2050 | D360: 7 | E360: 0.94 | F360: 0.9 | G360: 0.15 | H360: 0.84 | I360: 1.28 | J360: 0.87 | K360: 0.92 | L360: Likely above 3°C warming with limited mitigation | M360: Biomass price

Sheet ev_charging_uc
A10: =IFERROR(Veda!D5,"ts_216c") -> ts_annual | C10: day_night | D10: ts_012 | F10: day_night | G10: ts_024 | I10: day_night | J10: ts_036 | L10: day_night | M10: ts_048 | O10: day_night | P10: ts_annual | R10: day_night | S10: ts_12t | U10: day_night | V10: ts_60c | X10: day_night | Y10: ts_216c
C11: D | D11: S03aH02,S02aH02,S01aH02 | F11: D | G11: S02aH04,S02aH02,S03aH03,S01aH03,S02aH03,S03aH04,S01aH04,S03aH02,S01aH02 | I11: D | J11: S01aH02,S04aH04,S01aH04,S02aH03,S04aH02,S03aH02,S03aH04,S02aH02,S01aH03,S03aH03,S02aH04,S04aH03 | L11: D | M11: S03aH04,S04aH03,S04aH06,S04aH02,S01aH05,S03aH06,S01aH06,S02aH03,S01aH02,S04aH04,S01aH04,S02aH02,S03aH03,S01aH03,S02aH06,S03aH05,S02aH04,S02aH05,S04aH05,S03aH02 | O11: D | P11: AllSaAllH | R11: D | S11: WaD,SaD,FaD,RaD,WaP,FaP,SaP,RaP | U11: D | V11: S02aH06,S03aH08,S04aH07,S06aH04,S06aH08,S01aH04,S01aH07,S02aH07,S01aH03,S05aH02,S05aH03,S05aH06,S01aH02,S04aH04,S03aH04,S04aH06,S05aH04,S06aH02,S06aH03,S02aH04,S06aH07,S01aH06,S02aH03,S05aH07,S03aH03,S01aH08,S02aH08,S03aH06,S03aH07,S05aH08,S04aH08,S02aH02,S06aH06,S04aH02,S03aH02,S04aH03 | X11: D | Y11: S05aH11,S08aH07,S09aH03,S11aH03,S11aH04,S12aH11,S01aH09,S03aH04,S06aH14,S08aH05,S09aH07,S09aH13,S10aH09,S10aH10,S11aH05,S11aH10,S12aH03,S03aH03,S08aH12,S08aH14,S09aH05,S12aH07,S04aH04,S05aH10,S09aH11,S01aH11,S04aH10,S06aH06,S06aH10,S11aH08,S12aH12,S01aH03,S02aH10,S05aH03,S05aH06,S12aH09,S01aH14,S04aH14,S05aH08,S06aH13,S09aH06,S09aH12,S10aH08,S12aH13,S01aH06,S01aH12,S02aH03,S05aH07,S06aH09,S06aH11,S07aH03,S07aH11,S08aH06,S09aH09,S09aH10,S10aH07,S10aH14,S11aH14,S12aH10,S02aH14,S03aH11,S04aH03,S05aH13,S07aH04,S07aH09,S08aH03,S09aH04,S11aH07,S01aH05,S01aH08,S02aH08,S03aH06,S03aH07,S03aH12,S06aH05,S08aH10,S09aH14,S10aH06,S11aH06,S12aH04,S12aH05,S02aH06,S03aH05,S03aH08,S03aH10,S04aH07,S05aH05,S06aH04,S06aH08,S06aH12,S08aH04,S08aH13,S01aH04,S01aH07,S01aH13,S02aH07,S02aH09,S03aH13,S04aH09,S04aH11,S05aH12,S07aH06,S08aH09,S10aH11,S11aH13,S01aH10,S02aH11,S04aH12,S07aH05,S07aH10,S08aH11,S10aH12,S10aH13,S11aH11,S11aH12,S02aH13,S04aH05,S04aH08,S07aH12,S07aH13,S11aH09,S12aH08,S02aH12,S04aH06,S04aH13,S05aH04,S06aH03,S09aH08,S10aH04,S12aH06,S12aH14,S02aH04,S02aH05,S03aH09,S03aH14,S05aH09,S05aH14,S06aH07,S07aH07,S07aH08,S07aH14,S08aH08,S10aH03,S10aH05
C12: N | D12: S02aH03,S03aH01,S03aH03,S01aH03,S02aH01,S01aH01 | F12: N | G12: S02aH01,S02aH06,S03aH05,S03aH01,S01aH06,S01aH01,S02aH05,S01aH05,S03aH06 | I12: N | J12: S01aH05,S03aH06,S01aH01,S04aH01,S04aH06,S02aH05,S03aH01,S02aH06,S03aH05,S02aH01,S01aH06,S04aH05 | L12: N | M12: S01aH07,S02aH07,S02aH01,S01aH01,S04aH01,S04aH08,S01aH08,S02aH08,S03aH07,S03aH01,S03aH08,S04aH07 | O12: N | P12: AllSaAllH | R12: N | S12: SaN,WaN,FaN,FaP,SaP,RaP,WaP,RaN | U12: N | V12: S03aH09,S05aH09,S01aH09,S01aH08,S02aH08,S02aH09,S04aH09,S05aH01,S06aH09,S03aH08,S03aH10,S06aH08,S01aH01,S04aH01,S06aH02,S02aH02,S04aH10,S06aH10,S01aH02,S05aH10,S04aH08,S06aH01,S05aH08,S03aH01,S01aH10,S03aH02,S04aH02,S02aH01,S02aH10,S05aH02 | X12: N | Y12: S03aH02,S04aH18,S05aH01,S06aH15,S06aH16,S07aH02,S10aH17,S02aH02,S02aH16,S03aH17,S08aH16,S11aH15,S11aH18,S02aH17,S10aH02,S01aH15,S03aH01,S05aH16,S10aH15,S12aH16,S04aH17,S05aH15,S09aH01,S12aH02,S01aH16,S06aH01,S08aH17,S08aH18,S10aH18,S11aH17,S01aH01,S04aH01,S06aH02,S07aH15,S07aH16,S09aH15,S09aH16,S11aH01,S01aH17,S02aH01,S04aH16,S05aH02,S05aH18,S09aH18,S12aH17,S01aH02,S05aH17,S07aH18,S11aH16,S06aH18,S08aH01,S10aH01,S02aH18,S03aH16,S04aH02,S06aH17,S09aH02,S03aH15,S03aH18,S08aH02,S09aH17,S02aH15,S04aH15,S07aH01,S07aH17,S10aH16,S12aH18,S01aH18,S08aH15,S11aH02,S12aH01,S12aH15
I17: 0.75 | K17: share of charging at night
C18: ~UC_Sets: R_E: AllRegions
H21: =IF(H23=H24,"Not Required!","~UC_T: LO") -> Not Required!
C22: UC_N | D22: Pset_CI | E22: Pset_CO | F22: pset_pn | G22: Cset_CN | H22: TimeSlice | I22: UC_FLO | J22: UC_RHSRT | K22: UC_RHSRT~0
C23: UC_bev night chg limit | D23: ELC | E23: =G23 -> AuxStoIN | F23: *EV* | G23: AuxStoIN | H23: =HLOOKUP($A$10,$D$10:$CU$12,3,FALSE) -> AllSaAllH | I23: =1+I24 -> 0.25 | J23: 0 | K23: 3 | M23: night
D24: ELC | E24: =G24 -> AuxStoIN | F24: *EV* | G24: AuxStoIN | H24: =HLOOKUP($A$10,$D$10:$CU$12,2,FALSE) -> AllSaAllH | I24: =-$I$17 -> -0.75 | M24: day

Sheet ts_012
C9: =IF(A11="x","DeActivated","~TimeSlices") -> DeActivated | I9: =IF(A11="x","DeActivated","~TFM_DINS-AT") -> DeActivated | N9: =IF(A11="x","DeActivated","~TFM_DINS-AT") -> DeActivated | S9: =IF(A11="x","DeActivated","~TFM_DINS-AT") -> DeActivated | X9: =IF(A11="x","DeActivated","~TFM_DINS-TSL: attribute=FLO_EMIS; other_indexes=ACT") -> DeActivated | AJ9: =IF(A11="x","DeActivated","~TFM_INS-TSL: attribute=FLO_SHAR; limtype=FX") -> DeActivated | AV9: =IF(A11="x","DeActivated","~TFM_INS-TSL: attribute=FLO_SHAR; limtype=FX") -> DeActivated | BH9: =IF(A11="x","DeActivated","~TFM_DINS-TSL: attribute=NCAP_PKCNT") -> DeActivated | BS9: =IF(A11="x","DeActivated","~TFM_INS-AT") -> DeActivated | BX9: =IF(A11="x","DeActivated","~TFM_DINS-AT") -> DeActivated | CC9: =IF(A11="x","DeActivated","~TFM_DINS-AT") -> DeActivated | CG9: =IF(A11="x","DeActivated","~TFM_DINS-AT") -> DeActivated | CK9: =IF(A11="x","DeActivated","~TFM_INS-AT") -> DeActivated
A10: ts_012 | C10: season | D10: weekly | E10: daynite | F10: wparent | G10: dparent | I10: commodity | J10: timeslice | K10: com_fr | L10: process | N10: commodity | O10: timeslice | P10: com_fr | Q10: process | S10: commodity | T10: timeslice | U10: com_fr | V10: process | X10: process | Y10: commodity | Z10: S01aH01 | AA10: S01aH02 | AB10: S01aH03 | AC10: S02aH01 | AD10: S02aH02 | AE10: S02aH03 | AF10: S03aH01 | AG10: S03aH02 | AH10: S03aH03 | AJ10: process | AK10: commodity | AL10: S01aH01 | AM10: S01aH02 | AN10: S01aH03 | AO10: S02aH01 | AP10: S02aH02 | AQ10: S02aH03 | AR10: S03aH01 | AS10: S03aH02 | AT10: S03aH03 | AV10: process | AW10: commodity | AX10: S01aH01 | AY10: S01aH02 | AZ10: S01aH03 | BA10: S02aH01 | BB10: S02aH02 | BC10: S02aH03 | BD10: S03aH01 | BE10: S03aH02 | BF10: S03aH03 | BH10: process | BI10: S01aH01 | BJ10: S01aH02 | BK10: S01aH03 | BL10: S02aH01 | BM10: S02aH02 | BN10: S02aH03 | BO10: S03aH01 | BP10: S03aH02 | BQ10: S03aH03 | BS10: process | BT10: commodity | BU10: other_indexes | BV10: ncap_com | BX10: g_yrfr | BY10: com_fr | BZ10: timeslice | CA10: commodity | CC10: commodity | CD10: timeslice | CE10: com_fr | CG10: commodity | CH10: timeslice | CI10: com_pkflx | CK10: Year | CL10: timeslice | CM10: ncap_afs | CN10: pset_ci
A11: =IFERROR(IF(Veda!D5=A10,"ok","x"),"") -> x | C11: S01 | D11: a | E11: H01 | F11: S01,S02,S03 | G11: a | I11: elc_spv_ZAF_001 | J11: S01aH01 | K11: 0.011541313 | L11: IMPNRGZ | N11: elc_won_ZAF_001 | O11: S01aH01 | P11: 0.094917083 | Q11: IMPNRGZ | S11: elc_wof_ZAF_001 | T11: S01aH01 | U11: 0.14189169 | V11: IMPNRGZ | X11: distr_solelc_spv_ZAF_001 | Y11: DEF_E | Z11: 0.92899408 | AA11: 0.098416658 | AB11: 0.7905373 | AC11: 0 | AD11: 0.086374039 | AE11: 0.85714286 | AF11: 0.84232603 | AG11: 0.079696527 | AH11: 0.7859922 | AJ11: distr_sol* | AK11: ELC4H | AL11: 0.86556135 | AM11: 0.032351612 | AN11: 0.1403913 | AO11: 0 | AP11: 0.043283869 | AQ11: 0.2801233 | AR11: 0.70596801 | AS11: 0.024715046 | AT11: 0.34594185 | AV11: distr_sol* | AW11: ELC8H | AX11: 0 | AY11: 0.028186451 | AZ11: 0.18856074 | BA11: 0 | BB11: 0.012318336 | BC11: 0.35367736 | BD11: 0 | BE11: 0.010104536 | BF11: 0.10766033 | BH11: distr_solelc_spv_ZAF_001 | BI11: 0.021544156 | BJ11: 0.53529847 | BK11: 0.069509218 | BL11: 0 | BM11: 0.42548206 | BN11: 0.035504886 | BO11: 0.044627602 | BP11: 0.60864567 | BQ11: 0.068259104 | BS11: distr_sol* | BT11: DEF_C | BU11: OUT | BV11: 0.27522905 | BX11: 0.13504566 | BY11: 0.053332007 | BZ11: S01aH01 | CA11: elc_roadtransport | CC11: elc_buildings | CD11: S01aH01 | CE11: 0.096063649 | CG11: ELC | CH11: S01aH01 | CI11: 0.16784921 | CK11: 2020 | CL11: S01 | CM11: 0.1252 | CN11: hydro
C12: S02 | E12: H02 | G12: a | I12: elc_spv_ZAF_001 | J12: S01aH02 | K12: 0.40966011 | L12: IMPNRGZ | N12: elc_won_ZAF_001 | O12: S01aH02 | P12: 0.20427442 | Q12: IMPNRGZ | S12: elc_wof_ZAF_001 | T12: S01aH02 | U12: 0.17745345 | V12: IMPNRGZ | X12: distr_solelc_spv_ZAF_002 | Y12: DEF_E | Z12: 0.93852529 | AA12: 0.1062844 | AB12: 0.78982814 | AC12: 0 | AD12: 0.078988928 | AE12: 0.85714286 | AF12: 0.84795533 | AG12: 0.07349237 | AH12: 0.77706809 | AJ12: distr_won* | AK12: ELC4H | AL12: 0.0039654151 | AM12: 0.017406715 | AN12: 0.021437322 | AO12: 0.0027237818 | AP12: 0.012794927 | AQ12: 0.0055298843 | AR12: 0.0051669204 | AS12: 0.022602194 | AT12: 0.018315913 | AV12: distr_won* | AW12: ELC8H | AX12: 0.03335199 | AY12: 0.014528433 | AZ12: 0.030975534 | BA12: 0.021015031 | BB12: 0.012706833 | BC12: 0.017628705 | BD12: 0.034567627 | BE12: 0.038938746 | BF12: 0.021053134 | BH12: distr_solelc_spv_ZAF_002 | BI12: 0.021098174 | BJ12: 0.54505394 | BK12: 0.077536921 | BL12: 0 | BM12: 0.42438212 | BN12: 0.03897434 | BO12: 0.047816359 | BP12: 0.63567454 | BQ12: 0.083166003 | BS12: distr_won* | BT12: DEF_C | BU12: OUT | BV12: 0.27522905 | BX12: 0.19292237 | BY12: 0.27018936 | BZ12: S01aH02 | CA12: elc_roadtransport | CC12: elc_buildings | CD12: S01aH02 | CE12: 0.21131599 | CG12: ELC | CH12: S01aH02 | CI12: 0.18811595 | CK12: 2020 | CL12: S02 | CM12: 0.078466667 | CN12: hydro
C13: S03 | E13: H03 | G13: a | I13: elc_spv_ZAF_001 | J13: S01aH03 | K13: 0.037236437 | L13: IMPNRGZ | N13: elc_won_ZAF_001 | O13: S01aH03 | P13: 0.12436852 | Q13: IMPNRGZ | S13: elc_wof_ZAF_001 | T13: S01aH03 | U13: 0.14840869 | V13: IMPNRGZ | X13: distr_solelc_spv_ZAF_003 | Y13: DEF_E | Z13: 0.93829248 | AA13: 0.12940942 | AB13: 0.81339715 | AC13: 0 | AD13: 0.10576413 | AE13: 0.88307494 | AF13: 0.83232323 | AG13: 0.077896578 | AH13: 0.77145147 | AJ13: distr_wof* | AK13: ELC4H | AL13: 0.0042305662 | AM13: 0.0047905191 | AN13: 0.002129576 | AO13: 0.0027968255 | AP13: 0.001729322 | AQ13: 0.001335759 | AR13: 0.0039500475 | AS13: 0.0071324761 | AT13: 0.0020969843 | AV13: distr_wof* | AW13: ELC8H | AX13: 0.0065929357 | AY13: 0.0059278522 | AZ13: 0.0086611516 | BA13: 0.009755426 | BB13: 0.0063715079 | BC13: 0.0038399991 | BD13: 0.0069442865 | BE13: 0.010226445 | BF13: 0.012507806 | BH13: distr_solelc_spv_ZAF_003 | BI13: 0.023762742 | BJ13: 0.54117161 | BK13: 0.078973938 | BL13: 0 | BM13: 0.37798578 | BN13: 0.03140878 | BO13: 0.060077679 | BP13: 0.64032887 | BQ13: 0.090891611 | BS13: distr_wof* | BT13: DEF_C | BU13: OUT | BV13: 0.27522905 | BX13: 0.13504566 | BY13: 0.13949233 | BZ13: S01aH03 | CA13: elc_roadtransport | CC13: elc_buildings | CD13: S01aH03 | CE13: 0.15272227 | CG13: ELC | CH13: S01aH03 | CI13: 0.22084433 | CK13: 2020 | CL13: S03 | CM13: 0.10894 | CN13: hydro
I14: elc_spv_ZAF_001 | J14: S02aH01 | K14: 0 | L14: IMPNRGZ | N14: elc_won_ZAF_001 | O14: S02aH01 | P14: 0.06701279 | Q14: IMPNRGZ | S14: elc_wof_ZAF_001 | T14: S02aH01 | U14: 0.048064228 | V14: IMPNRGZ | X14: distr_solelc_spv_ZAF_004 | Y14: DEF_E | Z14: 0.92509059 | AA14: 0.12990724 | AB14: 0.82893577 | AC14: 0 | AD14: 0.088296494 | AE14: 0.90691647 | AF14: 0.81901846 | AG14: 0.080928264 | AH14: 0.78311996 | BH14: distr_solelc_spv_ZAF_004 | BI14: 0.026826399 | BJ14: 0.52958558 | BK14: 0.066849174 | BL14: 0 | BM14: 0.39479288 | BN14: 0.023518147 | BO14: 0.065963377 | BP14: 0.62946408 | BQ14: 0.081327988 | BX14: 0.051141553 | BY14: 0.020196737 | BZ14: S02aH01 | CA14: elc_roadtransport | CC14: elc_buildings | CD14: S02aH01 | CE14: 0.038053023 | CG14: ELC | CH14: S02aH01 | CI14: 0.13593048 | CK14: 2021 | CL14: S01 | CM14: 0.3028 | CN14: hydro
I15: elc_spv_ZAF_001 | J15: S02aH02 | K15: 0.12331111 | L15: IMPNRGZ | N15: elc_won_ZAF_001 | O15: S02aH02 | P15: 0.1262899 | Q15: IMPNRGZ | S15: elc_wof_ZAF_001 | T15: S02aH02 | U15: 0.063066427 | V15: IMPNRGZ | X15: distr_solelc_spv_ZAF_005 | Y15: DEF_E | Z15: 0.92867893 | AA15: 0.11584031 | AB15: 0.82377654 | AC15: 0 | AD15: 0.082288338 | AE15: 0.88903028 | AF15: 0.81986525 | AG15: 0.08230677 | AH15: 0.78980012 | BH15: distr_solelc_spv_ZAF_005 | BI15: 0.025659293 | BJ15: 0.53008135 | BK15: 0.062162488 | BL15: 0 | BM15: 0.41258284 | BN15: 0.027248685 | BO15: 0.062577237 | BP15: 0.62194392 | BQ15: 0.073077637 | BX15: 0.073059361 | BY15: 0.10232023 | BZ15: S02aH02 | CA15: elc_roadtransport | CC15: elc_buildings | CD15: S02aH02 | CE15: 0.085227601 | CG15: ELC | CH15: S02aH02 | CI15: 0.12575896 | CK15: 2021 | CL15: S02 | CM15: 0.066333333 | CN15: hydro
I16: elc_spv_ZAF_001 | J16: S02aH03 | K16: 0.0072028954 | L16: IMPNRGZ | N16: elc_won_ZAF_001 | O16: S02aH03 | P16: 0.05757298 | Q16: IMPNRGZ | S16: elc_wof_ZAF_001 | T16: S02aH03 | U16: 0.045061668 | V16: IMPNRGZ | X16: distr_solelc_spv_ZAF_006 | Y16: DEF_E | Z16: 0.95874557 | AA16: 0.12851295 | AB16: 0.75049827 | AC16: 0 | AD16: 0.12760787 | AE16: 0.85811563 | AF16: 0.8961039 | AG16: 0.075743987 | AH16: 0.72651165 | BH16: distr_solelc_spv_ZAF_006 | BI16: 0.014721624 | BJ16: 0.55358439 | BK16: 0.10830879 | BL16: 0 | BM16: 0.36646 | BN16: 0.039351041 | BO16: 0.039896532 | BP16: 0.6506824 | BQ16: 0.11869629 | BX16: 0.051141553 | BY16: 0.052825498 | BZ16: S02aH03 | CA16: elc_roadtransport | CC16: elc_buildings | CD16: S02aH03 | CE16: 0.065491197 | CG16: ELC | CH16: S02aH03 | CI16: 0.13858796 | CK16: 2021 | CL16: S03 | CM16: 0.20572 | CN16: hydro
I17: elc_spv_ZAF_001 | J17: S03aH01 | K17: 0.018673103 | L17: IMPNRGZ | N17: elc_won_ZAF_001 | O17: S03aH01 | P17: 0.05900543 | Q17: IMPNRGZ | S17: elc_wof_ZAF_001 | T17: S03aH01 | U17: 0.10856213 | V17: IMPNRGZ | X17: distr_solelc_spv_ZAF_007 | Y17: DEF_E | Z17: 0.9501268 | AA17: 0.13845082 | AB17: 0.76141502 | AC17: 0 | AD17: 0.15392715 | AE17: 0.85910517 | AF17: 0.88655213 | AG17: 0.082272844 | AH17: 0.74089411 | BH17: distr_solelc_spv_ZAF_007 | BI17: 0.018687772 | BJ17: 0.54108579 | BK17: 0.10199276 | BL17: 0 | BM17: 0.33797713 | BN17: 0.036757895 | BO17: 0.044089104 | BP17: 0.63764711 | BQ17: 0.10917211 | BX17: 0.10547945 | BY17: 0.041655769 | BZ17: S03aH01 | CA17: elc_roadtransport | CC17: elc_buildings | CD17: S03aH01 | CE17: 0.072929595 | CG17: ELC | CH17: S03aH01 | CI17: 0.12643215 | CK17: 2022 | CL17: S01 | CM17: 0.6472 | CN17: hydro
I18: elc_spv_ZAF_001 | J18: S03aH02 | K18: 0.36381403 | L18: IMPNRGZ | N18: elc_won_ZAF_001 | O18: S03aH02 | P18: 0.16783982 | Q18: IMPNRGZ | S18: elc_wof_ZAF_001 | T18: S03aH02 | U18: 0.14723236 | V18: IMPNRGZ | X18: distr_solelc_spv_ZAF_008 | Y18: DEF_E | Z18: 0.9602705 | AA18: 0.10303612 | AB18: 0.77911537 | AC18: 0 | AD18: 0.097115798 | AE18: 0.85714286 | AF18: 0.89633038 | AG18: 0.073369342 | AH18: 0.75508391 | BH18: distr_solelc_spv_ZAF_008 | BI18: 0.013003343 | BJ18: 0.56589764 | BK18: 0.09122252 | BL18: 0 | BM18: 0.42734956 | BN18: 0.043932753 | BO18: 0.036199531 | BP18: 0.64645569 | BQ18: 0.097790518 | BX18: 0.15068493 | BY18: 0.21103548 | BZ18: S03aH02 | CA18: elc_roadtransport | CC18: elc_buildings | CD18: S03aH02 | CE18: 0.16127614 | CG18: ELC | CH18: S03aH02 | CI18: 0.15828873 | CK18: 2022 | CL18: S02 | CM18: 0.1762 | CN18: hydro
I19: elc_spv_ZAF_001 | J19: S03aH03 | K19: 0.028561008 | L19: IMPNRGZ | N19: elc_won_ZAF_001 | O19: S03aH03 | P19: 0.098719054 | Q19: IMPNRGZ | S19: elc_wof_ZAF_001 | T19: S03aH03 | U19: 0.12025935 | V19: IMPNRGZ | X19: distr_solelc_spv_ZAF_009 | Y19: DEF_E | Z19: 0.94919054 | AA19: 0.11242705 | AB19: 0.77164191 | AC19: 0 | AD19: 0.10004689 | AE19: 0.85714286 | AF19: 0.88936459 | AG19: 0.071061713 | AH19: 0.75396161 | BH19: distr_solelc_spv_ZAF_009 | BI19: 0.017406009 | BJ19: 0.55666116 | BK19: 0.09202118 | BL19: 0 | BM19: 0.4023874 | BN19: 0.042320517 | BO19: 0.042409108 | BP19: 0.64781684 | BQ19: 0.099066422 | BX19: 0.10547945 | BY19: 0.10895259 | BZ19: S03aH03 | CA19: elc_roadtransport | CC19: elc_buildings | CD19: S03aH03 | CE19: 0.11692054 | CG19: ELC | CH19: S03aH03 | CI19: 0.20409847 | CK19: 2022 | CL19: S03 | CM19: 0.34526 | CN19: hydro
I20: elc_spv_ZAF_002 | J20: S01aH01 | K20: 0.010913439 | L20: IMPNRGZ | N20: elc_won_ZAF_002 | O20: S01aH01 | P20: 0.095496888 | Q20: IMPNRGZ | S20: elc_wof_ZAF_002 | T20: S01aH01 | U20: 0.14332091 | V20: IMPNRGZ | X20: distr_solelc_spv_ZAF_010 | Y20: DEF_E | Z20: 0.96025204 | AA20: 0.17891794 | AB20: 0.74470964 | AC20: 0 | AD20: 0.1819115 | AE20: 0.85722854 | AF20: 0.90127505 | AG20: 0.1203567 | AH20: 0.70922464 | BH20: distr_solelc_spv_ZAF_010 | BI20: 0.012676769 | BJ20: 0.48703933 | BK20: 0.11355664 | BL20: 0 | BM20: 0.27389468 | BN20: 0.033150347 | BO20: 0.033910851 | BP20: 0.58262746 | BQ20: 0.12669242 | CC20: elc_industry | CD20: S01aH01 | CE20: 0.13308094 | CK20: 2025 | CL20: S01 | CM20: 0.37473333 | CN20: hydro
I21: elc_spv_ZAF_002 | J21: S01aH02 | K21: 0.402771 | L21: IMPNRGZ | N21: elc_won_ZAF_002 | O21: S01aH02 | P21: 0.2018171 | Q21: IMPNRGZ | S21: elc_wof_ZAF_002 | T21: S01aH02 | U21: 0.17679872 | V21: IMPNRGZ | X21: distr_solelc_spv_ZAF_011 | Y21: DEF_E | Z21: 0.95519865 | AA21: 0.15980434 | AB21: 0.75215372 | AC21: 0 | AD21: 0.18516529 | AE21: 0.85714286 | AF21: 0.89718928 | AG21: 0.10369447 | AH21: 0.72590224 | BH21: distr_solelc_spv_ZAF_011 | BI21: 0.016497959 | BJ21: 0.50661409 | BK21: 0.10786288 | BL21: 0 | BM21: 0.28515673 | BN21: 0.034550803 | BO21: 0.039291132 | BP21: 0.60623088 | BQ21: 0.11847859 | CC21: elc_industry | CD21: S01aH02 | CE21: 0.19392633 | CK21: 2025 | CL21: S02 | CM21: 0.17863333 | CN21: hydro
I22: elc_spv_ZAF_002 | J22: S01aH03 | K22: 0.040107473 | L22: IMPNRGZ | N22: elc_won_ZAF_002 | O22: S01aH03 | P22: 0.1397454 | Q22: IMPNRGZ | S22: elc_wof_ZAF_002 | T22: S01aH03 | U22: 0.16120063 | V22: IMPNRGZ | X22: distr_solelc_spv_ZAF_012 | Y22: DEF_E | Z22: 0.96047285 | AA22: 0.16021441 | AB22: 0.73853236 | AC22: 0 | AD22: 0.18002685 | AE22: 0.85770036 | AF22: 0.89973178 | AG22: 0.1010028 | AH22: 0.70228802 | BH22: distr_solelc_spv_ZAF_012 | BI22: 0.010884293 | BJ22: 0.50740589 | BK22: 0.11679869 | BL22: 0 | BM22: 0.30287504 | BN22: 0.036592677 | BO22: 0.031169911 | BP22: 0.61279915 | BQ22: 0.13381202 | CC22: elc_industry | CD22: S01aH03 | CE22: 0.13599539 | CK22: 2025 | CL22: S03 | CM22: 0.10224 | CN22: hydro
I23: elc_spv_ZAF_002 | J23: S02aH01 | K23: 0 | L23: IMPNRGZ | N23: elc_won_ZAF_002 | O23: S02aH01 | P23: 0.056072228 | Q23: IMPNRGZ | S23: elc_wof_ZAF_002 | T23: S02aH01 | U23: 0.042678435 | V23: IMPNRGZ | X23: distr_solelc_spv_ZAF_013 | Y23: DEF_E | Z23: 0.95604396 | AA23: 0.14883494 | AB23: 0.7512989 | AC23: 0 | AD23: 0.18939073 | AE23: 0.85911433 | AF23: 0.89784726 | AG23: 0.094646575 | AH23: 0.71945637 | BH23: distr_solelc_spv_ZAF_013 | BI23: 0.014899621 | BJ23: 0.53044726 | BK23: 0.11305623 | BL23: 0 | BM23: 0.31323904 | BN23: 0.036599423 | BO23: 0.03887808 | BP23: 0.62726416 | BQ23: 0.12363892 | CC23: elc_industry | CD23: S02aH01 | CE23: 0.05028774 | CK23: 2026 | CL23: S01 | CM23: 0.34346667 | CN23: hydro
I24: elc_spv_ZAF_002 | J24: S02aH02 | K24: 0.11875969 | L24: IMPNRGZ | N24: elc_won_ZAF_002 | O24: S02aH02 | P24: 0.10753569 | Q24: IMPNRGZ | S24: elc_wof_ZAF_002 | T24: S02aH02 | U24: 0.057579963 | V24: IMPNRGZ | X24: distr_solelc_spv_ZAF_014 | Y24: DEF_E | Z24: 0.96449704 | AA24: 0.13724444 | AB24: 0.73816357 | AC24: 0 | AD24: 0.16542776 | AE24: 0.85773752 | AF24: 0.90151515 | AG24: 0.084242486 | AH24: 0.7026545 | BH24: distr_solelc_spv_ZAF_014 | BI24: 0.011048173 | BJ24: 0.54429729 | BK24: 0.1207129 | BL24: 0 | BM24: 0.34066656 | BN24: 0.039745052 | BO24: 0.034074905 | BP24: 0.64339922 | BQ24: 0.1363181 | CC24: elc_industry | CD24: S02aH02 | CE24: 0.073427345 | CK24: 2026 | CL24: S02 | CM24: 0.19226667 | CN24: hydro
I25: elc_spv_ZAF_002 | J25: S02aH03 | K25: 0.0076346439 | L25: IMPNRGZ | N25: elc_won_ZAF_002 | O25: S02aH03 | P25: 0.057844422 | Q25: IMPNRGZ | S25: elc_wof_ZAF_002 | T25: S02aH03 | U25: 0.042031748 | V25: IMPNRGZ | X25: distr_solelc_spv_ZAF_015 | Y25: DEF_E | Z25: 0.92014711 | AA25: 0.17123679 | AB25: 0.83559297 | AC25: 0 | AD25: 0.16614966 | AE25: 0.93526786 | AF25: 0.82224866 | AG25: 0.11706628 | AH25: 0.78274186 | BH25: distr_solelc_spv_ZAF_015 | BI25: 0.021123307 | BJ25: 0.44484469 | BK25: 0.060667622 | BL25: 0 | BM25: 0.28536803 | BN25: 0.012802154 | BO25: 0.050493347 | BP25: 0.53412726 | BQ25: 0.074162449 | CC25: elc_industry | CD25: S02aH03 | CE25: 0.051699126 | CK25: 2026 | CL25: S03 | CM25: 0.20544 | CN25: hydro
I26: elc_spv_ZAF_002 | J26: S03aH01 | K26: 0.019318815 | L26: IMPNRGZ | N26: elc_won_ZAF_002 | O26: S03aH01 | P26: 0.065080106 | Q26: IMPNRGZ | S26: elc_wof_ZAF_002 | T26: S03aH01 | U26: 0.10765832 | V26: IMPNRGZ | X26: distr_solelc_spv_ZAF_016 | Y26: DEF_E | Z26: 0.92189547 | AA26: 0.15430368 | AB26: 0.83769388 | AC26: 0 | AD26: 0.11371599 | AE26: 0.93526786 | AF26: 0.81787145 | AG26: 0.10306581 | AH26: 0.78618659 | BH26: distr_solelc_spv_ZAF_016 | BI26: 0.023319497 | BJ26: 0.47583749 | BK26: 0.060461887 | BL26: 0 | BM26: 0.34469064 | BN26: 0.0154472 | BO26: 0.057342329 | BP26: 0.57145782 | BQ26: 0.072764819 | CC26: elc_industry | CD26: S03aH01 | CE26: 0.10394521 | CK26: 2027 | CL26: S01 | CM26: 0.25593333 | CN26: hydro
I27: elc_spv_ZAF_002 | J27: S03aH02 | K27: 0.36689412 | L27: IMPNRGZ | N27: elc_won_ZAF_002 | O27: S03aH02 | P27: 0.16571497 | Q27: IMPNRGZ | S27: elc_wof_ZAF_002 | T27: S03aH02 | U27: 0.14386262 | V27: IMPNRGZ | X27: distr_solelc_spv_ZAF_017 | Y27: DEF_E | Z27: 0.93110281 | AA27: 0.16127166 | AB27: 0.82200081 | AC27: 0 | AD27: 0.14276559 | AE27: 0.90751614 | AF27: 0.82259335 | AG27: 0.097450807 | AH27: 0.77369379 | BH27: distr_solelc_spv_ZAF_017 | BI27: 0.020378097 | BJ27: 0.48501702 | BK27: 0.071632741 | BL27: 0 | BM27: 0.32255287 | BN27: 0.020831629 | BO27: 0.052753501 | BP27: 0.58551774 | BQ27: 0.082303772 | CC27: elc_industry | CD27: S03aH02 | CE27: 0.15142985 | CK27: 2027 | CL27: S02 | CM27: 0.11793333 | CN27: hydro
I28: elc_spv_ZAF_002 | J28: S03aH03 | K28: 0.033600814 | L28: IMPNRGZ | N28: elc_won_ZAF_002 | O28: S03aH03 | P28: 0.1106932 | Q28: IMPNRGZ | S28: elc_wof_ZAF_002 | T28: S03aH03 | U28: 0.12486865 | V28: IMPNRGZ | X28: distr_solelc_spv_ZAF_018 | Y28: DEF_E | Z28: 0.95500978 | AA28: 0.18329285 | AB28: 0.76567621 | AC28: 0 | AD28: 0.20289944 | AE28: 0.8633691 | AF28: 0.87803883 | AG28: 0.13340151 | AH28: 0.72778391 | BH28: distr_solelc_spv_ZAF_018 | BI28: 0.010968855 | BJ28: 0.4339993 | BK28: 0.089331968 | BL28: 0 | BM28: 0.25612872 | BN28: 0.028200455 | BO28: 0.029401667 | BP28: 0.53204998 | BQ28: 0.10428076 | CC28: elc_industry | CD28: S03aH03 | CE28: 0.10620805 | CK28: 2027 | CL28: S03 | CM28: 0.0801 | CN28: hydro
I29: elc_spv_ZAF_003 | J29: S01aH01 | K29: 0.012346698 | L29: IMPNRGZ | N29: elc_won_ZAF_003 | O29: S01aH01 | P29: 0.10234343 | Q29: IMPNRGZ | S29: elc_wof_ZAF_003 | T29: S01aH01 | U29: 0.11985598 | V29: IMPNRGZ | X29: distr_solelc_spv_ZAF_019 | Y29: DEF_E | Z29: 0.94843618 | AA29: 0.1773971 | AB29: 0.77851827 | AC29: 0 | AD29: 0.18237609 | AE29: 0.86917559 | AF29: 0.85648242 | AG29: 0.11471626 | AH29: 0.73801678 | BH29: distr_solelc_spv_ZAF_019 | BI29: 0.014972455 | BJ29: 0.4587518 | BK29: 0.087840939 | BL29: 0 | BM29: 0.27511307 | BN29: 0.02538381 | BO29: 0.038707187 | BP29: 0.56194435 | BQ29: 0.10178115 | CK29: 2028 | CL29: S01 | CM29: 0.3096 | CN29: hydro
I30: elc_spv_ZAF_003 | J30: S01aH02 | K30: 0.40169021 | L30: IMPNRGZ | N30: elc_won_ZAF_003 | O30: S01aH02 | P30: 0.17625711 | Q30: IMPNRGZ | S30: elc_wof_ZAF_003 | T30: S01aH02 | U30: 0.18117462 | V30: IMPNRGZ | X30: distr_solelc_spv_ZAF_020 | Y30: DEF_E | Z30: 0.93914172 | AA30: 0.17669525 | AB30: 0.80641602 | AC30: 0 | AD30: 0.17691703 | AE30: 0.91393698 | AF30: 0.83255438 | AG30: 0.10788304 | AH30: 0.76375443 | BH30: distr_solelc_spv_ZAF_020 | BI30: 0.018799148 | BJ30: 0.469005 | BK30: 0.078841458 | BL30: 0 | BM30: 0.29068919 | BN30: 0.019735413 | BO30: 0.04999182 | BP30: 0.57557767 | BQ30: 0.089128151 | CK30: 2028 | CL30: S02 | CM30: 0.1346 | CN30: hydro
I31: elc_spv_ZAF_003 | J31: S01aH03 | K31: 0.041033454 | L31: IMPNRGZ | N31: elc_won_ZAF_003 | O31: S01aH03 | P31: 0.17480586 | Q31: IMPNRGZ | S31: elc_wof_ZAF_003 | T31: S01aH03 | U31: 0.17685879 | V31: IMPNRGZ | X31: distr_solelc_spv_ZAF_021 | Y31: DEF_E | Z31: 0.94669248 | AA31: 0.16435914 | AB31: 0.78460931 | AC31: 0 | AD31: 0.16088514 | AE31: 0.87800437 | AF31: 0.85022869 | AG31: 0.094932714 | AH31: 0.7444675 | BH31: distr_solelc_spv_ZAF_021 | BI31: 0.01813632 | BJ31: 0.49611395 | BK31: 0.090293205 | BL31: 0 | BM31: 0.30934614 | BN31: 0.027451137 | BO31: 0.046247703 | BP31: 0.60211023 | BQ31: 0.10073282 | CK31: 2028 | CL31: S03 | CM31: 0.14776 | CN31: hydro
I32: elc_spv_ZAF_003 | J32: S02aH01 | K32: 0 | L32: IMPNRGZ | N32: elc_won_ZAF_003 | O32: S02aH01 | P32: 0.041052094 | Q32: IMPNRGZ | S32: elc_wof_ZAF_003 | T32: S02aH01 | U32: 0.040582604 | V32: IMPNRGZ | X32: distr_solelc_spv_ZAF_022 | Y32: DEF_E | Z32: 0.98478445 | AA32: 0.17083375 | AB32: 0.74911782 | AC32: 0 | AD32: 0.19045055 | AE32: 0.84397241 | AF32: 0.92200802 | AG32: 0.19587429 | AH32: 0.724067 | BH32: distr_solelc_spv_ZAF_022 | BI32: 0.0019124541 | BJ32: 0.41388918 | BK32: 0.078221917 | BL32: 0 | BM32: 0.32128138 | BN32: 0.036517677 | BO32: 0.013064759 | BP32: 0.43444601 | BQ32: 0.077825072 | CK32: 2029 | CL32: S01 | CM32: 0.25398333 | CN32: hydro
I33: elc_spv_ZAF_003 | J33: S02aH02 | K33: 0.10624903 | L33: IMPNRGZ | N33: elc_won_ZAF_003 | O33: S02aH02 | P33: 0.086080159 | Q33: IMPNRGZ | S33: elc_wof_ZAF_003 | T33: S02aH02 | U33: 0.056379517 | V33: IMPNRGZ | X33: distr_solelc_spv_ZAF_023 | Y33: DEF_E | Z33: 0.98300924 | AA33: 0.17387068 | AB33: 0.75000665 | AC33: 0 | AD33: 0.19487076 | AE33: 0.8450382 | AF33: 0.91835676 | AG33: 0.19920972 | AH33: 0.72189166 | BH33: distr_solelc_spv_ZAF_023 | BI33: 0.0019597829 | BJ33: 0.41173339 | BK33: 0.074456261 | BL33: 0 | BM33: 0.31843964 | BN33: 0.037257086 | BO33: 0.011354906 | BP33: 0.42576437 | BQ33: 0.074701492 | CK33: 2029 | CL33: S02 | CM33: 0.11596667 | CN33: hydro
I34: elc_spv_ZAF_003 | J34: S02aH03 | K34: 0.0061801442 | L34: IMPNRGZ | N34: elc_won_ZAF_003 | O34: S02aH03 | P34: 0.046886572 | Q34: IMPNRGZ | S34: elc_wof_ZAF_003 | T34: S02aH03 | U34: 0.044243071 | V34: IMPNRGZ | X34: distr_solelc_spv_ZAF_024 | Y34: DEF_E | Z34: 0.98647506 | AA34: 0.17562267 | AB34: 0.74461128 | AC34: 0 | AD34: 0.19325725 | AE34: 0.82522954 | AF34: 0.92277597 | AG34: 0.19643146 | AH34: 0.72888138 | BH34: distr_solelc_spv_ZAF_024 | BI34: 0.0015448918 | BJ34: 0.41690284 | BK34: 0.085280039 | BL34: 0 | BM34: 0.32600243 | BN34: 0.039666717 | BO34: 0.013123013 | BP34: 0.44334662 | BQ34: 0.081335925 | CK34: 2029 | CL34: S03 | CM34: 0.20442 | CN34: hydro
I35: elc_spv_ZAF_003 | J35: S03aH01 | K35: 0.024381176 | L35: IMPNRGZ | N35: elc_won_ZAF_003 | O35: S03aH01 | P35: 0.082460121 | Q35: IMPNRGZ | S35: elc_wof_ZAF_003 | T35: S03aH01 | U35: 0.092307512 | V35: IMPNRGZ | X35: distr_solelc_spv_ZAF_025 | Y35: DEF_E | Z35: 0.9898563 | AA35: 0.15639886 | AB35: 0.72565073 | AC35: 0 | AD35: 0.17885525 | AE35: 0.80010083 | AF35: 0.92238984 | AG35: 0.17676253 | AH35: 0.70418349 | BH35: distr_solelc_spv_ZAF_025 | BI35: 0.0011748317 | BJ35: 0.43923898 | BK35: 0.096043578 | BL35: 0 | BM35: 0.34300631 | BN35: 0.049517075 | BO35: 0.012311541 | BP35: 0.47070816 | BQ35: 0.091831773 | CK35: 2030 | CL35: S01 | CM35: 0.28353333 | CN35: hydro
I36: elc_spv_ZAF_003 | J36: S03aH02 | K36: 0.37123297 | L36: IMPNRGZ | N36: elc_won_ZAF_003 | O36: S03aH02 | P36: 0.1517032 | Q36: IMPNRGZ | S36: elc_wof_ZAF_003 | T36: S03aH02 | U36: 0.14878487 | V36: IMPNRGZ | X36: distr_solelc_spv_ZAF_026 | Y36: DEF_E | Z36: 0.98616907 | AA36: 0.16048869 | AB36: 0.7219341 | AC36: 0 | AD36: 0.15923542 | AE36: 0.81574316 | AF36: 0.92359706 | AG36: 0.1457877 | AH36: 0.69929788 | BH36: distr_solelc_spv_ZAF_026 | BI36: 0.0018481417 | BJ36: 0.46295319 | BK36: 0.091070424 | BL36: 0 | BM36: 0.37952071 | BN36: 0.059045443 | BO36: 0.0095048655 | BP36: 0.51896464 | BQ36: 0.09607157 | CK36: 2030 | CL36: S02 | CM36: 0.069066667 | CN36: hydro
I37: elc_spv_ZAF_003 | J37: S03aH03 | K37: 0.036886318 | L37: IMPNRGZ | N37: elc_won_ZAF_003 | O37: S03aH03 | P37: 0.13841144 | Q37: IMPNRGZ | S37: elc_wof_ZAF_003 | T37: S03aH03 | U37: 0.13981304 | V37: IMPNRGZ | X37: distr_solelc_spv_ZAF_027 | Y37: DEF_E | Z37: 0.98293986 | AA37: 0.17245491 | AB37: 0.73495105 | AC37: 0 | AD37: 0.17164665 | AE37: 0.83205559 | AF37: 0.92487654 | AG37: 0.15816435 | AH37: 0.70821391 | BH37: distr_solelc_spv_ZAF_027 | BI37: 0.0020496878 | BJ37: 0.44177431 | BK37: 0.086587647 | BL37: 0 | BM37: 0.35833625 | BN37: 0.05318935 | BO37: 0.0094263308 | BP37: 0.50050928 | BQ37: 0.093977573 | CK37: 2030 | CL37: S03 | CM37: 0.22374 | CN37: hydro
I38: elc_spv_ZAF_004 | J38: S01aH01 | K38: 0.014192966 | L38: IMPNRGZ | N38: elc_won_ZAF_004 | O38: S01aH01 | P38: 0.075488061 | Q38: IMPNRGZ | S38: elc_wof_ZAF_004 | T38: S01aH01 | U38: 0.14137386 | V38: IMPNRGZ | X38: distr_solelc_spv_ZAF_028 | Y38: DEF_E | Z38: 0.97608945 | AA38: 0.19110124 | AB38: 0.75379281 | AC38: 0 | AD38: 0.19760987 | AE38: 0.85936395 | AF38: 0.91996997 | AG38: 0.19510607 | AH38: 0.73054604 | BH38: distr_solelc_spv_ZAF_028 | BI38: 0.0030546922 | BJ38: 0.3873282 | BK38: 0.069951481 | BL38: 0 | BM38: 0.29978923 | BN38: 0.034266279 | BO38: 0.012566584 | BP38: 0.43134999 | BQ38: 0.071941757 | CK38: 2031 | CL38: S01 | CM38: 0.2595 | CN38: hydro
I39: elc_spv_ZAF_004 | J39: S01aH02 | K39: 0.40026617 | L39: IMPNRGZ | N39: elc_won_ZAF_004 | O39: S01aH02 | P39: 0.19912272 | Q39: IMPNRGZ | S39: elc_wof_ZAF_004 | T39: S01aH02 | U39: 0.18925255 | V39: IMPNRGZ | X39: distr_solelc_spv_ZAF_029 | Y39: DEF_E | Z39: 0.98024225 | AA39: 0.19081416 | AB39: 0.74871177 | AC39: 0 | AD39: 0.19442879 | AE39: 0.85092812 | AF39: 0.92317907 | AG39: 0.19098885 | AH39: 0.72346126 | BH39: distr_solelc_spv_ZAF_029 | BI39: 0.002519254 | BJ39: 0.40661292 | BK39: 0.074678797 | BL39: 0 | BM39: 0.32842237 | BN39: 0.042529301 | BO39: 0.010061293 | BP39: 0.45222622 | BQ39: 0.079285251 | CK39: 2031 | CL39: S02 | CM39: 0.0799 | CN39: hydro
I40: elc_spv_ZAF_004 | J40: S01aH03 | K40: 0.035367699 | L40: IMPNRGZ | N40: elc_won_ZAF_004 | O40: S01aH03 | P40: 0.13572086 | Q40: IMPNRGZ | S40: elc_wof_ZAF_004 | T40: S01aH03 | U40: 0.15835181 | V40: IMPNRGZ | X40: distr_solelc_spv_ZAF_030 | Y40: DEF_E | Z40: 0.98135573 | AA40: 0.18883187 | AB40: 0.75136527 | AC40: 0 | AD40: 0.19672154 | AE40: 0.84880729 | AF40: 0.92569412 | AG40: 0.19128931 | AH40: 0.72745022 | BH40: distr_solelc_spv_ZAF_030 | BI40: 0.0020486923 | BJ40: 0.41182127 | BK40: 0.076557568 | BL40: 0 | BM40: 0.33645088 | BN40: 0.041968211 | BO40: 0.0087002394 | BP40: 0.44677655 | BQ40: 0.077985909 | CK40: 2031 | CL40: S03 | CM40: 0.22068 | CN40: hydro
... I97: elc_spv_ZAF_010 | J97: S02aH03 | K97: 0.0071399368 | L97: IMPNRGZ | N97: elc_won_ZAF_010 | O97: S02aH03 | P97: 0.055979288 | Q97: IMPNRGZ | S97: elc_wof_ZAF_010 | T97: S02aH03 | U97: 0.053064292 | V97: IMPNRGZ | X97: distr_wonelc_won_ZAF_024 | Y97: DEF_E | Z97: 0.32570294 | AA97: 0.49220148 | AB97: 0.39572171 | AC97: 0.32054644 | AD97: 0.4553373 | AE97: 0.38601508 | AF97: 0.24621391 | AG97: 0.40433792 | AH97: 0.32183206 | BH97: distr_wonelc_won_ZAF_024 | BI97: 0.24593191 | BJ97: 0.11960177 | BK97: 0.1671844 | BL97: 0.23978494 | BM97: 0.12648286 | BN97: 0.20257592 | BO97: 0.371442 | BP97: 0.2154438 | BQ97: 0.31963438 | CK97: 2050 | CL97: S03 | CM97: 0.13136 | CN97: hydro
I98: elc_spv_ZAF_010 | J98: S03aH01 | K98: 0.015063952 | L98: IMPNRGZ | N98: elc_won_ZAF_010 | O98: S03aH01 | P98: 0.081153715 | Q98: IMPNRGZ | S98: elc_wof_ZAF_010 | T98: S03aH01 | U98: 0.1148595 | V98: IMPNRGZ | X98: distr_wonelc_won_ZAF_025 | Y98: DEF_E | Z98: 0.42069026 | AA98: 0.53567988 | AB98: 0.44082764 | AC98: 0.44507323 | AD98: 0.48725082 | AE98: 0.42892178 | AF98: 0.35979165 | AG98: 0.42367283 | AH98: 0.38817492 | BH98: distr_wonelc_won_ZAF_025 | BI98: 0.14335351 | BJ98: 0.081192328 | BK98: 0.11840436 | BL98: 0.17597412 | BM98: 0.10243447 | BN98: 0.15531995 | BO98: 0.20044789 | BP98: 0.17130885 | BQ98: 0.20335026
I99: elc_spv_ZAF_010 | J99: S03aH02 | K99: 0.3697372 | L99: IMPNRGZ | N99: elc_won_ZAF_010 | O99: S03aH02 | P99: 0.20000245 | Q99: IMPNRGZ | S99: elc_wof_ZAF_010 | T99: S03aH02 | U99: 0.16209461 | V99: IMPNRGZ | X99: distr_wonelc_won_ZAF_026 | Y99: DEF_E | Z99: 0.46223898 | AA99: 0.60438892 | AB99: 0.44641955 | AC99: 0.42087754 | AD99: 0.49872116 | AE99: 0.41654376 | AF99: 0.36066216 | AG99: 0.46476143 | AH99: 0.38126813 | BH99: distr_wonelc_won_ZAF_026 | BI99: 0.098180283 | BJ99: 0.05659413 | BK99: 0.10824842 | BL99: 0.099894726 | BM99: 0.062966234 | BN99: 0.12029464 | BO99: 0.15293712 | BP99: 0.10356782 | BQ99: 0.1956865
I100: elc_spv_ZAF_010 | J100: S03aH03 | K100: 0.056279582 | L100: IMPNRGZ | N100: elc_won_ZAF_010 | O100: S03aH03 | P100: 0.17884738 | Q100: IMPNRGZ | S100: elc_wof_ZAF_010 | T100: S03aH03 | U100: 0.13242244 | V100: IMPNRGZ | X100: distr_wonelc_won_ZAF_027 | Y100: DEF_E | Z100: 0.37246845 | AA100: 0.49509125 | AB100: 0.40548276 | AC100: 0.33303352 | AD100: 0.4637183 | AE100: 0.44615869 | AF100: 0.30261713 | AG100: 0.43289774 | AH100: 0.35140452 | BH100: distr_wonelc_won_ZAF_027 | BI100: 0.25725283 | BJ100: 0.12827988 | BK100: 0.19622497 | BL100: 0.2783401 | BM100: 0.16167169 | BN100: 0.20231161 | BO100: 0.35583288 | BP100: 0.22901479 | BQ100: 0.28730198
I101: elc_spv_ZAF_011 | J101: S01aH01 | K101: 0.009089214 | L101: IMPNRGZ | N101: elc_won_ZAF_011 | O101: S01aH01 | P101: 0.09272406 | Q101: IMPNRGZ | S101: elc_wof_ZAF_011 | T101: S01aH01 | U101: 0.12068721 | V101: IMPNRGZ | X101: distr_wonelc_won_ZAF_028 | Y101: DEF_E | Z101: 0.32463422 | AA101: 0.47539793 | AB101: 0.37354706 | AC101: 0.29974672 | AD101: 0.44798907 | AE101: 0.35986195 | AF101: 0.30825701 | AG101: 0.41366565 | AH101: 0.33073667 | BH101: distr_wonelc_won_ZAF_028 | BI101: 0.2548535 | BJ101: 0.14368595 | BK101: 0.17235986 | BL101: 0.31362596 | BM101: 0.19481814 | BN101: 0.24179119 | BO101: 0.36250079 | BP101: 0.26351576 | BQ101: 0.27723138
