Workbook

Sheet Veda
K1: 65 | L1: 66 | M1: 67 | N1: 68 | O1: 73 | P1: 74 | Q1: 75 | R1: 76 | S1: 81 | T1: 82 | U1: 83 | V1: 84 | W1: 89 | X1: 90 | Y1: 91 | Z1: 92 | AA1: 97 | AB1: 98 | AC1: 99 | AD1: 100 | AE1: 105 | AF1: 106 | AG1: 107 | AH1: 108 | AI1: 113 | AJ1: 114 | AK1: 115 | AL1: 116 | AM1: 121 | AN1: 122 | AO1: 123 | AP1: 124
B2: ="~Inputcell: "&_xlfn.TEXTJOIN(",",TRUE,K1:EI1) -> ~Inputcell: 65,66,67,68,73,74,75,76,81,82,83,84,89,90,91,92,97,98,99,100,105,106,107,108,113,114,115,116,121,122,123,124 | L2: Hi | M2: 1 | N2: 1.2 | O2: =AVERAGE(N2,P2) -> 1.265 | P2: 1.33 | Q2: 1.63 | R2: 2 | S2: 2.322 | U2: This is the q25 demand growth for C4 - the lowest demand cohort
B3: 66 | L3: Lo | M3: 1 | N3: =1+(N2-1)/3.5 -> 1.0571429 | O3: =1+(O2-1)/3.5 -> 1.0757143 | P3: =1+(P2-1)/3.5 -> 1.0942857 | Q3: =1+(Q2-1)/3.5 -> 1.18 | R3: =1+(R2-1)/3.5 -> 1.2857143 | S3: =1+(S2-1)/3.5 -> 1.3777143
D5: =VLOOKUP($B$3,$C$9:$K$999,COLUMN()-2,FALSE) -> Hi | E5: =VLOOKUP($B$3,$C$9:$K$999,COLUMN()-2,FALSE) -> 0 | F5: =VLOOKUP($B$3,$C$9:$K$999,COLUMN()-2,FALSE) -> CF1 | G5: =VLOOKUP($B$3,$C$9:$K$999,COLUMN()-2,FALSE) -> Y | H5: =VLOOKUP($B$3,$C$9:$K$999,COLUMN()-2,FALSE) -> Eco | I5: =VLOOKUP($B$3,$C$9:$K$999,COLUMN()-2,FALSE) -> 0.1 | L5: 0 | M5: 0 | N5: 0 | O5: 0 | P5: 0 | Q5: 0 | R5: 0 | S5: 0
L6: 95 | M6: 0 | N6: 0 | O6: 3 | P6: 35 | Q6: 60 | R6: 80 | S6: 95
B7: ~Scenmap
A8: priority | B8: scen | C8: case_no | D8: demand | E8: co2price | F8: coalflex | G8: DEF | H8: CoaRet | I8: trancost | AR8: bio price multiplier
A9: 5 | B9: =_xlfn.TEXTJOIN(".",TRUE,D9:I9) -> Lo.0.CF1.Y.Pln.1 | C9: 1 | D9: Lo | E9: 0 | F9: CF1 | G9: Y | H9: Pln | I9: 1 | K9: Limit warming to 1.5°C (>50%) with no or limited overshoot | AN9: 1 | AO9: C1 | AP9: e 1.5 deg no OS | AQ9: 5
A10: 5 | B10: =_xlfn.TEXTJOIN(".",TRUE,D10:I10) -> Hi.0.CF1.Y.Pln.1 | C10: =C9+1 -> 2 | D10: Hi | E10: 0 | F10: CF1 | G10: Y | H10: Pln | I10: 1 | K10: Limit warming to 1.5°C (>67%) with high overshoot | W10: IEA | AN10: 1 | AO10: C2 | AP10: d 1.5 deg OS | AQ10: 4
A11: 5 | B11: =_xlfn.TEXTJOIN(".",TRUE,D11:I11) -> Lo.95.CF1.Y.Pln.1 | C11: =C10+1 -> 3 | D11: =D9 -> Lo | E11: 95 | F11: CF1 | G11: Y | H11: Pln | I11: 1 | K11: Limit warming to 2°C (>67%) with higher action post-2030 | W11: 2022 | AN11: 1 | AO11: C3 | AP11: c 2 deg (67%) | AQ11: 3
A12: 5 | B12: =_xlfn.TEXTJOIN(".",TRUE,D12:I12) -> Hi.95.CF1.Y.Pln.1 | C12: =C11+1 -> 4 | D12: =D10 -> Hi | E12: 95 | F12: CF1 | G12: Y | H12: Pln | I12: 1 | K12: Limit warming to 2°C (>50%) with immediate action | W12: =SUMIFS(iea_data!I3:I9999,iea_data!$B$3:$B$9999,Veda!$W$11)+X28-X29 -> 229.26 | X12: base-year generation (TWh) | AN12: 1 | AO12: C4 | AP12: b 2 deg (50%) | AQ12: 3
A13: 5 | B13: =_xlfn.TEXTJOIN(".",TRUE,D13:I13) -> Lo.0.CF1.N.Pln.1 | C13: =C12+1 -> 5 | D13: =D11 -> Lo | E13: =E9 -> 0 | F13: CF1 | G13: N | H13: Pln | I13: 1 | K13: Likely above 3°C warming with limited mitigation | AN13: 1 | AO13: C7 | AP13: a 3 deg | AQ13: 1.5
A14: 5 | B14: =_xlfn.TEXTJOIN(".",TRUE,D14:I14) -> Hi.0.CF1.N.Pln.1 | C14: =C13+1 -> 6 | D14: =D12 -> Hi | E14: =E10 -> 0 | F14: CF1 | G14: N | H14: Pln | I14: 1 | X14: =W12 -> 229.26 | Y14: =$W$12*N15 -> 275.112 | Z14: =$W$12*O15 -> 290.0139 | AA14: =$W$12*P15 -> 304.9158 | AB14: =$W$12*Q15 -> 373.6938 | AC14: =$W$12*R15 -> 458.52 | AD14: =$W$12*S15 -> 532.34172 | AN14: =AN9+1 -> 2
A15: 5 | B15: =_xlfn.TEXTJOIN(".",TRUE,D15:I15) -> Lo.95.CF1.N.Pln.1 | C15: =C14+1 -> 7 | D15: =D13 -> Lo | E15: =E11 -> 95 | F15: CF1 | G15: N | H15: Pln | I15: 1 | K15: Electricity growth relative to 2020 | M15: =SUMIF($L$2:$L$6,$D$5,M$2:M$6) -> 1 | N15: =SUMIF($L$2:$L$6,$D$5,N$2:N$6) -> 1.2 | O15: =SUMIF($L$2:$L$6,$D$5,O$2:O$6) -> 1.265 | P15: =SUMIF($L$2:$L$6,$D$5,P$2:P$6) -> 1.33 | Q15: =SUMIF($L$2:$L$6,$D$5,Q$2:Q$6) -> 1.63 | R15: =SUMIF($L$2:$L$6,$D$5,R$2:R$6) -> 2 | S15: =SUMIF($L$2:$L$6,$D$5,S$2:S$6) -> 2.322 | AN15: =AN10+1 -> 2
A16: 5 | B16: =_xlfn.TEXTJOIN(".",TRUE,D16:I16) -> Hi.95.CF1.N.Pln.1 | C16: =C15+1 -> 8 | D16: =D14 -> Hi | E16: =E12 -> 95 | F16: CF1 | G16: N | H16: Pln | I16: 1 | W16: ~TFM_INS-TS | AN16: =AN11+1 -> 2
A17: 5 | B17: =_xlfn.TEXTJOIN(".",TRUE,D17:I17) -> Lo.0.CF6.Y.Pln.1 | C17: =C16+1 -> 9 | D17: =D15 -> Lo | E17: =E13 -> 0 | F17: CF6 | G17: =G9 -> Y | H17: Pln | I17: 1 | K17: C4 | M17: 2020 | N17: =Y17 -> 2025 | O17: =Z17 -> 2030 | P17: =AA17 -> 2035 | Q17: =AB17 -> 2040 | R17: =AC17 -> 2045 | S17: =AD17 -> 2050 | W17: commodity | X17: 2022 | Y17: 2025 | Z17: 2030 | AA17: 2035 | AB17: 2040 | AC17: 2045 | AD17: 2050 | AE17: attribute | AN17: =AN12+1 -> 2
A18: 5 | B18: =_xlfn.TEXTJOIN(".",TRUE,D18:I18) -> Hi.0.CF6.Y.Pln.1 | C18: =C17+1 -> 10 | D18: =D16 -> Hi | E18: =E14 -> 0 | F18: CF6 | G18: =G10 -> Y | H18: Pln | I18: 1 | K18: Hydrogen as a share of electricity | M18: =SUMIFS(ar6_r10!$K$2:$K$999,ar6_r10!$A$2:$A$999,$K$17,ar6_r10!$C$2:$C$999,Veda!M$17,ar6_r10!$M$2:$M$999,Veda!$K18) -> 0 | N18: =SUMIFS(ar6_r10!$K$2:$K$999,ar6_r10!$A$2:$A$999,$K$17,ar6_r10!$C$2:$C$999,Veda!N$17,ar6_r10!$M$2:$M$999,Veda!$K18) -> 0 | O18: =SUMIFS(ar6_r10!$K$2:$K$999,ar6_r10!$A$2:$A$999,$K$17,ar6_r10!$C$2:$C$999,Veda!O$17,ar6_r10!$M$2:$M$999,Veda!$K18) -> 0 | P18: =SUMIFS(ar6_r10!$K$2:$K$999,ar6_r10!$A$2:$A$999,$K$17,ar6_r10!$C$2:$C$999,Veda!P$17,ar6_r10!$M$2:$M$999,Veda!$K18) -> 0 | Q18: =SUMIFS(ar6_r10!$K$2:$K$999,ar6_r10!$A$2:$A$999,$K$17,ar6_r10!$C$2:$C$999,Veda!Q$17,ar6_r10!$M$2:$M$999,Veda!$K18) -> 0 | R18: =SUMIFS(ar6_r10!$K$2:$K$999,ar6_r10!$A$2:$A$999,$K$17,ar6_r10!$C$2:$C$999,Veda!R$17,ar6_r10!$M$2:$M$999,Veda!$K18) -> 0.01 | S18: =SUMIFS(ar6_r10!$K$2:$K$999,ar6_r10!$A$2:$A$999,$K$17,ar6_r10!$C$2:$C$999,Veda!S$17,ar6_r10!$M$2:$M$999,Veda!$K18) -> 0.01 | W18: hydrogen_allsect | X18: =M18*X$14 -> 0 | Y18: =N18*Y$14 -> 0 | Z18: =O18*Z$14 -> 0 | AA18: =P18*AA$14 -> 0 | AB18: =Q18*AB$14 -> 0 | AC18: =R18*AC$14 -> 4.5852 | AD18: =S18*AD$14 -> 5.3234172 | AE18: demand | AN18: =AN13+1 -> 2
A19: 5 | B19: =_xlfn.TEXTJOIN(".",TRUE,D19:I19) -> Lo.95.CF6.Y.Pln.1 | C19: =C18+1 -> 11 | D19: =D17 -> Lo | E19: =E15 -> 95 | F19: CF6 | G19: =G11 -> Y | H19: Pln | I19: 1 | K19: Industry electricity share | M19: =SUMIFS(ar6_r10!$J$2:$J$999,ar6_r10!$A$2:$A$999,$K$17,ar6_r10!$C$2:$C$999,Veda!M$17,ar6_r10!$M$2:$M$999,Veda!$K19) -> 0.4 | N19: =SUMIFS(ar6_r10!$J$2:$J$999,ar6_r10!$A$2:$A$999,$K$17,ar6_r10!$C$2:$C$999,Veda!N$17,ar6_r10!$M$2:$M$999,Veda!$K19) -> 0.35 | O19: =SUMIFS(ar6_r10!$J$2:$J$999,ar6_r10!$A$2:$A$999,$K$17,ar6_r10!$C$2:$C$999,Veda!O$17,ar6_r10!$M$2:$M$999,Veda!$K19) -> 0.33 | P19: =SUMIFS(ar6_r10!$J$2:$J$999,ar6_r10!$A$2:$A$999,$K$17,ar6_r10!$C$2:$C$999,Veda!P$17,ar6_r10!$M$2:$M$999,Veda!$K19) -> 0.32 | Q19: =SUMIFS(ar6_r10!$J$2:$J$999,ar6_r10!$A$2:$A$999,$K$17,ar6_r10!$C$2:$C$999,Veda!Q$17,ar6_r10!$M$2:$M$999,Veda!$K19) -> 0.31 | R19: =SUMIFS(ar6_r10!$J$2:$J$999,ar6_r10!$A$2:$A$999,$K$17,ar6_r10!$C$2:$C$999,Veda!R$17,ar6_r10!$M$2:$M$999,Veda!$K19) -> 0.31 | S19: =SUMIFS(ar6_r10!$J$2:$J$999,ar6_r10!$A$2:$A$999,$K$17,ar6_r10!$C$2:$C$999,Veda!S$17,ar6_r10!$M$2:$M$999,Veda!$K19) -> 0.31 | W19: elc_industry | X19: =M19*X$14 -> 91.704 | Y19: =N19*Y$14 -> 96.2892 | Z19: =O19*Z$14 -> 95.704587 | AA19: =P19*AA$14 -> 97.573056 | AB19: =Q19*AB$14 -> 115.84508 | AC19: =R19*AC$14 -> 142.1412 | AD19: =S19*AD$14 -> 165.02593 | AE19: demand | AN19: =AN14+1 -> 3
A20: 5 | B20: =_xlfn.TEXTJOIN(".",TRUE,D20:I20) -> Hi.95.CF6.Y.Pln.1 | C20: =C19+1 -> 12 | D20: =D18 -> Hi | E20: =E16 -> 95 | F20: CF6 | G20: =G12 -> Y | H20: Pln | I20: 1 | K20: Residential and commercial electricity share | M20: =SUMIFS(ar6_r10!$J$2:$J$999,ar6_r10!$A$2:$A$999,$K$17,ar6_r10!$C$2:$C$999,Veda!M$17,ar6_r10!$M$2:$M$999,Veda!$K20) -> 0.47 | N20: =SUMIFS(ar6_r10!$J$2:$J$999,ar6_r10!$A$2:$A$999,$K$17,ar6_r10!$C$2:$C$999,Veda!N$17,ar6_r10!$M$2:$M$999,Veda!$K20) -> 0.52 | O20: =SUMIFS(ar6_r10!$J$2:$J$999,ar6_r10!$A$2:$A$999,$K$17,ar6_r10!$C$2:$C$999,Veda!O$17,ar6_r10!$M$2:$M$999,Veda!$K20) -> 0.54 | P20: =SUMIFS(ar6_r10!$J$2:$J$999,ar6_r10!$A$2:$A$999,$K$17,ar6_r10!$C$2:$C$999,Veda!P$17,ar6_r10!$M$2:$M$999,Veda!$K20) -> 0.53 | Q20: =SUMIFS(ar6_r10!$J$2:$J$999,ar6_r10!$A$2:$A$999,$K$17,ar6_r10!$C$2:$C$999,Veda!Q$17,ar6_r10!$M$2:$M$999,Veda!$K20) -> 0.52 | R20: =SUMIFS(ar6_r10!$J$2:$J$999,ar6_r10!$A$2:$A$999,$K$17,ar6_r10!$C$2:$C$999,Veda!R$17,ar6_r10!$M$2:$M$999,Veda!$K20) -> 0.5 | S20: =SUMIFS(ar6_r10!$J$2:$J$999,ar6_r10!$A$2:$A$999,$K$17,ar6_r10!$C$2:$C$999,Veda!S$17,ar6_r10!$M$2:$M$999,Veda!$K20) -> 0.48 | W20: elc_buildings | X20: =M20*X$14 -> 107.7522 | Y20: =N20*Y$14 -> 143.05824 | Z20: =O20*Z$14 -> 156.60751 | AA20: =P20*AA$14 -> 161.60537 | AB20: =Q20*AB$14 -> 194.32078 | AC20: =R20*AC$14 -> 229.26 | AD20: =S20*AD$14 -> 255.52403 | AE20: demand | AN20: =AN15+1 -> 3
A21: 5 | B21: =_xlfn.TEXTJOIN(".",TRUE,D21:I21) -> Lo.0.CF6.N.Pln.1 | C21: =C20+1 -> 13 | D21: =D19 -> Lo | E21: =E17 -> 0 | F21: CF6 | G21: =G13 -> N | H21: Pln | I21: 1 | K21: Transportation electricity share | M21: =SUMIFS(ar6_r10!$J$2:$J$999,ar6_r10!$A$2:$A$999,$K$17,ar6_r10!$C$2:$C$999,Veda!M$17,ar6_r10!$M$2:$M$999,Veda!$K21) -> 0.01 | N21: =SUMIFS(ar6_r10!$J$2:$J$999,ar6_r10!$A$2:$A$999,$K$17,ar6_r10!$C$2:$C$999,Veda!N$17,ar6_r10!$M$2:$M$999,Veda!$K21) -> 0.01 | O21: =SUMIFS(ar6_r10!$J$2:$J$999,ar6_r10!$A$2:$A$999,$K$17,ar6_r10!$C$2:$C$999,Veda!O$17,ar6_r10!$M$2:$M$999,Veda!$K21) -> 0.01 | P21: =SUMIFS(ar6_r10!$J$2:$J$999,ar6_r10!$A$2:$A$999,$K$17,ar6_r10!$C$2:$C$999,Veda!P$17,ar6_r10!$M$2:$M$999,Veda!$K21) -> 0.01 | Q21: =SUMIFS(ar6_r10!$J$2:$J$999,ar6_r10!$A$2:$A$999,$K$17,ar6_r10!$C$2:$C$999,Veda!Q$17,ar6_r10!$M$2:$M$999,Veda!$K21) -> 0.01 | R21: =SUMIFS(ar6_r10!$J$2:$J$999,ar6_r10!$A$2:$A$999,$K$17,ar6_r10!$C$2:$C$999,Veda!R$17,ar6_r10!$M$2:$M$999,Veda!$K21) -> 0.02 | S21: =SUMIFS(ar6_r10!$J$2:$J$999,ar6_r10!$A$2:$A$999,$K$17,ar6_r10!$C$2:$C$999,Veda!S$17,ar6_r10!$M$2:$M$999,Veda!$K21) -> 0.02 | W21: elc_transport | X21: =M21*X$14 -> 2.2926 | Y21: =X21 -> 2.2926 | Z21: =Y21 -> 2.2926 | AA21: =Z21 -> 2.2926 | AB21: =AA21 -> 2.2926 | AC21: =AB21 -> 2.2926 | AD21: =AC21 -> 2.2926 | AE21: demand | AG21: non-road transport demand assumed to be constant | AN21: =AN16+1 -> 3
A22: 5 | B22: =_xlfn.TEXTJOIN(".",TRUE,D22:I22) -> Hi.0.CF6.N.Pln.1 | C22: =C21+1 -> 14 | D22: =D20 -> Hi | E22: =E18 -> 0 | F22: CF6 | G22: =G14 -> N | H22: Pln | I22: 1 | W22: elc_roadtransport | X22: =X14-SUM(X19:X21) -> 27.5112 | Y22: =Y14-SUM(Y19:Y21) -> 33.47196 | Z22: =Z14-SUM(Z19:Z21) -> 35.409207 | AA22: =AA14-SUM(AA19:AA21) -> 43.44477 | AB22: =AB14-SUM(AB19:AB21) -> 61.235346 | AC22: =AC14-SUM(AC19:AC21) -> 84.8262 | AD22: =AD14-SUM(AD19:AD21) -> 109.49916 | AE22: demand | AN22: =AN17+1 -> 3
A23: 5 | B23: =_xlfn.TEXTJOIN(".",TRUE,D23:I23) -> Lo.95.CF6.N.Pln.1 | C23: =C22+1 -> 15 | D23: =D21 -> Lo | E23: =E19 -> 95 | F23: CF6 | G23: =G15 -> N | H23: Pln | I23: 1 | W23: * | AN23: =AN18+1 -> 3
A24: 5 | B24: =_xlfn.TEXTJOIN(".",TRUE,D24:I24) -> Hi.95.CF6.N.Pln.1 | C24: =C23+1 -> 16 | D24: =D22 -> Hi | E24: =E20 -> 95 | F24: CF6 | G24: =G16 -> N | H24: Pln | I24: 1 | K24: CO2 price | M24: =SUMIF($L$2:$L$6,$E$5,M$2:M$6) -> 0 | N24: =SUMIF($L$2:$L$6,$E$5,N$2:N$6) -> 0 | O24: =SUMIF($L$2:$L$6,$E$5,O$2:O$6) -> 0 | P24: =SUMIF($L$2:$L$6,$E$5,P$2:P$6) -> 0 | Q24: =SUMIF($L$2:$L$6,$E$5,Q$2:Q$6) -> 0 | R24: =SUMIF($L$2:$L$6,$E$5,R$2:R$6) -> 0 | S24: =SUMIF($L$2:$L$6,$E$5,S$2:S$6) -> 0 | W24: co2net | Y24: 0 | Z24: =O24/1000 -> 0 | AA24: =P24/1000 -> 0 | AB24: =Q24/1000 -> 0 | AC24: =R24/1000 -> 0 | AD24: =S24/1000 -> 0 | AE24: com_taxnet | AN24: =AN19+1 -> 4
A25: 5 | B25: =_xlfn.TEXTJOIN(".",TRUE,D25:I25) -> Lo.0.CF1.Y.Pln.0.25 | C25: =C24+1 -> 17 | D25: =D23 -> Lo | E25: =E21 -> 0 | F25: =F9 -> CF1 | G25: =G17 -> Y | H25: Pln | I25: 0.25 | AN25: =AN20+1 -> 4
A26: 5 | B26: =_xlfn.TEXTJOIN(".",TRUE,D26:I26) -> Hi.0.CF1.Y.Pln.0.25 | C26: =C25+1 -> 18 | D26: =D24 -> Hi | E26: =E22 -> 0 | F26: =F10 -> CF1 | G26: =G18 -> Y | H26: Pln | I26: 0.25 | W26: ~TFM_INS-TS | AN26: =AN21+1 -> 4
A27: 5 | B27: =_xlfn.TEXTJOIN(".",TRUE,D27:I27) -> Lo.95.CF1.Y.Pln.0.25 | C27: =C26+1 -> 19 | D27: =D25 -> Lo | E27: =E23 -> 95 | F27: =F11 -> CF1 | G27: =G19 -> Y | H27: Pln | I27: 0.25 | W27: process | X27: =X17 -> 2022 | Y27: =Y17 -> 2025 | Z27: =Z17 -> 2030 | AA27: =AA17 -> 2035 | AB27: =AB17 -> 2040 | AC27: =AC17 -> 2045 | AD27: =AD17 -> 2050 | AE27: attribute | AF27: limtype | AN27: =AN22+1 -> 4
A28: 5 | B28: =_xlfn.TEXTJOIN(".",TRUE,D28:I28) -> Hi.95.CF1.Y.Pln.0.25 | C28: =C27+1 -> 20 | D28: =D26 -> Hi | E28: =E24 -> 95 | F28: =F12 -> CF1 | G28: =G20 -> Y | H28: Pln | I28: 0.25 | U28: =SUMIFS(iea_data!G3:G9999,iea_data!$B$3:$B$9999,Veda!$W$11) -> 10.76 | W28: Trd_electricity import | X28: =U28 -> 10.76 | AE28: ACT_BND | AF28: FX | AN28: =AN23+1 -> 4
A29: 5 | B29: =_xlfn.TEXTJOIN(".",TRUE,D29:I29) -> Lo.0.CF1.N.Pln.0.25 | C29: =C28+1 -> 21 | D29: =D27 -> Lo | E29: =E25 -> 0 | F29: =F13 -> CF1 | G29: =G21 -> N | H29: Pln | I29: 0.25 | U29: =SUMIFS(iea_data!H3:H9999,iea_data!$B$3:$B$9999,Veda!$W$11) -> -12.27 | W29: Trd_electricity export | X29: =-1*U29 -> 12.27 | AE29: ACT_BND | AF29: FX | AN29: =AN24+1 -> 5
A30: 5 | B30: =_xlfn.TEXTJOIN(".",TRUE,D30:I30) -> Hi.0.CF1.N.Pln.0.25 | C30: =C29+1 -> 22 | D30: =D28 -> Hi | E30: =E26 -> 0 | F30: =F14 -> CF1 | G30: =G22 -> N | H30: Pln | I30: 0.25 | AN30: =AN25+1 -> 5
A31: 5 | B31: =_xlfn.TEXTJOIN(".",TRUE,D31:I31) -> Lo.95.CF1.N.Pln.0.25 | C31: =C30+1 -> 23 | D31: =D29 -> Lo | E31: =E27 -> 95 | F31: =F15 -> CF1 | G31: =G23 -> N | H31: Pln | I31: 0.25 | AN31: =AN26+1 -> 5
A32: 5 | B32: =_xlfn.TEXTJOIN(".",TRUE,D32:I32) -> Hi.95.CF1.N.Pln.0.25 | C32: =C31+1 -> 24 | D32: =D30 -> Hi | E32: =E28 -> 95 | F32: =F16 -> CF1 | G32: =G24 -> N | H32: Pln | I32: 0.25 | W32: =IF($G$5="N","~TFM_UPD","DEF correction active") -> DEF correction active | AN32: =AN27+1 -> 5
A33: 5 | B33: =_xlfn.TEXTJOIN(".",TRUE,D33:I33) -> Lo.0.CF6.Y.Pln.0.25 | C33: =C32+1 -> 25 | D33: =D31 -> Lo | E33: =E29 -> 0 | F33: =F17 -> CF6 | G33: =G25 -> Y | H33: Pln | I33: 0.25 | W33: attribute | X33: commodity | Y33: pset_set | Z33: value | AN33: =AN28+1 -> 5
A34: 5 | B34: =_xlfn.TEXTJOIN(".",TRUE,D34:I34) -> Hi.0.CF6.Y.Pln.0.25 | C34: =C33+1 -> 26 | D34: =D32 -> Hi | E34: =E30 -> 0 | F34: =F18 -> CF6 | G34: =G26 -> Y | H34: Pln | I34: 0.25 | W34: Share | X34: ELC?H | Y34: Aggregators | Z34: 0 | AN34: =AN29+1 -> 6
A35: 5 | B35: =_xlfn.TEXTJOIN(".",TRUE,D35:I35) -> Lo.95.CF6.Y.Pln.0.25 | C35: =C34+1 -> 27 | D35: =D33 -> Lo | E35: =E31 -> 95 | F35: =F19 -> CF6 | G35: =G27 -> Y | H35: Pln | I35: 0.25 | AN35: =AN30+1 -> 6
A36: 5 | B36: =_xlfn.TEXTJOIN(".",TRUE,D36:I36) -> Hi.95.CF6.Y.Pln.0.25 | C36: =C35+1 -> 28 | D36: =D34 -> Hi | E36: =E32 -> 95 | F36: =F20 -> CF6 | G36: =G28 -> Y | H36: Pln | I36: 0.25 | K36: C7 | AN36: =AN31+1 -> 6
A37: 5 | B37: =_xlfn.TEXTJOIN(".",TRUE,D37:I37) -> Lo.0.CF6.N.Pln.0.25 | C37: =C36+1 -> 29 | D37: =D35 -> Lo | E37: =E33 -> 0 | F37: =F21 -> CF6 | G37: =G29 -> N | H37: Pln | I37: 0.25 | K37: Gas Price | M37: =SUMIFS(ar6_r10!$J$2:$J$999,ar6_r10!$A$2:$A$999,Veda!$K$36,ar6_r10!$C$2:$C$999,Veda!M$17,ar6_r10!$M$2:$M$999,Veda!$K37) -> 1 | N37: =M37 -> 1 | O37: =N37*(1+$U37)^5 -> 1.0510101 | P37: =O37*(1+$U37)^5 -> 1.1046221 | Q37: =P37*(1+$U37)^5 -> 1.160969 | R37: =Q37*(1+$U37)^5 -> 1.22019 | S37: =R37*(1+$U37)^5 -> 1.282432 | U37: 0.01 | W37: =IF($G$5="N","~TFM_INS: limtype=LO","DEF correction active") -> DEF correction active | AN37: =AN32+1 -> 6
A38: 5 | B38: =_xlfn.TEXTJOIN(".",TRUE,D38:I38) -> Hi.0.CF6.N.Pln.0.25 | C38: =C37+1 -> 30 | D38: =D36 -> Hi | E38: =E34 -> 0 | F38: =F22 -> CF6 | G38: =G30 -> N | H38: Pln | I38: 0.25 | K38: Coal Price | M38: =SUMIFS(ar6_r10!$J$2:$J$999,ar6_r10!$A$2:$A$999,Veda!$K$36,ar6_r10!$C$2:$C$999,Veda!M$17,ar6_r10!$M$2:$M$999,Veda!$K38) -> 1 | N38: =M38 -> 1 | O38: =N38 -> 1 | P38: =O38 -> 1 | Q38: =P38 -> 1 | R38: =Q38 -> 1 | S38: =R38 -> 1 | W38: attribute | X38: timeslice | Y38: year | Z38: value | AA38: UC_N | AN38: =AN33+1 -> 6
A39: 5 | B39: =_xlfn.TEXTJOIN(".",TRUE,D39:I39) -> Lo.95.CF6.N.Pln.0.25 | C39: =C38+1 -> 31 | D39: =D37 -> Lo | E39: =E35 -> 95 | F39: =F23 -> CF6 | G39: =G31 -> N | H39: Pln | I39: 0.25 | K39: Oil Price | M39: =SUMIFS(ar6_r10!$J$2:$J$999,ar6_r10!$A$2:$A$999,Veda!$K$36,ar6_r10!$C$2:$C$999,Veda!M$17,ar6_r10!$M$2:$M$999,Veda!$K39) -> 1 | N39: =M39 -> 1 | O39: =N39 -> 1 | P39: =O39 -> 1 | Q39: =P39 -> 1 | R39: =Q39 -> 1 | S39: =R39 -> 1 | W39: UC_RHSRTS | X39: DAYNITE | Y39: 0 | Z39: -13 | AA39: UCE_Min-DispatchablePrd | AN39: =AN34+1 -> 7
A40: 5 | B40: =_xlfn.TEXTJOIN(".",TRUE,D40:I40) -> Hi.95.CF6.N.Pln.0.25 | C40: =C39+1 -> 32 | D40: =D38 -> Hi | E40: =E36 -> 95 | F40: =F24 -> CF6 | G40: =G32 -> N | H40: Pln | I40: 0.25 | K40: Biomass Price | M40: =SUMIFS(ar6_r10!$J$2:$J$999,ar6_r10!$A$2:$A$999,Veda!$K$36,ar6_r10!$C$2:$C$999,Veda!M$17,ar6_r10!$M$2:$M$999,Veda!$K40) -> 1 | N40: =M40 -> 1 | O40: =N40 -> 1 | P40: =O40 -> 1 | Q40: =P40 -> 1 | R40: =Q40 -> 1 | S40: =R40 -> 1 | W40: UC_RHSRT | Y40: 0 | Z40: -13 | AA40: UCE_Min-DispatchableCAP | AN40: =AN35+1 -> 7
A41: 5 | B41: =_xlfn.TEXTJOIN(".",TRUE,D41:I41) -> Lo.0.CF1.Y.Pln.2 | C41: =C40+1 -> 33 | D41: =D39 -> Lo | E41: =E37 -> 0 | F41: =F25 -> CF1 | G41: =G33 -> Y | H41: Pln | I41: 2 | AN41: =AN36+1 -> 7
...

Sheet CF
A1: =Veda!F5 -> CF1
B2: Mapping to the smoke test
B4: For the 24-hour smoke test (2 demand × 2 CO2 × 6 coal variants = 24 cells):
B6: Smoke-test cell | C6: Maps to | D6: MSL | E6: Ramp | F6: Cold starts | G6: MSL | H6: ramp
A7: =LEFT(B7,3) -> CF1 | B7: CF1 (must-run reference) | C7: Meridian CF1 | D7: 0.7 | E7: 0.50× design | F7: 0 | G7: =D7/0.7 -> 1 | H7: 0.5
A8: =LEFT(B8,3) -> CF2 | B8: CF2 (reduced MSL only) | C8: Meridian CF2 | D8: 0.5 | E8: 1.0× design | F8: 0 | G8: =D8/0.7 -> 0.71428571 | H8: 1
A9: =LEFT(B9,3) -> CF3 | B9: CF3 (seasonal only, MSL held) | C9: Meridian CF3 | D9: 0.7 | E9: 1.0× design | F9: 1 | G9: =D9/0.7 -> 1 | H9: 1
A10: =LEFT(B10,3) -> CF4 | B10: CF4 (seasonal + reduced MSL) | C10: Meridian CF4 | D10: 0.5 | E10: 1.0× design | F10: 1 | G10: =D10/0.7 -> 0.71428571 | H10: 1
A11: =LEFT(B11,3) -> CF5 | B11: CF5 (seasonal + more starts) | C11: Meridian CF5 | D11: 0.7 | E11: 1.0× design | F11: 6 | G11: =D11/0.7 -> 1 | H11: 1
A12: =LEFT(B12,3) -> CF6 | B12: CF6 (fully flexible) | C12: Meridian CF6 | D12: 0.4 | E12: 1.5× design | F12: 12 | G12: =D12/0.7 -> 0.57142857 | H12: 1.5
G14: =SUMIF($A$7:$A$12,$A$1,G7:G12) -> 1 | H14: =SUMIF($A$7:$A$12,$A$1,H7:H12) -> 0.5
G16: ~TFM_UPD-AT
G17: ACT_MINLD | H17: ACT_UPS | I17: pset_set
G18: ="*"&G14 -> *1 | H18: ="*"&H14 -> *0.5 | I18: Subcritical Coal, Supercritical Coal, IGCC

Sheet fuel_prices
A9: Fuel Prices
A10: iso | B10: gas_low | C10: gas_high | D10: coal_low | E10: coal_high | F10: oil_low | G10: oil_high | H10: bioenergy_low | I10: bioenergy_high | J10: Notes
A11: ZAF | B11: =7*3.6 -> 25.2 | C11: =B11 -> 25.2 | D11: =1.2*3.6 -> 4.32 | E11: =1.4*3.6 -> 5.04 | F11: =22*3.6 -> 79.2 | G11: =F11 -> 79.2 | H11: 18 | I11: 26 | J11: Limited gas, abundant cheap coal

Sheet iea_data
A9: IEA Baseline Data
A10: iso | B10: year | C10: industry_twh | D10: buildings_agri_twh | E10: nonroad_transport_twh | F10: road_transport_twh | G10: imports_twh | H10: exports_twh | I10: total_production_twh
A11: ZAF | B11: 2000 | C11: 142.39 | D11: 49.83 | E11: 3.43 | F11: 0.03 | G11: 15.72 | H11: -3.39 | I11: 207.84
A12: ZAF | B12: 2001 | C12: 146.94 | D12: 57.1 | E12: 3.48 | F12: 0.02 | G12: 9.2 | H12: -7 | I12: 208.17
A13: ZAF | B13: 2002 | C13: 154.36 | D13: 53.29 | E13: 3.3 | F13: 0.02 | G13: 9.5 | H13: -7.24 | I13: 218.56
A14: ZAF | B14: 2003 | C14: 149.14 | D14: 60.29 | E14: 3.27 | F14: 0.02 | G14: 8.19 | H14: -10.26 | I14: 231.25
A15: ZAF | B15: 2004 | C15: 161.48 | D15: 67.38 | E15: 3.29 | F15: 0.02 | G15: 9.82 | H15: -13.25 | I15: 240.93
A16: ZAF | B16: 2005 | C16: 155.32 | D16: 69.59 | E16: 3.28 | F16: 0.02 | G16: 11.08 | H16: -13.42 | I16: 242.06
A17: ZAF | B17: 2006 | C17: 161.09 | D17: 74.34 | E17: 3.28 | F17: 0.02 | G17: 10.62 | H17: -13.59 | I17: 250.85
A18: ZAF | B18: 2007 | C18: 165.17 | D18: 77.16 | E18: 3.15 | F18: 0.02 | G18: 11.35 | H18: -14.5 | I18: 260.5
A19: ZAF | B19: 2008 | C19: 166.07 | D19: 75.49 | E19: 3.09 | F19: 0.02 | G19: 10.57 | H19: -14.17 | I19: 255.52
A20: ZAF | B20: 2009 | C20: 165.68 | D20: 73.45 | E20: 2.9 | F20: 0.02 | G20: 12.3 | H20: -14.05 | I20: 246.82
A21: ZAF | B21: 2010 | C21: 171.41 | D21: 76.43 | E21: 2.94 | F21: 0.02 | G21: 12.19 | H21: -14.67 | I21: 256.65
A22: ZAF | B22: 2011 | C22: 171.22 | D22: 76.88 | E22: 3.12 | F22: 0.03 | G22: 11.89 | H22: -14.96 | I22: 259.58
... A33: ZAF | B33: 2022 | C33: 140.8 | D33: 85.66 | E33: 1.67 | F33: 0.05 | G33: 10.76 | H33: -12.27 | I33: 230.77

Sheet ar6_r10
A9: AR6 Scenario Drivers
A10: Category | B10: Region | C10: Year | D10: count | E10: mean | F10: median | G10: std | H10: min | I10: max | J10: q25 | K10: q75 | L10: category_description | M10: attribute
A11: C1 | B11: R10AFRICA | C11: 2020 | D11: 58 | E11: 4.4 | F11: 0.43 | G11: 5.71 | H11: 0 | I11: 15.58 | J11: 0 | K11: 8.31 | L11: Limit warming to 1.5°C (>50%) with no or limited overshoot | M11: CO2 price
A12: C1 | B12: R10AFRICA | C12: 2025 | D12: 58 | E12: 132.94 | F12: 113.94 | G12: 135.33 | H12: 13.36 | I12: 626.48 | J12: 28.22 | K12: 179.27 | L12: Limit warming to 1.5°C (>50%) with no or limited overshoot | M12: CO2 price
A13: C1 | B13: R10AFRICA | C13: 2030 | D13: 58 | E13: 191.57 | F13: 180.17 | G13: 130.46 | H13: 3.02 | I13: 673.46 | J13: 89.49 | K13: 241.69 | L13: Limit warming to 1.5°C (>50%) with no or limited overshoot | M13: CO2 price
A14: C1 | B14: R10AFRICA | C14: 2035 | D14: 58 | E14: 278.86 | F14: 243.45 | G14: 167.16 | H14: 9.51 | I14: 859.53 | J14: 142.95 | K14: 358.71 | L14: Limit warming to 1.5°C (>50%) with no or limited overshoot | M14: CO2 price
A15: C1 | B15: R10AFRICA | C15: 2040 | D15: 58 | E15: 397.63 | F15: 326.01 | G15: 215.59 | H15: 115.55 | I15: 1097.01 | J15: 239.53 | K15: 539.74 | L15: Limit warming to 1.5°C (>50%) with no or limited overshoot | M15: CO2 price
A16: C1 | B16: R10AFRICA | C16: 2045 | D16: 58 | E16: 527.26 | F16: 415.81 | G16: 250.01 | H16: 193.42 | I16: 1269.88 | J16: 353.85 | K16: 714.5 | L16: Limit warming to 1.5°C (>50%) with no or limited overshoot | M16: CO2 price
A17: C1 | B17: R10AFRICA | C17: 2050 | D17: 58 | E17: 649.79 | F17: 605.23 | G17: 268.91 | H17: 209.76 | I17: 1271.76 | J17: 451.31 | K17: 863.42 | L17: Limit warming to 1.5°C (>50%) with no or limited overshoot | M17: CO2 price
A18: C2 | B18: R10AFRICA | C18: 2020 | D18: 76 | E18: 1.95 | F18: 0 | G18: 3.61 | H18: 0 | I18: 15.58 | J18: 0 | K18: 0.55 | L18: Limit warming to 1.5°C (>67%) with high overshoot | M18: CO2 price
A19: C2 | B19: R10AFRICA | C19: 2025 | D19: 65 | E19: 42.95 | F19: 32.69 | G19: 45.96 | H19: 0 | I19: 174.97 | J19: 5.54 | K19: 61.39 | L19: Limit warming to 1.5°C (>67%) with high overshoot | M19: CO2 price
A20: C2 | B20: R10AFRICA | C20: 2030 | D20: 76 | E20: 55.8 | F20: 49.85 | G20: 54.52 | H20: 0 | I20: 221.93 | J20: 10.8 | K20: 78.77 | L20: Limit warming to 1.5°C (>67%) with high overshoot | M20: CO2 price
A21: C2 | B21: R10AFRICA | C21: 2035 | D21: 65 | E21: 217.07 | F21: 152.99 | G21: 316.2 | H21: 29.98 | I21: 2037.12 | J21: 95.06 | K21: 208.88 | L21: Limit warming to 1.5°C (>67%) with high overshoot | M21: CO2 price
A22: C2 | B22: R10AFRICA | C22: 2040 | D22: 76 | E22: 257.11 | F22: 191.71 | G22: 381.8 | H22: 0 | I22: 2600 | J22: 106.05 | K22: 261.57 | L22: Limit warming to 1.5°C (>67%) with high overshoot | M22: CO2 price
... A360: C7 | B360: R10AFRICA | C360: 2050 | D360: 7 | E360: 0.94 | F360: 0.9 | G360: 0.15 | H360: 0.84 | I360: 1.28 | J360: 0.87 | K360: 0.92 | L360: Likely above 3°C warming with limited mitigation | M360: Biomass price
