Workbook

Sheet ScenMap
I2: =Q5 -> demand | J2: =R5 -> co2price
B4: ~ScenMap | H4: ~ScenG
B5: Oname | C5: Name | D5: Desc | E5: Ldesc | H5: Scen | I5: ="sg_"&I2 -> sg_demand | J5: ="sg_"&J2 -> sg_co2price | N5: priority | O5: scen | P5: case_no | Q5: demand | R5: co2price
B6: ="vs~"&TEXT(P6,"0000") -> vs~0001 | C6: =H6 -> base·$000 | H6: =O6 -> base·$000 | I6: =Q6 -> base | J6: =TEXT(R6,"$000") -> $000 | N6: 5 | O6: base·$000 | P6: 1 | Q6: base | R6: 0
B7: ="vs~"&TEXT(P7,"0000") -> vs~0002 | C7: =H7 -> base·$100 | H7: =O7 -> base·$100 | I7: =Q7 -> base | J7: =TEXT(R7,"$000") -> $100 | N7: 5 | O7: base·$100 | P7: 2 | Q7: base | R7: 100
B8: ="vs~"&TEXT(P8,"0000") -> vs~0003 | C8: =H8 -> base·$200 | H8: =O8 -> base·$200 | I8: =Q8 -> base | J8: =TEXT(R8,"$000") -> $200 | N8: 5 | O8: base·$200 | P8: 3 | Q8: base | R8: 200
B9: ="vs~"&TEXT(P9,"0000") -> vs~0004 | C9: =H9 -> base·$300 | H9: =O9 -> base·$300 | I9: =Q9 -> base | J9: =TEXT(R9,"$000") -> $300 | N9: 5 | O9: base·$300 | P9: 4 | Q9: base | R9: 300
B10: ="vs~"&TEXT(P10,"0000") -> vs~0005 | C10: =H10 -> high·$000 | H10: =O10 -> high·$000 | I10: =Q10 -> high | J10: =TEXT(R10,"$000") -> $000 | N10: 5 | O10: high·$000 | P10: 5 | Q10: high | R10: 0
B11: ="vs~"&TEXT(P11,"0000") -> vs~0006 | C11: =H11 -> high·$100 | H11: =O11 -> high·$100 | I11: =Q11 -> high | J11: =TEXT(R11,"$000") -> $100 | N11: 5 | O11: high·$100 | P11: 6 | Q11: high | R11: 100
B12: ="vs~"&TEXT(P12,"0000") -> vs~0007 | C12: =H12 -> high·$200 | H12: =O12 -> high·$200 | I12: =Q12 -> high | J12: =TEXT(R12,"$000") -> $200 | N12: 5 | O12: high·$200 | P12: 7 | Q12: high | R12: 200
B13: ="vs~"&TEXT(P13,"0000") -> vs~0008 | C13: =H13 -> high·$300 | H13: =O13 -> high·$300 | I13: =Q13 -> high | J13: =TEXT(R13,"$000") -> $300 | N13: 5 | O13: high·$300 | P13: 8 | Q13: high | R13: 300

Sheet TS_Defs
A1: ~TS_Defs
A2: Attribute | B2: WAttribute | C2: PSET_Set | D2: PSET_PN | E2: PSET_PD | F2: PSET_CI | G2: PSET_CO | H2: CSET_Set | I2: CSET_CN | J2: CSET_CD | K2: Unit | L2: TS | M2: UC_N | N2: Name | O2: Desc | P2: Ldesc | Q2: show_me | R2: discard
A3: VAR_CAP | C3: ELE,CHP,STG,IRE | D3: -ElcAgg*,-*EV*,-g[_]* | K3: GW | N3: Elec Capacity
A4: VAR_NCAP | C4: ELE,CHP,STG,IRE | D4: -ElcAgg*,-*EV*,-g[_]* | K4: GW | N4: Elec New Capacity | T4: group_by
A5: VAR_FOUT | C5: ELE,CHP,IRE | D5: -ElcAgg*,-*EV*,-g[_]* | I5: ELC,ELC_???[_]???*,e[_]* | K5: TWh | N5: Elec Production | T5: p | U5: process
A6: VAR_FIN | C6: ELE | D6: -ElcAgg*,-*EV*,-g[_]* | H6: NRG | K6: TWh | N6: Elec Fuel Consumption
A7: VAR_POUT | C7: ELE,CHP,STG,IRE,-Grid | H7: NRG | I7: -elc_roadtransport | K7: TWh2GW | N7: Power | Q7: t
A8: VAR_FOUT | I8: CO2 | K8: kt | N8: CO2_emission
A9: VAR_FOUT | I9: CO2Captured,CO2[_]* | K9: ktneg | N9: CO2_captured
A10: VAR_FIN | I10: co2s[_]* | K10: kt | N10: CO2_stored | Q10: p
A11: Cap_New | C11: ELE,CHP,STG,IRE,grid,aggregators | D11: -ElcAgg*,-*EV* | K11: m$2020 | M11: LUMPINV | N11: Cost_Inv_lumpsum
A12: Cost_Inv | C12: ELE,CHP,STG,IRE,grid,aggregators | D12: -ElcAgg*,-*EV* | K12: m$2020 | N12: Cost_Investment
A13: Cost_Dec | C13: ELE,CHP,STG,IRE,grid,aggregators | D13: -ElcAgg*,-*EV* | K13: m$2020 | N13: Cost_Investment
A14: Cost_Act | C14: ELE,CHP,STG,IRE | D14: -ElcAgg*,-*EV* | K14: m$2020 | N14: Cost_Variable
A15: Cost_Flo | C15: ELE,CHP,STG,IRE | D15: -ElcAgg*,-*EV* | K15: m$2020 | N15: Cost_Variable
A16: Cost_Fom | C16: ELE,CHP,STG,IRE | D16: -ElcAgg*,-*EV* | K16: m$2020 | N16: Cost_Fixed
A17: Val_Flo | C17: ELE | I17: coal,gas,oil,bioenergy | K17: m$2020 | N17: Cost_Fuel
A18: EQ_COMBALM | B18: VAR_COMPRD | H18: NRG | I18: coal,gas,oil,bioenergy | K18: $/MWh | N18: Price_Fuel | P18: Prices of all NRG - native TS | Q18: ct
A19: EQ_COMBALM | B19: VAR_COMPRD | I19: co2net | K19: 000$/t | N19: Price_CO2
A20: EQ_COMBALM | B20: VAR_COMPRD | H20: NRG | I20: e[_]*,ELC | K20: $/MWh | N20: Price_Electricity | P20: Marginal value of produced electricity | Q20: t
A21: User_conFXM | K21: m$/UCU | N21: UC_shadowprice | P21: shadow prices of all Ucs | Q21: u
A22: VAR_NCAPR | B22: VAR_NCAP | K22: $/MWh | N22: LCOE
A23: Reg_wobj | K23: m$2020 | N23: SysCost_NPV | Q23: u
A24: Reg_ACost | K24: m$2020 | N24: SysCost_Annual | Q24: u
A25: VAR_CAP | C25: grid,aggregators | K25: GW | N25: Grid Capacity
A26: VAR_NCAP | C26: grid,aggregators | K26: GW | N26: Grid New Capacity
A27: VAR_FIN | D27: e_dem*,ev_bat*,H2Prd* | I27: e* | K27: TWh | N27: Demand
A28: VAR_FIN | I28: ELC_???[_]???*,e[_]* | K28: TWh | N28: ~tradeflow_exp | P28: internal variable to enable grid flows visualization | Q28: p,c
A29: VAR_FOUT | I29: ELC_???[_]???*,e[_]* | K29: TWh | N29: ~tradeflow_imp | P29: internal variable to enable grid flows visualization | Q29: p,c
A30: VAR_CAP | F30: e[_]* | G30: e[_]* | K30: GW | N30: ~tradeflow_cap | P30: internal variable to enable grid capacity visualization | Q30: p
A31: VAR_NCAP | F31: e[_]* | G31: e[_]* | K31: GW | N31: ~tradeflow_ncap | P31: internal variable to enable grid new capacity visualization | Q31: p
A32: Cost_Act | C32: ELE,CHP | K32: m$ | N32: z_Elecprodcost
A33: Cost_Flox | C33: ELE,CHP | K33: m$ | N33: z_Elecprodcost
A34: Cost_Fom | C34: ELE,CHP | K34: m$ | N34: z_Elecprodcost
A35: Cost_Inv | C35: ELE,CHP | K35: m$ | N35: z_Elecprodcost
A36: Val_Flo | C36: ELE,CHP | H36: NRG,ENV | I36: -ELC*,-e[_]* | K36: m$ | N36: z_Elecprodcost | Q36: c
A37: VAR_FIN | I37: co2[_]*,co2s[_]* | K37: kt | N37: ~tradeflow_exp | P37: internal variable to enable grid flows visualization | Q37: p,c
A38: VAR_FOUT | I38: co2[_]*,co2s[_]* | K38: kt | N38: ~tradeflow_imp | P38: internal variable to enable grid flows visualization | Q38: p,c
A39: VAR_CAP | F39: co2[_]*,co2s[_]* | G39: co2[_]*,co2s[_]* | K39: ktpa | N39: ~tradeflow_cap | P39: internal variable to enable grid capacity visualization | Q39: p
A40: VAR_NCAP | F40: co2[_]*,co2s[_]* | G40: co2[_]*,co2s[_]* | K40: ktpa | N40: ~tradeflow_ncap | P40: internal variable to enable grid new capacity visualization | Q40: p
...

Sheet TS_ratios
C1: ~TS_Ratios
C2: var_num | D2: var_den | E2: Name | F2: Unit | G2: show_me | H2: ignore | I2: include_null | J2: include_dim | K2: scalar | L2: Ldesc
C3: Elec Production | D3: Elec Capacity | E3: Capacity_factor | F3: Twh/GW | G3: p | I3: y | J3: p | K3: 0
C4: z_Elecprodcost | D4: =C3 -> Elec Production | E4: Avg_cost_elec | F4: $/MWh | J4: p | K4: 0

Sheet Sankey
A3: DeACT TS_Defs: Snk_attr=SANKEY Grid Flows
A4: Attribute | B4: PSET_Set | C4: PSET_PN | D4: PSET_PD | E4: PSET_CI | F4: PSET_CO | G4: CSET_Set | H4: CSET_CN | I4: CSET_CD | J4: Unit | K4: TS | L4: UC_N | M4: Name | N4: Desc | O4: Ldesc | P4: show_me | Q4: ignore | R4: T_neg_andor | S4: downscale_option
A5: VAR_FOUT | B5: =_xlfn.TEXTJOIN(",",TRUE,PSet_MAP!$A$3:$A$28) -> CCGT,Int Comb,Gas_Oil Steam,OCGT (Peaker),Subcritical Coal,Supercritical Coal,IGCC,Bio Power,Solar Util,Wind onshore,Wind offshore,Geothermal P,Hydro Dam,Hydro RoR,Nuclear P,Nuclear SMR,Hydro pumped stg,Util Batt Stg,EV Batt,Demand,Transformers Dn,Transformers Up,Aggregators,DUMMY_IMP | G5: =_xlfn.TEXTJOIN(",",TRUE,CSET_MAP!$A$3:$A$22) -> Solar elec,Wind elec,hydrogen,ELC,buildings,industry,transport,EVs,fossil,renewable,bioenergy,nuclear | J5: TWh | M5: <cset>_Src_<pset> | S5: -1
A6: VAR_FIN | B6: =_xlfn.TEXTJOIN(",",TRUE,PSet_MAP!$A$3:$A$28) -> CCGT,Int Comb,Gas_Oil Steam,OCGT (Peaker),Subcritical Coal,Supercritical Coal,IGCC,Bio Power,Solar Util,Wind onshore,Wind offshore,Geothermal P,Hydro Dam,Hydro RoR,Nuclear P,Nuclear SMR,Hydro pumped stg,Util Batt Stg,EV Batt,Demand,Transformers Dn,Transformers Up,Aggregators,DUMMY_IMP | G6: =_xlfn.TEXTJOIN(",",TRUE,CSET_MAP!$A$3:$A$22) -> Solar elec,Wind elec,hydrogen,ELC,buildings,industry,transport,EVs,fossil,renewable,bioenergy,nuclear | J6: TWh | M6: <cset>_Snk_<pset> | S6: -1
A10: DeACT TS_Defs: Snk_attr=SANKEY whole system
A11: Attribute | B11: PSET_Set | C11: PSET_PN | D11: PSET_PD | E11: PSET_CI | F11: PSET_CO | G11: CSET_Set | H11: CSET_CN | I11: CSET_CD | J11: Unit | K11: TS | L11: UC_N | M11: Name | N11: Desc | O11: Ldesc | P11: show_me | Q11: ignore | R11: T_neg_andor | S11: downscale_option
A12: * | B12: Fuels
A13: VAR_FOUT | F13: =H13 -> bioenergy,coal,gas,geothermal,hydro,hydrogen,nuclear,oil,solar,windon,windoff | H13: =_xlfn.TEXTJOIN(",",TRUE,CName_MAP!$A$3:$A$16) -> bioenergy,coal,gas,geothermal,hydro,hydrogen,nuclear,oil,solar,windon,windoff | J13: TWh | M13: <gen_cname>_src_<gen_pname> | S13: -1
A14: VAR_FIN | B14: =B5 -> CCGT,Int Comb,Gas_Oil Steam,OCGT (Peaker),Subcritical Coal,Supercritical Coal,IGCC,Bio Power,Solar Util,Wind onshore,Wind offshore,Geothermal P,Hydro Dam,Hydro RoR,Nuclear P,Nuclear SMR,Hydro pumped stg,Util Batt Stg,EV Batt,Demand,Transformers Dn,Transformers Up,Aggregators,DUMMY_IMP | H14: =_xlfn.TEXTJOIN(",",TRUE,CName_MAP!$A$3:$A$16) -> bioenergy,coal,gas,geothermal,hydro,hydrogen,nuclear,oil,solar,windon,windoff | J14: TWh | M14: <gen_cname>_snk_<pset> | S14: -1
A15: * | B15: Electricity
A16: VAR_FOUT | B16: =_xlfn.TEXTJOIN(",",TRUE,PSet_MAP!$A$3:$A$28) -> CCGT,Int Comb,Gas_Oil Steam,OCGT (Peaker),Subcritical Coal,Supercritical Coal,IGCC,Bio Power,Solar Util,Wind onshore,Wind offshore,Geothermal P,Hydro Dam,Hydro RoR,Nuclear P,Nuclear SMR,Hydro pumped stg,Util Batt Stg,EV Batt,Demand,Transformers Dn,Transformers Up,Aggregators,DUMMY_IMP | G16: =_xlfn.TEXTJOIN(",",TRUE,CSET_MAP!$A$3:$A$10) -> Solar elec,Wind elec,hydrogen,ELC,buildings,industry,transport,EVs | J16: TWh | M16: <cset>_src_<pset> | S16: -1
A17: VAR_FIN | B17: =_xlfn.TEXTJOIN(",",TRUE,PSet_MAP!$A$3:$A$28) -> CCGT,Int Comb,Gas_Oil Steam,OCGT (Peaker),Subcritical Coal,Supercritical Coal,IGCC,Bio Power,Solar Util,Wind onshore,Wind offshore,Geothermal P,Hydro Dam,Hydro RoR,Nuclear P,Nuclear SMR,Hydro pumped stg,Util Batt Stg,EV Batt,Demand,Transformers Dn,Transformers Up,Aggregators,DUMMY_IMP | G17: =_xlfn.TEXTJOIN(",",TRUE,CSET_MAP!$A$3:$A$10) -> Solar elec,Wind elec,hydrogen,ELC,buildings,industry,transport,EVs | J17: TWh | M17: <cset>_snk_<pset> | S17: -1
A18: * | B18: Hydrogen
A19: VAR_FOUT | F19: =H19 -> hydrogen | H19: hydrogen | J19: TWh | M19: <gen_cname>_src_<gen_pname> | S19: -1
A20: VAR_FIN | F20: hydrogen | G20: =_xlfn.TEXTJOIN(",",TRUE,CSET_MAP!$A$3:$A$22) -> Solar elec,Wind elec,hydrogen,ELC,buildings,industry,transport,EVs,fossil,renewable,bioenergy,nuclear | J20: TWh | M20: <cset>_snk_<gen_pname> | S20: -1
A23: VAR_FIN | E23: hydrogen | H23: hydrogen | J23: TWh | M23: <gen_cname>_snk_<gen_pname> | S23: -1

Sheet PSet_MAP
A1: ~Pset_Map
A2: Pset | B2: Desc | C2: Ldesc
A3: CCGT | B3: =A3 -> CCGT
A4: Int Comb | B4: =A4 -> Int Comb
A5: Gas_Oil Steam | B5: =A5 -> Gas_Oil Steam
A6: OCGT (Peaker) | B6: =A6 -> OCGT (Peaker)
A7: Subcritical Coal | B7: =A7 -> Subcritical Coal
A8: Supercritical Coal | B8: =A8 -> Supercritical Coal
A9: IGCC | B9: =A9 -> IGCC
A10: Bio Power | B10: =A10 -> Bio Power
A11: Solar Util | B11: =A11 -> Solar Util
A12: Wind onshore | B12: Onshore Wind
A13: Wind offshore | B13: Offshore Wind
A14: Geothermal P | B14: =A14 -> Geothermal P
A15: Hydro Dam | B15: =A15 -> Hydro Dam
A16: Hydro RoR | B16: =A16 -> Hydro RoR
A17: Nuclear P | B17: =A17 -> Nuclear P
A18: Nuclear SMR | B18: =A18 -> Nuclear SMR
A19: Hydro pumped stg | B19: =A19 -> Hydro pumped stg
A20: Util Batt Stg | B20: =A20 -> Util Batt Stg
A21: EV Batt | B21: =A21 -> EV Batt
A22: Demand | B22: =A22 -> Demand
A23: Transformers Dn | B23: =A23 -> Transformers Dn
A24: Transformers Up | B24: =A24 -> Transformers Up
A25: Aggregators | B25: =A25 -> Aggregators
A26: DUMMY_IMP | B26: =A26 -> DUMMY_IMP

Sheet CSET_MAP
A1: ~Cset_Map
A2: Cset | B2: Desc | C2: Ldesc
A3: Solar elec | B3: Electricity
A4: Wind elec | B4: Electricity
A5: hydrogen | B5: =A5 -> hydrogen
A6: ELC | B6: Electricity
A7: buildings | B7: =A7 -> buildings
A8: industry | B8: =A8 -> industry
A9: transport | B9: =A9 -> transport
A10: EVs | B10: =A10 -> EVs
A11: fossil | B11: =A11 -> fossil
A12: renewable | B12: =A12 -> renewable
A13: bioenergy | B13: =A13 -> bioenergy
A14: nuclear | B14: =A14 -> nuclear

Sheet CName_MAP
A1: ~CName_Map
A2: CName | B2: Desc | C2: Ldesc
A3: bioenergy | B3: =A3 -> bioenergy
A4: coal | B4: =A4 -> coal
A5: gas | B5: =A5 -> gas
A6: geothermal | B6: =A6 -> geothermal
A7: hydro | B7: =A7 -> hydro
A8: hydrogen | B8: =A8 -> hydrogen
A9: nuclear | B9: =A9 -> nuclear
A10: oil | B10: =A10 -> oil
A11: solar | B11: =A11 -> solar
A12: windon | B12: wind onshore
A13: windoff | B13: wind offshore

Sheet timeslice map
A1: ~Timeslice_Map
A2: dimension | B2: name | C2: description
A3: ts_season | B3: S01* | C3: S01
A4: ts_season | B4: S02* | C4: S02
A5: ts_season | B5: S03* | C5: S03
A6: ts_season | B6: S04* | C6: S04
A7: ts_season | B7: S05* | C7: S05
A8: ts_season | B8: S06* | C8: S06
A9: ts_season | B9: S07* | C9: S07
A10: ts_season | B10: S08* | C10: S08
A11: ts_season | B11: S09* | C11: S09
A12: ts_season | B12: S10* | C12: S10
A13: ts_season | B13: S11* | C13: S11
... A32: ts_type | B32: S??p* | C32: type - p

Sheet geolocation
B9: ~geolocation | F9: ~geolocation
B10: region | C10: lat | D10: lng | F10: region | G10: lat | H10: lng
B11: p_Shanghai_CHN | C11: 31.383619 | D11: 121.40711 | F11: CHN-e_Shanghai_CHN | G11: 31.383619 | H11: 121.40711
B12: p_Shijiazhuang_CHN | C12: 38.244621 | D12: 114.53711 | F12: CHN-e_Shijiazhuang_CHN | G12: 38.244621 | H12: 114.53711
B13: p_Tianjin_CHN | C13: 38.961326 | D13: 117.45745 | F13: CHN-e_Tianjin_CHN | G13: 38.961326 | H13: 117.45745
B14: p_Anshan_CHN | C14: 40.868139 | D14: 122.83437 | F14: CHN-e_Anshan_CHN | G14: 40.868139 | H14: 122.83437
B15: p_Wuhan_CHN | C15: 30.505797 | D15: 114.58426 | F15: CHN-e_Wuhan_CHN | G15: 30.505797 | H15: 114.58426
B16: p_Sanhe_CHN | C16: 40.236864 | D16: 116.73578 | F16: CHN-e_Sanhe_CHN | G16: 40.236864 | H16: 116.73578
B17: p_Harbin_CHN | C17: 45.572049 | D17: 126.51288 | F17: CHN-e_Harbin_CHN | G17: 45.572049 | H17: 126.51288
B18: p_Changzhou_CHN | C18: 31.662907 | D18: 119.9901 | F18: CHN-e_Changzhou_CHN | G18: 31.662907 | H18: 119.9901
B19: p_Anshun_CHN | C19: 26.221368 | D19: 105.84403 | F19: CHN-e_Anshun_CHN | G19: 26.221368 | H19: 105.84403
B20: p_Yiyang_CHN | C20: 28.504248 | D20: 112.27308 | F20: CHN-e_Yiyang_CHN | G20: 28.504248 | H20: 112.27308
B21: p_Yakeshi_CHN | C21: 49.324112 | D21: 119.73373 | F21: CHN-e_Yakeshi_CHN | G21: 49.324112 | H21: 119.73373
B22: p_Linyi_CHN | C22: 35.262325 | D22: 118.31649 | F22: CHN-e_Linyi_CHN | G22: 35.262325 | H22: 118.31649
... B401: s_ogci10272_CHN | C401: 44.459722 | D401: 88.431667 | F401: CHN-co2_Liaoyang_CHN | G401: 41.379437 | H401: 123.34252
F402: CHN-co2_Tangshan_CHN | G402: 39.69802 | H402: 118.56122
F403: CHN-co2_Hejin_CHN | G403: 35.545856 | H403: 110.95747
F404: CHN-co2_CHN44p4N121p8E_CHN | G404: 44.389604 | H404: 121.7668
F405: CHN-co2_Sizhan_CHN | G405: 38.779998 | H405: 106.86916
F406: CHN-co2_Yangzhou_CHN | G406: 32.194015 | H406: 119.24693
F407: CHN-co2_CHN44p2N116p5E_CHN | G407: 44.246248 | H407: 116.50612
F408: CHN-co2_Tongshan_CHN | G408: 34.113939 | H408: 117.36213
F409: CHN-co2_Wuan_CHN | G409: 36.644683 | H409: 113.94414
F410: CHN-co2_Tongling_CHN | G410: 31.125492 | H410: 117.97847
F411: CHN-co2_Anqing_CHN | G411: 30.541789 | H411: 117.16286
F412: CHN-co2s_ogci10202_CHN | G412: 20.826111 | H412: 108.67083
F413: CHN-co2s_ogci10203_CHN | G413: 38.813333 | H413: 119.92333
... F460: CHN-co2s_ogci10272_CHN | G460: 44.459722 | H460: 88.431667

Sheet process_map_geo
B9: ~process_map | F9: ~process_map | J9: ~commodity_map
B10: dimension | C10: description | D10: pset_set | F10: pset_set | G10: dimension | H10: description | J10: dimension | K10: name | L10: description
B11: grid_node | C11: p_Shanghai_CHN | D11: p_Shanghai_CHN | F11: p_Shanghai_CHN | G11: admin_1 | H11: Shanghai | J11: region_com | K11: e_Shanghai_CHN | L11: e_Shanghai_CHN
B12: grid_node | C12: p_Shijiazhuang_CHN | D12: p_Shijiazhuang_CHN | F12: p_Shijiazhuang_CHN | G12: admin_1 | H12: Hebei | J12: region_com | K12: e_Shijiazhuang_CHN | L12: e_Shijiazhuang_CHN
B13: grid_node | C13: p_Tianjin_CHN | D13: p_Tianjin_CHN | F13: p_Tianjin_CHN | G13: admin_1 | H13: Tianjin | J13: region_com | K13: e_Tianjin_CHN | L13: e_Tianjin_CHN
B14: grid_node | C14: p_Anshan_CHN | D14: p_Anshan_CHN | F14: p_Anshan_CHN | G14: admin_1 | H14: Liaoning | J14: region_com | K14: e_Anshan_CHN | L14: e_Anshan_CHN
B15: grid_node | C15: p_Wuhan_CHN | D15: p_Wuhan_CHN | F15: p_Wuhan_CHN | G15: admin_1 | H15: Hubei | J15: region_com | K15: e_Wuhan_CHN | L15: e_Wuhan_CHN
B16: grid_node | C16: p_Sanhe_CHN | D16: p_Sanhe_CHN | F16: p_Sanhe_CHN | G16: admin_1 | H16: Beijing | J16: region_com | K16: e_Sanhe_CHN | L16: e_Sanhe_CHN
B17: grid_node | C17: p_Harbin_CHN | D17: p_Harbin_CHN | F17: p_Harbin_CHN | G17: admin_1 | H17: Heilongjiang | J17: region_com | K17: e_Harbin_CHN | L17: e_Harbin_CHN
B18: grid_node | C18: p_Changzhou_CHN | D18: p_Changzhou_CHN | F18: p_Changzhou_CHN | G18: admin_1 | H18: Jiangsu | J18: region_com | K18: e_Changzhou_CHN | L18: e_Changzhou_CHN
B19: grid_node | C19: p_Anshun_CHN | D19: p_Anshun_CHN | F19: p_Anshun_CHN | G19: admin_1 | H19: Guizhou | J19: region_com | K19: e_Anshun_CHN | L19: e_Anshun_CHN
B20: grid_node | C20: p_Yiyang_CHN | D20: p_Yiyang_CHN | F20: p_Yiyang_CHN | G20: admin_1 | H20: Hunan | J20: region_com | K20: e_Yiyang_CHN | L20: e_Yiyang_CHN
B21: grid_node | C21: p_Yakeshi_CHN | D21: p_Yakeshi_CHN | F21: p_Yakeshi_CHN | G21: admin_1 | H21: Inner Mongol | J21: region_com | K21: e_Yakeshi_CHN | L21: e_Yakeshi_CHN
... B401: grid_node | C401: rez_wof_CHN_034 | D401: rez_wof_CHN_034 | F401: s_ogci10272_CHN | G401: admin_1 | H401: Xinjiang | J401: region_com | K401: co2_Liaoyang_CHN | L401: co2_Liaoyang_CHN
J402: region_com | K402: co2_Tangshan_CHN | L402: co2_Tangshan_CHN
J403: region_com | K403: co2_Hejin_CHN | L403: co2_Hejin_CHN
J404: region_com | K404: co2_CHN44p4N121p8E_CHN | L404: co2_CHN44p4N121p8E_CHN
J405: region_com | K405: co2_Sizhan_CHN | L405: co2_Sizhan_CHN
J406: region_com | K406: co2_Yangzhou_CHN | L406: co2_Yangzhou_CHN
J407: region_com | K407: co2_CHN44p2N116p5E_CHN | L407: co2_CHN44p2N116p5E_CHN
J408: region_com | K408: co2_Tongshan_CHN | L408: co2_Tongshan_CHN
J409: region_com | K409: co2_Wuan_CHN | L409: co2_Wuan_CHN
J410: region_com | K410: co2_Tongling_CHN | L410: co2_Tongling_CHN
J411: region_com | K411: co2_Anqing_CHN | L411: co2_Anqing_CHN
J412: region_com | K412: co2s_ogci10202_CHN | L412: co2s_ogci10202_CHN
J413: region_com | K413: co2s_ogci10203_CHN | L413: co2s_ogci10203_CHN
... J460: region_com | K460: co2s_ogci10272_CHN | L460: co2s_ogci10272_CHN

Sheet process map
A1: ~process_map
A2: dimension | B2: name | C2: description | D2: pset_set | E2: pset_ci | F2: pset_co | G2: pset_pd
A3: old_new | B3: * | C3: new
A4: old_new | B4: ep* | C4: old
A5: Tech | C5: =D5 -> CCGT | D5: CCGT
A6: Tech | C6: =D6 -> OCGT | D6: OCGT
A7: Tech | C7: =D7 -> Gas_Oil_Steam | D7: Gas_Oil_Steam
A8: Tech | C8: =D8 -> Int_Comb | D8: Int_Comb
A9: Tech | C9: =D9 -> Subcrit_Coal | D9: Subcrit_Coal
A10: Tech | C10: =D10 -> Supercrit_Coal | D10: Supercrit_Coal
A11: Tech | C11: =D11 -> IGCC | D11: IGCC
A12: Tech | C12: =D12 -> CHP_Gas | D12: CHP_Gas
A13: Tech | C13: =D13 -> CHP_Coal | D13: CHP_Coal
A14: Tech | C14: =D14 -> CHP_Bio | D14: CHP_Bio
A15: Tech | C15: =D15 -> HOP_Gas | D15: HOP_Gas
A16: Tech | C16: =D16 -> HOP_Bio | D16: HOP_Bio
... A35: Tech | C35: =D35 -> DUMMY_IMP | D35: DUMMY_IMP
A36: Tech | C36: Coal CCS | E36: coal | F36: co2cap*,co2[_]*
A37: Tech | C37: Gas CCS | E37: gas | F37: co2cap*,co2[_]*
A38: Tech | B38: *ccs-rf* | C38: Coal CCS Retrofit | E38: coal
A39: Tech | B39: *ccs-rf* | C39: Gas CCS Retrofit | E39: gas
A40: Tech | B40: ElcAgg_Solar | C40: Solar
A41: Tech | B41: ElcAgg_Wind | C41: Wind
A42: Tech | B42: Trd* | C42: Trade
A43: Sector | B43: * | C43: Power
A44: Sector | B44: e_dem*build* | C44: Buildings
A45: Sector | B45: e_dem*ind* | C45: Industry
A46: Sector | B46: biofuels_*,cement_*,chemicals_*,fertilizer_*,glass_*,lime_*,non_ferrous_*,petchem_*,pulp_paper_*,soda_ash_*,steel_*,wood_* | C46: Industry
A47: Sector | B47: ev_bat* | C47: EV Batt
A48: Sector | B48: H2Prd* | C48: Hydrogen
A49: Tech_by_fuel | C49: =E49 -> bioenergy | E49: bioenergy
A50: Tech_by_fuel | C50: =E50 -> coal | E50: coal
A51: Tech_by_fuel | C51: =E51 -> gas | E51: gas
A52: Tech_by_fuel | C52: =E52 -> hydro | E52: hydro
A53: Tech_by_fuel | C53: =E53 -> nuclear | E53: nuclear
A54: Tech_by_fuel | C54: =E54 -> oil | E54: oil
A55: Tech_by_fuel | C55: =E55 -> solar | E55: solar
A56: Tech_by_fuel | C56: =E56 -> windoff | E56: windoff
A57: Tech_by_fuel | C57: =E57 -> windon | E57: windon
A58: Tech_by_fuel | C58: =E58 -> geothermal | E58: geothermal
...

Sheet commodity map
A1: ~commodity_map
A2: dimension | B2: name | C2: description | D2: cset_set | E2: cset_cd | F2: c_set_andor | G2: c_pos_andor | H2: c_neg_andor

Sheet ATS
A1: ~ATS_final
A2: Tech_by_fuel | B2: Year | C2: Unit | D2: val | E2: scen | F2: varbl | G2: model | H2: region
A3: coal | B3: 2000 | C3: TWh | D3: 1060.26 | E3: History | F3: Elec Production | G3: EMBER | H3: CHN
A4: gas | B4: 2000 | C4: TWh | D4: 5.77 | E4: History | F4: Elec Production | G4: EMBER | H4: CHN
A5: hydro | B5: 2000 | C5: TWh | D5: 222.41 | E5: History | F5: Elec Production | G5: EMBER | H5: CHN
A6: nuclear | B6: 2000 | C6: TWh | D6: 16.74 | E6: History | F6: Elec Production | G6: EMBER | H6: CHN
A7: oil | B7: 2000 | C7: TWh | D7: 47.27 | E7: History | F7: Elec Production | G7: EMBER | H7: CHN
A8: coal | B8: 2001 | C8: TWh | D8: 1129.14 | E8: History | F8: Elec Production | G8: EMBER | H8: CHN
A9: gas | B9: 2001 | C9: TWh | D9: 4.93 | E9: History | F9: Elec Production | G9: EMBER | H9: CHN
A10: hydro | B10: 2001 | C10: TWh | D10: 277.43 | E10: History | F10: Elec Production | G10: EMBER | H10: CHN
A11: nuclear | B11: 2001 | C11: TWh | D11: 17.47 | E11: History | F11: Elec Production | G11: EMBER | H11: CHN
A12: oil | B12: 2001 | C12: TWh | D12: 48.52 | E12: History | F12: Elec Production | G12: EMBER | H12: CHN
A13: coal | B13: 2002 | C13: TWh | D13: 1282.57 | E13: History | F13: Elec Production | G13: EMBER | H13: CHN
A14: gas | B14: 2002 | C14: TWh | D14: 4.19 | E14: History | F14: Elec Production | G14: EMBER | H14: CHN
... A832: Import | B832: 2022 | C832: TWh | D832: 7.1 | E832: History | F832: Elec Production | G832: EMBER | H832: CHN
A833: Export | B833: 2023 | C833: TWh | E833: History | F833: Elec Production | G833: EMBER | H833: CHN
A834: Import | B834: 2023 | C834: TWh | E834: History | F834: Elec Production | G834: EMBER | H834: CHN

Sheet UnitConv
A1: ~UnitConv
A2: Model | B2: Unit1 | C2: Unit2 | D2: MultFact
A3: VS | B3: Twh2GW | C3: GW | D3: =1/8.76 -> 0.11415525
A4: VS | B4: Twh/GW | C4: % | D4: =1/8.76*100 -> 11.415525
A5: VS | B5: kt | C5: mtCO2 | D5: 0.001
A6: VS | B6: ktneg | C6: mtCO2 | D6: -0.001
A7: VS | B7: 000$/t | C7: $/tCO2 | D7: -1000
A8: VS | B8: TWhneg | C8: TWh | D8: -1
