Workbook

Sheet Veda
G1: 1-25,36-60 | H1: 8 | I1: 13 | J1: 18 | K1: 23 | L1: 28 | M1: 33 | N1: 38
D2: ="~Inputcell: "&_xlfn.TEXTJOIN(",",TRUE,G1:EE1) -> ~Inputcell: 1-25,36-60,8,13,18,23,28,33,38
D3: 3
D5: =VLOOKUP(D3,$C$9:$E$999,2,FALSE) -> ts_annual | E5: =VLOOKUP(D3,$C$9:$E$999,3,FALSE) -> C3
B7: ~Scenmap
A8: priority | B8: scen | C8: case_no | D8: timeslice | E8: climate | AM8: bio price multiplier
A9: 5 | B9: =VLOOKUP(E9,$AK$9:$AL$15,2,FALSE)&"."&VLOOKUP(D9,$AH$9:$AI$24,2,FALSE) -> e 1.5 deg no OS.xAnn | C9: 1 | D9: =VLOOKUP(AJ9,$AG$9:$AH$22,2,FALSE) -> ts_annual | E9: C1 | G9: Limit warming to 1.5°C (>50%) with no or limited overshoot | AG9: 1 | AH9: ts_annual | AI9: xAnn | AJ9: 1 | AK9: C1 | AL9: e 1.5 deg no OS | AM9: 5
A10: 5 | B10: =VLOOKUP(E10,$AK$9:$AL$15,2,FALSE)&"."&VLOOKUP(D10,$AH$9:$AI$24,2,FALSE) -> d 1.5 deg OS.xAnn | C10: =C9+1 -> 2 | D10: =VLOOKUP(AJ10,$AG$9:$AH$22,2,FALSE) -> ts_annual | E10: C2 | G10: Limit warming to 1.5°C (>67%) with high overshoot | S10: IEA | AG10: 2 | AH10: ts_12t | AI10: x12 | AJ10: 1 | AK10: C2 | AL10: d 1.5 deg OS | AM10: 4
A11: 5 | B11: =VLOOKUP(E11,$AK$9:$AL$15,2,FALSE)&"."&VLOOKUP(D11,$AH$9:$AI$24,2,FALSE) -> c 2 deg (67%).xAnn | C11: =C10+1 -> 3 | D11: =VLOOKUP(AJ11,$AG$9:$AH$22,2,FALSE) -> ts_annual | E11: C3 | G11: Limit warming to 2°C (>67%) with higher action post-2030 | S11: 2022 | AG11: 3 | AH11: ts_012 | AI11: =AH11 -> ts_012 | AJ11: 1 | AK11: C3 | AL11: c 2 deg (67%) | AM11: 3
A12: 5 | B12: =VLOOKUP(E12,$AK$9:$AL$15,2,FALSE)&"."&VLOOKUP(D12,$AH$9:$AI$24,2,FALSE) -> b 2 deg (50%).xAnn | C12: =C11+1 -> 4 | D12: =VLOOKUP(AJ12,$AG$9:$AH$22,2,FALSE) -> ts_annual | E12: C4 | G12: Limit warming to 2°C (>50%) with immediate action | S12: =SUMIFS(iea_data!I3:I9999,iea_data!$B$3:$B$9999,Veda!$S$11)+T28-T29 -> 155.33 | T12: base-year generation (TWh) | AG12: 4 | AH12: ts_030 | AI12: =AH12 -> ts_030 | AJ12: 1 | AK12: C4 | AL12: b 2 deg (50%) | AM12: 3
A13: 5 | B13: =VLOOKUP(E13,$AK$9:$AL$15,2,FALSE)&"."&VLOOKUP(D13,$AH$9:$AI$24,2,FALSE) -> a 3 deg.xAnn | C13: =C12+1 -> 5 | D13: =VLOOKUP(AJ13,$AG$9:$AH$22,2,FALSE) -> ts_annual | E13: C7 | G13: Likely above 3°C warming with limited mitigation | AG13: 5 | AH13: ts_048 | AI13: =AH13 -> ts_048 | AJ13: 1 | AK13: C7 | AL13: a 3 deg | AM13: 1.5
A14: 5 | B14: =VLOOKUP(E14,$AK$9:$AL$15,2,FALSE)&"."&VLOOKUP(D14,$AH$9:$AI$24,2,FALSE) -> e 1.5 deg no OS.x12 | C14: =C13+1 -> 6 | D14: =VLOOKUP(AJ14,$AG$9:$AH$22,2,FALSE) -> ts_12t | E14: =E9 -> C1 | T14: =S12 -> 155.33 | U14: =$S$12*J15 -> 181.7361 | V14: =$S$12*K15 -> 217.462 | W14: =$S$12*L15 -> 254.7412 | X14: =$S$12*M15 -> 290.4671 | Y14: =$S$12*N15 -> 366.5788 | Z14: =$S$12*O15 -> 450.457 | AG14: 6 | AH14: ts_072 | AI14: =AH14 -> ts_072 | AJ14: =AJ9+1 -> 2
A15: 5 | B15: =VLOOKUP(E15,$AK$9:$AL$15,2,FALSE)&"."&VLOOKUP(D15,$AH$9:$AI$24,2,FALSE) -> d 1.5 deg OS.x12 | C15: =C14+1 -> 7 | D15: =VLOOKUP(AJ15,$AG$9:$AH$22,2,FALSE) -> ts_12t | E15: =E10 -> C2 | G15: Electricity growth relative to 2020 | I15: =SUMIFS(ar6_r10!$F$2:$F$999,ar6_r10!$A$2:$A$999,Veda!$E$5,ar6_r10!$C$2:$C$999,Veda!I$17,ar6_r10!$M$2:$M$999,Veda!$G15) -> 1 | J15: =SUMIFS(ar6_r10!$F$2:$F$999,ar6_r10!$A$2:$A$999,Veda!$E$5,ar6_r10!$C$2:$C$999,Veda!J$17,ar6_r10!$M$2:$M$999,Veda!$G15) -> 1.17 | K15: =SUMIFS(ar6_r10!$F$2:$F$999,ar6_r10!$A$2:$A$999,Veda!$E$5,ar6_r10!$C$2:$C$999,Veda!K$17,ar6_r10!$M$2:$M$999,Veda!$G15) -> 1.4 | L15: =SUMIFS(ar6_r10!$F$2:$F$999,ar6_r10!$A$2:$A$999,Veda!$E$5,ar6_r10!$C$2:$C$999,Veda!L$17,ar6_r10!$M$2:$M$999,Veda!$G15) -> 1.64 | M15: =SUMIFS(ar6_r10!$F$2:$F$999,ar6_r10!$A$2:$A$999,Veda!$E$5,ar6_r10!$C$2:$C$999,Veda!M$17,ar6_r10!$M$2:$M$999,Veda!$G15) -> 1.87 | N15: =SUMIFS(ar6_r10!$F$2:$F$999,ar6_r10!$A$2:$A$999,Veda!$E$5,ar6_r10!$C$2:$C$999,Veda!N$17,ar6_r10!$M$2:$M$999,Veda!$G15) -> 2.36 | O15: =SUMIFS(ar6_r10!$F$2:$F$999,ar6_r10!$A$2:$A$999,Veda!$E$5,ar6_r10!$C$2:$C$999,Veda!O$17,ar6_r10!$M$2:$M$999,Veda!$G15) -> 2.9 | AG15: 7 | AH15: ts_144 | AI15: =AH15 -> ts_144 | AJ15: =AJ10+1 -> 2
A16: 5 | B16: =VLOOKUP(E16,$AK$9:$AL$15,2,FALSE)&"."&VLOOKUP(D16,$AH$9:$AI$24,2,FALSE) -> c 2 deg (67%).x12 | C16: =C15+1 -> 8 | D16: =VLOOKUP(AJ16,$AG$9:$AH$22,2,FALSE) -> ts_12t | E16: =E11 -> C3 | S16: ~TFM_INS-TS | AG16: 8 | AH16: ts_288 | AI16: =AH16 -> ts_288 | AJ16: =AJ11+1 -> 2
A17: 5 | B17: =VLOOKUP(E17,$AK$9:$AL$15,2,FALSE)&"."&VLOOKUP(D17,$AH$9:$AI$24,2,FALSE) -> b 2 deg (50%).x12 | C17: =C16+1 -> 9 | D17: =VLOOKUP(AJ17,$AG$9:$AH$22,2,FALSE) -> ts_12t | E17: =E12 -> C4 | I17: 2020 | J17: =U17 -> 2025 | K17: =V17 -> 2030 | L17: =W17 -> 2035 | M17: =X17 -> 2040 | N17: =Y17 -> 2045 | O17: =Z17 -> 2050 | S17: commodity | T17: 2022 | U17: 2025 | V17: 2030 | W17: 2035 | X17: 2040 | Y17: 2045 | Z17: 2050 | AA17: attribute | AG17: 9 | AH17: s1v1_d | AI17: f2d96 | AJ17: =AJ12+1 -> 2
A18: 5 | B18: =VLOOKUP(E18,$AK$9:$AL$15,2,FALSE)&"."&VLOOKUP(D18,$AH$9:$AI$24,2,FALSE) -> a 3 deg.x12 | C18: =C17+1 -> 10 | D18: =VLOOKUP(AJ18,$AG$9:$AH$22,2,FALSE) -> ts_12t | E18: =E13 -> C7 | G18: Hydrogen as a share of electricity | I18: =SUMIFS(ar6_r10!$F$2:$F$999,ar6_r10!$A$2:$A$999,Veda!$E$5,ar6_r10!$C$2:$C$999,Veda!I$17,ar6_r10!$M$2:$M$999,Veda!$G18) -> 0 | J18: =SUMIFS(ar6_r10!$F$2:$F$999,ar6_r10!$A$2:$A$999,Veda!$E$5,ar6_r10!$C$2:$C$999,Veda!J$17,ar6_r10!$M$2:$M$999,Veda!$G18) -> 0 | K18: =SUMIFS(ar6_r10!$F$2:$F$999,ar6_r10!$A$2:$A$999,Veda!$E$5,ar6_r10!$C$2:$C$999,Veda!K$17,ar6_r10!$M$2:$M$999,Veda!$G18) -> 0 | L18: =SUMIFS(ar6_r10!$F$2:$F$999,ar6_r10!$A$2:$A$999,Veda!$E$5,ar6_r10!$C$2:$C$999,Veda!L$17,ar6_r10!$M$2:$M$999,Veda!$G18) -> 0.02 | M18: =SUMIFS(ar6_r10!$F$2:$F$999,ar6_r10!$A$2:$A$999,Veda!$E$5,ar6_r10!$C$2:$C$999,Veda!M$17,ar6_r10!$M$2:$M$999,Veda!$G18) -> 0.03 | N18: =SUMIFS(ar6_r10!$F$2:$F$999,ar6_r10!$A$2:$A$999,Veda!$E$5,ar6_r10!$C$2:$C$999,Veda!N$17,ar6_r10!$M$2:$M$999,Veda!$G18) -> 0.04 | O18: =SUMIFS(ar6_r10!$F$2:$F$999,ar6_r10!$A$2:$A$999,Veda!$E$5,ar6_r10!$C$2:$C$999,Veda!O$17,ar6_r10!$M$2:$M$999,Veda!$G18) -> 0.06 | S18: hydrogen_allsect | T18: =I18*T$14 -> 0 | U18: =J18*U$14 -> 0 | V18: =K18*V$14 -> 0 | W18: =L18*W$14 -> 5.094824 | X18: =M18*X$14 -> 8.714013 | Y18: =N18*Y$14 -> 14.663152 | Z18: =O18*Z$14 -> 27.02742 | AA18: demand | AG18: 10 | AH18: ts_096 | AI18: e96 | AJ18: =AJ13+1 -> 2
A19: 5 | B19: =VLOOKUP(E19,$AK$9:$AL$15,2,FALSE)&"."&VLOOKUP(D19,$AH$9:$AI$24,2,FALSE) -> e 1.5 deg no OS.ts_012 | C19: =C18+1 -> 11 | D19: =VLOOKUP(AJ19,$AG$9:$AH$22,2,FALSE) -> ts_012 | E19: =E14 -> C1 | G19: Industry electricity share | I19: =SUMIFS(ar6_r10!$F$2:$F$999,ar6_r10!$A$2:$A$999,Veda!$E$5,ar6_r10!$C$2:$C$999,Veda!I$17,ar6_r10!$M$2:$M$999,Veda!$G19) -> 0.25 | J19: =SUMIFS(ar6_r10!$F$2:$F$999,ar6_r10!$A$2:$A$999,Veda!$E$5,ar6_r10!$C$2:$C$999,Veda!J$17,ar6_r10!$M$2:$M$999,Veda!$G19) -> 0.27 | K19: =SUMIFS(ar6_r10!$F$2:$F$999,ar6_r10!$A$2:$A$999,Veda!$E$5,ar6_r10!$C$2:$C$999,Veda!K$17,ar6_r10!$M$2:$M$999,Veda!$G19) -> 0.29 | L19: =SUMIFS(ar6_r10!$F$2:$F$999,ar6_r10!$A$2:$A$999,Veda!$E$5,ar6_r10!$C$2:$C$999,Veda!L$17,ar6_r10!$M$2:$M$999,Veda!$G19) -> 0.3 | M19: =SUMIFS(ar6_r10!$F$2:$F$999,ar6_r10!$A$2:$A$999,Veda!$E$5,ar6_r10!$C$2:$C$999,Veda!M$17,ar6_r10!$M$2:$M$999,Veda!$G19) -> 0.31 | N19: =SUMIFS(ar6_r10!$F$2:$F$999,ar6_r10!$A$2:$A$999,Veda!$E$5,ar6_r10!$C$2:$C$999,Veda!N$17,ar6_r10!$M$2:$M$999,Veda!$G19) -> 0.33 | O19: =SUMIFS(ar6_r10!$F$2:$F$999,ar6_r10!$A$2:$A$999,Veda!$E$5,ar6_r10!$C$2:$C$999,Veda!O$17,ar6_r10!$M$2:$M$999,Veda!$G19) -> 0.33 | S19: elc_industry | T19: =I19*T$14 -> 38.8325 | U19: =J19*U$14 -> 49.068747 | V19: =K19*V$14 -> 63.06398 | W19: =L19*W$14 -> 76.42236 | X19: =M19*X$14 -> 90.044801 | Y19: =N19*Y$14 -> 120.971 | Z19: =O19*Z$14 -> 148.65081 | AA19: demand | AG19: 11 | AH19: s1p1v1_d | AI19: d9d | AJ19: =AJ14+1 -> 3
A20: 5 | B20: =VLOOKUP(E20,$AK$9:$AL$15,2,FALSE)&"."&VLOOKUP(D20,$AH$9:$AI$24,2,FALSE) -> d 1.5 deg OS.ts_012 | C20: =C19+1 -> 12 | D20: =VLOOKUP(AJ20,$AG$9:$AH$22,2,FALSE) -> ts_012 | E20: =E15 -> C2 | G20: Residential and commercial electricity share | I20: =SUMIFS(ar6_r10!$F$2:$F$999,ar6_r10!$A$2:$A$999,Veda!$E$5,ar6_r10!$C$2:$C$999,Veda!I$17,ar6_r10!$M$2:$M$999,Veda!$G20) -> 0.73 | J20: =SUMIFS(ar6_r10!$F$2:$F$999,ar6_r10!$A$2:$A$999,Veda!$E$5,ar6_r10!$C$2:$C$999,Veda!J$17,ar6_r10!$M$2:$M$999,Veda!$G20) -> 0.71 | K20: =SUMIFS(ar6_r10!$F$2:$F$999,ar6_r10!$A$2:$A$999,Veda!$E$5,ar6_r10!$C$2:$C$999,Veda!K$17,ar6_r10!$M$2:$M$999,Veda!$G20) -> 0.69 | L20: =SUMIFS(ar6_r10!$F$2:$F$999,ar6_r10!$A$2:$A$999,Veda!$E$5,ar6_r10!$C$2:$C$999,Veda!L$17,ar6_r10!$M$2:$M$999,Veda!$G20) -> 0.65 | M20: =SUMIFS(ar6_r10!$F$2:$F$999,ar6_r10!$A$2:$A$999,Veda!$E$5,ar6_r10!$C$2:$C$999,Veda!M$17,ar6_r10!$M$2:$M$999,Veda!$G20) -> 0.64 | N20: =SUMIFS(ar6_r10!$F$2:$F$999,ar6_r10!$A$2:$A$999,Veda!$E$5,ar6_r10!$C$2:$C$999,Veda!N$17,ar6_r10!$M$2:$M$999,Veda!$G20) -> 0.59 | O20: =SUMIFS(ar6_r10!$F$2:$F$999,ar6_r10!$A$2:$A$999,Veda!$E$5,ar6_r10!$C$2:$C$999,Veda!O$17,ar6_r10!$M$2:$M$999,Veda!$G20) -> 0.58 | S20: elc_buildings | T20: =I20*T$14 -> 113.3909 | U20: =J20*U$14 -> 129.03263 | V20: =K20*V$14 -> 150.04878 | W20: =L20*W$14 -> 165.58178 | X20: =M20*X$14 -> 185.89894 | Y20: =N20*Y$14 -> 216.28149 | Z20: =O20*Z$14 -> 261.26506 | AA20: demand | AG20: 12 | AH20: s5p5v5_d | AI20: c15d | AJ20: =AJ15+1 -> 3
A21: 5 | B21: =VLOOKUP(E21,$AK$9:$AL$15,2,FALSE)&"."&VLOOKUP(D21,$AH$9:$AI$24,2,FALSE) -> c 2 deg (67%).ts_012 | C21: =C20+1 -> 13 | D21: =VLOOKUP(AJ21,$AG$9:$AH$22,2,FALSE) -> ts_012 | E21: =E16 -> C3 | G21: Transportation electricity share | I21: =SUMIFS(ar6_r10!$F$2:$F$999,ar6_r10!$A$2:$A$999,Veda!$E$5,ar6_r10!$C$2:$C$999,Veda!I$17,ar6_r10!$M$2:$M$999,Veda!$G21) -> 0 | J21: =SUMIFS(ar6_r10!$F$2:$F$999,ar6_r10!$A$2:$A$999,Veda!$E$5,ar6_r10!$C$2:$C$999,Veda!J$17,ar6_r10!$M$2:$M$999,Veda!$G21) -> 0.01 | K21: =SUMIFS(ar6_r10!$F$2:$F$999,ar6_r10!$A$2:$A$999,Veda!$E$5,ar6_r10!$C$2:$C$999,Veda!K$17,ar6_r10!$M$2:$M$999,Veda!$G21) -> 0.01 | L21: =SUMIFS(ar6_r10!$F$2:$F$999,ar6_r10!$A$2:$A$999,Veda!$E$5,ar6_r10!$C$2:$C$999,Veda!L$17,ar6_r10!$M$2:$M$999,Veda!$G21) -> 0.01 | M21: =SUMIFS(ar6_r10!$F$2:$F$999,ar6_r10!$A$2:$A$999,Veda!$E$5,ar6_r10!$C$2:$C$999,Veda!M$17,ar6_r10!$M$2:$M$999,Veda!$G21) -> 0.03 | N21: =SUMIFS(ar6_r10!$F$2:$F$999,ar6_r10!$A$2:$A$999,Veda!$E$5,ar6_r10!$C$2:$C$999,Veda!N$17,ar6_r10!$M$2:$M$999,Veda!$G21) -> 0.05 | O21: =SUMIFS(ar6_r10!$F$2:$F$999,ar6_r10!$A$2:$A$999,Veda!$E$5,ar6_r10!$C$2:$C$999,Veda!O$17,ar6_r10!$M$2:$M$999,Veda!$G21) -> 0.07 | S21: elc_transport | T21: =I21*T$14 -> 0 | U21: =T21 -> 0 | V21: =U21 -> 0 | W21: =V21 -> 0 | X21: =W21 -> 0 | Y21: =X21 -> 0 | Z21: =Y21 -> 0 | AA21: demand | AC21: non-road transport demand assumed to be constant | AJ21: =AJ16+1 -> 3
A22: 5 | B22: =VLOOKUP(E22,$AK$9:$AL$15,2,FALSE)&"."&VLOOKUP(D22,$AH$9:$AI$24,2,FALSE) -> b 2 deg (50%).ts_012 | C22: =C21+1 -> 14 | D22: =VLOOKUP(AJ22,$AG$9:$AH$22,2,FALSE) -> ts_012 | E22: =E17 -> C4 | S22: elc_roadtransport | T22: =T14-SUM(T19:T21) -> 3.1066 | U22: =U14-SUM(U19:U21) -> 3.634722 | V22: =V14-SUM(V19:V21) -> 4.34924 | W22: =W14-SUM(W19:W21) -> 12.73706 | X22: =X14-SUM(X19:X21) -> 14.523355 | Y22: =Y14-SUM(Y19:Y21) -> 29.326304 | Z22: =Z14-SUM(Z19:Z21) -> 40.54113 | AA22: demand | AJ22: =AJ17+1 -> 3
A23: 5 | B23: =VLOOKUP(E23,$AK$9:$AL$15,2,FALSE)&"."&VLOOKUP(D23,$AH$9:$AI$24,2,FALSE) -> a 3 deg.ts_012 | C23: =C22+1 -> 15 | D23: =VLOOKUP(AJ23,$AG$9:$AH$22,2,FALSE) -> ts_012 | E23: =E18 -> C7 | S23: * | AJ23: =AJ18+1 -> 3
A24: 5 | B24: =VLOOKUP(E24,$AK$9:$AL$15,2,FALSE)&"."&VLOOKUP(D24,$AH$9:$AI$24,2,FALSE) -> e 1.5 deg no OS.ts_030 | C24: =C23+1 -> 16 | D24: =VLOOKUP(AJ24,$AG$9:$AH$22,2,FALSE) -> ts_030 | E24: =E19 -> C1 | G24: CO2 price | I24: 0 | J24: 0 | K24: =SUMIFS(ar6_r10!$F$2:$F$999,ar6_r10!$A$2:$A$999,Veda!$E$5,ar6_r10!$C$2:$C$999,Veda!K$17,ar6_r10!$M$2:$M$999,Veda!$G24) -> 49.21 | L24: =SUMIFS(ar6_r10!$F$2:$F$999,ar6_r10!$A$2:$A$999,Veda!$E$5,ar6_r10!$C$2:$C$999,Veda!L$17,ar6_r10!$M$2:$M$999,Veda!$G24) -> 100.47 | M24: =SUMIFS(ar6_r10!$F$2:$F$999,ar6_r10!$A$2:$A$999,Veda!$E$5,ar6_r10!$C$2:$C$999,Veda!M$17,ar6_r10!$M$2:$M$999,Veda!$G24) -> 127.66 | N24: =SUMIFS(ar6_r10!$F$2:$F$999,ar6_r10!$A$2:$A$999,Veda!$E$5,ar6_r10!$C$2:$C$999,Veda!N$17,ar6_r10!$M$2:$M$999,Veda!$G24) -> 171.28 | O24: =SUMIFS(ar6_r10!$F$2:$F$999,ar6_r10!$A$2:$A$999,Veda!$E$5,ar6_r10!$C$2:$C$999,Veda!O$17,ar6_r10!$M$2:$M$999,Veda!$G24) -> 208.73 | S24: co2net | U24: 0 | V24: =K24/1000 -> 0.04921 | W24: =L24/1000 -> 0.10047 | X24: =M24/1000 -> 0.12766 | Y24: =N24/1000 -> 0.17128 | Z24: =O24/1000 -> 0.20873 | AA24: com_taxnet | AJ24: =AJ19+1 -> 4
A25: 5 | B25: =VLOOKUP(E25,$AK$9:$AL$15,2,FALSE)&"."&VLOOKUP(D25,$AH$9:$AI$24,2,FALSE) -> d 1.5 deg OS.ts_030 | C25: =C24+1 -> 17 | D25: =VLOOKUP(AJ25,$AG$9:$AH$22,2,FALSE) -> ts_030 | E25: =E20 -> C2 | AJ25: =AJ20+1 -> 4
A26: 5 | B26: =VLOOKUP(E26,$AK$9:$AL$15,2,FALSE)&"."&VLOOKUP(D26,$AH$9:$AI$24,2,FALSE) -> c 2 deg (67%).ts_030 | C26: =C25+1 -> 18 | D26: =VLOOKUP(AJ26,$AG$9:$AH$22,2,FALSE) -> ts_030 | E26: =E21 -> C3 | S26: ~TFM_INS-TS | AJ26: =AJ21+1 -> 4
A27: 5 | B27: =VLOOKUP(E27,$AK$9:$AL$15,2,FALSE)&"."&VLOOKUP(D27,$AH$9:$AI$24,2,FALSE) -> b 2 deg (50%).ts_030 | C27: =C26+1 -> 19 | D27: =VLOOKUP(AJ27,$AG$9:$AH$22,2,FALSE) -> ts_030 | E27: =E22 -> C4 | S27: process | T27: =T17 -> 2022 | U27: =U17 -> 2025 | V27: =V17 -> 2030 | W27: =W17 -> 2035 | X27: =X17 -> 2040 | Y27: =Y17 -> 2045 | Z27: =Z17 -> 2050 | AA27: attribute | AB27: limtype | AJ27: =AJ22+1 -> 4
A28: 5 | B28: =VLOOKUP(E28,$AK$9:$AL$15,2,FALSE)&"."&VLOOKUP(D28,$AH$9:$AI$24,2,FALSE) -> a 3 deg.ts_030 | C28: =C27+1 -> 20 | D28: =VLOOKUP(AJ28,$AG$9:$AH$22,2,FALSE) -> ts_030 | E28: =E23 -> C7 | Q28: =SUMIFS(iea_data!G3:G9999,iea_data!$B$3:$B$9999,Veda!$S$11) -> 0.5 | S28: Trd_electricity import | T28: =Q28 -> 0.5 | AA28: ACT_BND | AB28: FX | AJ28: =AJ23+1 -> 4
A29: 5 | B29: =VLOOKUP(E29,$AK$9:$AL$15,2,FALSE)&"."&VLOOKUP(D29,$AH$9:$AI$24,2,FALSE) -> e 1.5 deg no OS.ts_048 | C29: =C28+1 -> 21 | D29: =VLOOKUP(AJ29,$AG$9:$AH$22,2,FALSE) -> ts_048 | E29: =E24 -> C1 | Q29: =SUMIFS(iea_data!H3:H9999,iea_data!$B$3:$B$9999,Veda!$S$11) -> -0.61 | S29: Trd_electricity export | T29: =-1*Q29 -> 0.61 | AA29: ACT_BND | AB29: FX | AJ29: =AJ24+1 -> 5
A30: 5 | B30: =VLOOKUP(E30,$AK$9:$AL$15,2,FALSE)&"."&VLOOKUP(D30,$AH$9:$AI$24,2,FALSE) -> d 1.5 deg OS.ts_048 | C30: =C29+1 -> 22 | D30: =VLOOKUP(AJ30,$AG$9:$AH$22,2,FALSE) -> ts_048 | E30: =E25 -> C2 | AJ30: =AJ25+1 -> 5
A31: 5 | B31: =VLOOKUP(E31,$AK$9:$AL$15,2,FALSE)&"."&VLOOKUP(D31,$AH$9:$AI$24,2,FALSE) -> c 2 deg (67%).ts_048 | C31: =C30+1 -> 23 | D31: =VLOOKUP(AJ31,$AG$9:$AH$22,2,FALSE) -> ts_048 | E31: =E26 -> C3 | AJ31: =AJ26+1 -> 5
A32: 5 | B32: =VLOOKUP(E32,$AK$9:$AL$15,2,FALSE)&"."&VLOOKUP(D32,$AH$9:$AI$24,2,FALSE) -> b 2 deg (50%).ts_048 | C32: =C31+1 -> 24 | D32: =VLOOKUP(AJ32,$AG$9:$AH$22,2,FALSE) -> ts_048 | E32: =E27 -> C4 | AJ32: =AJ27+1 -> 5
A33: 5 | B33: =VLOOKUP(E33,$AK$9:$AL$15,2,FALSE)&"."&VLOOKUP(D33,$AH$9:$AI$24,2,FALSE) -> a 3 deg.ts_048 | C33: =C32+1 -> 25 | D33: =VLOOKUP(AJ33,$AG$9:$AH$22,2,FALSE) -> ts_048 | E33: =E28 -> C7 | AJ33: =AJ28+1 -> 5
A34: 5 | B34: =VLOOKUP(E34,$AK$9:$AL$15,2,FALSE)&"."&VLOOKUP(D34,$AH$9:$AI$24,2,FALSE) -> e 1.5 deg no OS.ts_072 | C34: =C33+1 -> 26 | D34: =VLOOKUP(AJ34,$AG$9:$AH$22,2,FALSE) -> ts_072 | E34: =E29 -> C1 | AJ34: =AJ29+1 -> 6
A35: 5 | B35: =VLOOKUP(E35,$AK$9:$AL$15,2,FALSE)&"."&VLOOKUP(D35,$AH$9:$AI$24,2,FALSE) -> d 1.5 deg OS.ts_072 | C35: =C34+1 -> 27 | D35: =VLOOKUP(AJ35,$AG$9:$AH$22,2,FALSE) -> ts_072 | E35: =E30 -> C2 | AJ35: =AJ30+1 -> 6
A36: 5 | B36: =VLOOKUP(E36,$AK$9:$AL$15,2,FALSE)&"."&VLOOKUP(D36,$AH$9:$AI$24,2,FALSE) -> c 2 deg (67%).ts_072 | C36: =C35+1 -> 28 | D36: =VLOOKUP(AJ36,$AG$9:$AH$22,2,FALSE) -> ts_072 | E36: =E31 -> C3 | G36: C7 | AJ36: =AJ31+1 -> 6
A37: 5 | B37: =VLOOKUP(E37,$AK$9:$AL$15,2,FALSE)&"."&VLOOKUP(D37,$AH$9:$AI$24,2,FALSE) -> b 2 deg (50%).ts_072 | C37: =C36+1 -> 29 | D37: =VLOOKUP(AJ37,$AG$9:$AH$22,2,FALSE) -> ts_072 | E37: =E32 -> C4 | G37: Gas Price | I37: =SUMIFS(ar6_r10!$F$2:$F$999,ar6_r10!$A$2:$A$999,Veda!$G$36,ar6_r10!$C$2:$C$999,Veda!I$17,ar6_r10!$M$2:$M$999,Veda!$G37) -> 1 | J37: =SUMIFS(ar6_r10!$F$2:$F$999,ar6_r10!$A$2:$A$999,Veda!$G$36,ar6_r10!$C$2:$C$999,Veda!J$17,ar6_r10!$M$2:$M$999,Veda!$G37) -> 1.15 | K37: =SUMIFS(ar6_r10!$F$2:$F$999,ar6_r10!$A$2:$A$999,Veda!$G$36,ar6_r10!$C$2:$C$999,Veda!K$17,ar6_r10!$M$2:$M$999,Veda!$G37) -> 1.28 | L37: =SUMIFS(ar6_r10!$F$2:$F$999,ar6_r10!$A$2:$A$999,Veda!$G$36,ar6_r10!$C$2:$C$999,Veda!L$17,ar6_r10!$M$2:$M$999,Veda!$G37) -> 1.22 | M37: =SUMIFS(ar6_r10!$F$2:$F$999,ar6_r10!$A$2:$A$999,Veda!$G$36,ar6_r10!$C$2:$C$999,Veda!M$17,ar6_r10!$M$2:$M$999,Veda!$G37) -> 1.41 | N37: =SUMIFS(ar6_r10!$F$2:$F$999,ar6_r10!$A$2:$A$999,Veda!$G$36,ar6_r10!$C$2:$C$999,Veda!N$17,ar6_r10!$M$2:$M$999,Veda!$G37) -> 1.47 | O37: =SUMIFS(ar6_r10!$F$2:$F$999,ar6_r10!$A$2:$A$999,Veda!$G$36,ar6_r10!$C$2:$C$999,Veda!O$17,ar6_r10!$M$2:$M$999,Veda!$G37) -> 1.59 | AJ37: =AJ32+1 -> 6
A38: 5 | B38: =VLOOKUP(E38,$AK$9:$AL$15,2,FALSE)&"."&VLOOKUP(D38,$AH$9:$AI$24,2,FALSE) -> a 3 deg.ts_072 | C38: =C37+1 -> 30 | D38: =VLOOKUP(AJ38,$AG$9:$AH$22,2,FALSE) -> ts_072 | E38: =E33 -> C7 | G38: Coal Price | I38: =SUMIFS(ar6_r10!$F$2:$F$999,ar6_r10!$A$2:$A$999,Veda!$G$36,ar6_r10!$C$2:$C$999,Veda!I$17,ar6_r10!$M$2:$M$999,Veda!$G38) -> 1 | J38: =SUMIFS(ar6_r10!$F$2:$F$999,ar6_r10!$A$2:$A$999,Veda!$G$36,ar6_r10!$C$2:$C$999,Veda!J$17,ar6_r10!$M$2:$M$999,Veda!$G38) -> 1.02 | K38: =SUMIFS(ar6_r10!$F$2:$F$999,ar6_r10!$A$2:$A$999,Veda!$G$36,ar6_r10!$C$2:$C$999,Veda!K$17,ar6_r10!$M$2:$M$999,Veda!$G38) -> 1.06 | L38: =SUMIFS(ar6_r10!$F$2:$F$999,ar6_r10!$A$2:$A$999,Veda!$G$36,ar6_r10!$C$2:$C$999,Veda!L$17,ar6_r10!$M$2:$M$999,Veda!$G38) -> 1.08 | M38: =SUMIFS(ar6_r10!$F$2:$F$999,ar6_r10!$A$2:$A$999,Veda!$G$36,ar6_r10!$C$2:$C$999,Veda!M$17,ar6_r10!$M$2:$M$999,Veda!$G38) -> 1.17 | N38: =SUMIFS(ar6_r10!$F$2:$F$999,ar6_r10!$A$2:$A$999,Veda!$G$36,ar6_r10!$C$2:$C$999,Veda!N$17,ar6_r10!$M$2:$M$999,Veda!$G38) -> 1.21 | O38: =SUMIFS(ar6_r10!$F$2:$F$999,ar6_r10!$A$2:$A$999,Veda!$G$36,ar6_r10!$C$2:$C$999,Veda!O$17,ar6_r10!$M$2:$M$999,Veda!$G38) -> 1.26 | AJ38: =AJ33+1 -> 6
A39: 5 | B39: =VLOOKUP(E39,$AK$9:$AL$15,2,FALSE)&"."&VLOOKUP(D39,$AH$9:$AI$24,2,FALSE) -> e 1.5 deg no OS.ts_144 | C39: =C38+1 -> 31 | D39: =VLOOKUP(AJ39,$AG$9:$AH$22,2,FALSE) -> ts_144 | E39: =E34 -> C1 | G39: Oil Price | I39: =SUMIFS(ar6_r10!$F$2:$F$999,ar6_r10!$A$2:$A$999,Veda!$G$36,ar6_r10!$C$2:$C$999,Veda!I$17,ar6_r10!$M$2:$M$999,Veda!$G39) -> 1 | J39: =SUMIFS(ar6_r10!$F$2:$F$999,ar6_r10!$A$2:$A$999,Veda!$G$36,ar6_r10!$C$2:$C$999,Veda!J$17,ar6_r10!$M$2:$M$999,Veda!$G39) -> 0.97 | K39: =SUMIFS(ar6_r10!$F$2:$F$999,ar6_r10!$A$2:$A$999,Veda!$G$36,ar6_r10!$C$2:$C$999,Veda!K$17,ar6_r10!$M$2:$M$999,Veda!$G39) -> 1.28 | L39: =SUMIFS(ar6_r10!$F$2:$F$999,ar6_r10!$A$2:$A$999,Veda!$G$36,ar6_r10!$C$2:$C$999,Veda!L$17,ar6_r10!$M$2:$M$999,Veda!$G39) -> 1.09 | M39: =SUMIFS(ar6_r10!$F$2:$F$999,ar6_r10!$A$2:$A$999,Veda!$G$36,ar6_r10!$C$2:$C$999,Veda!M$17,ar6_r10!$M$2:$M$999,Veda!$G39) -> 1.39 | N39: =SUMIFS(ar6_r10!$F$2:$F$999,ar6_r10!$A$2:$A$999,Veda!$G$36,ar6_r10!$C$2:$C$999,Veda!N$17,ar6_r10!$M$2:$M$999,Veda!$G39) -> 1.53 | O39: =SUMIFS(ar6_r10!$F$2:$F$999,ar6_r10!$A$2:$A$999,Veda!$G$36,ar6_r10!$C$2:$C$999,Veda!O$17,ar6_r10!$M$2:$M$999,Veda!$G39) -> 1.73 | AJ39: =AJ34+1 -> 7
A40: 5 | B40: =VLOOKUP(E40,$AK$9:$AL$15,2,FALSE)&"."&VLOOKUP(D40,$AH$9:$AI$24,2,FALSE) -> d 1.5 deg OS.ts_144 | C40: =C39+1 -> 32 | D40: =VLOOKUP(AJ40,$AG$9:$AH$22,2,FALSE) -> ts_144 | E40: =E35 -> C2 | G40: Biomass Price | I40: =SUMIFS(ar6_r10!$F$2:$F$999,ar6_r10!$A$2:$A$999,Veda!$G$36,ar6_r10!$C$2:$C$999,Veda!I$17,ar6_r10!$M$2:$M$999,Veda!$G40) -> 1 | J40: =SUMIFS(ar6_r10!$F$2:$F$999,ar6_r10!$A$2:$A$999,Veda!$G$36,ar6_r10!$C$2:$C$999,Veda!J$17,ar6_r10!$M$2:$M$999,Veda!$G40) -> 1.05 | K40: =SUMIFS(ar6_r10!$F$2:$F$999,ar6_r10!$A$2:$A$999,Veda!$G$36,ar6_r10!$C$2:$C$999,Veda!K$17,ar6_r10!$M$2:$M$999,Veda!$G40) -> 1.1 | L40: =SUMIFS(ar6_r10!$F$2:$F$999,ar6_r10!$A$2:$A$999,Veda!$G$36,ar6_r10!$C$2:$C$999,Veda!L$17,ar6_r10!$M$2:$M$999,Veda!$G40) -> 1.16 | M40: =SUMIFS(ar6_r10!$F$2:$F$999,ar6_r10!$A$2:$A$999,Veda!$G$36,ar6_r10!$C$2:$C$999,Veda!M$17,ar6_r10!$M$2:$M$999,Veda!$G40) -> 1.17 | N40: =SUMIFS(ar6_r10!$F$2:$F$999,ar6_r10!$A$2:$A$999,Veda!$G$36,ar6_r10!$C$2:$C$999,Veda!N$17,ar6_r10!$M$2:$M$999,Veda!$G40) -> 1.16 | O40: =SUMIFS(ar6_r10!$F$2:$F$999,ar6_r10!$A$2:$A$999,Veda!$G$36,ar6_r10!$C$2:$C$999,Veda!O$17,ar6_r10!$M$2:$M$999,Veda!$G40) -> 1.17 | AJ40: =AJ35+1 -> 7
A41: 5 | B41: =VLOOKUP(E41,$AK$9:$AL$15,2,FALSE)&"."&VLOOKUP(D41,$AH$9:$AI$24,2,FALSE) -> c 2 deg (67%).ts_144 | C41: =C40+1 -> 33 | D41: =VLOOKUP(AJ41,$AG$9:$AH$22,2,FALSE) -> ts_144 | E41: =E36 -> C3 | AJ41: =AJ36+1 -> 7
A42: 5 | B42: =VLOOKUP(E42,$AK$9:$AL$15,2,FALSE)&"."&VLOOKUP(D42,$AH$9:$AI$24,2,FALSE) -> b 2 deg (50%).ts_144 | C42: =C41+1 -> 34 | D42: =VLOOKUP(AJ42,$AG$9:$AH$22,2,FALSE) -> ts_144 | E42: =E37 -> C4 | AJ42: =AJ37+1 -> 7
...

Sheet fuel_prices
A9: Fuel Prices
A10: iso | B10: gas_low | C10: gas_high | D10: coal_low | E10: coal_high | F10: oil_low | G10: oil_high | H10: bioenergy_low | I10: bioenergy_high | J10: Notes
A11: ARE | B11: 6.9 | C11: 13.7 | D11: 15.2 | E11: 19.8 | F11: 35 | G11: 45 | H11: 99 | I11: 99 | J11: Abundant gas, minimal biomass

Sheet iea_data
A9: IEA Baseline Data
A10: iso | B10: year | C10: industry_twh | D10: buildings_agri_twh | E10: nonroad_transport_twh | F10: road_transport_twh | G10: imports_twh | H10: exports_twh | I10: total_production_twh
A11: ARE | B11: 2000 | C11: 9.3 | D11: 30.16 | E11: 0 | F11: 0 | G11: 0 | H11: 0 | I11: 39.94
A12: ARE | B12: 2001 | C12: 10.04 | D12: 32.6 | E12: 0 | F12: 0 | G12: 0 | H12: 0 | I12: 43.17
A13: ARE | B13: 2002 | C13: 10.89 | D13: 35.38 | E13: 0 | F13: 0 | G13: 0 | H13: 0 | I13: 46.86
A14: ARE | B14: 2003 | C14: 11.56 | D14: 37.34 | E14: 0 | F14: 0 | G14: 0 | H14: 0 | I14: 49.45
A15: ARE | B15: 2004 | C15: 12.24 | D15: 39.58 | E15: 0 | F15: 0 | G15: 0 | H15: 0 | I15: 52.42
A16: ARE | B16: 2005 | C16: 13.94 | D16: 45.84 | E16: 0 | F16: 0 | G16: 0 | H16: 0 | I16: 60.7
A17: ARE | B17: 2006 | C17: 15.48 | D17: 50.42 | E17: 0 | F17: 0 | G17: 0 | H17: 0 | I17: 66.77
A18: ARE | B18: 2007 | C18: 18.02 | D18: 59.48 | E18: 0 | F18: 0 | G18: 0 | H18: 0 | I18: 78.76
A19: ARE | B19: 2008 | C19: 18.41 | D19: 60.9 | E19: 0 | F19: 0 | G19: 0 | H19: 0 | I19: 80.46
A20: ARE | B20: 2009 | C20: 19.61 | D20: 64.73 | E20: 0 | F20: 0 | G20: 0 | H20: 0 | I20: 85.7
A21: ARE | B21: 2010 | C21: 21.5 | D21: 70.59 | E21: 0 | F21: 0 | G21: 0 | H21: 0 | I21: 93.95
A22: ARE | B22: 2011 | C22: 22.68 | D22: 74.3 | E22: 0 | F22: 0 | G22: 0.02 | H22: -0.04 | I22: 99.14
... A33: ARE | B33: 2022 | C33: 38.34 | D33: 115.34 | E33: 0 | F33: 0 | G33: 0.5 | H33: -0.61 | I33: 155.44

Sheet ar6_r10
A9: AR6 Scenario Drivers
A10: Category | B10: Region | C10: Year | D10: count | E10: mean | F10: median | G10: std | H10: min | I10: max | J10: q25 | K10: q75 | L10: category_description | M10: attribute
A11: C1 | B11: R10MIDDLE_EAST | C11: 2020 | D11: 60 | E11: 2.9 | F11: 0.74 | G11: 3.32 | H11: 0 | I11: 15.11 | J11: 0 | K11: 5.64 | L11: Limit warming to 1.5°C (>50%) with no or limited overshoot | M11: CO2 price
A12: C1 | B12: R10MIDDLE_EAST | C12: 2025 | D12: 60 | E12: 153.67 | F12: 131.07 | G12: 125.79 | H12: 0 | I12: 626.48 | J12: 101.54 | K12: 190.02 | L12: Limit warming to 1.5°C (>50%) with no or limited overshoot | M12: CO2 price
A13: C1 | B13: R10MIDDLE_EAST | C13: 2030 | D13: 60 | E13: 220.76 | F13: 197.09 | G13: 111.16 | H13: 0 | I13: 673.46 | J13: 164.67 | K13: 241.99 | L13: Limit warming to 1.5°C (>50%) with no or limited overshoot | M13: CO2 price
A14: C1 | B14: R10MIDDLE_EAST | C14: 2035 | D14: 60 | E14: 310.56 | F14: 256.63 | G14: 147.59 | H14: 92.6 | I14: 859.53 | J14: 220.16 | K14: 396.19 | L14: Limit warming to 1.5°C (>50%) with no or limited overshoot | M14: CO2 price
A15: C1 | B15: R10MIDDLE_EAST | C15: 2040 | D15: 60 | E15: 420.22 | F15: 335.79 | G15: 205.86 | H15: 162.1 | I15: 1097.01 | J15: 287.98 | K15: 560.56 | L15: Limit warming to 1.5°C (>50%) with no or limited overshoot | M15: CO2 price
A16: C1 | B16: R10MIDDLE_EAST | C16: 2045 | D16: 60 | E16: 529.59 | F16: 460.87 | G16: 243.64 | H16: 193.42 | I16: 1269.88 | J16: 355.81 | K16: 713.93 | L16: Limit warming to 1.5°C (>50%) with no or limited overshoot | M16: CO2 price
A17: C1 | B17: R10MIDDLE_EAST | C17: 2050 | D17: 60 | E17: 625.34 | F17: 581.75 | G17: 256.99 | H17: 209.76 | I17: 1170.26 | J17: 412.98 | K17: 771.78 | L17: Limit warming to 1.5°C (>50%) with no or limited overshoot | M17: CO2 price
A18: C2 | B18: R10MIDDLE_EAST | C18: 2020 | D18: 86 | E18: 3.36 | F18: 0.55 | G18: 5.17 | H18: 0 | I18: 15.11 | J18: 0 | K18: 5.35 | L18: Limit warming to 1.5°C (>67%) with high overshoot | M18: CO2 price
A19: C2 | B19: R10MIDDLE_EAST | C19: 2025 | D19: 75 | E19: 37.47 | F19: 21.41 | G19: 46.36 | H19: 0 | I19: 174.97 | J19: 1.26 | K19: 55.72 | L19: Limit warming to 1.5°C (>67%) with high overshoot | M19: CO2 price
A20: C2 | B20: R10MIDDLE_EAST | C20: 2030 | D20: 86 | E20: 52.47 | F20: 41.97 | G20: 54.93 | H20: 0 | I20: 221.93 | J20: 1.28 | K20: 77.17 | L20: Limit warming to 1.5°C (>67%) with high overshoot | M20: CO2 price
A21: C2 | B21: R10MIDDLE_EAST | C21: 2035 | D21: 75 | E21: 208.06 | F21: 129.57 | G21: 312.6 | H21: 54.48 | I21: 2037.12 | J21: 87.35 | K21: 202.85 | L21: Limit warming to 1.5°C (>67%) with high overshoot | M21: CO2 price
A22: C2 | B22: R10MIDDLE_EAST | C22: 2040 | D22: 86 | E22: 247.16 | F22: 165.64 | G22: 360.3 | H22: 0 | I22: 2600 | J22: 108.54 | K22: 257.75 | L22: Limit warming to 1.5°C (>67%) with high overshoot | M22: CO2 price
... A360: C7 | B360: R10MIDDLE_EAST | C360: 2050 | D360: 7 | E360: 1.15 | F360: 1.17 | G360: 0.19 | H360: 0.9 | I360: 1.35 | J360: 1.03 | K360: 1.29 | L360: Likely above 3°C warming with limited mitigation | M360: Biomass price

Sheet ev_charging_uc
A10: =IFERROR(Veda!D5,"ts_12t") -> ts_annual | C10: day_night | D10: ts_012 | F10: day_night | G10: ts_030 | I10: day_night | J10: ts_048 | L10: day_night | M10: ts_072 | O10: day_night | P10: ts_144 | R10: day_night | S10: ts_288 | U10: day_night | V10: ts_072P10 | X10: day_night | Y10: ts_072P90 | AA10: day_night | AB10: ts_annual | AD10: day_night | AE10: ts_12t
C11: D | D11: S04aH02,S02aH02,S01aH02,S03aH02 | F11: D | G11: S03aH04,S04aH02,S03aH03,S05aH04,S02aH02,S04aH03,S02aH03,S01aH03,S05aH02,S05aH03,S02aH04,S01aH04,S01aH02,S04aH04,S03aH02 | I11: D | J11: S04aH03,S03aH05,S05aH05,S06aH04,S01aH04,S02aH04,S02aH05,S03aH03,S02aH03,S01aH05,S06aH05,S04aH02,S02aH02,S05aH04,S06aH02,S06aH03,S01aH03,S05aH02,S05aH03,S04aH05,S03aH02,S03aH04,S01aH02,S04aH04 | L11: D | M11: S05aH04,S06aH02,S06aH03,S10aH04,S02aH04,S02aH05,S10aH03,S10aH05,S04aH05,S03aH03,S09aH05,S01aH03,S05aH02,S05aH03,S01aH02,S04aH04,S03aH04,S08aH05,S02aH02,S04aH02,S09aH02,S09aH03,S04aH03,S07aH04,S08aH03,S09aH04,S02aH03,S07aH03,S01aH04,S07aH02,S08aH02,S03aH02,S07aH05,S01aH05,S06aH05,S10aH02,S03aH05,S05aH05,S06aH04,S08aH04 | O11: D | P11: S04aH03,S07aH04,S08aH03,S09aH04,S12aH02,S16aH03,S02aH03,S07aH03,S02aH04,S02aH05,S10aH03,S10aH05,S16aH05,S01aH02,S04aH04,S16aH02,S03aH02,S07aH05,S14aH02,S03aH05,S05aH05,S06aH04,S08aH04,S11aH02,S13aH02,S13aH03,S04aH02,S09aH02,S09aH03,S11aH03,S11aH04,S14aH03,S15aH03,S01aH03,S05aH02,S05aH03,S04aH05,S13aH04,S05aH04,S06aH02,S06aH03,S10aH04,S16aH04,S02aH02,S14aH04,S14aH05,S15aH05,S08aH02,S03aH03,S09aH05,S13aH05,S15aH02,S01aH05,S06aH05,S10aH02,S12aH04,S12aH05,S15aH04,S03aH04,S08aH05,S11aH05,S12aH03,S01aH04,S07aH02 | R11: D | S11: S01aH03,S05aH02,S05aH03,S05aH06,S16aH07,S17aH04,S03aH02,S07aH05,S14aH02,S18aH07,S19aH05,S01aH06,S02aH03,S05aH07,S07aH03,S08aH06,S10aH07,S01aH04,S01aH07,S02aH07,S07aH02,S07aH06,S13aH07,S18aH02,S18aH06,S03aH04,S08aH05,S09aH07,S11aH05,S12aH03,S20aH04,S20aH05,S01aH02,S04aH04,S15aH07,S16aH02,S16aH06,S17aH03,S17aH06,S20aH06,S02aH06,S03aH05,S04aH07,S05aH05,S06aH04,S08aH04,S11aH02,S13aH02,S13aH03,S18aH04,S19aH07,S04aH02,S08aH07,S09aH02,S09aH03,S11aH03,S11aH04,S14aH03,S15aH03,S18aH03,S19aH02,S19aH03,S04aH03,S07aH04,S08aH03,S09aH04,S11aH07,S12aH02,S14aH06,S16aH03,S20aH07,S08aH02,S09aH06,S14aH07,S17aH07,S19aH04,S19aH06,S02aH02,S06aH06,S14aH04,S14aH05,S15aH05,S18aH05,S03aH03,S09aH05,S12aH07,S13aH05,S15aH02,S20aH02,S04aH05,S13aH04,S01aH05,S03aH06,S03aH07,S06aH05,S10aH02,S10aH06,S11aH06,S12aH04,S12aH05,S15aH04,S02aH04,S02aH05,S06aH07,S07aH07,S10aH03,S10aH05,S16aH05,S20aH03,S04aH06,S05aH04,S06aH02,S06aH03,S10aH04,S12aH06,S13aH06,S15aH06,S16aH04,S17aH02,S17aH05 | U11: D | V11: S02aH03,S07aH03,S01aH02,S04aH04,S08aH02,S01aH03,S05aH02,S05aH03,S03aH03,S09aH05,S02aH02,S05aH04,S06aH02,S06aH03,S10aH04,S02aH04,S02aH05,S10aH03,S10aH05,S03aH02,S07aH05,S04aH03,S07aH04,S08aH03,S09aH04,S03aH05,S05aH05,S06aH04,S08aH04,S04aH05,S03aH04,S08aH05,S01aH05,S06aH05,S10aH02,S01aH04,S07aH02,S04aH02,S09aH02,S09aH03 | X11: D | Y11: S01aH03,S05aH02,S05aH03,S03aH02,S07aH05,S01aH05,S06aH05,S10aH02,S04aH03,S07aH04,S08aH03,S09aH04,S04aH05,S02aH04,S02aH05,S10aH03,S10aH05,S08aH02,S05aH04,S06aH02,S06aH03,S10aH04,S02aH03,S07aH03,S03aH05,S05aH05,S06aH04,S08aH04,S04aH02,S09aH02,S09aH03,S03aH03,S09aH05,S01aH02,S04aH04,S01aH04,S07aH02,S02aH02,S03aH04,S08aH05 | AA11: D | AB11: AllSaAllH | AD11: D | AE11: SaD,FaD,RaP,WaD,FaP,SaP,RaD,WaP
C12: N | D12: S01aH01,S04aH01,S03aH01,S03aH03,S01aH03,S02aH01,S04aH03,S02aH03 | F12: N | G12: S05aH01,S02aH05,S03aH01,S02aH01,S01aH01,S04aH01,S03aH05,S05aH05,S04aH05,S01aH05 | I12: N | J12: S02aH01,S05aH06,S02aH06,S06aH01,S06aH06,S01aH01,S04aH01,S04aH06,S03aH01,S01aH06,S05aH01,S03aH06 | L12: N | M12: S01aH06,S07aH01,S08aH06,S02aH06,S09aH06,S06aH06,S09aH01,S03aH06,S10aH06,S05aH01,S07aH06,S03aH01,S02aH01,S05aH06,S01aH01,S04aH01,S04aH06,S08aH01,S10aH01,S06aH01 | O12: N | P12: S02aH01,S05aH06,S01aH01,S04aH01,S04aH06,S11aH01,S12aH06,S13aH06,S15aH06,S02aH06,S12aH01,S03aH06,S10aH06,S11aH06,S15aH01,S16aH01,S09aH01,S13aH01,S14aH06,S09aH06,S01aH06,S07aH01,S08aH06,S03aH01,S06aH01,S14aH01,S06aH06,S16aH06,S05aH01,S07aH06,S08aH01,S10aH01 | R12: N | S12: S09aH01,S13aH01,S16aH08,S18aH08,S15aH01,S16aH01,S20aH08,S01aH01,S04aH01,S09aH08,S11aH01,S08aH01,S10aH01,S05aH01,S01aH08,S02aH08,S07aH08,S08aH08,S15aH08,S17aH08,S02aH01,S19aH01,S04aH08,S06aH01,S12aH08,S13aH08,S14aH01,S03aH01,S11aH08,S05aH08,S10aH08,S20aH01,S14aH08,S19aH08,S03aH08,S06aH08,S12aH01,S07aH01,S17aH01,S18aH01 | U12: N | V12: S01aH01,S04aH01,S04aH06,S03aH06,S10aH06,S06aH01,S09aH01,S06aH06,S03aH01,S01aH06,S07aH01,S08aH06,S02aH06,S02aH01,S05aH06,S09aH06,S05aH01,S07aH06,S08aH01,S10aH01 | X12: N | Y12: S09aH01,S02aH01,S05aH06,S09aH06,S02aH06,S06aH01,S01aH06,S07aH01,S08aH06,S01aH01,S04aH01,S04aH06,S06aH06,S03aH06,S10aH06,S08aH01,S10aH01,S03aH01,S05aH01,S07aH06 | AA12: N | AB12: AllSaAllH | AD12: N | AE12: FaP,SaP,RaP,SaN,WaN,RaN,FaN,WaP
I17: 0.75 | K17: share of charging at night
C18: ~UC_Sets: R_E: AllRegions
H21: =IF(H23=H24,"Not Required!","~UC_T: LO") -> Not Required!
C22: UC_N | D22: Pset_CI | E22: Pset_CO | F22: pset_pn | G22: Cset_CN | H22: TimeSlice | I22: UC_FLO | J22: UC_RHSRT | K22: UC_RHSRT~0
C23: UC_bev night chg limit | D23: ELC | E23: =G23 -> AuxStoIN | F23: *EV* | G23: AuxStoIN | H23: =HLOOKUP($A$10,$D$10:$CU$12,3,FALSE) -> AllSaAllH | I23: =1+I24 -> 0.25 | J23: 0 | K23: 3 | M23: night
D24: ELC | E24: =G24 -> AuxStoIN | F24: *EV* | G24: AuxStoIN | H24: =HLOOKUP($A$10,$D$10:$CU$12,2,FALSE) -> AllSaAllH | I24: =-$I$17 -> -0.75 | M24: day

Sheet ts_012
C9: =IF(A11="x","DeActivated","~TimeSlices") -> DeActivated | I9: =IF(A11="x","DeActivated","~TFM_DINS-AT") -> DeActivated | N9: =IF(A11="x","DeActivated","~TFM_DINS-AT") -> DeActivated | S9: =IF(A11="x","DeActivated","~TFM_DINS-AT") -> DeActivated | X9: =IF(A11="x","DeActivated","~TFM_DINS-AT") -> DeActivated | AC9: =IF(A11="x","DeActivated","~TFM_DINS-AT") -> DeActivated | AG9: =IF(A11="x","DeActivated","~TFM_DINS-AT") -> DeActivated | AK9: =IF(A11="x","DeActivated","~TFM_INS-AT") -> DeActivated
A10: ts_012 | C10: season | D10: weekly | E10: daynite | F10: wparent | G10: dparent | I10: commodity | J10: timeslice | K10: com_fr | L10: process | N10: commodity | O10: timeslice | P10: com_fr | Q10: process | S10: commodity | T10: timeslice | U10: com_fr | V10: process | X10: g_yrfr | Y10: com_fr | Z10: timeslice | AA10: commodity | AC10: commodity | AD10: timeslice | AE10: com_fr | AG10: commodity | AH10: timeslice | AI10: com_pkflx | AK10: Year | AL10: timeslice | AM10: ncap_afs | AN10: pset_ci
A11: =IFERROR(IF(Veda!D5=A10,"ok","x"),"") -> x | C11: S01 | D11: a | E11: H01 | F11: S01,S02,S03,S04 | G11: a | I11: elc_spv_ARE_001 | J11: S01aH01 | K11: 0 | L11: IMPNRGZ | N11: elc_won_ARE_001 | O11: S01aH01 | P11: 0.03492479 | Q11: IMPNRGZ | S11: elc_wof_ARE_001 | T11: S01aH01 | U11: 0.032876003 | V11: IMPNRGZ | X11: 0.026369863 | Y11: 0.010413942 | Z11: S01aH01 | AA11: elc_roadtransport | AC11: elc_buildings | AD11: S01aH01 | AE11: 0.019692598 | AG11: ELC | AH11: S01aH01 | AI11: 0.28386338 | AK11: 2025 | AL11: S01 | AM11: 0.35325 | AN11: hydro
C12: S02 | E12: H02 | G12: a | I12: elc_spv_ARE_001 | J12: S01aH02 | K12: 0.083103507 | L12: IMPNRGZ | N12: elc_won_ARE_001 | O12: S01aH02 | P12: 0.042512056 | Q12: IMPNRGZ | S12: elc_wof_ARE_001 | T12: S01aH02 | U12: 0.046512889 | V12: IMPNRGZ | X12: 0.041438356 | Y12: 0.060088009 | Z12: S01aH02 | AA12: elc_roadtransport | AC12: elc_buildings | AD12: S01aH02 | AE12: 0.036912692 | AG12: ELC | AH12: S01aH02 | AI12: 0.085474116 | AK12: 2025 | AL12: S02 | AM12: 0.37815 | AN12: hydro
C13: S03 | E13: H03 | G13: a | I13: elc_spv_ARE_001 | J13: S01aH03 | K13: 0 | L13: IMPNRGZ | N13: elc_won_ARE_001 | O13: S01aH03 | P13: 0.025427076 | Q13: IMPNRGZ | S13: elc_wof_ARE_001 | T13: S01aH03 | U13: 0.021459282 | V13: IMPNRGZ | X13: 0.02260274 | Y13: 0.019909007 | Z13: S01aH03 | AA13: elc_roadtransport | AC13: elc_buildings | AD13: S01aH03 | AE13: 0.014481575 | AG13: ELC | AH13: S01aH03 | AI13: 0.26490089 | AK13: 2025 | AL13: S03 | AM13: 0.3941 | AN13: hydro
C14: S04 | I14: elc_spv_ARE_001 | J14: S02aH01 | K14: 0 | L14: IMPNRGZ | N14: elc_won_ARE_001 | O14: S02aH01 | P14: 0.032520303 | Q14: IMPNRGZ | S14: elc_wof_ARE_001 | T14: S02aH01 | U14: 0.036591759 | V14: IMPNRGZ | X14: 0.028767123 | Y14: 0.011360664 | Z14: S02aH01 | AA14: elc_roadtransport | AC14: elc_buildings | AD14: S02aH01 | AE14: 0.02132841 | AG14: ELC | AH14: S02aH01 | AI14: 0.21638212 | AK14: 2025 | AL14: S04 | AM14: 0.40786 | AN14: hydro
I15: elc_spv_ARE_001 | J15: S02aH02 | K15: 0.10426263 | L15: IMPNRGZ | N15: elc_won_ARE_001 | O15: S02aH02 | P15: 0.042371374 | Q15: IMPNRGZ | S15: elc_wof_ARE_001 | T15: S02aH02 | U15: 0.049644712 | V15: IMPNRGZ | X15: 0.045205479 | Y15: 0.065550556 | Z15: S02aH02 | AA15: elc_roadtransport | AC15: elc_buildings | AD15: S02aH02 | AE15: 0.040329694 | AG15: ELC | AH15: S02aH02 | AI15: 0.12375715 | AK15: 2026 | AL15: S01 | AM15: 0.38345 | AN15: hydro
I16: elc_spv_ARE_001 | J16: S02aH03 | K16: 0.00033329258 | L16: IMPNRGZ | N16: elc_won_ARE_001 | O16: S02aH03 | P16: 0.024429198 | Q16: IMPNRGZ | S16: elc_wof_ARE_001 | T16: S02aH03 | U16: 0.02623714 | V16: IMPNRGZ | X16: 0.024657534 | Y16: 0.021718917 | Z16: S02aH03 | AA16: elc_roadtransport | AC16: elc_buildings | AD16: S02aH03 | AE16: 0.015959572 | AG16: ELC | AH16: S02aH03 | AI16: 0.25062667 | AK16: 2026 | AL16: S02 | AM16: 0.40485 | AN16: hydro
I17: elc_spv_ARE_001 | J17: S03aH01 | K17: 0 | L17: IMPNRGZ | N17: elc_won_ARE_001 | O17: S03aH01 | P17: 0.015596668 | Q17: IMPNRGZ | S17: elc_wof_ARE_001 | T17: S03aH01 | U17: 0.0127238 | V17: IMPNRGZ | X17: 0.011986301 | Y17: 0.0047336101 | Z17: S03aH01 | AA17: elc_roadtransport | AC17: elc_buildings | AD17: S03aH01 | AE17: 0.0087986696 | AG17: ELC | AH17: S03aH01 | AI17: 0.22155446 | AK17: 2026 | AL17: S03 | AM17: 0.4263 | AN17: hydro
I18: elc_spv_ARE_001 | J18: S03aH02 | K18: 0.042054651 | L18: IMPNRGZ | N18: elc_won_ARE_001 | O18: S03aH02 | P18: 0.02085864 | Q18: IMPNRGZ | S18: elc_wof_ARE_001 | T18: S03aH02 | U18: 0.021602885 | V18: IMPNRGZ | X18: 0.018835616 | Y18: 0.027312732 | Z18: S03aH02 | AA18: elc_roadtransport | AC18: elc_buildings | AD18: S03aH02 | AE18: 0.016932796 | AG18: ELC | AH18: S03aH02 | AI18: 0.11624408 | AK18: 2026 | AL18: S04 | AM18: 0.41719 | AN18: hydro
I19: elc_spv_ARE_001 | J19: S03aH03 | K19: 0.0012948782 | L19: IMPNRGZ | N19: elc_won_ARE_001 | O19: S03aH03 | P19: 0.014743941 | Q19: IMPNRGZ | S19: elc_wof_ARE_001 | T19: S03aH03 | U19: 0.013294486 | V19: IMPNRGZ | X19: 0.010273973 | Y19: 0.0090495488 | Z19: S03aH03 | AA19: elc_roadtransport | AC19: elc_buildings | AD19: S03aH03 | AE19: 0.0066933224 | AG19: ELC | AH19: S03aH03 | AI19: 0.24198635 | AK19: 2027 | AL19: S01 | AM19: 0.37135 | AN19: hydro
I20: elc_spv_ARE_001 | J20: S04aH01 | K20: 0.010357882 | L20: IMPNRGZ | N20: elc_won_ARE_001 | O20: S04aH01 | P20: 0.20291498 | Q20: IMPNRGZ | S20: elc_wof_ARE_001 | T20: S04aH01 | U20: 0.2245517 | V20: IMPNRGZ | X20: 0.22454338 | Y20: 0.088676296 | Z20: S04aH01 | AA20: elc_roadtransport | AC20: elc_buildings | AD20: S04aH01 | AE20: 0.22226948 | AG20: ELC | AH20: S04aH01 | AI20: 0.34740219 | AK20: 2027 | AL20: S02 | AM20: 0.41015 | AN20: hydro
I21: elc_spv_ARE_001 | J21: S04aH02 | K21: 0.74700971 | L21: IMPNRGZ | N21: elc_won_ARE_001 | O21: S04aH02 | P21: 0.32236846 | Q21: IMPNRGZ | S21: elc_wof_ARE_001 | T21: S04aH02 | U21: 0.32562597 | V21: IMPNRGZ | X21: 0.35285388 | Y21: 0.5116585 | Z21: S04aH02 | AA21: elc_roadtransport | AC21: elc_buildings | AD21: S04aH02 | AE21: 0.41087687 | AG21: ELC | AH21: S04aH02 | AI21: 0.17873107 | AK21: 2027 | AL21: S03 | AM21: 0.4375 | AN21: hydro
I22: elc_spv_ARE_001 | J22: S04aH03 | K22: 0.011583454 | L22: IMPNRGZ | N22: elc_won_ARE_001 | O22: S04aH03 | P22: 0.22133252 | Q22: IMPNRGZ | S22: elc_wof_ARE_001 | T22: S04aH03 | U22: 0.18887938 | V22: IMPNRGZ | X22: 0.19246575 | Y22: 0.16952821 | Z22: S04aH03 | AA22: elc_roadtransport | AC22: elc_buildings | AD22: S04aH03 | AE22: 0.18572432 | AG22: ELC | AH22: S04aH03 | AI22: 0.32079127 | AK22: 2027 | AL22: S04 | AM22: 0.41674 | AN22: hydro
I23: elc_spv_ARE_002 | J23: S01aH01 | K23: 0 | L23: IMPNRGZ | N23: elc_won_ARE_002 | O23: S01aH01 | P23: 0.035847087 | Q23: IMPNRGZ | S23: elc_wof_ARE_002 | T23: S01aH01 | U23: 0.033214668 | V23: IMPNRGZ | AC23: elc_industry | AD23: S01aH01 | AE23: 0.026233781 | AK23: 2028 | AL23: S01 | AM23: 0.36245 | AN23: hydro
I24: elc_spv_ARE_002 | J24: S01aH02 | K24: 0.08187978 | L24: IMPNRGZ | N24: elc_won_ARE_002 | O24: S01aH02 | P24: 0.046740129 | Q24: IMPNRGZ | S24: elc_wof_ARE_002 | T24: S01aH02 | U24: 0.047086473 | V24: IMPNRGZ | AC24: elc_industry | AD24: S01aH02 | AE24: 0.041719815 | AK24: 2028 | AL24: S02 | AM24: 0.37055 | AN24: hydro
I25: elc_spv_ARE_002 | J25: S01aH03 | K25: 0 | L25: IMPNRGZ | N25: elc_won_ARE_002 | O25: S01aH03 | P25: 0.024563921 | Q25: IMPNRGZ | S25: elc_wof_ARE_002 | T25: S01aH03 | U25: 0.021846482 | V25: IMPNRGZ | AC25: elc_industry | AD25: S01aH03 | AE25: 0.022287071 | AK25: 2028 | AL25: S03 | AM25: 0.3601 | AN25: hydro
I26: elc_spv_ARE_002 | J26: S02aH01 | K26: 0 | L26: IMPNRGZ | N26: elc_won_ARE_002 | O26: S02aH01 | P26: 0.032877462 | Q26: IMPNRGZ | S26: elc_wof_ARE_002 | T26: S02aH01 | U26: 0.037940756 | V26: IMPNRGZ | AC26: elc_industry | AD26: S02aH01 | AE26: 0.028605115 | AK26: 2028 | AL26: S04 | AM26: 0.40663 | AN26: hydro
I27: elc_spv_ARE_002 | J27: S02aH02 | K27: 0.10351612 | L27: IMPNRGZ | N27: elc_won_ARE_002 | O27: S02aH02 | P27: 0.04353993 | Q27: IMPNRGZ | S27: elc_wof_ARE_002 | T27: S02aH02 | U27: 0.050308863 | V27: IMPNRGZ | AC27: elc_industry | AD27: S02aH02 | AE27: 0.045516455 | AK27: 2029 | AL27: S01 | AM27: 0.3986 | AN27: hydro
I28: elc_spv_ARE_002 | J28: S02aH03 | K28: 0.00039916467 | L28: IMPNRGZ | N28: elc_won_ARE_002 | O28: S02aH03 | P28: 0.026307129 | Q28: IMPNRGZ | S28: elc_wof_ARE_002 | T28: S02aH03 | U28: 0.026752313 | V28: IMPNRGZ | AC28: elc_industry | AD28: S02aH03 | AE28: 0.02432594 | AK28: 2029 | AL28: S02 | AM28: 0.43955 | AN28: hydro
I29: elc_spv_ARE_002 | J29: S03aH01 | K29: 0 | L29: IMPNRGZ | N29: elc_won_ARE_002 | O29: S03aH01 | P29: 0.013366532 | Q29: IMPNRGZ | S29: elc_wof_ARE_002 | T29: S03aH01 | U29: 0.013290092 | V29: IMPNRGZ | AC29: elc_industry | AD29: S03aH01 | AE29: 0.011917545 | AK29: 2029 | AL29: S03 | AM29: 0.5023 | AN29: hydro
I30: elc_spv_ARE_002 | J30: S03aH02 | K30: 0.042502294 | L30: IMPNRGZ | N30: elc_won_ARE_002 | O30: S03aH02 | P30: 0.021169968 | Q30: IMPNRGZ | S30: elc_wof_ARE_002 | T30: S03aH02 | U30: 0.022781819 | V30: IMPNRGZ | AC30: elc_industry | AD30: S03aH02 | AE30: 0.018985409 | AK30: 2029 | AL30: S04 | AM30: 0.46541 | AN30: hydro
I31: elc_spv_ARE_002 | J31: S03aH03 | K31: 0.0012409468 | L31: IMPNRGZ | N31: elc_won_ARE_002 | O31: S03aH03 | P31: 0.013943848 | Q31: IMPNRGZ | S31: elc_wof_ARE_002 | T31: S03aH03 | U31: 0.013857053 | V31: IMPNRGZ | AC31: elc_industry | AD31: S03aH03 | AE31: 0.010144618 | AK31: 2030 | AL31: S01 | AM31: 0.42715 | AN31: hydro
I32: elc_spv_ARE_002 | J32: S04aH01 | K32: 0.010203392 | L32: IMPNRGZ | N32: elc_won_ARE_002 | O32: S04aH01 | P32: 0.19838186 | Q32: IMPNRGZ | S32: elc_wof_ARE_002 | T32: S04aH01 | U32: 0.2302615 | V32: IMPNRGZ | AC32: elc_industry | AD32: S04aH01 | AE32: 0.22328521 | AK32: 2030 | AL32: S02 | AM32: 0.4651 | AN32: hydro
I33: elc_spv_ARE_002 | J33: S04aH02 | K33: 0.74802363 | L33: IMPNRGZ | N33: elc_won_ARE_002 | O33: S04aH02 | P33: 0.34247677 | Q33: IMPNRGZ | S33: elc_wof_ARE_002 | T33: S04aH02 | U33: 0.30576445 | V33: IMPNRGZ | AC33: elc_industry | AD33: S04aH02 | AE33: 0.35598951 | AK33: 2030 | AL33: S03 | AM33: 0.4961 | AN33: hydro
I34: elc_spv_ARE_002 | J34: S04aH03 | K34: 0.012234674 | L34: IMPNRGZ | N34: elc_won_ARE_002 | O34: S04aH03 | P34: 0.20078536 | Q34: IMPNRGZ | S34: elc_wof_ARE_002 | T34: S04aH03 | U34: 0.19689553 | V34: IMPNRGZ | AC34: elc_industry | AD34: S04aH03 | AE34: 0.19098953 | AK34: 2030 | AL34: S04 | AM34: 0.47617 | AN34: hydro
I35: elc_spv_ARE_003 | J35: S01aH01 | K35: 0 | L35: IMPNRGZ | N35: elc_won_ARE_003 | O35: S01aH01 | P35: 0.035469057 | Q35: IMPNRGZ | AK35: 2031 | AL35: S01 | AM35: 0.41055 | AN35: hydro
I36: elc_spv_ARE_003 | J36: S01aH02 | K36: 0.083054963 | L36: IMPNRGZ | N36: elc_won_ARE_003 | O36: S01aH02 | P36: 0.043912122 | Q36: IMPNRGZ | AK36: 2031 | AL36: S02 | AM36: 0.4376 | AN36: hydro
I37: elc_spv_ARE_003 | J37: S01aH03 | K37: 0 | L37: IMPNRGZ | N37: elc_won_ARE_003 | O37: S01aH03 | P37: 0.028412001 | Q37: IMPNRGZ | AK37: 2031 | AL37: S03 | AM37: 0.4624 | AN37: hydro
I38: elc_spv_ARE_003 | J38: S02aH01 | K38: 0 | L38: IMPNRGZ | N38: elc_won_ARE_003 | O38: S02aH01 | P38: 0.031856916 | Q38: IMPNRGZ | AK38: 2031 | AL38: S04 | AM38: 0.46911 | AN38: hydro
I39: elc_spv_ARE_003 | J39: S02aH02 | K39: 0.10400522 | L39: IMPNRGZ | N39: elc_won_ARE_003 | O39: S02aH02 | P39: 0.036925908 | Q39: IMPNRGZ | AK39: 2032 | AL39: S01 | AM39: 0.3858 | AN39: hydro
I40: elc_spv_ARE_003 | J40: S02aH03 | K40: 0 | L40: IMPNRGZ | N40: elc_won_ARE_003 | O40: S02aH03 | P40: 0.02661381 | Q40: IMPNRGZ | AK40: 2032 | AL40: S02 | AM40: 0.40265 | AN40: hydro
I41: elc_spv_ARE_003 | J41: S03aH01 | K41: 1.7261925e-07 | L41: IMPNRGZ | N41: elc_won_ARE_003 | O41: S03aH01 | P41: 0.015454483 | Q41: IMPNRGZ | AK41: 2032 | AL41: S03 | AM41: 0.427 | AN41: hydro
I42: elc_spv_ARE_003 | J42: S03aH02 | K42: 0.04124475 | L42: IMPNRGZ | N42: elc_won_ARE_003 | O42: S03aH02 | P42: 0.021296653 | Q42: IMPNRGZ | AK42: 2032 | AL42: S04 | AM42: 0.46355 | AN42: hydro
I43: elc_spv_ARE_003 | J43: S03aH03 | K43: 0.00038215243 | L43: IMPNRGZ | N43: elc_won_ARE_003 | O43: S03aH03 | P43: 0.011962553 | Q43: IMPNRGZ | AK43: 2033 | AL43: S01 | AM43: 0.4184 | AN43: hydro
I44: elc_spv_ARE_003 | J44: S04aH01 | K44: 0.013697187 | L44: IMPNRGZ | N44: elc_won_ARE_003 | O44: S04aH01 | P44: 0.21393995 | Q44: IMPNRGZ | AK44: 2033 | AL44: S02 | AM44: 0.45025 | AN44: hydro
I45: elc_spv_ARE_003 | J45: S04aH02 | K45: 0.74726521 | L45: IMPNRGZ | N45: elc_won_ARE_003 | O45: S04aH02 | P45: 0.29583634 | Q45: IMPNRGZ | AK45: 2033 | AL45: S03 | AM45: 0.4917 | AN45: hydro
I46: elc_spv_ARE_003 | J46: S04aH03 | K46: 0.010350345 | L46: IMPNRGZ | N46: elc_won_ARE_003 | O46: S04aH03 | P46: 0.2383202 | Q46: IMPNRGZ | AK46: 2033 | AL46: S04 | AM46: 0.46288 | AN46: hydro
... I114: elc_spv_ARE_009 | J114: S03aH02 | K114: 0.040802855 | L114: IMPNRGZ | N114: elc_won_ARE_009 | O114: S03aH02 | P114: 0.02041299 | Q114: IMPNRGZ | AK114: 2050 | AL114: S04 | AM114: 0.46579 | AN114: hydro
I115: elc_spv_ARE_009 | J115: S03aH03 | K115: 0 | L115: IMPNRGZ | N115: elc_won_ARE_009 | O115: S03aH03 | P115: 0.01219197 | Q115: IMPNRGZ
...

Sheet ts_030
C9: =IF(A11="x","DeActivated","~TimeSlices") -> DeActivated | I9: =IF(A11="x","DeActivated","~TFM_DINS-AT") -> DeActivated | N9: =IF(A11="x","DeActivated","~TFM_DINS-AT") -> DeActivated | S9: =IF(A11="x","DeActivated","~TFM_DINS-AT") -> DeActivated | X9: =IF(A11="x","DeActivated","~TFM_DINS-AT") -> DeActivated | AC9: =IF(A11="x","DeActivated","~TFM_DINS-AT") -> DeActivated | AG9: =IF(A11="x","DeActivated","~TFM_DINS-AT") -> DeActivated | AK9: =IF(A11="x","DeActivated","~TFM_INS-AT") -> DeActivated
A10: ts_030 | C10: season | D10: weekly | E10: daynite | F10: wparent | G10: dparent | I10: commodity | J10: timeslice | K10: com_fr | L10: process | N10: commodity | O10: timeslice | P10: com_fr | Q10: process | S10: commodity | T10: timeslice | U10: com_fr | V10: process | X10: g_yrfr | Y10: com_fr | Z10: timeslice | AA10: commodity | AC10: commodity | AD10: timeslice | AE10: com_fr | AG10: commodity | AH10: timeslice | AI10: com_pkflx | AK10: Year | AL10: timeslice | AM10: ncap_afs | AN10: pset_ci
A11: =IFERROR(IF(Veda!D5=A10,"ok","x"),"") -> x | C11: S01 | D11: a | E11: H01 | F11: S01,S02,S03,S04,S05 | G11: a | I11: elc_spv_ARE_001 | J11: S01aH01 | K11: 0 | L11: IMPNRGZ | N11: elc_won_ARE_001 | O11: S01aH01 | P11: 0.03492479 | Q11: IMPNRGZ | S11: elc_wof_ARE_001 | T11: S01aH01 | U11: 0.032876003 | V11: IMPNRGZ | X11: 0.026369863 | Y11: 0.010413942 | Z11: S01aH01 | AA11: elc_roadtransport | AC11: elc_buildings | AD11: S01aH01 | AE11: 0.019692598 | AG11: ELC | AH11: S01aH01 | AI11: 0.28386338 | AK11: 2025 | AL11: S01 | AM11: 0.35325 | AN11: hydro
C12: S02 | E12: H02 | G12: a | I12: elc_spv_ARE_001 | J12: S01aH02 | K12: 0.0034239542 | L12: IMPNRGZ | N12: elc_won_ARE_001 | O12: S01aH02 | P12: 0.0050609669 | Q12: IMPNRGZ | S12: elc_wof_ARE_001 | T12: S01aH02 | U12: 0.0049941354 | V12: IMPNRGZ | X12: 0.0037671233 | Y12: 0.0062899336 | Z12: S01aH02 | AA12: elc_roadtransport | AC12: elc_buildings | AD12: S01aH02 | AE12: 0.003277828 | AG12: ELC | AH12: S01aH02 | AI12: 0.070880197 | AK12: 2025 | AL12: S02 | AM12: 0.37815 | AN12: hydro
C13: S03 | E13: H03 | G13: a | I13: elc_spv_ARE_001 | J13: S01aH03 | K13: 0.075511163 | L13: IMPNRGZ | N13: elc_won_ARE_001 | O13: S01aH03 | P13: 0.033851568 | Q13: IMPNRGZ | S13: elc_wof_ARE_001 | T13: S01aH03 | U13: 0.038140964 | V13: IMPNRGZ | X13: 0.03390411 | Y13: 0.046468936 | Z13: S01aH03 | AA13: elc_roadtransport | AC13: elc_buildings | AD13: S01aH03 | AE13: 0.030258721 | AG13: ELC | AH13: S01aH03 | AI13: 0.083803848 | AK13: 2025 | AL13: S03 | AM13: 0.3941 | AN13: hydro
C14: S04 | E14: H04 | G14: a | I14: elc_spv_ARE_001 | J14: S01aH04 | K14: 0.0041683899 | L14: IMPNRGZ | N14: elc_won_ARE_001 | O14: S01aH04 | P14: 0.0035995211 | Q14: IMPNRGZ | S14: elc_wof_ARE_001 | T14: S01aH04 | U14: 0.0033777895 | V14: IMPNRGZ | X14: 0.0037671233 | Y14: 0.00732914 | Z14: S01aH04 | AA14: elc_roadtransport | AC14: elc_buildings | AD14: S01aH04 | AE14: 0.0033761434 | AG14: ELC | AH14: S01aH04 | AI14: 0.051221544 | AK14: 2025 | AL14: S04 | AM14: 0.454775 | AN14: hydro
C15: S05 | E15: H05 | G15: a | I15: elc_spv_ARE_001 | J15: S01aH05 | K15: 0 | L15: IMPNRGZ | N15: elc_won_ARE_001 | O15: S01aH05 | P15: 0.025427076 | Q15: IMPNRGZ | S15: elc_wof_ARE_001 | T15: S01aH05 | U15: 0.021459282 | V15: IMPNRGZ | X15: 0.02260274 | Y15: 0.019909007 | Z15: S01aH05 | AA15: elc_roadtransport | AC15: elc_buildings | AD15: S01aH05 | AE15: 0.014481575 | AG15: ELC | AH15: S01aH05 | AI15: 0.26490089 | AK15: 2025 | AL15: S05 | AM15: 0.39522857 | AN15: hydro
I16: elc_spv_ARE_001 | J16: S02aH01 | K16: 0 | L16: IMPNRGZ | N16: elc_won_ARE_001 | O16: S02aH01 | P16: 0.032520303 | Q16: IMPNRGZ | S16: elc_wof_ARE_001 | T16: S02aH01 | U16: 0.036591759 | V16: IMPNRGZ | X16: 0.028767123 | Y16: 0.011360664 | Z16: S02aH01 | AA16: elc_roadtransport | AC16: elc_buildings | AD16: S02aH01 | AE16: 0.02132841 | AG16: ELC | AH16: S02aH01 | AI16: 0.21638212 | AK16: 2026 | AL16: S01 | AM16: 0.38345 | AN16: hydro
I17: elc_spv_ARE_001 | J17: S02aH02 | K17: 0.0041653724 | L17: IMPNRGZ | N17: elc_won_ARE_001 | O17: S02aH02 | P17: 0.0048721154 | Q17: IMPNRGZ | S17: elc_wof_ARE_001 | T17: S02aH02 | U17: 0.0056681116 | V17: IMPNRGZ | X17: 0.004109589 | Y17: 0.0068617458 | Z17: S02aH02 | AA17: elc_roadtransport | AC17: elc_buildings | AD17: S02aH02 | AE17: 0.0035605273 | AG17: ELC | AH17: S02aH02 | AI17: 0.074592087 | AK17: 2026 | AL17: S02 | AM17: 0.40485 | AN17: hydro
I18: elc_spv_ARE_001 | J18: S02aH03 | K18: 0.093774263 | L18: IMPNRGZ | N18: elc_won_ARE_001 | O18: S02aH03 | P18: 0.034345893 | Q18: IMPNRGZ | S18: elc_wof_ARE_001 | T18: S02aH03 | U18: 0.039910487 | V18: IMPNRGZ | X18: 0.036986301 | Y18: 0.050693384 | Z18: S02aH03 | AA18: elc_roadtransport | AC18: elc_buildings | AD18: S02aH03 | AE18: 0.033097162 | AG18: ELC | AH18: S02aH03 | AI18: 0.12099906 | AK18: 2026 | AL18: S03 | AM18: 0.4263 | AN18: hydro
I19: elc_spv_ARE_001 | J19: S02aH04 | K19: 0.0063229907 | L19: IMPNRGZ | N19: elc_won_ARE_001 | O19: S02aH04 | P19: 0.003153366 | Q19: IMPNRGZ | S19: elc_wof_ARE_001 | T19: S02aH04 | U19: 0.0040661135 | V19: IMPNRGZ | X19: 0.004109589 | Y19: 0.0079954255 | Z19: S02aH04 | AA19: elc_roadtransport | AC19: elc_buildings | AD19: S02aH04 | AE19: 0.0036720044 | AG19: ELC | AH19: S02aH04 | AI19: 0.049991496 | AK19: 2026 | AL19: S04 | AM19: 0.45435 | AN19: hydro
I20: elc_spv_ARE_001 | J20: S02aH05 | K20: 0.00033329258 | L20: IMPNRGZ | N20: elc_won_ARE_001 | O20: S02aH05 | P20: 0.024429198 | Q20: IMPNRGZ | S20: elc_wof_ARE_001 | T20: S02aH05 | U20: 0.02623714 | V20: IMPNRGZ | X20: 0.024657534 | Y20: 0.021718917 | Z20: S02aH05 | AA20: elc_roadtransport | AC20: elc_buildings | AD20: S02aH05 | AE20: 0.015959572 | AG20: ELC | AH20: S02aH05 | AI20: 0.25062667 | AK20: 2026 | AL20: S05 | AM20: 0.39935714 | AN20: hydro
I21: elc_spv_ARE_001 | J21: S03aH01 | K21: 0 | L21: IMPNRGZ | N21: elc_won_ARE_001 | O21: S03aH01 | P21: 0.013517961 | Q21: IMPNRGZ | S21: elc_wof_ARE_001 | T21: S03aH01 | U21: 0.0093386566 | V21: IMPNRGZ | X21: 0.0087899543 | Y21: 0.0034713141 | Z21: S03aH01 | AA21: elc_roadtransport | AC21: elc_buildings | AD21: S03aH01 | AE21: 0.0065582528 | AG21: ELC | AH21: S03aH01 | AI21: 0.20613673 | AK21: 2027 | AL21: S01 | AM21: 0.37135 | AN21: hydro
I22: elc_spv_ARE_001 | J22: S03aH02 | K22: 0.001313983 | L22: IMPNRGZ | N22: elc_won_ARE_001 | O22: S03aH02 | P22: 0.002080229 | Q22: IMPNRGZ | S22: elc_wof_ARE_001 | T22: S03aH02 | U22: 0.0015514461 | V22: IMPNRGZ | X22: 0.0012557078 | Y22: 0.0020966445 | Z22: S03aH02 | AA22: elc_roadtransport | AC22: elc_buildings | AD22: S03aH02 | AE22: 0.0011236654 | AG22: ELC | AH22: S03aH02 | AI22: 0.042647003 | AK22: 2027 | AL22: S02 | AM22: 0.41015 | AN22: hydro
I23: elc_spv_ARE_001 | J23: S03aH03 | K23: 0.027633113 | L23: IMPNRGZ | N23: elc_won_ARE_001 | O23: S03aH03 | P23: 0.014314416 | Q23: IMPNRGZ | S23: elc_wof_ARE_001 | T23: S03aH03 | U23: 0.013140768 | V23: IMPNRGZ | X23: 0.01130137 | Y23: 0.015489645 | Z23: S03aH03 | AA23: elc_roadtransport | AC23: elc_buildings | AD23: S03aH03 | AE23: 0.010420397 | AG23: ELC | AH23: S03aH03 | AI23: 0.09346432 | AK23: 2027 | AL23: S03 | AM23: 0.4375 | AN23: hydro
I24: elc_spv_ARE_001 | J24: S03aH04 | K24: 0.0020121629 | L24: IMPNRGZ | N24: elc_won_ARE_001 | O24: S03aH04 | P24: 0.0017626496 | Q24: IMPNRGZ | S24: elc_wof_ARE_001 | T24: S03aH04 | U24: 0.0013415202 | V24: IMPNRGZ | X24: 0.0012557078 | Y24: 0.0024430467 | Z24: S03aH04 | AA24: elc_roadtransport | AC24: elc_buildings | AD24: S03aH04 | AE24: 0.0011155386 | AG24: ELC | AH24: S03aH04 | AI24: 0.043347679 | AK24: 2027 | AL24: S04 | AM24: 0.4681 | AN24: hydro
I25: elc_spv_ARE_001 | J25: S03aH05 | K25: 0.00097962363 | L25: IMPNRGZ | N25: elc_won_ARE_001 | O25: S03aH05 | P25: 0.010733637 | Q25: IMPNRGZ | S25: elc_wof_ARE_001 | T25: S03aH05 | U25: 0.0094458032 | V25: IMPNRGZ | X25: 0.0075342466 | Y25: 0.0066363358 | Z25: S03aH05 | AA25: elc_roadtransport | AC25: elc_buildings | AD25: S03aH05 | AE25: 0.004935811 | AG25: ELC | AH25: S03aH05 | AI25: 0.23676057 | AK25: 2027 | AL25: S05 | AM25: 0.4024 | AN25: hydro
I26: elc_spv_ARE_001 | J26: S04aH01 | K26: 0.0048561385 | L26: IMPNRGZ | N26: elc_won_ARE_001 | O26: S04aH01 | P26: 0.068775094 | Q26: IMPNRGZ | S26: elc_wof_ARE_001 | T26: S04aH01 | U26: 0.074552546 | V26: IMPNRGZ | X26: 0.062328767 | Y26: 0.024614773 | Z26: S04aH01 | AA26: elc_roadtransport | AC26: elc_buildings | AD26: S04aH01 | AE26: 0.05431542 | AG26: ELC | AH26: S04aH01 | AI26: 0.43212461 | AK26: 2028 | AL26: S01 | AM26: 0.36245 | AN26: hydro
I27: elc_spv_ARE_001 | J27: S04aH02 | K27: 0.012438348 | L27: IMPNRGZ | N27: elc_won_ARE_001 | O27: S04aH02 | P27: 0.0084382813 | Q27: IMPNRGZ | S27: elc_wof_ARE_001 | T27: S04aH02 | U27: 0.010098666 | V27: IMPNRGZ | X27: 0.0089041096 | Y27: 0.014867116 | Z27: S04aH02 | AA27: elc_roadtransport | AC27: elc_buildings | AD27: S04aH02 | AE27: 0.0094057692 | AG27: ELC | AH27: S04aH02 | AI27: 0.23830225 | AK27: 2028 | AL27: S02 | AM27: 0.37055 | AN27: hydro
... I35: elc_spv_ARE_001 | J35: S05aH05 | K35: 0.0059769631 | L35: IMPNRGZ | N35: elc_won_ARE_001 | O35: S05aH05 | P35: 0.1508789 | Q35: IMPNRGZ | S35: elc_wof_ARE_001 | T35: S05aH05 | U35: 0.12843827 | V35: IMPNRGZ | X35: 0.14178082 | Y35: 0.12488377 | Z35: S05aH05 | AA35: elc_roadtransport | AC35: elc_buildings | AD35: S05aH05 | AE35: 0.14275646 | AG35: ELC | AH35: S05aH05 | AI35: 0.27568453 | AK35: 2029 | AL35: S05 | AM35: 0.44334286 | AN35: hydro
I36: elc_spv_ARE_002 | J36: S01aH01 | K36: 0 | L36: IMPNRGZ | N36: elc_won_ARE_002 | O36: S01aH01 | P36: 0.035847087 | Q36: IMPNRGZ | S36: elc_wof_ARE_002 | T36: S01aH01 | U36: 0.033214668 | V36: IMPNRGZ | AC36: elc_industry | AD36: S01aH01 | AE36: 0.026233781 | AK36: 2030 | AL36: S01 | AM36: 0.42715 | AN36: hydro
I37: elc_spv_ARE_002 | J37: S01aH02 | K37: 0.0037465748 | L37: IMPNRGZ | N37: elc_won_ARE_002 | O37: S01aH02 | P37: 0.0054877951 | Q37: IMPNRGZ | S37: elc_wof_ARE_002 | T37: S01aH02 | U37: 0.0051326615 | V37: IMPNRGZ | AC37: elc_industry | AD37: S01aH02 | AE37: 0.0037862468 | AK37: 2030 | AL37: S02 | AM37: 0.4651 | AN37: hydro
I38: elc_spv_ARE_002 | J38: S01aH03 | K38: 0.074099326 | L38: IMPNRGZ | N38: elc_won_ARE_002 | O38: S01aH03 | P38: 0.037630129 | Q38: IMPNRGZ | S38: elc_wof_ARE_002 | T38: S01aH03 | U38: 0.038638918 | V38: IMPNRGZ | AC38: elc_industry | AD38: S01aH03 | AE38: 0.034139161 | AK38: 2030 | AL38: S03 | AM38: 0.4961 | AN38: hydro
I39: elc_spv_ARE_002 | J39: S01aH04 | K39: 0.0040338786 | L39: IMPNRGZ | N39: elc_won_ARE_002 | O39: S01aH04 | P39: 0.0036222045 | Q39: IMPNRGZ | S39: elc_wof_ARE_002 | T39: S01aH04 | U39: 0.0033148937 | V39: IMPNRGZ | AC39: elc_industry | AD39: S01aH04 | AE39: 0.0037944075 | AK39: 2030 | AL39: S04 | AM39: 0.533525 | AN39: hydro
I40: elc_spv_ARE_002 | J40: S01aH05 | K40: 0 | L40: IMPNRGZ | N40: elc_won_ARE_002 | O40: S01aH05 | P40: 0.024563921 | Q40: IMPNRGZ | S40: elc_wof_ARE_002 | T40: S01aH05 | U40: 0.021846482 | V40: IMPNRGZ | AC40: elc_industry | AD40: S01aH05 | AE40: 0.022287071 | AK40: 2030 | AL40: S05 | AM40: 0.45697143 | AN40: hydro
I41: elc_spv_ARE_002 | J41: S02aH01 | K41: 0 | L41: IMPNRGZ | N41: elc_won_ARE_002 | O41: S02aH01 | P41: 0.032877462 | Q41: IMPNRGZ | S41: elc_wof_ARE_002 | T41: S02aH01 | U41: 0.037940756 | V41: IMPNRGZ | AC41: elc_industry | AD41: S02aH01 | AE41: 0.028605115 | AK41: 2031 | AL41: S01 | AM41: 0.41055 | AN41: hydro
I42: elc_spv_ARE_002 | J42: S02aH02 | K42: 0.0041592119 | L42: IMPNRGZ | N42: elc_won_ARE_002 | O42: S02aH02 | P42: 0.0049545066 | Q42: IMPNRGZ | S42: elc_wof_ARE_002 | T42: S02aH02 | U42: 0.0056166364 | V42: IMPNRGZ | AC42: elc_industry | AD42: S02aH02 | AE42: 0.004129077 | AK42: 2031 | AL42: S02 | AM42: 0.4376 | AN42: hydro
I43: elc_spv_ARE_002 | J43: S02aH03 | K43: 0.093054279 | L43: IMPNRGZ | N43: elc_won_ARE_002 | O43: S02aH03 | P43: 0.035105748 | Q43: IMPNRGZ | S43: elc_wof_ARE_002 | T43: S02aH03 | U43: 0.040558379 | V43: IMPNRGZ | AC43: elc_industry | AD43: S02aH03 | AE43: 0.037249048 | AK43: 2031 | AL43: S03 | AM43: 0.4624 | AN43: hydro
I44: elc_spv_ARE_002 | J44: S02aH04 | K44: 0.0063026277 | L44: IMPNRGZ | N44: elc_won_ARE_002 | O44: S02aH04 | P44: 0.0034796752 | Q44: IMPNRGZ | S44: elc_wof_ARE_002 | T44: S02aH04 | U44: 0.004133848 | V44: IMPNRGZ | AC44: elc_industry | AD44: S02aH04 | AE44: 0.0041383301 | AK44: 2031 | AL44: S04 | AM44: 0.51995 | AN44: hydro
I45: elc_spv_ARE_002 | J45: S02aH05 | K45: 0.00039916467 | L45: IMPNRGZ | N45: elc_won_ARE_002 | O45: S02aH05 | P45: 0.026307129 | Q45: IMPNRGZ | S45: elc_wof_ARE_002 | T45: S02aH05 | U45: 0.026752313 | V45: IMPNRGZ | AC45: elc_industry | AD45: S02aH05 | AE45: 0.02432594 | AK45: 2031 | AL45: S05 | AM45: 0.45467143 | AN45: hydro
I46: elc_spv_ARE_002 | J46: S03aH01 | K46: 0 | L46: IMPNRGZ | N46: elc_won_ARE_002 | O46: S03aH01 | P46: 0.011664326 | Q46: IMPNRGZ | S46: elc_wof_ARE_002 | T46: S03aH01 | U46: 0.0094532739 | V46: IMPNRGZ | AC46: elc_industry | AD46: S03aH01 | AE46: 0.008748323 | AK46: 2032 | AL46: S01 | AM46: 0.3858 | AN46: hydro
I47: elc_spv_ARE_002 | J47: S03aH02 | K47: 0.0013457146 | L47: IMPNRGZ | N47: elc_won_ARE_002 | O47: S03aH02 | P47: 0.0017785819 | Q47: IMPNRGZ | S47: elc_wof_ARE_002 | T47: S03aH02 | U47: 0.0016203442 | V47: IMPNRGZ | AC47: elc_industry | AD47: S03aH02 | AE47: 0.0012652633 | AK47: 2032 | AL47: S02 | AM47: 0.40265 | AN47: hydro
... I60: elc_spv_ARE_002 | J60: S05aH05 | K60: 0.0065212462 | L60: IMPNRGZ | N60: elc_won_ARE_002 | O60: S05aH05 | P60: 0.13606895 | Q60: IMPNRGZ | S60: elc_wof_ARE_002 | T60: S05aH05 | U60: 0.12932154 | V60: IMPNRGZ | AC60: elc_industry | AD60: S05aH05 | AE60: 0.1408149 | AK60: 2034 | AL60: S05 | AM60: 0.39028571 | AN60: hydro
I61: elc_spv_ARE_003 | J61: S01aH01 | K61: 0 | L61: IMPNRGZ | N61: elc_won_ARE_003 | O61: S01aH01 | P61: 0.035469057 | Q61: IMPNRGZ | AK61: 2035 | AL61: S01 | AM61: 0.3303 | AN61: hydro
I62: elc_spv_ARE_003 | J62: S01aH02 | K62: 0.0033382379 | L62: IMPNRGZ | N62: elc_won_ARE_003 | O62: S01aH02 | P62: 0.0048406264 | Q62: IMPNRGZ | AK62: 2035 | AL62: S02 | AM62: 0.3849 | AN62: hydro
I63: elc_spv_ARE_003 | J63: S01aH03 | K63: 0.075713374 | L63: IMPNRGZ | N63: elc_won_ARE_003 | O63: S01aH03 | P63: 0.035324433 | Q63: IMPNRGZ | AK63: 2035 | AL63: S03 | AM63: 0.4326 | AN63: hydro
I64: elc_spv_ARE_003 | J64: S01aH04 | K64: 0.0040033507 | L64: IMPNRGZ | N64: elc_won_ARE_003 | O64: S01aH04 | P64: 0.0037470632 | Q64: IMPNRGZ | AK64: 2035 | AL64: S04 | AM64: 0.460025 | AN64: hydro
I65: elc_spv_ARE_003 | J65: S01aH05 | K65: 0 | L65: IMPNRGZ | N65: elc_won_ARE_003 | O65: S01aH05 | P65: 0.028412001 | Q65: IMPNRGZ | AK65: 2035 | AL65: S05 | AM65: 0.38968571 | AN65: hydro
I66: elc_spv_ARE_003 | J66: S02aH01 | K66: 0 | L66: IMPNRGZ | N66: elc_won_ARE_003 | O66: S02aH01 | P66: 0.031856916 | Q66: IMPNRGZ | AK66: 2036 | AL66: S01 | AM66: 0.2904 | AN66: hydro
I67: elc_spv_ARE_003 | J67: S02aH02 | K67: 0.0043078992 | L67: IMPNRGZ | N67: elc_won_ARE_003 | O67: S02aH02 | P67: 0.0045348469 | Q67: IMPNRGZ | AK67: 2036 | AL67: S02 | AM67: 0.31885 | AN67: hydro
...

Sheet ts_048
C9: =IF(A11="x","DeActivated","~TimeSlices") -> DeActivated | I9: =IF(A11="x","DeActivated","~TFM_DINS-AT") -> DeActivated | N9: =IF(A11="x","DeActivated","~TFM_DINS-AT") -> DeActivated | S9: =IF(A11="x","DeActivated","~TFM_DINS-AT") -> DeActivated | X9: =IF(A11="x","DeActivated","~TFM_DINS-AT") -> DeActivated | AC9: =IF(A11="x","DeActivated","~TFM_DINS-AT") -> DeActivated | AG9: =IF(A11="x","DeActivated","~TFM_DINS-AT") -> DeActivated | AK9: =IF(A11="x","DeActivated","~TFM_INS-AT") -> DeActivated
