Workbook

Sheet Veda
G1: 1,2,3,4,5,6,7,8,9,10,11,12,13,14,15,21,22,23,24,25,31,32,33,34,35,36,37,38,39,40,41,42,43,44,45,46,47,48,49,50,56,57,58,59,60,66,67,68,69,70
D2: ="~Inputcell: "&_xlfn.TEXTJOIN(",",TRUE,G1:EE1) -> ~Inputcell: 1,2,3,4,5,6,7,8,9,10,11,12,13,14,15,21,22,23,24,25,31,32,33,34,35,36,37,38,39,40,41,42,43,44,45,46,47,48,49,50,56,57,58,59,60,66,67,68,69,70 | G2: 5 | H2: 6 | I2: 7 | J2: 9 | K2: 10 | L2: 11 | M2: 16 | N2: 17 | O2: 18 | P2: 20 | Q2: 21 | R2: 22 | S2: 27 | T2: 28 | U2: 29 | V2: 31 | W2: 32 | X2: 33 | Y2: 38 | Z2: 39 | AA2: 40 | AB2: 42 | AC2: 43 | AD2: 44 | AE2: 49 | AF2: 50 | AG2: 51 | AH2: 53 | AI2: 54 | AJ2: 55
D3: 3
D5: =VLOOKUP(D3,$C$9:$E$999,2,FALSE) -> ts_annual | E5: =VLOOKUP(D3,$C$9:$E$999,3,FALSE) -> C3
B7: ~Scenmap
A8: priority | B8: scen | C8: case_no | D8: timeslice | E8: climate | AM8: bio price multiplier
A9: 5 | B9: =VLOOKUP(E9,$AK$9:$AL$15,2,FALSE)&"."&VLOOKUP(D9,$AH$9:$AI$24,2,FALSE) -> e 1.5 deg no OS.kAnn | C9: 1 | D9: =VLOOKUP(AJ9,$AG$9:$AH$22,2,FALSE) -> ts_annual | E9: C1 | G9: Limit warming to 1.5°C (>50%) with no or limited overshoot | AG9: 1 | AH9: ts_annual | AI9: kAnn | AJ9: 1 | AK9: C1 | AL9: e 1.5 deg no OS | AM9: 5
A10: 5 | B10: =VLOOKUP(E10,$AK$9:$AL$15,2,FALSE)&"."&VLOOKUP(D10,$AH$9:$AI$24,2,FALSE) -> d 1.5 deg OS.kAnn | C10: =C9+1 -> 2 | D10: =VLOOKUP(AJ10,$AG$9:$AH$22,2,FALSE) -> ts_annual | E10: C2 | G10: Limit warming to 1.5°C (>67%) with high overshoot | S10: IEA | AG10: 2 | AH10: ts_12t | AI10: k12 | AJ10: 1 | AK10: C2 | AL10: d 1.5 deg OS | AM10: 4
A11: 5 | B11: =VLOOKUP(E11,$AK$9:$AL$15,2,FALSE)&"."&VLOOKUP(D11,$AH$9:$AI$24,2,FALSE) -> c 2 deg (67%).kAnn | C11: =C10+1 -> 3 | D11: =VLOOKUP(AJ11,$AG$9:$AH$22,2,FALSE) -> ts_annual | E11: C3 | G11: Limit warming to 2°C (>67%) with higher action post-2030 | S11: 2022 | AG11: 3 | AH11: ts_012 | AI11: j12 | AJ11: 1 | AK11: C3 | AL11: c 2 deg (67%) | AM11: 3
A12: 5 | B12: =VLOOKUP(E12,$AK$9:$AL$15,2,FALSE)&"."&VLOOKUP(D12,$AH$9:$AI$24,2,FALSE) -> b 2 deg (50%).kAnn | C12: =C11+1 -> 4 | D12: =VLOOKUP(AJ12,$AG$9:$AH$22,2,FALSE) -> ts_annual | E12: C4 | G12: Limit warming to 2°C (>50%) with immediate action | S12: =SUMIFS(iea_data!I3:I9999,iea_data!$B$3:$B$9999,Veda!$S$11)+T28-T29 -> 7.31 | T12: base-year generation (TWh) | AG12: 4 | AH12: ts_024 | AI12: i24 | AJ12: 1 | AK12: C4 | AL12: b 2 deg (50%) | AM12: 3
A13: 5 | B13: =VLOOKUP(E13,$AK$9:$AL$15,2,FALSE)&"."&VLOOKUP(D13,$AH$9:$AI$24,2,FALSE) -> a 3 deg.kAnn | C13: =C12+1 -> 5 | D13: =VLOOKUP(AJ13,$AG$9:$AH$22,2,FALSE) -> ts_annual | E13: C7 | G13: Likely above 3°C warming with limited mitigation | AG13: 5 | AH13: ts_048 | AI13: h48 | AJ13: 1 | AK13: C7 | AL13: a 3 deg | AM13: 1.5
A14: 5 | B14: =VLOOKUP(E14,$AK$9:$AL$15,2,FALSE)&"."&VLOOKUP(D14,$AH$9:$AI$24,2,FALSE) -> e 1.5 deg no OS.k12 | C14: =C13+1 -> 6 | D14: =VLOOKUP(AJ14,$AG$9:$AH$22,2,FALSE) -> ts_12t | E14: =E9 -> C1 | T14: =S12 -> 7.31 | U14: =$S$12*J15 -> 7.6755 | V14: =$S$12*K15 -> 8.5527 | W14: =$S$12*L15 -> 9.6492 | X14: =$S$12*M15 -> 10.965 | Y14: =$S$12*N15 -> 12.2808 | Z14: =$S$12*O15 -> 13.2311 | AG14: 6 | AH14: ts_064 | AI14: g64 | AJ14: =AJ9+1 -> 2
A15: 5 | B15: =VLOOKUP(E15,$AK$9:$AL$15,2,FALSE)&"."&VLOOKUP(D15,$AH$9:$AI$24,2,FALSE) -> d 1.5 deg OS.k12 | C15: =C14+1 -> 7 | D15: =VLOOKUP(AJ15,$AG$9:$AH$22,2,FALSE) -> ts_12t | E15: =E10 -> C2 | G15: Electricity growth relative to 2020 | I15: =SUMIFS(ar6_r10!$F$2:$F$999,ar6_r10!$A$2:$A$999,Veda!$E$5,ar6_r10!$C$2:$C$999,Veda!I$17,ar6_r10!$M$2:$M$999,Veda!$G15) -> 1 | J15: =SUMIFS(ar6_r10!$F$2:$F$999,ar6_r10!$A$2:$A$999,Veda!$E$5,ar6_r10!$C$2:$C$999,Veda!J$17,ar6_r10!$M$2:$M$999,Veda!$G15) -> 1.05 | K15: =SUMIFS(ar6_r10!$F$2:$F$999,ar6_r10!$A$2:$A$999,Veda!$E$5,ar6_r10!$C$2:$C$999,Veda!K$17,ar6_r10!$M$2:$M$999,Veda!$G15) -> 1.17 | L15: =SUMIFS(ar6_r10!$F$2:$F$999,ar6_r10!$A$2:$A$999,Veda!$E$5,ar6_r10!$C$2:$C$999,Veda!L$17,ar6_r10!$M$2:$M$999,Veda!$G15) -> 1.32 | M15: =SUMIFS(ar6_r10!$F$2:$F$999,ar6_r10!$A$2:$A$999,Veda!$E$5,ar6_r10!$C$2:$C$999,Veda!M$17,ar6_r10!$M$2:$M$999,Veda!$G15) -> 1.5 | N15: =SUMIFS(ar6_r10!$F$2:$F$999,ar6_r10!$A$2:$A$999,Veda!$E$5,ar6_r10!$C$2:$C$999,Veda!N$17,ar6_r10!$M$2:$M$999,Veda!$G15) -> 1.68 | O15: =SUMIFS(ar6_r10!$F$2:$F$999,ar6_r10!$A$2:$A$999,Veda!$E$5,ar6_r10!$C$2:$C$999,Veda!O$17,ar6_r10!$M$2:$M$999,Veda!$G15) -> 1.81 | AG15: 7 | AH15: ts_096P50 | AI15: f96p50 | AJ15: =AJ10+1 -> 2
A16: 5 | B16: =VLOOKUP(E16,$AK$9:$AL$15,2,FALSE)&"."&VLOOKUP(D16,$AH$9:$AI$24,2,FALSE) -> c 2 deg (67%).k12 | C16: =C15+1 -> 8 | D16: =VLOOKUP(AJ16,$AG$9:$AH$22,2,FALSE) -> ts_12t | E16: =E11 -> C3 | S16: ~TFM_INS-TS | AG16: 8 | AH16: ts_096P10 | AI16: f96p10 | AJ16: =AJ11+1 -> 2
A17: 5 | B17: =VLOOKUP(E17,$AK$9:$AL$15,2,FALSE)&"."&VLOOKUP(D17,$AH$9:$AI$24,2,FALSE) -> b 2 deg (50%).k12 | C17: =C16+1 -> 9 | D17: =VLOOKUP(AJ17,$AG$9:$AH$22,2,FALSE) -> ts_12t | E17: =E12 -> C4 | I17: 2020 | J17: =U17 -> 2025 | K17: =V17 -> 2030 | L17: =W17 -> 2035 | M17: =X17 -> 2040 | N17: =Y17 -> 2045 | O17: =Z17 -> 2050 | S17: commodity | T17: 2022 | U17: 2025 | V17: 2030 | W17: 2035 | X17: 2040 | Y17: 2045 | Z17: 2050 | AA17: attribute | AG17: 9 | AH17: ts_096P90 | AI17: f96p90 | AJ17: =AJ12+1 -> 2
A18: 5 | B18: =VLOOKUP(E18,$AK$9:$AL$15,2,FALSE)&"."&VLOOKUP(D18,$AH$9:$AI$24,2,FALSE) -> a 3 deg.k12 | C18: =C17+1 -> 10 | D18: =VLOOKUP(AJ18,$AG$9:$AH$22,2,FALSE) -> ts_12t | E18: =E13 -> C7 | G18: Hydrogen as a share of electricity | I18: =SUMIFS(ar6_r10!$F$2:$F$999,ar6_r10!$A$2:$A$999,Veda!$E$5,ar6_r10!$C$2:$C$999,Veda!I$17,ar6_r10!$M$2:$M$999,Veda!$G18) -> 0 | J18: =SUMIFS(ar6_r10!$F$2:$F$999,ar6_r10!$A$2:$A$999,Veda!$E$5,ar6_r10!$C$2:$C$999,Veda!J$17,ar6_r10!$M$2:$M$999,Veda!$G18) -> 0 | K18: =SUMIFS(ar6_r10!$F$2:$F$999,ar6_r10!$A$2:$A$999,Veda!$E$5,ar6_r10!$C$2:$C$999,Veda!K$17,ar6_r10!$M$2:$M$999,Veda!$G18) -> 0.01 | L18: =SUMIFS(ar6_r10!$F$2:$F$999,ar6_r10!$A$2:$A$999,Veda!$E$5,ar6_r10!$C$2:$C$999,Veda!L$17,ar6_r10!$M$2:$M$999,Veda!$G18) -> 0.01 | M18: =SUMIFS(ar6_r10!$F$2:$F$999,ar6_r10!$A$2:$A$999,Veda!$E$5,ar6_r10!$C$2:$C$999,Veda!M$17,ar6_r10!$M$2:$M$999,Veda!$G18) -> 0.01 | N18: =SUMIFS(ar6_r10!$F$2:$F$999,ar6_r10!$A$2:$A$999,Veda!$E$5,ar6_r10!$C$2:$C$999,Veda!N$17,ar6_r10!$M$2:$M$999,Veda!$G18) -> 0.02 | O18: =SUMIFS(ar6_r10!$F$2:$F$999,ar6_r10!$A$2:$A$999,Veda!$E$5,ar6_r10!$C$2:$C$999,Veda!O$17,ar6_r10!$M$2:$M$999,Veda!$G18) -> 0.03 | S18: hydrogen_allsect | T18: =I18*T$14 -> 0 | U18: =J18*U$14 -> 0 | V18: =K18*V$14 -> 0.085527 | W18: =L18*W$14 -> 0.096492 | X18: =M18*X$14 -> 0.10965 | Y18: =N18*Y$14 -> 0.245616 | Z18: =O18*Z$14 -> 0.396933 | AA18: demand | AG18: 10 | AH18: s1p1v1_d | AI18: e3d | AJ18: =AJ13+1 -> 2
A19: 5 | B19: =VLOOKUP(E19,$AK$9:$AL$15,2,FALSE)&"."&VLOOKUP(D19,$AH$9:$AI$24,2,FALSE) -> e 1.5 deg no OS.j12 | C19: =C18+1 -> 11 | D19: =VLOOKUP(AJ19,$AG$9:$AH$22,2,FALSE) -> ts_012 | E19: =E14 -> C1 | G19: Industry electricity share | I19: =SUMIFS(ar6_r10!$F$2:$F$999,ar6_r10!$A$2:$A$999,Veda!$E$5,ar6_r10!$C$2:$C$999,Veda!I$17,ar6_r10!$M$2:$M$999,Veda!$G19) -> 0.36 | J19: =SUMIFS(ar6_r10!$F$2:$F$999,ar6_r10!$A$2:$A$999,Veda!$E$5,ar6_r10!$C$2:$C$999,Veda!J$17,ar6_r10!$M$2:$M$999,Veda!$G19) -> 0.32 | K19: =SUMIFS(ar6_r10!$F$2:$F$999,ar6_r10!$A$2:$A$999,Veda!$E$5,ar6_r10!$C$2:$C$999,Veda!K$17,ar6_r10!$M$2:$M$999,Veda!$G19) -> 0.31 | L19: =SUMIFS(ar6_r10!$F$2:$F$999,ar6_r10!$A$2:$A$999,Veda!$E$5,ar6_r10!$C$2:$C$999,Veda!L$17,ar6_r10!$M$2:$M$999,Veda!$G19) -> 0.29 | M19: =SUMIFS(ar6_r10!$F$2:$F$999,ar6_r10!$A$2:$A$999,Veda!$E$5,ar6_r10!$C$2:$C$999,Veda!M$17,ar6_r10!$M$2:$M$999,Veda!$G19) -> 0.29 | N19: =SUMIFS(ar6_r10!$F$2:$F$999,ar6_r10!$A$2:$A$999,Veda!$E$5,ar6_r10!$C$2:$C$999,Veda!N$17,ar6_r10!$M$2:$M$999,Veda!$G19) -> 0.29 | O19: =SUMIFS(ar6_r10!$F$2:$F$999,ar6_r10!$A$2:$A$999,Veda!$E$5,ar6_r10!$C$2:$C$999,Veda!O$17,ar6_r10!$M$2:$M$999,Veda!$G19) -> 0.3 | S19: elc_industry | T19: =I19*T$14 -> 2.6316 | U19: =J19*U$14 -> 2.45616 | V19: =K19*V$14 -> 2.651337 | W19: =L19*W$14 -> 2.798268 | X19: =M19*X$14 -> 3.17985 | Y19: =N19*Y$14 -> 3.561432 | Z19: =O19*Z$14 -> 3.96933 | AA19: demand | AG19: 11 | AH19: s3p3v3_d | AI19: d9d | AJ19: =AJ14+1 -> 3
A20: 5 | B20: =VLOOKUP(E20,$AK$9:$AL$15,2,FALSE)&"."&VLOOKUP(D20,$AH$9:$AI$24,2,FALSE) -> d 1.5 deg OS.j12 | C20: =C19+1 -> 12 | D20: =VLOOKUP(AJ20,$AG$9:$AH$22,2,FALSE) -> ts_012 | E20: =E15 -> C2 | G20: Residential and commercial electricity share | I20: =SUMIFS(ar6_r10!$F$2:$F$999,ar6_r10!$A$2:$A$999,Veda!$E$5,ar6_r10!$C$2:$C$999,Veda!I$17,ar6_r10!$M$2:$M$999,Veda!$G20) -> 0.6 | J20: =SUMIFS(ar6_r10!$F$2:$F$999,ar6_r10!$A$2:$A$999,Veda!$E$5,ar6_r10!$C$2:$C$999,Veda!J$17,ar6_r10!$M$2:$M$999,Veda!$G20) -> 0.6 | K20: =SUMIFS(ar6_r10!$F$2:$F$999,ar6_r10!$A$2:$A$999,Veda!$E$5,ar6_r10!$C$2:$C$999,Veda!K$17,ar6_r10!$M$2:$M$999,Veda!$G20) -> 0.6 | L20: =SUMIFS(ar6_r10!$F$2:$F$999,ar6_r10!$A$2:$A$999,Veda!$E$5,ar6_r10!$C$2:$C$999,Veda!L$17,ar6_r10!$M$2:$M$999,Veda!$G20) -> 0.57 | M20: =SUMIFS(ar6_r10!$F$2:$F$999,ar6_r10!$A$2:$A$999,Veda!$E$5,ar6_r10!$C$2:$C$999,Veda!M$17,ar6_r10!$M$2:$M$999,Veda!$G20) -> 0.54 | N20: =SUMIFS(ar6_r10!$F$2:$F$999,ar6_r10!$A$2:$A$999,Veda!$E$5,ar6_r10!$C$2:$C$999,Veda!N$17,ar6_r10!$M$2:$M$999,Veda!$G20) -> 0.52 | O20: =SUMIFS(ar6_r10!$F$2:$F$999,ar6_r10!$A$2:$A$999,Veda!$E$5,ar6_r10!$C$2:$C$999,Veda!O$17,ar6_r10!$M$2:$M$999,Veda!$G20) -> 0.53 | S20: elc_buildings | T20: =I20*T$14 -> 4.386 | U20: =J20*U$14 -> 4.6053 | V20: =K20*V$14 -> 5.13162 | W20: =L20*W$14 -> 5.500044 | X20: =M20*X$14 -> 5.9211 | Y20: =N20*Y$14 -> 6.386016 | Z20: =O20*Z$14 -> 7.012483 | AA20: demand | AG20: 12 | AH20: s5p5v5_d | AI20: c15d | AJ20: =AJ15+1 -> 3
A21: 5 | B21: =VLOOKUP(E21,$AK$9:$AL$15,2,FALSE)&"."&VLOOKUP(D21,$AH$9:$AI$24,2,FALSE) -> c 2 deg (67%).j12 | C21: =C20+1 -> 13 | D21: =VLOOKUP(AJ21,$AG$9:$AH$22,2,FALSE) -> ts_012 | E21: =E16 -> C3 | G21: Transportation electricity share | I21: =SUMIFS(ar6_r10!$F$2:$F$999,ar6_r10!$A$2:$A$999,Veda!$E$5,ar6_r10!$C$2:$C$999,Veda!I$17,ar6_r10!$M$2:$M$999,Veda!$G21) -> 0.03 | J21: =SUMIFS(ar6_r10!$F$2:$F$999,ar6_r10!$A$2:$A$999,Veda!$E$5,ar6_r10!$C$2:$C$999,Veda!J$17,ar6_r10!$M$2:$M$999,Veda!$G21) -> 0.06 | K21: =SUMIFS(ar6_r10!$F$2:$F$999,ar6_r10!$A$2:$A$999,Veda!$E$5,ar6_r10!$C$2:$C$999,Veda!K$17,ar6_r10!$M$2:$M$999,Veda!$G21) -> 0.08 | L21: =SUMIFS(ar6_r10!$F$2:$F$999,ar6_r10!$A$2:$A$999,Veda!$E$5,ar6_r10!$C$2:$C$999,Veda!L$17,ar6_r10!$M$2:$M$999,Veda!$G21) -> 0.11 | M21: =SUMIFS(ar6_r10!$F$2:$F$999,ar6_r10!$A$2:$A$999,Veda!$E$5,ar6_r10!$C$2:$C$999,Veda!M$17,ar6_r10!$M$2:$M$999,Veda!$G21) -> 0.12 | N21: =SUMIFS(ar6_r10!$F$2:$F$999,ar6_r10!$A$2:$A$999,Veda!$E$5,ar6_r10!$C$2:$C$999,Veda!N$17,ar6_r10!$M$2:$M$999,Veda!$G21) -> 0.18 | O21: =SUMIFS(ar6_r10!$F$2:$F$999,ar6_r10!$A$2:$A$999,Veda!$E$5,ar6_r10!$C$2:$C$999,Veda!O$17,ar6_r10!$M$2:$M$999,Veda!$G21) -> 0.19 | S21: elc_transport | T21: =I21*T$14 -> 0.2193 | U21: =T21 -> 0.2193 | V21: =U21 -> 0.2193 | W21: =V21 -> 0.2193 | X21: =W21 -> 0.2193 | Y21: =X21 -> 0.2193 | Z21: =Y21 -> 0.2193 | AA21: demand | AC21: non-road transport demand assumed to be constant | AG21: 13 | AH21: s2_w | AI21: b2w | AJ21: =AJ16+1 -> 3
A22: 5 | B22: =VLOOKUP(E22,$AK$9:$AL$15,2,FALSE)&"."&VLOOKUP(D22,$AH$9:$AI$24,2,FALSE) -> b 2 deg (50%).j12 | C22: =C21+1 -> 14 | D22: =VLOOKUP(AJ22,$AG$9:$AH$22,2,FALSE) -> ts_012 | E22: =E17 -> C4 | S22: elc_roadtransport | T22: =T14-SUM(T19:T21) -> 0.0731 | U22: =U14-SUM(U19:U21) -> 0.39474 | V22: =V14-SUM(V19:V21) -> 0.550443 | W22: =W14-SUM(W19:W21) -> 1.131588 | X22: =X14-SUM(X19:X21) -> 1.64475 | Y22: =Y14-SUM(Y19:Y21) -> 2.114052 | Z22: =Z14-SUM(Z19:Z21) -> 2.029987 | AA22: demand | AG22: 14 | AH22: s2_w_p2_d | AI22: a2w2d | AJ22: =AJ17+1 -> 3
A23: 5 | B23: =VLOOKUP(E23,$AK$9:$AL$15,2,FALSE)&"."&VLOOKUP(D23,$AH$9:$AI$24,2,FALSE) -> a 3 deg.j12 | C23: =C22+1 -> 15 | D23: =VLOOKUP(AJ23,$AG$9:$AH$22,2,FALSE) -> ts_012 | E23: =E18 -> C7 | S23: * | AJ23: =AJ18+1 -> 3
A24: 5 | B24: =VLOOKUP(E24,$AK$9:$AL$15,2,FALSE)&"."&VLOOKUP(D24,$AH$9:$AI$24,2,FALSE) -> e 1.5 deg no OS.i24 | C24: =C23+1 -> 16 | D24: =VLOOKUP(AJ24,$AG$9:$AH$22,2,FALSE) -> ts_024 | E24: =E19 -> C1 | G24: CO2 price | I24: 0 | J24: 0 | K24: =SUMIFS(ar6_r10!$F$2:$F$999,ar6_r10!$A$2:$A$999,Veda!$E$5,ar6_r10!$C$2:$C$999,Veda!K$17,ar6_r10!$M$2:$M$999,Veda!$G24) -> 71.48 | L24: =SUMIFS(ar6_r10!$F$2:$F$999,ar6_r10!$A$2:$A$999,Veda!$E$5,ar6_r10!$C$2:$C$999,Veda!L$17,ar6_r10!$M$2:$M$999,Veda!$G24) -> 104.42 | M24: =SUMIFS(ar6_r10!$F$2:$F$999,ar6_r10!$A$2:$A$999,Veda!$E$5,ar6_r10!$C$2:$C$999,Veda!M$17,ar6_r10!$M$2:$M$999,Veda!$G24) -> 134.85 | N24: =SUMIFS(ar6_r10!$F$2:$F$999,ar6_r10!$A$2:$A$999,Veda!$E$5,ar6_r10!$C$2:$C$999,Veda!N$17,ar6_r10!$M$2:$M$999,Veda!$G24) -> 178.1 | O24: =SUMIFS(ar6_r10!$F$2:$F$999,ar6_r10!$A$2:$A$999,Veda!$E$5,ar6_r10!$C$2:$C$999,Veda!O$17,ar6_r10!$M$2:$M$999,Veda!$G24) -> 209.45 | S24: co2net | U24: 0 | V24: =K24/1000 -> 0.07148 | W24: =L24/1000 -> 0.10442 | X24: =M24/1000 -> 0.13485 | Y24: =N24/1000 -> 0.1781 | Z24: =O24/1000 -> 0.20945 | AA24: com_taxnet | AJ24: =AJ19+1 -> 4
A25: 5 | B25: =VLOOKUP(E25,$AK$9:$AL$15,2,FALSE)&"."&VLOOKUP(D25,$AH$9:$AI$24,2,FALSE) -> d 1.5 deg OS.i24 | C25: =C24+1 -> 17 | D25: =VLOOKUP(AJ25,$AG$9:$AH$22,2,FALSE) -> ts_024 | E25: =E20 -> C2 | AJ25: =AJ20+1 -> 4
A26: 5 | B26: =VLOOKUP(E26,$AK$9:$AL$15,2,FALSE)&"."&VLOOKUP(D26,$AH$9:$AI$24,2,FALSE) -> c 2 deg (67%).i24 | C26: =C25+1 -> 18 | D26: =VLOOKUP(AJ26,$AG$9:$AH$22,2,FALSE) -> ts_024 | E26: =E21 -> C3 | S26: ~TFM_INS-TS | AJ26: =AJ21+1 -> 4
A27: 5 | B27: =VLOOKUP(E27,$AK$9:$AL$15,2,FALSE)&"."&VLOOKUP(D27,$AH$9:$AI$24,2,FALSE) -> b 2 deg (50%).i24 | C27: =C26+1 -> 19 | D27: =VLOOKUP(AJ27,$AG$9:$AH$22,2,FALSE) -> ts_024 | E27: =E22 -> C4 | S27: process | T27: =T17 -> 2022 | U27: =U17 -> 2025 | V27: =V17 -> 2030 | W27: =W17 -> 2035 | X27: =X17 -> 2040 | Y27: =Y17 -> 2045 | Z27: =Z17 -> 2050 | AA27: attribute | AB27: limtype | AJ27: =AJ22+1 -> 4
A28: 5 | B28: =VLOOKUP(E28,$AK$9:$AL$15,2,FALSE)&"."&VLOOKUP(D28,$AH$9:$AI$24,2,FALSE) -> a 3 deg.i24 | C28: =C27+1 -> 20 | D28: =VLOOKUP(AJ28,$AG$9:$AH$22,2,FALSE) -> ts_024 | E28: =E23 -> C7 | Q28: =SUMIFS(iea_data!G3:G9999,iea_data!$B$3:$B$9999,Veda!$S$11) -> 5.31 | S28: Trd_electricity import | T28: =Q28 -> 5.31 | AA28: ACT_BND | AB28: FX | AJ28: =AJ23+1 -> 4
A29: 5 | B29: =VLOOKUP(E29,$AK$9:$AL$15,2,FALSE)&"."&VLOOKUP(D29,$AH$9:$AI$24,2,FALSE) -> e 1.5 deg no OS.h48 | C29: =C28+1 -> 21 | D29: =VLOOKUP(AJ29,$AG$9:$AH$22,2,FALSE) -> ts_048 | E29: =E24 -> C1 | Q29: =SUMIFS(iea_data!H3:H9999,iea_data!$B$3:$B$9999,Veda!$S$11) -> -3 | S29: Trd_electricity export | T29: =-1*Q29 -> 3 | AA29: ACT_BND | AB29: FX | AJ29: =AJ24+1 -> 5
A30: 5 | B30: =VLOOKUP(E30,$AK$9:$AL$15,2,FALSE)&"."&VLOOKUP(D30,$AH$9:$AI$24,2,FALSE) -> d 1.5 deg OS.h48 | C30: =C29+1 -> 22 | D30: =VLOOKUP(AJ30,$AG$9:$AH$22,2,FALSE) -> ts_048 | E30: =E25 -> C2 | AJ30: =AJ25+1 -> 5
A31: 5 | B31: =VLOOKUP(E31,$AK$9:$AL$15,2,FALSE)&"."&VLOOKUP(D31,$AH$9:$AI$24,2,FALSE) -> c 2 deg (67%).h48 | C31: =C30+1 -> 23 | D31: =VLOOKUP(AJ31,$AG$9:$AH$22,2,FALSE) -> ts_048 | E31: =E26 -> C3 | AJ31: =AJ26+1 -> 5
A32: 5 | B32: =VLOOKUP(E32,$AK$9:$AL$15,2,FALSE)&"."&VLOOKUP(D32,$AH$9:$AI$24,2,FALSE) -> b 2 deg (50%).h48 | C32: =C31+1 -> 24 | D32: =VLOOKUP(AJ32,$AG$9:$AH$22,2,FALSE) -> ts_048 | E32: =E27 -> C4 | AJ32: =AJ27+1 -> 5
A33: 5 | B33: =VLOOKUP(E33,$AK$9:$AL$15,2,FALSE)&"."&VLOOKUP(D33,$AH$9:$AI$24,2,FALSE) -> a 3 deg.h48 | C33: =C32+1 -> 25 | D33: =VLOOKUP(AJ33,$AG$9:$AH$22,2,FALSE) -> ts_048 | E33: =E28 -> C7 | AJ33: =AJ28+1 -> 5
A34: 5 | B34: =VLOOKUP(E34,$AK$9:$AL$15,2,FALSE)&"."&VLOOKUP(D34,$AH$9:$AI$24,2,FALSE) -> e 1.5 deg no OS.g64 | C34: =C33+1 -> 26 | D34: =VLOOKUP(AJ34,$AG$9:$AH$22,2,FALSE) -> ts_064 | E34: =E29 -> C1 | AJ34: =AJ29+1 -> 6
A35: 5 | B35: =VLOOKUP(E35,$AK$9:$AL$15,2,FALSE)&"."&VLOOKUP(D35,$AH$9:$AI$24,2,FALSE) -> d 1.5 deg OS.g64 | C35: =C34+1 -> 27 | D35: =VLOOKUP(AJ35,$AG$9:$AH$22,2,FALSE) -> ts_064 | E35: =E30 -> C2 | AJ35: =AJ30+1 -> 6
A36: 5 | B36: =VLOOKUP(E36,$AK$9:$AL$15,2,FALSE)&"."&VLOOKUP(D36,$AH$9:$AI$24,2,FALSE) -> c 2 deg (67%).g64 | C36: =C35+1 -> 28 | D36: =VLOOKUP(AJ36,$AG$9:$AH$22,2,FALSE) -> ts_064 | E36: =E31 -> C3 | G36: C7 | AJ36: =AJ31+1 -> 6
A37: 5 | B37: =VLOOKUP(E37,$AK$9:$AL$15,2,FALSE)&"."&VLOOKUP(D37,$AH$9:$AI$24,2,FALSE) -> b 2 deg (50%).g64 | C37: =C36+1 -> 29 | D37: =VLOOKUP(AJ37,$AG$9:$AH$22,2,FALSE) -> ts_064 | E37: =E32 -> C4 | G37: Gas Price | I37: =SUMIFS(ar6_r10!$F$2:$F$999,ar6_r10!$A$2:$A$999,Veda!$G$36,ar6_r10!$C$2:$C$999,Veda!I$17,ar6_r10!$M$2:$M$999,Veda!$G37) -> 1 | J37: =SUMIFS(ar6_r10!$F$2:$F$999,ar6_r10!$A$2:$A$999,Veda!$G$36,ar6_r10!$C$2:$C$999,Veda!J$17,ar6_r10!$M$2:$M$999,Veda!$G37) -> 1.07 | K37: =SUMIFS(ar6_r10!$F$2:$F$999,ar6_r10!$A$2:$A$999,Veda!$G$36,ar6_r10!$C$2:$C$999,Veda!K$17,ar6_r10!$M$2:$M$999,Veda!$G37) -> 1.24 | L37: =SUMIFS(ar6_r10!$F$2:$F$999,ar6_r10!$A$2:$A$999,Veda!$G$36,ar6_r10!$C$2:$C$999,Veda!L$17,ar6_r10!$M$2:$M$999,Veda!$G37) -> 1.15 | M37: =SUMIFS(ar6_r10!$F$2:$F$999,ar6_r10!$A$2:$A$999,Veda!$G$36,ar6_r10!$C$2:$C$999,Veda!M$17,ar6_r10!$M$2:$M$999,Veda!$G37) -> 1.25 | N37: =SUMIFS(ar6_r10!$F$2:$F$999,ar6_r10!$A$2:$A$999,Veda!$G$36,ar6_r10!$C$2:$C$999,Veda!N$17,ar6_r10!$M$2:$M$999,Veda!$G37) -> 1.17 | O37: =SUMIFS(ar6_r10!$F$2:$F$999,ar6_r10!$A$2:$A$999,Veda!$G$36,ar6_r10!$C$2:$C$999,Veda!O$17,ar6_r10!$M$2:$M$999,Veda!$G37) -> 1.34 | AJ37: =AJ32+1 -> 6
A38: 5 | B38: =VLOOKUP(E38,$AK$9:$AL$15,2,FALSE)&"."&VLOOKUP(D38,$AH$9:$AI$24,2,FALSE) -> a 3 deg.g64 | C38: =C37+1 -> 30 | D38: =VLOOKUP(AJ38,$AG$9:$AH$22,2,FALSE) -> ts_064 | E38: =E33 -> C7 | G38: Coal Price | I38: =SUMIFS(ar6_r10!$F$2:$F$999,ar6_r10!$A$2:$A$999,Veda!$G$36,ar6_r10!$C$2:$C$999,Veda!I$17,ar6_r10!$M$2:$M$999,Veda!$G38) -> 1 | J38: =SUMIFS(ar6_r10!$F$2:$F$999,ar6_r10!$A$2:$A$999,Veda!$G$36,ar6_r10!$C$2:$C$999,Veda!J$17,ar6_r10!$M$2:$M$999,Veda!$G38) -> 1.02 | K38: =SUMIFS(ar6_r10!$F$2:$F$999,ar6_r10!$A$2:$A$999,Veda!$G$36,ar6_r10!$C$2:$C$999,Veda!K$17,ar6_r10!$M$2:$M$999,Veda!$G38) -> 1.06 | L38: =SUMIFS(ar6_r10!$F$2:$F$999,ar6_r10!$A$2:$A$999,Veda!$G$36,ar6_r10!$C$2:$C$999,Veda!L$17,ar6_r10!$M$2:$M$999,Veda!$G38) -> 1.07 | M38: =SUMIFS(ar6_r10!$F$2:$F$999,ar6_r10!$A$2:$A$999,Veda!$G$36,ar6_r10!$C$2:$C$999,Veda!M$17,ar6_r10!$M$2:$M$999,Veda!$G38) -> 1.08 | N38: =SUMIFS(ar6_r10!$F$2:$F$999,ar6_r10!$A$2:$A$999,Veda!$G$36,ar6_r10!$C$2:$C$999,Veda!N$17,ar6_r10!$M$2:$M$999,Veda!$G38) -> 1.1 | O38: =SUMIFS(ar6_r10!$F$2:$F$999,ar6_r10!$A$2:$A$999,Veda!$G$36,ar6_r10!$C$2:$C$999,Veda!O$17,ar6_r10!$M$2:$M$999,Veda!$G38) -> 1.12 | AJ38: =AJ33+1 -> 6
A39: 5 | B39: =VLOOKUP(E39,$AK$9:$AL$15,2,FALSE)&"."&VLOOKUP(D39,$AH$9:$AI$24,2,FALSE) -> e 1.5 deg no OS.f96p50 | C39: =C38+1 -> 31 | D39: =VLOOKUP(AJ39,$AG$9:$AH$22,2,FALSE) -> ts_096P50 | E39: =E34 -> C1 | G39: Oil Price | I39: =SUMIFS(ar6_r10!$F$2:$F$999,ar6_r10!$A$2:$A$999,Veda!$G$36,ar6_r10!$C$2:$C$999,Veda!I$17,ar6_r10!$M$2:$M$999,Veda!$G39) -> 1 | J39: =SUMIFS(ar6_r10!$F$2:$F$999,ar6_r10!$A$2:$A$999,Veda!$G$36,ar6_r10!$C$2:$C$999,Veda!J$17,ar6_r10!$M$2:$M$999,Veda!$G39) -> 1.01 | K39: =SUMIFS(ar6_r10!$F$2:$F$999,ar6_r10!$A$2:$A$999,Veda!$G$36,ar6_r10!$C$2:$C$999,Veda!K$17,ar6_r10!$M$2:$M$999,Veda!$G39) -> 1.11 | L39: =SUMIFS(ar6_r10!$F$2:$F$999,ar6_r10!$A$2:$A$999,Veda!$G$36,ar6_r10!$C$2:$C$999,Veda!L$17,ar6_r10!$M$2:$M$999,Veda!$G39) -> 1.01 | M39: =SUMIFS(ar6_r10!$F$2:$F$999,ar6_r10!$A$2:$A$999,Veda!$G$36,ar6_r10!$C$2:$C$999,Veda!M$17,ar6_r10!$M$2:$M$999,Veda!$G39) -> 1.01 | N39: =SUMIFS(ar6_r10!$F$2:$F$999,ar6_r10!$A$2:$A$999,Veda!$G$36,ar6_r10!$C$2:$C$999,Veda!N$17,ar6_r10!$M$2:$M$999,Veda!$G39) -> 1.04 | O39: =SUMIFS(ar6_r10!$F$2:$F$999,ar6_r10!$A$2:$A$999,Veda!$G$36,ar6_r10!$C$2:$C$999,Veda!O$17,ar6_r10!$M$2:$M$999,Veda!$G39) -> 1.14 | AJ39: =AJ34+1 -> 7
A40: 5 | B40: =VLOOKUP(E40,$AK$9:$AL$15,2,FALSE)&"."&VLOOKUP(D40,$AH$9:$AI$24,2,FALSE) -> d 1.5 deg OS.f96p50 | C40: =C39+1 -> 32 | D40: =VLOOKUP(AJ40,$AG$9:$AH$22,2,FALSE) -> ts_096P50 | E40: =E35 -> C2 | G40: Biomass Price | I40: =SUMIFS(ar6_r10!$F$2:$F$999,ar6_r10!$A$2:$A$999,Veda!$G$36,ar6_r10!$C$2:$C$999,Veda!I$17,ar6_r10!$M$2:$M$999,Veda!$G40) -> 1 | J40: =SUMIFS(ar6_r10!$F$2:$F$999,ar6_r10!$A$2:$A$999,Veda!$G$36,ar6_r10!$C$2:$C$999,Veda!J$17,ar6_r10!$M$2:$M$999,Veda!$G40) -> 0.96 | K40: =SUMIFS(ar6_r10!$F$2:$F$999,ar6_r10!$A$2:$A$999,Veda!$G$36,ar6_r10!$C$2:$C$999,Veda!K$17,ar6_r10!$M$2:$M$999,Veda!$G40) -> 1.04 | L40: =SUMIFS(ar6_r10!$F$2:$F$999,ar6_r10!$A$2:$A$999,Veda!$G$36,ar6_r10!$C$2:$C$999,Veda!L$17,ar6_r10!$M$2:$M$999,Veda!$G40) -> 1.04 | M40: =SUMIFS(ar6_r10!$F$2:$F$999,ar6_r10!$A$2:$A$999,Veda!$G$36,ar6_r10!$C$2:$C$999,Veda!M$17,ar6_r10!$M$2:$M$999,Veda!$G40) -> 0.98 | N40: =SUMIFS(ar6_r10!$F$2:$F$999,ar6_r10!$A$2:$A$999,Veda!$G$36,ar6_r10!$C$2:$C$999,Veda!N$17,ar6_r10!$M$2:$M$999,Veda!$G40) -> 0.99 | O40: =SUMIFS(ar6_r10!$F$2:$F$999,ar6_r10!$A$2:$A$999,Veda!$G$36,ar6_r10!$C$2:$C$999,Veda!O$17,ar6_r10!$M$2:$M$999,Veda!$G40) -> 1 | AJ40: =AJ35+1 -> 7
A41: 5 | B41: =VLOOKUP(E41,$AK$9:$AL$15,2,FALSE)&"."&VLOOKUP(D41,$AH$9:$AI$24,2,FALSE) -> c 2 deg (67%).f96p50 | C41: =C40+1 -> 33 | D41: =VLOOKUP(AJ41,$AG$9:$AH$22,2,FALSE) -> ts_096P50 | E41: =E36 -> C3 | AJ41: =AJ36+1 -> 7
A42: 5 | B42: =VLOOKUP(E42,$AK$9:$AL$15,2,FALSE)&"."&VLOOKUP(D42,$AH$9:$AI$24,2,FALSE) -> b 2 deg (50%).f96p50 | C42: =C41+1 -> 34 | D42: =VLOOKUP(AJ42,$AG$9:$AH$22,2,FALSE) -> ts_096P50 | E42: =E37 -> C4 | AJ42: =AJ37+1 -> 7
...

Sheet fuel_prices
A9: Fuel Prices
A10: iso | B10: gas_low | C10: gas_high | D10: coal_low | E10: coal_high | F10: oil_low | G10: oil_high | H10: bioenergy_low | I10: bioenergy_high | J10: Notes
A11: LVA | B11: 27.4 | C11: 39.4 | D11: 12.2 | E11: 15.2 | F11: 48 | G11: 58 | H11: 20 | I11: 28 | J11: Baltic market, forest resources

Sheet iea_data
A9: IEA Baseline Data
A10: iso | B10: year | C10: industry_twh | D10: buildings_agri_twh | E10: nonroad_transport_twh | F10: road_transport_twh | G10: imports_twh | H10: exports_twh | I10: total_production_twh
A11: LVA | B11: 2000 | C11: 2.91 | D11: 2.88 | E11: 0.04 | F11: 0.08 | G11: 2.11 | H11: -0.32 | I11: 4.14
A12: LVA | B12: 2001 | C12: 3.19 | D12: 2.84 | E12: 0.04 | F12: 0.08 | G12: 2.34 | H12: -0.46 | I12: 4.28
A13: LVA | B13: 2002 | C13: 3 | D13: 3.19 | E13: 0.04 | F13: 0.08 | G13: 2.84 | H13: -0.49 | I13: 3.98
A14: LVA | B14: 2003 | C14: 3.03 | D14: 3.44 | E14: 0.04 | F14: 0.08 | G14: 2.67 | H14: -0.04 | I14: 3.98
A15: LVA | B15: 2004 | C15: 3.04 | D15: 3.61 | E15: 0.04 | F15: 0.08 | G15: 2.73 | H15: -0.64 | I15: 4.69
A16: LVA | B16: 2005 | C16: 3.05 | D16: 3.86 | E16: 0.04 | F16: 0.08 | G16: 2.85 | H16: -0.71 | I16: 4.91
A17: LVA | B17: 2006 | C17: 3.04 | D17: 4.22 | E17: 0.04 | F17: 0.08 | G17: 2.81 | H17: -0.3 | I17: 4.89
A18: LVA | B18: 2007 | C18: 3 | D18: 4.63 | E18: 0.04 | F18: 0.08 | G18: 4.96 | H18: -1.96 | I18: 4.77
A19: LVA | B19: 2008 | C19: 2.87 | D19: 4.79 | E19: 0.04 | F19: 0.08 | G19: 4.64 | H19: -2.12 | I19: 5.27
A20: LVA | B20: 2009 | C20: 2.64 | D20: 4.46 | E20: 0.04 | F20: 0.07 | G20: 4.26 | H20: -2.61 | I20: 5.57
A21: LVA | B21: 2010 | C21: 2.89 | D21: 4.49 | E21: 0.04 | F21: 0.07 | G21: 3.97 | H21: -3.1 | I21: 6.63
A22: LVA | B22: 2011 | C22: 2.83 | D22: 4.39 | E22: 0.04 | F22: 0.07 | G22: 4.01 | H22: -2.76 | I22: 6.09
... A33: LVA | B33: 2022 | C33: 2.44 | D33: 4.5 | E33: 0.06 | F33: 0.03 | G33: 5.31 | H33: -3 | I33: 5

Sheet ar6_r10
A9: AR6 Scenario Drivers
A10: Category | B10: Region | C10: Year | D10: count | E10: mean | F10: median | G10: std | H10: min | I10: max | J10: q25 | K10: q75 | L10: category_description | M10: attribute
A11: C1 | B11: R10EUROPE | C11: 2020 | D11: 60 | E11: 8.68 | F11: 6.87 | G11: 10.43 | H11: 0 | I11: 55.17 | J11: 0 | K11: 13.64 | L11: Limit warming to 1.5°C (>50%) with no or limited overshoot | M11: CO2 price
A12: C1 | B12: R10EUROPE | C12: 2025 | D12: 60 | E12: 190.52 | F12: 181.51 | G12: 136.23 | H12: 1.81 | I12: 626.48 | J12: 115.48 | K12: 238.58 | L12: Limit warming to 1.5°C (>50%) with no or limited overshoot | M12: CO2 price
A13: C1 | B13: R10EUROPE | C13: 2030 | D13: 60 | E13: 268.18 | F13: 241.69 | G13: 134.29 | H13: 1.27 | I13: 673.46 | J13: 182.47 | K13: 329.7 | L13: Limit warming to 1.5°C (>50%) with no or limited overshoot | M13: CO2 price
A14: C1 | B14: R10EUROPE | C14: 2035 | D14: 60 | E14: 363.27 | F14: 339.03 | G14: 173.79 | H14: 14.37 | I14: 859.53 | J14: 227.05 | K14: 483.38 | L14: Limit warming to 1.5°C (>50%) with no or limited overshoot | M14: CO2 price
A15: C1 | B15: R10EUROPE | C15: 2040 | D15: 60 | E15: 471.65 | F15: 410.28 | G15: 224.31 | H15: 162.1 | I15: 1097.01 | J15: 298.63 | K15: 622.14 | L15: Limit warming to 1.5°C (>50%) with no or limited overshoot | M15: CO2 price
A16: C1 | B16: R10EUROPE | C16: 2045 | D16: 60 | E16: 565.69 | F16: 494.2 | G16: 256.15 | H16: 193.42 | I16: 1269.88 | J16: 352.78 | K16: 748.01 | L16: Limit warming to 1.5°C (>50%) with no or limited overshoot | M16: CO2 price
A17: C1 | B17: R10EUROPE | C17: 2050 | D17: 60 | E17: 647.44 | F17: 635.43 | G17: 273.56 | H17: 209.76 | I17: 1170.26 | J17: 409.79 | K17: 887.68 | L17: Limit warming to 1.5°C (>50%) with no or limited overshoot | M17: CO2 price
A18: C2 | B18: R10EUROPE | C18: 2020 | D18: 86 | E18: 6.44 | F18: 0 | G18: 8.34 | H18: 0 | I18: 24.5 | J18: 0 | K18: 12.68 | L18: Limit warming to 1.5°C (>67%) with high overshoot | M18: CO2 price
A19: C2 | B19: R10EUROPE | C19: 2025 | D19: 75 | E19: 63.21 | F19: 44.89 | G19: 56.62 | H19: 3.21 | I19: 273 | J19: 27.09 | K19: 77.31 | L19: Limit warming to 1.5°C (>67%) with high overshoot | M19: CO2 price
A20: C2 | B20: R10EUROPE | C20: 2030 | D20: 86 | E20: 85.48 | F20: 63.36 | G20: 73.46 | H20: 0 | I20: 409.5 | J20: 50 | K20: 111.1 | L20: Limit warming to 1.5°C (>67%) with high overshoot | M20: CO2 price
A21: C2 | B21: R10EUROPE | C21: 2035 | D21: 75 | E21: 208.71 | F21: 154.82 | G21: 291.78 | H21: 60.83 | I21: 2037.12 | J21: 93.79 | K21: 206.26 | L21: Limit warming to 1.5°C (>67%) with high overshoot | M21: CO2 price
A22: C2 | B22: R10EUROPE | C22: 2040 | D22: 86 | E22: 253.33 | F22: 172.09 | G22: 359.35 | H22: 0 | I22: 2600 | J22: 119.07 | K22: 259.4 | L22: Limit warming to 1.5°C (>67%) with high overshoot | M22: CO2 price
... A221: C1 | B221: R10EUROPE | C221: 2020 | D221: 33 | E221: 1 | F221: 1 | G221: 0 | H221: 1 | I221: 1 | J221: 1 | K221: 1 | L221: Limit warming to 1.5°C (>50%) with no or limited overshoot | M221: Gas price
A222: C1 | B222: R10EUROPE | C222: 2025 | D222: 34 | E222: 65535 | F222: 2.42 | H222: 1.18 | I222: 65535 | J222: 2.01 | K222: 2.75 | L222: Limit warming to 1.5°C (>50%) with no or limited overshoot | M222: Gas price
A223: C1 | B223: R10EUROPE | C223: 2030 | D223: 34 | E223: 65535 | F223: 3.1 | H223: 1.71 | I223: 65535 | J223: 2.38 | K223: 3.46 | L223: Limit warming to 1.5°C (>50%) with no or limited overshoot | M223: Gas price
A224: C1 | B224: R10EUROPE | C224: 2035 | D224: 34 | E224: 65535 | F224: 3.54 | H224: 1.91 | I224: 65535 | J224: 2.66 | K224: 4.16 | L224: Limit warming to 1.5°C (>50%) with no or limited overshoot | M224: Gas price
A225: C1 | B225: R10EUROPE | C225: 2040 | D225: 34 | E225: 65535 | F225: 4.1 | H225: 2.27 | I225: 65535 | J225: 2.96 | K225: 4.52 | L225: Limit warming to 1.5°C (>50%) with no or limited overshoot | M225: Gas price
A226: C1 | B226: R10EUROPE | C226: 2045 | D226: 34 | E226: 65535 | F226: 3.86 | H226: 2.54 | I226: 65535 | J226: 3.3 | K226: 4.89 | L226: Limit warming to 1.5°C (>50%) with no or limited overshoot | M226: Gas price
A227: C1 | B227: R10EUROPE | C227: 2050 | D227: 34 | E227: 65535 | F227: 3.59 | H227: 2.73 | I227: 65535 | J227: 3.07 | K227: 4.06 | L227: Limit warming to 1.5°C (>50%) with no or limited overshoot | M227: Gas price
A228: C2 | B228: R10EUROPE | C228: 2020 | D228: 43 | E228: 1 | F228: 1 | G228: 0 | H228: 1 | I228: 1 | J228: 1 | K228: 1 | L228: Limit warming to 1.5°C (>67%) with high overshoot | M228: Gas price
A229: C2 | B229: R10EUROPE | C229: 2025 | D229: 44 | E229: 65535 | F229: 1.22 | H229: 0 | I229: 65535 | J229: 1.13 | K229: 1.35 | L229: Limit warming to 1.5°C (>67%) with high overshoot | M229: Gas price
A230: C2 | B230: R10EUROPE | C230: 2030 | D230: 44 | E230: 65535 | F230: 1.5 | H230: 0 | I230: 65535 | J230: 1.31 | K230: 1.83 | L230: Limit warming to 1.5°C (>67%) with high overshoot | M230: Gas price
A231: C2 | B231: R10EUROPE | C231: 2035 | D231: 44 | E231: 65535 | F231: 2.12 | H231: 0 | I231: 65535 | J231: 1.68 | K231: 2.46 | L231: Limit warming to 1.5°C (>67%) with high overshoot | M231: Gas price
A232: C2 | B232: R10EUROPE | C232: 2040 | D232: 44 | E232: 65535 | F232: 2.5 | H232: 0 | I232: 65535 | J232: 2 | K232: 2.94 | L232: Limit warming to 1.5°C (>67%) with high overshoot | M232: Gas price
A233: C2 | B233: R10EUROPE | C233: 2045 | D233: 44 | E233: 65535 | F233: 2.79 | H233: 0 | I233: 65535 | J233: 2.08 | K233: 3.44 | L233: Limit warming to 1.5°C (>67%) with high overshoot | M233: Gas price
A234: C2 | B234: R10EUROPE | C234: 2050 | D234: 44 | E234: 65535 | F234: 2.95 | H234: 0 | I234: 65535 | J234: 2.49 | K234: 3.78 | L234: Limit warming to 1.5°C (>67%) with high overshoot | M234: Gas price
A235: C3 | B235: R10EUROPE | C235: 2020 | D235: 103 | E235: 1 | F235: 1 | G235: 0 | H235: 1 | I235: 1 | J235: 1 | K235: 1 | L235: Limit warming to 2°C (>67%) with higher action post-2030 | M235: Gas price
A236: C3 | B236: R10EUROPE | C236: 2025 | D236: 112 | E236: 65535 | F236: 1.41 | H236: 0.98 | I236: 65535 | J236: 1.23 | K236: 1.96 | L236: Limit warming to 2°C (>67%) with higher action post-2030 | M236: Gas price
A237: C3 | B237: R10EUROPE | C237: 2030 | D237: 112 | E237: 65535 | F237: 2.04 | H237: 1.05 | I237: 65535 | J237: 1.52 | K237: 2.55 | L237: Limit warming to 2°C (>67%) with higher action post-2030 | M237: Gas price
A238: C3 | B238: R10EUROPE | C238: 2035 | D238: 112 | E238: 65535 | F238: 2.4 | H238: 1.05 | I238: 65535 | J238: 1.71 | K238: 3.14 | L238: Limit warming to 2°C (>67%) with higher action post-2030 | M238: Gas price
A239: C3 | B239: R10EUROPE | C239: 2040 | D239: 112 | E239: 65535 | F239: 2.6 | H239: 1.06 | I239: 65535 | J239: 1.85 | K239: 3.74 | L239: Limit warming to 2°C (>67%) with higher action post-2030 | M239: Gas price
A240: C3 | B240: R10EUROPE | C240: 2045 | D240: 112 | E240: 65535 | F240: 2.85 | H240: 1.08 | I240: 65535 | J240: 2 | K240: 4.28 | L240: Limit warming to 2°C (>67%) with higher action post-2030 | M240: Gas price
A241: C3 | B241: R10EUROPE | C241: 2050 | D241: 112 | E241: 65535 | F241: 2.97 | H241: 0 | I241: 65535 | J241: 2.15 | K241: 4.51 | L241: Limit warming to 2°C (>67%) with higher action post-2030 | M241: Gas price
A242: C4 | B242: R10EUROPE | C242: 2020 | D242: 27 | E242: 1 | F242: 1 | G242: 0 | H242: 1 | I242: 1 | J242: 1 | K242: 1 | L242: Limit warming to 2°C (>50%) with immediate action | M242: Gas price
A243: C4 | B243: R10EUROPE | C243: 2025 | D243: 27 | E243: 1.33 | F243: 1.31 | G243: 0.18 | H243: 1.06 | I243: 1.66 | J243: 1.22 | K243: 1.45 | L243: Limit warming to 2°C (>50%) with immediate action | M243: Gas price
A244: C4 | B244: R10EUROPE | C244: 2030 | D244: 27 | E244: 1.84 | F244: 2.02 | G244: 0.28 | H244: 1.24 | I244: 2.17 | J244: 1.52 | K244: 2.07 | L244: Limit warming to 2°C (>50%) with immediate action | M244: Gas price
A245: C4 | B245: R10EUROPE | C245: 2035 | D245: 27 | E245: 1.84 | F245: 1.96 | G245: 0.41 | H245: 1.19 | I245: 2.46 | J245: 1.42 | K245: 2.11 | L245: Limit warming to 2°C (>50%) with immediate action | M245: Gas price
A246: C4 | B246: R10EUROPE | C246: 2040 | D246: 27 | E246: 2.12 | F246: 2.22 | G246: 0.47 | H246: 1.41 | I246: 2.78 | J246: 1.54 | K246: 2.43 | L246: Limit warming to 2°C (>50%) with immediate action | M246: Gas price
...

Sheet ev_charging_uc
A10: =IFERROR(Veda!D5,"ts_12t") -> ts_annual | C10: day_night | D10: ts_annual | F10: day_night | G10: ts_12t
C11: D | D11: AllSaAllH | F11: D | G11: WaD,FaD,RaD,FaP,SaP,WaP,SaD,RaP
C12: N | D12: AllSaAllH | F12: N | G12: RaP,SaN,WaN,FaN,RaN,FaP,SaP,WaP
I17: 0.75 | K17: share of charging at night
C18: ~UC_Sets: R_E: AllRegions
H21: =IF(H23=H24,"Not Required!","~UC_T: LO") -> Not Required!
C22: UC_N | D22: Pset_CI | E22: Pset_CO | F22: pset_pn | G22: Cset_CN | H22: TimeSlice | I22: UC_FLO | J22: UC_RHSRT | K22: UC_RHSRT~0
C23: UC_bev night chg limit | D23: ELC | E23: =G23 -> AuxStoIN | F23: *EV* | G23: AuxStoIN | H23: =HLOOKUP($A$10,$D$10:$CU$12,3,FALSE) -> AllSaAllH | I23: =1+I24 -> 0.25 | J23: 0 | K23: 3 | M23: night
D24: ELC | E24: =G24 -> AuxStoIN | F24: *EV* | G24: AuxStoIN | H24: =HLOOKUP($A$10,$D$10:$CU$12,2,FALSE) -> AllSaAllH | I24: =-$I$17 -> -0.75 | M24: day

Sheet ts_annual
C9: =IF(A11="x","DeActivated","~TimeSlices") -> ~TimeSlices | I9: =IF(A11="x","DeActivated","~TFM_DINS-AT") -> ~TFM_DINS-AT | N9: =IF(A11="x","DeActivated","~TFM_DINS-AT") -> ~TFM_DINS-AT | S9: =IF(A11="x","DeActivated","~TFM_DINS-AT") -> ~TFM_DINS-AT | X9: =IF(A11="x","DeActivated","~TFM_DINS-AT") -> ~TFM_DINS-AT | AC9: =IF(A11="x","DeActivated","~TFM_DINS-AT") -> ~TFM_DINS-AT | AG9: =IF(A11="x","DeActivated","~TFM_DINS-AT") -> ~TFM_DINS-AT | AK9: =IF(A11="x","DeActivated","~TFM_INS-AT") -> ~TFM_INS-AT
A10: ts_annual | C10: season | D10: weekly | E10: daynite | F10: wparent | G10: dparent | I10: commodity | J10: timeslice | K10: com_fr | L10: process | N10: commodity | O10: timeslice | P10: com_fr | Q10: process | S10: commodity | T10: timeslice | U10: com_fr | V10: process | X10: g_yrfr | Y10: com_fr | Z10: timeslice | AA10: commodity | AC10: commodity | AD10: timeslice | AE10: com_fr | AG10: commodity | AH10: timeslice | AI10: com_pkflx | AK10: Year | AL10: timeslice | AM10: ncap_afs | AN10: pset_ci
A11: =IFERROR(IF(Veda!D5=A10,"ok","x"),"") -> ok | C11: AllS | D11: a | E11: AllH | F11: AllS | G11: a | I11: elc_spv_001 | J11: AllSaAllH | K11: 1 | L11: IMPNRGZ | N11: elc_won_001 | O11: AllSaAllH | P11: 1 | Q11: IMPNRGZ | S11: elc_wof_001 | T11: AllSaAllH | U11: 1 | V11: IMPNRGZ | X11: 1 | Y11: 1 | Z11: AllSaAllH | AA11: elc_roadtransport | AC11: elc_buildings | AD11: AllSaAllH | AE11: 1 | AG11: ELC | AH11: AllSaAllH | AI11: 0.33611115 | AK11: 2020 | AL11: AllS | AM11: 0.17999608 | AN11: hydro
I12: elc_spv_002 | J12: AllSaAllH | K12: 1 | L12: IMPNRGZ | N12: elc_won_002 | O12: AllSaAllH | P12: 1 | Q12: IMPNRGZ | S12: elc_wof_002 | T12: AllSaAllH | U12: 1 | V12: IMPNRGZ | AC12: elc_industry | AD12: AllSaAllH | AE12: 1 | AK12: 2021 | AL12: AllS | AM12: 0.18745518 | AN12: hydro
I13: elc_spv_003 | J13: AllSaAllH | K13: 1 | L13: IMPNRGZ | N13: elc_won_003 | O13: AllSaAllH | P13: 1 | Q13: IMPNRGZ | S13: elc_wof_003 | T13: AllSaAllH | U13: 1 | V13: IMPNRGZ | AK13: 2022 | AL13: AllS | AM13: 0.19272848 | AN13: hydro
I14: elc_spv_004 | J14: AllSaAllH | K14: 1 | L14: IMPNRGZ | N14: elc_won_004 | O14: AllSaAllH | P14: 1 | Q14: IMPNRGZ | S14: elc_wof_004 | T14: AllSaAllH | U14: 1 | V14: IMPNRGZ
I15: elc_spv_005 | J15: AllSaAllH | K15: 1 | L15: IMPNRGZ | N15: elc_won_005 | O15: AllSaAllH | P15: 1 | Q15: IMPNRGZ | S15: elc_wof_005 | T15: AllSaAllH | U15: 1 | V15: IMPNRGZ
I16: elc_spv_006 | J16: AllSaAllH | K16: 1 | L16: IMPNRGZ | N16: elc_won_006 | O16: AllSaAllH | P16: 1 | Q16: IMPNRGZ | S16: elc_wof_006 | T16: AllSaAllH | U16: 1 | V16: IMPNRGZ
I17: elc_spv_007 | J17: AllSaAllH | K17: 1 | L17: IMPNRGZ | N17: elc_won_007 | O17: AllSaAllH | P17: 1 | Q17: IMPNRGZ | S17: elc_wof_007 | T17: AllSaAllH | U17: 1 | V17: IMPNRGZ
I18: elc_spv_008 | J18: AllSaAllH | K18: 1 | L18: IMPNRGZ | N18: elc_won_008 | O18: AllSaAllH | P18: 1 | Q18: IMPNRGZ | S18: elc_wof_008 | T18: AllSaAllH | U18: 1 | V18: IMPNRGZ
I19: elc_spv_009 | J19: AllSaAllH | K19: 1 | L19: IMPNRGZ | N19: elc_won_009 | O19: AllSaAllH | P19: 1 | Q19: IMPNRGZ | S19: elc_wof_009 | T19: AllSaAllH | U19: 1 | V19: IMPNRGZ
I20: elc_spv_010 | J20: AllSaAllH | K20: 1 | L20: IMPNRGZ | N20: elc_won_010 | O20: AllSaAllH | P20: 1 | Q20: IMPNRGZ | S20: elc_wof_010 | T20: AllSaAllH | U20: 1 | V20: IMPNRGZ

Sheet ts_12t
C9: =IF(A11="x","DeActivated","~TimeSlices") -> DeActivated | I9: =IF(A11="x","DeActivated","~TFM_DINS-AT") -> DeActivated | N9: =IF(A11="x","DeActivated","~TFM_DINS-AT") -> DeActivated | S9: =IF(A11="x","DeActivated","~TFM_DINS-AT") -> DeActivated | X9: =IF(A11="x","DeActivated","~TFM_DINS-AT") -> DeActivated | AC9: =IF(A11="x","DeActivated","~TFM_DINS-AT") -> DeActivated | AG9: =IF(A11="x","DeActivated","~TFM_DINS-AT") -> DeActivated | AK9: =IF(A11="x","DeActivated","~TFM_INS-AT") -> DeActivated
A10: ts_12t | C10: season | D10: weekly | E10: daynite | F10: wparent | G10: dparent | I10: commodity | J10: timeslice | K10: com_fr | L10: process | N10: commodity | O10: timeslice | P10: com_fr | Q10: process | S10: commodity | T10: timeslice | U10: com_fr | V10: process | X10: g_yrfr | Y10: com_fr | Z10: timeslice | AA10: commodity | AC10: commodity | AD10: timeslice | AE10: com_fr | AG10: commodity | AH10: timeslice | AI10: com_pkflx | AK10: Year | AL10: timeslice | AM10: ncap_afs | AN10: pset_ci
A11: =IFERROR(IF(Veda!D5=A10,"ok","x"),"") -> x | C11: F | D11: a | E11: D | F11: W,R,S,F | G11: a | I11: elc_spv_001 | J11: FaD | K11: 0.12961562 | L11: IMPNRGZ | N11: elc_won_001 | O11: FaD | P11: 0.12527694 | Q11: IMPNRGZ | S11: elc_wof_001 | T11: FaD | U11: 0.12711721 | V11: IMPNRGZ | X11: 0.11426941 | Y11: 0.16087081 | Z11: FaD | AA11: elc_roadtransport | AC11: elc_buildings | AD11: FaD | AE11: 0.12274609 | AG11: ELC | AH11: FaD | AI11: 0.079440067 | AK11: 2020 | AL11: F | AM11: 0.10378861 | AN11: hydro
C12: R | E12: N | G12: a | I12: elc_spv_001 | J12: FaN | K12: 0 | L12: IMPNRGZ | N12: elc_won_001 | O12: FaN | P12: 0.12719682 | Q12: IMPNRGZ | S12: elc_wof_001 | T12: FaN | U12: 0.13089774 | V12: IMPNRGZ | X12: 0.11426941 | Y12: 0.052547713 | Z12: FaN | AA12: elc_roadtransport | AC12: elc_buildings | AD12: FaN | AE12: 0.092155891 | AG12: ELC | AH12: FaN | AI12: 0.29294397 | AK12: 2020 | AL12: R | AM12: 0.2527558 | AN12: hydro
C13: S | E13: P | G13: a | I13: elc_spv_001 | J13: FaP | K13: 0.0063796647 | L13: IMPNRGZ | N13: elc_won_001 | O13: FaP | P13: 0.023844119 | Q13: IMPNRGZ | S13: elc_wof_001 | T13: FaP | U13: 0.02521236 | V13: IMPNRGZ | X13: 0.020776256 | Y13: 0.035896543 | Z13: FaP | AA13: elc_roadtransport | AC13: elc_buildings | AD13: FaP | AE13: 0.022287308 | AG13: ELC | AH13: FaP | AI13: 0.077124346 | AK13: 2020 | AL13: S | AM13: 0.10021941 | AN13: hydro
C14: W | I14: elc_spv_001 | J14: RaD | K14: 0.33959075 | L14: IMPNRGZ | N14: elc_won_001 | O14: RaD | P14: 0.1018728 | Q14: IMPNRGZ | S14: elc_wof_001 | T14: RaD | U14: 0.097831959 | V14: IMPNRGZ | X14: 0.11552511 | Y14: 0.16263862 | Z14: RaD | AA14: elc_roadtransport | AC14: elc_buildings | AD14: RaD | AE14: 0.13448914 | AG14: ELC | AH14: RaD | AI14: 0.18427145 | AK14: 2020 | AL14: W | AM14: 0.26322049 | AN14: hydro
I15: elc_spv_001 | J15: RaN | K15: 0.011456169 | L15: IMPNRGZ | N15: elc_won_001 | O15: RaN | P15: 0.11627325 | Q15: IMPNRGZ | S15: elc_wof_001 | T15: RaN | U15: 0.1114085 | V15: IMPNRGZ | X15: 0.11552511 | Y15: 0.053125161 | Z15: RaN | AA15: elc_roadtransport | AC15: elc_buildings | AD15: RaN | AE15: 0.10279744 | AG15: ELC | AH15: RaN | AI15: 0.43467319 | AK15: 2021 | AL15: F | AM15: 0.095241316 | AN15: hydro
I16: elc_spv_001 | J16: RaP | K16: 0.03056002 | L16: IMPNRGZ | N16: elc_won_001 | O16: RaP | P16: 0.020002471 | Q16: IMPNRGZ | S16: elc_wof_001 | T16: RaP | U16: 0.020861711 | V16: IMPNRGZ | X16: 0.021004566 | Y16: 0.036291011 | Z16: RaP | AA16: elc_roadtransport | AC16: elc_buildings | AD16: RaP | AE16: 0.024520932 | AG16: ELC | AH16: RaP | AI16: 0.19135234 | AK16: 2021 | AL16: R | AM16: 0.37382686 | AN16: hydro
I17: elc_spv_001 | J17: SaD | K17: 0.35000344 | L17: IMPNRGZ | N17: elc_won_001 | O17: SaD | P17: 0.075383855 | Q17: IMPNRGZ | S17: elc_wof_001 | T17: SaD | U17: 0.070790229 | V17: IMPNRGZ | X17: 0.11552511 | Y17: 0.16263862 | Z17: SaD | AA17: elc_roadtransport | AC17: elc_buildings | AD17: SaD | AE17: 0.12339527 | AG17: ELC | AH17: SaD | AI17: 0.11075361 | AK17: 2021 | AL17: S | AM17: 0.091859967 | AN17: hydro
I18: elc_spv_001 | J18: SaN | K18: 0.028350243 | L18: IMPNRGZ | N18: elc_won_001 | O18: SaN | P18: 0.084996375 | Q18: IMPNRGZ | S18: elc_wof_001 | T18: SaN | U18: 0.08816377 | V18: IMPNRGZ | X18: 0.11552511 | Y18: 0.053125161 | Z18: SaN | AA18: elc_roadtransport | AC18: elc_buildings | AD18: SaN | AE18: 0.087951066 | AG18: ELC | AH18: SaN | AI18: 0.36249886 | AK18: 2021 | AL18: W | AM18: 0.18889259 | AN18: hydro
I19: elc_spv_001 | J19: SaP | K19: 0.041618791 | L19: IMPNRGZ | N19: elc_won_001 | O19: SaP | P19: 0.014423152 | Q19: IMPNRGZ | S19: elc_wof_001 | T19: SaP | U19: 0.014711794 | V19: IMPNRGZ | X19: 0.021004566 | Y19: 0.036291011 | Z19: SaP | AA19: elc_roadtransport | AC19: elc_buildings | AD19: SaP | AE19: 0.021875174 | AG19: ELC | AH19: SaP | AI19: 0.099292387 | AK19: 2022 | AL19: F | AM19: 0.094959537 | AN19: hydro
I20: elc_spv_001 | J20: WaD | K20: 0.061653176 | L20: IMPNRGZ | N20: elc_won_001 | O20: WaD | P20: 0.14120384 | Q20: IMPNRGZ | S20: elc_wof_001 | T20: WaD | U20: 0.14397385 | V20: IMPNRGZ | X20: 0.1130137 | Y20: 0.159103 | Z20: WaD | AA20: elc_roadtransport | AC20: elc_buildings | AD20: WaD | AE20: 0.13660843 | AG20: ELC | AH20: WaD | AI20: 0.16101867 | AK20: 2022 | AL20: R | AM20: 0.3490303 | AN20: hydro
I21: elc_spv_001 | J21: WaN | K21: 0 | L21: IMPNRGZ | N21: elc_won_001 | O21: WaN | P21: 0.14398397 | Q21: IMPNRGZ | S21: elc_wof_001 | T21: WaN | U21: 0.14329637 | V21: IMPNRGZ | X21: 0.1130137 | Y21: 0.051970266 | Z21: WaN | AA21: elc_roadtransport | AC21: elc_buildings | AD21: WaN | AE21: 0.10572679 | AG21: ELC | AH21: WaN | AI21: 0.35430917 | AK21: 2022 | AL21: S | AM21: 0.12313744 | AN21: hydro
I22: elc_spv_001 | J22: WaP | K22: 0.0007721146 | L22: IMPNRGZ | N22: elc_won_001 | O22: WaP | P22: 0.025542408 | Q22: IMPNRGZ | S22: elc_wof_001 | T22: WaP | U22: 0.025734502 | V22: IMPNRGZ | X22: 0.020547945 | Y22: 0.035502076 | Z22: WaP | AA22: elc_roadtransport | AC22: elc_buildings | AD22: WaP | AE22: 0.02544646 | AG22: ELC | AH22: WaP | AI22: 0.13756314 | AK22: 2022 | AL22: W | AM22: 0.20378663 | AN22: hydro
I23: elc_spv_002 | J23: FaD | K23: 0.13436152 | L23: IMPNRGZ | N23: elc_won_002 | O23: FaD | P23: 0.12623231 | Q23: IMPNRGZ | S23: elc_wof_002 | T23: FaD | U23: 0.12276267 | V23: IMPNRGZ | AC23: elc_industry | AD23: FaD | AE23: 0.11525474
I24: elc_spv_002 | J24: FaN | K24: 0 | L24: IMPNRGZ | N24: elc_won_002 | O24: FaN | P24: 0.1305535 | Q24: IMPNRGZ | S24: elc_wof_002 | T24: FaN | U24: 0.1226461 | V24: IMPNRGZ | AC24: elc_industry | AD24: FaN | AE24: 0.1130209
I25: elc_spv_002 | J25: FaP | K25: 0.0063106644 | L25: IMPNRGZ | N25: elc_won_002 | O25: FaP | P25: 0.024624778 | Q25: IMPNRGZ | S25: elc_wof_002 | T25: FaP | U25: 0.022993521 | V25: IMPNRGZ | AC25: elc_industry | AD25: FaP | AE25: 0.020953205
I26: elc_spv_002 | J26: RaD | K26: 0.33870928 | L26: IMPNRGZ | N26: elc_won_002 | O26: RaD | P26: 0.095114771 | Q26: IMPNRGZ | S26: elc_wof_002 | T26: RaD | U26: 0.1057535 | V26: IMPNRGZ | AC26: elc_industry | AD26: RaD | AE26: 0.11661532
I27: elc_spv_002 | J27: RaN | K27: 0.011715744 | L27: IMPNRGZ | N27: elc_won_002 | O27: RaN | P27: 0.11973772 | Q27: IMPNRGZ | S27: elc_wof_002 | T27: RaN | U27: 0.12531325 | V27: IMPNRGZ | AC27: elc_industry | AD27: RaN | AE27: 0.11430105
I28: elc_spv_002 | J28: RaP | K28: 0.03196046 | L28: IMPNRGZ | N28: elc_won_002 | O28: RaP | P28: 0.02051426 | Q28: IMPNRGZ | S28: elc_wof_002 | T28: RaP | U28: 0.020882782 | V28: IMPNRGZ | AC28: elc_industry | AD28: RaP | AE28: 0.021207777
I29: elc_spv_002 | J29: SaD | K29: 0.34749175 | L29: IMPNRGZ | N29: elc_won_002 | O29: SaD | P29: 0.070704085 | Q29: IMPNRGZ | S29: elc_wof_002 | T29: SaD | U29: 0.075863541 | V29: IMPNRGZ | AC29: elc_industry | AD29: SaD | AE29: 0.11666879
I30: elc_spv_002 | J30: SaN | K30: 0.028299687 | L30: IMPNRGZ | N30: elc_won_002 | O30: SaN | P30: 0.0823386 | Q30: IMPNRGZ | S30: elc_wof_002 | T30: SaN | U30: 0.084370901 | V30: IMPNRGZ | AC30: elc_industry | AD30: SaN | AE30: 0.11408049
I31: elc_spv_002 | J31: SaP | K31: 0.042660602 | L31: IMPNRGZ | N31: elc_won_002 | O31: SaP | P31: 0.013608212 | Q31: IMPNRGZ | S31: elc_wof_002 | T31: SaP | U31: 0.015564114 | V31: IMPNRGZ | AC31: elc_industry | AD31: SaP | AE31: 0.02117159
I32: elc_spv_002 | J32: WaD | K32: 0.057662058 | L32: IMPNRGZ | N32: elc_won_002 | O32: WaD | P32: 0.14244029 | Q32: IMPNRGZ | S32: elc_wof_002 | T32: WaD | U32: 0.1386126 | V32: IMPNRGZ | AC32: elc_industry | AD32: WaD | AE32: 0.11409604
I33: elc_spv_002 | J33: WaN | K33: 0 | L33: IMPNRGZ | N33: elc_won_002 | O33: WaN | P33: 0.14785376 | Q33: IMPNRGZ | S33: elc_wof_002 | T33: WaN | U33: 0.1394758 | V33: IMPNRGZ | AC33: elc_industry | AD33: WaN | AE33: 0.11184092
I34: elc_spv_002 | J34: WaP | K34: 0.00082823389 | L34: IMPNRGZ | N34: elc_won_002 | O34: WaP | P34: 0.026277723 | Q34: IMPNRGZ | S34: elc_wof_002 | T34: WaP | U34: 0.025761227 | V34: IMPNRGZ | AC34: elc_industry | AD34: WaP | AE34: 0.020789174
I35: elc_spv_003 | J35: FaD | K35: 0.1350031 | L35: IMPNRGZ | N35: elc_won_003 | O35: FaD | P35: 0.12536188 | Q35: IMPNRGZ | S35: elc_wof_003 | T35: FaD | U35: 0.12443394 | V35: IMPNRGZ
I36: elc_spv_003 | J36: FaN | K36: 0 | L36: IMPNRGZ | N36: elc_won_003 | O36: FaN | P36: 0.1278386 | Q36: IMPNRGZ | S36: elc_wof_003 | T36: FaN | U36: 0.12613453 | V36: IMPNRGZ
I37: elc_spv_003 | J37: FaP | K37: 0.0066959495 | L37: IMPNRGZ | N37: elc_won_003 | O37: FaP | P37: 0.023704504 | Q37: IMPNRGZ | S37: elc_wof_003 | T37: FaP | U37: 0.023635694 | V37: IMPNRGZ
I38: elc_spv_003 | J38: RaD | K38: 0.33118047 | L38: IMPNRGZ | N38: elc_won_003 | O38: RaD | P38: 0.09883523 | Q38: IMPNRGZ | S38: elc_wof_003 | T38: RaD | U38: 0.099841239 | V38: IMPNRGZ
I39: elc_spv_003 | J39: RaN | K39: 0.011755526 | L39: IMPNRGZ | N39: elc_won_003 | O39: RaN | P39: 0.11789755 | Q39: IMPNRGZ | S39: elc_wof_003 | T39: RaN | U39: 0.11791771 | V39: IMPNRGZ
I40: elc_spv_003 | J40: RaP | K40: 0.036251176 | L40: IMPNRGZ | N40: elc_won_003 | O40: RaP | P40: 0.019373887 | Q40: IMPNRGZ | S40: elc_wof_003 | T40: RaP | U40: 0.019760943 | V40: IMPNRGZ
I41: elc_spv_003 | J41: SaD | K41: 0.34625255 | L41: IMPNRGZ | N41: elc_won_003 | O41: SaD | P41: 0.072572416 | Q41: IMPNRGZ | S41: elc_wof_003 | T41: SaD | U41: 0.077026188 | V41: IMPNRGZ
I42: elc_spv_003 | J42: SaN | K42: 0.029156779 | L42: IMPNRGZ | N42: elc_won_003 | O42: SaN | P42: 0.077635094 | Q42: IMPNRGZ | S42: elc_wof_003 | T42: SaN | U42: 0.081221551 | V42: IMPNRGZ
I43: elc_spv_003 | J43: SaP | K43: 0.048401757 | L43: IMPNRGZ | N43: elc_won_003 | O43: SaP | P43: 0.01342177 | Q43: IMPNRGZ | S43: elc_wof_003 | T43: SaP | U43: 0.015154139 | V43: IMPNRGZ
I44: elc_spv_003 | J44: WaD | K44: 0.054329616 | L44: IMPNRGZ | N44: elc_won_003 | O44: WaD | P44: 0.14477685 | Q44: IMPNRGZ | S44: elc_wof_003 | T44: WaD | U44: 0.14190074 | V44: IMPNRGZ
I45: elc_spv_003 | J45: WaN | K45: 0 | L45: IMPNRGZ | N45: elc_won_003 | O45: WaN | P45: 0.1518102 | Q45: IMPNRGZ | S45: elc_wof_003 | T45: WaN | U45: 0.14660511 | V45: IMPNRGZ
I46: elc_spv_003 | J46: WaP | K46: 0.00097306485 | L46: IMPNRGZ | N46: elc_won_003 | O46: WaP | P46: 0.026772015 | Q46: IMPNRGZ | S46: elc_wof_003 | T46: WaP | U46: 0.026368226 | V46: IMPNRGZ
... I130: elc_spv_010 | J130: WaP | K130: 0.00025281481 | L130: IMPNRGZ | N130: elc_won_010 | O130: WaP | P130: 0.026098834 | Q130: IMPNRGZ | S130: elc_wof_010 | T130: WaP | U130: 0.02504303 | V130: IMPNRGZ
