Workbook

Sheet Veda
G1: 1-25,36-40
D2: ="~Inputcell: "&_xlfn.TEXTJOIN(",",TRUE,G1:EE1) -> ~Inputcell: 1-25,36-40 | G2: 5 | H2: 6 | I2: 7 | J2: 9 | K2: 10 | L2: 11 | M2: 16 | N2: 17 | O2: 18 | P2: 20 | Q2: 21 | R2: 22 | S2: 27 | T2: 28 | U2: 29 | V2: 31 | W2: 32 | X2: 33 | Y2: 38 | Z2: 39 | AA2: 40 | AB2: 42 | AC2: 43 | AD2: 44 | AE2: 49 | AF2: 50 | AG2: 51 | AH2: 53 | AI2: 54 | AJ2: 55
D3: 3
D5: =VLOOKUP(D3,$C$9:$E$999,2,FALSE) -> ts_annual | E5: =VLOOKUP(D3,$C$9:$E$999,3,FALSE) -> C3
B7: ~Scenmap
A8: priority | B8: scen | C8: case_no | D8: timeslice | E8: climate | AM8: bio price multiplier
A9: 5 | B9: =VLOOKUP(E9,$AK$9:$AL$15,2,FALSE)&"."&VLOOKUP(D9,$AH$9:$AI$24,2,FALSE) -> e 1.5 deg no OS.kAnn | C9: 1 | D9: =VLOOKUP(AJ9,$AG$9:$AH$22,2,FALSE) -> ts_annual | E9: C1 | G9: Limit warming to 1.5°C (>50%) with no or limited overshoot | AG9: 1 | AH9: ts_annual | AI9: kAnn | AJ9: 1 | AK9: C1 | AL9: e 1.5 deg no OS | AM9: 5
A10: 5 | B10: =VLOOKUP(E10,$AK$9:$AL$15,2,FALSE)&"."&VLOOKUP(D10,$AH$9:$AI$24,2,FALSE) -> d 1.5 deg OS.kAnn | C10: =C9+1 -> 2 | D10: =VLOOKUP(AJ10,$AG$9:$AH$22,2,FALSE) -> ts_annual | E10: C2 | G10: Limit warming to 1.5°C (>67%) with high overshoot | S10: IEA | AG10: 2 | AH10: ts_12t | AI10: k12 | AJ10: 1 | AK10: C2 | AL10: d 1.5 deg OS | AM10: 4
A11: 5 | B11: =VLOOKUP(E11,$AK$9:$AL$15,2,FALSE)&"."&VLOOKUP(D11,$AH$9:$AI$24,2,FALSE) -> c 2 deg (67%).kAnn | C11: =C10+1 -> 3 | D11: =VLOOKUP(AJ11,$AG$9:$AH$22,2,FALSE) -> ts_annual | E11: C3 | G11: Limit warming to 2°C (>67%) with higher action post-2030 | S11: 2022 | AG11: 3 | AH11: ts_012 | AI11: j12 | AJ11: 1 | AK11: C3 | AL11: c 2 deg (67%) | AM11: 3
A12: 5 | B12: =VLOOKUP(E12,$AK$9:$AL$15,2,FALSE)&"."&VLOOKUP(D12,$AH$9:$AI$24,2,FALSE) -> b 2 deg (50%).kAnn | C12: =C11+1 -> 4 | D12: =VLOOKUP(AJ12,$AG$9:$AH$22,2,FALSE) -> ts_annual | E12: C4 | G12: Limit warming to 2°C (>50%) with immediate action | S12: =SUMIFS(iea_data!I3:I9999,iea_data!$B$3:$B$9999,Veda!$S$11)+T28-T29 -> 0 | T12: base-year generation (TWh) | AG12: 4 | AH12: ts_030 | AI12: i30 | AJ12: 1 | AK12: C4 | AL12: b 2 deg (50%) | AM12: 3
A13: 5 | B13: =VLOOKUP(E13,$AK$9:$AL$15,2,FALSE)&"."&VLOOKUP(D13,$AH$9:$AI$24,2,FALSE) -> a 3 deg.kAnn | C13: =C12+1 -> 5 | D13: =VLOOKUP(AJ13,$AG$9:$AH$22,2,FALSE) -> ts_annual | E13: C7 | G13: Likely above 3°C warming with limited mitigation | AG13: 5 | AH13: ts_048 | AI13: h48 | AJ13: 1 | AK13: C7 | AL13: a 3 deg | AM13: 1.5
A14: 5 | B14: =VLOOKUP(E14,$AK$9:$AL$15,2,FALSE)&"."&VLOOKUP(D14,$AH$9:$AI$24,2,FALSE) -> e 1.5 deg no OS.k12 | C14: =C13+1 -> 6 | D14: =VLOOKUP(AJ14,$AG$9:$AH$22,2,FALSE) -> ts_12t | E14: =E9 -> C1 | T14: =S12 -> 0 | U14: =$S$12*J15 -> 0 | V14: =$S$12*K15 -> 0 | W14: =$S$12*L15 -> 0 | X14: =$S$12*M15 -> 0 | Y14: =$S$12*N15 -> 0 | Z14: =$S$12*O15 -> 0 | AG14: 6 | AH14: ts_048P10 | AI14: h48P10 | AJ14: =AJ9+1 -> 2
A15: 5 | B15: =VLOOKUP(E15,$AK$9:$AL$15,2,FALSE)&"."&VLOOKUP(D15,$AH$9:$AI$24,2,FALSE) -> d 1.5 deg OS.k12 | C15: =C14+1 -> 7 | D15: =VLOOKUP(AJ15,$AG$9:$AH$22,2,FALSE) -> ts_12t | E15: =E10 -> C2 | G15: Electricity growth relative to 2020 | I15: =SUMIFS(ar6_r10!$F$2:$F$999,ar6_r10!$A$2:$A$999,Veda!$E$5,ar6_r10!$C$2:$C$999,Veda!I$17,ar6_r10!$M$2:$M$999,Veda!$G15) -> 1 | J15: =SUMIFS(ar6_r10!$F$2:$F$999,ar6_r10!$A$2:$A$999,Veda!$E$5,ar6_r10!$C$2:$C$999,Veda!J$17,ar6_r10!$M$2:$M$999,Veda!$G15) -> 1.27 | K15: =SUMIFS(ar6_r10!$F$2:$F$999,ar6_r10!$A$2:$A$999,Veda!$E$5,ar6_r10!$C$2:$C$999,Veda!K$17,ar6_r10!$M$2:$M$999,Veda!$G15) -> 1.68 | L15: =SUMIFS(ar6_r10!$F$2:$F$999,ar6_r10!$A$2:$A$999,Veda!$E$5,ar6_r10!$C$2:$C$999,Veda!L$17,ar6_r10!$M$2:$M$999,Veda!$G15) -> 2.26 | M15: =SUMIFS(ar6_r10!$F$2:$F$999,ar6_r10!$A$2:$A$999,Veda!$E$5,ar6_r10!$C$2:$C$999,Veda!M$17,ar6_r10!$M$2:$M$999,Veda!$G15) -> 2.92 | N15: =SUMIFS(ar6_r10!$F$2:$F$999,ar6_r10!$A$2:$A$999,Veda!$E$5,ar6_r10!$C$2:$C$999,Veda!N$17,ar6_r10!$M$2:$M$999,Veda!$G15) -> 4.48 | O15: =SUMIFS(ar6_r10!$F$2:$F$999,ar6_r10!$A$2:$A$999,Veda!$E$5,ar6_r10!$C$2:$C$999,Veda!O$17,ar6_r10!$M$2:$M$999,Veda!$G15) -> 6.01 | AG15: 7 | AH15: ts_048P90 | AI15: h48P90 | AJ15: =AJ10+1 -> 2
A16: 5 | B16: =VLOOKUP(E16,$AK$9:$AL$15,2,FALSE)&"."&VLOOKUP(D16,$AH$9:$AI$24,2,FALSE) -> c 2 deg (67%).k12 | C16: =C15+1 -> 8 | D16: =VLOOKUP(AJ16,$AG$9:$AH$22,2,FALSE) -> ts_12t | E16: =E11 -> C3 | S16: ~TFM_INS-TS | AG16: 8 | AH16: s1_d | AI16: g1d72 | AJ16: =AJ11+1 -> 2
A17: 5 | B17: =VLOOKUP(E17,$AK$9:$AL$15,2,FALSE)&"."&VLOOKUP(D17,$AH$9:$AI$24,2,FALSE) -> b 2 deg (50%).k12 | C17: =C16+1 -> 9 | D17: =VLOOKUP(AJ17,$AG$9:$AH$22,2,FALSE) -> ts_12t | E17: =E12 -> C4 | I17: 2020 | J17: =U17 -> 2025 | K17: =V17 -> 2030 | L17: =W17 -> 2035 | M17: =X17 -> 2040 | N17: =Y17 -> 2045 | O17: =Z17 -> 2050 | S17: commodity | T17: 2022 | U17: 2025 | V17: 2030 | W17: 2035 | X17: 2040 | Y17: 2045 | Z17: 2050 | AA17: attribute | AG17: 9 | AH17: s1v1_d | AI17: f2d96 | AJ17: =AJ12+1 -> 2
A18: 5 | B18: =VLOOKUP(E18,$AK$9:$AL$15,2,FALSE)&"."&VLOOKUP(D18,$AH$9:$AI$24,2,FALSE) -> a 3 deg.k12 | C18: =C17+1 -> 10 | D18: =VLOOKUP(AJ18,$AG$9:$AH$22,2,FALSE) -> ts_12t | E18: =E13 -> C7 | G18: Hydrogen as a share of electricity | I18: =SUMIFS(ar6_r10!$F$2:$F$999,ar6_r10!$A$2:$A$999,Veda!$E$5,ar6_r10!$C$2:$C$999,Veda!I$17,ar6_r10!$M$2:$M$999,Veda!$G18) -> 0 | J18: =SUMIFS(ar6_r10!$F$2:$F$999,ar6_r10!$A$2:$A$999,Veda!$E$5,ar6_r10!$C$2:$C$999,Veda!J$17,ar6_r10!$M$2:$M$999,Veda!$G18) -> 0 | K18: =SUMIFS(ar6_r10!$F$2:$F$999,ar6_r10!$A$2:$A$999,Veda!$E$5,ar6_r10!$C$2:$C$999,Veda!K$17,ar6_r10!$M$2:$M$999,Veda!$G18) -> 0 | L18: =SUMIFS(ar6_r10!$F$2:$F$999,ar6_r10!$A$2:$A$999,Veda!$E$5,ar6_r10!$C$2:$C$999,Veda!L$17,ar6_r10!$M$2:$M$999,Veda!$G18) -> 0.01 | M18: =SUMIFS(ar6_r10!$F$2:$F$999,ar6_r10!$A$2:$A$999,Veda!$E$5,ar6_r10!$C$2:$C$999,Veda!M$17,ar6_r10!$M$2:$M$999,Veda!$G18) -> 0.02 | N18: =SUMIFS(ar6_r10!$F$2:$F$999,ar6_r10!$A$2:$A$999,Veda!$E$5,ar6_r10!$C$2:$C$999,Veda!N$17,ar6_r10!$M$2:$M$999,Veda!$G18) -> 0.02 | O18: =SUMIFS(ar6_r10!$F$2:$F$999,ar6_r10!$A$2:$A$999,Veda!$E$5,ar6_r10!$C$2:$C$999,Veda!O$17,ar6_r10!$M$2:$M$999,Veda!$G18) -> 0.03 | S18: hydrogen_allsect | T18: =I18*T$14 -> 0 | U18: =J18*U$14 -> 0 | V18: =K18*V$14 -> 0 | W18: =L18*W$14 -> 0 | X18: =M18*X$14 -> 0 | Y18: =N18*Y$14 -> 0 | Z18: =O18*Z$14 -> 0 | AA18: demand | AG18: 10 | AH18: ts_096 | AI18: e96 | AJ18: =AJ13+1 -> 2
A19: 5 | B19: =VLOOKUP(E19,$AK$9:$AL$15,2,FALSE)&"."&VLOOKUP(D19,$AH$9:$AI$24,2,FALSE) -> e 1.5 deg no OS.j12 | C19: =C18+1 -> 11 | D19: =VLOOKUP(AJ19,$AG$9:$AH$22,2,FALSE) -> ts_012 | E19: =E14 -> C1 | G19: Industry electricity share | I19: =SUMIFS(ar6_r10!$F$2:$F$999,ar6_r10!$A$2:$A$999,Veda!$E$5,ar6_r10!$C$2:$C$999,Veda!I$17,ar6_r10!$M$2:$M$999,Veda!$G19) -> 0.49 | J19: =SUMIFS(ar6_r10!$F$2:$F$999,ar6_r10!$A$2:$A$999,Veda!$E$5,ar6_r10!$C$2:$C$999,Veda!J$17,ar6_r10!$M$2:$M$999,Veda!$G19) -> 0.45 | K19: =SUMIFS(ar6_r10!$F$2:$F$999,ar6_r10!$A$2:$A$999,Veda!$E$5,ar6_r10!$C$2:$C$999,Veda!K$17,ar6_r10!$M$2:$M$999,Veda!$G19) -> 0.43 | L19: =SUMIFS(ar6_r10!$F$2:$F$999,ar6_r10!$A$2:$A$999,Veda!$E$5,ar6_r10!$C$2:$C$999,Veda!L$17,ar6_r10!$M$2:$M$999,Veda!$G19) -> 0.42 | M19: =SUMIFS(ar6_r10!$F$2:$F$999,ar6_r10!$A$2:$A$999,Veda!$E$5,ar6_r10!$C$2:$C$999,Veda!M$17,ar6_r10!$M$2:$M$999,Veda!$G19) -> 0.4 | N19: =SUMIFS(ar6_r10!$F$2:$F$999,ar6_r10!$A$2:$A$999,Veda!$E$5,ar6_r10!$C$2:$C$999,Veda!N$17,ar6_r10!$M$2:$M$999,Veda!$G19) -> 0.41 | O19: =SUMIFS(ar6_r10!$F$2:$F$999,ar6_r10!$A$2:$A$999,Veda!$E$5,ar6_r10!$C$2:$C$999,Veda!O$17,ar6_r10!$M$2:$M$999,Veda!$G19) -> 0.38 | S19: elc_industry | T19: =I19*T$14 -> 0 | U19: =J19*U$14 -> 0 | V19: =K19*V$14 -> 0 | W19: =L19*W$14 -> 0 | X19: =M19*X$14 -> 0 | Y19: =N19*Y$14 -> 0 | Z19: =O19*Z$14 -> 0 | AA19: demand | AG19: 11 | AH19: s1p1v1_d | AI19: d9d | AJ19: =AJ14+1 -> 3
A20: 5 | B20: =VLOOKUP(E20,$AK$9:$AL$15,2,FALSE)&"."&VLOOKUP(D20,$AH$9:$AI$24,2,FALSE) -> d 1.5 deg OS.j12 | C20: =C19+1 -> 12 | D20: =VLOOKUP(AJ20,$AG$9:$AH$22,2,FALSE) -> ts_012 | E20: =E15 -> C2 | G20: Residential and commercial electricity share | I20: =SUMIFS(ar6_r10!$F$2:$F$999,ar6_r10!$A$2:$A$999,Veda!$E$5,ar6_r10!$C$2:$C$999,Veda!I$17,ar6_r10!$M$2:$M$999,Veda!$G20) -> 0.49 | J20: =SUMIFS(ar6_r10!$F$2:$F$999,ar6_r10!$A$2:$A$999,Veda!$E$5,ar6_r10!$C$2:$C$999,Veda!J$17,ar6_r10!$M$2:$M$999,Veda!$G20) -> 0.52 | K20: =SUMIFS(ar6_r10!$F$2:$F$999,ar6_r10!$A$2:$A$999,Veda!$E$5,ar6_r10!$C$2:$C$999,Veda!K$17,ar6_r10!$M$2:$M$999,Veda!$G20) -> 0.54 | L20: =SUMIFS(ar6_r10!$F$2:$F$999,ar6_r10!$A$2:$A$999,Veda!$E$5,ar6_r10!$C$2:$C$999,Veda!L$17,ar6_r10!$M$2:$M$999,Veda!$G20) -> 0.51 | M20: =SUMIFS(ar6_r10!$F$2:$F$999,ar6_r10!$A$2:$A$999,Veda!$E$5,ar6_r10!$C$2:$C$999,Veda!M$17,ar6_r10!$M$2:$M$999,Veda!$G20) -> 0.51 | N20: =SUMIFS(ar6_r10!$F$2:$F$999,ar6_r10!$A$2:$A$999,Veda!$E$5,ar6_r10!$C$2:$C$999,Veda!N$17,ar6_r10!$M$2:$M$999,Veda!$G20) -> 0.48 | O20: =SUMIFS(ar6_r10!$F$2:$F$999,ar6_r10!$A$2:$A$999,Veda!$E$5,ar6_r10!$C$2:$C$999,Veda!O$17,ar6_r10!$M$2:$M$999,Veda!$G20) -> 0.47 | S20: elc_buildings | T20: =I20*T$14 -> 0 | U20: =J20*U$14 -> 0 | V20: =K20*V$14 -> 0 | W20: =L20*W$14 -> 0 | X20: =M20*X$14 -> 0 | Y20: =N20*Y$14 -> 0 | Z20: =O20*Z$14 -> 0 | AA20: demand | AG20: 12 | AH20: s5p5v5_d | AI20: c15d | AJ20: =AJ15+1 -> 3
A21: 5 | B21: =VLOOKUP(E21,$AK$9:$AL$15,2,FALSE)&"."&VLOOKUP(D21,$AH$9:$AI$24,2,FALSE) -> c 2 deg (67%).j12 | C21: =C20+1 -> 13 | D21: =VLOOKUP(AJ21,$AG$9:$AH$22,2,FALSE) -> ts_012 | E21: =E16 -> C3 | G21: Transportation electricity share | I21: =SUMIFS(ar6_r10!$F$2:$F$999,ar6_r10!$A$2:$A$999,Veda!$E$5,ar6_r10!$C$2:$C$999,Veda!I$17,ar6_r10!$M$2:$M$999,Veda!$G21) -> 0.01 | J21: =SUMIFS(ar6_r10!$F$2:$F$999,ar6_r10!$A$2:$A$999,Veda!$E$5,ar6_r10!$C$2:$C$999,Veda!J$17,ar6_r10!$M$2:$M$999,Veda!$G21) -> 0.01 | K21: =SUMIFS(ar6_r10!$F$2:$F$999,ar6_r10!$A$2:$A$999,Veda!$E$5,ar6_r10!$C$2:$C$999,Veda!K$17,ar6_r10!$M$2:$M$999,Veda!$G21) -> 0.02 | L21: =SUMIFS(ar6_r10!$F$2:$F$999,ar6_r10!$A$2:$A$999,Veda!$E$5,ar6_r10!$C$2:$C$999,Veda!L$17,ar6_r10!$M$2:$M$999,Veda!$G21) -> 0.02 | M21: =SUMIFS(ar6_r10!$F$2:$F$999,ar6_r10!$A$2:$A$999,Veda!$E$5,ar6_r10!$C$2:$C$999,Veda!M$17,ar6_r10!$M$2:$M$999,Veda!$G21) -> 0.03 | N21: =SUMIFS(ar6_r10!$F$2:$F$999,ar6_r10!$A$2:$A$999,Veda!$E$5,ar6_r10!$C$2:$C$999,Veda!N$17,ar6_r10!$M$2:$M$999,Veda!$G21) -> 0.05 | O21: =SUMIFS(ar6_r10!$F$2:$F$999,ar6_r10!$A$2:$A$999,Veda!$E$5,ar6_r10!$C$2:$C$999,Veda!O$17,ar6_r10!$M$2:$M$999,Veda!$G21) -> 0.05 | S21: elc_transport | T21: =I21*T$14 -> 0 | U21: =T21 -> 0 | V21: =U21 -> 0 | W21: =V21 -> 0 | X21: =W21 -> 0 | Y21: =X21 -> 0 | Z21: =Y21 -> 0 | AA21: demand | AC21: non-road transport demand assumed to be constant | AJ21: =AJ16+1 -> 3
A22: 5 | B22: =VLOOKUP(E22,$AK$9:$AL$15,2,FALSE)&"."&VLOOKUP(D22,$AH$9:$AI$24,2,FALSE) -> b 2 deg (50%).j12 | C22: =C21+1 -> 14 | D22: =VLOOKUP(AJ22,$AG$9:$AH$22,2,FALSE) -> ts_012 | E22: =E17 -> C4 | S22: elc_roadtransport | T22: =T14-SUM(T19:T21) -> 0 | U22: =U14-SUM(U19:U21) -> 0 | V22: =V14-SUM(V19:V21) -> 0 | W22: =W14-SUM(W19:W21) -> 0 | X22: =X14-SUM(X19:X21) -> 0 | Y22: =Y14-SUM(Y19:Y21) -> 0 | Z22: =Z14-SUM(Z19:Z21) -> 0 | AA22: demand | AJ22: =AJ17+1 -> 3
A23: 5 | B23: =VLOOKUP(E23,$AK$9:$AL$15,2,FALSE)&"."&VLOOKUP(D23,$AH$9:$AI$24,2,FALSE) -> a 3 deg.j12 | C23: =C22+1 -> 15 | D23: =VLOOKUP(AJ23,$AG$9:$AH$22,2,FALSE) -> ts_012 | E23: =E18 -> C7 | S23: * | AJ23: =AJ18+1 -> 3
A24: 5 | B24: =VLOOKUP(E24,$AK$9:$AL$15,2,FALSE)&"."&VLOOKUP(D24,$AH$9:$AI$24,2,FALSE) -> e 1.5 deg no OS.i30 | C24: =C23+1 -> 16 | D24: =VLOOKUP(AJ24,$AG$9:$AH$22,2,FALSE) -> ts_030 | E24: =E19 -> C1 | G24: CO2 price | I24: 0 | J24: 0 | K24: =SUMIFS(ar6_r10!$F$2:$F$999,ar6_r10!$A$2:$A$999,Veda!$E$5,ar6_r10!$C$2:$C$999,Veda!K$17,ar6_r10!$M$2:$M$999,Veda!$G24) -> 48.97 | L24: =SUMIFS(ar6_r10!$F$2:$F$999,ar6_r10!$A$2:$A$999,Veda!$E$5,ar6_r10!$C$2:$C$999,Veda!L$17,ar6_r10!$M$2:$M$999,Veda!$G24) -> 87.7 | M24: =SUMIFS(ar6_r10!$F$2:$F$999,ar6_r10!$A$2:$A$999,Veda!$E$5,ar6_r10!$C$2:$C$999,Veda!M$17,ar6_r10!$M$2:$M$999,Veda!$G24) -> 122.55 | N24: =SUMIFS(ar6_r10!$F$2:$F$999,ar6_r10!$A$2:$A$999,Veda!$E$5,ar6_r10!$C$2:$C$999,Veda!N$17,ar6_r10!$M$2:$M$999,Veda!$G24) -> 179.54 | O24: =SUMIFS(ar6_r10!$F$2:$F$999,ar6_r10!$A$2:$A$999,Veda!$E$5,ar6_r10!$C$2:$C$999,Veda!O$17,ar6_r10!$M$2:$M$999,Veda!$G24) -> 211.71 | S24: co2net | U24: 0 | V24: =K24/1000 -> 0.04897 | W24: =L24/1000 -> 0.0877 | X24: =M24/1000 -> 0.12255 | Y24: =N24/1000 -> 0.17954 | Z24: =O24/1000 -> 0.21171 | AA24: com_taxnet | AJ24: =AJ19+1 -> 4
A25: 5 | B25: =VLOOKUP(E25,$AK$9:$AL$15,2,FALSE)&"."&VLOOKUP(D25,$AH$9:$AI$24,2,FALSE) -> d 1.5 deg OS.i30 | C25: =C24+1 -> 17 | D25: =VLOOKUP(AJ25,$AG$9:$AH$22,2,FALSE) -> ts_030 | E25: =E20 -> C2 | AJ25: =AJ20+1 -> 4
A26: 5 | B26: =VLOOKUP(E26,$AK$9:$AL$15,2,FALSE)&"."&VLOOKUP(D26,$AH$9:$AI$24,2,FALSE) -> c 2 deg (67%).i30 | C26: =C25+1 -> 18 | D26: =VLOOKUP(AJ26,$AG$9:$AH$22,2,FALSE) -> ts_030 | E26: =E21 -> C3 | S26: ~TFM_INS-TS | AJ26: =AJ21+1 -> 4
A27: 5 | B27: =VLOOKUP(E27,$AK$9:$AL$15,2,FALSE)&"."&VLOOKUP(D27,$AH$9:$AI$24,2,FALSE) -> b 2 deg (50%).i30 | C27: =C26+1 -> 19 | D27: =VLOOKUP(AJ27,$AG$9:$AH$22,2,FALSE) -> ts_030 | E27: =E22 -> C4 | S27: process | T27: =T17 -> 2022 | U27: =U17 -> 2025 | V27: =V17 -> 2030 | W27: =W17 -> 2035 | X27: =X17 -> 2040 | Y27: =Y17 -> 2045 | Z27: =Z17 -> 2050 | AA27: attribute | AB27: limtype | AJ27: =AJ22+1 -> 4
A28: 5 | B28: =VLOOKUP(E28,$AK$9:$AL$15,2,FALSE)&"."&VLOOKUP(D28,$AH$9:$AI$24,2,FALSE) -> a 3 deg.i30 | C28: =C27+1 -> 20 | D28: =VLOOKUP(AJ28,$AG$9:$AH$22,2,FALSE) -> ts_030 | E28: =E23 -> C7 | Q28: =SUMIFS(iea_data!G3:G9999,iea_data!$B$3:$B$9999,Veda!$S$11) -> 0 | S28: Trd_electricity import | T28: =Q28 -> 0 | AA28: ACT_BND | AB28: FX | AJ28: =AJ23+1 -> 4
A29: 5 | B29: =VLOOKUP(E29,$AK$9:$AL$15,2,FALSE)&"."&VLOOKUP(D29,$AH$9:$AI$24,2,FALSE) -> e 1.5 deg no OS.h48 | C29: =C28+1 -> 21 | D29: =VLOOKUP(AJ29,$AG$9:$AH$22,2,FALSE) -> ts_048 | E29: =E24 -> C1 | Q29: =SUMIFS(iea_data!H3:H9999,iea_data!$B$3:$B$9999,Veda!$S$11) -> 0 | S29: Trd_electricity export | T29: =-1*Q29 -> 0 | AA29: ACT_BND | AB29: FX | AJ29: =AJ24+1 -> 5
A30: 5 | B30: =VLOOKUP(E30,$AK$9:$AL$15,2,FALSE)&"."&VLOOKUP(D30,$AH$9:$AI$24,2,FALSE) -> d 1.5 deg OS.h48 | C30: =C29+1 -> 22 | D30: =VLOOKUP(AJ30,$AG$9:$AH$22,2,FALSE) -> ts_048 | E30: =E25 -> C2 | AJ30: =AJ25+1 -> 5
A31: 5 | B31: =VLOOKUP(E31,$AK$9:$AL$15,2,FALSE)&"."&VLOOKUP(D31,$AH$9:$AI$24,2,FALSE) -> c 2 deg (67%).h48 | C31: =C30+1 -> 23 | D31: =VLOOKUP(AJ31,$AG$9:$AH$22,2,FALSE) -> ts_048 | E31: =E26 -> C3 | AJ31: =AJ26+1 -> 5
A32: 5 | B32: =VLOOKUP(E32,$AK$9:$AL$15,2,FALSE)&"."&VLOOKUP(D32,$AH$9:$AI$24,2,FALSE) -> b 2 deg (50%).h48 | C32: =C31+1 -> 24 | D32: =VLOOKUP(AJ32,$AG$9:$AH$22,2,FALSE) -> ts_048 | E32: =E27 -> C4 | AJ32: =AJ27+1 -> 5
A33: 5 | B33: =VLOOKUP(E33,$AK$9:$AL$15,2,FALSE)&"."&VLOOKUP(D33,$AH$9:$AI$24,2,FALSE) -> a 3 deg.h48 | C33: =C32+1 -> 25 | D33: =VLOOKUP(AJ33,$AG$9:$AH$22,2,FALSE) -> ts_048 | E33: =E28 -> C7 | AJ33: =AJ28+1 -> 5
A34: 5 | B34: =VLOOKUP(E34,$AK$9:$AL$15,2,FALSE)&"."&VLOOKUP(D34,$AH$9:$AI$24,2,FALSE) -> e 1.5 deg no OS.h48P10 | C34: =C33+1 -> 26 | D34: =VLOOKUP(AJ34,$AG$9:$AH$22,2,FALSE) -> ts_048P10 | E34: =E29 -> C1 | AJ34: =AJ29+1 -> 6
A35: 5 | B35: =VLOOKUP(E35,$AK$9:$AL$15,2,FALSE)&"."&VLOOKUP(D35,$AH$9:$AI$24,2,FALSE) -> d 1.5 deg OS.h48P10 | C35: =C34+1 -> 27 | D35: =VLOOKUP(AJ35,$AG$9:$AH$22,2,FALSE) -> ts_048P10 | E35: =E30 -> C2 | AJ35: =AJ30+1 -> 6
A36: 5 | B36: =VLOOKUP(E36,$AK$9:$AL$15,2,FALSE)&"."&VLOOKUP(D36,$AH$9:$AI$24,2,FALSE) -> c 2 deg (67%).h48P10 | C36: =C35+1 -> 28 | D36: =VLOOKUP(AJ36,$AG$9:$AH$22,2,FALSE) -> ts_048P10 | E36: =E31 -> C3 | G36: C7 | AJ36: =AJ31+1 -> 6
A37: 5 | B37: =VLOOKUP(E37,$AK$9:$AL$15,2,FALSE)&"."&VLOOKUP(D37,$AH$9:$AI$24,2,FALSE) -> b 2 deg (50%).h48P10 | C37: =C36+1 -> 29 | D37: =VLOOKUP(AJ37,$AG$9:$AH$22,2,FALSE) -> ts_048P10 | E37: =E32 -> C4 | G37: Gas Price | I37: =SUMIFS(ar6_r10!$F$2:$F$999,ar6_r10!$A$2:$A$999,Veda!$G$36,ar6_r10!$C$2:$C$999,Veda!I$17,ar6_r10!$M$2:$M$999,Veda!$G37) -> 1 | J37: =SUMIFS(ar6_r10!$F$2:$F$999,ar6_r10!$A$2:$A$999,Veda!$G$36,ar6_r10!$C$2:$C$999,Veda!J$17,ar6_r10!$M$2:$M$999,Veda!$G37) -> 1.04 | K37: =SUMIFS(ar6_r10!$F$2:$F$999,ar6_r10!$A$2:$A$999,Veda!$G$36,ar6_r10!$C$2:$C$999,Veda!K$17,ar6_r10!$M$2:$M$999,Veda!$G37) -> 1.37 | L37: =SUMIFS(ar6_r10!$F$2:$F$999,ar6_r10!$A$2:$A$999,Veda!$G$36,ar6_r10!$C$2:$C$999,Veda!L$17,ar6_r10!$M$2:$M$999,Veda!$G37) -> 1.3 | M37: =SUMIFS(ar6_r10!$F$2:$F$999,ar6_r10!$A$2:$A$999,Veda!$G$36,ar6_r10!$C$2:$C$999,Veda!M$17,ar6_r10!$M$2:$M$999,Veda!$G37) -> 1.55 | N37: =SUMIFS(ar6_r10!$F$2:$F$999,ar6_r10!$A$2:$A$999,Veda!$G$36,ar6_r10!$C$2:$C$999,Veda!N$17,ar6_r10!$M$2:$M$999,Veda!$G37) -> 1.63 | O37: =SUMIFS(ar6_r10!$F$2:$F$999,ar6_r10!$A$2:$A$999,Veda!$G$36,ar6_r10!$C$2:$C$999,Veda!O$17,ar6_r10!$M$2:$M$999,Veda!$G37) -> 1.71 | AJ37: =AJ32+1 -> 6
A38: 5 | B38: =VLOOKUP(E38,$AK$9:$AL$15,2,FALSE)&"."&VLOOKUP(D38,$AH$9:$AI$24,2,FALSE) -> a 3 deg.h48P10 | C38: =C37+1 -> 30 | D38: =VLOOKUP(AJ38,$AG$9:$AH$22,2,FALSE) -> ts_048P10 | E38: =E33 -> C7 | G38: Coal Price | I38: =SUMIFS(ar6_r10!$F$2:$F$999,ar6_r10!$A$2:$A$999,Veda!$G$36,ar6_r10!$C$2:$C$999,Veda!I$17,ar6_r10!$M$2:$M$999,Veda!$G38) -> 1 | J38: =SUMIFS(ar6_r10!$F$2:$F$999,ar6_r10!$A$2:$A$999,Veda!$G$36,ar6_r10!$C$2:$C$999,Veda!J$17,ar6_r10!$M$2:$M$999,Veda!$G38) -> 1.08 | K38: =SUMIFS(ar6_r10!$F$2:$F$999,ar6_r10!$A$2:$A$999,Veda!$G$36,ar6_r10!$C$2:$C$999,Veda!K$17,ar6_r10!$M$2:$M$999,Veda!$G38) -> 1.2 | L38: =SUMIFS(ar6_r10!$F$2:$F$999,ar6_r10!$A$2:$A$999,Veda!$G$36,ar6_r10!$C$2:$C$999,Veda!L$17,ar6_r10!$M$2:$M$999,Veda!$G38) -> 1.34 | M38: =SUMIFS(ar6_r10!$F$2:$F$999,ar6_r10!$A$2:$A$999,Veda!$G$36,ar6_r10!$C$2:$C$999,Veda!M$17,ar6_r10!$M$2:$M$999,Veda!$G38) -> 1.52 | N38: =SUMIFS(ar6_r10!$F$2:$F$999,ar6_r10!$A$2:$A$999,Veda!$G$36,ar6_r10!$C$2:$C$999,Veda!N$17,ar6_r10!$M$2:$M$999,Veda!$G38) -> 1.46 | O38: =SUMIFS(ar6_r10!$F$2:$F$999,ar6_r10!$A$2:$A$999,Veda!$G$36,ar6_r10!$C$2:$C$999,Veda!O$17,ar6_r10!$M$2:$M$999,Veda!$G38) -> 1.57 | AJ38: =AJ33+1 -> 6
A39: 5 | B39: =VLOOKUP(E39,$AK$9:$AL$15,2,FALSE)&"."&VLOOKUP(D39,$AH$9:$AI$24,2,FALSE) -> e 1.5 deg no OS.h48P90 | C39: =C38+1 -> 31 | D39: =VLOOKUP(AJ39,$AG$9:$AH$22,2,FALSE) -> ts_048P90 | E39: =E34 -> C1 | G39: Oil Price | I39: =SUMIFS(ar6_r10!$F$2:$F$999,ar6_r10!$A$2:$A$999,Veda!$G$36,ar6_r10!$C$2:$C$999,Veda!I$17,ar6_r10!$M$2:$M$999,Veda!$G39) -> 1 | J39: =SUMIFS(ar6_r10!$F$2:$F$999,ar6_r10!$A$2:$A$999,Veda!$G$36,ar6_r10!$C$2:$C$999,Veda!J$17,ar6_r10!$M$2:$M$999,Veda!$G39) -> 1.15 | K39: =SUMIFS(ar6_r10!$F$2:$F$999,ar6_r10!$A$2:$A$999,Veda!$G$36,ar6_r10!$C$2:$C$999,Veda!K$17,ar6_r10!$M$2:$M$999,Veda!$G39) -> 1.6 | L39: =SUMIFS(ar6_r10!$F$2:$F$999,ar6_r10!$A$2:$A$999,Veda!$G$36,ar6_r10!$C$2:$C$999,Veda!L$17,ar6_r10!$M$2:$M$999,Veda!$G39) -> 1.33 | M39: =SUMIFS(ar6_r10!$F$2:$F$999,ar6_r10!$A$2:$A$999,Veda!$G$36,ar6_r10!$C$2:$C$999,Veda!M$17,ar6_r10!$M$2:$M$999,Veda!$G39) -> 1.47 | N39: =SUMIFS(ar6_r10!$F$2:$F$999,ar6_r10!$A$2:$A$999,Veda!$G$36,ar6_r10!$C$2:$C$999,Veda!N$17,ar6_r10!$M$2:$M$999,Veda!$G39) -> 1.61 | O39: =SUMIFS(ar6_r10!$F$2:$F$999,ar6_r10!$A$2:$A$999,Veda!$G$36,ar6_r10!$C$2:$C$999,Veda!O$17,ar6_r10!$M$2:$M$999,Veda!$G39) -> 1.77 | AJ39: =AJ34+1 -> 7
A40: 5 | B40: =VLOOKUP(E40,$AK$9:$AL$15,2,FALSE)&"."&VLOOKUP(D40,$AH$9:$AI$24,2,FALSE) -> d 1.5 deg OS.h48P90 | C40: =C39+1 -> 32 | D40: =VLOOKUP(AJ40,$AG$9:$AH$22,2,FALSE) -> ts_048P90 | E40: =E35 -> C2 | G40: Biomass Price | I40: =SUMIFS(ar6_r10!$F$2:$F$999,ar6_r10!$A$2:$A$999,Veda!$G$36,ar6_r10!$C$2:$C$999,Veda!I$17,ar6_r10!$M$2:$M$999,Veda!$G40) -> 1 | J40: =SUMIFS(ar6_r10!$F$2:$F$999,ar6_r10!$A$2:$A$999,Veda!$G$36,ar6_r10!$C$2:$C$999,Veda!J$17,ar6_r10!$M$2:$M$999,Veda!$G40) -> 0.84 | K40: =SUMIFS(ar6_r10!$F$2:$F$999,ar6_r10!$A$2:$A$999,Veda!$G$36,ar6_r10!$C$2:$C$999,Veda!K$17,ar6_r10!$M$2:$M$999,Veda!$G40) -> 0.79 | L40: =SUMIFS(ar6_r10!$F$2:$F$999,ar6_r10!$A$2:$A$999,Veda!$G$36,ar6_r10!$C$2:$C$999,Veda!L$17,ar6_r10!$M$2:$M$999,Veda!$G40) -> 0.82 | M40: =SUMIFS(ar6_r10!$F$2:$F$999,ar6_r10!$A$2:$A$999,Veda!$G$36,ar6_r10!$C$2:$C$999,Veda!M$17,ar6_r10!$M$2:$M$999,Veda!$G40) -> 0.86 | N40: =SUMIFS(ar6_r10!$F$2:$F$999,ar6_r10!$A$2:$A$999,Veda!$G$36,ar6_r10!$C$2:$C$999,Veda!N$17,ar6_r10!$M$2:$M$999,Veda!$G40) -> 0.88 | O40: =SUMIFS(ar6_r10!$F$2:$F$999,ar6_r10!$A$2:$A$999,Veda!$G$36,ar6_r10!$C$2:$C$999,Veda!O$17,ar6_r10!$M$2:$M$999,Veda!$G40) -> 0.9 | AJ40: =AJ35+1 -> 7
A41: 5 | B41: =VLOOKUP(E41,$AK$9:$AL$15,2,FALSE)&"."&VLOOKUP(D41,$AH$9:$AI$24,2,FALSE) -> c 2 deg (67%).h48P90 | C41: =C40+1 -> 33 | D41: =VLOOKUP(AJ41,$AG$9:$AH$22,2,FALSE) -> ts_048P90 | E41: =E36 -> C3 | AJ41: =AJ36+1 -> 7
A42: 5 | B42: =VLOOKUP(E42,$AK$9:$AL$15,2,FALSE)&"."&VLOOKUP(D42,$AH$9:$AI$24,2,FALSE) -> b 2 deg (50%).h48P90 | C42: =C41+1 -> 34 | D42: =VLOOKUP(AJ42,$AG$9:$AH$22,2,FALSE) -> ts_048P90 | E42: =E37 -> C4 | AJ42: =AJ37+1 -> 7
...

Sheet fuel_prices
A9: Fuel Prices
A10: iso | B10: gas_low | C10: gas_high | D10: coal_low | E10: coal_high | F10: oil_low | G10: oil_high | H10: bioenergy_low | I10: bioenergy_high | J10: Notes
A11: UGA | B11: 24 | C11: 34.3 | D11: 12.2 | E11: 16.7 | F11: 42 | G11: 52 | H11: 12 | I11: 20 | J11: Oil discoveries, agricultural waste

Sheet iea_data
A9: IEA Baseline Data
A10: iso | B10: year | C10: industry_twh | D10: buildings_agri_twh | E10: nonroad_transport_twh | F10: road_transport_twh | G10: imports_twh | H10: exports_twh | I10: total_production_twh

Sheet ar6_r10
A9: AR6 Scenario Drivers
A10: Category | B10: Region | C10: Year | D10: count | E10: mean | F10: median | G10: std | H10: min | I10: max | J10: q25 | K10: q75 | L10: category_description | M10: attribute
A11: C1 | B11: R10AFRICA | C11: 2020 | D11: 58 | E11: 4.4 | F11: 0.43 | G11: 5.71 | H11: 0 | I11: 15.58 | J11: 0 | K11: 8.31 | L11: Limit warming to 1.5°C (>50%) with no or limited overshoot | M11: CO2 price
A12: C1 | B12: R10AFRICA | C12: 2025 | D12: 58 | E12: 132.94 | F12: 113.94 | G12: 135.33 | H12: 13.36 | I12: 626.48 | J12: 28.22 | K12: 179.27 | L12: Limit warming to 1.5°C (>50%) with no or limited overshoot | M12: CO2 price
A13: C1 | B13: R10AFRICA | C13: 2030 | D13: 58 | E13: 191.57 | F13: 180.17 | G13: 130.46 | H13: 3.02 | I13: 673.46 | J13: 89.49 | K13: 241.69 | L13: Limit warming to 1.5°C (>50%) with no or limited overshoot | M13: CO2 price
A14: C1 | B14: R10AFRICA | C14: 2035 | D14: 58 | E14: 278.86 | F14: 243.45 | G14: 167.16 | H14: 9.51 | I14: 859.53 | J14: 142.95 | K14: 358.71 | L14: Limit warming to 1.5°C (>50%) with no or limited overshoot | M14: CO2 price
A15: C1 | B15: R10AFRICA | C15: 2040 | D15: 58 | E15: 397.63 | F15: 326.01 | G15: 215.59 | H15: 115.55 | I15: 1097.01 | J15: 239.53 | K15: 539.74 | L15: Limit warming to 1.5°C (>50%) with no or limited overshoot | M15: CO2 price
A16: C1 | B16: R10AFRICA | C16: 2045 | D16: 58 | E16: 527.26 | F16: 415.81 | G16: 250.01 | H16: 193.42 | I16: 1269.88 | J16: 353.85 | K16: 714.5 | L16: Limit warming to 1.5°C (>50%) with no or limited overshoot | M16: CO2 price
A17: C1 | B17: R10AFRICA | C17: 2050 | D17: 58 | E17: 649.79 | F17: 605.23 | G17: 268.91 | H17: 209.76 | I17: 1271.76 | J17: 451.31 | K17: 863.42 | L17: Limit warming to 1.5°C (>50%) with no or limited overshoot | M17: CO2 price
A18: C2 | B18: R10AFRICA | C18: 2020 | D18: 76 | E18: 1.95 | F18: 0 | G18: 3.61 | H18: 0 | I18: 15.58 | J18: 0 | K18: 0.55 | L18: Limit warming to 1.5°C (>67%) with high overshoot | M18: CO2 price
A19: C2 | B19: R10AFRICA | C19: 2025 | D19: 65 | E19: 42.95 | F19: 32.69 | G19: 45.96 | H19: 0 | I19: 174.97 | J19: 5.54 | K19: 61.39 | L19: Limit warming to 1.5°C (>67%) with high overshoot | M19: CO2 price
A20: C2 | B20: R10AFRICA | C20: 2030 | D20: 76 | E20: 55.8 | F20: 49.85 | G20: 54.52 | H20: 0 | I20: 221.93 | J20: 10.8 | K20: 78.77 | L20: Limit warming to 1.5°C (>67%) with high overshoot | M20: CO2 price
A21: C2 | B21: R10AFRICA | C21: 2035 | D21: 65 | E21: 217.07 | F21: 152.99 | G21: 316.2 | H21: 29.98 | I21: 2037.12 | J21: 95.06 | K21: 208.88 | L21: Limit warming to 1.5°C (>67%) with high overshoot | M21: CO2 price
A22: C2 | B22: R10AFRICA | C22: 2040 | D22: 76 | E22: 257.11 | F22: 191.71 | G22: 381.8 | H22: 0 | I22: 2600 | J22: 106.05 | K22: 261.57 | L22: Limit warming to 1.5°C (>67%) with high overshoot | M22: CO2 price
... A360: C7 | B360: R10AFRICA | C360: 2050 | D360: 7 | E360: 0.94 | F360: 0.9 | G360: 0.15 | H360: 0.84 | I360: 1.28 | J360: 0.87 | K360: 0.92 | L360: Likely above 3°C warming with limited mitigation | M360: Biomass price

Sheet ev_charging_uc
A10: =IFERROR(Veda!D5,"ts_12t") -> ts_annual | C10: day_night | D10: ts_030 | F10: day_night | G10: ts_048 | I10: day_night | J10: s1_d | L10: day_night | M10: s1v1_d | O10: day_night | P10: ts_annual | R10: day_night | S10: ts_12t
C11: D | D11: S01aH01 | F11: D | G11: S01aH01 | I11: D | J11: S01b0101h18,S01aH01,S01b0101h09,S01b0101h12,S01b0101h14,S01b0101h13,S01b0101h15,S01b0101h17,S01b0101h07,S01b0101h08,S01b0101h10,S01b0101h11,S01b0101h16 | L11: D | M11: S01b0101h13,S01b0101h15,S01c0102h11,S01c0102h13,S01b0101h16,S01c0102h17,S01c0102h09,S01c0102h16,S01b0101h08,S01b0101h18,S01b0101h12,S01c0102h12,S01c0102h14,S01c0102h08,S01c0102h10,S01b0101h17,S01aH01,S01b0101h09,S01b0101h10,S01b0101h11,S01b0101h07,S01c0102h07,S01b0101h14,S01c0102h15,S01c0102h18 | O11: D | P11: AllSaAllH | R11: D | S11: RaP,FaD,SaD,RaD,WaP,FaP,SaP,WaD
C12: N | D12: S01aH03,S01aH04,S01aH02 | F12: N | G12: S01aH03,S01aH02,S01aH04,S01aH05 | I12: N | J12: S01aH02,S01aH04,S01b0101h21,S01b0101h19,S01b0101h22,S01b0101h06,S01b0101h24,S01aH03,S01b0101h02,S01b0101h23,S01aH05,S01b0101h01,S01b0101h04,S01b0101h05,S01b0101h03,S01b0101h20 | L12: N | M12: S01aH04,S01b0101h21,S01aH03,S01b0101h02,S01b0101h23,S01c0102h06,S01b0101h04,S01b0101h05,S01b0101h03,S01b0101h20,S01c0102h19,S01c0102h20,S01b0101h19,S01b0101h22,S01c0102h23,S01c0102h04,S01c0102h24,S01aH05,S01aH02,S01c0102h02,S01c0102h05,S01b0101h06,S01c0102h01,S01c0102h21,S01b0101h01,S01c0102h03,S01c0102h22,S01b0101h24 | O12: N | P12: AllSaAllH | R12: N | S12: RaP,FaP,SaP,RaN,WaP,SaN,WaN,FaN
I17: 0.75 | K17: share of charging at night
C18: ~UC_Sets: R_E: AllRegions
H21: =IF(H23=H24,"Not Required!","~UC_T: LO") -> Not Required!
C22: UC_N | D22: Pset_CI | E22: Pset_CO | F22: pset_pn | G22: Cset_CN | H22: TimeSlice | I22: UC_FLO | J22: UC_RHSRT | K22: UC_RHSRT~0
C23: UC_bev night chg limit | D23: ELC | E23: =G23 -> AuxStoIN | F23: *EV* | G23: AuxStoIN | H23: =HLOOKUP($A$10,$D$10:$CU$12,3,FALSE) -> AllSaAllH | I23: =1+I24 -> 0.25 | J23: 0 | K23: 3 | M23: night
D24: ELC | E24: =G24 -> AuxStoIN | F24: *EV* | G24: AuxStoIN | H24: =HLOOKUP($A$10,$D$10:$CU$12,2,FALSE) -> AllSaAllH | I24: =-$I$17 -> -0.75 | M24: day

Sheet ts_012
C9: =IF(A11="x","DeActivated","~TimeSlices") -> DeActivated
A10: ts_012 | C10: season | D10: weekly | E10: daynite | F10: wparent | G10: dparent
A11: =IFERROR(IF(Veda!D5=A10,"ok","x"),"") -> x | C11: S01 | D11: a | E11: H01 | F11: S01 | G11: a
E12: H02 | G12: a

Sheet ts_030
C9: =IF(A11="x","DeActivated","~TimeSlices") -> DeActivated | I9: =IF(A11="x","DeActivated","~TFM_DINS-AT") -> DeActivated | N9: =IF(A11="x","DeActivated","~TFM_DINS-AT") -> DeActivated | S9: =IF(A11="x","DeActivated","~TFM_DINS-AT") -> DeActivated | X9: =IF(A11="x","DeActivated","~TFM_DINS-AT") -> DeActivated
A10: ts_030 | C10: season | D10: weekly | E10: daynite | F10: wparent | G10: dparent | I10: commodity | J10: timeslice | K10: com_fr | L10: process | N10: commodity | O10: timeslice | P10: com_fr | Q10: process | S10: commodity | T10: timeslice | U10: com_fr | V10: process | X10: g_yrfr | Y10: com_fr | Z10: timeslice | AA10: commodity
A11: =IFERROR(IF(Veda!D5=A10,"ok","x"),"") -> x | C11: S01 | D11: a | E11: H01 | F11: S01 | G11: a | I11: elc_spv_001 | J11: S01aH01 | K11: 1 | L11: IMPNRGZ | N11: elc_won_001 | O11: S01aH01 | P11: 0.85637232 | Q11: IMPNRGZ | S11: elc_wof_001 | T11: S01aH01 | U11: 0.85637232 | V11: IMPNRGZ | X11: 0.875 | Y11: 0.93950393 | Z11: S01aH01 | AA11: elc_roadtransport
E12: H02 | G12: a | I12: elc_spv_001 | J12: S01aH02 | K12: 0 | L12: IMPNRGZ | N12: elc_won_001 | O12: S01aH02 | P12: 0.053956079 | Q12: IMPNRGZ | S12: elc_wof_001 | T12: S01aH02 | U12: 0.053956079 | V12: IMPNRGZ | X12: 0.041666667 | Y12: 0.029038113 | Z12: S01aH02 | AA12: elc_roadtransport
E13: H03 | G13: a | I13: elc_spv_001 | J13: S01aH03 | K13: 0 | L13: IMPNRGZ | N13: elc_won_001 | O13: S01aH03 | P13: 0.048621924 | Q13: IMPNRGZ | S13: elc_wof_001 | T13: S01aH03 | U13: 0.048621924 | V13: IMPNRGZ | X13: 0.041666667 | Y13: 0.020568663 | Z13: S01aH03 | AA13: elc_roadtransport
E14: H04 | G14: a | I14: elc_spv_001 | J14: S01aH04 | K14: 0 | L14: IMPNRGZ | N14: elc_won_001 | O14: S01aH04 | P14: 0.041049672 | Q14: IMPNRGZ | S14: elc_wof_001 | T14: S01aH04 | U14: 0.041049672 | V14: IMPNRGZ | X14: 0.041666667 | Y14: 0.010889292 | Z14: S01aH04 | AA14: elc_roadtransport
I15: elc_spv_002 | J15: S01aH01 | K15: 1 | L15: IMPNRGZ | N15: elc_won_002 | O15: S01aH01 | P15: 0.89239818 | Q15: IMPNRGZ | S15: elc_wof_002 | T15: S01aH01 | U15: 0.89239818 | V15: IMPNRGZ
I16: elc_spv_002 | J16: S01aH02 | K16: 0 | L16: IMPNRGZ | N16: elc_won_002 | O16: S01aH02 | P16: 0.04033766 | Q16: IMPNRGZ | S16: elc_wof_002 | T16: S01aH02 | U16: 0.04033766 | V16: IMPNRGZ
I17: elc_spv_002 | J17: S01aH03 | K17: 0 | L17: IMPNRGZ | N17: elc_won_002 | O17: S01aH03 | P17: 0.036232557 | Q17: IMPNRGZ | S17: elc_wof_002 | T17: S01aH03 | U17: 0.036232557 | V17: IMPNRGZ
I18: elc_spv_002 | J18: S01aH04 | K18: 0 | L18: IMPNRGZ | N18: elc_won_002 | O18: S01aH04 | P18: 0.0310316 | Q18: IMPNRGZ | S18: elc_wof_002 | T18: S01aH04 | U18: 0.0310316 | V18: IMPNRGZ
I19: elc_spv_003 | J19: S01aH01 | K19: 1 | L19: IMPNRGZ | N19: elc_won_003 | O19: S01aH01 | P19: 0.86542194 | Q19: IMPNRGZ | S19: elc_wof_003 | T19: S01aH01 | U19: 0.86542194 | V19: IMPNRGZ
I20: elc_spv_003 | J20: S01aH02 | K20: 0 | L20: IMPNRGZ | N20: elc_won_003 | O20: S01aH02 | P20: 0.053566747 | Q20: IMPNRGZ | S20: elc_wof_003 | T20: S01aH02 | U20: 0.053566747 | V20: IMPNRGZ
I21: elc_spv_003 | J21: S01aH03 | K21: 0 | L21: IMPNRGZ | N21: elc_won_003 | O21: S01aH03 | P21: 0.044695857 | Q21: IMPNRGZ | S21: elc_wof_003 | T21: S01aH03 | U21: 0.044695857 | V21: IMPNRGZ
I22: elc_spv_003 | J22: S01aH04 | K22: 0 | L22: IMPNRGZ | N22: elc_won_003 | O22: S01aH04 | P22: 0.036315459 | Q22: IMPNRGZ | S22: elc_wof_003 | T22: S01aH04 | U22: 0.036315459 | V22: IMPNRGZ
I23: elc_spv_004 | J23: S01aH01 | K23: 1 | L23: IMPNRGZ | N23: elc_won_004 | O23: S01aH01 | P23: 0.89410943 | Q23: IMPNRGZ | S23: elc_wof_004 | T23: S01aH01 | U23: 0.89410943 | V23: IMPNRGZ
I24: elc_spv_004 | J24: S01aH02 | K24: 0 | L24: IMPNRGZ | N24: elc_won_004 | O24: S01aH02 | P24: 0.041810028 | Q24: IMPNRGZ | S24: elc_wof_004 | T24: S01aH02 | U24: 0.041810028 | V24: IMPNRGZ
I25: elc_spv_004 | J25: S01aH03 | K25: 0 | L25: IMPNRGZ | N25: elc_won_004 | O25: S01aH03 | P25: 0.034802644 | Q25: IMPNRGZ | S25: elc_wof_004 | T25: S01aH03 | U25: 0.034802644 | V25: IMPNRGZ
I26: elc_spv_004 | J26: S01aH04 | K26: 0 | L26: IMPNRGZ | N26: elc_won_004 | O26: S01aH04 | P26: 0.029277901 | Q26: IMPNRGZ | S26: elc_wof_004 | T26: S01aH04 | U26: 0.029277901 | V26: IMPNRGZ
... I30: elc_spv_005 | J30: S01aH04 | K30: 0 | L30: IMPNRGZ | N30: elc_won_005 | O30: S01aH04 | P30: 0.024652976 | Q30: IMPNRGZ | S30: elc_wof_005 | T30: S01aH04 | U30: 0.024652976 | V30: IMPNRGZ
I31: elc_spv_006 | J31: S01aH01 | K31: 1 | L31: IMPNRGZ
I32: elc_spv_006 | J32: S01aH02 | K32: 0 | L32: IMPNRGZ
I33: elc_spv_006 | J33: S01aH03 | K33: 0 | L33: IMPNRGZ
I34: elc_spv_006 | J34: S01aH04 | K34: 0 | L34: IMPNRGZ
I35: elc_spv_007 | J35: S01aH01 | K35: 1 | L35: IMPNRGZ
I36: elc_spv_007 | J36: S01aH02 | K36: 0 | L36: IMPNRGZ
I37: elc_spv_007 | J37: S01aH03 | K37: 0 | L37: IMPNRGZ
I38: elc_spv_007 | J38: S01aH04 | K38: 0 | L38: IMPNRGZ
I39: elc_spv_008 | J39: S01aH01 | K39: 1 | L39: IMPNRGZ
I40: elc_spv_008 | J40: S01aH02 | K40: 0 | L40: IMPNRGZ
I41: elc_spv_008 | J41: S01aH03 | K41: 0 | L41: IMPNRGZ
I42: elc_spv_008 | J42: S01aH04 | K42: 0 | L42: IMPNRGZ
... I78: elc_spv_017 | J78: S01aH04 | K78: 0 | L78: IMPNRGZ

Sheet ts_048
C9: =IF(A11="x","DeActivated","~TimeSlices") -> DeActivated | I9: =IF(A11="x","DeActivated","~TFM_DINS-AT") -> DeActivated | N9: =IF(A11="x","DeActivated","~TFM_DINS-AT") -> DeActivated | S9: =IF(A11="x","DeActivated","~TFM_DINS-AT") -> DeActivated | X9: =IF(A11="x","DeActivated","~TFM_DINS-AT") -> DeActivated
A10: ts_048 | C10: season | D10: weekly | E10: daynite | F10: wparent | G10: dparent | I10: commodity | J10: timeslice | K10: com_fr | L10: process | N10: commodity | O10: timeslice | P10: com_fr | Q10: process | S10: commodity | T10: timeslice | U10: com_fr | V10: process | X10: g_yrfr | Y10: com_fr | Z10: timeslice | AA10: commodity
A11: =IFERROR(IF(Veda!D5=A10,"ok","x"),"") -> x | C11: S01 | D11: a | E11: H01 | F11: S01 | G11: a | I11: elc_spv_001 | J11: S01aH01 | K11: 1 | L11: IMPNRGZ | N11: elc_won_001 | O11: S01aH01 | P11: 0.80298053 | Q11: IMPNRGZ | S11: elc_wof_001 | T11: S01aH01 | U11: 0.80298053 | V11: IMPNRGZ | X11: 0.83333333 | Y11: 0.89957653 | Z11: S01aH01 | AA11: elc_roadtransport
E12: H02 | G12: a | I12: elc_spv_001 | J12: S01aH02 | K12: 0 | L12: IMPNRGZ | N12: elc_won_001 | O12: S01aH02 | P12: 0.053391799 | Q12: IMPNRGZ | S12: elc_wof_001 | T12: S01aH02 | U12: 0.053391799 | V12: IMPNRGZ | X12: 0.041666667 | Y12: 0.039927405 | Z12: S01aH02 | AA12: elc_roadtransport
E13: H03 | G13: a | I13: elc_spv_001 | J13: S01aH03 | K13: 0 | L13: IMPNRGZ | N13: elc_won_001 | O13: S01aH03 | P13: 0.053956079 | Q13: IMPNRGZ | S13: elc_wof_001 | T13: S01aH03 | U13: 0.053956079 | V13: IMPNRGZ | X13: 0.041666667 | Y13: 0.029038113 | Z13: S01aH03 | AA13: elc_roadtransport
E14: H04 | G14: a | I14: elc_spv_001 | J14: S01aH04 | K14: 0 | L14: IMPNRGZ | N14: elc_won_001 | O14: S01aH04 | P14: 0.048621924 | Q14: IMPNRGZ | S14: elc_wof_001 | T14: S01aH04 | U14: 0.048621924 | V14: IMPNRGZ | X14: 0.041666667 | Y14: 0.020568663 | Z14: S01aH04 | AA14: elc_roadtransport
E15: H05 | G15: a | I15: elc_spv_001 | J15: S01aH05 | K15: 0 | L15: IMPNRGZ | N15: elc_won_001 | O15: S01aH05 | P15: 0.041049672 | Q15: IMPNRGZ | S15: elc_wof_001 | T15: S01aH05 | U15: 0.041049672 | V15: IMPNRGZ | X15: 0.041666667 | Y15: 0.010889292 | Z15: S01aH05 | AA15: elc_roadtransport
I16: elc_spv_002 | J16: S01aH01 | K16: 1 | L16: IMPNRGZ | N16: elc_won_002 | O16: S01aH01 | P16: 0.85194469 | Q16: IMPNRGZ | S16: elc_wof_002 | T16: S01aH01 | U16: 0.85194469 | V16: IMPNRGZ
I17: elc_spv_002 | J17: S01aH02 | K17: 0 | L17: IMPNRGZ | N17: elc_won_002 | O17: S01aH02 | P17: 0.040453497 | Q17: IMPNRGZ | S17: elc_wof_002 | T17: S01aH02 | U17: 0.040453497 | V17: IMPNRGZ
I18: elc_spv_002 | J18: S01aH03 | K18: 0 | L18: IMPNRGZ | N18: elc_won_002 | O18: S01aH03 | P18: 0.04033766 | Q18: IMPNRGZ | S18: elc_wof_002 | T18: S01aH03 | U18: 0.04033766 | V18: IMPNRGZ
I19: elc_spv_002 | J19: S01aH04 | K19: 0 | L19: IMPNRGZ | N19: elc_won_002 | O19: S01aH04 | P19: 0.036232557 | Q19: IMPNRGZ | S19: elc_wof_002 | T19: S01aH04 | U19: 0.036232557 | V19: IMPNRGZ
I20: elc_spv_002 | J20: S01aH05 | K20: 0 | L20: IMPNRGZ | N20: elc_won_002 | O20: S01aH05 | P20: 0.0310316 | Q20: IMPNRGZ | S20: elc_wof_002 | T20: S01aH05 | U20: 0.0310316 | V20: IMPNRGZ
I21: elc_spv_003 | J21: S01aH01 | K21: 1 | L21: IMPNRGZ | N21: elc_won_003 | O21: S01aH01 | P21: 0.80668991 | Q21: IMPNRGZ | S21: elc_wof_003 | T21: S01aH01 | U21: 0.80668991 | V21: IMPNRGZ
I22: elc_spv_003 | J22: S01aH02 | K22: 0 | L22: IMPNRGZ | N22: elc_won_003 | O22: S01aH02 | P22: 0.058732029 | Q22: IMPNRGZ | S22: elc_wof_003 | T22: S01aH02 | U22: 0.058732029 | V22: IMPNRGZ
I23: elc_spv_003 | J23: S01aH03 | K23: 0 | L23: IMPNRGZ | N23: elc_won_003 | O23: S01aH03 | P23: 0.053566747 | Q23: IMPNRGZ | S23: elc_wof_003 | T23: S01aH03 | U23: 0.053566747 | V23: IMPNRGZ
I24: elc_spv_003 | J24: S01aH04 | K24: 0 | L24: IMPNRGZ | N24: elc_won_003 | O24: S01aH04 | P24: 0.044695857 | Q24: IMPNRGZ | S24: elc_wof_003 | T24: S01aH04 | U24: 0.044695857 | V24: IMPNRGZ
I25: elc_spv_003 | J25: S01aH05 | K25: 0 | L25: IMPNRGZ | N25: elc_won_003 | O25: S01aH05 | P25: 0.036315459 | Q25: IMPNRGZ | S25: elc_wof_003 | T25: S01aH05 | U25: 0.036315459 | V25: IMPNRGZ
I26: elc_spv_004 | J26: S01aH01 | K26: 1 | L26: IMPNRGZ | N26: elc_won_004 | O26: S01aH01 | P26: 0.84771988 | Q26: IMPNRGZ | S26: elc_wof_004 | T26: S01aH01 | U26: 0.84771988 | V26: IMPNRGZ
I27: elc_spv_004 | J27: S01aH02 | K27: 0 | L27: IMPNRGZ | N27: elc_won_004 | O27: S01aH02 | P27: 0.046389549 | Q27: IMPNRGZ | S27: elc_wof_004 | T27: S01aH02 | U27: 0.046389549 | V27: IMPNRGZ
... I35: elc_spv_005 | J35: S01aH05 | K35: 0 | L35: IMPNRGZ | N35: elc_won_005 | O35: S01aH05 | P35: 0.024652976 | Q35: IMPNRGZ | S35: elc_wof_005 | T35: S01aH05 | U35: 0.024652976 | V35: IMPNRGZ
I36: elc_spv_006 | J36: S01aH01 | K36: 1 | L36: IMPNRGZ
I37: elc_spv_006 | J37: S01aH02 | K37: 0 | L37: IMPNRGZ
I38: elc_spv_006 | J38: S01aH03 | K38: 0 | L38: IMPNRGZ
I39: elc_spv_006 | J39: S01aH04 | K39: 0 | L39: IMPNRGZ
I40: elc_spv_006 | J40: S01aH05 | K40: 0 | L40: IMPNRGZ
I41: elc_spv_007 | J41: S01aH01 | K41: 1 | L41: IMPNRGZ
I42: elc_spv_007 | J42: S01aH02 | K42: 0 | L42: IMPNRGZ
I43: elc_spv_007 | J43: S01aH03 | K43: 0 | L43: IMPNRGZ
I44: elc_spv_007 | J44: S01aH04 | K44: 0 | L44: IMPNRGZ
I45: elc_spv_007 | J45: S01aH05 | K45: 0 | L45: IMPNRGZ
I46: elc_spv_008 | J46: S01aH01 | K46: 1 | L46: IMPNRGZ
I47: elc_spv_008 | J47: S01aH02 | K47: 0 | L47: IMPNRGZ
... I95: elc_spv_017 | J95: S01aH05 | K95: 0 | L95: IMPNRGZ

Sheet s1_d
C9: =IF(A11="x","DeActivated","~TimeSlices") -> DeActivated | I9: =IF(A11="x","DeActivated","~TFM_DINS-AT") -> DeActivated | N9: =IF(A11="x","DeActivated","~TFM_DINS-AT") -> DeActivated | S9: =IF(A11="x","DeActivated","~TFM_DINS-AT") -> DeActivated | X9: =IF(A11="x","DeActivated","~TFM_DINS-AT") -> DeActivated
A10: s1_d | C10: season | D10: weekly | E10: daynite | F10: wparent | G10: dparent | I10: commodity | J10: timeslice | K10: com_fr | L10: process | N10: commodity | O10: timeslice | P10: com_fr | Q10: process | S10: commodity | T10: timeslice | U10: com_fr | V10: process | X10: g_yrfr | Y10: com_fr | Z10: timeslice | AA10: commodity
A11: =IFERROR(IF(Veda!D5=A10,"ok","x"),"") -> x | C11: S01 | D11: a | E11: 0101h01 | F11: S01 | G11: b | I11: elc_spv_001 | J11: S01aH01 | K11: 0.99678665 | L11: IMPNRGZ | N11: elc_won_001 | O11: S01aH01 | P11: 0.80157882 | Q11: IMPNRGZ | S11: elc_wof_001 | T11: S01aH01 | U11: 0.80157882 | V11: IMPNRGZ | X11: 0.83105023 | Y11: 0.89711193 | Z11: S01aH01 | AA11: elc_roadtransport
D12: b | E12: 0101h02 | F12: S01 | G12: b | I12: elc_spv_001 | J12: S01aH02 | K12: 0 | L12: IMPNRGZ | N12: elc_won_001 | O12: S01aH02 | P12: 0.053026236 | Q12: IMPNRGZ | S12: elc_wof_001 | T12: S01aH02 | U12: 0.053026236 | V12: IMPNRGZ | X12: 0.041552511 | Y12: 0.039818015 | Z12: S01aH02 | AA12: elc_roadtransport
E13: 0101h03 | G13: b | I13: elc_spv_001 | J13: S01aH03 | K13: 0 | L13: IMPNRGZ | N13: elc_won_001 | O13: S01aH03 | P13: 0.053616375 | Q13: IMPNRGZ | S13: elc_wof_001 | T13: S01aH03 | U13: 0.053616375 | V13: IMPNRGZ | X13: 0.041552511 | Y13: 0.028958556 | Z13: S01aH03 | AA13: elc_roadtransport
E14: 0101h04 | G14: b | I14: elc_spv_001 | J14: S01aH04 | K14: 0 | L14: IMPNRGZ | N14: elc_won_001 | O14: S01aH04 | P14: 0.048351447 | Q14: IMPNRGZ | S14: elc_wof_001 | T14: S01aH04 | U14: 0.048351447 | V14: IMPNRGZ | X14: 0.041552511 | Y14: 0.020512311 | Z14: S01aH04 | AA14: elc_roadtransport
E15: 0101h05 | G15: b | I15: elc_spv_001 | J15: S01aH05 | K15: 0 | L15: IMPNRGZ | N15: elc_won_001 | O15: S01aH05 | P15: 0.040837076 | Q15: IMPNRGZ | S15: elc_wof_001 | T15: S01aH05 | U15: 0.040837076 | V15: IMPNRGZ | X15: 0.041552511 | Y15: 0.010859459 | Z15: S01aH05 | AA15: elc_roadtransport
E16: 0101h06 | G16: b | I16: elc_spv_001 | J16: S01b0101h01 | K16: 0 | L16: IMPNRGZ | N16: elc_won_001 | O16: S01b0101h01 | P16: 2.1666408e-05 | Q16: IMPNRGZ | S16: elc_wof_001 | T16: S01b0101h01 | U16: 2.1666408e-05 | V16: IMPNRGZ | X16: 0.00011415525 | Y16: 2.1546545e-05 | Z16: S01b0101h01 | AA16: elc_roadtransport
E17: 0101h07 | G17: b | I17: elc_spv_001 | J17: S01b0101h02 | K17: 0 | L17: IMPNRGZ | N17: elc_won_001 | O17: S01b0101h02 | P17: 1.4922984e-05 | Q17: IMPNRGZ | S17: elc_wof_001 | T17: S01b0101h02 | U17: 1.4922984e-05 | V17: IMPNRGZ | X17: 0.00011415525 | Y17: 1.4916839e-05 | Z17: S01b0101h02 | AA17: elc_roadtransport
E18: 0101h08 | G18: b | I18: elc_spv_001 | J18: S01b0101h03 | K18: 0 | L18: IMPNRGZ | N18: elc_won_001 | O18: S01b0101h03 | P18: 1.3659638e-05 | Q18: IMPNRGZ | S18: elc_wof_001 | T18: S01b0101h03 | U18: 1.3659638e-05 | V18: IMPNRGZ | X18: 0.00011415525 | Y18: 1.6574265e-05 | Z18: S01b0101h03 | AA18: elc_roadtransport
E19: 0101h09 | G19: b | I19: elc_spv_001 | J19: S01b0101h04 | K19: 0 | L19: IMPNRGZ | N19: elc_won_001 | O19: S01b0101h04 | P19: 2.1244554e-05 | Q19: IMPNRGZ | S19: elc_wof_001 | T19: S01b0101h04 | U19: 2.1244554e-05 | V19: IMPNRGZ | X19: 0.00011415525 | Y19: 1.4585353e-05 | Z19: S01b0101h04 | AA19: elc_roadtransport
E20: 0101h10 | G20: b | I20: elc_spv_001 | J20: S01b0101h05 | K20: 0 | L20: IMPNRGZ | N20: elc_won_001 | O20: S01b0101h05 | P20: 1.9842827e-05 | Q20: IMPNRGZ | S20: elc_wof_001 | T20: S01b0101h05 | U20: 1.9842827e-05 | V20: IMPNRGZ | X20: 0.00011415525 | Y20: 2.1215059e-05 | Z20: S01b0101h05 | AA20: elc_roadtransport
E21: 0101h11 | G21: b | I21: elc_spv_001 | J21: S01b0101h06 | K21: 0 | L21: IMPNRGZ | N21: elc_won_001 | O21: S01b0101h06 | P21: 1.8525786e-05 | Q21: IMPNRGZ | S21: elc_wof_001 | T21: S01b0101h06 | U21: 1.8525786e-05 | V21: IMPNRGZ | X21: 0.00011415525 | Y21: 5.7678443e-05 | Z21: S01b0101h06 | AA21: elc_roadtransport
E22: 0101h12 | G22: b | I22: elc_spv_001 | J22: S01b0101h07 | K22: 0 | L22: IMPNRGZ | N22: elc_won_001 | O22: S01b0101h07 | P22: 1.800281e-05 | Q22: IMPNRGZ | S22: elc_wof_001 | T22: S01b0101h07 | U22: 1.800281e-05 | V22: IMPNRGZ | X22: 0.00011415525 | Y22: 0.0001690575 | Z22: S01b0101h07 | AA22: elc_roadtransport
E23: 0101h13 | G23: b | I23: elc_spv_001 | J23: S01b0101h08 | K23: 0.00011983367 | L23: IMPNRGZ | N23: elc_won_001 | O23: S01b0101h08 | P23: 1.5135502e-05 | Q23: IMPNRGZ | S23: elc_wof_001 | T23: S01b0101h08 | U23: 1.5135502e-05 | V23: IMPNRGZ | X23: 0.00011415525 | Y23: 0.00019060405 | Z23: S01b0101h08 | AA23: elc_roadtransport
E24: 0101h14 | G24: b | I24: elc_spv_001 | J24: S01b0101h09 | K24: 0.00024890525 | L24: IMPNRGZ | N24: elc_won_001 | O24: S01b0101h09 | P24: 3.1424963e-07 | Q24: IMPNRGZ | S24: elc_wof_001 | T24: S01b0101h09 | U24: 3.1424963e-07 | V24: IMPNRGZ | X24: 0.00011415525 | Y24: 0.00014585353 | Z24: S01b0101h09 | AA24: elc_roadtransport
... E39: H05 | G39: a | I39: elc_spv_001 | J39: S01b0101h24 | K39: 0 | L39: IMPNRGZ | N39: elc_won_001 | O39: S01b0101h24 | P39: 0.00021259559 | Q39: IMPNRGZ | S39: elc_wof_001 | T39: S01b0101h24 | U39: 0.00021259559 | V39: IMPNRGZ | X39: 0.00011415525 | Y39: 2.9833677e-05 | Z39: S01b0101h24 | AA39: elc_roadtransport
I40: elc_spv_002 | J40: S01aH01 | K40: 0.996849 | L40: IMPNRGZ | N40: elc_won_002 | O40: S01aH01 | P40: 0.85063997 | Q40: IMPNRGZ | S40: elc_wof_002 | T40: S01aH01 | U40: 0.85063997 | V40: IMPNRGZ
I41: elc_spv_002 | J41: S01aH02 | K41: 0 | L41: IMPNRGZ | N41: elc_won_002 | O41: S01aH02 | P41: 0.04024578 | Q41: IMPNRGZ | S41: elc_wof_002 | T41: S01aH02 | U41: 0.04024578 | V41: IMPNRGZ
I42: elc_spv_002 | J42: S01aH03 | K42: 0 | L42: IMPNRGZ | N42: elc_won_002 | O42: S01aH03 | P42: 0.040139847 | Q42: IMPNRGZ | S42: elc_wof_002 | T42: S01aH03 | U42: 0.040139847 | V42: IMPNRGZ
I43: elc_spv_002 | J43: S01aH04 | K43: 0 | L43: IMPNRGZ | N43: elc_won_002 | O43: S01aH04 | P43: 0.036069719 | Q43: IMPNRGZ | S43: elc_wof_002 | T43: S01aH04 | U43: 0.036069719 | V43: IMPNRGZ
I44: elc_spv_002 | J44: S01aH05 | K44: 0 | L44: IMPNRGZ | N44: elc_won_002 | O44: S01aH05 | P44: 0.030909748 | Q44: IMPNRGZ | S44: elc_wof_002 | T44: S01aH05 | U44: 0.030909748 | V44: IMPNRGZ
I45: elc_spv_002 | J45: S01b0101h01 | K45: 0 | L45: IMPNRGZ | N45: elc_won_002 | O45: S01b0101h01 | P45: 2.2732548e-05 | Q45: IMPNRGZ | S45: elc_wof_002 | T45: S01b0101h01 | U45: 2.2732548e-05 | V45: IMPNRGZ
I46: elc_spv_002 | J46: S01b0101h02 | K46: 0 | L46: IMPNRGZ | N46: elc_won_002 | O46: S01b0101h02 | P46: 2.9160169e-06 | Q46: IMPNRGZ | S46: elc_wof_002 | T46: S01b0101h02 | U46: 2.9160169e-06 | V46: IMPNRGZ
I47: elc_spv_002 | J47: S01b0101h03 | K47: 0 | L47: IMPNRGZ | N47: elc_won_002 | O47: S01b0101h03 | P47: 3.7282911e-05 | Q47: IMPNRGZ | S47: elc_wof_002 | T47: S01b0101h03 | U47: 3.7282911e-05 | V47: IMPNRGZ
I48: elc_spv_002 | J48: S01b0101h04 | K48: 0 | L48: IMPNRGZ | N48: elc_won_002 | O48: S01b0101h04 | P48: 1.6515008e-05 | Q48: IMPNRGZ | S48: elc_wof_002 | T48: S01b0101h04 | U48: 1.6515008e-05 | V48: IMPNRGZ
I49: elc_spv_002 | J49: S01b0101h05 | K49: 0 | L49: IMPNRGZ | N49: elc_won_002 | O49: S01b0101h05 | P49: 5.33096e-06 | Q49: IMPNRGZ | S49: elc_wof_002 | T49: S01b0101h05 | U49: 5.33096e-06 | V49: IMPNRGZ
I50: elc_spv_002 | J50: S01b0101h06 | K50: 0 | L50: IMPNRGZ | N50: elc_won_002 | O50: S01b0101h06 | P50: 4.9861382e-06 | Q50: IMPNRGZ | S50: elc_wof_002 | T50: S01b0101h06 | U50: 4.9861382e-06 | V50: IMPNRGZ
I51: elc_spv_002 | J51: S01b0101h07 | K51: 0 | L51: IMPNRGZ | N51: elc_won_002 | O51: S01b0101h07 | P51: 5.3202848e-06 | Q51: IMPNRGZ | S51: elc_wof_002 | T51: S01b0101h07 | U51: 5.3202848e-06 | V51: IMPNRGZ
... I155: elc_spv_005 | J155: S01b0101h24 | K155: 0 | L155: IMPNRGZ | N155: elc_won_005 | O155: S01b0101h24 | P155: 2.7544626e-05 | Q155: IMPNRGZ | S155: elc_wof_005 | T155: S01b0101h24 | U155: 2.7544626e-05 | V155: IMPNRGZ
I156: elc_spv_006 | J156: S01aH01 | K156: 0.99685162 | L156: IMPNRGZ
I157: elc_spv_006 | J157: S01aH02 | K157: 0 | L157: IMPNRGZ
I158: elc_spv_006 | J158: S01aH03 | K158: 0 | L158: IMPNRGZ
I159: elc_spv_006 | J159: S01aH04 | K159: 0 | L159: IMPNRGZ
I160: elc_spv_006 | J160: S01aH05 | K160: 0 | L160: IMPNRGZ
I161: elc_spv_006 | J161: S01b0101h01 | K161: 0 | L161: IMPNRGZ
I162: elc_spv_006 | J162: S01b0101h02 | K162: 0 | L162: IMPNRGZ
I163: elc_spv_006 | J163: S01b0101h03 | K163: 0 | L163: IMPNRGZ
I164: elc_spv_006 | J164: S01b0101h04 | K164: 0 | L164: IMPNRGZ
I165: elc_spv_006 | J165: S01b0101h05 | K165: 0 | L165: IMPNRGZ
...

Sheet s1v1_d
C9: =IF(A11="x","DeActivated","~TimeSlices") -> DeActivated | I9: =IF(A11="x","DeActivated","~TFM_DINS-AT") -> DeActivated | N9: =IF(A11="x","DeActivated","~TFM_DINS-AT") -> DeActivated | S9: =IF(A11="x","DeActivated","~TFM_DINS-AT") -> DeActivated | X9: =IF(A11="x","DeActivated","~TFM_DINS-AT") -> DeActivated
A10: s1v1_d | C10: season | D10: weekly | E10: daynite | F10: wparent | G10: dparent | I10: commodity | J10: timeslice | K10: com_fr | L10: process | N10: commodity | O10: timeslice | P10: com_fr | Q10: process | S10: commodity | T10: timeslice | U10: com_fr | V10: process | X10: g_yrfr | Y10: com_fr | Z10: timeslice | AA10: commodity
A11: =IFERROR(IF(Veda!D5=A10,"ok","x"),"") -> x | C11: S01 | D11: a | E11: 0101h01 | F11: S01 | G11: b | I11: elc_spv_001 | J11: S01aH01 | K11: 0.99321152 | L11: IMPNRGZ | N11: elc_won_001 | O11: S01aH01 | P11: 0.80013268 | Q11: IMPNRGZ | S11: elc_wof_001 | T11: S01aH01 | U11: 0.80013268 | V11: IMPNRGZ | X11: 0.82876712 | Y11: 0.89464734 | Z11: S01aH01 | AA11: elc_roadtransport
D12: b | E12: 0101h02 | F12: S01 | G12: b | I12: elc_spv_001 | J12: S01aH02 | K12: 0 | L12: IMPNRGZ | N12: elc_won_001 | O12: S01aH02 | P12: 0.052757572 | Q12: IMPNRGZ | S12: elc_wof_001 | T12: S01aH02 | U12: 0.052757572 | V12: IMPNRGZ | X12: 0.041438356 | Y12: 0.039708624 | Z12: S01aH02 | AA12: elc_roadtransport
D13: c | E13: 0101h03 | F13: S01 | G13: b | I13: elc_spv_001 | J13: S01aH03 | K13: 0 | L13: IMPNRGZ | N13: elc_won_001 | O13: S01aH03 | P13: 0.053279794 | Q13: IMPNRGZ | S13: elc_wof_001 | T13: S01aH03 | U13: 0.053279794 | V13: IMPNRGZ | X13: 0.041438356 | Y13: 0.028879 | Z13: S01aH03 | AA13: elc_roadtransport
E14: 0101h04 | G14: b | I14: elc_spv_001 | J14: S01aH04 | K14: 0 | L14: IMPNRGZ | N14: elc_won_001 | O14: S01aH04 | P14: 0.048006644 | Q14: IMPNRGZ | S14: elc_wof_001 | T14: S01aH04 | U14: 0.048006644 | V14: IMPNRGZ | X14: 0.041438356 | Y14: 0.020455958 | Z14: S01aH04 | AA14: elc_roadtransport
E15: 0101h05 | G15: b | I15: elc_spv_001 | J15: S01aH05 | K15: 0 | L15: IMPNRGZ | N15: elc_won_001 | O15: S01aH05 | P15: 0.040538506 | Q15: IMPNRGZ | S15: elc_wof_001 | T15: S01aH05 | U15: 0.040538506 | V15: IMPNRGZ | X15: 0.041438356 | Y15: 0.010829625 | Z15: S01aH05 | AA15: elc_roadtransport
E16: 0101h06 | G16: b | I16: elc_spv_001 | J16: S01b0101h01 | K16: 0 | L16: IMPNRGZ | N16: elc_won_001 | O16: S01b0101h01 | P16: 2.1666408e-05 | Q16: IMPNRGZ | S16: elc_wof_001 | T16: S01b0101h01 | U16: 2.1666408e-05 | V16: IMPNRGZ | X16: 0.00011415525 | Y16: 2.1546545e-05 | Z16: S01b0101h01 | AA16: elc_roadtransport
E17: 0101h07 | G17: b | I17: elc_spv_001 | J17: S01b0101h02 | K17: 0 | L17: IMPNRGZ | N17: elc_won_001 | O17: S01b0101h02 | P17: 1.4922984e-05 | Q17: IMPNRGZ | S17: elc_wof_001 | T17: S01b0101h02 | U17: 1.4922984e-05 | V17: IMPNRGZ | X17: 0.00011415525 | Y17: 1.4916839e-05 | Z17: S01b0101h02 | AA17: elc_roadtransport
E18: 0101h08 | G18: b | I18: elc_spv_001 | J18: S01b0101h03 | K18: 0 | L18: IMPNRGZ | N18: elc_won_001 | O18: S01b0101h03 | P18: 1.3659638e-05 | Q18: IMPNRGZ | S18: elc_wof_001 | T18: S01b0101h03 | U18: 1.3659638e-05 | V18: IMPNRGZ | X18: 0.00011415525 | Y18: 1.6574265e-05 | Z18: S01b0101h03 | AA18: elc_roadtransport
E19: 0101h09 | G19: b | I19: elc_spv_001 | J19: S01b0101h04 | K19: 0 | L19: IMPNRGZ | N19: elc_won_001 | O19: S01b0101h04 | P19: 2.1244554e-05 | Q19: IMPNRGZ | S19: elc_wof_001 | T19: S01b0101h04 | U19: 2.1244554e-05 | V19: IMPNRGZ | X19: 0.00011415525 | Y19: 1.4585353e-05 | Z19: S01b0101h04 | AA19: elc_roadtransport
E20: 0101h10 | G20: b | I20: elc_spv_001 | J20: S01b0101h05 | K20: 0 | L20: IMPNRGZ | N20: elc_won_001 | O20: S01b0101h05 | P20: 1.9842827e-05 | Q20: IMPNRGZ | S20: elc_wof_001 | T20: S01b0101h05 | U20: 1.9842827e-05 | V20: IMPNRGZ | X20: 0.00011415525 | Y20: 2.1215059e-05 | Z20: S01b0101h05 | AA20: elc_roadtransport
E21: 0101h11 | G21: b | I21: elc_spv_001 | J21: S01b0101h06 | K21: 0 | L21: IMPNRGZ | N21: elc_won_001 | O21: S01b0101h06 | P21: 1.8525786e-05 | Q21: IMPNRGZ | S21: elc_wof_001 | T21: S01b0101h06 | U21: 1.8525786e-05 | V21: IMPNRGZ | X21: 0.00011415525 | Y21: 5.7678443e-05 | Z21: S01b0101h06 | AA21: elc_roadtransport
E22: 0101h12 | G22: b | I22: elc_spv_001 | J22: S01b0101h07 | K22: 0 | L22: IMPNRGZ | N22: elc_won_001 | O22: S01b0101h07 | P22: 1.800281e-05 | Q22: IMPNRGZ | S22: elc_wof_001 | T22: S01b0101h07 | U22: 1.800281e-05 | V22: IMPNRGZ | X22: 0.00011415525 | Y22: 0.0001690575 | Z22: S01b0101h07 | AA22: elc_roadtransport
E23: 0101h13 | G23: b | I23: elc_spv_001 | J23: S01b0101h08 | K23: 0.00011983367 | L23: IMPNRGZ | N23: elc_won_001 | O23: S01b0101h08 | P23: 1.5135502e-05 | Q23: IMPNRGZ | S23: elc_wof_001 | T23: S01b0101h08 | U23: 1.5135502e-05 | V23: IMPNRGZ | X23: 0.00011415525 | Y23: 0.00019060405 | Z23: S01b0101h08 | AA23: elc_roadtransport
E24: 0101h14 | G24: b | I24: elc_spv_001 | J24: S01b0101h09 | K24: 0.00024890525 | L24: IMPNRGZ | N24: elc_won_001 | O24: S01b0101h09 | P24: 3.1424963e-07 | Q24: IMPNRGZ | S24: elc_wof_001 | T24: S01b0101h09 | U24: 3.1424963e-07 | V24: IMPNRGZ | X24: 0.00011415525 | Y24: 0.00014585353 | Z24: S01b0101h09 | AA24: elc_roadtransport
E25: 0101h15 | G25: b | I25: elc_spv_001 | J25: S01b0101h10 | K25: 0.00023952384 | L25: IMPNRGZ | N25: elc_won_001 | O25: S01b0101h10 | P25: 8.6732413e-06 | Q25: IMPNRGZ | S25: elc_wof_001 | T25: S01b0101h10 | U25: 8.6732413e-06 | V25: IMPNRGZ | X25: 0.00011415525 | Y25: 0.00014452759 | Z25: S01b0101h10 | AA25: elc_roadtransport
... E63: H05 | G63: a | I63: elc_spv_001 | J63: S01c0102h24 | K63: 0 | L63: IMPNRGZ | N63: elc_won_001 | O63: S01c0102h24 | P63: 0.00029857084 | Q63: IMPNRGZ | S63: elc_wof_001 | T63: S01c0102h24 | U63: 0.00029857084 | V63: IMPNRGZ | X63: 0.00011415525 | Y63: 2.9833677e-05 | Z63: S01c0102h24 | AA63: elc_roadtransport
I64: elc_spv_002 | J64: S01aH01 | K64: 0.99334191 | L64: IMPNRGZ | N64: elc_won_002 | O64: S01aH01 | P64: 0.84930025 | Q64: IMPNRGZ | S64: elc_wof_002 | T64: S01aH01 | U64: 0.84930025 | V64: IMPNRGZ
I65: elc_spv_002 | J65: S01aH02 | K65: 0 | L65: IMPNRGZ | N65: elc_won_002 | O65: S01aH02 | P65: 0.040086561 | Q65: IMPNRGZ | S65: elc_wof_002 | T65: S01aH02 | U65: 0.040086561 | V65: IMPNRGZ
I66: elc_spv_002 | J66: S01aH03 | K66: 0 | L66: IMPNRGZ | N66: elc_won_002 | O66: S01aH03 | P66: 0.039956554 | Q66: IMPNRGZ | S66: elc_wof_002 | T66: S01aH03 | U66: 0.039956554 | V66: IMPNRGZ
I67: elc_spv_002 | J67: S01aH04 | K67: 0 | L67: IMPNRGZ | N67: elc_won_002 | O67: S01aH04 | P67: 0.035886049 | Q67: IMPNRGZ | S67: elc_wof_002 | T67: S01aH04 | U67: 0.035886049 | V67: IMPNRGZ
I68: elc_spv_002 | J68: S01aH05 | K68: 0 | L68: IMPNRGZ | N68: elc_won_002 | O68: S01aH05 | P68: 0.030748657 | Q68: IMPNRGZ | S68: elc_wof_002 | T68: S01aH05 | U68: 0.030748657 | V68: IMPNRGZ
I69: elc_spv_002 | J69: S01b0101h01 | K69: 0 | L69: IMPNRGZ | N69: elc_won_002 | O69: S01b0101h01 | P69: 2.2732548e-05 | Q69: IMPNRGZ | S69: elc_wof_002 | T69: S01b0101h01 | U69: 2.2732548e-05 | V69: IMPNRGZ
I70: elc_spv_002 | J70: S01b0101h02 | K70: 0 | L70: IMPNRGZ | N70: elc_won_002 | O70: S01b0101h02 | P70: 2.9160169e-06 | Q70: IMPNRGZ | S70: elc_wof_002 | T70: S01b0101h02 | U70: 2.9160169e-06 | V70: IMPNRGZ
I71: elc_spv_002 | J71: S01b0101h03 | K71: 0 | L71: IMPNRGZ | N71: elc_won_002 | O71: S01b0101h03 | P71: 3.7282911e-05 | Q71: IMPNRGZ | S71: elc_wof_002 | T71: S01b0101h03 | U71: 3.7282911e-05 | V71: IMPNRGZ
I72: elc_spv_002 | J72: S01b0101h04 | K72: 0 | L72: IMPNRGZ | N72: elc_won_002 | O72: S01b0101h04 | P72: 1.6515008e-05 | Q72: IMPNRGZ | S72: elc_wof_002 | T72: S01b0101h04 | U72: 1.6515008e-05 | V72: IMPNRGZ
I73: elc_spv_002 | J73: S01b0101h05 | K73: 0 | L73: IMPNRGZ | N73: elc_won_002 | O73: S01b0101h05 | P73: 5.33096e-06 | Q73: IMPNRGZ | S73: elc_wof_002 | T73: S01b0101h05 | U73: 5.33096e-06 | V73: IMPNRGZ
I74: elc_spv_002 | J74: S01b0101h06 | K74: 0 | L74: IMPNRGZ | N74: elc_won_002 | O74: S01b0101h06 | P74: 4.9861382e-06 | Q74: IMPNRGZ | S74: elc_wof_002 | T74: S01b0101h06 | U74: 4.9861382e-06 | V74: IMPNRGZ
I75: elc_spv_002 | J75: S01b0101h07 | K75: 0 | L75: IMPNRGZ | N75: elc_won_002 | O75: S01b0101h07 | P75: 5.3202848e-06 | Q75: IMPNRGZ | S75: elc_wof_002 | T75: S01b0101h07 | U75: 5.3202848e-06 | V75: IMPNRGZ
... I275: elc_spv_005 | J275: S01c0102h24 | K275: 0 | L275: IMPNRGZ | N275: elc_won_005 | O275: S01c0102h24 | P275: 3.9548687e-05 | Q275: IMPNRGZ | S275: elc_wof_005 | T275: S01c0102h24 | U275: 3.9548687e-05 | V275: IMPNRGZ
I276: elc_spv_006 | J276: S01aH01 | K276: 0.99359901 | L276: IMPNRGZ
I277: elc_spv_006 | J277: S01aH02 | K277: 0 | L277: IMPNRGZ
I278: elc_spv_006 | J278: S01aH03 | K278: 0 | L278: IMPNRGZ
I279: elc_spv_006 | J279: S01aH04 | K279: 0 | L279: IMPNRGZ
I280: elc_spv_006 | J280: S01aH05 | K280: 0 | L280: IMPNRGZ
I281: elc_spv_006 | J281: S01b0101h01 | K281: 0 | L281: IMPNRGZ
I282: elc_spv_006 | J282: S01b0101h02 | K282: 0 | L282: IMPNRGZ
I283: elc_spv_006 | J283: S01b0101h03 | K283: 0 | L283: IMPNRGZ
I284: elc_spv_006 | J284: S01b0101h04 | K284: 0 | L284: IMPNRGZ
...

Sheet ts_annual
C9: =IF(A11="x","DeActivated","~TimeSlices") -> ~TimeSlices | I9: =IF(A11="x","DeActivated","~TFM_DINS-AT") -> ~TFM_DINS-AT | N9: =IF(A11="x","DeActivated","~TFM_DINS-AT") -> ~TFM_DINS-AT | S9: =IF(A11="x","DeActivated","~TFM_DINS-AT") -> ~TFM_DINS-AT | X9: =IF(A11="x","DeActivated","~TFM_DINS-AT") -> ~TFM_DINS-AT
A10: ts_annual | C10: season | D10: weekly | E10: daynite | F10: wparent | G10: dparent | I10: commodity | J10: timeslice | K10: com_fr | L10: process | N10: commodity | O10: timeslice | P10: com_fr | Q10: process | S10: commodity | T10: timeslice | U10: com_fr | V10: process | X10: g_yrfr | Y10: com_fr | Z10: timeslice | AA10: commodity
A11: =IFERROR(IF(Veda!D5=A10,"ok","x"),"") -> ok | C11: AllS | D11: a | E11: AllH | F11: AllS | G11: a | I11: elc_spv_001 | J11: AllSaAllH | K11: 1 | L11: IMPNRGZ | N11: elc_won_001 | O11: AllSaAllH | P11: 1 | Q11: IMPNRGZ | S11: elc_wof_001 | T11: AllSaAllH | U11: 1 | V11: IMPNRGZ | X11: 1 | Y11: 1 | Z11: AllSaAllH | AA11: elc_roadtransport
I12: elc_spv_002 | J12: AllSaAllH | K12: 1 | L12: IMPNRGZ | N12: elc_won_002 | O12: AllSaAllH | P12: 1 | Q12: IMPNRGZ | S12: elc_wof_002 | T12: AllSaAllH | U12: 1 | V12: IMPNRGZ
I13: elc_spv_003 | J13: AllSaAllH | K13: 1 | L13: IMPNRGZ | N13: elc_won_003 | O13: AllSaAllH | P13: 1 | Q13: IMPNRGZ | S13: elc_wof_003 | T13: AllSaAllH | U13: 1 | V13: IMPNRGZ
I14: elc_spv_004 | J14: AllSaAllH | K14: 1 | L14: IMPNRGZ | N14: elc_won_004 | O14: AllSaAllH | P14: 1 | Q14: IMPNRGZ | S14: elc_wof_004 | T14: AllSaAllH | U14: 1 | V14: IMPNRGZ
I15: elc_spv_005 | J15: AllSaAllH | K15: 1 | L15: IMPNRGZ | N15: elc_won_005 | O15: AllSaAllH | P15: 1 | Q15: IMPNRGZ | S15: elc_wof_005 | T15: AllSaAllH | U15: 1 | V15: IMPNRGZ
I16: elc_spv_006 | J16: AllSaAllH | K16: 1 | L16: IMPNRGZ
I17: elc_spv_007 | J17: AllSaAllH | K17: 1 | L17: IMPNRGZ
I18: elc_spv_008 | J18: AllSaAllH | K18: 1 | L18: IMPNRGZ
I19: elc_spv_009 | J19: AllSaAllH | K19: 1 | L19: IMPNRGZ
I20: elc_spv_010 | J20: AllSaAllH | K20: 1 | L20: IMPNRGZ
I21: elc_spv_011 | J21: AllSaAllH | K21: 1 | L21: IMPNRGZ
I22: elc_spv_012 | J22: AllSaAllH | K22: 1 | L22: IMPNRGZ
I23: elc_spv_013 | J23: AllSaAllH | K23: 1 | L23: IMPNRGZ
I24: elc_spv_014 | J24: AllSaAllH | K24: 1 | L24: IMPNRGZ
I25: elc_spv_015 | J25: AllSaAllH | K25: 1 | L25: IMPNRGZ
I26: elc_spv_016 | J26: AllSaAllH | K26: 1 | L26: IMPNRGZ
I27: elc_spv_017 | J27: AllSaAllH | K27: 1 | L27: IMPNRGZ

Sheet ts_12t
C9: =IF(A11="x","DeActivated","~TimeSlices") -> DeActivated | I9: =IF(A11="x","DeActivated","~TFM_DINS-AT") -> DeActivated | N9: =IF(A11="x","DeActivated","~TFM_DINS-AT") -> DeActivated | S9: =IF(A11="x","DeActivated","~TFM_DINS-AT") -> DeActivated | X9: =IF(A11="x","DeActivated","~TFM_DINS-AT") -> DeActivated
A10: ts_12t | C10: season | D10: weekly | E10: daynite | F10: wparent | G10: dparent | I10: commodity | J10: timeslice | K10: com_fr | L10: process | N10: commodity | O10: timeslice | P10: com_fr | Q10: process | S10: commodity | T10: timeslice | U10: com_fr | V10: process | X10: g_yrfr | Y10: com_fr | Z10: timeslice | AA10: commodity
A11: =IFERROR(IF(Veda!D5=A10,"ok","x"),"") -> x | C11: F | D11: a | E11: D | F11: W,R,S,F | G11: a | I11: elc_spv_001 | J11: FaD | K11: 0.23022636 | L11: IMPNRGZ | N11: elc_won_001 | O11: FaD | P11: 0.14938822 | Q11: IMPNRGZ | S11: elc_wof_001 | T11: FaD | U11: 0.14938822 | V11: IMPNRGZ | X11: 0.11426941 | Y11: 0.16087081 | Z11: FaD | AA11: elc_roadtransport
C12: R | E12: N | G12: a | I12: elc_spv_001 | J12: FaN | K12: 0 | L12: IMPNRGZ | N12: elc_won_001 | O12: FaN | P12: 0.099049377 | Q12: IMPNRGZ | S12: elc_wof_001 | T12: FaN | U12: 0.099049377 | V12: IMPNRGZ | X12: 0.11426941 | Y12: 0.052547713 | Z12: FaN | AA12: elc_roadtransport
C13: S | E13: P | G13: a | I13: elc_spv_001 | J13: FaP | K13: 0.028197022 | L13: IMPNRGZ | N13: elc_won_001 | O13: FaP | P13: 0.015082775 | Q13: IMPNRGZ | S13: elc_wof_001 | T13: FaP | U13: 0.015082775 | V13: IMPNRGZ | X13: 0.020776256 | Y13: 0.035896543 | Z13: FaP | AA13: elc_roadtransport
C14: W | I14: elc_spv_001 | J14: RaD | K14: 0.1943636 | L14: IMPNRGZ | N14: elc_won_001 | O14: RaD | P14: 0.084836745 | Q14: IMPNRGZ | S14: elc_wof_001 | T14: RaD | U14: 0.084836745 | V14: IMPNRGZ | X14: 0.11552511 | Y14: 0.16263862 | Z14: RaD | AA14: elc_roadtransport
I15: elc_spv_001 | J15: RaN | K15: 0 | L15: IMPNRGZ | N15: elc_won_001 | O15: RaN | P15: 0.093223344 | Q15: IMPNRGZ | S15: elc_wof_001 | T15: RaN | U15: 0.093223344 | V15: IMPNRGZ | X15: 0.11552511 | Y15: 0.053125161 | Z15: RaN | AA15: elc_roadtransport
I16: elc_spv_001 | J16: RaP | K16: 0.028521865 | L16: IMPNRGZ | N16: elc_won_001 | O16: RaP | P16: 0.013917712 | Q16: IMPNRGZ | S16: elc_wof_001 | T16: RaP | U16: 0.013917712 | V16: IMPNRGZ | X16: 0.021004566 | Y16: 0.036291011 | Z16: RaP | AA16: elc_roadtransport
